Workbook

Sheet ALL Tube Results
A1: =IFERROR(__xludf.DUMMYFUNCTION("QUERY({ 'APS Tubes Import'!A1:A809; 'ARF Tubes'!M2:M809 }, ""SELECT Col1 WHERE Col1 IS NOT NULL"", 0)"),"TUBE ID") -> TUBE ID | B1: =IFERROR(__xludf.DUMMYFUNCTION("QUERY({ 'APS Tubes Import'!V1:V809; 'ARF Tubes'!N2:N809 }, ""SELECT Col1 WHERE Col1 IS NOT NULL"", 0)"),"FINAL ASSIGNED RUN ID") -> FINAL ASSIGNED RUN ID | C1: ='Run Reconcile'!B1 -> RUN DATE | D1: ='APS Tubes Import'!B1 -> COLLECTION DATE | E1: ='APS Tubes Import'!C1 -> COLLECTION TIME | F1: =IFERROR(__xludf.DUMMYFUNCTION("QUERY({ 'APS Tubes Import'!H1:H809; 'ARF Tubes'!P2:P809 }, ""SELECT Col1 WHERE Col1 IS NOT NULL"", 0)"),"FINAL RESULT") -> FINAL RESULT | G1: ='APS Tubes Import'!N1 -> NUM SAMPLES (Pool Level)
A2: =IFERROR(__xludf.DUMMYFUNCTION("""COMPUTED_VALUE"""),"MAX88") -> MAX88 | B2: =IFERROR(__xludf.DUMMYFUNCTION("""COMPUTED_VALUE"""),"RUN-BEND_2021-12-10_APS-001") -> RUN-BEND_2021-12-10_APS-001 | C2: =VLOOKUP(B2,'Run Reconcile'!A$2:B809,2,FALSE) -> 44540 | D2: =IFERROR(__xludf.DUMMYFUNCTION("QUERY({ 'APS Tubes Import'!B2:B809 }, ""SELECT Col1 WHERE Col1 IS NOT NULL"", 0)"),44540.0) -> 44540 | E2: =IFERROR(__xludf.DUMMYFUNCTION("QUERY({ 'APS Tubes Import'!C2:C809; 'ARF Tubes'!P2:P809 }, ""SELECT Col1 WHERE Col1 IS NOT NULL"", 0)"),0.29401620370481396) -> 0.2940162 | F2: =IFERROR(__xludf.DUMMYFUNCTION("""COMPUTED_VALUE"""),"Negative") -> Negative | G2: =IFERROR(__xludf.DUMMYFUNCTION("QUERY({ 'APS Tubes Import'!N2:N809 }, ""SELECT Col1 WHERE Col1 IS NOT NULL"", 0)"),1.0) -> 1
A3: =IFERROR(__xludf.DUMMYFUNCTION("""COMPUTED_VALUE"""),"MAX136") -> MAX136 | B3: =IFERROR(__xludf.DUMMYFUNCTION("""COMPUTED_VALUE"""),"RUN-BEND_2021-12-10_APS-001") -> RUN-BEND_2021-12-10_APS-001 | C3: =VLOOKUP(B3,'Run Reconcile'!A$2:B809,2,FALSE) -> 44540 | D3: =IFERROR(__xludf.DUMMYFUNCTION("""COMPUTED_VALUE"""),44540.0) -> 44540 | E3: =IFERROR(__xludf.DUMMYFUNCTION("""COMPUTED_VALUE"""),0.2980092592588335) -> 0.29800926 | F3: =IFERROR(__xludf.DUMMYFUNCTION("""COMPUTED_VALUE"""),"Negative") -> Negative | G3: =IFERROR(__xludf.DUMMYFUNCTION("""COMPUTED_VALUE"""),1.0) -> 1
A4: =IFERROR(__xludf.DUMMYFUNCTION("""COMPUTED_VALUE"""),"MAX79") -> MAX79 | B4: =IFERROR(__xludf.DUMMYFUNCTION("""COMPUTED_VALUE"""),"RUN-BEND_2021-12-10_APS-001") -> RUN-BEND_2021-12-10_APS-001 | C4: =VLOOKUP(B4,'Run Reconcile'!A$2:B809,2,FALSE) -> 44540 | D4: =IFERROR(__xludf.DUMMYFUNCTION("""COMPUTED_VALUE"""),44540.0) -> 44540 | E4: =IFERROR(__xludf.DUMMYFUNCTION("""COMPUTED_VALUE"""),0.3005439814805868) -> 0.30054398 | F4: =IFERROR(__xludf.DUMMYFUNCTION("""COMPUTED_VALUE"""),"Negative") -> Negative | G4: =IFERROR(__xludf.DUMMYFUNCTION("""COMPUTED_VALUE"""),1.0) -> 1
A5: =IFERROR(__xludf.DUMMYFUNCTION("""COMPUTED_VALUE"""),"MAX64") -> MAX64 | B5: =IFERROR(__xludf.DUMMYFUNCTION("""COMPUTED_VALUE"""),"RUN-BEND_2021-12-10_APS-001") -> RUN-BEND_2021-12-10_APS-001 | C5: =VLOOKUP(B5,'Run Reconcile'!A$2:B809,2,FALSE) -> 44540 | D5: =IFERROR(__xludf.DUMMYFUNCTION("""COMPUTED_VALUE"""),44540.0) -> 44540 | E5: =IFERROR(__xludf.DUMMYFUNCTION("""COMPUTED_VALUE"""),0.3010532407424762) -> 0.30105324 | F5: =IFERROR(__xludf.DUMMYFUNCTION("""COMPUTED_VALUE"""),"Negative") -> Negative | G5: =IFERROR(__xludf.DUMMYFUNCTION("""COMPUTED_VALUE"""),1.0) -> 1
A6: =IFERROR(__xludf.DUMMYFUNCTION("""COMPUTED_VALUE"""),"MA1025") -> MA1025 | B6: =IFERROR(__xludf.DUMMYFUNCTION("""COMPUTED_VALUE"""),"RUN-BEND_2021-12-10_APS-001") -> RUN-BEND_2021-12-10_APS-001 | C6: =VLOOKUP(B6,'Run Reconcile'!A$2:B809,2,FALSE) -> 44540 | D6: =IFERROR(__xludf.DUMMYFUNCTION("""COMPUTED_VALUE"""),44540.0) -> 44540 | E6: =IFERROR(__xludf.DUMMYFUNCTION("""COMPUTED_VALUE"""),0.31128472222189885) -> 0.31128472 | F6: =IFERROR(__xludf.DUMMYFUNCTION("""COMPUTED_VALUE"""),"Negative") -> Negative | G6: =IFERROR(__xludf.DUMMYFUNCTION("""COMPUTED_VALUE"""),1.0) -> 1
A7: =IFERROR(__xludf.DUMMYFUNCTION("""COMPUTED_VALUE"""),"MAX70") -> MAX70 | B7: =IFERROR(__xludf.DUMMYFUNCTION("""COMPUTED_VALUE"""),"RUN-BEND_2021-12-13_RFR-002") -> RUN-BEND_2021-12-13_RFR-002 | C7: =VLOOKUP(B7,'Run Reconcile'!A$2:B809,2,FALSE) -> 44543 | D7: =IFERROR(__xludf.DUMMYFUNCTION("""COMPUTED_VALUE"""),44543.0) -> 44543 | E7: =IFERROR(__xludf.DUMMYFUNCTION("""COMPUTED_VALUE"""),0.4924074074078817) -> 0.49240741 | F7: =IFERROR(__xludf.DUMMYFUNCTION("""COMPUTED_VALUE"""),"Negative") -> Negative | G7: =IFERROR(__xludf.DUMMYFUNCTION("""COMPUTED_VALUE"""),1.0) -> 1
A8: =IFERROR(__xludf.DUMMYFUNCTION("""COMPUTED_VALUE"""),"MAX111") -> MAX111 | B8: =IFERROR(__xludf.DUMMYFUNCTION("""COMPUTED_VALUE"""),"RUN-BEND_2021-12-13_RFR-002") -> RUN-BEND_2021-12-13_RFR-002 | C8: =VLOOKUP(B8,'Run Reconcile'!A$2:B809,2,FALSE) -> 44543 | D8: =IFERROR(__xludf.DUMMYFUNCTION("""COMPUTED_VALUE"""),44543.0) -> 44543 | E8: =IFERROR(__xludf.DUMMYFUNCTION("""COMPUTED_VALUE"""),0.5629166666658421) -> 0.56291667 | F8: =IFERROR(__xludf.DUMMYFUNCTION("""COMPUTED_VALUE"""),"Negative") -> Negative | G8: =IFERROR(__xludf.DUMMYFUNCTION("""COMPUTED_VALUE"""),1.0) -> 1
A9: =IFERROR(__xludf.DUMMYFUNCTION("""COMPUTED_VALUE"""),"MAX113") -> MAX113 | B9: =IFERROR(__xludf.DUMMYFUNCTION("""COMPUTED_VALUE"""),"RUN-BEND_2021-12-13_RFR-002") -> RUN-BEND_2021-12-13_RFR-002 | C9: =VLOOKUP(B9,'Run Reconcile'!A$2:B809,2,FALSE) -> 44543 | D9: =IFERROR(__xludf.DUMMYFUNCTION("""COMPUTED_VALUE"""),44543.0) -> 44543 | E9: =IFERROR(__xludf.DUMMYFUNCTION("""COMPUTED_VALUE"""),0.5630208333350311) -> 0.56302083 | F9: =IFERROR(__xludf.DUMMYFUNCTION("""COMPUTED_VALUE"""),"Negative") -> Negative | G9: =IFERROR(__xludf.DUMMYFUNCTION("""COMPUTED_VALUE"""),1.0) -> 1
A10: =IFERROR(__xludf.DUMMYFUNCTION("""COMPUTED_VALUE"""),"MAX122") -> MAX122 | B10: =IFERROR(__xludf.DUMMYFUNCTION("""COMPUTED_VALUE"""),"RUN-BEND_2021-12-13_RFR-002") -> RUN-BEND_2021-12-13_RFR-002 | C10: =VLOOKUP(B10,'Run Reconcile'!A$2:B809,2,FALSE) -> 44543 | D10: =IFERROR(__xludf.DUMMYFUNCTION("""COMPUTED_VALUE"""),44543.0) -> 44543 | E10: =IFERROR(__xludf.DUMMYFUNCTION("""COMPUTED_VALUE"""),0.5931712962956226) -> 0.5931713 | F10: =IFERROR(__xludf.DUMMYFUNCTION("""COMPUTED_VALUE"""),"Negative") -> Negative | G10: =IFERROR(__xludf.DUMMYFUNCTION("""COMPUTED_VALUE"""),1.0) -> 1
A11: =IFERROR(__xludf.DUMMYFUNCTION("""COMPUTED_VALUE"""),"MAX94") -> MAX94 | B11: =IFERROR(__xludf.DUMMYFUNCTION("""COMPUTED_VALUE"""),"RUN-BEND_2021-12-13_RFR-002") -> RUN-BEND_2021-12-13_RFR-002 | C11: =VLOOKUP(B11,'Run Reconcile'!A$2:B809,2,FALSE) -> 44543 | D11: =IFERROR(__xludf.DUMMYFUNCTION("""COMPUTED_VALUE"""),44543.0) -> 44543 | E11: =IFERROR(__xludf.DUMMYFUNCTION("""COMPUTED_VALUE"""),0.5967476851838001) -> 0.59674769 | F11: =IFERROR(__xludf.DUMMYFUNCTION("""COMPUTED_VALUE"""),"Negative") -> Negative | G11: =IFERROR(__xludf.DUMMYFUNCTION("""COMPUTED_VALUE"""),1.0) -> 1
A12: =IFERROR(__xludf.DUMMYFUNCTION("""COMPUTED_VALUE"""),"MAX28") -> MAX28 | B12: =IFERROR(__xludf.DUMMYFUNCTION("""COMPUTED_VALUE"""),"RUN-BEND_2021-12-13_RFR-002") -> RUN-BEND_2021-12-13_RFR-002 | C12: =VLOOKUP(B12,'Run Reconcile'!A$2:B809,2,FALSE) -> 44543 | D12: =IFERROR(__xludf.DUMMYFUNCTION("""COMPUTED_VALUE"""),44543.0) -> 44543 | E12: =IFERROR(__xludf.DUMMYFUNCTION("""COMPUTED_VALUE"""),0.5984027777776646) -> 0.59840278 | F12: =IFERROR(__xludf.DUMMYFUNCTION("""COMPUTED_VALUE"""),"Negative") -> Negative | G12: =IFERROR(__xludf.DUMMYFUNCTION("""COMPUTED_VALUE"""),1.0) -> 1
A13: =IFERROR(__xludf.DUMMYFUNCTION("""COMPUTED_VALUE"""),"MAX63") -> MAX63 | B13: =IFERROR(__xludf.DUMMYFUNCTION("""COMPUTED_VALUE"""),"RUN-BEND_2021-12-13_RFR-002") -> RUN-BEND_2021-12-13_RFR-002 | C13: =VLOOKUP(B13,'Run Reconcile'!A$2:B809,2,FALSE) -> 44543 | D13: =IFERROR(__xludf.DUMMYFUNCTION("""COMPUTED_VALUE"""),44543.0) -> 44543 | E13: =IFERROR(__xludf.DUMMYFUNCTION("""COMPUTED_VALUE"""),0.60407407407547) -> 0.60407407 | F13: =IFERROR(__xludf.DUMMYFUNCTION("""COMPUTED_VALUE"""),"Negative") -> Negative | G13: =IFERROR(__xludf.DUMMYFUNCTION("""COMPUTED_VALUE"""),1.0) -> 1
A14: =IFERROR(__xludf.DUMMYFUNCTION("""COMPUTED_VALUE"""),"MA1255") -> MA1255 | B14: =IFERROR(__xludf.DUMMYFUNCTION("""COMPUTED_VALUE"""),"RUN-BEND_2021-12-15_APS-002") -> RUN-BEND_2021-12-15_APS-002 | C14: =VLOOKUP(B14,'Run Reconcile'!A$2:B809,2,FALSE) -> 44545 | D14: =IFERROR(__xludf.DUMMYFUNCTION("""COMPUTED_VALUE"""),44545.0) -> 44545 | E14: =IFERROR(__xludf.DUMMYFUNCTION("""COMPUTED_VALUE"""),0.5749768518508063) -> 0.57497685 | F14: =IFERROR(__xludf.DUMMYFUNCTION("""COMPUTED_VALUE"""),"Negative") -> Negative | G14: =IFERROR(__xludf.DUMMYFUNCTION("""COMPUTED_VALUE"""),1.0) -> 1
A15: =IFERROR(__xludf.DUMMYFUNCTION("""COMPUTED_VALUE"""),"MA327") -> MA327 | B15: =IFERROR(__xludf.DUMMYFUNCTION("""COMPUTED_VALUE"""),"RUN-BEND_2021-12-15_APS-002") -> RUN-BEND_2021-12-15_APS-002 | C15: =VLOOKUP(B15,'Run Reconcile'!A$2:B809,2,FALSE) -> 44545 | D15: =IFERROR(__xludf.DUMMYFUNCTION("""COMPUTED_VALUE"""),44545.0) -> 44545 | E15: =IFERROR(__xludf.DUMMYFUNCTION("""COMPUTED_VALUE"""),0.586215277777228) -> 0.58621528 | F15: =IFERROR(__xludf.DUMMYFUNCTION("""COMPUTED_VALUE"""),"Negative") -> Negative | G15: =IFERROR(__xludf.DUMMYFUNCTION("""COMPUTED_VALUE"""),1.0) -> 1
A16: =IFERROR(__xludf.DUMMYFUNCTION("""COMPUTED_VALUE"""),"MA460") -> MA460 | B16: =IFERROR(__xludf.DUMMYFUNCTION("""COMPUTED_VALUE"""),"RUN-BEND_2021-12-15_APS-002") -> RUN-BEND_2021-12-15_APS-002 | C16: =VLOOKUP(B16,'Run Reconcile'!A$2:B809,2,FALSE) -> 44545 | D16: =IFERROR(__xludf.DUMMYFUNCTION("""COMPUTED_VALUE"""),44545.0) -> 44545 | E16: =IFERROR(__xludf.DUMMYFUNCTION("""COMPUTED_VALUE"""),0.6131944444459805) -> 0.61319444 | F16: =IFERROR(__xludf.DUMMYFUNCTION("""COMPUTED_VALUE"""),"Negative") -> Negative | G16: =IFERROR(__xludf.DUMMYFUNCTION("""COMPUTED_VALUE"""),1.0) -> 1
A17: =IFERROR(__xludf.DUMMYFUNCTION("""COMPUTED_VALUE"""),"MA1155") -> MA1155 | B17: =IFERROR(__xludf.DUMMYFUNCTION("""COMPUTED_VALUE"""),"RUN-BEND_2021-12-15_APS-002") -> RUN-BEND_2021-12-15_APS-002 | C17: =VLOOKUP(B17,'Run Reconcile'!A$2:B809,2,FALSE) -> 44545 | D17: =IFERROR(__xludf.DUMMYFUNCTION("""COMPUTED_VALUE"""),44545.0) -> 44545 | E17: =IFERROR(__xludf.DUMMYFUNCTION("""COMPUTED_VALUE"""),0.6686805555546016) -> 0.66868056 | F17: =IFERROR(__xludf.DUMMYFUNCTION("""COMPUTED_VALUE"""),"Negative") -> Negative | G17: =IFERROR(__xludf.DUMMYFUNCTION("""COMPUTED_VALUE"""),1.0) -> 1
A18: =IFERROR(__xludf.DUMMYFUNCTION("""COMPUTED_VALUE"""),"MA1043") -> MA1043 | B18: =IFERROR(__xludf.DUMMYFUNCTION("""COMPUTED_VALUE"""),"RUN-BEND_2021-12-17_APS-003") -> RUN-BEND_2021-12-17_APS-003 | C18: =VLOOKUP(B18,'Run Reconcile'!A$2:B809,2,FALSE) -> 44547 | D18: =IFERROR(__xludf.DUMMYFUNCTION("""COMPUTED_VALUE"""),44547.0) -> 44547 | E18: =IFERROR(__xludf.DUMMYFUNCTION("""COMPUTED_VALUE"""),0.3417824074058444) -> 0.34178241 | F18: =IFERROR(__xludf.DUMMYFUNCTION("""COMPUTED_VALUE"""),"Positive") -> Positive | G18: =IFERROR(__xludf.DUMMYFUNCTION("""COMPUTED_VALUE"""),1.0) -> 1
A19: =IFERROR(__xludf.DUMMYFUNCTION("""COMPUTED_VALUE"""),"MA1036") -> MA1036 | B19: =IFERROR(__xludf.DUMMYFUNCTION("""COMPUTED_VALUE"""),"RUN-BEND_2021-12-17_APS-003") -> RUN-BEND_2021-12-17_APS-003 | C19: =VLOOKUP(B19,'Run Reconcile'!A$2:B809,2,FALSE) -> 44547 | D19: =IFERROR(__xludf.DUMMYFUNCTION("""COMPUTED_VALUE"""),44547.0) -> 44547 | E19: =IFERROR(__xludf.DUMMYFUNCTION("""COMPUTED_VALUE"""),0.3711805555540195) -> 0.37118056 | F19: =IFERROR(__xludf.DUMMYFUNCTION("""COMPUTED_VALUE"""),"Negative") -> Negative | G19: =IFERROR(__xludf.DUMMYFUNCTION("""COMPUTED_VALUE"""),1.0) -> 1
A20: =IFERROR(__xludf.DUMMYFUNCTION("""COMPUTED_VALUE"""),"MA705") -> MA705 | B20: =IFERROR(__xludf.DUMMYFUNCTION("""COMPUTED_VALUE"""),"RUN-BEND_2021-12-20_RFR-003") -> RUN-BEND_2021-12-20_RFR-003 | C20: =VLOOKUP(B20,'Run Reconcile'!A$2:B809,2,FALSE) -> 44550 | D20: =IFERROR(__xludf.DUMMYFUNCTION("""COMPUTED_VALUE"""),44549.0) -> 44549 | E20: =IFERROR(__xludf.DUMMYFUNCTION("""COMPUTED_VALUE"""),0.8899537037032133) -> 0.8899537 | F20: =IFERROR(__xludf.DUMMYFUNCTION("""COMPUTED_VALUE"""),"Negative") -> Negative | G20: =IFERROR(__xludf.DUMMYFUNCTION("""COMPUTED_VALUE"""),1.0) -> 1
A21: =IFERROR(__xludf.DUMMYFUNCTION("""COMPUTED_VALUE"""),"MA1091") -> MA1091 | B21: =IFERROR(__xludf.DUMMYFUNCTION("""COMPUTED_VALUE"""),"RUN-BEND_2021-12-20_RFR-003") -> RUN-BEND_2021-12-20_RFR-003 | C21: =VLOOKUP(B21,'Run Reconcile'!A$2:B809,2,FALSE) -> 44550 | D21: =IFERROR(__xludf.DUMMYFUNCTION("""COMPUTED_VALUE"""),44550.0) -> 44550 | E21: =IFERROR(__xludf.DUMMYFUNCTION("""COMPUTED_VALUE"""),0.31734953703562496) -> 0.31734954 | F21: =IFERROR(__xludf.DUMMYFUNCTION("""COMPUTED_VALUE"""),"Negative") -> Negative | G21: =IFERROR(__xludf.DUMMYFUNCTION("""COMPUTED_VALUE"""),1.0) -> 1
A22: =IFERROR(__xludf.DUMMYFUNCTION("""COMPUTED_VALUE"""),"MA1160") -> MA1160 | B22: =IFERROR(__xludf.DUMMYFUNCTION("""COMPUTED_VALUE"""),"RUN-BEND_2021-12-20_RFR-003") -> RUN-BEND_2021-12-20_RFR-003 | C22: =VLOOKUP(B22,'Run Reconcile'!A$2:B809,2,FALSE) -> 44550 | D22: =IFERROR(__xludf.DUMMYFUNCTION("""COMPUTED_VALUE"""),44550.0) -> 44550 | E22: =IFERROR(__xludf.DUMMYFUNCTION("""COMPUTED_VALUE"""),0.33541666666496894) -> 0.33541667 | F22: =IFERROR(__xludf.DUMMYFUNCTION("""COMPUTED_VALUE"""),"Negative") -> Negative | G22: =IFERROR(__xludf.DUMMYFUNCTION("""COMPUTED_VALUE"""),1.0) -> 1
A23: =IFERROR(__xludf.DUMMYFUNCTION("""COMPUTED_VALUE"""),"MA542") -> MA542 | B23: =IFERROR(__xludf.DUMMYFUNCTION("""COMPUTED_VALUE"""),"RUN-BEND_2021-12-20_RFR-003") -> RUN-BEND_2021-12-20_RFR-003 | C23: =VLOOKUP(B23,'Run Reconcile'!A$2:B809,2,FALSE) -> 44550 | D23: =IFERROR(__xludf.DUMMYFUNCTION("""COMPUTED_VALUE"""),44550.0) -> 44550 | E23: =IFERROR(__xludf.DUMMYFUNCTION("""COMPUTED_VALUE"""),0.34329861111109494) -> 0.34329861 | F23: =IFERROR(__xludf.DUMMYFUNCTION("""COMPUTED_VALUE"""),"Negative") -> Negative | G23: =IFERROR(__xludf.DUMMYFUNCTION("""COMPUTED_VALUE"""),1.0) -> 1
A24: =IFERROR(__xludf.DUMMYFUNCTION("""COMPUTED_VALUE"""),"MA197") -> MA197 | B24: =IFERROR(__xludf.DUMMYFUNCTION("""COMPUTED_VALUE"""),"RUN-BEND_2021-12-20_RFR-003") -> RUN-BEND_2021-12-20_RFR-003 | C24: =VLOOKUP(B24,'Run Reconcile'!A$2:B809,2,FALSE) -> 44550 | D24: =IFERROR(__xludf.DUMMYFUNCTION("""COMPUTED_VALUE"""),44550.0) -> 44550 | E24: =IFERROR(__xludf.DUMMYFUNCTION("""COMPUTED_VALUE"""),0.40135416666817036) -> 0.40135417 | F24: =IFERROR(__xludf.DUMMYFUNCTION("""COMPUTED_VALUE"""),"Negative") -> Negative | G24: =IFERROR(__xludf.DUMMYFUNCTION("""COMPUTED_VALUE"""),1.0) -> 1
A25: =IFERROR(__xludf.DUMMYFUNCTION("""COMPUTED_VALUE"""),"MA269") -> MA269 | B25: =IFERROR(__xludf.DUMMYFUNCTION("""COMPUTED_VALUE"""),"RUN-BEND_2021-12-20_RFR-003") -> RUN-BEND_2021-12-20_RFR-003 | C25: =VLOOKUP(B25,'Run Reconcile'!A$2:B809,2,FALSE) -> 44550 | D25: =IFERROR(__xludf.DUMMYFUNCTION("""COMPUTED_VALUE"""),44550.0) -> 44550 | E25: =IFERROR(__xludf.DUMMYFUNCTION("""COMPUTED_VALUE"""),0.40187499999956344) -> 0.401875 | F25: =IFERROR(__xludf.DUMMYFUNCTION("""COMPUTED_VALUE"""),"Negative") -> Negative | G25: =IFERROR(__xludf.DUMMYFUNCTION("""COMPUTED_VALUE"""),1.0) -> 1
A26: =IFERROR(__xludf.DUMMYFUNCTION("""COMPUTED_VALUE"""),"MA1080") -> MA1080 | B26: =IFERROR(__xludf.DUMMYFUNCTION("""COMPUTED_VALUE"""),"RUN-BEND_2021-12-20_RFR-003") -> RUN-BEND_2021-12-20_RFR-003 | C26: =VLOOKUP(B26,'Run Reconcile'!A$2:B809,2,FALSE) -> 44550 | D26: =IFERROR(__xludf.DUMMYFUNCTION("""COMPUTED_VALUE"""),44550.0) -> 44550 | E26: =IFERROR(__xludf.DUMMYFUNCTION("""COMPUTED_VALUE"""),0.4363425925912452) -> 0.43634259 | F26: =IFERROR(__xludf.DUMMYFUNCTION("""COMPUTED_VALUE"""),"Negative") -> Negative | G26: =IFERROR(__xludf.DUMMYFUNCTION("""COMPUTED_VALUE"""),1.0) -> 1
A27: =IFERROR(__xludf.DUMMYFUNCTION("""COMPUTED_VALUE"""),"MA1030") -> MA1030 | B27: =IFERROR(__xludf.DUMMYFUNCTION("""COMPUTED_VALUE"""),"RUN-BEND_2021-12-22_RFR-004") -> RUN-BEND_2021-12-22_RFR-004 | C27: =VLOOKUP(B27,'Run Reconcile'!A$2:B809,2,FALSE) -> 44552 | D27: =IFERROR(__xludf.DUMMYFUNCTION("""COMPUTED_VALUE"""),44551.0) -> 44551 | E27: =IFERROR(__xludf.DUMMYFUNCTION("""COMPUTED_VALUE"""),0.18810185185066075) -> 0.18810185 | F27: =IFERROR(__xludf.DUMMYFUNCTION("""COMPUTED_VALUE"""),"Negative") -> Negative | G27: =IFERROR(__xludf.DUMMYFUNCTION("""COMPUTED_VALUE"""),1.0) -> 1
A28: =IFERROR(__xludf.DUMMYFUNCTION("""COMPUTED_VALUE"""),"MA1315") -> MA1315 | B28: =IFERROR(__xludf.DUMMYFUNCTION("""COMPUTED_VALUE"""),"RUN-BEND_2021-12-22_RFR-004") -> RUN-BEND_2021-12-22_RFR-004 | C28: =VLOOKUP(B28,'Run Reconcile'!A$2:B809,2,FALSE) -> 44552 | D28: =IFERROR(__xludf.DUMMYFUNCTION("""COMPUTED_VALUE"""),44551.0) -> 44551 | E28: =IFERROR(__xludf.DUMMYFUNCTION("""COMPUTED_VALUE"""),0.47054398148247856) -> 0.47054398 | F28: =IFERROR(__xludf.DUMMYFUNCTION("""COMPUTED_VALUE"""),"Negative") -> Negative | G28: =IFERROR(__xludf.DUMMYFUNCTION("""COMPUTED_VALUE"""),1.0) -> 1
A29: =IFERROR(__xludf.DUMMYFUNCTION("""COMPUTED_VALUE"""),"MA1203") -> MA1203 | B29: =IFERROR(__xludf.DUMMYFUNCTION("""COMPUTED_VALUE"""),"RUN-BEND_2021-12-22_RFR-004") -> RUN-BEND_2021-12-22_RFR-004 | C29: =VLOOKUP(B29,'Run Reconcile'!A$2:B809,2,FALSE) -> 44552 | D29: =IFERROR(__xludf.DUMMYFUNCTION("""COMPUTED_VALUE"""),44552.0) -> 44552 | E29: =IFERROR(__xludf.DUMMYFUNCTION("""COMPUTED_VALUE"""),0.3487962962972233) -> 0.3487963 | F29: =IFERROR(__xludf.DUMMYFUNCTION("""COMPUTED_VALUE"""),"Negative") -> Negative | G29: =IFERROR(__xludf.DUMMYFUNCTION("""COMPUTED_VALUE"""),1.0) -> 1
A30: =IFERROR(__xludf.DUMMYFUNCTION("""COMPUTED_VALUE"""),"MA1088") -> MA1088 | B30: =IFERROR(__xludf.DUMMYFUNCTION("""COMPUTED_VALUE"""),"RUN-BEND_2021-12-22_RFR-004") -> RUN-BEND_2021-12-22_RFR-004 | C30: =VLOOKUP(B30,'Run Reconcile'!A$2:B809,2,FALSE) -> 44552 | D30: =IFERROR(__xludf.DUMMYFUNCTION("""COMPUTED_VALUE"""),44552.0) -> 44552 | E30: =IFERROR(__xludf.DUMMYFUNCTION("""COMPUTED_VALUE"""),0.35877314814933925) -> 0.35877315 | F30: =IFERROR(__xludf.DUMMYFUNCTION("""COMPUTED_VALUE"""),"Negative") -> Negative | G30: =IFERROR(__xludf.DUMMYFUNCTION("""COMPUTED_VALUE"""),1.0) -> 1
A31: =IFERROR(__xludf.DUMMYFUNCTION("""COMPUTED_VALUE"""),"MA1057") -> MA1057 | B31: =IFERROR(__xludf.DUMMYFUNCTION("""COMPUTED_VALUE"""),"RUN-BEND_2021-12-22_RFR-004") -> RUN-BEND_2021-12-22_RFR-004 | C31: =VLOOKUP(B31,'Run Reconcile'!A$2:B809,2,FALSE) -> 44552 | D31: =IFERROR(__xludf.DUMMYFUNCTION("""COMPUTED_VALUE"""),44552.0) -> 44552 | E31: =IFERROR(__xludf.DUMMYFUNCTION("""COMPUTED_VALUE"""),0.3660185185181035) -> 0.36601852 | F31: =IFERROR(__xludf.DUMMYFUNCTION("""COMPUTED_VALUE"""),"Negative") -> Negative | G31: =IFERROR(__xludf.DUMMYFUNCTION("""COMPUTED_VALUE"""),1.0) -> 1
A32: =IFERROR(__xludf.DUMMYFUNCTION("""COMPUTED_VALUE"""),"MA447") -> MA447 | B32: =IFERROR(__xludf.DUMMYFUNCTION("""COMPUTED_VALUE"""),"RUN-BEND_2021-12-27_RFR-005") -> RUN-BEND_2021-12-27_RFR-005 | C32: =VLOOKUP(B32,'Run Reconcile'!A$2:B809,2,FALSE) -> 44557 | D32: =IFERROR(__xludf.DUMMYFUNCTION("""COMPUTED_VALUE"""),44556.0) -> 44556 | E32: =IFERROR(__xludf.DUMMYFUNCTION("""COMPUTED_VALUE"""),0.6234837962947495) -> 0.6234838 | F32: =IFERROR(__xludf.DUMMYFUNCTION("""COMPUTED_VALUE"""),"Negative") -> Negative | G32: =IFERROR(__xludf.DUMMYFUNCTION("""COMPUTED_VALUE"""),1.0) -> 1
A33: =IFERROR(__xludf.DUMMYFUNCTION("""COMPUTED_VALUE"""),"MA1179") -> MA1179 | B33: =IFERROR(__xludf.DUMMYFUNCTION("""COMPUTED_VALUE"""),"RUN-BEND_2021-12-27_RFR-005") -> RUN-BEND_2021-12-27_RFR-005 | C33: =VLOOKUP(B33,'Run Reconcile'!A$2:B809,2,FALSE) -> 44557 | D33: =IFERROR(__xludf.DUMMYFUNCTION("""COMPUTED_VALUE"""),44557.0) -> 44557 | E33: =IFERROR(__xludf.DUMMYFUNCTION("""COMPUTED_VALUE"""),0.3123148148151813) -> 0.31231481 | F33: =IFERROR(__xludf.DUMMYFUNCTION("""COMPUTED_VALUE"""),"Negative") -> Negative | G33: =IFERROR(__xludf.DUMMYFUNCTION("""COMPUTED_VALUE"""),1.0) -> 1
A34: =IFERROR(__xludf.DUMMYFUNCTION("""COMPUTED_VALUE"""),"MA690") -> MA690 | B34: =IFERROR(__xludf.DUMMYFUNCTION("""COMPUTED_VALUE"""),"RUN-BEND_2021-12-27_RFR-005") -> RUN-BEND_2021-12-27_RFR-005 | C34: =VLOOKUP(B34,'Run Reconcile'!A$2:B809,2,FALSE) -> 44557 | D34: =IFERROR(__xludf.DUMMYFUNCTION("""COMPUTED_VALUE"""),44557.0) -> 44557 | E34: =IFERROR(__xludf.DUMMYFUNCTION("""COMPUTED_VALUE"""),0.31266203703853535) -> 0.31266204 | F34: =IFERROR(__xludf.DUMMYFUNCTION("""COMPUTED_VALUE"""),"Negative") -> Negative | G34: =IFERROR(__xludf.DUMMYFUNCTION("""COMPUTED_VALUE"""),1.0) -> 1
A35: =IFERROR(__xludf.DUMMYFUNCTION("""COMPUTED_VALUE"""),"MA707") -> MA707 | B35: =IFERROR(__xludf.DUMMYFUNCTION("""COMPUTED_VALUE"""),"RUN-BEND_2021-12-27_RFR-005") -> RUN-BEND_2021-12-27_RFR-005 | C35: =VLOOKUP(B35,'Run Reconcile'!A$2:B809,2,FALSE) -> 44557 | D35: =IFERROR(__xludf.DUMMYFUNCTION("""COMPUTED_VALUE"""),44557.0) -> 44557 | E35: =IFERROR(__xludf.DUMMYFUNCTION("""COMPUTED_VALUE"""),0.3275462962956226) -> 0.3275463 | F35: =IFERROR(__xludf.DUMMYFUNCTION("""COMPUTED_VALUE"""),"Negative") -> Negative | G35: =IFERROR(__xludf.DUMMYFUNCTION("""COMPUTED_VALUE"""),1.0) -> 1
A36: =IFERROR(__xludf.DUMMYFUNCTION("""COMPUTED_VALUE"""),"MA307") -> MA307 | B36: =IFERROR(__xludf.DUMMYFUNCTION("""COMPUTED_VALUE"""),"RUN-BEND_2021-12-27_RFR-005") -> RUN-BEND_2021-12-27_RFR-005 | C36: =VLOOKUP(B36,'Run Reconcile'!A$2:B809,2,FALSE) -> 44557 | D36: =IFERROR(__xludf.DUMMYFUNCTION("""COMPUTED_VALUE"""),44557.0) -> 44557 | E36: =IFERROR(__xludf.DUMMYFUNCTION("""COMPUTED_VALUE"""),0.32893518518540077) -> 0.32893519 | F36: =IFERROR(__xludf.DUMMYFUNCTION("""COMPUTED_VALUE"""),"Negative") -> Negative | G36: =IFERROR(__xludf.DUMMYFUNCTION("""COMPUTED_VALUE"""),1.0) -> 1
A37: =IFERROR(__xludf.DUMMYFUNCTION("""COMPUTED_VALUE"""),"MA609") -> MA609 | B37: =IFERROR(__xludf.DUMMYFUNCTION("""COMPUTED_VALUE"""),"RUN-BEND_2021-12-27_RFR-005") -> RUN-BEND_2021-12-27_RFR-005 | C37: =VLOOKUP(B37,'Run Reconcile'!A$2:B809,2,FALSE) -> 44557 | D37: =IFERROR(__xludf.DUMMYFUNCTION("""COMPUTED_VALUE"""),44557.0) -> 44557 | E37: =IFERROR(__xludf.DUMMYFUNCTION("""COMPUTED_VALUE"""),0.33370370370539604) -> 0.3337037 | F37: =IFERROR(__xludf.DUMMYFUNCTION("""COMPUTED_VALUE"""),"Negative") -> Negative | G37: =IFERROR(__xludf.DUMMYFUNCTION("""COMPUTED_VALUE"""),1.0) -> 1
A38: =IFERROR(__xludf.DUMMYFUNCTION("""COMPUTED_VALUE"""),"MA603") -> MA603 | B38: =IFERROR(__xludf.DUMMYFUNCTION("""COMPUTED_VALUE"""),"RUN-BEND_2021-12-27_RFR-005") -> RUN-BEND_2021-12-27_RFR-005 | C38: =VLOOKUP(B38,'Run Reconcile'!A$2:B809,2,FALSE) -> 44557 | D38: =IFERROR(__xludf.DUMMYFUNCTION("""COMPUTED_VALUE"""),44557.0) -> 44557 | E38: =IFERROR(__xludf.DUMMYFUNCTION("""COMPUTED_VALUE"""),0.3368865740740148) -> 0.33688657 | F38: =IFERROR(__xludf.DUMMYFUNCTION("""COMPUTED_VALUE"""),"Negative") -> Negative | G38: =IFERROR(__xludf.DUMMYFUNCTION("""COMPUTED_VALUE"""),1.0) -> 1
A39: =IFERROR(__xludf.DUMMYFUNCTION("""COMPUTED_VALUE"""),"MAX55") -> MAX55 | B39: =IFERROR(__xludf.DUMMYFUNCTION("""COMPUTED_VALUE"""),"RUN-BEND_2021-12-27_RFR-005") -> RUN-BEND_2021-12-27_RFR-005 | C39: =VLOOKUP(B39,'Run Reconcile'!A$2:B809,2,FALSE) -> 44557 | D39: =IFERROR(__xludf.DUMMYFUNCTION("""COMPUTED_VALUE"""),44557.0) -> 44557 | E39: =IFERROR(__xludf.DUMMYFUNCTION("""COMPUTED_VALUE"""),0.34068287037007394) -> 0.34068287 | F39: =IFERROR(__xludf.DUMMYFUNCTION("""COMPUTED_VALUE"""),"Negative") -> Negative | G39: =IFERROR(__xludf.DUMMYFUNCTION("""COMPUTED_VALUE"""),1.0) -> 1
A40: =IFERROR(__xludf.DUMMYFUNCTION("""COMPUTED_VALUE"""),"MA343") -> MA343 | B40: =IFERROR(__xludf.DUMMYFUNCTION("""COMPUTED_VALUE"""),"RUN-BEND_2021-12-27_RFR-005") -> RUN-BEND_2021-12-27_RFR-005 | C40: =VLOOKUP(B40,'Run Reconcile'!A$2:B809,2,FALSE) -> 44557 | D40: =IFERROR(__xludf.DUMMYFUNCTION("""COMPUTED_VALUE"""),44557.0) -> 44557 | E40: =IFERROR(__xludf.DUMMYFUNCTION("""COMPUTED_VALUE"""),0.3411805555551837) -> 0.34118056 | F40: =IFERROR(__xludf.DUMMYFUNCTION("""COMPUTED_VALUE"""),"Negative") -> Negative | G40: =IFERROR(__xludf.DUMMYFUNCTION("""COMPUTED_VALUE"""),1.0) -> 1
...

Sheet Weekly
A1: Week Start Date | B1: Week End Date | C1: =CONCATENATE("Weekly Participants ",SUM(C2:C99)) -> Weekly Participants 767 | D1: =CONCATENATE("Weekly Tubes Run ",SUM(D2:D99)) -> Weekly Tubes Run 772 | E1: =CONCATENATE("Weekly Positive Tubes ",SUM(E2:E99)) -> Weekly Positive Tubes 71 | F1: =CONCATENATE("Weekly Inconclusive Tubes ",SUM(F2:F99)) -> Weekly Inconclusive Tubes 2 | G1: % Positive
A2: =MIN('ALL Tube Results'!C:C) - WEEKDAY(MIN('ALL Tube Results'!C:C), 3) -> 44536 | B2: =A2+6 -> 44542 | C2: =SUMIFS('ALL Tube Results'!$G$2:$G99, 'ALL Tube Results'!$C$2:$C99, ">="&A2, 'ALL Tube Results'!$C$2:$C99, "<="&B2) -> 5 | D2: =COUNTIFS('ALL Tube Results'!$C2:$C99, ">="&A2, 'ALL Tube Results'!$C2:$C99, "<="&B2) -> 5 | E2: =COUNTIFS('ALL Tube Results'!$C2:$C99, ">="&A2, 'ALL Tube Results'!$C2:$C99, "<="&B2, 'ALL Tube Results'!$F2:$F99, "Positive") -> 0 | F2: =COUNTIFS('ALL Tube Results'!$C2:$C99, ">="&A2, 'ALL Tube Results'!$C2:$C99, "<="&B2, 'ALL Tube Results'!$F2:$F99, "Inconclusive") -> 0 | G2: =IFERROR(E2/D2,IFERROR(0/0,"")) -> 0 | I2: =TEXT(A2,"ddd") -> Mon
A3: =B2+1 -> 44543 | B3: =A3+6 -> 44549 | C3: =SUMIFS('ALL Tube Results'!$G$2:$G99, 'ALL Tube Results'!$C$2:$C99, ">="&A3, 'ALL Tube Results'!$C$2:$C99, "<="&B3) -> 13 | D3: =COUNTIFS('ALL Tube Results'!$C3:$C99, ">="&A3, 'ALL Tube Results'!$C3:$C99, "<="&B3) -> 13 | E3: =COUNTIFS('ALL Tube Results'!$C3:$C99, ">="&A3, 'ALL Tube Results'!$C3:$C99, "<="&B3, 'ALL Tube Results'!$F3:$F99, "Positive") -> 1 | F3: =COUNTIFS('ALL Tube Results'!$C3:$C99, ">="&A3, 'ALL Tube Results'!$C3:$C99, "<="&B3, 'ALL Tube Results'!$F3:$F99, "Inconclusive") -> 0 | G3: =IFERROR(E3/D3,IFERROR(0/0,"")) -> 0.076923077
A4: =A3+7 -> 44550 | B4: =A4+6 -> 44556 | C4: =SUMIFS('ALL Tube Results'!$G$2:$G99, 'ALL Tube Results'!$C$2:$C99, ">="&A4, 'ALL Tube Results'!$C$2:$C99, "<="&B4) -> 12 | D4: =COUNTIFS('ALL Tube Results'!$C4:$C99, ">="&A4, 'ALL Tube Results'!$C4:$C99, "<="&B4) -> 12 | E4: =COUNTIFS('ALL Tube Results'!$C4:$C99, ">="&A4, 'ALL Tube Results'!$C4:$C99, "<="&B4, 'ALL Tube Results'!$F4:$F99, "Positive") -> 0 | F4: =COUNTIFS('ALL Tube Results'!$C4:$C99, ">="&A4, 'ALL Tube Results'!$C4:$C99, "<="&B4, 'ALL Tube Results'!$F4:$F99, "Inconclusive") -> 0 | G4: =IFERROR(E4/D4,IFERROR(0/0,"")) -> 0
A5: =A4+7 -> 44557 | B5: =A5+6 -> 44563 | C5: =SUMIFS('ALL Tube Results'!$G$2:$G99, 'ALL Tube Results'!$C$2:$C99, ">="&A5, 'ALL Tube Results'!$C$2:$C99, "<="&B5) -> 27 | D5: =COUNTIFS('ALL Tube Results'!$C5:$C99, ">="&A5, 'ALL Tube Results'!$C5:$C99, "<="&B5) -> 27 | E5: =COUNTIFS('ALL Tube Results'!$C5:$C99, ">="&A5, 'ALL Tube Results'!$C5:$C99, "<="&B5, 'ALL Tube Results'!$F5:$F99, "Positive") -> 2 | F5: =COUNTIFS('ALL Tube Results'!$C5:$C99, ">="&A5, 'ALL Tube Results'!$C5:$C99, "<="&B5, 'ALL Tube Results'!$F5:$F99, "Inconclusive") -> 0 | G5: =IFERROR(E5/D5,IFERROR(0/0,"")) -> 0.074074074
A6: =A5+7 -> 44564 | B6: =A6+6 -> 44570 | C6: =SUMIFS('ALL Tube Results'!$G$2:$G99, 'ALL Tube Results'!$C$2:$C99, ">="&A6, 'ALL Tube Results'!$C$2:$C99, "<="&B6) -> 54 | D6: =COUNTIFS('ALL Tube Results'!$C6:$C99, ">="&A6, 'ALL Tube Results'!$C6:$C99, "<="&B6) -> 56 | E6: =COUNTIFS('ALL Tube Results'!$C6:$C99, ">="&A6, 'ALL Tube Results'!$C6:$C99, "<="&B6, 'ALL Tube Results'!$F6:$F99, "Positive") -> 10 | F6: =COUNTIFS('ALL Tube Results'!$C6:$C99, ">="&A6, 'ALL Tube Results'!$C6:$C99, "<="&B6, 'ALL Tube Results'!$F6:$F99, "Inconclusive") -> 1 | G6: =IFERROR(E6/D6,IFERROR(0/0,"")) -> 0.17857143
A7: =A6+7 -> 44571 | B7: =A7+6 -> 44577 | C7: =SUMIFS('ALL Tube Results'!$G$2:$G99, 'ALL Tube Results'!$C$2:$C99, ">="&A7, 'ALL Tube Results'!$C$2:$C99, "<="&B7) -> 75 | D7: =COUNTIFS('ALL Tube Results'!$C7:$C99, ">="&A7, 'ALL Tube Results'!$C7:$C99, "<="&B7) -> 75 | E7: =COUNTIFS('ALL Tube Results'!$C7:$C99, ">="&A7, 'ALL Tube Results'!$C7:$C99, "<="&B7, 'ALL Tube Results'!$F7:$F99, "Positive") -> 18 | F7: =COUNTIFS('ALL Tube Results'!$C7:$C99, ">="&A7, 'ALL Tube Results'!$C7:$C99, "<="&B7, 'ALL Tube Results'!$F7:$F99, "Inconclusive") -> 0 | G7: =IFERROR(E7/D7,IFERROR(0/0,"")) -> 0.24
A8: =A7+7 -> 44578 | B8: =A8+6 -> 44584 | C8: =SUMIFS('ALL Tube Results'!$G$2:$G99, 'ALL Tube Results'!$C$2:$C99, ">="&A8, 'ALL Tube Results'!$C$2:$C99, "<="&B8) -> 63 | D8: =COUNTIFS('ALL Tube Results'!$C8:$C99, ">="&A8, 'ALL Tube Results'!$C8:$C99, "<="&B8) -> 63 | E8: =COUNTIFS('ALL Tube Results'!$C8:$C99, ">="&A8, 'ALL Tube Results'!$C8:$C99, "<="&B8, 'ALL Tube Results'!$F8:$F99, "Positive") -> 23 | F8: =COUNTIFS('ALL Tube Results'!$C8:$C99, ">="&A8, 'ALL Tube Results'!$C8:$C99, "<="&B8, 'ALL Tube Results'!$F8:$F99, "Inconclusive") -> 0 | G8: =IFERROR(E8/D8,IFERROR(0/0,"")) -> 0.36507937
A9: =A8+7 -> 44585 | B9: =A9+6 -> 44591 | C9: =SUMIFS('ALL Tube Results'!$G$2:$G99, 'ALL Tube Results'!$C$2:$C99, ">="&A9, 'ALL Tube Results'!$C$2:$C99, "<="&B9) -> 36 | D9: =COUNTIFS('ALL Tube Results'!$C9:$C99, ">="&A9, 'ALL Tube Results'!$C9:$C99, "<="&B9) -> 36 | E9: =COUNTIFS('ALL Tube Results'!$C9:$C99, ">="&A9, 'ALL Tube Results'!$C9:$C99, "<="&B9, 'ALL Tube Results'!$F9:$F99, "Positive") -> 4 | F9: =COUNTIFS('ALL Tube Results'!$C9:$C99, ">="&A9, 'ALL Tube Results'!$C9:$C99, "<="&B9, 'ALL Tube Results'!$F9:$F99, "Inconclusive") -> 0 | G9: =IFERROR(E9/D9,IFERROR(0/0,"")) -> 0.11111111
A10: =A9+7 -> 44592 | B10: =A10+6 -> 44598 | C10: =SUMIFS('ALL Tube Results'!$G$2:$G99, 'ALL Tube Results'!$C$2:$C99, ">="&A10, 'ALL Tube Results'!$C$2:$C99, "<="&B10) -> 24 | D10: =COUNTIFS('ALL Tube Results'!$C10:$C99, ">="&A10, 'ALL Tube Results'!$C10:$C99, "<="&B10) -> 24 | E10: =COUNTIFS('ALL Tube Results'!$C10:$C99, ">="&A10, 'ALL Tube Results'!$C10:$C99, "<="&B10, 'ALL Tube Results'!$F10:$F99, "Positive") -> 1 | F10: =COUNTIFS('ALL Tube Results'!$C10:$C99, ">="&A10, 'ALL Tube Results'!$C10:$C99, "<="&B10, 'ALL Tube Results'!$F10:$F99, "Inconclusive") -> 0 | G10: =IFERROR(E10/D10,IFERROR(0/0,"")) -> 0.041666667
A11: =A10+7 -> 44599 | B11: =A11+6 -> 44605 | C11: =SUMIFS('ALL Tube Results'!$G$2:$G99, 'ALL Tube Results'!$C$2:$C99, ">="&A11, 'ALL Tube Results'!$C$2:$C99, "<="&B11) -> 38 | D11: =COUNTIFS('ALL Tube Results'!$C11:$C99, ">="&A11, 'ALL Tube Results'!$C11:$C99, "<="&B11) -> 38 | E11: =COUNTIFS('ALL Tube Results'!$C11:$C99, ">="&A11, 'ALL Tube Results'!$C11:$C99, "<="&B11, 'ALL Tube Results'!$F11:$F99, "Positive") -> 6 | F11: =COUNTIFS('ALL Tube Results'!$C11:$C99, ">="&A11, 'ALL Tube Results'!$C11:$C99, "<="&B11, 'ALL Tube Results'!$F11:$F99, "Inconclusive") -> 0 | G11: =IFERROR(E11/D11,IFERROR(0/0,"")) -> 0.15789474
A12: =A11+7 -> 44606 | B12: =A12+6 -> 44612 | C12: =SUMIFS('ALL Tube Results'!$G$2:$G99, 'ALL Tube Results'!$C$2:$C99, ">="&A12, 'ALL Tube Results'!$C$2:$C99, "<="&B12) -> 97 | D12: =COUNTIFS('ALL Tube Results'!$C12:$C99, ">="&A12, 'ALL Tube Results'!$C12:$C99, "<="&B12) -> 97 | E12: =COUNTIFS('ALL Tube Results'!$C12:$C99, ">="&A12, 'ALL Tube Results'!$C12:$C99, "<="&B12, 'ALL Tube Results'!$F12:$F99, "Positive") -> 0 | F12: =COUNTIFS('ALL Tube Results'!$C12:$C99, ">="&A12, 'ALL Tube Results'!$C12:$C99, "<="&B12, 'ALL Tube Results'!$F12:$F99, "Inconclusive") -> 1 | G12: =IFERROR(E12/D12,IFERROR(0/0,"")) -> 0
A13: =A12+7 -> 44613 | B13: =A13+6 -> 44619 | C13: =SUMIFS('ALL Tube Results'!$G$2:$G99, 'ALL Tube Results'!$C$2:$C99, ">="&A13, 'ALL Tube Results'!$C$2:$C99, "<="&B13) -> 128 | D13: =COUNTIFS('ALL Tube Results'!$C13:$C99, ">="&A13, 'ALL Tube Results'!$C13:$C99, "<="&B13) -> 129 | E13: =COUNTIFS('ALL Tube Results'!$C13:$C99, ">="&A13, 'ALL Tube Results'!$C13:$C99, "<="&B13, 'ALL Tube Results'!$F13:$F99, "Positive") -> 3 | F13: =COUNTIFS('ALL Tube Results'!$C13:$C99, ">="&A13, 'ALL Tube Results'!$C13:$C99, "<="&B13, 'ALL Tube Results'!$F13:$F99, "Inconclusive") -> 0 | G13: =IFERROR(E13/D13,IFERROR(0/0,"")) -> 0.023255814
A14: =A13+7 -> 44620 | B14: =A14+6 -> 44626 | C14: =SUMIFS('ALL Tube Results'!$G$2:$G99, 'ALL Tube Results'!$C$2:$C99, ">="&A14, 'ALL Tube Results'!$C$2:$C99, "<="&B14) -> 99 | D14: =COUNTIFS('ALL Tube Results'!$C14:$C99, ">="&A14, 'ALL Tube Results'!$C14:$C99, "<="&B14) -> 101 | E14: =COUNTIFS('ALL Tube Results'!$C14:$C99, ">="&A14, 'ALL Tube Results'!$C14:$C99, "<="&B14, 'ALL Tube Results'!$F14:$F99, "Positive") -> 3 | F14: =COUNTIFS('ALL Tube Results'!$C14:$C99, ">="&A14, 'ALL Tube Results'!$C14:$C99, "<="&B14, 'ALL Tube Results'!$F14:$F99, "Inconclusive") -> 0 | G14: =IFERROR(E14/D14,IFERROR(0/0,"")) -> 0.02970297
A15: =A14+7 -> 44627 | B15: =A15+6 -> 44633 | C15: =SUMIFS('ALL Tube Results'!$G$2:$G99, 'ALL Tube Results'!$C$2:$C99, ">="&A15, 'ALL Tube Results'!$C$2:$C99, "<="&B15) -> 86 | D15: =COUNTIFS('ALL Tube Results'!$C15:$C99, ">="&A15, 'ALL Tube Results'!$C15:$C99, "<="&B15) -> 86 | E15: =COUNTIFS('ALL Tube Results'!$C15:$C99, ">="&A15, 'ALL Tube Results'!$C15:$C99, "<="&B15, 'ALL Tube Results'!$F15:$F99, "Positive") -> 0 | F15: =COUNTIFS('ALL Tube Results'!$C15:$C99, ">="&A15, 'ALL Tube Results'!$C15:$C99, "<="&B15, 'ALL Tube Results'!$F15:$F99, "Inconclusive") -> 0 | G15: =IFERROR(E15/D15,IFERROR(0/0,"")) -> 0
A16: =A15+7 -> 44634 | B16: =A16+6 -> 44640 | C16: =SUMIFS('ALL Tube Results'!$G$2:$G99, 'ALL Tube Results'!$C$2:$C99, ">="&A16, 'ALL Tube Results'!$C$2:$C99, "<="&B16) -> 0 | D16: =COUNTIFS('ALL Tube Results'!$C16:$C99, ">="&A16, 'ALL Tube Results'!$C16:$C99, "<="&B16) -> 0 | E16: =COUNTIFS('ALL Tube Results'!$C16:$C99, ">="&A16, 'ALL Tube Results'!$C16:$C99, "<="&B16, 'ALL Tube Results'!$F16:$F99, "Positive") -> 0 | F16: =COUNTIFS('ALL Tube Results'!$C16:$C99, ">="&A16, 'ALL Tube Results'!$C16:$C99, "<="&B16, 'ALL Tube Results'!$F16:$F99, "Inconclusive") -> 0 | G16: =IFERROR(E16/D16,IFERROR(0/0,""))
A17: =A16+7 -> 44641 | B17: =A17+6 -> 44647 | C17: =SUMIFS('ALL Tube Results'!$G$2:$G99, 'ALL Tube Results'!$C$2:$C99, ">="&A17, 'ALL Tube Results'!$C$2:$C99, "<="&B17) -> 0 | D17: =COUNTIFS('ALL Tube Results'!$C17:$C99, ">="&A17, 'ALL Tube Results'!$C17:$C99, "<="&B17) -> 0 | E17: =COUNTIFS('ALL Tube Results'!$C17:$C99, ">="&A17, 'ALL Tube Results'!$C17:$C99, "<="&B17, 'ALL Tube Results'!$F17:$F99, "Positive") -> 0 | F17: =COUNTIFS('ALL Tube Results'!$C17:$C99, ">="&A17, 'ALL Tube Results'!$C17:$C99, "<="&B17, 'ALL Tube Results'!$F17:$F99, "Inconclusive") -> 0 | G17: =IFERROR(E17/D17,IFERROR(0/0,""))
A18: =A17+7 -> 44648 | B18: =A18+6 -> 44654 | C18: =SUMIFS('ALL Tube Results'!$G$2:$G99, 'ALL Tube Results'!$C$2:$C99, ">="&A18, 'ALL Tube Results'!$C$2:$C99, "<="&B18) -> 0 | D18: =COUNTIFS('ALL Tube Results'!$C18:$C99, ">="&A18, 'ALL Tube Results'!$C18:$C99, "<="&B18) -> 0 | E18: =COUNTIFS('ALL Tube Results'!$C18:$C99, ">="&A18, 'ALL Tube Results'!$C18:$C99, "<="&B18, 'ALL Tube Results'!$F18:$F99, "Positive") -> 0 | F18: =COUNTIFS('ALL Tube Results'!$C18:$C99, ">="&A18, 'ALL Tube Results'!$C18:$C99, "<="&B18, 'ALL Tube Results'!$F18:$F99, "Inconclusive") -> 0 | G18: =IFERROR(E18/D18,IFERROR(0/0,""))
A19: =A18+7 -> 44655 | B19: =A19+6 -> 44661 | C19: =SUMIFS('ALL Tube Results'!$G$2:$G99, 'ALL Tube Results'!$C$2:$C99, ">="&A19, 'ALL Tube Results'!$C$2:$C99, "<="&B19) -> 0 | D19: =COUNTIFS('ALL Tube Results'!$C19:$C99, ">="&A19, 'ALL Tube Results'!$C19:$C99, "<="&B19) -> 0 | E19: =COUNTIFS('ALL Tube Results'!$C19:$C99, ">="&A19, 'ALL Tube Results'!$C19:$C99, "<="&B19, 'ALL Tube Results'!$F19:$F99, "Positive") -> 0 | F19: =COUNTIFS('ALL Tube Results'!$C19:$C99, ">="&A19, 'ALL Tube Results'!$C19:$C99, "<="&B19, 'ALL Tube Results'!$F19:$F99, "Inconclusive") -> 0 | G19: =IFERROR(E19/D19,IFERROR(0/0,""))
A20: =A19+7 -> 44662 | B20: =A20+6 -> 44668 | C20: =SUMIFS('ALL Tube Results'!$G$2:$G99, 'ALL Tube Results'!$C$2:$C99, ">="&A20, 'ALL Tube Results'!$C$2:$C99, "<="&B20) -> 1 | D20: =COUNTIFS('ALL Tube Results'!$C20:$C99, ">="&A20, 'ALL Tube Results'!$C20:$C99, "<="&B20) -> 1 | E20: =COUNTIFS('ALL Tube Results'!$C20:$C99, ">="&A20, 'ALL Tube Results'!$C20:$C99, "<="&B20, 'ALL Tube Results'!$F20:$F99, "Positive") -> 0 | F20: =COUNTIFS('ALL Tube Results'!$C20:$C99, ">="&A20, 'ALL Tube Results'!$C20:$C99, "<="&B20, 'ALL Tube Results'!$F20:$F99, "Inconclusive") -> 0 | G20: =IFERROR(E20/D20,IFERROR(0/0,"")) -> 0
A21: =A20+7 -> 44669 | B21: =A21+6 -> 44675 | C21: =SUMIFS('ALL Tube Results'!$G$2:$G99, 'ALL Tube Results'!$C$2:$C99, ">="&A21, 'ALL Tube Results'!$C$2:$C99, "<="&B21) -> 0 | D21: =COUNTIFS('ALL Tube Results'!$C21:$C99, ">="&A21, 'ALL Tube Results'!$C21:$C99, "<="&B21) -> 0 | E21: =COUNTIFS('ALL Tube Results'!$C21:$C99, ">="&A21, 'ALL Tube Results'!$C21:$C99, "<="&B21, 'ALL Tube Results'!$F21:$F99, "Positive") -> 0 | F21: =COUNTIFS('ALL Tube Results'!$C21:$C99, ">="&A21, 'ALL Tube Results'!$C21:$C99, "<="&B21, 'ALL Tube Results'!$F21:$F99, "Inconclusive") -> 0 | G21: =IFERROR(E21/D21,IFERROR(0/0,""))
A22: =A21+7 -> 44676 | B22: =A22+6 -> 44682 | C22: =SUMIFS('ALL Tube Results'!$G$2:$G99, 'ALL Tube Results'!$C$2:$C99, ">="&A22, 'ALL Tube Results'!$C$2:$C99, "<="&B22) -> 0 | D22: =COUNTIFS('ALL Tube Results'!$C22:$C99, ">="&A22, 'ALL Tube Results'!$C22:$C99, "<="&B22) -> 0 | E22: =COUNTIFS('ALL Tube Results'!$C22:$C99, ">="&A22, 'ALL Tube Results'!$C22:$C99, "<="&B22, 'ALL Tube Results'!$F22:$F99, "Positive") -> 0 | F22: =COUNTIFS('ALL Tube Results'!$C22:$C99, ">="&A22, 'ALL Tube Results'!$C22:$C99, "<="&B22, 'ALL Tube Results'!$F22:$F99, "Inconclusive") -> 0 | G22: =IFERROR(E22/D22,IFERROR(0/0,""))
A23: =A22+7 -> 44683 | B23: =A23+6 -> 44689 | C23: =SUMIFS('ALL Tube Results'!$G$2:$G99, 'ALL Tube Results'!$C$2:$C99, ">="&A23, 'ALL Tube Results'!$C$2:$C99, "<="&B23) -> 0 | D23: =COUNTIFS('ALL Tube Results'!$C23:$C99, ">="&A23, 'ALL Tube Results'!$C23:$C99, "<="&B23) -> 0 | E23: =COUNTIFS('ALL Tube Results'!$C23:$C99, ">="&A23, 'ALL Tube Results'!$C23:$C99, "<="&B23, 'ALL Tube Results'!$F23:$F99, "Positive") -> 0 | F23: =COUNTIFS('ALL Tube Results'!$C23:$C99, ">="&A23, 'ALL Tube Results'!$C23:$C99, "<="&B23, 'ALL Tube Results'!$F23:$F99, "Inconclusive") -> 0 | G23: =IFERROR(E23/D23,IFERROR(0/0,""))
A24: =A23+7 -> 44690 | B24: =A24+6 -> 44696 | C24: =SUMIFS('ALL Tube Results'!$G$2:$G99, 'ALL Tube Results'!$C$2:$C99, ">="&A24, 'ALL Tube Results'!$C$2:$C99, "<="&B24) -> 9 | D24: =COUNTIFS('ALL Tube Results'!$C24:$C99, ">="&A24, 'ALL Tube Results'!$C24:$C99, "<="&B24) -> 9 | E24: =COUNTIFS('ALL Tube Results'!$C24:$C99, ">="&A24, 'ALL Tube Results'!$C24:$C99, "<="&B24, 'ALL Tube Results'!$F24:$F99, "Positive") -> 0 | F24: =COUNTIFS('ALL Tube Results'!$C24:$C99, ">="&A24, 'ALL Tube Results'!$C24:$C99, "<="&B24, 'ALL Tube Results'!$F24:$F99, "Inconclusive") -> 0 | G24: =IFERROR(E24/D24,IFERROR(0/0,"")) -> 0

Sheet Runs Compare
A1: ALL Tube RESULTS by Run ID | B1: =COUNT(B3:B259) -> 44 | C1: =SUM(C2:C259) -> 772 | D1: =SUM(D2:D259) -> 699 | E1: =SUM(E2:E259) -> 71 | F1: =SUM(F2:F259) -> 2 | H1: =SUM(H2:H259) -> 0 | L1: =SUM(L2:L259) -> 7 | M1: =SUM(M2:M259) -> 1 | N1: =SUM(N2:N259) -> -3 | P1: =SUM(P2:P259) -> 5 | R1: Run Reconciled RESULTS | S1: =CONCATENATE("Delta Run Reconciled to ALL Tubes ",T1-C1) -> Delta Run Reconciled to ALL Tubes 0 | T1: =SUM(T2:T259) -> 772 | U1: =COUNTIF(U3:U259,FALSE) -> 0 | V1: =SUM(V2:V259) -> 0 | W1: =SUM(W2:W259) -> 0 | Y1: RFR Data - PreExcl RESULTS | AA1: =SUM(AA2:AA259) -> 765 | AB1: =SUM(AB2:AB259) -> 690 | AC1: =SUM(AC2:AC259) -> 70 | AD1: =SUM(AD2:AD259) -> 5 | AG1: APS Final RESULTS by Reconciled Run ID | AI1: =SUM(AI3:AI259) -> 767 | AJ1: =SUM(AJ3:AJ259) -> 694 | AK1: =SUM(AK3:AK259) -> 71 | AL1: =SUM(AL3:AL259) -> 2 | AM1: =SUM(AM3:AM259) -> 0 | AO1: APS Final RESULTS by Collect Date | AP1: =SUM(AP2:AP259) -> 767 | AQ1: =SUM(AQ2:AQ259) -> 694 | AR1: =SUM(AR2:AR259) -> 71 | AS1: =SUM(AS2:AS259) -> 2 | AT1: =SUM(AT2:AT259) -> 0
A2: Run ID | B2: Run Date | C2: Number of Tubes | D2: Negative | E2: Positive | F2: Inconclusive | H2: Delta to Run Reconciled Results | I2: T | J2: P | K2: I | L2: Delta to RFR preExcl Audit Num Run Tubes | M2: Delta to RFR preExcl Audit Num Positives | N2: Delta to RFR preExcl Audit Num Inconclusives | P2: Delta to APS | R2: Run ID | S2: Run Date | T2: Reconciled Tube Run Count | U2: Exact Run ID Match to ALL Tube Results (Col A) | Y2: Run ID - RFR Initial Only | Z2: Run Date | AA2: ='RFR Data - preExcl'!AK1 -> RFR Audit Num Run Tubes | AB2: Calculated Negs | AC2: ='RFR Data - preExcl'!AI1 -> Audit Pos Session Calls | AD2: ='RFR Data - preExcl'!AF1 -> Audit Inc Session Calls | AE2: preExcl Match Row | AG2: Final Assigned Run ID | AH2: Run Date | AI2: Number of Tubes | AJ2: Negative | AK2: Positive | AL2: Inconclusive | AM2: Null | AO2: ='APS Tubes by Date Import'!B1 -> APS COLLECT DATE | AP2: Number of Tubes | AQ2: Negative | AR2: Positive | AS2: Inconclusive | AT2: Null
A3: {=SORT(UNIQUE('ALL Tube Results'!B2:B259))} -> RUN-BEND_2021-12-10_APS-001 | B3: =VLOOKUP(A3,'Run Reconcile'!A$2:B259,2,FALSE) -> 44540 | C3: =COUNTIF('ALL Tube Results'!B2:B259, A3) -> 5 | D3: =COUNTIFS('ALL Tube Results'!$B2:$B259, $A3, 'ALL Tube Results'!$F2:$F259, "Negative") -> 5 | E3: =COUNTIFS('ALL Tube Results'!$B2:$B259, $A3, 'ALL Tube Results'!$F2:$F259, "Positive") -> 0 | F3: =COUNTIFS('ALL Tube Results'!$B2:$B259, $A3, 'ALL Tube Results'!$F2:$F259, "Inconclusive") -> 0 | G3: =IFERROR(VLOOKUP($A3,R$3:T259,3,FALSE),IFERROR(0/0,"") ) -> 5 | H3: =IF($C3=G3,IFERROR(0/0,""),$C3-G3) | I3: =IFERROR(VLOOKUP($A3,Y$3:AA259,3,FALSE),IFERROR(0/0,"") ) | J3: =IFERROR(VLOOKUP($A3,Y$3:AD259,5,FALSE),IFERROR(0/0,"") ) | K3: =IFERROR(VLOOKUP($A3,Y$3:AD259,6,FALSE),IFERROR(0/0,"")) | L3: =IF($C3=I3,IFERROR(0/0,""),$C3-I3) -> 5 | M3: =IF($E3=J3,IFERROR(0/0,""),$E3-J3) | N3: =IF($F3=K3,IFERROR(0/0,""),$F3-K3) | O3: =IFERROR(VLOOKUP($A3,AG$3:AI259,3,FALSE),IFERROR(0/0,"") ) -> 5 | P3: =IF($C3=O3,IFERROR(0/0,""),$C3-O3) | R3: {=SORT('Run Reconcile'!A2:B259,1,TRUE)} -> RUN-BEND_2021-12-10_APS-001 | S3: 44540 | T3: =VLOOKUP(R3,'Run Reconcile'!$A$2:$L259,12,FALSE) -> 5 | U3: =IF(EXACT(A2,R2),IFERROR(0/0,""),FALSE) | Y3: =IFERROR(__xludf.DUMMYFUNCTION("SORT(FILTER('Run Reconcile'!A2:B259,'Run Reconcile'!A2:A259<>""*"",REGEXMATCH('Run Reconcile'!A2:A259,""RFR-"")),1,TRUE) "),"RUN-BEND_2021-12-13_RFR-002") -> RUN-BEND_2021-12-13_RFR-002 | Z3: =IFERROR(__xludf.DUMMYFUNCTION("""COMPUTED_VALUE"""),44543.0) -> 44543 | AA3: {=INDEX('RFR Data - preExcl'!AK$2:AK259,$AE3,1)} -> 7 | AB3: =AA3-AC3-AD3 -> 7 | AC3: {=INDEX('RFR Data - preExcl'!AI$2:AI259,$AE3,1)} -> 0 | AD3: {=INDEX('RFR Data - preExcl'!AF$2:AF259,$AE3,1)} -> 0 | AE3: =IFNA(MATCH(Y3,'RFR Data - preExcl'!A$2:A259,0),"") -> 2 | AG3: {=SORT(UNIQUE('APS Tubes Import'!V2:V259))} -> RUN-BEND_2021-12-10_APS-001 | AH3: =VLOOKUP(AG3,'Run Reconcile'!A$2:B259,2,FALSE) -> 44540 | AI3: =COUNTIF('APS Tubes Import'!$V$2:$V259, AG3) -> 5 | AJ3: =COUNTIFS('APS Tubes Import'!V$2:V259, AG3, 'APS Tubes Import'!H$2:H259, "Negative") -> 5 | AK3: =COUNTIFS('APS Tubes Import'!V$2:V259, AG3, 'APS Tubes Import'!H$2:H259, "Positive") -> 0 | AL3: =COUNTIFS('APS Tubes Import'!V$2:V259, AG3, 'APS Tubes Import'!H$2:H259, "Inconclusive") -> 0 | AM3: =COUNTIFS('APS Tubes Import'!V$2:V259, AG3, 'APS Tubes Import'!H$2:H259, "Null") -> 0 | AO3: ='APS Tubes by Date Import'!B2 -> 44540 | AP3: ='APS Tubes by Date Import'!C2 -> 5 | AQ3: ='APS Tubes by Date Import'!D2 -> 5 | AR3: ='APS Tubes by Date Import'!E2 -> 0 | AS3: ='APS Tubes by Date Import'!F2 -> 0 | AT3: ='APS Tubes by Date Import'!G2 -> 0
A4: RUN-BEND_2021-12-13_RFR-002 | B4: =VLOOKUP(A4,'Run Reconcile'!A$2:B259,2,FALSE) -> 44543 | C4: =COUNTIF('ALL Tube Results'!B3:B259, A4) -> 7 | D4: =COUNTIFS('ALL Tube Results'!$B3:$B259, $A4, 'ALL Tube Results'!$F3:$F259, "Negative") -> 7 | E4: =COUNTIFS('ALL Tube Results'!$B3:$B259, $A4, 'ALL Tube Results'!$F3:$F259, "Positive") -> 0 | F4: =COUNTIFS('ALL Tube Results'!$B3:$B259, $A4, 'ALL Tube Results'!$F3:$F259, "Inconclusive") -> 0 | G4: =IFERROR(VLOOKUP($A4,R$3:T260,3,FALSE),IFERROR(0/0,"") ) -> 7 | H4: =IF($C4=G4,IFERROR(0/0,""),$C4-G4) | I4: =IFERROR(VLOOKUP($A4,Y$3:AA260,3,FALSE),IFERROR(0/0,"") ) -> 7 | J4: =IFERROR(VLOOKUP($A4,Y$3:AD260,5,FALSE),IFERROR(0/0,"") ) -> 0 | K4: =IFERROR(VLOOKUP($A4,Y$3:AD260,6,FALSE),IFERROR(0/0,"")) -> 0 | L4: =IF($C4=I4,IFERROR(0/0,""),$C4-I4) | M4: =IF($E4=J4,IFERROR(0/0,""),$E4-J4) | N4: =IF($F4=K4,IFERROR(0/0,""),$F4-K4) | O4: =IFERROR(VLOOKUP($A4,AG$3:AI260,3,FALSE),IFERROR(0/0,"") ) -> 7 | P4: =IF($C4=O4,IFERROR(0/0,""),$C4-O4) | R4: RUN-BEND_2021-12-13_RFR-002 | S4: 44543 | T4: =VLOOKUP(R4,'Run Reconcile'!$A$2:$L259,12,FALSE) -> 7 | U4: =IF(EXACT(A3,R3),IFERROR(0/0,""),FALSE) | Y4: =IFERROR(__xludf.DUMMYFUNCTION("""COMPUTED_VALUE"""),"RUN-BEND_2021-12-20_RFR-003") -> RUN-BEND_2021-12-20_RFR-003 | Z4: =IFERROR(__xludf.DUMMYFUNCTION("""COMPUTED_VALUE"""),44550.0) -> 44550 | AA4: {=INDEX('RFR Data - preExcl'!AK$2:AK259,$AE4,1)} -> 7 | AB4: =AA4-AC4-AD4 -> 7 | AC4: {=INDEX('RFR Data - preExcl'!AI$2:AI259,$AE4,1)} -> 0 | AD4: {=INDEX('RFR Data - preExcl'!AF$2:AF259,$AE4,1)} -> 0 | AE4: =IFNA(MATCH(Y4,'RFR Data - preExcl'!A$2:A259,0),"") -> 3 | AG4: RUN-BEND_2021-12-13_RFR-002 | AH4: =VLOOKUP(AG4,'Run Reconcile'!A$2:B259,2,FALSE) -> 44543 | AI4: =COUNTIF('APS Tubes Import'!$V$2:$V259, AG4) -> 7 | AJ4: =COUNTIFS('APS Tubes Import'!V$2:V259, AG4, 'APS Tubes Import'!H$2:H259, "Negative") -> 7 | AK4: =COUNTIFS('APS Tubes Import'!V$2:V259, AG4, 'APS Tubes Import'!H$2:H259, "Positive") -> 0 | AL4: =COUNTIFS('APS Tubes Import'!V$2:V259, AG4, 'APS Tubes Import'!H$2:H259, "Inconclusive") -> 0 | AM4: =COUNTIFS('APS Tubes Import'!V$2:V259, AG4, 'APS Tubes Import'!H$2:H259, "Null") -> 0 | AO4: ='APS Tubes by Date Import'!B3 -> 44543 | AP4: ='APS Tubes by Date Import'!C3 -> 7 | AQ4: ='APS Tubes by Date Import'!D3 -> 7 | AR4: ='APS Tubes by Date Import'!E3 -> 0 | AS4: ='APS Tubes by Date Import'!F3 -> 0 | AT4: ='APS Tubes by Date Import'!G3 -> 0
A5: RUN-BEND_2021-12-15_APS-002 | B5: =VLOOKUP(A5,'Run Reconcile'!A$2:B259,2,FALSE) -> 44545 | C5: =COUNTIF('ALL Tube Results'!B4:B259, A5) -> 4 | D5: =COUNTIFS('ALL Tube Results'!$B4:$B259, $A5, 'ALL Tube Results'!$F4:$F259, "Negative") -> 4 | E5: =COUNTIFS('ALL Tube Results'!$B4:$B259, $A5, 'ALL Tube Results'!$F4:$F259, "Positive") -> 0 | F5: =COUNTIFS('ALL Tube Results'!$B4:$B259, $A5, 'ALL Tube Results'!$F4:$F259, "Inconclusive") -> 0 | G5: =IFERROR(VLOOKUP($A5,R$3:T261,3,FALSE),IFERROR(0/0,"") ) -> 4 | H5: =IF($C5=G5,IFERROR(0/0,""),$C5-G5) | I5: =IFERROR(VLOOKUP($A5,Y$3:AA261,3,FALSE),IFERROR(0/0,"") ) | J5: =IFERROR(VLOOKUP($A5,Y$3:AD261,5,FALSE),IFERROR(0/0,"") ) | K5: =IFERROR(VLOOKUP($A5,Y$3:AD261,6,FALSE),IFERROR(0/0,"")) | L5: =IF($C5=I5,IFERROR(0/0,""),$C5-I5) -> 4 | M5: =IF($E5=J5,IFERROR(0/0,""),$E5-J5) | N5: =IF($F5=K5,IFERROR(0/0,""),$F5-K5) | O5: =IFERROR(VLOOKUP($A5,AG$3:AI261,3,FALSE),IFERROR(0/0,"") ) -> 4 | P5: =IF($C5=O5,IFERROR(0/0,""),$C5-O5) | R5: RUN-BEND_2021-12-15_APS-002 | S5: 44545 | T5: =VLOOKUP(R5,'Run Reconcile'!$A$2:$L259,12,FALSE) -> 4 | U5: =IF(EXACT(A4,R4),IFERROR(0/0,""),FALSE) | Y5: =IFERROR(__xludf.DUMMYFUNCTION("""COMPUTED_VALUE"""),"RUN-BEND_2021-12-22_RFR-004") -> RUN-BEND_2021-12-22_RFR-004 | Z5: =IFERROR(__xludf.DUMMYFUNCTION("""COMPUTED_VALUE"""),44552.0) -> 44552 | AA5: {=INDEX('RFR Data - preExcl'!AK$2:AK259,$AE5,1)} -> 5 | AB5: =AA5-AC5-AD5 -> 5 | AC5: {=INDEX('RFR Data - preExcl'!AI$2:AI259,$AE5,1)} -> 0 | AD5: {=INDEX('RFR Data - preExcl'!AF$2:AF259,$AE5,1)} -> 0 | AE5: =IFNA(MATCH(Y5,'RFR Data - preExcl'!A$2:A259,0),"") -> 4 | AG5: RUN-BEND_2021-12-15_APS-002 | AH5: =VLOOKUP(AG5,'Run Reconcile'!A$2:B259,2,FALSE) -> 44545 | AI5: =COUNTIF('APS Tubes Import'!$V$2:$V259, AG5) -> 4 | AJ5: =COUNTIFS('APS Tubes Import'!V$2:V259, AG5, 'APS Tubes Import'!H$2:H259, "Negative") -> 4 | AK5: =COUNTIFS('APS Tubes Import'!V$2:V259, AG5, 'APS Tubes Import'!H$2:H259, "Positive") -> 0 | AL5: =COUNTIFS('APS Tubes Import'!V$2:V259, AG5, 'APS Tubes Import'!H$2:H259, "Inconclusive") -> 0 | AM5: =COUNTIFS('APS Tubes Import'!V$2:V259, AG5, 'APS Tubes Import'!H$2:H259, "Null") -> 0 | AO5: ='APS Tubes by Date Import'!B4 -> 44545 | AP5: ='APS Tubes by Date Import'!C4 -> 4 | AQ5: ='APS Tubes by Date Import'!D4 -> 4 | AR5: ='APS Tubes by Date Import'!E4 -> 0 | AS5: ='APS Tubes by Date Import'!F4 -> 0 | AT5: ='APS Tubes by Date Import'!G4 -> 0
A6: RUN-BEND_2021-12-17_APS-003 | B6: =VLOOKUP(A6,'Run Reconcile'!A$2:B259,2,FALSE) -> 44547 | C6: =COUNTIF('ALL Tube Results'!B5:B259, A6) -> 2 | D6: =COUNTIFS('ALL Tube Results'!$B5:$B259, $A6, 'ALL Tube Results'!$F5:$F259, "Negative") -> 1 | E6: =COUNTIFS('ALL Tube Results'!$B5:$B259, $A6, 'ALL Tube Results'!$F5:$F259, "Positive") -> 1 | F6: =COUNTIFS('ALL Tube Results'!$B5:$B259, $A6, 'ALL Tube Results'!$F5:$F259, "Inconclusive") -> 0 | G6: =IFERROR(VLOOKUP($A6,R$3:T262,3,FALSE),IFERROR(0/0,"") ) -> 2 | H6: =IF($C6=G6,IFERROR(0/0,""),$C6-G6) | I6: =IFERROR(VLOOKUP($A6,Y$3:AA262,3,FALSE),IFERROR(0/0,"") ) | J6: =IFERROR(VLOOKUP($A6,Y$3:AD262,5,FALSE),IFERROR(0/0,"") ) | K6: =IFERROR(VLOOKUP($A6,Y$3:AD262,6,FALSE),IFERROR(0/0,"")) | L6: =IF($C6=I6,IFERROR(0/0,""),$C6-I6) -> 2 | M6: =IF($E6=J6,IFERROR(0/0,""),$E6-J6) -> 1 | N6: =IF($F6=K6,IFERROR(0/0,""),$F6-K6) | O6: =IFERROR(VLOOKUP($A6,AG$3:AI262,3,FALSE),IFERROR(0/0,"") ) -> 2 | P6: =IF($C6=O6,IFERROR(0/0,""),$C6-O6) | R6: RUN-BEND_2021-12-17_APS-003 | S6: 44547 | T6: =VLOOKUP(R6,'Run Reconcile'!$A$2:$L259,12,FALSE) -> 2 | U6: =IF(EXACT(A5,R5),IFERROR(0/0,""),FALSE) | Y6: =IFERROR(__xludf.DUMMYFUNCTION("""COMPUTED_VALUE"""),"RUN-BEND_2021-12-27_RFR-005") -> RUN-BEND_2021-12-27_RFR-005 | Z6: =IFERROR(__xludf.DUMMYFUNCTION("""COMPUTED_VALUE"""),44557.0) -> 44557 | AA6: {=INDEX('RFR Data - preExcl'!AK$2:AK259,$AE6,1)} -> 15 | AB6: =AA6-AC6-AD6 -> 15 | AC6: {=INDEX('RFR Data - preExcl'!AI$2:AI259,$AE6,1)} -> 0 | AD6: {=INDEX('RFR Data - preExcl'!AF$2:AF259,$AE6,1)} -> 0 | AE6: =IFNA(MATCH(Y6,'RFR Data - preExcl'!A$2:A259,0),"") -> 5 | AG6: RUN-BEND_2021-12-17_APS-003 | AH6: =VLOOKUP(AG6,'Run Reconcile'!A$2:B259,2,FALSE) -> 44547 | AI6: =COUNTIF('APS Tubes Import'!$V$2:$V259, AG6) -> 2 | AJ6: =COUNTIFS('APS Tubes Import'!V$2:V259, AG6, 'APS Tubes Import'!H$2:H259, "Negative") -> 1 | AK6: =COUNTIFS('APS Tubes Import'!V$2:V259, AG6, 'APS Tubes Import'!H$2:H259, "Positive") -> 1 | AL6: =COUNTIFS('APS Tubes Import'!V$2:V259, AG6, 'APS Tubes Import'!H$2:H259, "Inconclusive") -> 0 | AM6: =COUNTIFS('APS Tubes Import'!V$2:V259, AG6, 'APS Tubes Import'!H$2:H259, "Null") -> 0 | AO6: ='APS Tubes by Date Import'!B5 -> 44547 | AP6: ='APS Tubes by Date Import'!C5 -> 2 | AQ6: ='APS Tubes by Date Import'!D5 -> 1 | AR6: ='APS Tubes by Date Import'!E5 -> 1 | AS6: ='APS Tubes by Date Import'!F5 -> 0 | AT6: ='APS Tubes by Date Import'!G5 -> 0
A7: RUN-BEND_2021-12-20_RFR-003 | B7: =VLOOKUP(A7,'Run Reconcile'!A$2:B259,2,FALSE) -> 44550 | C7: =COUNTIF('ALL Tube Results'!B6:B259, A7) -> 7 | D7: =COUNTIFS('ALL Tube Results'!$B6:$B259, $A7, 'ALL Tube Results'!$F6:$F259, "Negative") -> 7 | E7: =COUNTIFS('ALL Tube Results'!$B6:$B259, $A7, 'ALL Tube Results'!$F6:$F259, "Positive") -> 0 | F7: =COUNTIFS('ALL Tube Results'!$B6:$B259, $A7, 'ALL Tube Results'!$F6:$F259, "Inconclusive") -> 0 | G7: =IFERROR(VLOOKUP($A7,R$3:T263,3,FALSE),IFERROR(0/0,"") ) -> 7 | H7: =IF($C7=G7,IFERROR(0/0,""),$C7-G7) | I7: =IFERROR(VLOOKUP($A7,Y$3:AA263,3,FALSE),IFERROR(0/0,"") ) -> 7 | J7: =IFERROR(VLOOKUP($A7,Y$3:AD263,5,FALSE),IFERROR(0/0,"") ) -> 0 | K7: =IFERROR(VLOOKUP($A7,Y$3:AD263,6,FALSE),IFERROR(0/0,"")) -> 0 | L7: =IF($C7=I7,IFERROR(0/0,""),$C7-I7) | M7: =IF($E7=J7,IFERROR(0/0,""),$E7-J7) | N7: =IF($F7=K7,IFERROR(0/0,""),$F7-K7) | O7: =IFERROR(VLOOKUP($A7,AG$3:AI263,3,FALSE),IFERROR(0/0,"") ) -> 7 | P7: =IF($C7=O7,IFERROR(0/0,""),$C7-O7) | R7: RUN-BEND_2021-12-20_RFR-003 | S7: 44550 | T7: =VLOOKUP(R7,'Run Reconcile'!$A$2:$L259,12,FALSE) -> 7 | U7: =IF(EXACT(A6,R6),IFERROR(0/0,""),FALSE) | Y7: =IFERROR(__xludf.DUMMYFUNCTION("""COMPUTED_VALUE"""),"RUN-BEND_2021-12-29_RFR-006") -> RUN-BEND_2021-12-29_RFR-006 | Z7: =IFERROR(__xludf.DUMMYFUNCTION("""COMPUTED_VALUE"""),44559.0) -> 44559 | AA7: {=INDEX('RFR Data - preExcl'!AK$2:AK259,$AE7,1)} -> 5 | AB7: =AA7-AC7-AD7 -> 5 | AC7: {=INDEX('RFR Data - preExcl'!AI$2:AI259,$AE7,1)} -> 0 | AD7: {=INDEX('RFR Data - preExcl'!AF$2:AF259,$AE7,1)} -> 0 | AE7: =IFNA(MATCH(Y7,'RFR Data - preExcl'!A$2:A259,0),"") -> 6 | AG7: RUN-BEND_2021-12-20_RFR-003 | AH7: =VLOOKUP(AG7,'Run Reconcile'!A$2:B259,2,FALSE) -> 44550 | AI7: =COUNTIF('APS Tubes Import'!$V$2:$V259, AG7) -> 7 | AJ7: =COUNTIFS('APS Tubes Import'!V$2:V259, AG7, 'APS Tubes Import'!H$2:H259, "Negative") -> 7 | AK7: =COUNTIFS('APS Tubes Import'!V$2:V259, AG7, 'APS Tubes Import'!H$2:H259, "Positive") -> 0 | AL7: =COUNTIFS('APS Tubes Import'!V$2:V259, AG7, 'APS Tubes Import'!H$2:H259, "Inconclusive") -> 0 | AM7: =COUNTIFS('APS Tubes Import'!V$2:V259, AG7, 'APS Tubes Import'!H$2:H259, "Null") -> 0 | AO7: ='APS Tubes by Date Import'!B6 -> 44549 | AP7: ='APS Tubes by Date Import'!C6 -> 1 | AQ7: ='APS Tubes by Date Import'!D6 -> 1 | AR7: ='APS Tubes by Date Import'!E6 -> 0 | AS7: ='APS Tubes by Date Import'!F6 -> 0 | AT7: ='APS Tubes by Date Import'!G6 -> 0
A8: RUN-BEND_2021-12-22_RFR-004 | B8: =VLOOKUP(A8,'Run Reconcile'!A$2:B259,2,FALSE) -> 44552 | C8: =COUNTIF('ALL Tube Results'!B7:B259, A8) -> 5 | D8: =COUNTIFS('ALL Tube Results'!$B7:$B259, $A8, 'ALL Tube Results'!$F7:$F259, "Negative") -> 5 | E8: =COUNTIFS('ALL Tube Results'!$B7:$B259, $A8, 'ALL Tube Results'!$F7:$F259, "Positive") -> 0 | F8: =COUNTIFS('ALL Tube Results'!$B7:$B259, $A8, 'ALL Tube Results'!$F7:$F259, "Inconclusive") -> 0 | G8: =IFERROR(VLOOKUP($A8,R$3:T264,3,FALSE),IFERROR(0/0,"") ) -> 5 | H8: =IF($C8=G8,IFERROR(0/0,""),$C8-G8) | I8: =IFERROR(VLOOKUP($A8,Y$3:AA264,3,FALSE),IFERROR(0/0,"") ) -> 5 | J8: =IFERROR(VLOOKUP($A8,Y$3:AD264,5,FALSE),IFERROR(0/0,"") ) -> 0 | K8: =IFERROR(VLOOKUP($A8,Y$3:AD264,6,FALSE),IFERROR(0/0,"")) -> 0 | L8: =IF($C8=I8,IFERROR(0/0,""),$C8-I8) | M8: =IF($E8=J8,IFERROR(0/0,""),$E8-J8) | N8: =IF($F8=K8,IFERROR(0/0,""),$F8-K8) | O8: =IFERROR(VLOOKUP($A8,AG$3:AI264,3,FALSE),IFERROR(0/0,"") ) -> 5 | P8: =IF($C8=O8,IFERROR(0/0,""),$C8-O8) | R8: RUN-BEND_2021-12-22_RFR-004 | S8: 44552 | T8: =VLOOKUP(R8,'Run Reconcile'!$A$2:$L259,12,FALSE) -> 5 | U8: =IF(EXACT(A7,R7),IFERROR(0/0,""),FALSE) | Y8: =IFERROR(__xludf.DUMMYFUNCTION("""COMPUTED_VALUE"""),"RUN-BEND_2021-12-31_RFR-007") -> RUN-BEND_2021-12-31_RFR-007 | Z8: =IFERROR(__xludf.DUMMYFUNCTION("""COMPUTED_VALUE"""),44561.0) -> 44561 | AA8: {=INDEX('RFR Data - preExcl'!AK$2:AK259,$AE8,1)} -> 8 | AB8: =AA8-AC8-AD8 -> 6 | AC8: {=INDEX('RFR Data - preExcl'!AI$2:AI259,$AE8,1)} -> 2 | AD8: {=INDEX('RFR Data - preExcl'!AF$2:AF259,$AE8,1)} -> 0 | AE8: =IFNA(MATCH(Y8,'RFR Data - preExcl'!A$2:A259,0),"") -> 7 | AG8: RUN-BEND_2021-12-22_RFR-004 | AH8: =VLOOKUP(AG8,'Run Reconcile'!A$2:B259,2,FALSE) -> 44552 | AI8: =COUNTIF('APS Tubes Import'!$V$2:$V259, AG8) -> 5 | AJ8: =COUNTIFS('APS Tubes Import'!V$2:V259, AG8, 'APS Tubes Import'!H$2:H259, "Negative") -> 5 | AK8: =COUNTIFS('APS Tubes Import'!V$2:V259, AG8, 'APS Tubes Import'!H$2:H259, "Positive") -> 0 | AL8: =COUNTIFS('APS Tubes Import'!V$2:V259, AG8, 'APS Tubes Import'!H$2:H259, "Inconclusive") -> 0 | AM8: =COUNTIFS('APS Tubes Import'!V$2:V259, AG8, 'APS Tubes Import'!H$2:H259, "Null") -> 0 | AO8: ='APS Tubes by Date Import'!B7 -> 44550 | AP8: ='APS Tubes by Date Import'!C7 -> 6 | AQ8: ='APS Tubes by Date Import'!D7 -> 6 | AR8: ='APS Tubes by Date Import'!E7 -> 0 | AS8: ='APS Tubes by Date Import'!F7 -> 0 | AT8: ='APS Tubes by Date Import'!G7 -> 0
A9: RUN-BEND_2021-12-27_RFR-005 | B9: =VLOOKUP(A9,'Run Reconcile'!A$2:B259,2,FALSE) -> 44557 | C9: =COUNTIF('ALL Tube Results'!B8:B259, A9) -> 15 | D9: =COUNTIFS('ALL Tube Results'!$B8:$B259, $A9, 'ALL Tube Results'!$F8:$F259, "Negative") -> 15 | E9: =COUNTIFS('ALL Tube Results'!$B8:$B259, $A9, 'ALL Tube Results'!$F8:$F259, "Positive") -> 0 | F9: =COUNTIFS('ALL Tube Results'!$B8:$B259, $A9, 'ALL Tube Results'!$F8:$F259, "Inconclusive") -> 0 | G9: =IFERROR(VLOOKUP($A9,R$3:T265,3,FALSE),IFERROR(0/0,"") ) -> 15 | H9: =IF($C9=G9,IFERROR(0/0,""),$C9-G9) | I9: =IFERROR(VLOOKUP($A9,Y$3:AA265,3,FALSE),IFERROR(0/0,"") ) -> 15 | J9: =IFERROR(VLOOKUP($A9,Y$3:AD265,5,FALSE),IFERROR(0/0,"") ) -> 0 | K9: =IFERROR(VLOOKUP($A9,Y$3:AD265,6,FALSE),IFERROR(0/0,"")) -> 0 | L9: =IF($C9=I9,IFERROR(0/0,""),$C9-I9) | M9: =IF($E9=J9,IFERROR(0/0,""),$E9-J9) | N9: =IF($F9=K9,IFERROR(0/0,""),$F9-K9) | O9: =IFERROR(VLOOKUP($A9,AG$3:AI265,3,FALSE),IFERROR(0/0,"") ) -> 15 | P9: =IF($C9=O9,IFERROR(0/0,""),$C9-O9) | R9: RUN-BEND_2021-12-27_RFR-005 | S9: 44557 | T9: =VLOOKUP(R9,'Run Reconcile'!$A$2:$L259,12,FALSE) -> 15 | U9: =IF(EXACT(A8,R8),IFERROR(0/0,""),FALSE) | Y9: =IFERROR(__xludf.DUMMYFUNCTION("""COMPUTED_VALUE"""),"RUN-BEND_2022-01-03_RFR-009") -> RUN-BEND_2022-01-03_RFR-009 | Z9: =IFERROR(__xludf.DUMMYFUNCTION("""COMPUTED_VALUE"""),44564.0) -> 44564 | AA9: {=INDEX('RFR Data - preExcl'!AK$2:AK259,$AE9,1)} -> 14 | AB9: =AA9-AC9-AD9 -> 10 | AC9: {=INDEX('RFR Data - preExcl'!AI$2:AI259,$AE9,1)} -> 4 | AD9: {=INDEX('RFR Data - preExcl'!AF$2:AF259,$AE9,1)} -> 0 | AE9: =IFNA(MATCH(Y9,'RFR Data - preExcl'!A$2:A259,0),"") -> 9 | AG9: RUN-BEND_2021-12-27_RFR-005 | AH9: =VLOOKUP(AG9,'Run Reconcile'!A$2:B259,2,FALSE) -> 44557 | AI9: =COUNTIF('APS Tubes Import'!$V$2:$V259, AG9) -> 15 | AJ9: =COUNTIFS('APS Tubes Import'!V$2:V259, AG9, 'APS Tubes Import'!H$2:H259, "Negative") -> 15 | AK9: =COUNTIFS('APS Tubes Import'!V$2:V259, AG9, 'APS Tubes Import'!H$2:H259, "Positive") -> 0 | AL9: =COUNTIFS('APS Tubes Import'!V$2:V259, AG9, 'APS Tubes Import'!H$2:H259, "Inconclusive") -> 0 | AM9: =COUNTIFS('APS Tubes Import'!V$2:V259, AG9, 'APS Tubes Import'!H$2:H259, "Null") -> 0 | AO9: ='APS Tubes by Date Import'!B8 -> 44551 | AP9: ='APS Tubes by Date Import'!C8 -> 2 | AQ9: ='APS Tubes by Date Import'!D8 -> 2 | AR9: ='APS Tubes by Date Import'!E8 -> 0 | AS9: ='APS Tubes by Date Import'!F8 -> 0 | AT9: ='APS Tubes by Date Import'!G8 -> 0
