Workbook
Name nondeleteRangeTubeID: #REF!
Name deleteRangeDeleteCode: #REF!
Name nondeleteRange: #REF!

Sheet Stats
A1: BEND_RFR_deID_PUB | B1: RFR File
A2: NONE | B2: RTR File
A3: NONE | B3: RSR File | N3: 1-14 0622
B4: Overall | C4: Details | D4: Comments | M4: =COUNTIF(M5:M1020, FALSE) -> 0 | N4: VALUES
A5: =IFERROR(__xludf.DUMMYFUNCTION("IMPORTRANGE($A$1,""Runs Compare!C1"") "),772.0) -> 772 | B5: Number of Tubes Tested (initial only - no re-runs) | C5: initial run tubes only so excludes re-runs | M5: =IF(NOT(ISBLANK(N5)),A5=N5,IFERROR(0/0,"")) -> TRUE | N5: 772 | Q5: 772 | R5: Number of Tubes Tested | S5: initial run tubes only so excludes reruns
A6: =A5+A17 -> 792 | B6: Number of Tube Tests Run (includes re-runs) | C6: includes re-runs | M6: =IF(NOT(ISBLANK(N6)),A6=N6,IFERROR(0/0,"")) -> TRUE | N6: 792 | Q6: 792 | R6: Number of Tube Tests Run | S6: includes re-runs
A7: =IFERROR(__xludf.DUMMYFUNCTION("IMPORTRANGE($A$1,""Runs Compare!B1"") "),44.0) -> 44 | B7: Number of Initial Runs | M7: =IF(NOT(ISBLANK(N7)),A7=N7,IFERROR(0/0,"")) -> TRUE | N7: 44
A8: =IFERROR(__xludf.DUMMYFUNCTION("IMPORTRANGE($A$1,""Run Reconcile!AE1"") "),11.0) -> 11 | B8: Number of APS Only Tubes run | M8: =IF(NOT(ISBLANK(N8)),A8=N8,IFERROR(0/0,"")) -> TRUE | N8: 11 | Q8: 11 | R8: Number of APS Only Tubes run
A9: =IFERROR(__xludf.DUMMYFUNCTION("SUM(IMPORTRANGE($A$1,""RFR Data - preExcl!AC2:AC""))+A8 +A8"),822.0) -> 822 | B9: Number of Test Reactions (RFR plus APS only tubes run) | C9: includes technical replicates (the same tube sample in multiple reactions in the same run) | M9: =IF(NOT(ISBLANK(N9)),A9=N9,IFERROR(0/0,"")) -> TRUE | N9: 822 | Q9: 811 | R9: Number of Test Reactions | S9: includes technical replicates (the same tube sample in multiple reactions in the same run)
M10: =IF(NOT(ISBLANK(N10)),A10=N10,IFERROR(0/0,""))
A11: =COUNTA(postDEL!A2:A1020) -> 767 | B11: Number of Participant Results | C11: counts individual samples in pools and excludes re-runs | M11: =IF(NOT(ISBLANK(N11)),A11=N11,IFERROR(0/0,"")) -> TRUE | N11: 767 | Q11: 767 | R11: Number of Participant Results | S11: counts individual samples in pools and excludes re-runs
A12: =IFERROR(__xludf.DUMMYFUNCTION("COUNTA(IMPORTRANGE($A$1,""ARF Tubes!M2:M""))"),5.0) -> 5 | B12: Number of ARF Tubes | C12: tubes run and present in RFR but not in Appivo - created tube IDs that start with ARF | M12: =IF(NOT(ISBLANK(N12)),A12=N12,IFERROR(0/0,"")) -> TRUE | N12: 5 | Q12: 5 | R12: Number of ARF Tubes | S12: tubes run and present in RFR but not in Appivo - created tube IDs that start with ARF
A13: =A12+A11 -> 772 | B13: Sum of Participant Results plus ARF Tubes | C13: Will be equal to the number of tubes tested if no pooling. | M13: =IF(NOT(ISBLANK(N13)),A13=N13,IFERROR(0/0,"")) -> TRUE | N13: 772 | Q13: 772 | R13: Sum of Participant Results plus ARF Tubes | S13: Will be equal to the number of tubes tested if no pooling
A14: 1 | B14: Average Pool Level (excludes ARF) | M14: =IF(NOT(ISBLANK(N14)),A14=N14,IFERROR(0/0,"")) -> TRUE | N14: 1 | Q14: 1 | R14: Avgerage Pool Level (excludes ARF)
M15: =IF(NOT(ISBLANK(N15)),A15=N15,IFERROR(0/0,""))
B16: Re-runs | C16: section | M16: =IF(NOT(ISBLANK(N16)),A16=N16,IFERROR(0/0,"")) | R16: Re-runs
A17: =IFERROR(__xludf.DUMMYFUNCTION("SUM(IMPORTRANGE($A$1,""Run Reconcile!AB2:AB"")) "),20.0) -> 20 | B17: Number of Run Tubes (re-runs only) | C17: from RFR Audit Num Run Tubes | M17: =IF(NOT(ISBLANK(N17)),A17=N17,IFERROR(0/0,"")) -> TRUE | N17: 20 | Q17: 20 | R17: Number of Run Tubes (Re-runs only) | S17: from RFR Audit Num Run Tubes
A18: =IFERROR(__xludf.DUMMYFUNCTION("SUM(IMPORTRANGE($A$1,""Run Reconcile!AA2:AA"")) "),27.0) -> 27 | B18: Number of Reactions (re-runs only) | C18: from RFR Audit Num rxns (excl ctrls) | M18: =IF(NOT(ISBLANK(N18)),A18=N18,IFERROR(0/0,"")) -> TRUE | N18: 27 | Q18: 27 | R18: Number of Reactions (Re-runs only) | S18: from RFR Audit Num rxns (excl ctrls)
A19: =A17/A5 -> 0.025906736 | B19: Re-run % of Tubes | C19: re-run / initial | M19: =IF(NOT(ISBLANK(N19)),A19=N19,IFERROR(0/0,"")) -> TRUE | N19: 0.025906736
A20: =IFERROR(__xludf.DUMMYFUNCTION("IMPORTRANGE($A$1,""Run Reconcile!Z1"")"),10.0) -> 10 | B20: Number of Initial Runs with Re-runs | M20: =IF(NOT(ISBLANK(N20)),A20=N20,IFERROR(0/0,"")) -> TRUE | N20: 10
A21: =A20/A7 -> 0.22727273 | B21: % Initial Runs with Re-runs | M21: =IF(NOT(ISBLANK(N21)),A21=N21,IFERROR(0/0,"")) -> TRUE | N21: 0.22727273
M22: =IF(NOT(ISBLANK(N22)),A22=N22,IFERROR(0/0,""))
B23: Positives | C23: section | F23: Number of Tubes with FL Result | G23: Number of Test Person Cases | H23: Number with Ref or Corresp | I23: Agree with Ref or Corresp | J23: % Agree | K23: Disagree with Ref or Corresp | L23: % Disagree | M23: =IF(NOT(ISBLANK(N23)),A23=N23,IFERROR(0/0,"")) | R23: Positives
A24: =COUNTIF('Pos and Incl'!H$2:H1020,"Positive") -> 71 | B24: Number of Tubes with Final Result Positive | E24: Positive | F24: =A24 -> 71 | G24: =A26 -> 51 | H24: =G24-'Pos and Incl'!Z32 -> 51 | I24: =A45 -> 51 | J24: =IF(H24<>0,I24/H24,IFERROR(0/0,"")) -> 1 | K24: =H24-I24 -> 0 | L24: =IF(H24<>0,K24/H24,IFERROR(0/0,"")) -> 0 | M24: =IF(NOT(ISBLANK(N24)),A24=N24,IFERROR(0/0,"")) -> TRUE | N24: 71 | Q24: 71 | R24: Number of Tubes with Final Result Positive
A25: =A24/A$5 -> 0.091968912 | B25: % of Tubes Positives (Final Result) | M25: =IF(NOT(ISBLANK(N25)),A25=N25,IFERROR(0/0,"")) -> TRUE | N25: 0.091968912 | Q25: 0.091968912 | R25: % of Tubes Positives
A26: ='Pos and Incl'!Z81+'Pos and Incl'!Z83+'Pos and Incl'!Z88 -> 51 | B26: Number of Cases with Final Result Positive (Indiv or Pool) | C26: Subtract off Re-tests | I26: Ref/Cor Pos | J26: % Incl > Pos | K26: Ref/Cor Neg | L26: % Incl > Neg | M26: =IF(NOT(ISBLANK(N26)),A26=N26,IFERROR(0/0,"")) -> TRUE | N26: 51
A27: =COUNTIF('Pos and Incl'!Y$2:Y$75,TRUE) -> 0 | B27: Known Positive Cases | C27: Previous tested (including by FloodLAMP test) or reported positive | E27: Inconclusive | F27: =A33 -> 5 | G27: =F27 -> 5 | H27: =G27-A37 -> 3 | I27: =A46 -> 1 | J27: =IF(H27<>0,I27/H27,IFERROR(0/0,"")) -> 0.33333333 | K27: =A48 -> 1 | L27: =IF(H27<>0,K27/H27,IFERROR(0/0,"")) -> 0.33333333 | M27: =IF(NOT(ISBLANK(N27)),A27=N27,IFERROR(0/0,"")) -> TRUE | N27: 0
A28: =A26-A27 -> 51 | B28: Unknown Positive Cases | M28: =IF(NOT(ISBLANK(N28)),A28=N28,IFERROR(0/0,"")) -> TRUE | N28: 51
M29: =IF(NOT(ISBLANK(N29)),A29=N29,IFERROR(0/0,""))
B30: Inconclusives | C30: section | M30: =IF(NOT(ISBLANK(N30)),A30=N30,IFERROR(0/0,"")) | R30: Inconclusives
A31: =COUNTIF('Pos and Incl'!H$2:H1020,"Inconclusive") -> 2 | B31: Number of Tubes with Final Result Inconclusive | M31: =IF(NOT(ISBLANK(N31)),A31=N31,IFERROR(0/0,"")) -> TRUE | N31: 2 | Q31: 2 | R31: Number of Tubes with Final Result Inconclusive
A32: 3 | B32: Number of Tubes in RFR Audit Inconclusive not in Appivo Final Results | M32: =IF(NOT(ISBLANK(N32)),A32=N32,IFERROR(0/0,"")) -> TRUE | N32: 3 | Q32: 0.0025906736 | R32: % of Tubes Inconclusive
A33: =A32+A31 -> 5 | B33: Total Number of Inconclusive Tubes | M33: =IF(NOT(ISBLANK(N33)),A33=N33,IFERROR(0/0,"")) -> TRUE | N33: 5
A34: =A33/A$5 -> 0.0064766839 | B34: % of Tubes Inconclusive | M34: =IF(NOT(ISBLANK(N34)),A34=N34,IFERROR(0/0,"")) -> TRUE | N34: 0.0064766839
A35: 1 | B35: Number of Inconclusive Tubes resolved Positive by Referral Test or Correspondence | M35: =IF(NOT(ISBLANK(N35)),A35=N35,IFERROR(0/0,"")) -> TRUE | N35: 1
A36: =IF(A33<>0,A35/A33,IFERROR(0/0,"")) -> 0.2 | B36: % Inconclusives resolved Positive by Referral Tests | M36: =IF(NOT(ISBLANK(N36)),A36=N36,IFERROR(0/0,"")) -> TRUE | N36: 0.2
A37: 2 | B37: Number of Inconclusive Tubes with Referral Test or Correspondence Negative | M37: =IF(NOT(ISBLANK(N37)),A37=N37,IFERROR(0/0,"")) -> TRUE | N37: 2
A38: =A33-A35-A37 -> 2 | B38: Number of Inconclusive Tubes with no Referral Test result or Correspondence | M38: =IF(NOT(ISBLANK(N38)),A38=N38,IFERROR(0/0,"")) -> TRUE | N38: 2
A39: 7 | B39: Number of Tubes with Initial Inconclusives and Re-run Negative | C39: Count Result Correction Code=2.5 in preDel col AJ, or from RFR preExcl if not resulted as Incl in App | D39: 1/26, 1/28, 2/15, 2/25, 3/5 2, 3/7 | M39: =IF(NOT(ISBLANK(N39)),A39=N39,IFERROR(0/0,"")) -> TRUE | N39: 7
A40: =IFERROR(__xludf.DUMMYFUNCTION("SUM(IMPORTRANGE($A1,""RFR Data - preExcl!AE2:AE""))"),12.0) -> 12 | B40: Number of Inconclusive Test Run Calls | C40: includes re-runs - from RFR Audit only and excludes any APS only resulted inconclusives | M40: =IF(NOT(ISBLANK(N40)),A40=N40,IFERROR(0/0,"")) -> TRUE | N40: 12
...

Sheet REF Weekly
A1: =IFERROR(__xludf.DUMMYFUNCTION("IMPORTRANGE(Stats!$A$1,""Weekly!A1:G"")"),"Week Start Date") -> Week Start Date | B1: =IFERROR(__xludf.DUMMYFUNCTION("""COMPUTED_VALUE"""),"Week End Date") -> Week End Date | C1: =IFERROR(__xludf.DUMMYFUNCTION("""COMPUTED_VALUE"""),"Weekly Participants 767") -> Weekly Participants 767 | D1: =IFERROR(__xludf.DUMMYFUNCTION("""COMPUTED_VALUE"""),"Weekly Tubes Run 772") -> Weekly Tubes Run 772 | E1: =IFERROR(__xludf.DUMMYFUNCTION("""COMPUTED_VALUE"""),"Weekly Positive Tubes 71") -> Weekly Positive Tubes 71 | F1: =IFERROR(__xludf.DUMMYFUNCTION("""COMPUTED_VALUE"""),"Weekly Inconclusive Tubes 2") -> Weekly Inconclusive Tubes 2 | G1: =IFERROR(__xludf.DUMMYFUNCTION("""COMPUTED_VALUE"""),"% Positive") -> % Positive
A2: =IFERROR(__xludf.DUMMYFUNCTION("""COMPUTED_VALUE"""),44536.0) -> 44536 | B2: =IFERROR(__xludf.DUMMYFUNCTION("""COMPUTED_VALUE"""),44542.0) -> 44542 | C2: =IFERROR(__xludf.DUMMYFUNCTION("""COMPUTED_VALUE"""),5.0) -> 5 | D2: =IFERROR(__xludf.DUMMYFUNCTION("""COMPUTED_VALUE"""),5.0) -> 5 | E2: =IFERROR(__xludf.DUMMYFUNCTION("""COMPUTED_VALUE"""),0.0) -> 0 | F2: =IFERROR(__xludf.DUMMYFUNCTION("""COMPUTED_VALUE"""),0.0) -> 0 | G2: =IFERROR(__xludf.DUMMYFUNCTION("""COMPUTED_VALUE"""),0.0) -> 0
A3: =IFERROR(__xludf.DUMMYFUNCTION("""COMPUTED_VALUE"""),44543.0) -> 44543 | B3: =IFERROR(__xludf.DUMMYFUNCTION("""COMPUTED_VALUE"""),44549.0) -> 44549 | C3: =IFERROR(__xludf.DUMMYFUNCTION("""COMPUTED_VALUE"""),13.0) -> 13 | D3: =IFERROR(__xludf.DUMMYFUNCTION("""COMPUTED_VALUE"""),13.0) -> 13 | E3: =IFERROR(__xludf.DUMMYFUNCTION("""COMPUTED_VALUE"""),1.0) -> 1 | F3: =IFERROR(__xludf.DUMMYFUNCTION("""COMPUTED_VALUE"""),0.0) -> 0 | G3: =IFERROR(__xludf.DUMMYFUNCTION("""COMPUTED_VALUE"""),0.07692307692307693) -> 0.076923077
A4: =IFERROR(__xludf.DUMMYFUNCTION("""COMPUTED_VALUE"""),44550.0) -> 44550 | B4: =IFERROR(__xludf.DUMMYFUNCTION("""COMPUTED_VALUE"""),44556.0) -> 44556 | C4: =IFERROR(__xludf.DUMMYFUNCTION("""COMPUTED_VALUE"""),12.0) -> 12 | D4: =IFERROR(__xludf.DUMMYFUNCTION("""COMPUTED_VALUE"""),12.0) -> 12 | E4: =IFERROR(__xludf.DUMMYFUNCTION("""COMPUTED_VALUE"""),0.0) -> 0 | F4: =IFERROR(__xludf.DUMMYFUNCTION("""COMPUTED_VALUE"""),0.0) -> 0 | G4: =IFERROR(__xludf.DUMMYFUNCTION("""COMPUTED_VALUE"""),0.0) -> 0
A5: =IFERROR(__xludf.DUMMYFUNCTION("""COMPUTED_VALUE"""),44557.0) -> 44557 | B5: =IFERROR(__xludf.DUMMYFUNCTION("""COMPUTED_VALUE"""),44563.0) -> 44563 | C5: =IFERROR(__xludf.DUMMYFUNCTION("""COMPUTED_VALUE"""),27.0) -> 27 | D5: =IFERROR(__xludf.DUMMYFUNCTION("""COMPUTED_VALUE"""),27.0) -> 27 | E5: =IFERROR(__xludf.DUMMYFUNCTION("""COMPUTED_VALUE"""),2.0) -> 2 | F5: =IFERROR(__xludf.DUMMYFUNCTION("""COMPUTED_VALUE"""),0.0) -> 0 | G5: =IFERROR(__xludf.DUMMYFUNCTION("""COMPUTED_VALUE"""),0.07407407407407407) -> 0.074074074
A6: =IFERROR(__xludf.DUMMYFUNCTION("""COMPUTED_VALUE"""),44564.0) -> 44564 | B6: =IFERROR(__xludf.DUMMYFUNCTION("""COMPUTED_VALUE"""),44570.0) -> 44570 | C6: =IFERROR(__xludf.DUMMYFUNCTION("""COMPUTED_VALUE"""),54.0) -> 54 | D6: =IFERROR(__xludf.DUMMYFUNCTION("""COMPUTED_VALUE"""),56.0) -> 56 | E6: =IFERROR(__xludf.DUMMYFUNCTION("""COMPUTED_VALUE"""),10.0) -> 10 | F6: =IFERROR(__xludf.DUMMYFUNCTION("""COMPUTED_VALUE"""),1.0) -> 1 | G6: =IFERROR(__xludf.DUMMYFUNCTION("""COMPUTED_VALUE"""),0.17857142857142858) -> 0.17857143
A7: =IFERROR(__xludf.DUMMYFUNCTION("""COMPUTED_VALUE"""),44571.0) -> 44571 | B7: =IFERROR(__xludf.DUMMYFUNCTION("""COMPUTED_VALUE"""),44577.0) -> 44577 | C7: =IFERROR(__xludf.DUMMYFUNCTION("""COMPUTED_VALUE"""),75.0) -> 75 | D7: =IFERROR(__xludf.DUMMYFUNCTION("""COMPUTED_VALUE"""),75.0) -> 75 | E7: =IFERROR(__xludf.DUMMYFUNCTION("""COMPUTED_VALUE"""),18.0) -> 18 | F7: =IFERROR(__xludf.DUMMYFUNCTION("""COMPUTED_VALUE"""),0.0) -> 0 | G7: =IFERROR(__xludf.DUMMYFUNCTION("""COMPUTED_VALUE"""),0.24) -> 0.24
A8: =IFERROR(__xludf.DUMMYFUNCTION("""COMPUTED_VALUE"""),44578.0) -> 44578 | B8: =IFERROR(__xludf.DUMMYFUNCTION("""COMPUTED_VALUE"""),44584.0) -> 44584 | C8: =IFERROR(__xludf.DUMMYFUNCTION("""COMPUTED_VALUE"""),63.0) -> 63 | D8: =IFERROR(__xludf.DUMMYFUNCTION("""COMPUTED_VALUE"""),63.0) -> 63 | E8: =IFERROR(__xludf.DUMMYFUNCTION("""COMPUTED_VALUE"""),23.0) -> 23 | F8: =IFERROR(__xludf.DUMMYFUNCTION("""COMPUTED_VALUE"""),0.0) -> 0 | G8: =IFERROR(__xludf.DUMMYFUNCTION("""COMPUTED_VALUE"""),0.36507936507936506) -> 0.36507937
A9: =IFERROR(__xludf.DUMMYFUNCTION("""COMPUTED_VALUE"""),44585.0) -> 44585 | B9: =IFERROR(__xludf.DUMMYFUNCTION("""COMPUTED_VALUE"""),44591.0) -> 44591 | C9: =IFERROR(__xludf.DUMMYFUNCTION("""COMPUTED_VALUE"""),36.0) -> 36 | D9: =IFERROR(__xludf.DUMMYFUNCTION("""COMPUTED_VALUE"""),36.0) -> 36 | E9: =IFERROR(__xludf.DUMMYFUNCTION("""COMPUTED_VALUE"""),4.0) -> 4 | F9: =IFERROR(__xludf.DUMMYFUNCTION("""COMPUTED_VALUE"""),0.0) -> 0 | G9: =IFERROR(__xludf.DUMMYFUNCTION("""COMPUTED_VALUE"""),0.1111111111111111) -> 0.11111111
A10: =IFERROR(__xludf.DUMMYFUNCTION("""COMPUTED_VALUE"""),44592.0) -> 44592 | B10: =IFERROR(__xludf.DUMMYFUNCTION("""COMPUTED_VALUE"""),44598.0) -> 44598 | C10: =IFERROR(__xludf.DUMMYFUNCTION("""COMPUTED_VALUE"""),24.0) -> 24 | D10: =IFERROR(__xludf.DUMMYFUNCTION("""COMPUTED_VALUE"""),24.0) -> 24 | E10: =IFERROR(__xludf.DUMMYFUNCTION("""COMPUTED_VALUE"""),1.0) -> 1 | F10: =IFERROR(__xludf.DUMMYFUNCTION("""COMPUTED_VALUE"""),0.0) -> 0 | G10: =IFERROR(__xludf.DUMMYFUNCTION("""COMPUTED_VALUE"""),0.041666666666666664) -> 0.041666667
A11: =IFERROR(__xludf.DUMMYFUNCTION("""COMPUTED_VALUE"""),44599.0) -> 44599 | B11: =IFERROR(__xludf.DUMMYFUNCTION("""COMPUTED_VALUE"""),44605.0) -> 44605 | C11: =IFERROR(__xludf.DUMMYFUNCTION("""COMPUTED_VALUE"""),38.0) -> 38 | D11: =IFERROR(__xludf.DUMMYFUNCTION("""COMPUTED_VALUE"""),38.0) -> 38 | E11: =IFERROR(__xludf.DUMMYFUNCTION("""COMPUTED_VALUE"""),6.0) -> 6 | F11: =IFERROR(__xludf.DUMMYFUNCTION("""COMPUTED_VALUE"""),0.0) -> 0 | G11: =IFERROR(__xludf.DUMMYFUNCTION("""COMPUTED_VALUE"""),0.15789473684210525) -> 0.15789474
A12: =IFERROR(__xludf.DUMMYFUNCTION("""COMPUTED_VALUE"""),44606.0) -> 44606 | B12: =IFERROR(__xludf.DUMMYFUNCTION("""COMPUTED_VALUE"""),44612.0) -> 44612 | C12: =IFERROR(__xludf.DUMMYFUNCTION("""COMPUTED_VALUE"""),97.0) -> 97 | D12: =IFERROR(__xludf.DUMMYFUNCTION("""COMPUTED_VALUE"""),97.0) -> 97 | E12: =IFERROR(__xludf.DUMMYFUNCTION("""COMPUTED_VALUE"""),0.0) -> 0 | F12: =IFERROR(__xludf.DUMMYFUNCTION("""COMPUTED_VALUE"""),1.0) -> 1 | G12: =IFERROR(__xludf.DUMMYFUNCTION("""COMPUTED_VALUE"""),0.0) -> 0
A13: =IFERROR(__xludf.DUMMYFUNCTION("""COMPUTED_VALUE"""),44613.0) -> 44613 | B13: =IFERROR(__xludf.DUMMYFUNCTION("""COMPUTED_VALUE"""),44619.0) -> 44619 | C13: =IFERROR(__xludf.DUMMYFUNCTION("""COMPUTED_VALUE"""),128.0) -> 128 | D13: =IFERROR(__xludf.DUMMYFUNCTION("""COMPUTED_VALUE"""),129.0) -> 129 | E13: =IFERROR(__xludf.DUMMYFUNCTION("""COMPUTED_VALUE"""),3.0) -> 3 | F13: =IFERROR(__xludf.DUMMYFUNCTION("""COMPUTED_VALUE"""),0.0) -> 0 | G13: =IFERROR(__xludf.DUMMYFUNCTION("""COMPUTED_VALUE"""),0.023255813953488372) -> 0.023255814
A14: =IFERROR(__xludf.DUMMYFUNCTION("""COMPUTED_VALUE"""),44620.0) -> 44620 | B14: =IFERROR(__xludf.DUMMYFUNCTION("""COMPUTED_VALUE"""),44626.0) -> 44626 | C14: =IFERROR(__xludf.DUMMYFUNCTION("""COMPUTED_VALUE"""),99.0) -> 99 | D14: =IFERROR(__xludf.DUMMYFUNCTION("""COMPUTED_VALUE"""),101.0) -> 101 | E14: =IFERROR(__xludf.DUMMYFUNCTION("""COMPUTED_VALUE"""),3.0) -> 3 | F14: =IFERROR(__xludf.DUMMYFUNCTION("""COMPUTED_VALUE"""),0.0) -> 0 | G14: =IFERROR(__xludf.DUMMYFUNCTION("""COMPUTED_VALUE"""),0.0297029702970297) -> 0.02970297
A15: =IFERROR(__xludf.DUMMYFUNCTION("""COMPUTED_VALUE"""),44627.0) -> 44627 | B15: =IFERROR(__xludf.DUMMYFUNCTION("""COMPUTED_VALUE"""),44633.0) -> 44633 | C15: =IFERROR(__xludf.DUMMYFUNCTION("""COMPUTED_VALUE"""),86.0) -> 86 | D15: =IFERROR(__xludf.DUMMYFUNCTION("""COMPUTED_VALUE"""),86.0) -> 86 | E15: =IFERROR(__xludf.DUMMYFUNCTION("""COMPUTED_VALUE"""),0.0) -> 0 | F15: =IFERROR(__xludf.DUMMYFUNCTION("""COMPUTED_VALUE"""),0.0) -> 0 | G15: =IFERROR(__xludf.DUMMYFUNCTION("""COMPUTED_VALUE"""),0.0) -> 0
A16: =IFERROR(__xludf.DUMMYFUNCTION("""COMPUTED_VALUE"""),44634.0) -> 44634 | B16: =IFERROR(__xludf.DUMMYFUNCTION("""COMPUTED_VALUE"""),44640.0) -> 44640 | C16: =IFERROR(__xludf.DUMMYFUNCTION("""COMPUTED_VALUE"""),0.0) -> 0 | D16: =IFERROR(__xludf.DUMMYFUNCTION("""COMPUTED_VALUE"""),0.0) -> 0 | E16: =IFERROR(__xludf.DUMMYFUNCTION("""COMPUTED_VALUE"""),0.0) -> 0 | F16: =IFERROR(__xludf.DUMMYFUNCTION("""COMPUTED_VALUE"""),0.0) -> 0
A17: =IFERROR(__xludf.DUMMYFUNCTION("""COMPUTED_VALUE"""),44641.0) -> 44641 | B17: =IFERROR(__xludf.DUMMYFUNCTION("""COMPUTED_VALUE"""),44647.0) -> 44647 | C17: =IFERROR(__xludf.DUMMYFUNCTION("""COMPUTED_VALUE"""),0.0) -> 0 | D17: =IFERROR(__xludf.DUMMYFUNCTION("""COMPUTED_VALUE"""),0.0) -> 0 | E17: =IFERROR(__xludf.DUMMYFUNCTION("""COMPUTED_VALUE"""),0.0) -> 0 | F17: =IFERROR(__xludf.DUMMYFUNCTION("""COMPUTED_VALUE"""),0.0) -> 0
A18: =IFERROR(__xludf.DUMMYFUNCTION("""COMPUTED_VALUE"""),44648.0) -> 44648 | B18: =IFERROR(__xludf.DUMMYFUNCTION("""COMPUTED_VALUE"""),44654.0) -> 44654 | C18: =IFERROR(__xludf.DUMMYFUNCTION("""COMPUTED_VALUE"""),0.0) -> 0 | D18: =IFERROR(__xludf.DUMMYFUNCTION("""COMPUTED_VALUE"""),0.0) -> 0 | E18: =IFERROR(__xludf.DUMMYFUNCTION("""COMPUTED_VALUE"""),0.0) -> 0 | F18: =IFERROR(__xludf.DUMMYFUNCTION("""COMPUTED_VALUE"""),0.0) -> 0
A19: =IFERROR(__xludf.DUMMYFUNCTION("""COMPUTED_VALUE"""),44655.0) -> 44655 | B19: =IFERROR(__xludf.DUMMYFUNCTION("""COMPUTED_VALUE"""),44661.0) -> 44661 | C19: =IFERROR(__xludf.DUMMYFUNCTION("""COMPUTED_VALUE"""),0.0) -> 0 | D19: =IFERROR(__xludf.DUMMYFUNCTION("""COMPUTED_VALUE"""),0.0) -> 0 | E19: =IFERROR(__xludf.DUMMYFUNCTION("""COMPUTED_VALUE"""),0.0) -> 0 | F19: =IFERROR(__xludf.DUMMYFUNCTION("""COMPUTED_VALUE"""),0.0) -> 0
A20: =IFERROR(__xludf.DUMMYFUNCTION("""COMPUTED_VALUE"""),44662.0) -> 44662 | B20: =IFERROR(__xludf.DUMMYFUNCTION("""COMPUTED_VALUE"""),44668.0) -> 44668 | C20: =IFERROR(__xludf.DUMMYFUNCTION("""COMPUTED_VALUE"""),1.0) -> 1 | D20: =IFERROR(__xludf.DUMMYFUNCTION("""COMPUTED_VALUE"""),1.0) -> 1 | E20: =IFERROR(__xludf.DUMMYFUNCTION("""COMPUTED_VALUE"""),0.0) -> 0 | F20: =IFERROR(__xludf.DUMMYFUNCTION("""COMPUTED_VALUE"""),0.0) -> 0 | G20: =IFERROR(__xludf.DUMMYFUNCTION("""COMPUTED_VALUE"""),0.0) -> 0
A21: =IFERROR(__xludf.DUMMYFUNCTION("""COMPUTED_VALUE"""),44669.0) -> 44669 | B21: =IFERROR(__xludf.DUMMYFUNCTION("""COMPUTED_VALUE"""),44675.0) -> 44675 | C21: =IFERROR(__xludf.DUMMYFUNCTION("""COMPUTED_VALUE"""),0.0) -> 0 | D21: =IFERROR(__xludf.DUMMYFUNCTION("""COMPUTED_VALUE"""),0.0) -> 0 | E21: =IFERROR(__xludf.DUMMYFUNCTION("""COMPUTED_VALUE"""),0.0) -> 0 | F21: =IFERROR(__xludf.DUMMYFUNCTION("""COMPUTED_VALUE"""),0.0) -> 0
A22: =IFERROR(__xludf.DUMMYFUNCTION("""COMPUTED_VALUE"""),44676.0) -> 44676 | B22: =IFERROR(__xludf.DUMMYFUNCTION("""COMPUTED_VALUE"""),44682.0) -> 44682 | C22: =IFERROR(__xludf.DUMMYFUNCTION("""COMPUTED_VALUE"""),0.0) -> 0 | D22: =IFERROR(__xludf.DUMMYFUNCTION("""COMPUTED_VALUE"""),0.0) -> 0 | E22: =IFERROR(__xludf.DUMMYFUNCTION("""COMPUTED_VALUE"""),0.0) -> 0 | F22: =IFERROR(__xludf.DUMMYFUNCTION("""COMPUTED_VALUE"""),0.0) -> 0
A23: =IFERROR(__xludf.DUMMYFUNCTION("""COMPUTED_VALUE"""),44683.0) -> 44683 | B23: =IFERROR(__xludf.DUMMYFUNCTION("""COMPUTED_VALUE"""),44689.0) -> 44689 | C23: =IFERROR(__xludf.DUMMYFUNCTION("""COMPUTED_VALUE"""),0.0) -> 0 | D23: =IFERROR(__xludf.DUMMYFUNCTION("""COMPUTED_VALUE"""),0.0) -> 0 | E23: =IFERROR(__xludf.DUMMYFUNCTION("""COMPUTED_VALUE"""),0.0) -> 0 | F23: =IFERROR(__xludf.DUMMYFUNCTION("""COMPUTED_VALUE"""),0.0) -> 0
A24: =IFERROR(__xludf.DUMMYFUNCTION("""COMPUTED_VALUE"""),44690.0) -> 44690 | B24: =IFERROR(__xludf.DUMMYFUNCTION("""COMPUTED_VALUE"""),44696.0) -> 44696 | C24: =IFERROR(__xludf.DUMMYFUNCTION("""COMPUTED_VALUE"""),9.0) -> 9 | D24: =IFERROR(__xludf.DUMMYFUNCTION("""COMPUTED_VALUE"""),9.0) -> 9 | E24: =IFERROR(__xludf.DUMMYFUNCTION("""COMPUTED_VALUE"""),0.0) -> 0 | F24: =IFERROR(__xludf.DUMMYFUNCTION("""COMPUTED_VALUE"""),0.0) -> 0 | G24: =IFERROR(__xludf.DUMMYFUNCTION("""COMPUTED_VALUE"""),0.0) -> 0

Sheet Pos and Incl
A1: {='APS Tubes'!A1:O1} -> TUBE ID | B1: COLLECTION DATE | C1: COLLECTION TIME | D1: SPONSOR PERSON ID | E1: SPONSOR FIRSTNAME | F1: SPONSOR LASTNAME | G1: APP RESULT | H1: FINAL RESULT | I1: RESULT DATE | J1: RESULT TIME | K1: Result Correct Code | L1: Correction Notes | M1: NOTE | N1: NUM SAMPLES (Pool Level) | O1: Match Row in APS Data PHI - postDEL | P1: Sample Person1 | Q1: Sample Person2 | R1: Sample Person3 | S1: Sample Person4 | T1: Referral Eval Notes | U1: =CONCATENATE(COUNTIF(U2:U1340,TRUE), " ACCOUNTED FOR IN RTR?") -> 0 ACCOUNTED FOR IN RTR? | V1: Re-test? | W1: Correspondence but no Referral Test | X1: Agreement with Referral or Correspondence? | Y1: Known Positive (not Re-test)? | Z1: =CONCATENATE(SUM(Z2:Z74), " Check") -> 0 Check | AA1: FloodLAMP Result Eval
A2: =IFERROR(__xludf.DUMMYFUNCTION("{FILTER('APS Tubes'!A2:O1340,EXACT('APS Tubes'!H2:H1340,""Positive"")); FILTER('APS Tubes'!A2:O1340,EXACT('APS Tubes'!H2:H1340,""Inconclusive""))} "),"MA1043") -> MA1043 | B2: =IFERROR(__xludf.DUMMYFUNCTION("""COMPUTED_VALUE"""),44547.0) -> 44547 | C2: =IFERROR(__xludf.DUMMYFUNCTION("""COMPUTED_VALUE"""),0.3417824074074074) -> 0.34178241 | D2: =IFERROR(__xludf.DUMMYFUNCTION("""COMPUTED_VALUE"""),"SpBEND548976") -> SpBEND548976 | G2: =IFERROR(__xludf.DUMMYFUNCTION("""COMPUTED_VALUE"""),"Positive") -> Positive | H2: =IFERROR(__xludf.DUMMYFUNCTION("""COMPUTED_VALUE"""),"Positive") -> Positive | I2: =IFERROR(__xludf.DUMMYFUNCTION("""COMPUTED_VALUE"""),44547.0) -> 44547 | J2: =IFERROR(__xludf.DUMMYFUNCTION("""COMPUTED_VALUE"""),0.5028472222222222) -> 0.50284722 | N2: =IFERROR(__xludf.DUMMYFUNCTION("""COMPUTED_VALUE"""),1.0) -> 1 | O2: =IFERROR(__xludf.DUMMYFUNCTION("""COMPUTED_VALUE"""),17.0) -> 17 | P2: {=INDEX(postDEL!$A$2:$AR1340,$O2,40)} -> BEND704851 | Q2: {=IF($N2>1, INDEX(postDEL!$A$2:$AR1340,$O2+1,40),IFERROR(0/0,""))} | R2: {=IF($N2>2, INDEX(postDEL!$A$2:$AR1340,$O2+2,40),IFERROR(0/0,""))} | S2: {=IF($N2>3, INDEX(postDEL!$A$2:$AR1340,$O2+3,40),IFERROR(0/0,""))} | U2: FALSE | V2: sep cases | W2: TRUE | X2: TRUE | Y2: =IFERROR(IF(V2,TRUE,IFERROR(0/0,"")),"")
A3: =IFERROR(__xludf.DUMMYFUNCTION("""COMPUTED_VALUE"""),"MA1081") -> MA1081 | B3: =IFERROR(__xludf.DUMMYFUNCTION("""COMPUTED_VALUE"""),44561.0) -> 44561 | C3: =IFERROR(__xludf.DUMMYFUNCTION("""COMPUTED_VALUE"""),0.3053240740740741) -> 0.30532407 | D3: =IFERROR(__xludf.DUMMYFUNCTION("""COMPUTED_VALUE"""),"SpBEND734943") -> SpBEND734943 | G3: =IFERROR(__xludf.DUMMYFUNCTION("""COMPUTED_VALUE"""),"Positive") -> Positive | H3: =IFERROR(__xludf.DUMMYFUNCTION("""COMPUTED_VALUE"""),"Positive") -> Positive | I3: =IFERROR(__xludf.DUMMYFUNCTION("""COMPUTED_VALUE"""),44561.0) -> 44561 | J3: =IFERROR(__xludf.DUMMYFUNCTION("""COMPUTED_VALUE"""),0.44559027777777777) -> 0.44559028 | N3: =IFERROR(__xludf.DUMMYFUNCTION("""COMPUTED_VALUE"""),1.0) -> 1 | O3: =IFERROR(__xludf.DUMMYFUNCTION("""COMPUTED_VALUE"""),50.0) -> 50 | P3: {=INDEX(postDEL!$A$2:$AR1340,$O3,40)} -> BEND710690 | Q3: {=IF($N3>1, INDEX(postDEL!$A$2:$AR1340,$O3+1,40),IFERROR(0/0,""))} | R3: {=IF($N3>2, INDEX(postDEL!$A$2:$AR1340,$O3+2,40),IFERROR(0/0,""))} | S3: {=IF($N3>3, INDEX(postDEL!$A$2:$AR1340,$O3+3,40),IFERROR(0/0,""))} | U3: FALSE | V3: =IF(COUNTIF($P$2:$P$74,P3)=1,"-",IF(COUNTIF($P$2:P3,P3)=1,"1st",TRUE)) -> - | W3: TRUE | X3: TRUE | Y3: =IFERROR(IF(V3,TRUE,IFERROR(0/0,"")),"")
A4: =IFERROR(__xludf.DUMMYFUNCTION("""COMPUTED_VALUE"""),"MA316") -> MA316 | B4: =IFERROR(__xludf.DUMMYFUNCTION("""COMPUTED_VALUE"""),44561.0) -> 44561 | C4: =IFERROR(__xludf.DUMMYFUNCTION("""COMPUTED_VALUE"""),0.40042824074074074) -> 0.40042824 | D4: =IFERROR(__xludf.DUMMYFUNCTION("""COMPUTED_VALUE"""),"SpBEND394154") -> SpBEND394154 | G4: =IFERROR(__xludf.DUMMYFUNCTION("""COMPUTED_VALUE"""),"Positive") -> Positive | H4: =IFERROR(__xludf.DUMMYFUNCTION("""COMPUTED_VALUE"""),"Positive") -> Positive | I4: =IFERROR(__xludf.DUMMYFUNCTION("""COMPUTED_VALUE"""),44561.0) -> 44561 | J4: =IFERROR(__xludf.DUMMYFUNCTION("""COMPUTED_VALUE"""),0.44559027777777777) -> 0.44559028 | N4: =IFERROR(__xludf.DUMMYFUNCTION("""COMPUTED_VALUE"""),1.0) -> 1 | O4: =IFERROR(__xludf.DUMMYFUNCTION("""COMPUTED_VALUE"""),57.0) -> 57 | P4: {=INDEX(postDEL!$A$2:$AR1340,$O4,40)} -> BEND796718 | Q4: {=IF($N4>1, INDEX(postDEL!$A$2:$AR1340,$O4+1,40),IFERROR(0/0,""))} | R4: {=IF($N4>2, INDEX(postDEL!$A$2:$AR1340,$O4+2,40),IFERROR(0/0,""))} | S4: {=IF($N4>3, INDEX(postDEL!$A$2:$AR1340,$O4+3,40),IFERROR(0/0,""))} | U4: FALSE | V4: =IF(COUNTIF($P$2:$P$74,P4)=1,"-",IF(COUNTIF($P$2:P4,P4)=1,"1st",TRUE)) -> 1st | W4: TRUE | X4: TRUE | Y4: =IFERROR(IF(V4,TRUE,IFERROR(0/0,"")),"")
A5: =IFERROR(__xludf.DUMMYFUNCTION("""COMPUTED_VALUE"""),"MA639") -> MA639 | B5: =IFERROR(__xludf.DUMMYFUNCTION("""COMPUTED_VALUE"""),44564.0) -> 44564 | C5: =IFERROR(__xludf.DUMMYFUNCTION("""COMPUTED_VALUE"""),0.3048032407407407) -> 0.30480324 | D5: =IFERROR(__xludf.DUMMYFUNCTION("""COMPUTED_VALUE"""),"SpBEND899578") -> SpBEND899578 | G5: =IFERROR(__xludf.DUMMYFUNCTION("""COMPUTED_VALUE"""),"Positive") -> Positive | H5: =IFERROR(__xludf.DUMMYFUNCTION("""COMPUTED_VALUE"""),"Positive") -> Positive | I5: =IFERROR(__xludf.DUMMYFUNCTION("""COMPUTED_VALUE"""),44564.0) -> 44564 | J5: =IFERROR(__xludf.DUMMYFUNCTION("""COMPUTED_VALUE"""),0.5280439814814815) -> 0.52804398 | N5: =IFERROR(__xludf.DUMMYFUNCTION("""COMPUTED_VALUE"""),1.0) -> 1 | O5: =IFERROR(__xludf.DUMMYFUNCTION("""COMPUTED_VALUE"""),59.0) -> 59 | P5: {=INDEX(postDEL!$A$2:$AR1340,$O5,40)} -> BEND949070 | Q5: {=IF($N5>1, INDEX(postDEL!$A$2:$AR1340,$O5+1,40),IFERROR(0/0,""))} | R5: {=IF($N5>2, INDEX(postDEL!$A$2:$AR1340,$O5+2,40),IFERROR(0/0,""))} | S5: {=IF($N5>3, INDEX(postDEL!$A$2:$AR1340,$O5+3,40),IFERROR(0/0,""))} | U5: FALSE | V5: =IF(COUNTIF($P$2:$P$74,P5)=1,"-",IF(COUNTIF($P$2:P5,P5)=1,"1st",TRUE)) -> 1st | W5: TRUE | X5: TRUE | Y5: =IFERROR(IF(V5,TRUE,IFERROR(0/0,"")),"")
A6: =IFERROR(__xludf.DUMMYFUNCTION("""COMPUTED_VALUE"""),"MA448") -> MA448 | B6: =IFERROR(__xludf.DUMMYFUNCTION("""COMPUTED_VALUE"""),44564.0) -> 44564 | C6: =IFERROR(__xludf.DUMMYFUNCTION("""COMPUTED_VALUE"""),0.33775462962962965) -> 0.33775463 | D6: =IFERROR(__xludf.DUMMYFUNCTION("""COMPUTED_VALUE"""),"SpBEND139600") -> SpBEND139600 | G6: =IFERROR(__xludf.DUMMYFUNCTION("""COMPUTED_VALUE"""),"Positive") -> Positive | H6: =IFERROR(__xludf.DUMMYFUNCTION("""COMPUTED_VALUE"""),"Positive") -> Positive | I6: =IFERROR(__xludf.DUMMYFUNCTION("""COMPUTED_VALUE"""),44564.0) -> 44564 | J6: =IFERROR(__xludf.DUMMYFUNCTION("""COMPUTED_VALUE"""),0.5280439814814815) -> 0.52804398 | N6: =IFERROR(__xludf.DUMMYFUNCTION("""COMPUTED_VALUE"""),1.0) -> 1 | O6: =IFERROR(__xludf.DUMMYFUNCTION("""COMPUTED_VALUE"""),63.0) -> 63 | P6: {=INDEX(postDEL!$A$2:$AR1340,$O6,40)} -> BEND133778 | Q6: {=IF($N6>1, INDEX(postDEL!$A$2:$AR1340,$O6+1,40),IFERROR(0/0,""))} | R6: {=IF($N6>2, INDEX(postDEL!$A$2:$AR1340,$O6+2,40),IFERROR(0/0,""))} | S6: {=IF($N6>3, INDEX(postDEL!$A$2:$AR1340,$O6+3,40),IFERROR(0/0,""))} | U6: FALSE | V6: =IF(COUNTIF($P$2:$P$74,P6)=1,"-",IF(COUNTIF($P$2:P6,P6)=1,"1st",TRUE)) -> - | W6: TRUE | X6: TRUE
A7: =IFERROR(__xludf.DUMMYFUNCTION("""COMPUTED_VALUE"""),"MA287") -> MA287 | B7: =IFERROR(__xludf.DUMMYFUNCTION("""COMPUTED_VALUE"""),44564.0) -> 44564 | C7: =IFERROR(__xludf.DUMMYFUNCTION("""COMPUTED_VALUE"""),0.35965277777777777) -> 0.35965278 | D7: =IFERROR(__xludf.DUMMYFUNCTION("""COMPUTED_VALUE"""),"SpBEND387532") -> SpBEND387532 | G7: =IFERROR(__xludf.DUMMYFUNCTION("""COMPUTED_VALUE"""),"Positive") -> Positive | H7: =IFERROR(__xludf.DUMMYFUNCTION("""COMPUTED_VALUE"""),"Positive") -> Positive | I7: =IFERROR(__xludf.DUMMYFUNCTION("""COMPUTED_VALUE"""),44564.0) -> 44564 | J7: =IFERROR(__xludf.DUMMYFUNCTION("""COMPUTED_VALUE"""),0.5280439814814815) -> 0.52804398 | N7: =IFERROR(__xludf.DUMMYFUNCTION("""COMPUTED_VALUE"""),1.0) -> 1 | O7: =IFERROR(__xludf.DUMMYFUNCTION("""COMPUTED_VALUE"""),66.0) -> 66 | P7: {=INDEX(postDEL!$A$2:$AR1340,$O7,40)} -> BEND796718 | Q7: {=IF($N7>1, INDEX(postDEL!$A$2:$AR1340,$O7+1,40),IFERROR(0/0,""))} | R7: {=IF($N7>2, INDEX(postDEL!$A$2:$AR1340,$O7+2,40),IFERROR(0/0,""))} | S7: {=IF($N7>3, INDEX(postDEL!$A$2:$AR1340,$O7+3,40),IFERROR(0/0,""))} | U7: FALSE | V7: =IF(COUNTIF($P$2:$P$74,P7)=1,"-",IF(COUNTIF($P$2:P7,P7)=1,"1st",TRUE)) -> TRUE | W7: TRUE | X7: TRUE
A8: =IFERROR(__xludf.DUMMYFUNCTION("""COMPUTED_VALUE"""),"MA473") -> MA473 | B8: =IFERROR(__xludf.DUMMYFUNCTION("""COMPUTED_VALUE"""),44564.0) -> 44564 | C8: =IFERROR(__xludf.DUMMYFUNCTION("""COMPUTED_VALUE"""),0.3654513888888889) -> 0.36545139 | D8: =IFERROR(__xludf.DUMMYFUNCTION("""COMPUTED_VALUE"""),"SpBEND394154") -> SpBEND394154 | G8: =IFERROR(__xludf.DUMMYFUNCTION("""COMPUTED_VALUE"""),"Positive") -> Positive | H8: =IFERROR(__xludf.DUMMYFUNCTION("""COMPUTED_VALUE"""),"Positive") -> Positive | I8: =IFERROR(__xludf.DUMMYFUNCTION("""COMPUTED_VALUE"""),44564.0) -> 44564 | J8: =IFERROR(__xludf.DUMMYFUNCTION("""COMPUTED_VALUE"""),0.5280439814814815) -> 0.52804398 | N8: =IFERROR(__xludf.DUMMYFUNCTION("""COMPUTED_VALUE"""),1.0) -> 1 | O8: =IFERROR(__xludf.DUMMYFUNCTION("""COMPUTED_VALUE"""),67.0) -> 67 | P8: {=INDEX(postDEL!$A$2:$AR1340,$O8,40)} -> BEND927956 | Q8: {=IF($N8>1, INDEX(postDEL!$A$2:$AR1340,$O8+1,40),IFERROR(0/0,""))} | R8: {=IF($N8>2, INDEX(postDEL!$A$2:$AR1340,$O8+2,40),IFERROR(0/0,""))} | S8: {=IF($N8>3, INDEX(postDEL!$A$2:$AR1340,$O8+3,40),IFERROR(0/0,""))} | U8: FALSE | V8: =IF(COUNTIF($P$2:$P$74,P8)=1,"-",IF(COUNTIF($P$2:P8,P8)=1,"1st",TRUE)) -> - | W8: TRUE | X8: TRUE
A9: =IFERROR(__xludf.DUMMYFUNCTION("""COMPUTED_VALUE"""),"MA263") -> MA263 | B9: =IFERROR(__xludf.DUMMYFUNCTION("""COMPUTED_VALUE"""),44566.0) -> 44566 | C9: =IFERROR(__xludf.DUMMYFUNCTION("""COMPUTED_VALUE"""),0.3297453703703704) -> 0.32974537 | D9: =IFERROR(__xludf.DUMMYFUNCTION("""COMPUTED_VALUE"""),"SpBEND944634") -> SpBEND944634 | G9: =IFERROR(__xludf.DUMMYFUNCTION("""COMPUTED_VALUE"""),"Positive") -> Positive | H9: =IFERROR(__xludf.DUMMYFUNCTION("""COMPUTED_VALUE"""),"Positive") -> Positive | I9: =IFERROR(__xludf.DUMMYFUNCTION("""COMPUTED_VALUE"""),44568.0) -> 44568 | J9: =IFERROR(__xludf.DUMMYFUNCTION("""COMPUTED_VALUE"""),0.508275462962963) -> 0.50827546 | N9: =IFERROR(__xludf.DUMMYFUNCTION("""COMPUTED_VALUE"""),1.0) -> 1 | O9: =IFERROR(__xludf.DUMMYFUNCTION("""COMPUTED_VALUE"""),78.0) -> 78 | P9: {=INDEX(postDEL!$A$2:$AR1340,$O9,40)} -> BEND626338 | Q9: {=IF($N9>1, INDEX(postDEL!$A$2:$AR1340,$O9+1,40),IFERROR(0/0,""))} | R9: {=IF($N9>2, INDEX(postDEL!$A$2:$AR1340,$O9+2,40),IFERROR(0/0,""))} | S9: {=IF($N9>3, INDEX(postDEL!$A$2:$AR1340,$O9+3,40),IFERROR(0/0,""))} | U9: FALSE | V9: =IF(COUNTIF($P$2:$P$74,P9)=1,"-",IF(COUNTIF($P$2:P9,P9)=1,"1st",TRUE)) -> - | W9: TRUE | X9: TRUE
A10: =IFERROR(__xludf.DUMMYFUNCTION("""COMPUTED_VALUE"""),"MA218") -> MA218 | B10: =IFERROR(__xludf.DUMMYFUNCTION("""COMPUTED_VALUE"""),44566.0) -> 44566 | C10: =IFERROR(__xludf.DUMMYFUNCTION("""COMPUTED_VALUE"""),0.3307638888888889) -> 0.33076389 | D10: =IFERROR(__xludf.DUMMYFUNCTION("""COMPUTED_VALUE"""),"SpBEND387532") -> SpBEND387532 | G10: =IFERROR(__xludf.DUMMYFUNCTION("""COMPUTED_VALUE"""),"Positive") -> Positive | H10: =IFERROR(__xludf.DUMMYFUNCTION("""COMPUTED_VALUE"""),"Positive") -> Positive | I10: =IFERROR(__xludf.DUMMYFUNCTION("""COMPUTED_VALUE"""),44568.0) -> 44568 | J10: =IFERROR(__xludf.DUMMYFUNCTION("""COMPUTED_VALUE"""),0.508275462962963) -> 0.50827546 | N10: =IFERROR(__xludf.DUMMYFUNCTION("""COMPUTED_VALUE"""),1.0) -> 1 | O10: =IFERROR(__xludf.DUMMYFUNCTION("""COMPUTED_VALUE"""),79.0) -> 79 | P10: {=INDEX(postDEL!$A$2:$AR1340,$O10,40)} -> BEND796718 | Q10: {=IF($N10>1, INDEX(postDEL!$A$2:$AR1340,$O10+1,40),IFERROR(0/0,""))} | R10: {=IF($N10>2, INDEX(postDEL!$A$2:$AR1340,$O10+2,40),IFERROR(0/0,""))} | S10: {=IF($N10>3, INDEX(postDEL!$A$2:$AR1340,$O10+3,40),IFERROR(0/0,""))} | U10: FALSE | V10: =IF(COUNTIF($P$2:$P$74,P10)=1,"-",IF(COUNTIF($P$2:P10,P10)=1,"1st",TRUE)) -> TRUE | W10: TRUE | X10: TRUE
A11: =IFERROR(__xludf.DUMMYFUNCTION("""COMPUTED_VALUE"""),"MA605") -> MA605 | B11: =IFERROR(__xludf.DUMMYFUNCTION("""COMPUTED_VALUE"""),44566.0) -> 44566 | C11: =IFERROR(__xludf.DUMMYFUNCTION("""COMPUTED_VALUE"""),0.4199421296296296) -> 0.41994213 | D11: =IFERROR(__xludf.DUMMYFUNCTION("""COMPUTED_VALUE"""),"SpBEND110967") -> SpBEND110967 | G11: =IFERROR(__xludf.DUMMYFUNCTION("""COMPUTED_VALUE"""),"Positive") -> Positive | H11: =IFERROR(__xludf.DUMMYFUNCTION("""COMPUTED_VALUE"""),"Positive") -> Positive | I11: =IFERROR(__xludf.DUMMYFUNCTION("""COMPUTED_VALUE"""),44568.0) -> 44568 | J11: =IFERROR(__xludf.DUMMYFUNCTION("""COMPUTED_VALUE"""),0.508275462962963) -> 0.50827546 | N11: =IFERROR(__xludf.DUMMYFUNCTION("""COMPUTED_VALUE"""),1.0) -> 1 | O11: =IFERROR(__xludf.DUMMYFUNCTION("""COMPUTED_VALUE"""),91.0) -> 91 | P11: {=INDEX(postDEL!$A$2:$AR1340,$O11,40)} -> BEND202183 | Q11: {=IF($N11>1, INDEX(postDEL!$A$2:$AR1340,$O11+1,40),IFERROR(0/0,""))} | R11: {=IF($N11>2, INDEX(postDEL!$A$2:$AR1340,$O11+2,40),IFERROR(0/0,""))} | S11: {=IF($N11>3, INDEX(postDEL!$A$2:$AR1340,$O11+3,40),IFERROR(0/0,""))} | U11: FALSE | V11: =IF(COUNTIF($P$2:$P$74,P11)=1,"-",IF(COUNTIF($P$2:P11,P11)=1,"1st",TRUE)) -> - | W11: TRUE | X11: TRUE
A12: =IFERROR(__xludf.DUMMYFUNCTION("""COMPUTED_VALUE"""),"MA1188") -> MA1188 | B12: =IFERROR(__xludf.DUMMYFUNCTION("""COMPUTED_VALUE"""),44568.0) -> 44568 | C12: =IFERROR(__xludf.DUMMYFUNCTION("""COMPUTED_VALUE"""),0.34097222222222223) -> 0.34097222 | D12: =IFERROR(__xludf.DUMMYFUNCTION("""COMPUTED_VALUE"""),"SpBEND387532") -> SpBEND387532 | G12: =IFERROR(__xludf.DUMMYFUNCTION("""COMPUTED_VALUE"""),"Positive") -> Positive | H12: =IFERROR(__xludf.DUMMYFUNCTION("""COMPUTED_VALUE"""),"Positive") -> Positive | I12: =IFERROR(__xludf.DUMMYFUNCTION("""COMPUTED_VALUE"""),44568.0) -> 44568 | J12: =IFERROR(__xludf.DUMMYFUNCTION("""COMPUTED_VALUE"""),0.5079050925925926) -> 0.50790509 | N12: =IFERROR(__xludf.DUMMYFUNCTION("""COMPUTED_VALUE"""),1.0) -> 1 | O12: =IFERROR(__xludf.DUMMYFUNCTION("""COMPUTED_VALUE"""),104.0) -> 104 | P12: {=INDEX(postDEL!$A$2:$AR1340,$O12,40)} -> BEND796718 | Q12: {=IF($N12>1, INDEX(postDEL!$A$2:$AR1340,$O12+1,40),IFERROR(0/0,""))} | R12: {=IF($N12>2, INDEX(postDEL!$A$2:$AR1340,$O12+2,40),IFERROR(0/0,""))} | S12: {=IF($N12>3, INDEX(postDEL!$A$2:$AR1340,$O12+3,40),IFERROR(0/0,""))} | U12: FALSE | V12: =IF(COUNTIF($P$2:$P$74,P12)=1,"-",IF(COUNTIF($P$2:P12,P12)=1,"1st",TRUE)) -> TRUE | W12: TRUE | X12: TRUE
A13: =IFERROR(__xludf.DUMMYFUNCTION("""COMPUTED_VALUE"""),"MA1078") -> MA1078 | B13: =IFERROR(__xludf.DUMMYFUNCTION("""COMPUTED_VALUE"""),44568.0) -> 44568 | C13: =IFERROR(__xludf.DUMMYFUNCTION("""COMPUTED_VALUE"""),0.34717592592592594) -> 0.34717593 | D13: =IFERROR(__xludf.DUMMYFUNCTION("""COMPUTED_VALUE"""),"SpBEND652059") -> SpBEND652059 | G13: =IFERROR(__xludf.DUMMYFUNCTION("""COMPUTED_VALUE"""),"Positive") -> Positive | H13: =IFERROR(__xludf.DUMMYFUNCTION("""COMPUTED_VALUE"""),"Positive") -> Positive | I13: =IFERROR(__xludf.DUMMYFUNCTION("""COMPUTED_VALUE"""),44568.0) -> 44568 | J13: =IFERROR(__xludf.DUMMYFUNCTION("""COMPUTED_VALUE"""),0.5079050925925926) -> 0.50790509 | N13: =IFERROR(__xludf.DUMMYFUNCTION("""COMPUTED_VALUE"""),1.0) -> 1 | O13: =IFERROR(__xludf.DUMMYFUNCTION("""COMPUTED_VALUE"""),108.0) -> 108 | P13: {=INDEX(postDEL!$A$2:$AR1340,$O13,40)} -> BEND520608 | Q13: {=IF($N13>1, INDEX(postDEL!$A$2:$AR1340,$O13+1,40),IFERROR(0/0,""))} | R13: {=IF($N13>2, INDEX(postDEL!$A$2:$AR1340,$O13+2,40),IFERROR(0/0,""))} | S13: {=IF($N13>3, INDEX(postDEL!$A$2:$AR1340,$O13+3,40),IFERROR(0/0,""))} | U13: FALSE | V13: =IF(COUNTIF($P$2:$P$74,P13)=1,"-",IF(COUNTIF($P$2:P13,P13)=1,"1st",TRUE)) -> - | W13: TRUE | X13: TRUE
A14: =IFERROR(__xludf.DUMMYFUNCTION("""COMPUTED_VALUE"""),"MAX74") -> MAX74 | B14: =IFERROR(__xludf.DUMMYFUNCTION("""COMPUTED_VALUE"""),44568.0) -> 44568 | C14: =IFERROR(__xludf.DUMMYFUNCTION("""COMPUTED_VALUE"""),0.3647800925925926) -> 0.36478009 | D14: =IFERROR(__xludf.DUMMYFUNCTION("""COMPUTED_VALUE"""),"SpBEND642175") -> SpBEND642175 | G14: =IFERROR(__xludf.DUMMYFUNCTION("""COMPUTED_VALUE"""),"Positive") -> Positive | H14: =IFERROR(__xludf.DUMMYFUNCTION("""COMPUTED_VALUE"""),"Positive") -> Positive | I14: =IFERROR(__xludf.DUMMYFUNCTION("""COMPUTED_VALUE"""),44568.0) -> 44568 | J14: =IFERROR(__xludf.DUMMYFUNCTION("""COMPUTED_VALUE"""),0.508275462962963) -> 0.50827546 | N14: =IFERROR(__xludf.DUMMYFUNCTION("""COMPUTED_VALUE"""),1.0) -> 1 | O14: =IFERROR(__xludf.DUMMYFUNCTION("""COMPUTED_VALUE"""),110.0) -> 110 | P14: {=INDEX(postDEL!$A$2:$AR1340,$O14,40)} -> BEND883134 | Q14: {=IF($N14>1, INDEX(postDEL!$A$2:$AR1340,$O14+1,40),IFERROR(0/0,""))} | R14: {=IF($N14>2, INDEX(postDEL!$A$2:$AR1340,$O14+2,40),IFERROR(0/0,""))} | S14: {=IF($N14>3, INDEX(postDEL!$A$2:$AR1340,$O14+3,40),IFERROR(0/0,""))} | U14: FALSE | V14: =IF(COUNTIF($P$2:$P$74,P14)=1,"-",IF(COUNTIF($P$2:P14,P14)=1,"1st",TRUE)) -> - | W14: TRUE | X14: TRUE
A15: =IFERROR(__xludf.DUMMYFUNCTION("""COMPUTED_VALUE"""),"MA1024") -> MA1024 | B15: =IFERROR(__xludf.DUMMYFUNCTION("""COMPUTED_VALUE"""),44571.0) -> 44571 | C15: =IFERROR(__xludf.DUMMYFUNCTION("""COMPUTED_VALUE"""),0.35119212962962965) -> 0.35119213 | D15: =IFERROR(__xludf.DUMMYFUNCTION("""COMPUTED_VALUE"""),"SpBEND652059") -> SpBEND652059 | G15: =IFERROR(__xludf.DUMMYFUNCTION("""COMPUTED_VALUE"""),"Positive") -> Positive | H15: =IFERROR(__xludf.DUMMYFUNCTION("""COMPUTED_VALUE"""),"Positive") -> Positive | I15: =IFERROR(__xludf.DUMMYFUNCTION("""COMPUTED_VALUE"""),44579.0) -> 44579 | J15: =IFERROR(__xludf.DUMMYFUNCTION("""COMPUTED_VALUE"""),0.5015740740740741) -> 0.50157407 | N15: =IFERROR(__xludf.DUMMYFUNCTION("""COMPUTED_VALUE"""),1.0) -> 1 | O15: =IFERROR(__xludf.DUMMYFUNCTION("""COMPUTED_VALUE"""),126.0) -> 126 | P15: {=INDEX(postDEL!$A$2:$AR1340,$O15,40)} -> BEND305148 | Q15: {=IF($N15>1, INDEX(postDEL!$A$2:$AR1340,$O15+1,40),IFERROR(0/0,""))} | R15: {=IF($N15>2, INDEX(postDEL!$A$2:$AR1340,$O15+2,40),IFERROR(0/0,""))} | S15: {=IF($N15>3, INDEX(postDEL!$A$2:$AR1340,$O15+3,40),IFERROR(0/0,""))} | U15: FALSE | V15: =IF(COUNTIF($P$2:$P$74,P15)=1,"-",IF(COUNTIF($P$2:P15,P15)=1,"1st",TRUE)) -> - | W15: TRUE | X15: TRUE
A16: =IFERROR(__xludf.DUMMYFUNCTION("""COMPUTED_VALUE"""),"MA463") -> MA463 | B16: =IFERROR(__xludf.DUMMYFUNCTION("""COMPUTED_VALUE"""),44571.0) -> 44571 | C16: =IFERROR(__xludf.DUMMYFUNCTION("""COMPUTED_VALUE"""),0.3882638888888889) -> 0.38826389 | D16: =IFERROR(__xludf.DUMMYFUNCTION("""COMPUTED_VALUE"""),"SpBEND394154") -> SpBEND394154 | G16: =IFERROR(__xludf.DUMMYFUNCTION("""COMPUTED_VALUE"""),"Positive") -> Positive | H16: =IFERROR(__xludf.DUMMYFUNCTION("""COMPUTED_VALUE"""),"Positive") -> Positive | I16: =IFERROR(__xludf.DUMMYFUNCTION("""COMPUTED_VALUE"""),44579.0) -> 44579 | J16: =IFERROR(__xludf.DUMMYFUNCTION("""COMPUTED_VALUE"""),0.5015740740740741) -> 0.50157407 | N16: =IFERROR(__xludf.DUMMYFUNCTION("""COMPUTED_VALUE"""),1.0) -> 1 | O16: =IFERROR(__xludf.DUMMYFUNCTION("""COMPUTED_VALUE"""),128.0) -> 128 | P16: {=INDEX(postDEL!$A$2:$AR1340,$O16,40)} -> BEND319589 | Q16: {=IF($N16>1, INDEX(postDEL!$A$2:$AR1340,$O16+1,40),IFERROR(0/0,""))} | R16: {=IF($N16>2, INDEX(postDEL!$A$2:$AR1340,$O16+2,40),IFERROR(0/0,""))} | S16: {=IF($N16>3, INDEX(postDEL!$A$2:$AR1340,$O16+3,40),IFERROR(0/0,""))} | U16: FALSE | V16: =IF(COUNTIF($P$2:$P$74,P16)=1,"-",IF(COUNTIF($P$2:P16,P16)=1,"1st",TRUE)) -> - | W16: TRUE | X16: TRUE
A17: =IFERROR(__xludf.DUMMYFUNCTION("""COMPUTED_VALUE"""),"MAX51") -> MAX51 | B17: =IFERROR(__xludf.DUMMYFUNCTION("""COMPUTED_VALUE"""),44571.0) -> 44571 | C17: =IFERROR(__xludf.DUMMYFUNCTION("""COMPUTED_VALUE"""),0.38880787037037035) -> 0.38880787 | D17: =IFERROR(__xludf.DUMMYFUNCTION("""COMPUTED_VALUE"""),"SpBEND394154") -> SpBEND394154 | G17: =IFERROR(__xludf.DUMMYFUNCTION("""COMPUTED_VALUE"""),"Positive") -> Positive | H17: =IFERROR(__xludf.DUMMYFUNCTION("""COMPUTED_VALUE"""),"Positive") -> Positive | I17: =IFERROR(__xludf.DUMMYFUNCTION("""COMPUTED_VALUE"""),44579.0) -> 44579 | J17: =IFERROR(__xludf.DUMMYFUNCTION("""COMPUTED_VALUE"""),0.5015740740740741) -> 0.50157407 | N17: =IFERROR(__xludf.DUMMYFUNCTION("""COMPUTED_VALUE"""),1.0) -> 1 | O17: =IFERROR(__xludf.DUMMYFUNCTION("""COMPUTED_VALUE"""),129.0) -> 129 | P17: {=INDEX(postDEL!$A$2:$AR1340,$O17,40)} -> BEND219153 | Q17: {=IF($N17>1, INDEX(postDEL!$A$2:$AR1340,$O17+1,40),IFERROR(0/0,""))} | R17: {=IF($N17>2, INDEX(postDEL!$A$2:$AR1340,$O17+2,40),IFERROR(0/0,""))} | S17: {=IF($N17>3, INDEX(postDEL!$A$2:$AR1340,$O17+3,40),IFERROR(0/0,""))} | U17: FALSE | V17: =IF(COUNTIF($P$2:$P$74,P17)=1,"-",IF(COUNTIF($P$2:P17,P17)=1,"1st",TRUE)) -> 1st | W17: TRUE | X17: TRUE
A18: =IFERROR(__xludf.DUMMYFUNCTION("""COMPUTED_VALUE"""),"MAX95") -> MAX95 | B18: =IFERROR(__xludf.DUMMYFUNCTION("""COMPUTED_VALUE"""),44571.0) -> 44571 | C18: =IFERROR(__xludf.DUMMYFUNCTION("""COMPUTED_VALUE"""),0.38936342592592593) -> 0.38936343 | D18: =IFERROR(__xludf.DUMMYFUNCTION("""COMPUTED_VALUE"""),"SpBEND394154") -> SpBEND394154 | G18: =IFERROR(__xludf.DUMMYFUNCTION("""COMPUTED_VALUE"""),"Positive") -> Positive | H18: =IFERROR(__xludf.DUMMYFUNCTION("""COMPUTED_VALUE"""),"Positive") -> Positive | I18: =IFERROR(__xludf.DUMMYFUNCTION("""COMPUTED_VALUE"""),44579.0) -> 44579 | J18: =IFERROR(__xludf.DUMMYFUNCTION("""COMPUTED_VALUE"""),0.5015740740740741) -> 0.50157407 | N18: =IFERROR(__xludf.DUMMYFUNCTION("""COMPUTED_VALUE"""),1.0) -> 1 | O18: =IFERROR(__xludf.DUMMYFUNCTION("""COMPUTED_VALUE"""),130.0) -> 130 | P18: {=INDEX(postDEL!$A$2:$AR1340,$O18,40)} -> BEND421116 | Q18: {=IF($N18>1, INDEX(postDEL!$A$2:$AR1340,$O18+1,40),IFERROR(0/0,""))} | R18: {=IF($N18>2, INDEX(postDEL!$A$2:$AR1340,$O18+2,40),IFERROR(0/0,""))} | S18: {=IF($N18>3, INDEX(postDEL!$A$2:$AR1340,$O18+3,40),IFERROR(0/0,""))} | U18: FALSE | V18: =IF(COUNTIF($P$2:$P$74,P18)=1,"-",IF(COUNTIF($P$2:P18,P18)=1,"1st",TRUE)) -> - | W18: TRUE | X18: TRUE
A19: =IFERROR(__xludf.DUMMYFUNCTION("""COMPUTED_VALUE"""),"MAX69") -> MAX69 | B19: =IFERROR(__xludf.DUMMYFUNCTION("""COMPUTED_VALUE"""),44571.0) -> 44571 | C19: =IFERROR(__xludf.DUMMYFUNCTION("""COMPUTED_VALUE"""),0.3899768518518518) -> 0.38997685 | D19: =IFERROR(__xludf.DUMMYFUNCTION("""COMPUTED_VALUE"""),"SpBEND394154") -> SpBEND394154 | G19: =IFERROR(__xludf.DUMMYFUNCTION("""COMPUTED_VALUE"""),"Positive") -> Positive | H19: =IFERROR(__xludf.DUMMYFUNCTION("""COMPUTED_VALUE"""),"Positive") -> Positive | I19: =IFERROR(__xludf.DUMMYFUNCTION("""COMPUTED_VALUE"""),44579.0) -> 44579 | J19: =IFERROR(__xludf.DUMMYFUNCTION("""COMPUTED_VALUE"""),0.5015740740740741) -> 0.50157407 | N19: =IFERROR(__xludf.DUMMYFUNCTION("""COMPUTED_VALUE"""),1.0) -> 1 | O19: =IFERROR(__xludf.DUMMYFUNCTION("""COMPUTED_VALUE"""),131.0) -> 131 | P19: {=INDEX(postDEL!$A$2:$AR1340,$O19,40)} -> BEND530620 | Q19: {=IF($N19>1, INDEX(postDEL!$A$2:$AR1340,$O19+1,40),IFERROR(0/0,""))} | R19: {=IF($N19>2, INDEX(postDEL!$A$2:$AR1340,$O19+2,40),IFERROR(0/0,""))} | S19: {=IF($N19>3, INDEX(postDEL!$A$2:$AR1340,$O19+3,40),IFERROR(0/0,""))} | U19: FALSE | V19: =IF(COUNTIF($P$2:$P$74,P19)=1,"-",IF(COUNTIF($P$2:P19,P19)=1,"1st",TRUE)) -> 1st | W19: TRUE | X19: TRUE
A20: =IFERROR(__xludf.DUMMYFUNCTION("""COMPUTED_VALUE"""),"MA341") -> MA341 | B20: =IFERROR(__xludf.DUMMYFUNCTION("""COMPUTED_VALUE"""),44571.0) -> 44571 | C20: =IFERROR(__xludf.DUMMYFUNCTION("""COMPUTED_VALUE"""),0.3928935185185185) -> 0.39289352 | D20: =IFERROR(__xludf.DUMMYFUNCTION("""COMPUTED_VALUE"""),"SpBEND394154") -> SpBEND394154 | G20: =IFERROR(__xludf.DUMMYFUNCTION("""COMPUTED_VALUE"""),"Positive") -> Positive | H20: =IFERROR(__xludf.DUMMYFUNCTION("""COMPUTED_VALUE"""),"Positive") -> Positive | I20: =IFERROR(__xludf.DUMMYFUNCTION("""COMPUTED_VALUE"""),44579.0) -> 44579 | J20: =IFERROR(__xludf.DUMMYFUNCTION("""COMPUTED_VALUE"""),0.5015740740740741) -> 0.50157407 | N20: =IFERROR(__xludf.DUMMYFUNCTION("""COMPUTED_VALUE"""),1.0) -> 1 | O20: =IFERROR(__xludf.DUMMYFUNCTION("""COMPUTED_VALUE"""),136.0) -> 136 | P20: {=INDEX(postDEL!$A$2:$AR1340,$O20,40)} -> BEND524074 | Q20: {=IF($N20>1, INDEX(postDEL!$A$2:$AR1340,$O20+1,40),IFERROR(0/0,""))} | R20: {=IF($N20>2, INDEX(postDEL!$A$2:$AR1340,$O20+2,40),IFERROR(0/0,""))} | S20: {=IF($N20>3, INDEX(postDEL!$A$2:$AR1340,$O20+3,40),IFERROR(0/0,""))} | U20: FALSE | V20: =IF(COUNTIF($P$2:$P$74,P20)=1,"-",IF(COUNTIF($P$2:P20,P20)=1,"1st",TRUE)) -> 1st | W20: TRUE | X20: TRUE
A21: =IFERROR(__xludf.DUMMYFUNCTION("""COMPUTED_VALUE"""),"MA435") -> MA435 | B21: =IFERROR(__xludf.DUMMYFUNCTION("""COMPUTED_VALUE"""),44571.0) -> 44571 | C21: =IFERROR(__xludf.DUMMYFUNCTION("""COMPUTED_VALUE"""),0.42716435185185186) -> 0.42716435 | D21: =IFERROR(__xludf.DUMMYFUNCTION("""COMPUTED_VALUE"""),"SpBEND394154") -> SpBEND394154 | G21: =IFERROR(__xludf.DUMMYFUNCTION("""COMPUTED_VALUE"""),"Positive") -> Positive | H21: =IFERROR(__xludf.DUMMYFUNCTION("""COMPUTED_VALUE"""),"Positive") -> Positive | I21: =IFERROR(__xludf.DUMMYFUNCTION("""COMPUTED_VALUE"""),44579.0) -> 44579 | J21: =IFERROR(__xludf.DUMMYFUNCTION("""COMPUTED_VALUE"""),0.5015740740740741) -> 0.50157407 | N21: =IFERROR(__xludf.DUMMYFUNCTION("""COMPUTED_VALUE"""),1.0) -> 1 | O21: =IFERROR(__xludf.DUMMYFUNCTION("""COMPUTED_VALUE"""),138.0) -> 138 | P21: {=INDEX(postDEL!$A$2:$AR1340,$O21,40)} -> BEND732984 | Q21: {=IF($N21>1, INDEX(postDEL!$A$2:$AR1340,$O21+1,40),IFERROR(0/0,""))} | R21: {=IF($N21>2, INDEX(postDEL!$A$2:$AR1340,$O21+2,40),IFERROR(0/0,""))} | S21: {=IF($N21>3, INDEX(postDEL!$A$2:$AR1340,$O21+3,40),IFERROR(0/0,""))} | U21: FALSE | V21: =IF(COUNTIF($P$2:$P$74,P21)=1,"-",IF(COUNTIF($P$2:P21,P21)=1,"1st",TRUE)) -> - | W21: TRUE | X21: TRUE
A22: =IFERROR(__xludf.DUMMYFUNCTION("""COMPUTED_VALUE"""),"MA1156") -> MA1156 | B22: =IFERROR(__xludf.DUMMYFUNCTION("""COMPUTED_VALUE"""),44573.0) -> 44573 | C22: =IFERROR(__xludf.DUMMYFUNCTION("""COMPUTED_VALUE"""),0.32337962962962963) -> 0.32337963 | D22: =IFERROR(__xludf.DUMMYFUNCTION("""COMPUTED_VALUE"""),"SpBEND198321") -> SpBEND198321 | G22: =IFERROR(__xludf.DUMMYFUNCTION("""COMPUTED_VALUE"""),"Positive") -> Positive | H22: =IFERROR(__xludf.DUMMYFUNCTION("""COMPUTED_VALUE"""),"Positive") -> Positive | I22: =IFERROR(__xludf.DUMMYFUNCTION("""COMPUTED_VALUE"""),44579.0) -> 44579 | J22: =IFERROR(__xludf.DUMMYFUNCTION("""COMPUTED_VALUE"""),0.5015856481481481) -> 0.50158565 | N22: =IFERROR(__xludf.DUMMYFUNCTION("""COMPUTED_VALUE"""),1.0) -> 1 | O22: =IFERROR(__xludf.DUMMYFUNCTION("""COMPUTED_VALUE"""),148.0) -> 148 | P22: {=INDEX(postDEL!$A$2:$AR1340,$O22,40)} -> BEND772881 | Q22: {=IF($N22>1, INDEX(postDEL!$A$2:$AR1340,$O22+1,40),IFERROR(0/0,""))} | R22: {=IF($N22>2, INDEX(postDEL!$A$2:$AR1340,$O22+2,40),IFERROR(0/0,""))} | S22: {=IF($N22>3, INDEX(postDEL!$A$2:$AR1340,$O22+3,40),IFERROR(0/0,""))} | U22: FALSE | V22: =IF(COUNTIF($P$2:$P$74,P22)=1,"-",IF(COUNTIF($P$2:P22,P22)=1,"1st",TRUE)) -> 1st | W22: TRUE | X22: TRUE
A23: =IFERROR(__xludf.DUMMYFUNCTION("""COMPUTED_VALUE"""),"MAX20") -> MAX20 | B23: =IFERROR(__xludf.DUMMYFUNCTION("""COMPUTED_VALUE"""),44573.0) -> 44573 | C23: =IFERROR(__xludf.DUMMYFUNCTION("""COMPUTED_VALUE"""),0.38359953703703703) -> 0.38359954 | D23: =IFERROR(__xludf.DUMMYFUNCTION("""COMPUTED_VALUE"""),"SpBEND394154") -> SpBEND394154 | G23: =IFERROR(__xludf.DUMMYFUNCTION("""COMPUTED_VALUE"""),"Positive") -> Positive | H23: =IFERROR(__xludf.DUMMYFUNCTION("""COMPUTED_VALUE"""),"Positive") -> Positive | I23: =IFERROR(__xludf.DUMMYFUNCTION("""COMPUTED_VALUE"""),44579.0) -> 44579 | J23: =IFERROR(__xludf.DUMMYFUNCTION("""COMPUTED_VALUE"""),0.5015856481481481) -> 0.50158565 | N23: =IFERROR(__xludf.DUMMYFUNCTION("""COMPUTED_VALUE"""),1.0) -> 1 | O23: =IFERROR(__xludf.DUMMYFUNCTION("""COMPUTED_VALUE"""),155.0) -> 155 | P23: {=INDEX(postDEL!$A$2:$AR1340,$O23,40)} -> BEND219153 | Q23: {=IF($N23>1, INDEX(postDEL!$A$2:$AR1340,$O23+1,40),IFERROR(0/0,""))} | R23: {=IF($N23>2, INDEX(postDEL!$A$2:$AR1340,$O23+2,40),IFERROR(0/0,""))} | S23: {=IF($N23>3, INDEX(postDEL!$A$2:$AR1340,$O23+3,40),IFERROR(0/0,""))} | U23: FALSE | V23: =IF(COUNTIF($P$2:$P$74,P23)=1,"-",IF(COUNTIF($P$2:P23,P23)=1,"1st",TRUE)) -> TRUE | W23: TRUE | X23: TRUE
A24: =IFERROR(__xludf.DUMMYFUNCTION("""COMPUTED_VALUE"""),"MAX72") -> MAX72 | B24: =IFERROR(__xludf.DUMMYFUNCTION("""COMPUTED_VALUE"""),44573.0) -> 44573 | C24: =IFERROR(__xludf.DUMMYFUNCTION("""COMPUTED_VALUE"""),0.3858564814814815) -> 0.38585648 | D24: =IFERROR(__xludf.DUMMYFUNCTION("""COMPUTED_VALUE"""),"SpBEND394154") -> SpBEND394154 | G24: =IFERROR(__xludf.DUMMYFUNCTION("""COMPUTED_VALUE"""),"Positive") -> Positive | H24: =IFERROR(__xludf.DUMMYFUNCTION("""COMPUTED_VALUE"""),"Positive") -> Positive | I24: =IFERROR(__xludf.DUMMYFUNCTION("""COMPUTED_VALUE"""),44579.0) -> 44579 | J24: =IFERROR(__xludf.DUMMYFUNCTION("""COMPUTED_VALUE"""),0.5015856481481481) -> 0.50158565 | N24: =IFERROR(__xludf.DUMMYFUNCTION("""COMPUTED_VALUE"""),1.0) -> 1 | O24: =IFERROR(__xludf.DUMMYFUNCTION("""COMPUTED_VALUE"""),157.0) -> 157 | P24: {=INDEX(postDEL!$A$2:$AR1340,$O24,40)} -> BEND389048 | Q24: {=IF($N24>1, INDEX(postDEL!$A$2:$AR1340,$O24+1,40),IFERROR(0/0,""))} | R24: {=IF($N24>2, INDEX(postDEL!$A$2:$AR1340,$O24+2,40),IFERROR(0/0,""))} | S24: {=IF($N24>3, INDEX(postDEL!$A$2:$AR1340,$O24+3,40),IFERROR(0/0,""))} | U24: FALSE | V24: =IF(COUNTIF($P$2:$P$74,P24)=1,"-",IF(COUNTIF($P$2:P24,P24)=1,"1st",TRUE)) -> - | W24: TRUE | X24: TRUE
A25: =IFERROR(__xludf.DUMMYFUNCTION("""COMPUTED_VALUE"""),"MAX36") -> MAX36 | B25: =IFERROR(__xludf.DUMMYFUNCTION("""COMPUTED_VALUE"""),44573.0) -> 44573 | C25: =IFERROR(__xludf.DUMMYFUNCTION("""COMPUTED_VALUE"""),0.3869444444444444) -> 0.38694444 | D25: =IFERROR(__xludf.DUMMYFUNCTION("""COMPUTED_VALUE"""),"SpBEND394154") -> SpBEND394154 | G25: =IFERROR(__xludf.DUMMYFUNCTION("""COMPUTED_VALUE"""),"Positive") -> Positive | H25: =IFERROR(__xludf.DUMMYFUNCTION("""COMPUTED_VALUE"""),"Positive") -> Positive | I25: =IFERROR(__xludf.DUMMYFUNCTION("""COMPUTED_VALUE"""),44579.0) -> 44579 | J25: =IFERROR(__xludf.DUMMYFUNCTION("""COMPUTED_VALUE"""),0.5015856481481481) -> 0.50158565 | N25: =IFERROR(__xludf.DUMMYFUNCTION("""COMPUTED_VALUE"""),1.0) -> 1 | O25: =IFERROR(__xludf.DUMMYFUNCTION("""COMPUTED_VALUE"""),159.0) -> 159 | P25: {=INDEX(postDEL!$A$2:$AR1340,$O25,40)} -> BEND524074 | Q25: {=IF($N25>1, INDEX(postDEL!$A$2:$AR1340,$O25+1,40),IFERROR(0/0,""))} | R25: {=IF($N25>2, INDEX(postDEL!$A$2:$AR1340,$O25+2,40),IFERROR(0/0,""))} | S25: {=IF($N25>3, INDEX(postDEL!$A$2:$AR1340,$O25+3,40),IFERROR(0/0,""))} | U25: FALSE | V25: =IF(COUNTIF($P$2:$P$74,P25)=1,"-",IF(COUNTIF($P$2:P25,P25)=1,"1st",TRUE)) -> TRUE | W25: TRUE | X25: TRUE
A26: =IFERROR(__xludf.DUMMYFUNCTION("""COMPUTED_VALUE"""),"MA1062") -> MA1062 | B26: =IFERROR(__xludf.DUMMYFUNCTION("""COMPUTED_VALUE"""),44574.0) -> 44574 | C26: =IFERROR(__xludf.DUMMYFUNCTION("""COMPUTED_VALUE"""),0.5845023148148148) -> 0.58450231 | D26: =IFERROR(__xludf.DUMMYFUNCTION("""COMPUTED_VALUE"""),"SpBEND328905") -> SpBEND328905 | G26: =IFERROR(__xludf.DUMMYFUNCTION("""COMPUTED_VALUE"""),"Positive") -> Positive | H26: =IFERROR(__xludf.DUMMYFUNCTION("""COMPUTED_VALUE"""),"Positive") -> Positive | I26: =IFERROR(__xludf.DUMMYFUNCTION("""COMPUTED_VALUE"""),44579.0) -> 44579 | J26: =IFERROR(__xludf.DUMMYFUNCTION("""COMPUTED_VALUE"""),0.5015856481481481) -> 0.50158565 | N26: =IFERROR(__xludf.DUMMYFUNCTION("""COMPUTED_VALUE"""),1.0) -> 1 | O26: =IFERROR(__xludf.DUMMYFUNCTION("""COMPUTED_VALUE"""),165.0) -> 165 | P26: {=INDEX(postDEL!$A$2:$AR1340,$O26,40)} -> BEND972161 | Q26: {=IF($N26>1, INDEX(postDEL!$A$2:$AR1340,$O26+1,40),IFERROR(0/0,""))} | R26: {=IF($N26>2, INDEX(postDEL!$A$2:$AR1340,$O26+2,40),IFERROR(0/0,""))} | S26: {=IF($N26>3, INDEX(postDEL!$A$2:$AR1340,$O26+3,40),IFERROR(0/0,""))} | U26: FALSE | V26: sep cases | W26: TRUE | X26: TRUE
A27: =IFERROR(__xludf.DUMMYFUNCTION("""COMPUTED_VALUE"""),"MA1092") -> MA1092 | B27: =IFERROR(__xludf.DUMMYFUNCTION("""COMPUTED_VALUE"""),44574.0) -> 44574 | C27: =IFERROR(__xludf.DUMMYFUNCTION("""COMPUTED_VALUE"""),0.6161342592592592) -> 0.61613426 | D27: =IFERROR(__xludf.DUMMYFUNCTION("""COMPUTED_VALUE"""),"SpBEND328905") -> SpBEND328905 | G27: =IFERROR(__xludf.DUMMYFUNCTION("""COMPUTED_VALUE"""),"Positive") -> Positive | H27: =IFERROR(__xludf.DUMMYFUNCTION("""COMPUTED_VALUE"""),"Positive") -> Positive | I27: =IFERROR(__xludf.DUMMYFUNCTION("""COMPUTED_VALUE"""),44579.0) -> 44579 | J27: =IFERROR(__xludf.DUMMYFUNCTION("""COMPUTED_VALUE"""),0.5015856481481481) -> 0.50158565 | N27: =IFERROR(__xludf.DUMMYFUNCTION("""COMPUTED_VALUE"""),1.0) -> 1 | O27: =IFERROR(__xludf.DUMMYFUNCTION("""COMPUTED_VALUE"""),166.0) -> 166 | P27: {=INDEX(postDEL!$A$2:$AR1340,$O27,40)} -> BEND373460 | Q27: {=IF($N27>1, INDEX(postDEL!$A$2:$AR1340,$O27+1,40),IFERROR(0/0,""))} | R27: {=IF($N27>2, INDEX(postDEL!$A$2:$AR1340,$O27+2,40),IFERROR(0/0,""))} | S27: {=IF($N27>3, INDEX(postDEL!$A$2:$AR1340,$O27+3,40),IFERROR(0/0,""))} | U27: FALSE | V27: =IF(COUNTIF($P$2:$P$74,P27)=1,"-",IF(COUNTIF($P$2:P27,P27)=1,"1st",TRUE)) -> - | W27: TRUE | X27: TRUE
A28: =IFERROR(__xludf.DUMMYFUNCTION("""COMPUTED_VALUE"""),"MA1243") -> MA1243 | B28: =IFERROR(__xludf.DUMMYFUNCTION("""COMPUTED_VALUE"""),44575.0) -> 44575 | C28: =IFERROR(__xludf.DUMMYFUNCTION("""COMPUTED_VALUE"""),0.3230439814814815) -> 0.32304398 | D28: =IFERROR(__xludf.DUMMYFUNCTION("""COMPUTED_VALUE"""),"SpBEND767550") -> SpBEND767550 | G28: =IFERROR(__xludf.DUMMYFUNCTION("""COMPUTED_VALUE"""),"Positive") -> Positive | H28: =IFERROR(__xludf.DUMMYFUNCTION("""COMPUTED_VALUE"""),"Positive") -> Positive | I28: =IFERROR(__xludf.DUMMYFUNCTION("""COMPUTED_VALUE"""),44579.0) -> 44579 | J28: =IFERROR(__xludf.DUMMYFUNCTION("""COMPUTED_VALUE"""),0.5015856481481481) -> 0.50158565 | N28: =IFERROR(__xludf.DUMMYFUNCTION("""COMPUTED_VALUE"""),1.0) -> 1 | O28: =IFERROR(__xludf.DUMMYFUNCTION("""COMPUTED_VALUE"""),175.0) -> 175 | P28: {=INDEX(postDEL!$A$2:$AR1340,$O28,40)} -> BEND245933 | Q28: {=IF($N28>1, INDEX(postDEL!$A$2:$AR1340,$O28+1,40),IFERROR(0/0,""))} | R28: {=IF($N28>2, INDEX(postDEL!$A$2:$AR1340,$O28+2,40),IFERROR(0/0,""))} | S28: {=IF($N28>3, INDEX(postDEL!$A$2:$AR1340,$O28+3,40),IFERROR(0/0,""))} | U28: FALSE | V28: =IF(COUNTIF($P$2:$P$74,P28)=1,"-",IF(COUNTIF($P$2:P28,P28)=1,"1st",TRUE)) -> 1st | W28: TRUE | X28: TRUE
A29: =IFERROR(__xludf.DUMMYFUNCTION("""COMPUTED_VALUE"""),"MA1186") -> MA1186 | B29: =IFERROR(__xludf.DUMMYFUNCTION("""COMPUTED_VALUE"""),44575.0) -> 44575 | C29: =IFERROR(__xludf.DUMMYFUNCTION("""COMPUTED_VALUE"""),0.3400578703703704) -> 0.34005787 | D29: =IFERROR(__xludf.DUMMYFUNCTION("""COMPUTED_VALUE"""),"SpBEND302553") -> SpBEND302553 | G29: =IFERROR(__xludf.DUMMYFUNCTION("""COMPUTED_VALUE"""),"Positive") -> Positive | H29: =IFERROR(__xludf.DUMMYFUNCTION("""COMPUTED_VALUE"""),"Positive") -> Positive | I29: =IFERROR(__xludf.DUMMYFUNCTION("""COMPUTED_VALUE"""),44579.0) -> 44579 | J29: =IFERROR(__xludf.DUMMYFUNCTION("""COMPUTED_VALUE"""),0.5015856481481481) -> 0.50158565 | N29: =IFERROR(__xludf.DUMMYFUNCTION("""COMPUTED_VALUE"""),1.0) -> 1 | O29: =IFERROR(__xludf.DUMMYFUNCTION("""COMPUTED_VALUE"""),177.0) -> 177 | P29: {=INDEX(postDEL!$A$2:$AR1340,$O29,40)} -> BEND455768 | Q29: {=IF($N29>1, INDEX(postDEL!$A$2:$AR1340,$O29+1,40),IFERROR(0/0,""))} | R29: {=IF($N29>2, INDEX(postDEL!$A$2:$AR1340,$O29+2,40),IFERROR(0/0,""))} | S29: {=IF($N29>3, INDEX(postDEL!$A$2:$AR1340,$O29+3,40),IFERROR(0/0,""))} | U29: FALSE | V29: =IF(COUNTIF($P$2:$P$74,P29)=1,"-",IF(COUNTIF($P$2:P29,P29)=1,"1st",TRUE)) -> 1st | W29: TRUE | X29: TRUE
A30: =IFERROR(__xludf.DUMMYFUNCTION("""COMPUTED_VALUE"""),"MAX110") -> MAX110 | B30: =IFERROR(__xludf.DUMMYFUNCTION("""COMPUTED_VALUE"""),44575.0) -> 44575 | C30: =IFERROR(__xludf.DUMMYFUNCTION("""COMPUTED_VALUE"""),0.3859722222222222) -> 0.38597222 | D30: =IFERROR(__xludf.DUMMYFUNCTION("""COMPUTED_VALUE"""),"SpBEND394154") -> SpBEND394154 | G30: =IFERROR(__xludf.DUMMYFUNCTION("""COMPUTED_VALUE"""),"Positive") -> Positive | H30: =IFERROR(__xludf.DUMMYFUNCTION("""COMPUTED_VALUE"""),"Positive") -> Positive | I30: =IFERROR(__xludf.DUMMYFUNCTION("""COMPUTED_VALUE"""),44579.0) -> 44579 | J30: =IFERROR(__xludf.DUMMYFUNCTION("""COMPUTED_VALUE"""),0.5015856481481481) -> 0.50158565 | N30: =IFERROR(__xludf.DUMMYFUNCTION("""COMPUTED_VALUE"""),1.0) -> 1 | O30: =IFERROR(__xludf.DUMMYFUNCTION("""COMPUTED_VALUE"""),182.0) -> 182 | P30: {=INDEX(postDEL!$A$2:$AR1340,$O30,40)} -> BEND530620 | Q30: {=IF($N30>1, INDEX(postDEL!$A$2:$AR1340,$O30+1,40),IFERROR(0/0,""))} | R30: {=IF($N30>2, INDEX(postDEL!$A$2:$AR1340,$O30+2,40),IFERROR(0/0,""))} | S30: {=IF($N30>3, INDEX(postDEL!$A$2:$AR1340,$O30+3,40),IFERROR(0/0,""))} | U30: FALSE | V30: =IF(COUNTIF($P$2:$P$74,P30)=1,"-",IF(COUNTIF($P$2:P30,P30)=1,"1st",TRUE)) -> TRUE | W30: TRUE | X30: TRUE
A31: =IFERROR(__xludf.DUMMYFUNCTION("""COMPUTED_VALUE"""),"MA1058") -> MA1058 | B31: =IFERROR(__xludf.DUMMYFUNCTION("""COMPUTED_VALUE"""),44575.0) -> 44575 | C31: =IFERROR(__xludf.DUMMYFUNCTION("""COMPUTED_VALUE"""),0.38623842592592594) -> 0.38623843 | D31: =IFERROR(__xludf.DUMMYFUNCTION("""COMPUTED_VALUE"""),"SpBEND394154") -> SpBEND394154 | G31: =IFERROR(__xludf.DUMMYFUNCTION("""COMPUTED_VALUE"""),"Positive") -> Positive | H31: =IFERROR(__xludf.DUMMYFUNCTION("""COMPUTED_VALUE"""),"Positive") -> Positive | I31: =IFERROR(__xludf.DUMMYFUNCTION("""COMPUTED_VALUE"""),44579.0) -> 44579 | J31: =IFERROR(__xludf.DUMMYFUNCTION("""COMPUTED_VALUE"""),0.5015856481481481) -> 0.50158565 | L31: =IFERROR(__xludf.DUMMYFUNCTION("""COMPUTED_VALUE"""),"RT Jan26 nothing else seems off so conclude it's 2 swabs from the same person. OLD NOTE: review - same person, positive twice on same day") -> RT Jan26 nothing else seems off so conclude it's 2 swabs from the same person. OLD NOTE: review - same person, positive twice on same day | N31: =IFERROR(__xludf.DUMMYFUNCTION("""COMPUTED_VALUE"""),1.0) -> 1 | O31: =IFERROR(__xludf.DUMMYFUNCTION("""COMPUTED_VALUE"""),183.0) -> 183 | P31: {=INDEX(postDEL!$A$2:$AR1340,$O31,40)} -> BEND219153 | Q31: {=IF($N31>1, INDEX(postDEL!$A$2:$AR1340,$O31+1,40),IFERROR(0/0,""))} | R31: {=IF($N31>2, INDEX(postDEL!$A$2:$AR1340,$O31+2,40),IFERROR(0/0,""))} | S31: {=IF($N31>3, INDEX(postDEL!$A$2:$AR1340,$O31+3,40),IFERROR(0/0,""))} | U31: FALSE | V31: =IF(COUNTIF($P$2:$P$74,P31)=1,"-",IF(COUNTIF($P$2:P31,P31)=1,"1st",TRUE)) -> TRUE | W31: TRUE | X31: TRUE
