Workbook

Sheet ALL Tube Results
A1: =IFERROR(__xludf.DUMMYFUNCTION("QUERY({ 'APS Tubes Import'!A1:A100; 'ARF Tubes'!M2:M100 }, ""SELECT Col1 WHERE Col1 IS NOT NULL"", 0)"),"TUBE ID") -> TUBE ID | B1: =IFERROR(__xludf.DUMMYFUNCTION("QUERY({ 'APS Tubes Import'!V1:V100; 'ARF Tubes'!N2:N100 }, ""SELECT Col1 WHERE Col1 IS NOT NULL"", 0)"),"FINAL ASSIGNED RUN ID") -> FINAL ASSIGNED RUN ID | C1: ='Run Reconcile'!B1 -> RUN DATE | D1: ='APS Tubes Import'!B1 -> COLLECTION DATE | E1: ='APS Tubes Import'!C1 -> COLLECTION TIME | F1: =IFERROR(__xludf.DUMMYFUNCTION("QUERY({ 'APS Tubes Import'!H1:H100; 'ARF Tubes'!P2:P100 }, ""SELECT Col1 WHERE Col1 IS NOT NULL"", 0)"),"FINAL RESULT") -> FINAL RESULT | G1: ='APS Tubes Import'!N1 -> NUM SAMPLES (Pool Level)
A2: =IFERROR(__xludf.DUMMYFUNCTION("""COMPUTED_VALUE"""),"AG575") -> AG575 | B2: =IFERROR(__xludf.DUMMYFUNCTION("""COMPUTED_VALUE"""),"RUN-NDHM_2022-05-02_RFR-006") -> RUN-NDHM_2022-05-02_RFR-006 | C2: =VLOOKUP(B2,'Run Reconcile'!A$2:B100,2,FALSE) -> 44683 | D2: =IFERROR(__xludf.DUMMYFUNCTION("QUERY({ 'APS Tubes Import'!B2:B100 }, ""SELECT Col1 WHERE Col1 IS NOT NULL"", 0)"),44683.0) -> 44683 | E2: =IFERROR(__xludf.DUMMYFUNCTION("QUERY({ 'APS Tubes Import'!C2:C100; 'ARF Tubes'!P2:P100 }, ""SELECT Col1 WHERE Col1 IS NOT NULL"", 0)"),0.17497685185298906) -> 0.17497685 | F2: =IFERROR(__xludf.DUMMYFUNCTION("""COMPUTED_VALUE"""),"Negative") -> Negative | G2: =IFERROR(__xludf.DUMMYFUNCTION("QUERY({ 'APS Tubes Import'!N2:N100 }, ""SELECT Col1 WHERE Col1 IS NOT NULL"", 0)"),4.0) -> 4
A3: =IFERROR(__xludf.DUMMYFUNCTION("""COMPUTED_VALUE"""),"AK7133") -> AK7133 | B3: =IFERROR(__xludf.DUMMYFUNCTION("""COMPUTED_VALUE"""),"RUN-NDHM_2022-05-02_RFR-006") -> RUN-NDHM_2022-05-02_RFR-006 | C3: =VLOOKUP(B3,'Run Reconcile'!A$2:B100,2,FALSE) -> 44683 | D3: =IFERROR(__xludf.DUMMYFUNCTION("""COMPUTED_VALUE"""),44683.0) -> 44683 | E3: =IFERROR(__xludf.DUMMYFUNCTION("""COMPUTED_VALUE"""),0.17721064814759302) -> 0.17721065 | F3: =IFERROR(__xludf.DUMMYFUNCTION("""COMPUTED_VALUE"""),"Negative") -> Negative | G3: =IFERROR(__xludf.DUMMYFUNCTION("""COMPUTED_VALUE"""),2.0) -> 2
A4: =IFERROR(__xludf.DUMMYFUNCTION("""COMPUTED_VALUE"""),"AG91") -> AG91 | B4: =IFERROR(__xludf.DUMMYFUNCTION("""COMPUTED_VALUE"""),"RUN-NDHM_2022-05-02_RFR-006") -> RUN-NDHM_2022-05-02_RFR-006 | C4: =VLOOKUP(B4,'Run Reconcile'!A$2:B100,2,FALSE) -> 44683 | D4: =IFERROR(__xludf.DUMMYFUNCTION("""COMPUTED_VALUE"""),44683.0) -> 44683 | E4: =IFERROR(__xludf.DUMMYFUNCTION("""COMPUTED_VALUE"""),0.17770833333270275) -> 0.17770833 | F4: =IFERROR(__xludf.DUMMYFUNCTION("""COMPUTED_VALUE"""),"Negative") -> Negative | G4: =IFERROR(__xludf.DUMMYFUNCTION("""COMPUTED_VALUE"""),2.0) -> 2
A5: =IFERROR(__xludf.DUMMYFUNCTION("""COMPUTED_VALUE"""),"AG1419") -> AG1419 | B5: =IFERROR(__xludf.DUMMYFUNCTION("""COMPUTED_VALUE"""),"RUN-NDHM_2022-05-02_RFR-006") -> RUN-NDHM_2022-05-02_RFR-006 | C5: =VLOOKUP(B5,'Run Reconcile'!A$2:B100,2,FALSE) -> 44683 | D5: =IFERROR(__xludf.DUMMYFUNCTION("""COMPUTED_VALUE"""),44683.0) -> 44683 | E5: =IFERROR(__xludf.DUMMYFUNCTION("""COMPUTED_VALUE"""),0.17806712962919846) -> 0.17806713 | F5: =IFERROR(__xludf.DUMMYFUNCTION("""COMPUTED_VALUE"""),"Negative") -> Negative | G5: =IFERROR(__xludf.DUMMYFUNCTION("""COMPUTED_VALUE"""),2.0) -> 2
A6: =IFERROR(__xludf.DUMMYFUNCTION("""COMPUTED_VALUE"""),"AH7292") -> AH7292 | B6: =IFERROR(__xludf.DUMMYFUNCTION("""COMPUTED_VALUE"""),"RUN-NDHM_2022-05-02_RFR-006") -> RUN-NDHM_2022-05-02_RFR-006 | C6: =VLOOKUP(B6,'Run Reconcile'!A$2:B100,2,FALSE) -> 44683 | D6: =IFERROR(__xludf.DUMMYFUNCTION("""COMPUTED_VALUE"""),44683.0) -> 44683 | E6: =IFERROR(__xludf.DUMMYFUNCTION("""COMPUTED_VALUE"""),0.17832175926014315) -> 0.17832176 | F6: =IFERROR(__xludf.DUMMYFUNCTION("""COMPUTED_VALUE"""),"Negative") -> Negative | G6: =IFERROR(__xludf.DUMMYFUNCTION("""COMPUTED_VALUE"""),1.0) -> 1
A7: =IFERROR(__xludf.DUMMYFUNCTION("""COMPUTED_VALUE"""),"AH7299") -> AH7299 | B7: =IFERROR(__xludf.DUMMYFUNCTION("""COMPUTED_VALUE"""),"RUN-NDHM_2022-05-02_RFR-006") -> RUN-NDHM_2022-05-02_RFR-006 | C7: =VLOOKUP(B7,'Run Reconcile'!A$2:B100,2,FALSE) -> 44683 | D7: =IFERROR(__xludf.DUMMYFUNCTION("""COMPUTED_VALUE"""),44683.0) -> 44683 | E7: =IFERROR(__xludf.DUMMYFUNCTION("""COMPUTED_VALUE"""),0.1799421296309447) -> 0.17994213 | F7: =IFERROR(__xludf.DUMMYFUNCTION("""COMPUTED_VALUE"""),"Negative") -> Negative | G7: =IFERROR(__xludf.DUMMYFUNCTION("""COMPUTED_VALUE"""),2.0) -> 2
A8: =IFERROR(__xludf.DUMMYFUNCTION("""COMPUTED_VALUE"""),"AJ9453") -> AJ9453 | B8: =IFERROR(__xludf.DUMMYFUNCTION("""COMPUTED_VALUE"""),"RUN-NDHM_2022-05-02_RFR-006") -> RUN-NDHM_2022-05-02_RFR-006 | C8: =VLOOKUP(B8,'Run Reconcile'!A$2:B100,2,FALSE) -> 44683 | D8: =IFERROR(__xludf.DUMMYFUNCTION("""COMPUTED_VALUE"""),44683.0) -> 44683 | E8: =IFERROR(__xludf.DUMMYFUNCTION("""COMPUTED_VALUE"""),0.19702546296321088) -> 0.19702546 | F8: =IFERROR(__xludf.DUMMYFUNCTION("""COMPUTED_VALUE"""),"Negative") -> Negative | G8: =IFERROR(__xludf.DUMMYFUNCTION("""COMPUTED_VALUE"""),4.0) -> 4
A9: =IFERROR(__xludf.DUMMYFUNCTION("""COMPUTED_VALUE"""),"AJ8392") -> AJ8392 | B9: =IFERROR(__xludf.DUMMYFUNCTION("""COMPUTED_VALUE"""),"RUN-NDHM_2022-05-02_RFR-006") -> RUN-NDHM_2022-05-02_RFR-006 | C9: =VLOOKUP(B9,'Run Reconcile'!A$2:B100,2,FALSE) -> 44683 | D9: =IFERROR(__xludf.DUMMYFUNCTION("""COMPUTED_VALUE"""),44683.0) -> 44683 | E9: =IFERROR(__xludf.DUMMYFUNCTION("""COMPUTED_VALUE"""),0.20218749999912689) -> 0.2021875 | F9: =IFERROR(__xludf.DUMMYFUNCTION("""COMPUTED_VALUE"""),"Negative") -> Negative | G9: =IFERROR(__xludf.DUMMYFUNCTION("""COMPUTED_VALUE"""),2.0) -> 2
A10: =IFERROR(__xludf.DUMMYFUNCTION("""COMPUTED_VALUE"""),"AJ9417") -> AJ9417 | B10: =IFERROR(__xludf.DUMMYFUNCTION("""COMPUTED_VALUE"""),"RUN-NDHM_2022-05-02_RFR-006") -> RUN-NDHM_2022-05-02_RFR-006 | C10: =VLOOKUP(B10,'Run Reconcile'!A$2:B100,2,FALSE) -> 44683 | D10: =IFERROR(__xludf.DUMMYFUNCTION("""COMPUTED_VALUE"""),44683.0) -> 44683 | E10: =IFERROR(__xludf.DUMMYFUNCTION("""COMPUTED_VALUE"""),0.20903935185197042) -> 0.20903935 | F10: =IFERROR(__xludf.DUMMYFUNCTION("""COMPUTED_VALUE"""),"Negative") -> Negative | G10: =IFERROR(__xludf.DUMMYFUNCTION("""COMPUTED_VALUE"""),4.0) -> 4
A11: =IFERROR(__xludf.DUMMYFUNCTION("""COMPUTED_VALUE"""),"AG1713") -> AG1713 | B11: =IFERROR(__xludf.DUMMYFUNCTION("""COMPUTED_VALUE"""),"RUN-NDHM_2022-05-02_RFR-006") -> RUN-NDHM_2022-05-02_RFR-006 | C11: =VLOOKUP(B11,'Run Reconcile'!A$2:B100,2,FALSE) -> 44683 | D11: =IFERROR(__xludf.DUMMYFUNCTION("""COMPUTED_VALUE"""),44683.0) -> 44683 | E11: =IFERROR(__xludf.DUMMYFUNCTION("""COMPUTED_VALUE"""),0.2125694444439432) -> 0.21256944 | F11: =IFERROR(__xludf.DUMMYFUNCTION("""COMPUTED_VALUE"""),"Negative") -> Negative | G11: =IFERROR(__xludf.DUMMYFUNCTION("""COMPUTED_VALUE"""),4.0) -> 4
A12: =IFERROR(__xludf.DUMMYFUNCTION("""COMPUTED_VALUE"""),"AJ9703") -> AJ9703 | B12: =IFERROR(__xludf.DUMMYFUNCTION("""COMPUTED_VALUE"""),"RUN-NDHM_2022-05-02_RFR-006") -> RUN-NDHM_2022-05-02_RFR-006 | C12: =VLOOKUP(B12,'Run Reconcile'!A$2:B100,2,FALSE) -> 44683 | D12: =IFERROR(__xludf.DUMMYFUNCTION("""COMPUTED_VALUE"""),44683.0) -> 44683 | E12: =IFERROR(__xludf.DUMMYFUNCTION("""COMPUTED_VALUE"""),0.23635416666729725) -> 0.23635417 | F12: =IFERROR(__xludf.DUMMYFUNCTION("""COMPUTED_VALUE"""),"Negative") -> Negative | G12: =IFERROR(__xludf.DUMMYFUNCTION("""COMPUTED_VALUE"""),1.0) -> 1
A13: =IFERROR(__xludf.DUMMYFUNCTION("""COMPUTED_VALUE"""),"AG213") -> AG213 | B13: =IFERROR(__xludf.DUMMYFUNCTION("""COMPUTED_VALUE"""),"RUN-NDHM_2022-05-02_RFR-006") -> RUN-NDHM_2022-05-02_RFR-006 | C13: =VLOOKUP(B13,'Run Reconcile'!A$2:B100,2,FALSE) -> 44683 | D13: =IFERROR(__xludf.DUMMYFUNCTION("""COMPUTED_VALUE"""),44683.0) -> 44683 | E13: =IFERROR(__xludf.DUMMYFUNCTION("""COMPUTED_VALUE"""),0.2382638888884685) -> 0.23826389 | F13: =IFERROR(__xludf.DUMMYFUNCTION("""COMPUTED_VALUE"""),"Negative") -> Negative | G13: =IFERROR(__xludf.DUMMYFUNCTION("""COMPUTED_VALUE"""),1.0) -> 1
A14: =IFERROR(__xludf.DUMMYFUNCTION("""COMPUTED_VALUE"""),"AG252") -> AG252 | B14: =IFERROR(__xludf.DUMMYFUNCTION("""COMPUTED_VALUE"""),"RUN-NDHM_2022-05-02_RFR-006") -> RUN-NDHM_2022-05-02_RFR-006 | C14: =VLOOKUP(B14,'Run Reconcile'!A$2:B100,2,FALSE) -> 44683 | D14: =IFERROR(__xludf.DUMMYFUNCTION("""COMPUTED_VALUE"""),44683.0) -> 44683 | E14: =IFERROR(__xludf.DUMMYFUNCTION("""COMPUTED_VALUE"""),0.23990740740919136) -> 0.23990741 | F14: =IFERROR(__xludf.DUMMYFUNCTION("""COMPUTED_VALUE"""),"Negative") -> Negative | G14: =IFERROR(__xludf.DUMMYFUNCTION("""COMPUTED_VALUE"""),1.0) -> 1
A15: =IFERROR(__xludf.DUMMYFUNCTION("""COMPUTED_VALUE"""),"AG2164") -> AG2164 | B15: =IFERROR(__xludf.DUMMYFUNCTION("""COMPUTED_VALUE"""),"RUN-NDHM_2022-05-02_RFR-006") -> RUN-NDHM_2022-05-02_RFR-006 | C15: =VLOOKUP(B15,'Run Reconcile'!A$2:B100,2,FALSE) -> 44683 | D15: =IFERROR(__xludf.DUMMYFUNCTION("""COMPUTED_VALUE"""),44683.0) -> 44683 | E15: =IFERROR(__xludf.DUMMYFUNCTION("""COMPUTED_VALUE"""),0.2581712962964957) -> 0.2581713 | F15: =IFERROR(__xludf.DUMMYFUNCTION("""COMPUTED_VALUE"""),"Negative") -> Negative | G15: =IFERROR(__xludf.DUMMYFUNCTION("""COMPUTED_VALUE"""),1.0) -> 1
A16: =IFERROR(__xludf.DUMMYFUNCTION("""COMPUTED_VALUE"""),"AK7529") -> AK7529 | B16: =IFERROR(__xludf.DUMMYFUNCTION("""COMPUTED_VALUE"""),"RUN-NDHM_2022-05-02_RFR-006") -> RUN-NDHM_2022-05-02_RFR-006 | C16: =VLOOKUP(B16,'Run Reconcile'!A$2:B100,2,FALSE) -> 44683 | D16: =IFERROR(__xludf.DUMMYFUNCTION("""COMPUTED_VALUE"""),44683.0) -> 44683 | E16: =IFERROR(__xludf.DUMMYFUNCTION("""COMPUTED_VALUE"""),0.2757638888906513) -> 0.27576389 | F16: =IFERROR(__xludf.DUMMYFUNCTION("""COMPUTED_VALUE"""),"Negative") -> Negative | G16: =IFERROR(__xludf.DUMMYFUNCTION("""COMPUTED_VALUE"""),1.0) -> 1
A17: =IFERROR(__xludf.DUMMYFUNCTION("""COMPUTED_VALUE"""),"AH9504") -> AH9504 | B17: =IFERROR(__xludf.DUMMYFUNCTION("""COMPUTED_VALUE"""),"RUN-NDHM_2022-05-02_RFR-006") -> RUN-NDHM_2022-05-02_RFR-006 | C17: =VLOOKUP(B17,'Run Reconcile'!A$2:B100,2,FALSE) -> 44683 | D17: =IFERROR(__xludf.DUMMYFUNCTION("""COMPUTED_VALUE"""),44683.0) -> 44683 | E17: =IFERROR(__xludf.DUMMYFUNCTION("""COMPUTED_VALUE"""),0.27810185185080627) -> 0.27810185 | F17: =IFERROR(__xludf.DUMMYFUNCTION("""COMPUTED_VALUE"""),"Negative") -> Negative | G17: =IFERROR(__xludf.DUMMYFUNCTION("""COMPUTED_VALUE"""),1.0) -> 1
A18: =IFERROR(__xludf.DUMMYFUNCTION("""COMPUTED_VALUE"""),"AG1866") -> AG1866 | B18: =IFERROR(__xludf.DUMMYFUNCTION("""COMPUTED_VALUE"""),"RUN-NDHM_2022-05-02_RFR-006") -> RUN-NDHM_2022-05-02_RFR-006 | C18: =VLOOKUP(B18,'Run Reconcile'!A$2:B100,2,FALSE) -> 44683 | D18: =IFERROR(__xludf.DUMMYFUNCTION("""COMPUTED_VALUE"""),44683.0) -> 44683 | E18: =IFERROR(__xludf.DUMMYFUNCTION("""COMPUTED_VALUE"""),0.3842013888897782) -> 0.38420139 | F18: =IFERROR(__xludf.DUMMYFUNCTION("""COMPUTED_VALUE"""),"Negative") -> Negative | G18: =IFERROR(__xludf.DUMMYFUNCTION("""COMPUTED_VALUE"""),1.0) -> 1
A19: =IFERROR(__xludf.DUMMYFUNCTION("""COMPUTED_VALUE"""),"AK5211") -> AK5211 | B19: =IFERROR(__xludf.DUMMYFUNCTION("""COMPUTED_VALUE"""),"RUN-NDHM_2022-05-09_RFR-009") -> RUN-NDHM_2022-05-09_RFR-009 | C19: =VLOOKUP(B19,'Run Reconcile'!A$2:B100,2,FALSE) -> 44690 | D19: =IFERROR(__xludf.DUMMYFUNCTION("""COMPUTED_VALUE"""),44689.0) -> 44689 | E19: =IFERROR(__xludf.DUMMYFUNCTION("""COMPUTED_VALUE"""),0.8260300925940101) -> 0.82603009 | F19: =IFERROR(__xludf.DUMMYFUNCTION("""COMPUTED_VALUE"""),"Negative") -> Negative | G19: =IFERROR(__xludf.DUMMYFUNCTION("""COMPUTED_VALUE"""),4.0) -> 4
A20: =IFERROR(__xludf.DUMMYFUNCTION("""COMPUTED_VALUE"""),"AG469") -> AG469 | B20: =IFERROR(__xludf.DUMMYFUNCTION("""COMPUTED_VALUE"""),"RUN-NDHM_2022-05-09_RFR-009") -> RUN-NDHM_2022-05-09_RFR-009 | C20: =VLOOKUP(B20,'Run Reconcile'!A$2:B100,2,FALSE) -> 44690 | D20: =IFERROR(__xludf.DUMMYFUNCTION("""COMPUTED_VALUE"""),44690.0) -> 44690 | E20: =IFERROR(__xludf.DUMMYFUNCTION("""COMPUTED_VALUE"""),0.1700231481481751) -> 0.17002315 | F20: =IFERROR(__xludf.DUMMYFUNCTION("""COMPUTED_VALUE"""),"Negative") -> Negative | G20: =IFERROR(__xludf.DUMMYFUNCTION("""COMPUTED_VALUE"""),4.0) -> 4
A21: =IFERROR(__xludf.DUMMYFUNCTION("""COMPUTED_VALUE"""),"AH7931") -> AH7931 | B21: =IFERROR(__xludf.DUMMYFUNCTION("""COMPUTED_VALUE"""),"RUN-NDHM_2022-05-09_RFR-009") -> RUN-NDHM_2022-05-09_RFR-009 | C21: =VLOOKUP(B21,'Run Reconcile'!A$2:B100,2,FALSE) -> 44690 | D21: =IFERROR(__xludf.DUMMYFUNCTION("""COMPUTED_VALUE"""),44690.0) -> 44690 | E21: =IFERROR(__xludf.DUMMYFUNCTION("""COMPUTED_VALUE"""),0.1787037037029222) -> 0.1787037 | F21: =IFERROR(__xludf.DUMMYFUNCTION("""COMPUTED_VALUE"""),"Negative") -> Negative | G21: =IFERROR(__xludf.DUMMYFUNCTION("""COMPUTED_VALUE"""),3.0) -> 3
A22: =IFERROR(__xludf.DUMMYFUNCTION("""COMPUTED_VALUE"""),"AH1039") -> AH1039 | B22: =IFERROR(__xludf.DUMMYFUNCTION("""COMPUTED_VALUE"""),"RUN-NDHM_2022-05-09_RFR-009") -> RUN-NDHM_2022-05-09_RFR-009 | C22: =VLOOKUP(B22,'Run Reconcile'!A$2:B100,2,FALSE) -> 44690 | D22: =IFERROR(__xludf.DUMMYFUNCTION("""COMPUTED_VALUE"""),44690.0) -> 44690 | E22: =IFERROR(__xludf.DUMMYFUNCTION("""COMPUTED_VALUE"""),0.2029050925921183) -> 0.20290509 | F22: =IFERROR(__xludf.DUMMYFUNCTION("""COMPUTED_VALUE"""),"Negative") -> Negative | G22: =IFERROR(__xludf.DUMMYFUNCTION("""COMPUTED_VALUE"""),3.0) -> 3
A23: =IFERROR(__xludf.DUMMYFUNCTION("""COMPUTED_VALUE"""),"AJ8556") -> AJ8556 | B23: =IFERROR(__xludf.DUMMYFUNCTION("""COMPUTED_VALUE"""),"RUN-NDHM_2022-05-09_RFR-009") -> RUN-NDHM_2022-05-09_RFR-009 | C23: =VLOOKUP(B23,'Run Reconcile'!A$2:B100,2,FALSE) -> 44690 | D23: =IFERROR(__xludf.DUMMYFUNCTION("""COMPUTED_VALUE"""),44690.0) -> 44690 | E23: =IFERROR(__xludf.DUMMYFUNCTION("""COMPUTED_VALUE"""),0.21353009259109967) -> 0.21353009 | F23: =IFERROR(__xludf.DUMMYFUNCTION("""COMPUTED_VALUE"""),"Negative") -> Negative | G23: =IFERROR(__xludf.DUMMYFUNCTION("""COMPUTED_VALUE"""),4.0) -> 4
A24: =IFERROR(__xludf.DUMMYFUNCTION("""COMPUTED_VALUE"""),"AG815") -> AG815 | B24: =IFERROR(__xludf.DUMMYFUNCTION("""COMPUTED_VALUE"""),"RUN-NDHM_2022-05-09_RFR-009") -> RUN-NDHM_2022-05-09_RFR-009 | C24: =VLOOKUP(B24,'Run Reconcile'!A$2:B100,2,FALSE) -> 44690 | D24: =IFERROR(__xludf.DUMMYFUNCTION("""COMPUTED_VALUE"""),44690.0) -> 44690 | E24: =IFERROR(__xludf.DUMMYFUNCTION("""COMPUTED_VALUE"""),0.24370370370525052) -> 0.2437037 | F24: =IFERROR(__xludf.DUMMYFUNCTION("""COMPUTED_VALUE"""),"Negative") -> Negative | G24: =IFERROR(__xludf.DUMMYFUNCTION("""COMPUTED_VALUE"""),1.0) -> 1
A25: =IFERROR(__xludf.DUMMYFUNCTION("""COMPUTED_VALUE"""),"AG1523") -> AG1523 | B25: =IFERROR(__xludf.DUMMYFUNCTION("""COMPUTED_VALUE"""),"RUN-NDHM_2022-05-09_RFR-009") -> RUN-NDHM_2022-05-09_RFR-009 | C25: =VLOOKUP(B25,'Run Reconcile'!A$2:B100,2,FALSE) -> 44690 | D25: =IFERROR(__xludf.DUMMYFUNCTION("""COMPUTED_VALUE"""),44690.0) -> 44690 | E25: =IFERROR(__xludf.DUMMYFUNCTION("""COMPUTED_VALUE"""),0.27951388889050577) -> 0.27951389 | F25: =IFERROR(__xludf.DUMMYFUNCTION("""COMPUTED_VALUE"""),"Negative") -> Negative | G25: =IFERROR(__xludf.DUMMYFUNCTION("""COMPUTED_VALUE"""),1.0) -> 1
A26: =IFERROR(__xludf.DUMMYFUNCTION("""COMPUTED_VALUE"""),"AH266") -> AH266 | B26: =IFERROR(__xludf.DUMMYFUNCTION("""COMPUTED_VALUE"""),"RUN-NDHM_2022-05-09_RFR-009") -> RUN-NDHM_2022-05-09_RFR-009 | C26: =VLOOKUP(B26,'Run Reconcile'!A$2:B100,2,FALSE) -> 44690 | D26: =IFERROR(__xludf.DUMMYFUNCTION("""COMPUTED_VALUE"""),44690.0) -> 44690 | E26: =IFERROR(__xludf.DUMMYFUNCTION("""COMPUTED_VALUE"""),0.2801620370373712) -> 0.28016204 | F26: =IFERROR(__xludf.DUMMYFUNCTION("""COMPUTED_VALUE"""),"Negative") -> Negative | G26: =IFERROR(__xludf.DUMMYFUNCTION("""COMPUTED_VALUE"""),2.0) -> 2
A27: =IFERROR(__xludf.DUMMYFUNCTION("""COMPUTED_VALUE"""),"AJ8574") -> AJ8574 | B27: =IFERROR(__xludf.DUMMYFUNCTION("""COMPUTED_VALUE"""),"RUN-NDHM_2022-05-16_RFR-010") -> RUN-NDHM_2022-05-16_RFR-010 | C27: =VLOOKUP(B27,'Run Reconcile'!A$2:B100,2,FALSE) -> 44697 | D27: =IFERROR(__xludf.DUMMYFUNCTION("""COMPUTED_VALUE"""),44696.0) -> 44696 | E27: =IFERROR(__xludf.DUMMYFUNCTION("""COMPUTED_VALUE"""),0.7482523148137261) -> 0.74825231 | F27: =IFERROR(__xludf.DUMMYFUNCTION("""COMPUTED_VALUE"""),"Negative") -> Negative | G27: =IFERROR(__xludf.DUMMYFUNCTION("""COMPUTED_VALUE"""),2.0) -> 2
A28: =IFERROR(__xludf.DUMMYFUNCTION("""COMPUTED_VALUE"""),"AH7225") -> AH7225 | B28: =IFERROR(__xludf.DUMMYFUNCTION("""COMPUTED_VALUE"""),"RUN-NDHM_2022-05-16_RFR-010") -> RUN-NDHM_2022-05-16_RFR-010 | C28: =VLOOKUP(B28,'Run Reconcile'!A$2:B100,2,FALSE) -> 44697 | D28: =IFERROR(__xludf.DUMMYFUNCTION("""COMPUTED_VALUE"""),44697.0) -> 44697 | E28: =IFERROR(__xludf.DUMMYFUNCTION("""COMPUTED_VALUE"""),0.15361111111269565) -> 0.15361111 | F28: =IFERROR(__xludf.DUMMYFUNCTION("""COMPUTED_VALUE"""),"Negative") -> Negative | G28: =IFERROR(__xludf.DUMMYFUNCTION("""COMPUTED_VALUE"""),2.0) -> 2
A29: =IFERROR(__xludf.DUMMYFUNCTION("""COMPUTED_VALUE"""),"AG1637") -> AG1637 | B29: =IFERROR(__xludf.DUMMYFUNCTION("""COMPUTED_VALUE"""),"RUN-NDHM_2022-05-16_RFR-010") -> RUN-NDHM_2022-05-16_RFR-010 | C29: =VLOOKUP(B29,'Run Reconcile'!A$2:B100,2,FALSE) -> 44697 | D29: =IFERROR(__xludf.DUMMYFUNCTION("""COMPUTED_VALUE"""),44697.0) -> 44697 | E29: =IFERROR(__xludf.DUMMYFUNCTION("""COMPUTED_VALUE"""),0.17675925925868796) -> 0.17675926 | F29: =IFERROR(__xludf.DUMMYFUNCTION("""COMPUTED_VALUE"""),"Negative") -> Negative | G29: =IFERROR(__xludf.DUMMYFUNCTION("""COMPUTED_VALUE"""),4.0) -> 4
A30: =IFERROR(__xludf.DUMMYFUNCTION("""COMPUTED_VALUE"""),"AG1103") -> AG1103 | B30: =IFERROR(__xludf.DUMMYFUNCTION("""COMPUTED_VALUE"""),"RUN-NDHM_2022-05-16_RFR-010") -> RUN-NDHM_2022-05-16_RFR-010 | C30: =VLOOKUP(B30,'Run Reconcile'!A$2:B100,2,FALSE) -> 44697 | D30: =IFERROR(__xludf.DUMMYFUNCTION("""COMPUTED_VALUE"""),44697.0) -> 44697 | E30: =IFERROR(__xludf.DUMMYFUNCTION("""COMPUTED_VALUE"""),0.1903009259258397) -> 0.19030093 | F30: =IFERROR(__xludf.DUMMYFUNCTION("""COMPUTED_VALUE"""),"Negative") -> Negative | G30: =IFERROR(__xludf.DUMMYFUNCTION("""COMPUTED_VALUE"""),4.0) -> 4
A31: =IFERROR(__xludf.DUMMYFUNCTION("""COMPUTED_VALUE"""),"AJ7985") -> AJ7985 | B31: =IFERROR(__xludf.DUMMYFUNCTION("""COMPUTED_VALUE"""),"RUN-NDHM_2022-05-16_RFR-010") -> RUN-NDHM_2022-05-16_RFR-010 | C31: =VLOOKUP(B31,'Run Reconcile'!A$2:B100,2,FALSE) -> 44697 | D31: =IFERROR(__xludf.DUMMYFUNCTION("""COMPUTED_VALUE"""),44697.0) -> 44697 | E31: =IFERROR(__xludf.DUMMYFUNCTION("""COMPUTED_VALUE"""),0.2023611111108039) -> 0.20236111 | F31: =IFERROR(__xludf.DUMMYFUNCTION("""COMPUTED_VALUE"""),"Negative") -> Negative | G31: =IFERROR(__xludf.DUMMYFUNCTION("""COMPUTED_VALUE"""),3.0) -> 3
A32: =IFERROR(__xludf.DUMMYFUNCTION("""COMPUTED_VALUE"""),"AH9668") -> AH9668 | B32: =IFERROR(__xludf.DUMMYFUNCTION("""COMPUTED_VALUE"""),"RUN-NDHM_2022-05-16_RFR-010") -> RUN-NDHM_2022-05-16_RFR-010 | C32: =VLOOKUP(B32,'Run Reconcile'!A$2:B100,2,FALSE) -> 44697 | D32: =IFERROR(__xludf.DUMMYFUNCTION("""COMPUTED_VALUE"""),44697.0) -> 44697 | E32: =IFERROR(__xludf.DUMMYFUNCTION("""COMPUTED_VALUE"""),0.20684027777679148) -> 0.20684028 | F32: =IFERROR(__xludf.DUMMYFUNCTION("""COMPUTED_VALUE"""),"Negative") -> Negative | G32: =IFERROR(__xludf.DUMMYFUNCTION("""COMPUTED_VALUE"""),2.0) -> 2
A33: =IFERROR(__xludf.DUMMYFUNCTION("""COMPUTED_VALUE"""),"AJ8977") -> AJ8977 | B33: =IFERROR(__xludf.DUMMYFUNCTION("""COMPUTED_VALUE"""),"RUN-NDHM_2022-05-16_RFR-010") -> RUN-NDHM_2022-05-16_RFR-010 | C33: =VLOOKUP(B33,'Run Reconcile'!A$2:B100,2,FALSE) -> 44697 | D33: =IFERROR(__xludf.DUMMYFUNCTION("""COMPUTED_VALUE"""),44697.0) -> 44697 | E33: =IFERROR(__xludf.DUMMYFUNCTION("""COMPUTED_VALUE"""),0.20903935185197042) -> 0.20903935 | F33: =IFERROR(__xludf.DUMMYFUNCTION("""COMPUTED_VALUE"""),"Negative") -> Negative | G33: =IFERROR(__xludf.DUMMYFUNCTION("""COMPUTED_VALUE"""),4.0) -> 4
A34: =IFERROR(__xludf.DUMMYFUNCTION("""COMPUTED_VALUE"""),"AG570") -> AG570 | B34: =IFERROR(__xludf.DUMMYFUNCTION("""COMPUTED_VALUE"""),"RUN-NDHM_2022-05-16_RFR-010") -> RUN-NDHM_2022-05-16_RFR-010 | C34: =VLOOKUP(B34,'Run Reconcile'!A$2:B100,2,FALSE) -> 44697 | D34: =IFERROR(__xludf.DUMMYFUNCTION("""COMPUTED_VALUE"""),44697.0) -> 44697 | E34: =IFERROR(__xludf.DUMMYFUNCTION("""COMPUTED_VALUE"""),0.2689351851840911) -> 0.26893519 | F34: =IFERROR(__xludf.DUMMYFUNCTION("""COMPUTED_VALUE"""),"Negative") -> Negative | G34: =IFERROR(__xludf.DUMMYFUNCTION("""COMPUTED_VALUE"""),1.0) -> 1
A35: =IFERROR(__xludf.DUMMYFUNCTION("""COMPUTED_VALUE"""),"AH63") -> AH63 | B35: =IFERROR(__xludf.DUMMYFUNCTION("""COMPUTED_VALUE"""),"RUN-NDHM_2022-05-16_RFR-010") -> RUN-NDHM_2022-05-16_RFR-010 | C35: =VLOOKUP(B35,'Run Reconcile'!A$2:B100,2,FALSE) -> 44697 | D35: =IFERROR(__xludf.DUMMYFUNCTION("""COMPUTED_VALUE"""),44697.0) -> 44697 | E35: =IFERROR(__xludf.DUMMYFUNCTION("""COMPUTED_VALUE"""),0.3187152777791198) -> 0.31871528 | F35: =IFERROR(__xludf.DUMMYFUNCTION("""COMPUTED_VALUE"""),"Negative") -> Negative | G35: =IFERROR(__xludf.DUMMYFUNCTION("""COMPUTED_VALUE"""),1.0) -> 1
A36: =IFERROR(__xludf.DUMMYFUNCTION("""COMPUTED_VALUE"""),"AG2159") -> AG2159 | B36: =IFERROR(__xludf.DUMMYFUNCTION("""COMPUTED_VALUE"""),"RUN-NDHM_2022-05-16_RFR-010") -> RUN-NDHM_2022-05-16_RFR-010 | C36: =VLOOKUP(B36,'Run Reconcile'!A$2:B100,2,FALSE) -> 44697 | D36: =IFERROR(__xludf.DUMMYFUNCTION("""COMPUTED_VALUE"""),44697.0) -> 44697 | E36: =IFERROR(__xludf.DUMMYFUNCTION("""COMPUTED_VALUE"""),0.32215277777868323) -> 0.32215278 | F36: =IFERROR(__xludf.DUMMYFUNCTION("""COMPUTED_VALUE"""),"Negative") -> Negative | G36: =IFERROR(__xludf.DUMMYFUNCTION("""COMPUTED_VALUE"""),3.0) -> 3
A37: =IFERROR(__xludf.DUMMYFUNCTION("""COMPUTED_VALUE"""),"AJ5950") -> AJ5950 | B37: =IFERROR(__xludf.DUMMYFUNCTION("""COMPUTED_VALUE"""),"RUN-NDHM_2022-05-23_RFR-011") -> RUN-NDHM_2022-05-23_RFR-011 | C37: =VLOOKUP(B37,'Run Reconcile'!A$2:B100,2,FALSE) -> 44704 | D37: =IFERROR(__xludf.DUMMYFUNCTION("""COMPUTED_VALUE"""),44704.0) -> 44704 | E37: =IFERROR(__xludf.DUMMYFUNCTION("""COMPUTED_VALUE"""),0.1565393518503697) -> 0.15653935 | F37: =IFERROR(__xludf.DUMMYFUNCTION("""COMPUTED_VALUE"""),"Negative") -> Negative | G37: =IFERROR(__xludf.DUMMYFUNCTION("""COMPUTED_VALUE"""),4.0) -> 4
A38: =IFERROR(__xludf.DUMMYFUNCTION("""COMPUTED_VALUE"""),"AH7211") -> AH7211 | B38: =IFERROR(__xludf.DUMMYFUNCTION("""COMPUTED_VALUE"""),"RUN-NDHM_2022-05-23_RFR-011") -> RUN-NDHM_2022-05-23_RFR-011 | C38: =VLOOKUP(B38,'Run Reconcile'!A$2:B100,2,FALSE) -> 44704 | D38: =IFERROR(__xludf.DUMMYFUNCTION("""COMPUTED_VALUE"""),44704.0) -> 44704 | E38: =IFERROR(__xludf.DUMMYFUNCTION("""COMPUTED_VALUE"""),0.17846064814875717) -> 0.17846065 | F38: =IFERROR(__xludf.DUMMYFUNCTION("""COMPUTED_VALUE"""),"Negative") -> Negative | G38: =IFERROR(__xludf.DUMMYFUNCTION("""COMPUTED_VALUE"""),4.0) -> 4
A39: =IFERROR(__xludf.DUMMYFUNCTION("""COMPUTED_VALUE"""),"AH330") -> AH330 | B39: =IFERROR(__xludf.DUMMYFUNCTION("""COMPUTED_VALUE"""),"RUN-NDHM_2022-05-23_RFR-011") -> RUN-NDHM_2022-05-23_RFR-011 | C39: =VLOOKUP(B39,'Run Reconcile'!A$2:B100,2,FALSE) -> 44704 | D39: =IFERROR(__xludf.DUMMYFUNCTION("""COMPUTED_VALUE"""),44704.0) -> 44704 | E39: =IFERROR(__xludf.DUMMYFUNCTION("""COMPUTED_VALUE"""),0.1878240740734327) -> 0.18782407 | F39: =IFERROR(__xludf.DUMMYFUNCTION("""COMPUTED_VALUE"""),"Negative") -> Negative | G39: =IFERROR(__xludf.DUMMYFUNCTION("""COMPUTED_VALUE"""),4.0) -> 4
A40: =IFERROR(__xludf.DUMMYFUNCTION("""COMPUTED_VALUE"""),"AG1640") -> AG1640 | B40: =IFERROR(__xludf.DUMMYFUNCTION("""COMPUTED_VALUE"""),"RUN-NDHM_2022-05-23_RFR-011") -> RUN-NDHM_2022-05-23_RFR-011 | C40: =VLOOKUP(B40,'Run Reconcile'!A$2:B100,2,FALSE) -> 44704 | D40: =IFERROR(__xludf.DUMMYFUNCTION("""COMPUTED_VALUE"""),44704.0) -> 44704 | E40: =IFERROR(__xludf.DUMMYFUNCTION("""COMPUTED_VALUE"""),0.19054398148000473) -> 0.19054398 | F40: =IFERROR(__xludf.DUMMYFUNCTION("""COMPUTED_VALUE"""),"Negative") -> Negative | G40: =IFERROR(__xludf.DUMMYFUNCTION("""COMPUTED_VALUE"""),2.0) -> 2
...

Sheet Weekly
A1: Week Start Date | B1: Week End Date | C1: =CONCATENATE("Weekly Participants ",SUM(C2:C99)) -> Weekly Participants 190 | D1: =CONCATENATE("Weekly Tubes Run ",SUM(D2:D99)) -> Weekly Tubes Run 80 | E1: =CONCATENATE("Weekly Positive Tubes ",SUM(E2:E99)) -> Weekly Positive Tubes 0 | F1: =CONCATENATE("Weekly Inconclusive Tubes ",SUM(F2:F99)) -> Weekly Inconclusive Tubes 0 | G1: % Positive
A2: =MIN('ALL Tube Results'!C:C) - WEEKDAY(MIN('ALL Tube Results'!C:C), 3) -> 44683 | B2: =A2+6 -> 44689 | C2: =SUMIFS('ALL Tube Results'!$G$2:$G99, 'ALL Tube Results'!$C$2:$C99, ">="&A2, 'ALL Tube Results'!$C$2:$C99, "<="&B2) -> 34 | D2: =COUNTIFS('ALL Tube Results'!$C2:$C99, ">="&A2, 'ALL Tube Results'!$C2:$C99, "<="&B2) -> 17 | E2: =COUNTIFS('ALL Tube Results'!$C2:$C99, ">="&A2, 'ALL Tube Results'!$C2:$C99, "<="&B2, 'ALL Tube Results'!$F2:$F99, "Positive") -> 0 | F2: =COUNTIFS('ALL Tube Results'!$C2:$C99, ">="&A2, 'ALL Tube Results'!$C2:$C99, "<="&B2, 'ALL Tube Results'!$F2:$F99, "Inconclusive") -> 0 | G2: =IFERROR(E2/D2,IFERROR(0/0,"")) -> 0 | I2: =TEXT(A2,"ddd") -> Mon
A3: =B2+1 -> 44690 | B3: =A3+6 -> 44696 | C3: =SUMIFS('ALL Tube Results'!$G$2:$G99, 'ALL Tube Results'!$C$2:$C99, ">="&A3, 'ALL Tube Results'!$C$2:$C99, "<="&B3) -> 22 | D3: =COUNTIFS('ALL Tube Results'!$C3:$C99, ">="&A3, 'ALL Tube Results'!$C3:$C99, "<="&B3) -> 9 | E3: =COUNTIFS('ALL Tube Results'!$C3:$C99, ">="&A3, 'ALL Tube Results'!$C3:$C99, "<="&B3, 'ALL Tube Results'!$F3:$F99, "Positive") -> 0 | F3: =COUNTIFS('ALL Tube Results'!$C3:$C99, ">="&A3, 'ALL Tube Results'!$C3:$C99, "<="&B3, 'ALL Tube Results'!$F3:$F99, "Inconclusive") -> 0 | G3: =IFERROR(E3/D3,IFERROR(0/0,"")) -> 0
A4: =A3+7 -> 44697 | B4: =A4+6 -> 44703 | C4: =SUMIFS('ALL Tube Results'!$G$2:$G99, 'ALL Tube Results'!$C$2:$C99, ">="&A4, 'ALL Tube Results'!$C$2:$C99, "<="&B4) -> 26 | D4: =COUNTIFS('ALL Tube Results'!$C4:$C99, ">="&A4, 'ALL Tube Results'!$C4:$C99, "<="&B4) -> 10 | E4: =COUNTIFS('ALL Tube Results'!$C4:$C99, ">="&A4, 'ALL Tube Results'!$C4:$C99, "<="&B4, 'ALL Tube Results'!$F4:$F99, "Positive") -> 0 | F4: =COUNTIFS('ALL Tube Results'!$C4:$C99, ">="&A4, 'ALL Tube Results'!$C4:$C99, "<="&B4, 'ALL Tube Results'!$F4:$F99, "Inconclusive") -> 0 | G4: =IFERROR(E4/D4,IFERROR(0/0,"")) -> 0
A5: =A4+7 -> 44704 | B5: =A5+6 -> 44710 | C5: =SUMIFS('ALL Tube Results'!$G$2:$G99, 'ALL Tube Results'!$C$2:$C99, ">="&A5, 'ALL Tube Results'!$C$2:$C99, "<="&B5) -> 22 | D5: =COUNTIFS('ALL Tube Results'!$C5:$C99, ">="&A5, 'ALL Tube Results'!$C5:$C99, "<="&B5) -> 8 | E5: =COUNTIFS('ALL Tube Results'!$C5:$C99, ">="&A5, 'ALL Tube Results'!$C5:$C99, "<="&B5, 'ALL Tube Results'!$F5:$F99, "Positive") -> 0 | F5: =COUNTIFS('ALL Tube Results'!$C5:$C99, ">="&A5, 'ALL Tube Results'!$C5:$C99, "<="&B5, 'ALL Tube Results'!$F5:$F99, "Inconclusive") -> 0 | G5: =IFERROR(E5/D5,IFERROR(0/0,"")) -> 0
A6: =A5+7 -> 44711 | B6: =A6+6 -> 44717 | C6: =SUMIFS('ALL Tube Results'!$G$2:$G99, 'ALL Tube Results'!$C$2:$C99, ">="&A6, 'ALL Tube Results'!$C$2:$C99, "<="&B6) -> 28 | D6: =COUNTIFS('ALL Tube Results'!$C6:$C99, ">="&A6, 'ALL Tube Results'!$C6:$C99, "<="&B6) -> 13 | E6: =COUNTIFS('ALL Tube Results'!$C6:$C99, ">="&A6, 'ALL Tube Results'!$C6:$C99, "<="&B6, 'ALL Tube Results'!$F6:$F99, "Positive") -> 0 | F6: =COUNTIFS('ALL Tube Results'!$C6:$C99, ">="&A6, 'ALL Tube Results'!$C6:$C99, "<="&B6, 'ALL Tube Results'!$F6:$F99, "Inconclusive") -> 0 | G6: =IFERROR(E6/D6,IFERROR(0/0,"")) -> 0
A7: =A6+7 -> 44718 | B7: =A7+6 -> 44724 | C7: =SUMIFS('ALL Tube Results'!$G$2:$G99, 'ALL Tube Results'!$C$2:$C99, ">="&A7, 'ALL Tube Results'!$C$2:$C99, "<="&B7) -> 19 | D7: =COUNTIFS('ALL Tube Results'!$C7:$C99, ">="&A7, 'ALL Tube Results'!$C7:$C99, "<="&B7) -> 8 | E7: =COUNTIFS('ALL Tube Results'!$C7:$C99, ">="&A7, 'ALL Tube Results'!$C7:$C99, "<="&B7, 'ALL Tube Results'!$F7:$F99, "Positive") -> 0 | F7: =COUNTIFS('ALL Tube Results'!$C7:$C99, ">="&A7, 'ALL Tube Results'!$C7:$C99, "<="&B7, 'ALL Tube Results'!$F7:$F99, "Inconclusive") -> 0 | G7: =IFERROR(E7/D7,IFERROR(0/0,"")) -> 0
A8: =A7+7 -> 44725 | B8: =A8+6 -> 44731 | C8: =SUMIFS('ALL Tube Results'!$G$2:$G99, 'ALL Tube Results'!$C$2:$C99, ">="&A8, 'ALL Tube Results'!$C$2:$C99, "<="&B8) -> 12 | D8: =COUNTIFS('ALL Tube Results'!$C8:$C99, ">="&A8, 'ALL Tube Results'!$C8:$C99, "<="&B8) -> 4 | E8: =COUNTIFS('ALL Tube Results'!$C8:$C99, ">="&A8, 'ALL Tube Results'!$C8:$C99, "<="&B8, 'ALL Tube Results'!$F8:$F99, "Positive") -> 0 | F8: =COUNTIFS('ALL Tube Results'!$C8:$C99, ">="&A8, 'ALL Tube Results'!$C8:$C99, "<="&B8, 'ALL Tube Results'!$F8:$F99, "Inconclusive") -> 0 | G8: =IFERROR(E8/D8,IFERROR(0/0,"")) -> 0
A9: =A8+7 -> 44732 | B9: =A9+6 -> 44738 | C9: =SUMIFS('ALL Tube Results'!$G$2:$G99, 'ALL Tube Results'!$C$2:$C99, ">="&A9, 'ALL Tube Results'!$C$2:$C99, "<="&B9) -> 4 | D9: =COUNTIFS('ALL Tube Results'!$C9:$C99, ">="&A9, 'ALL Tube Results'!$C9:$C99, "<="&B9) -> 2 | E9: =COUNTIFS('ALL Tube Results'!$C9:$C99, ">="&A9, 'ALL Tube Results'!$C9:$C99, "<="&B9, 'ALL Tube Results'!$F9:$F99, "Positive") -> 0 | F9: =COUNTIFS('ALL Tube Results'!$C9:$C99, ">="&A9, 'ALL Tube Results'!$C9:$C99, "<="&B9, 'ALL Tube Results'!$F9:$F99, "Inconclusive") -> 0 | G9: =IFERROR(E9/D9,IFERROR(0/0,"")) -> 0
A10: =A9+7 -> 44739 | B10: =A10+6 -> 44745 | C10: =SUMIFS('ALL Tube Results'!$G$2:$G99, 'ALL Tube Results'!$C$2:$C99, ">="&A10, 'ALL Tube Results'!$C$2:$C99, "<="&B10) -> 3 | D10: =COUNTIFS('ALL Tube Results'!$C10:$C99, ">="&A10, 'ALL Tube Results'!$C10:$C99, "<="&B10) -> 1 | E10: =COUNTIFS('ALL Tube Results'!$C10:$C99, ">="&A10, 'ALL Tube Results'!$C10:$C99, "<="&B10, 'ALL Tube Results'!$F10:$F99, "Positive") -> 0 | F10: =COUNTIFS('ALL Tube Results'!$C10:$C99, ">="&A10, 'ALL Tube Results'!$C10:$C99, "<="&B10, 'ALL Tube Results'!$F10:$F99, "Inconclusive") -> 0 | G10: =IFERROR(E10/D10,IFERROR(0/0,"")) -> 0
A11: =A10+7 -> 44746 | B11: =A11+6 -> 44752 | C11: =SUMIFS('ALL Tube Results'!$G$2:$G99, 'ALL Tube Results'!$C$2:$C99, ">="&A11, 'ALL Tube Results'!$C$2:$C99, "<="&B11) -> 0 | D11: =COUNTIFS('ALL Tube Results'!$C11:$C99, ">="&A11, 'ALL Tube Results'!$C11:$C99, "<="&B11) -> 0 | E11: =COUNTIFS('ALL Tube Results'!$C11:$C99, ">="&A11, 'ALL Tube Results'!$C11:$C99, "<="&B11, 'ALL Tube Results'!$F11:$F99, "Positive") -> 0 | F11: =COUNTIFS('ALL Tube Results'!$C11:$C99, ">="&A11, 'ALL Tube Results'!$C11:$C99, "<="&B11, 'ALL Tube Results'!$F11:$F99, "Inconclusive") -> 0 | G11: =IFERROR(E11/D11,IFERROR(0/0,""))
A12: =A11+7 -> 44753 | B12: =A12+6 -> 44759 | C12: =SUMIFS('ALL Tube Results'!$G$2:$G99, 'ALL Tube Results'!$C$2:$C99, ">="&A12, 'ALL Tube Results'!$C$2:$C99, "<="&B12) -> 2 | D12: =COUNTIFS('ALL Tube Results'!$C12:$C99, ">="&A12, 'ALL Tube Results'!$C12:$C99, "<="&B12) -> 1 | E12: =COUNTIFS('ALL Tube Results'!$C12:$C99, ">="&A12, 'ALL Tube Results'!$C12:$C99, "<="&B12, 'ALL Tube Results'!$F12:$F99, "Positive") -> 0 | F12: =COUNTIFS('ALL Tube Results'!$C12:$C99, ">="&A12, 'ALL Tube Results'!$C12:$C99, "<="&B12, 'ALL Tube Results'!$F12:$F99, "Inconclusive") -> 0 | G12: =IFERROR(E12/D12,IFERROR(0/0,"")) -> 0
A13: =A12+7 -> 44760 | B13: =A13+6 -> 44766 | C13: =SUMIFS('ALL Tube Results'!$G$2:$G99, 'ALL Tube Results'!$C$2:$C99, ">="&A13, 'ALL Tube Results'!$C$2:$C99, "<="&B13) -> 2 | D13: =COUNTIFS('ALL Tube Results'!$C13:$C99, ">="&A13, 'ALL Tube Results'!$C13:$C99, "<="&B13) -> 1 | E13: =COUNTIFS('ALL Tube Results'!$C13:$C99, ">="&A13, 'ALL Tube Results'!$C13:$C99, "<="&B13, 'ALL Tube Results'!$F13:$F99, "Positive") -> 0 | F13: =COUNTIFS('ALL Tube Results'!$C13:$C99, ">="&A13, 'ALL Tube Results'!$C13:$C99, "<="&B13, 'ALL Tube Results'!$F13:$F99, "Inconclusive") -> 0 | G13: =IFERROR(E13/D13,IFERROR(0/0,"")) -> 0
A14: =A13+7 -> 44767 | B14: =A14+6 -> 44773 | C14: =SUMIFS('ALL Tube Results'!$G$2:$G99, 'ALL Tube Results'!$C$2:$C99, ">="&A14, 'ALL Tube Results'!$C$2:$C99, "<="&B14) -> 6 | D14: =COUNTIFS('ALL Tube Results'!$C14:$C99, ">="&A14, 'ALL Tube Results'!$C14:$C99, "<="&B14) -> 3 | E14: =COUNTIFS('ALL Tube Results'!$C14:$C99, ">="&A14, 'ALL Tube Results'!$C14:$C99, "<="&B14, 'ALL Tube Results'!$F14:$F99, "Positive") -> 0 | F14: =COUNTIFS('ALL Tube Results'!$C14:$C99, ">="&A14, 'ALL Tube Results'!$C14:$C99, "<="&B14, 'ALL Tube Results'!$F14:$F99, "Inconclusive") -> 0 | G14: =IFERROR(E14/D14,IFERROR(0/0,"")) -> 0
A15: =A14+7 -> 44774 | B15: =A15+6 -> 44780 | C15: =SUMIFS('ALL Tube Results'!$G$2:$G99, 'ALL Tube Results'!$C$2:$C99, ">="&A15, 'ALL Tube Results'!$C$2:$C99, "<="&B15) -> 3 | D15: =COUNTIFS('ALL Tube Results'!$C15:$C99, ">="&A15, 'ALL Tube Results'!$C15:$C99, "<="&B15) -> 1 | E15: =COUNTIFS('ALL Tube Results'!$C15:$C99, ">="&A15, 'ALL Tube Results'!$C15:$C99, "<="&B15, 'ALL Tube Results'!$F15:$F99, "Positive") -> 0 | F15: =COUNTIFS('ALL Tube Results'!$C15:$C99, ">="&A15, 'ALL Tube Results'!$C15:$C99, "<="&B15, 'ALL Tube Results'!$F15:$F99, "Inconclusive") -> 0 | G15: =IFERROR(E15/D15,IFERROR(0/0,"")) -> 0
A16: =A15+7 -> 44781 | B16: =A16+6 -> 44787 | C16: =SUMIFS('ALL Tube Results'!$G$2:$G99, 'ALL Tube Results'!$C$2:$C99, ">="&A16, 'ALL Tube Results'!$C$2:$C99, "<="&B16) -> 0 | D16: =COUNTIFS('ALL Tube Results'!$C16:$C99, ">="&A16, 'ALL Tube Results'!$C16:$C99, "<="&B16) -> 0 | E16: =COUNTIFS('ALL Tube Results'!$C16:$C99, ">="&A16, 'ALL Tube Results'!$C16:$C99, "<="&B16, 'ALL Tube Results'!$F16:$F99, "Positive") -> 0 | F16: =COUNTIFS('ALL Tube Results'!$C16:$C99, ">="&A16, 'ALL Tube Results'!$C16:$C99, "<="&B16, 'ALL Tube Results'!$F16:$F99, "Inconclusive") -> 0 | G16: =IFERROR(E16/D16,IFERROR(0/0,""))
A17: =A16+7 -> 44788 | B17: =A17+6 -> 44794 | C17: =SUMIFS('ALL Tube Results'!$G$2:$G99, 'ALL Tube Results'!$C$2:$C99, ">="&A17, 'ALL Tube Results'!$C$2:$C99, "<="&B17) -> 0 | D17: =COUNTIFS('ALL Tube Results'!$C17:$C99, ">="&A17, 'ALL Tube Results'!$C17:$C99, "<="&B17) -> 0 | E17: =COUNTIFS('ALL Tube Results'!$C17:$C99, ">="&A17, 'ALL Tube Results'!$C17:$C99, "<="&B17, 'ALL Tube Results'!$F17:$F99, "Positive") -> 0 | F17: =COUNTIFS('ALL Tube Results'!$C17:$C99, ">="&A17, 'ALL Tube Results'!$C17:$C99, "<="&B17, 'ALL Tube Results'!$F17:$F99, "Inconclusive") -> 0 | G17: =IFERROR(E17/D17,IFERROR(0/0,""))
A18: =A17+7 -> 44795 | B18: =A18+6 -> 44801 | C18: =SUMIFS('ALL Tube Results'!$G$2:$G99, 'ALL Tube Results'!$C$2:$C99, ">="&A18, 'ALL Tube Results'!$C$2:$C99, "<="&B18) -> 0 | D18: =COUNTIFS('ALL Tube Results'!$C18:$C99, ">="&A18, 'ALL Tube Results'!$C18:$C99, "<="&B18) -> 0 | E18: =COUNTIFS('ALL Tube Results'!$C18:$C99, ">="&A18, 'ALL Tube Results'!$C18:$C99, "<="&B18, 'ALL Tube Results'!$F18:$F99, "Positive") -> 0 | F18: =COUNTIFS('ALL Tube Results'!$C18:$C99, ">="&A18, 'ALL Tube Results'!$C18:$C99, "<="&B18, 'ALL Tube Results'!$F18:$F99, "Inconclusive") -> 0 | G18: =IFERROR(E18/D18,IFERROR(0/0,""))
A19: =A18+7 -> 44802 | B19: =A19+6 -> 44808 | C19: =SUMIFS('ALL Tube Results'!$G$2:$G99, 'ALL Tube Results'!$C$2:$C99, ">="&A19, 'ALL Tube Results'!$C$2:$C99, "<="&B19) -> 0 | D19: =COUNTIFS('ALL Tube Results'!$C19:$C99, ">="&A19, 'ALL Tube Results'!$C19:$C99, "<="&B19) -> 0 | E19: =COUNTIFS('ALL Tube Results'!$C19:$C99, ">="&A19, 'ALL Tube Results'!$C19:$C99, "<="&B19, 'ALL Tube Results'!$F19:$F99, "Positive") -> 0 | F19: =COUNTIFS('ALL Tube Results'!$C19:$C99, ">="&A19, 'ALL Tube Results'!$C19:$C99, "<="&B19, 'ALL Tube Results'!$F19:$F99, "Inconclusive") -> 0 | G19: =IFERROR(E19/D19,IFERROR(0/0,""))
A20: =A19+7 -> 44809 | B20: =A20+6 -> 44815 | C20: =SUMIFS('ALL Tube Results'!$G$2:$G99, 'ALL Tube Results'!$C$2:$C99, ">="&A20, 'ALL Tube Results'!$C$2:$C99, "<="&B20) -> 0 | D20: =COUNTIFS('ALL Tube Results'!$C20:$C99, ">="&A20, 'ALL Tube Results'!$C20:$C99, "<="&B20) -> 0 | E20: =COUNTIFS('ALL Tube Results'!$C20:$C99, ">="&A20, 'ALL Tube Results'!$C20:$C99, "<="&B20, 'ALL Tube Results'!$F20:$F99, "Positive") -> 0 | F20: =COUNTIFS('ALL Tube Results'!$C20:$C99, ">="&A20, 'ALL Tube Results'!$C20:$C99, "<="&B20, 'ALL Tube Results'!$F20:$F99, "Inconclusive") -> 0 | G20: =IFERROR(E20/D20,IFERROR(0/0,""))
A21: =A20+7 -> 44816 | B21: =A21+6 -> 44822 | C21: =SUMIFS('ALL Tube Results'!$G$2:$G99, 'ALL Tube Results'!$C$2:$C99, ">="&A21, 'ALL Tube Results'!$C$2:$C99, "<="&B21) -> 4 | D21: =COUNTIFS('ALL Tube Results'!$C21:$C99, ">="&A21, 'ALL Tube Results'!$C21:$C99, "<="&B21) -> 1 | E21: =COUNTIFS('ALL Tube Results'!$C21:$C99, ">="&A21, 'ALL Tube Results'!$C21:$C99, "<="&B21, 'ALL Tube Results'!$F21:$F99, "Positive") -> 0 | F21: =COUNTIFS('ALL Tube Results'!$C21:$C99, ">="&A21, 'ALL Tube Results'!$C21:$C99, "<="&B21, 'ALL Tube Results'!$F21:$F99, "Inconclusive") -> 0 | G21: =IFERROR(E21/D21,IFERROR(0/0,"")) -> 0
A22: =A21+7 -> 44823 | B22: =A22+6 -> 44829 | C22: =SUMIFS('ALL Tube Results'!$G$2:$G99, 'ALL Tube Results'!$C$2:$C99, ">="&A22, 'ALL Tube Results'!$C$2:$C99, "<="&B22) -> 0 | D22: =COUNTIFS('ALL Tube Results'!$C22:$C99, ">="&A22, 'ALL Tube Results'!$C22:$C99, "<="&B22) -> 0 | E22: =COUNTIFS('ALL Tube Results'!$C22:$C99, ">="&A22, 'ALL Tube Results'!$C22:$C99, "<="&B22, 'ALL Tube Results'!$F22:$F99, "Positive") -> 0 | F22: =COUNTIFS('ALL Tube Results'!$C22:$C99, ">="&A22, 'ALL Tube Results'!$C22:$C99, "<="&B22, 'ALL Tube Results'!$F22:$F99, "Inconclusive") -> 0 | G22: =IFERROR(E22/D22,IFERROR(0/0,""))
A23: =A22+7 -> 44830 | B23: =A23+6 -> 44836 | C23: =SUMIFS('ALL Tube Results'!$G$2:$G99, 'ALL Tube Results'!$C$2:$C99, ">="&A23, 'ALL Tube Results'!$C$2:$C99, "<="&B23) -> 0 | D23: =COUNTIFS('ALL Tube Results'!$C23:$C99, ">="&A23, 'ALL Tube Results'!$C23:$C99, "<="&B23) -> 0 | E23: =COUNTIFS('ALL Tube Results'!$C23:$C99, ">="&A23, 'ALL Tube Results'!$C23:$C99, "<="&B23, 'ALL Tube Results'!$F23:$F99, "Positive") -> 0 | F23: =COUNTIFS('ALL Tube Results'!$C23:$C99, ">="&A23, 'ALL Tube Results'!$C23:$C99, "<="&B23, 'ALL Tube Results'!$F23:$F99, "Inconclusive") -> 0 | G23: =IFERROR(E23/D23,IFERROR(0/0,""))
A24: =A23+7 -> 44837 | B24: =A24+6 -> 44843 | C24: =SUMIFS('ALL Tube Results'!$G$2:$G99, 'ALL Tube Results'!$C$2:$C99, ">="&A24, 'ALL Tube Results'!$C$2:$C99, "<="&B24) -> 3 | D24: =COUNTIFS('ALL Tube Results'!$C24:$C99, ">="&A24, 'ALL Tube Results'!$C24:$C99, "<="&B24) -> 1 | E24: =COUNTIFS('ALL Tube Results'!$C24:$C99, ">="&A24, 'ALL Tube Results'!$C24:$C99, "<="&B24, 'ALL Tube Results'!$F24:$F99, "Positive") -> 0 | F24: =COUNTIFS('ALL Tube Results'!$C24:$C99, ">="&A24, 'ALL Tube Results'!$C24:$C99, "<="&B24, 'ALL Tube Results'!$F24:$F99, "Inconclusive") -> 0 | G24: =IFERROR(E24/D24,IFERROR(0/0,"")) -> 0

Sheet Runs Compare
A1: ALL Tube RESULTS by Run ID | B1: =COUNT(B3:B49) -> 15 | C1: =SUM(C2:C49) -> 80 | D1: =SUM(D2:D49) -> 80 | E1: =SUM(E2:E49) -> 0 | F1: =SUM(F2:F49) -> 0 | H1: =SUM(H2:H49) -> 0 | L1: =SUM(L2:L49) -> -6 | M1: =SUM(M2:M49) -> 0 | N1: =SUM(N2:N49) -> 0 | P1: =SUM(P2:P49) -> 2 | R1: Run Reconciled RESULTS | S1: =CONCATENATE("Delta Run Reconciled to ALL Tubes ",T1-C1) -> Delta Run Reconciled to ALL Tubes 0 | T1: =SUM(T2:T49) -> 80 | U1: =SUM(U2:U49) -> 0 | V1: =SUM(V2:V49) -> 0 | W1: =SUM(W2:W49) -> 0 | Y1: RFR Data - PreExcl RESULTS | AA1: =SUM(AA2:AA49) -> 86 | AB1: =SUM(AB2:AB49) -> 86 | AC1: =SUM(AC2:AC49) -> 0 | AD1: =SUM(AD2:AD49) -> 0 | AG1: APS Final RESULTS by Reconciled Run ID | AI1: =SUM(AI3:AI49) -> 78 | AJ1: =SUM(AJ3:AJ49) -> 78 | AK1: =SUM(AK3:AK49) -> 0 | AL1: =SUM(AL3:AL49) -> 0 | AM1: =SUM(AM3:AM49) -> 0 | AO1: APS Final RESULTS by Collect Date | AP1: =SUM(AP2:AP49) -> 78 | AQ1: =SUM(AQ2:AQ49) -> 78 | AR1: =SUM(AR2:AR49) -> 0 | AS1: =SUM(AS2:AS49) -> 0 | AT1: =SUM(AT2:AT49) -> 0
A2: Run ID | B2: Run Date | C2: Number of Tubes | D2: Negative | E2: Positive | F2: Inconclusive | H2: Delta to Run Reconciled Results | I2: T | J2: P | K2: I | L2: Delta to RFR preExcl Audit Num Run Tubes | M2: Delta to RFR preExcl Audit Num Positives | N2: Delta to RFR preExcl Audit Num Inconclusives | P2: Delta to APS | R2: Run ID | S2: Run Date | T2: Reconciled Tube Run Count | Y2: Run ID - RFR Initial Only | Z2: Run Date | AA2: ='RFR Data - preExcl'!AK1 -> RFR Audit Num Run Tubes | AB2: Calculated Negs | AC2: ='RFR Data - preExcl'!AI1 -> Audit Pos Session Calls | AD2: ='RFR Data - preExcl'!AF1 -> Audit Inc Session Calls | AE2: preExcl Match Row | AG2: Final Assigned Run ID | AH2: Run Date | AI2: Number of Tubes | AJ2: Negative | AK2: Positive | AL2: Inconclusive | AM2: Null | AO2: ='APS Tubes by Date Import'!B1 -> APS COLLECT DATE | AP2: Number of Tubes | AQ2: Negative | AR2: Positive | AS2: Inconclusive | AT2: Null
A3: {=UNIQUE('ALL Tube Results'!B2:B49)} -> RUN-NDHM_2022-05-02_RFR-006 | B3: =VLOOKUP(A3,'ALL Tube Results'!$B$2:$D49,2,FALSE) -> 44683 | C3: =COUNTIF('ALL Tube Results'!B2:B49, A3) -> 17 | D3: =COUNTIFS('ALL Tube Results'!$B2:$B49, $A3, 'ALL Tube Results'!$F2:$F49, "Negative") -> 17 | E3: =COUNTIFS('ALL Tube Results'!$B2:$B49, $A3, 'ALL Tube Results'!$F2:$F49, "Positive") -> 0 | F3: =COUNTIFS('ALL Tube Results'!$B2:$B49, $A3, 'ALL Tube Results'!$F2:$F49, "Inconclusive") -> 0 | G3: =IFERROR(VLOOKUP($A3,R$3:T49,3,FALSE),IFERROR(0/0,"") ) -> 17 | H3: =IF($C3=G3,IFERROR(0/0,""),$C3-G3) | I3: =IFERROR(VLOOKUP($A3,Y$3:AA49,3,FALSE),IFERROR(0/0,"") ) -> 18 | J3: =IFERROR(VLOOKUP($A3,Y$3:AD49,5,FALSE),IFERROR(0/0,"") ) -> 0 | K3: =IFERROR(VLOOKUP($A3,Y$3:AD49,6,FALSE),IFERROR(0/0,"")) -> 0 | L3: =IF($C3=I3,IFERROR(0/0,""),$C3-I3) -> -1 | M3: =IF($E3=J3,IFERROR(0/0,""),$E3-J3) | N3: =IF($F3=K3,IFERROR(0/0,""),$F3-K3) | O3: =IFERROR(VLOOKUP($A3,AG$3:AI49,3,FALSE),IFERROR(0/0,"") ) -> 17 | P3: =IF($C3=O3,IFERROR(0/0,""),$C3-O3) | R3: {=SORT('Run Reconcile'!A2:B49,1,TRUE)} -> RUN-NDHM_2022-05-02_RFR-006 | S3: 44683 | T3: =VLOOKUP(R3,'Run Reconcile'!$A$2:$L49,12,FALSE) -> 17 | Y3: =IFERROR(__xludf.DUMMYFUNCTION("SORT(FILTER('Run Reconcile'!A2:B49,'Run Reconcile'!A2:A49<>""*"",REGEXMATCH('Run Reconcile'!A2:A49,""RFR-"")),1,TRUE) "),"RUN-NDHM_2022-05-02_RFR-006") -> RUN-NDHM_2022-05-02_RFR-006 | Z3: =IFERROR(__xludf.DUMMYFUNCTION("""COMPUTED_VALUE"""),44683.0) -> 44683 | AA3: {=INDEX('RFR Data - preExcl'!AK$2:AK49,$AE3,1)} -> 18 | AB3: =AA3-AC3-AD3 -> 18 | AC3: {=INDEX('RFR Data - preExcl'!AI$2:AI49,$AE3,1)} -> 0 | AD3: {=INDEX('RFR Data - preExcl'!AF$2:AF49,$AE3,1)} -> 0 | AE3: =IFNA(MATCH(Y3,'RFR Data - preExcl'!A$2:A49,0),"") -> 6 | AG3: {=SORT(UNIQUE('APS Tubes Import'!V2:V49))} -> RUN-NDHM_2022-05-02_RFR-006 | AH3: =VLOOKUP(AG3,'Run Reconcile'!A$2:B49,2,FALSE) -> 44683 | AI3: =COUNTIF('APS Tubes Import'!$V$2:$V49, AG3) -> 17 | AJ3: =COUNTIFS('APS Tubes Import'!V$2:V49, AG3, 'APS Tubes Import'!H$2:H49, "Negative") -> 17 | AK3: =COUNTIFS('APS Tubes Import'!V$2:V49, AG3, 'APS Tubes Import'!H$2:H49, "Positive") -> 0 | AL3: =COUNTIFS('APS Tubes Import'!V$2:V49, AG3, 'APS Tubes Import'!H$2:H49, "Inconclusive") -> 0 | AM3: =COUNTIFS('APS Tubes Import'!V$2:V49, AG3, 'APS Tubes Import'!H$2:H49, "Null") -> 0 | AO3: ='APS Tubes by Date Import'!B2 -> 44683 | AP3: ='APS Tubes by Date Import'!C2 -> 17 | AQ3: ='APS Tubes by Date Import'!D2 -> 17 | AR3: ='APS Tubes by Date Import'!E2 -> 0 | AS3: ='APS Tubes by Date Import'!F2 -> 0 | AT3: ='APS Tubes by Date Import'!G2 -> 0
A4: RUN-NDHM_2022-05-09_RFR-009 | B4: =VLOOKUP(A4,'ALL Tube Results'!$B$2:$D49,2,FALSE) -> 44690 | C4: =COUNTIF('ALL Tube Results'!B3:B49, A4) -> 9 | D4: =COUNTIFS('ALL Tube Results'!$B3:$B49, $A4, 'ALL Tube Results'!$F3:$F49, "Negative") -> 9 | E4: =COUNTIFS('ALL Tube Results'!$B3:$B49, $A4, 'ALL Tube Results'!$F3:$F49, "Positive") -> 0 | F4: =COUNTIFS('ALL Tube Results'!$B3:$B49, $A4, 'ALL Tube Results'!$F3:$F49, "Inconclusive") -> 0 | G4: =IFERROR(VLOOKUP($A4,R$3:T50,3,FALSE),IFERROR(0/0,"") ) -> 9 | H4: =IF($C4=G4,IFERROR(0/0,""),$C4-G4) | I4: =IFERROR(VLOOKUP($A4,Y$3:AA50,3,FALSE),IFERROR(0/0,"") ) -> 9 | J4: =IFERROR(VLOOKUP($A4,Y$3:AD50,5,FALSE),IFERROR(0/0,"") ) -> 0 | K4: =IFERROR(VLOOKUP($A4,Y$3:AD50,6,FALSE),IFERROR(0/0,"")) -> 0 | L4: =IF($C4=I4,IFERROR(0/0,""),$C4-I4) | M4: =IF($E4=J4,IFERROR(0/0,""),$E4-J4) | N4: =IF($F4=K4,IFERROR(0/0,""),$F4-K4) | O4: =IFERROR(VLOOKUP($A4,AG$3:AI50,3,FALSE),IFERROR(0/0,"") ) -> 8 | P4: =IF($C4=O4,IFERROR(0/0,""),$C4-O4) -> 1 | R4: RUN-NDHM_2022-05-09_RFR-009 | S4: 44690 | T4: =VLOOKUP(R4,'Run Reconcile'!$A$2:$L49,12,FALSE) -> 9 | Y4: =IFERROR(__xludf.DUMMYFUNCTION("""COMPUTED_VALUE"""),"RUN-NDHM_2022-05-09_RFR-009") -> RUN-NDHM_2022-05-09_RFR-009 | Z4: =IFERROR(__xludf.DUMMYFUNCTION("""COMPUTED_VALUE"""),44690.0) -> 44690 | AA4: {=INDEX('RFR Data - preExcl'!AK$2:AK49,$AE4,1)} -> 9 | AB4: =AA4-AC4-AD4 -> 9 | AC4: {=INDEX('RFR Data - preExcl'!AI$2:AI49,$AE4,1)} -> 0 | AD4: {=INDEX('RFR Data - preExcl'!AF$2:AF49,$AE4,1)} -> 0 | AE4: =IFNA(MATCH(Y4,'RFR Data - preExcl'!A$2:A49,0),"") -> 9 | AG4: RUN-NDHM_2022-05-09_RFR-009 | AH4: =VLOOKUP(AG4,'Run Reconcile'!A$2:B49,2,FALSE) -> 44690 | AI4: =COUNTIF('APS Tubes Import'!$V$2:$V49, AG4) -> 8 | AJ4: =COUNTIFS('APS Tubes Import'!V$2:V49, AG4, 'APS Tubes Import'!H$2:H49, "Negative") -> 8 | AK4: =COUNTIFS('APS Tubes Import'!V$2:V49, AG4, 'APS Tubes Import'!H$2:H49, "Positive") -> 0 | AL4: =COUNTIFS('APS Tubes Import'!V$2:V49, AG4, 'APS Tubes Import'!H$2:H49, "Inconclusive") -> 0 | AM4: =COUNTIFS('APS Tubes Import'!V$2:V49, AG4, 'APS Tubes Import'!H$2:H49, "Null") -> 0 | AO4: ='APS Tubes by Date Import'!B3 -> 44689 | AP4: ='APS Tubes by Date Import'!C3 -> 1 | AQ4: ='APS Tubes by Date Import'!D3 -> 1 | AR4: ='APS Tubes by Date Import'!E3 -> 0 | AS4: ='APS Tubes by Date Import'!F3 -> 0 | AT4: ='APS Tubes by Date Import'!G3 -> 0
A5: RUN-NDHM_2022-05-16_RFR-010 | B5: =VLOOKUP(A5,'ALL Tube Results'!$B$2:$D49,2,FALSE) -> 44697 | C5: =COUNTIF('ALL Tube Results'!B4:B49, A5) -> 10 | D5: =COUNTIFS('ALL Tube Results'!$B4:$B49, $A5, 'ALL Tube Results'!$F4:$F49, "Negative") -> 10 | E5: =COUNTIFS('ALL Tube Results'!$B4:$B49, $A5, 'ALL Tube Results'!$F4:$F49, "Positive") -> 0 | F5: =COUNTIFS('ALL Tube Results'!$B4:$B49, $A5, 'ALL Tube Results'!$F4:$F49, "Inconclusive") -> 0 | G5: =IFERROR(VLOOKUP($A5,R$3:T51,3,FALSE),IFERROR(0/0,"") ) -> 10 | H5: =IF($C5=G5,IFERROR(0/0,""),$C5-G5) | I5: =IFERROR(VLOOKUP($A5,Y$3:AA51,3,FALSE),IFERROR(0/0,"") ) -> 10 | J5: =IFERROR(VLOOKUP($A5,Y$3:AD51,5,FALSE),IFERROR(0/0,"") ) -> 0 | K5: =IFERROR(VLOOKUP($A5,Y$3:AD51,6,FALSE),IFERROR(0/0,"")) -> 0 | L5: =IF($C5=I5,IFERROR(0/0,""),$C5-I5) | M5: =IF($E5=J5,IFERROR(0/0,""),$E5-J5) | N5: =IF($F5=K5,IFERROR(0/0,""),$F5-K5) | O5: =IFERROR(VLOOKUP($A5,AG$3:AI51,3,FALSE),IFERROR(0/0,"") ) -> 10 | P5: =IF($C5=O5,IFERROR(0/0,""),$C5-O5) | R5: RUN-NDHM_2022-05-16_RFR-010 | S5: 44697 | T5: =VLOOKUP(R5,'Run Reconcile'!$A$2:$L49,12,FALSE) -> 10 | Y5: =IFERROR(__xludf.DUMMYFUNCTION("""COMPUTED_VALUE"""),"RUN-NDHM_2022-05-16_RFR-010") -> RUN-NDHM_2022-05-16_RFR-010 | Z5: =IFERROR(__xludf.DUMMYFUNCTION("""COMPUTED_VALUE"""),44697.0) -> 44697 | AA5: {=INDEX('RFR Data - preExcl'!AK$2:AK49,$AE5,1)} -> 10 | AB5: =AA5-AC5-AD5 -> 10 | AC5: {=INDEX('RFR Data - preExcl'!AI$2:AI49,$AE5,1)} -> 0 | AD5: {=INDEX('RFR Data - preExcl'!AF$2:AF49,$AE5,1)} -> 0 | AE5: =IFNA(MATCH(Y5,'RFR Data - preExcl'!A$2:A49,0),"") -> 10 | AG5: RUN-NDHM_2022-05-16_RFR-010 | AH5: =VLOOKUP(AG5,'Run Reconcile'!A$2:B49,2,FALSE) -> 44697 | AI5: =COUNTIF('APS Tubes Import'!$V$2:$V49, AG5) -> 10 | AJ5: =COUNTIFS('APS Tubes Import'!V$2:V49, AG5, 'APS Tubes Import'!H$2:H49, "Negative") -> 10 | AK5: =COUNTIFS('APS Tubes Import'!V$2:V49, AG5, 'APS Tubes Import'!H$2:H49, "Positive") -> 0 | AL5: =COUNTIFS('APS Tubes Import'!V$2:V49, AG5, 'APS Tubes Import'!H$2:H49, "Inconclusive") -> 0 | AM5: =COUNTIFS('APS Tubes Import'!V$2:V49, AG5, 'APS Tubes Import'!H$2:H49, "Null") -> 0 | AO5: ='APS Tubes by Date Import'!B4 -> 44690 | AP5: ='APS Tubes by Date Import'!C4 -> 7 | AQ5: ='APS Tubes by Date Import'!D4 -> 7 | AR5: ='APS Tubes by Date Import'!E4 -> 0 | AS5: ='APS Tubes by Date Import'!F4 -> 0 | AT5: ='APS Tubes by Date Import'!G4 -> 0
A6: RUN-NDHM_2022-05-23_RFR-011 | B6: =VLOOKUP(A6,'ALL Tube Results'!$B$2:$D49,2,FALSE) -> 44704 | C6: =COUNTIF('ALL Tube Results'!B5:B49, A6) -> 8 | D6: =COUNTIFS('ALL Tube Results'!$B5:$B49, $A6, 'ALL Tube Results'!$F5:$F49, "Negative") -> 8 | E6: =COUNTIFS('ALL Tube Results'!$B5:$B49, $A6, 'ALL Tube Results'!$F5:$F49, "Positive") -> 0 | F6: =COUNTIFS('ALL Tube Results'!$B5:$B49, $A6, 'ALL Tube Results'!$F5:$F49, "Inconclusive") -> 0 | G6: =IFERROR(VLOOKUP($A6,R$3:T52,3,FALSE),IFERROR(0/0,"") ) -> 8 | H6: =IF($C6=G6,IFERROR(0/0,""),$C6-G6) | I6: =IFERROR(VLOOKUP($A6,Y$3:AA52,3,FALSE),IFERROR(0/0,"") ) -> 8 | J6: =IFERROR(VLOOKUP($A6,Y$3:AD52,5,FALSE),IFERROR(0/0,"") ) -> 0 | K6: =IFERROR(VLOOKUP($A6,Y$3:AD52,6,FALSE),IFERROR(0/0,"")) -> 0 | L6: =IF($C6=I6,IFERROR(0/0,""),$C6-I6) | M6: =IF($E6=J6,IFERROR(0/0,""),$E6-J6) | N6: =IF($F6=K6,IFERROR(0/0,""),$F6-K6) | O6: =IFERROR(VLOOKUP($A6,AG$3:AI52,3,FALSE),IFERROR(0/0,"") ) -> 8 | P6: =IF($C6=O6,IFERROR(0/0,""),$C6-O6) | R6: RUN-NDHM_2022-05-23_RFR-011 | S6: 44704 | T6: =VLOOKUP(R6,'Run Reconcile'!$A$2:$L49,12,FALSE) -> 8 | Y6: =IFERROR(__xludf.DUMMYFUNCTION("""COMPUTED_VALUE"""),"RUN-NDHM_2022-05-23_RFR-011") -> RUN-NDHM_2022-05-23_RFR-011 | Z6: =IFERROR(__xludf.DUMMYFUNCTION("""COMPUTED_VALUE"""),44704.0) -> 44704 | AA6: {=INDEX('RFR Data - preExcl'!AK$2:AK49,$AE6,1)} -> 8 | AB6: =AA6-AC6-AD6 -> 8 | AC6: {=INDEX('RFR Data - preExcl'!AI$2:AI49,$AE6,1)} -> 0 | AD6: {=INDEX('RFR Data - preExcl'!AF$2:AF49,$AE6,1)} -> 0 | AE6: =IFNA(MATCH(Y6,'RFR Data - preExcl'!A$2:A49,0),"") -> 11 | AG6: RUN-NDHM_2022-05-23_RFR-011 | AH6: =VLOOKUP(AG6,'Run Reconcile'!A$2:B49,2,FALSE) -> 44704 | AI6: =COUNTIF('APS Tubes Import'!$V$2:$V49, AG6) -> 8 | AJ6: =COUNTIFS('APS Tubes Import'!V$2:V49, AG6, 'APS Tubes Import'!H$2:H49, "Negative") -> 8 | AK6: =COUNTIFS('APS Tubes Import'!V$2:V49, AG6, 'APS Tubes Import'!H$2:H49, "Positive") -> 0 | AL6: =COUNTIFS('APS Tubes Import'!V$2:V49, AG6, 'APS Tubes Import'!H$2:H49, "Inconclusive") -> 0 | AM6: =COUNTIFS('APS Tubes Import'!V$2:V49, AG6, 'APS Tubes Import'!H$2:H49, "Null") -> 0 | AO6: ='APS Tubes by Date Import'!B5 -> 44696 | AP6: ='APS Tubes by Date Import'!C5 -> 1 | AQ6: ='APS Tubes by Date Import'!D5 -> 1 | AR6: ='APS Tubes by Date Import'!E5 -> 0 | AS6: ='APS Tubes by Date Import'!F5 -> 0 | AT6: ='APS Tubes by Date Import'!G5 -> 0
A7: RUN-NDHM_2022-06-01_RFR-012 | B7: =VLOOKUP(A7,'ALL Tube Results'!$B$2:$D49,2,FALSE) -> 44713 | C7: =COUNTIF('ALL Tube Results'!B6:B49, A7) -> 13 | D7: =COUNTIFS('ALL Tube Results'!$B6:$B49, $A7, 'ALL Tube Results'!$F6:$F49, "Negative") -> 13 | E7: =COUNTIFS('ALL Tube Results'!$B6:$B49, $A7, 'ALL Tube Results'!$F6:$F49, "Positive") -> 0 | F7: =COUNTIFS('ALL Tube Results'!$B6:$B49, $A7, 'ALL Tube Results'!$F6:$F49, "Inconclusive") -> 0 | G7: =IFERROR(VLOOKUP($A7,R$3:T53,3,FALSE),IFERROR(0/0,"") ) -> 13 | H7: =IF($C7=G7,IFERROR(0/0,""),$C7-G7) | I7: =IFERROR(VLOOKUP($A7,Y$3:AA53,3,FALSE),IFERROR(0/0,"") ) -> 14 | J7: =IFERROR(VLOOKUP($A7,Y$3:AD53,5,FALSE),IFERROR(0/0,"") ) -> 0 | K7: =IFERROR(VLOOKUP($A7,Y$3:AD53,6,FALSE),IFERROR(0/0,"")) -> 0 | L7: =IF($C7=I7,IFERROR(0/0,""),$C7-I7) -> -1 | M7: =IF($E7=J7,IFERROR(0/0,""),$E7-J7) | N7: =IF($F7=K7,IFERROR(0/0,""),$F7-K7) | O7: =IFERROR(VLOOKUP($A7,AG$3:AI53,3,FALSE),IFERROR(0/0,"") ) -> 13 | P7: =IF($C7=O7,IFERROR(0/0,""),$C7-O7) | R7: RUN-NDHM_2022-06-01_RFR-012 | S7: 44713 | T7: =VLOOKUP(R7,'Run Reconcile'!$A$2:$L49,12,FALSE) -> 13 | Y7: =IFERROR(__xludf.DUMMYFUNCTION("""COMPUTED_VALUE"""),"RUN-NDHM_2022-06-01_RFR-012") -> RUN-NDHM_2022-06-01_RFR-012 | Z7: =IFERROR(__xludf.DUMMYFUNCTION("""COMPUTED_VALUE"""),44713.0) -> 44713 | AA7: {=INDEX('RFR Data - preExcl'!AK$2:AK49,$AE7,1)} -> 14 | AB7: =AA7-AC7-AD7 -> 14 | AC7: {=INDEX('RFR Data - preExcl'!AI$2:AI49,$AE7,1)} -> 0 | AD7: {=INDEX('RFR Data - preExcl'!AF$2:AF49,$AE7,1)} -> 0 | AE7: =IFNA(MATCH(Y7,'RFR Data - preExcl'!A$2:A49,0),"") -> 12 | AG7: RUN-NDHM_2022-06-01_RFR-012 | AH7: =VLOOKUP(AG7,'Run Reconcile'!A$2:B49,2,FALSE) -> 44713 | AI7: =COUNTIF('APS Tubes Import'!$V$2:$V49, AG7) -> 13 | AJ7: =COUNTIFS('APS Tubes Import'!V$2:V49, AG7, 'APS Tubes Import'!H$2:H49, "Negative") -> 13 | AK7: =COUNTIFS('APS Tubes Import'!V$2:V49, AG7, 'APS Tubes Import'!H$2:H49, "Positive") -> 0 | AL7: =COUNTIFS('APS Tubes Import'!V$2:V49, AG7, 'APS Tubes Import'!H$2:H49, "Inconclusive") -> 0 | AM7: =COUNTIFS('APS Tubes Import'!V$2:V49, AG7, 'APS Tubes Import'!H$2:H49, "Null") -> 0 | AO7: ='APS Tubes by Date Import'!B6 -> 44697 | AP7: ='APS Tubes by Date Import'!C6 -> 9 | AQ7: ='APS Tubes by Date Import'!D6 -> 9 | AR7: ='APS Tubes by Date Import'!E6 -> 0 | AS7: ='APS Tubes by Date Import'!F6 -> 0 | AT7: ='APS Tubes by Date Import'!G6 -> 0
A8: RUN-NDHM_2022-06-06_RFR-013 | B8: =VLOOKUP(A8,'ALL Tube Results'!$B$2:$D49,2,FALSE) -> 44718 | C8: =COUNTIF('ALL Tube Results'!B7:B49, A8) -> 8 | D8: =COUNTIFS('ALL Tube Results'!$B7:$B49, $A8, 'ALL Tube Results'!$F7:$F49, "Negative") -> 8 | E8: =COUNTIFS('ALL Tube Results'!$B7:$B49, $A8, 'ALL Tube Results'!$F7:$F49, "Positive") -> 0 | F8: =COUNTIFS('ALL Tube Results'!$B7:$B49, $A8, 'ALL Tube Results'!$F7:$F49, "Inconclusive") -> 0 | G8: =IFERROR(VLOOKUP($A8,R$3:T54,3,FALSE),IFERROR(0/0,"") ) -> 8 | H8: =IF($C8=G8,IFERROR(0/0,""),$C8-G8) | I8: =IFERROR(VLOOKUP($A8,Y$3:AA54,3,FALSE),IFERROR(0/0,"") ) -> 14 | J8: =IFERROR(VLOOKUP($A8,Y$3:AD54,5,FALSE),IFERROR(0/0,"") ) -> 0 | K8: =IFERROR(VLOOKUP($A8,Y$3:AD54,6,FALSE),IFERROR(0/0,"")) -> 0 | L8: =IF($C8=I8,IFERROR(0/0,""),$C8-I8) -> -6 | M8: =IF($E8=J8,IFERROR(0/0,""),$E8-J8) | N8: =IF($F8=K8,IFERROR(0/0,""),$F8-K8) | O8: =IFERROR(VLOOKUP($A8,AG$3:AI54,3,FALSE),IFERROR(0/0,"") ) -> 7 | P8: =IF($C8=O8,IFERROR(0/0,""),$C8-O8) -> 1 | R8: RUN-NDHM_2022-06-06_RFR-013 | S8: 44718 | T8: =VLOOKUP(R8,'Run Reconcile'!$A$2:$L49,12,FALSE) -> 8 | Y8: =IFERROR(__xludf.DUMMYFUNCTION("""COMPUTED_VALUE"""),"RUN-NDHM_2022-06-06_RFR-013") -> RUN-NDHM_2022-06-06_RFR-013 | Z8: =IFERROR(__xludf.DUMMYFUNCTION("""COMPUTED_VALUE"""),44718.0) -> 44718 | AA8: {=INDEX('RFR Data - preExcl'!AK$2:AK49,$AE8,1)} -> 14 | AB8: =AA8-AC8-AD8 -> 14 | AC8: {=INDEX('RFR Data - preExcl'!AI$2:AI49,$AE8,1)} -> 0 | AD8: {=INDEX('RFR Data - preExcl'!AF$2:AF49,$AE8,1)} -> 0 | AE8: =IFNA(MATCH(Y8,'RFR Data - preExcl'!A$2:A49,0),"") -> 13 | AG8: RUN-NDHM_2022-06-06_RFR-013 | AH8: =VLOOKUP(AG8,'Run Reconcile'!A$2:B49,2,FALSE) -> 44718 | AI8: =COUNTIF('APS Tubes Import'!$V$2:$V49, AG8) -> 7 | AJ8: =COUNTIFS('APS Tubes Import'!V$2:V49, AG8, 'APS Tubes Import'!H$2:H49, "Negative") -> 7 | AK8: =COUNTIFS('APS Tubes Import'!V$2:V49, AG8, 'APS Tubes Import'!H$2:H49, "Positive") -> 0 | AL8: =COUNTIFS('APS Tubes Import'!V$2:V49, AG8, 'APS Tubes Import'!H$2:H49, "Inconclusive") -> 0 | AM8: =COUNTIFS('APS Tubes Import'!V$2:V49, AG8, 'APS Tubes Import'!H$2:H49, "Null") -> 0 | AO8: ='APS Tubes by Date Import'!B7 -> 44704 | AP8: ='APS Tubes by Date Import'!C7 -> 8 | AQ8: ='APS Tubes by Date Import'!D7 -> 8 | AR8: ='APS Tubes by Date Import'!E7 -> 0 | AS8: ='APS Tubes by Date Import'!F7 -> 0 | AT8: ='APS Tubes by Date Import'!G7 -> 0
A9: RUN-NDHM_2022-06-13_RFR-014 | B9: =VLOOKUP(A9,'ALL Tube Results'!$B$2:$D49,2,FALSE) -> 44725 | C9: =COUNTIF('ALL Tube Results'!B8:B49, A9) -> 4 | D9: =COUNTIFS('ALL Tube Results'!$B8:$B49, $A9, 'ALL Tube Results'!$F8:$F49, "Negative") -> 4 | E9: =COUNTIFS('ALL Tube Results'!$B8:$B49, $A9, 'ALL Tube Results'!$F8:$F49, "Positive") -> 0 | F9: =COUNTIFS('ALL Tube Results'!$B8:$B49, $A9, 'ALL Tube Results'!$F8:$F49, "Inconclusive") -> 0 | G9: =IFERROR(VLOOKUP($A9,R$3:T55,3,FALSE),IFERROR(0/0,"") ) -> 4 | H9: =IF($C9=G9,IFERROR(0/0,""),$C9-G9) | I9: =IFERROR(VLOOKUP($A9,Y$3:AA55,3,FALSE),IFERROR(0/0,"") ) -> 4 | J9: =IFERROR(VLOOKUP($A9,Y$3:AD55,5,FALSE),IFERROR(0/0,"") ) -> 0 | K9: =IFERROR(VLOOKUP($A9,Y$3:AD55,6,FALSE),IFERROR(0/0,"")) -> 0 | L9: =IF($C9=I9,IFERROR(0/0,""),$C9-I9) | M9: =IF($E9=J9,IFERROR(0/0,""),$E9-J9) | N9: =IF($F9=K9,IFERROR(0/0,""),$F9-K9) | O9: =IFERROR(VLOOKUP($A9,AG$3:AI55,3,FALSE),IFERROR(0/0,"") ) -> 4 | P9: =IF($C9=O9,IFERROR(0/0,""),$C9-O9) | R9: RUN-NDHM_2022-06-13_RFR-014 | S9: 44725 | T9: =VLOOKUP(R9,'Run Reconcile'!$A$2:$L49,12,FALSE) -> 4 | Y9: =IFERROR(__xludf.DUMMYFUNCTION("""COMPUTED_VALUE"""),"RUN-NDHM_2022-06-13_RFR-014") -> RUN-NDHM_2022-06-13_RFR-014 | Z9: =IFERROR(__xludf.DUMMYFUNCTION("""COMPUTED_VALUE"""),44725.0) -> 44725 | AA9: {=INDEX('RFR Data - preExcl'!AK$2:AK49,$AE9,1)} -> 4 | AB9: =AA9-AC9-AD9 -> 4 | AC9: {=INDEX('RFR Data - preExcl'!AI$2:AI49,$AE9,1)} -> 0 | AD9: {=INDEX('RFR Data - preExcl'!AF$2:AF49,$AE9,1)} -> 0 | AE9: =IFNA(MATCH(Y9,'RFR Data - preExcl'!A$2:A49,0),"") -> 14 | AG9: RUN-NDHM_2022-06-13_RFR-014 | AH9: =VLOOKUP(AG9,'Run Reconcile'!A$2:B49,2,FALSE) -> 44725 | AI9: =COUNTIF('APS Tubes Import'!$V$2:$V49, AG9) -> 4 | AJ9: =COUNTIFS('APS Tubes Import'!V$2:V49, AG9, 'APS Tubes Import'!H$2:H49, "Negative") -> 4 | AK9: =COUNTIFS('APS Tubes Import'!V$2:V49, AG9, 'APS Tubes Import'!H$2:H49, "Positive") -> 0 | AL9: =COUNTIFS('APS Tubes Import'!V$2:V49, AG9, 'APS Tubes Import'!H$2:H49, "Inconclusive") -> 0 | AM9: =COUNTIFS('APS Tubes Import'!V$2:V49, AG9, 'APS Tubes Import'!H$2:H49, "Null") -> 0 | AO9: ='APS Tubes by Date Import'!B8 -> 44712 | AP9: ='APS Tubes by Date Import'!C8 -> 3 | AQ9: ='APS Tubes by Date Import'!D8 -> 3 | AR9: ='APS Tubes by Date Import'!E8 -> 0 | AS9: ='APS Tubes by Date Import'!F8 -> 0 | AT9: ='APS Tubes by Date Import'!G8 -> 0
A10: RUN-NDHM_2022-06-21_RFR-016 | B10: =VLOOKUP(A10,'ALL Tube Results'!$B$2:$D49,2,FALSE) -> 44733 | C10: =COUNTIF('ALL Tube Results'!B9:B49, A10) -> 2 | D10: =COUNTIFS('ALL Tube Results'!$B9:$B49, $A10, 'ALL Tube Results'!$F9:$F49, "Negative") -> 2 | E10: =COUNTIFS('ALL Tube Results'!$B9:$B49, $A10, 'ALL Tube Results'!$F9:$F49, "Positive") -> 0 | F10: =COUNTIFS('ALL Tube Results'!$B9:$B49, $A10, 'ALL Tube Results'!$F9:$F49, "Inconclusive") -> 0 | G10: =IFERROR(VLOOKUP($A10,R$3:T56,3,FALSE),IFERROR(0/0,"") ) -> 2 | H10: =IF($C10=G10,IFERROR(0/0,""),$C10-G10) | I10: =IFERROR(VLOOKUP($A10,Y$3:AA56,3,FALSE),IFERROR(0/0,"") ) -> 2 | J10: =IFERROR(VLOOKUP($A10,Y$3:AD56,5,FALSE),IFERROR(0/0,"") ) -> 0 | K10: =IFERROR(VLOOKUP($A10,Y$3:AD56,6,FALSE),IFERROR(0/0,"")) -> 0 | L10: =IF($C10=I10,IFERROR(0/0,""),$C10-I10) | M10: =IF($E10=J10,IFERROR(0/0,""),$E10-J10) | N10: =IF($F10=K10,IFERROR(0/0,""),$F10-K10) | O10: =IFERROR(VLOOKUP($A10,AG$3:AI56,3,FALSE),IFERROR(0/0,"") ) -> 2 | P10: =IF($C10=O10,IFERROR(0/0,""),$C10-O10) | R10: RUN-NDHM_2022-06-21_RFR-016 | S10: 44733 | T10: =VLOOKUP(R10,'Run Reconcile'!$A$2:$L49,12,FALSE) -> 2 | Y10: =IFERROR(__xludf.DUMMYFUNCTION("""COMPUTED_VALUE"""),"RUN-NDHM_2022-06-21_RFR-016") -> RUN-NDHM_2022-06-21_RFR-016 | Z10: =IFERROR(__xludf.DUMMYFUNCTION("""COMPUTED_VALUE"""),44733.0) -> 44733 | AA10: {=INDEX('RFR Data - preExcl'!AK$2:AK49,$AE10,1)} -> 2 | AB10: =AA10-AC10-AD10 -> 2 | AC10: {=INDEX('RFR Data - preExcl'!AI$2:AI49,$AE10,1)} -> 0 | AD10: {=INDEX('RFR Data - preExcl'!AF$2:AF49,$AE10,1)} -> 0 | AE10: =IFNA(MATCH(Y10,'RFR Data - preExcl'!A$2:A49,0),"") -> 16 | AG10: RUN-NDHM_2022-06-21_RFR-016 | AH10: =VLOOKUP(AG10,'Run Reconcile'!A$2:B49,2,FALSE) -> 44733 | AI10: =COUNTIF('APS Tubes Import'!$V$2:$V49, AG10) -> 2 | AJ10: =COUNTIFS('APS Tubes Import'!V$2:V49, AG10, 'APS Tubes Import'!H$2:H49, "Negative") -> 2 | AK10: =COUNTIFS('APS Tubes Import'!V$2:V49, AG10, 'APS Tubes Import'!H$2:H49, "Positive") -> 0 | AL10: =COUNTIFS('APS Tubes Import'!V$2:V49, AG10, 'APS Tubes Import'!H$2:H49, "Inconclusive") -> 0 | AM10: =COUNTIFS('APS Tubes Import'!V$2:V49, AG10, 'APS Tubes Import'!H$2:H49, "Null") -> 0 | AO10: ='APS Tubes by Date Import'!B9 -> 44713 | AP10: ='APS Tubes by Date Import'!C9 -> 10 | AQ10: ='APS Tubes by Date Import'!D9 -> 10 | AR10: ='APS Tubes by Date Import'!E9 -> 0 | AS10: ='APS Tubes by Date Import'!F9 -> 0 | AT10: ='APS Tubes by Date Import'!G9 -> 0
