Workbook
Name nondeleteRange: #REF!

Sheet Stats
A1: NDHM_RFR_deID_PUB | B1: RFR File
A2: NONE | B2: RTR File
A3: NONE | B3: RSR File | N3: 1-14 1143
B4: Overall | C4: Details | D4: Comments | M4: =COUNTIF(M5:M1019, FALSE) -> 1 | N4: VALUES
A5: =IFERROR(__xludf.DUMMYFUNCTION("IMPORTRANGE($A$1,""Runs Compare!C1"") "),80.0) -> 80 | B5: Number of Tubes Tested (initial only - no re-runs) | C5: initial run tubes only so excludes re-runs | M5: =IF(NOT(ISBLANK(N5)),A5=N5,IFERROR(0/0,"")) -> TRUE | N5: 80
A6: =A5+A17 -> 85 | B6: Number of Tube Tests Run (includes re-runs) | C6: includes re-runs | M6: =IF(NOT(ISBLANK(N6)),A6=N6,IFERROR(0/0,"")) -> TRUE | N6: 85
A7: =IFERROR(__xludf.DUMMYFUNCTION("IMPORTRANGE($A$1,""Runs Compare!B1"") "),15.0) -> 15 | B7: Number of Initial Runs | M7: =IF(NOT(ISBLANK(N7)),A7=N7,IFERROR(0/0,"")) -> TRUE | N7: 15
A8: =IFERROR(__xludf.DUMMYFUNCTION("IMPORTRANGE($A$1,""Run Reconcile!AE1"") "),0.0) -> 0 | B8: Number of APS Only Tubes run | M8: =IF(NOT(ISBLANK(N8)),A8=N8,IFERROR(0/0,"")) -> TRUE | N8: 0
A9: =IFERROR(__xludf.DUMMYFUNCTION("SUM(IMPORTRANGE($A$1,""RFR Data - preExcl!AC2:AC""))+A8 +A8"),109.0) -> 109 | B9: Number of Test Reactions (RFR plus APS only tubes run) | C9: includes technical replicates (the same tube sample in multiple reactions in the same run) | M9: =IF(NOT(ISBLANK(N9)),A9=N9,IFERROR(0/0,"")) -> TRUE | N9: 109
M10: =IF(NOT(ISBLANK(N10)),A10=N10,IFERROR(0/0,""))
A11: =COUNTA(postDEL!A2:A1019) -> 190 | B11: Number of Participant Results | C11: counts individual samples in pools and excludes re-runs | M11: =IF(NOT(ISBLANK(N11)),A11=N11,IFERROR(0/0,"")) -> TRUE | N11: 190
A12: =IFERROR(__xludf.DUMMYFUNCTION("COUNTA(IMPORTRANGE($A$1,""ARF Tubes!M2:M""))"),2.0) -> 2 | B12: Number of ARF Tubes | C12: tubes run and present in RFR but not in Appivo - created tube IDs that start with ARF | M12: =IF(NOT(ISBLANK(N12)),A12=N12,IFERROR(0/0,"")) -> TRUE | N12: 2
A13: =A12+A11 -> 192 | B13: Sum of Participant Results plus ARF Tubes | C13: Will be equal to the number of tubes tested if no pooling. | M13: =IF(NOT(ISBLANK(N13)),A13=N13,IFERROR(0/0,"")) -> TRUE | N13: 192
A14: =A11/(A5-A12) -> 2.4358974 | B14: Average Pool Level (excludes ARF) | M14: =IF(NOT(ISBLANK(N14)),A14=N14,IFERROR(0/0,"")) -> FALSE | N14: 2.4
M15: =IF(NOT(ISBLANK(N15)),A15=N15,IFERROR(0/0,""))
B16: Re-runs | C16: section | M16: =IF(NOT(ISBLANK(N16)),A16=N16,IFERROR(0/0,""))
A17: =IFERROR(__xludf.DUMMYFUNCTION("SUM(IMPORTRANGE($A$1,""Run Reconcile!AB2:AB"")) "),5.0) -> 5 | B17: Number of Run Tubes (re-runs only) | C17: from RFR Audit Num Run Tubes | M17: =IF(NOT(ISBLANK(N17)),A17=N17,IFERROR(0/0,"")) -> TRUE | N17: 5
A18: =IFERROR(__xludf.DUMMYFUNCTION("SUM(IMPORTRANGE($A$1,""Run Reconcile!AA2:AA"")) "),18.0) -> 18 | B18: Number of Reactions (re-runs only) | C18: from RFR Audit Num rxns (excl ctrls) | M18: =IF(NOT(ISBLANK(N18)),A18=N18,IFERROR(0/0,"")) -> TRUE | N18: 18
A19: =A17/A5 -> 0.0625 | B19: Re-run % of Tubes | C19: re-run / initial | M19: =IF(NOT(ISBLANK(N19)),A19=N19,IFERROR(0/0,"")) -> TRUE | N19: 0.0625
A20: =IFERROR(__xludf.DUMMYFUNCTION("IMPORTRANGE($A$1,""Run Reconcile!Z1"")"),3.0) -> 3 | B20: Number of Initial Runs with Re-runs | M20: =IF(NOT(ISBLANK(N20)),A20=N20,IFERROR(0/0,"")) -> TRUE | N20: 3
A21: =A20/A7 -> 0.2 | B21: % Initial Runs with Re-runs | M21: =IF(NOT(ISBLANK(N21)),A21=N21,IFERROR(0/0,"")) -> TRUE | N21: 0.2
M22: =IF(NOT(ISBLANK(N22)),A22=N22,IFERROR(0/0,""))
B23: Positives | C23: section | M23: =IF(NOT(ISBLANK(N23)),A23=N23,IFERROR(0/0,""))
A24: =COUNTIF('Pos and Incl'!H$2:H1019,"Positive") -> 0 | B24: Number of Tubes with Final Result Positive | M24: =IF(NOT(ISBLANK(N24)),A24=N24,IFERROR(0/0,"")) -> TRUE | N24: 0
B25: % of Tubes Positives (Final Result) | M25: =IF(NOT(ISBLANK(N25)),A25=N25,IFERROR(0/0,""))
A26: 0 | B26: Number of Cases with Final Result Positive (Indiv or Pool) | C26: Subtract off Re-tests | M26: =IF(NOT(ISBLANK(N26)),A26=N26,IFERROR(0/0,"")) -> TRUE | N26: 0
A27: 0 | B27: Known Positive Cases | C27: Previous tested (including by FloodLAMP test) or reported positive | M27: =IF(NOT(ISBLANK(N27)),A27=N27,IFERROR(0/0,"")) -> TRUE | N27: 0
A28: =A26-A27 -> 0 | B28: Unknown Positive Cases | M28: =IF(NOT(ISBLANK(N28)),A28=N28,IFERROR(0/0,"")) -> TRUE | N28: 0
M29: =IF(NOT(ISBLANK(N29)),A29=N29,IFERROR(0/0,""))
B30: Inconclusives | C30: section | M30: =IF(NOT(ISBLANK(N30)),A30=N30,IFERROR(0/0,""))
A31: =COUNTIF('Pos and Incl'!H$2:H1019,"Inconclusive") -> 0 | B31: Number of Tubes with Final Result Inconclusive | M31: =IF(NOT(ISBLANK(N31)),A31=N31,IFERROR(0/0,"")) -> TRUE | N31: 0
A32: 0 | B32: Number of Tubes in RFR Audit Inconclusive not in Appivo Final Results | M32: =IF(NOT(ISBLANK(N32)),A32=N32,IFERROR(0/0,"")) -> TRUE | N32: 0
A33: 0 | B33: Total Number of Inconclusive Tubes | M33: =IF(NOT(ISBLANK(N33)),A33=N33,IFERROR(0/0,"")) -> TRUE | N33: 0
B34: % of Tubes Inconclusive | M34: =IF(NOT(ISBLANK(N34)),A34=N34,IFERROR(0/0,""))
A35: 0 | B35: Number of Inconclusive Tubes resolved Positive by Referral Test or Correspondence | M35: =IF(NOT(ISBLANK(N35)),A35=N35,IFERROR(0/0,"")) -> TRUE | N35: 0
A36: =IF(A33<>0,A35/A33,IFERROR(0/0,"")) | B36: % Inconclusives resolved Positive by Referral Tests | M36: =IF(NOT(ISBLANK(N36)),A36=N36,IFERROR(0/0,""))
A37: =A33-A35 -> 0 | B37: Number of Inconclusive Tubes with Referral Test or Correspondence Negative | M37: =IF(NOT(ISBLANK(N37)),A37=N37,IFERROR(0/0,"")) -> TRUE | N37: 0
A38: =A33-A35-A37 -> 0 | B38: Number of Inconclusive Tubes with no Referral Test result or Correspondence | M38: =IF(NOT(ISBLANK(N38)),A38=N38,IFERROR(0/0,"")) -> TRUE | N38: 0
A39: 3 | B39: Number of Tubes with Initial Inconclusives and Re-run Negative | C39: Count Result Correction Code=2.5 in preDel col AJ, or from RFR preExcl if not resulted as Incl in App | M39: =IF(NOT(ISBLANK(N39)),A39=N39,IFERROR(0/0,"")) -> TRUE | N39: 3
A40: 4 | B40: Number of Inconclusive Test Run Calls | C40: includes re-runs - from RFR Audit only and excludes any APS only resulted inconclusives | M40: =IF(NOT(ISBLANK(N40)),A40=N40,IFERROR(0/0,"")) -> TRUE | N40: 4
...

Sheet REF Weekly
A1: =IFERROR(__xludf.DUMMYFUNCTION("IMPORTRANGE(Stats!$A$1,""Weekly!A1:G"")"),"Week Start Date") -> Week Start Date | B1: =IFERROR(__xludf.DUMMYFUNCTION("""COMPUTED_VALUE"""),"Week End Date") -> Week End Date | C1: =IFERROR(__xludf.DUMMYFUNCTION("""COMPUTED_VALUE"""),"Weekly Participants 190") -> Weekly Participants 190 | D1: =IFERROR(__xludf.DUMMYFUNCTION("""COMPUTED_VALUE"""),"Weekly Tubes Run 80") -> Weekly Tubes Run 80 | E1: =IFERROR(__xludf.DUMMYFUNCTION("""COMPUTED_VALUE"""),"Weekly Positive Tubes 0") -> Weekly Positive Tubes 0 | F1: =IFERROR(__xludf.DUMMYFUNCTION("""COMPUTED_VALUE"""),"Weekly Inconclusive Tubes 0") -> Weekly Inconclusive Tubes 0 | G1: =IFERROR(__xludf.DUMMYFUNCTION("""COMPUTED_VALUE"""),"% Positive") -> % Positive
A2: =IFERROR(__xludf.DUMMYFUNCTION("""COMPUTED_VALUE"""),44683.0) -> 44683 | B2: =IFERROR(__xludf.DUMMYFUNCTION("""COMPUTED_VALUE"""),44689.0) -> 44689 | C2: =IFERROR(__xludf.DUMMYFUNCTION("""COMPUTED_VALUE"""),34.0) -> 34 | D2: =IFERROR(__xludf.DUMMYFUNCTION("""COMPUTED_VALUE"""),17.0) -> 17 | E2: =IFERROR(__xludf.DUMMYFUNCTION("""COMPUTED_VALUE"""),0.0) -> 0 | F2: =IFERROR(__xludf.DUMMYFUNCTION("""COMPUTED_VALUE"""),0.0) -> 0 | G2: =IFERROR(__xludf.DUMMYFUNCTION("""COMPUTED_VALUE"""),0.0) -> 0
A3: =IFERROR(__xludf.DUMMYFUNCTION("""COMPUTED_VALUE"""),44690.0) -> 44690 | B3: =IFERROR(__xludf.DUMMYFUNCTION("""COMPUTED_VALUE"""),44696.0) -> 44696 | C3: =IFERROR(__xludf.DUMMYFUNCTION("""COMPUTED_VALUE"""),22.0) -> 22 | D3: =IFERROR(__xludf.DUMMYFUNCTION("""COMPUTED_VALUE"""),9.0) -> 9 | E3: =IFERROR(__xludf.DUMMYFUNCTION("""COMPUTED_VALUE"""),0.0) -> 0 | F3: =IFERROR(__xludf.DUMMYFUNCTION("""COMPUTED_VALUE"""),0.0) -> 0 | G3: =IFERROR(__xludf.DUMMYFUNCTION("""COMPUTED_VALUE"""),0.0) -> 0
A4: =IFERROR(__xludf.DUMMYFUNCTION("""COMPUTED_VALUE"""),44697.0) -> 44697 | B4: =IFERROR(__xludf.DUMMYFUNCTION("""COMPUTED_VALUE"""),44703.0) -> 44703 | C4: =IFERROR(__xludf.DUMMYFUNCTION("""COMPUTED_VALUE"""),26.0) -> 26 | D4: =IFERROR(__xludf.DUMMYFUNCTION("""COMPUTED_VALUE"""),10.0) -> 10 | E4: =IFERROR(__xludf.DUMMYFUNCTION("""COMPUTED_VALUE"""),0.0) -> 0 | F4: =IFERROR(__xludf.DUMMYFUNCTION("""COMPUTED_VALUE"""),0.0) -> 0 | G4: =IFERROR(__xludf.DUMMYFUNCTION("""COMPUTED_VALUE"""),0.0) -> 0
A5: =IFERROR(__xludf.DUMMYFUNCTION("""COMPUTED_VALUE"""),44704.0) -> 44704 | B5: =IFERROR(__xludf.DUMMYFUNCTION("""COMPUTED_VALUE"""),44710.0) -> 44710 | C5: =IFERROR(__xludf.DUMMYFUNCTION("""COMPUTED_VALUE"""),22.0) -> 22 | D5: =IFERROR(__xludf.DUMMYFUNCTION("""COMPUTED_VALUE"""),8.0) -> 8 | E5: =IFERROR(__xludf.DUMMYFUNCTION("""COMPUTED_VALUE"""),0.0) -> 0 | F5: =IFERROR(__xludf.DUMMYFUNCTION("""COMPUTED_VALUE"""),0.0) -> 0 | G5: =IFERROR(__xludf.DUMMYFUNCTION("""COMPUTED_VALUE"""),0.0) -> 0
A6: =IFERROR(__xludf.DUMMYFUNCTION("""COMPUTED_VALUE"""),44711.0) -> 44711 | B6: =IFERROR(__xludf.DUMMYFUNCTION("""COMPUTED_VALUE"""),44717.0) -> 44717 | C6: =IFERROR(__xludf.DUMMYFUNCTION("""COMPUTED_VALUE"""),28.0) -> 28 | D6: =IFERROR(__xludf.DUMMYFUNCTION("""COMPUTED_VALUE"""),13.0) -> 13 | E6: =IFERROR(__xludf.DUMMYFUNCTION("""COMPUTED_VALUE"""),0.0) -> 0 | F6: =IFERROR(__xludf.DUMMYFUNCTION("""COMPUTED_VALUE"""),0.0) -> 0 | G6: =IFERROR(__xludf.DUMMYFUNCTION("""COMPUTED_VALUE"""),0.0) -> 0
A7: =IFERROR(__xludf.DUMMYFUNCTION("""COMPUTED_VALUE"""),44718.0) -> 44718 | B7: =IFERROR(__xludf.DUMMYFUNCTION("""COMPUTED_VALUE"""),44724.0) -> 44724 | C7: =IFERROR(__xludf.DUMMYFUNCTION("""COMPUTED_VALUE"""),19.0) -> 19 | D7: =IFERROR(__xludf.DUMMYFUNCTION("""COMPUTED_VALUE"""),8.0) -> 8 | E7: =IFERROR(__xludf.DUMMYFUNCTION("""COMPUTED_VALUE"""),0.0) -> 0 | F7: =IFERROR(__xludf.DUMMYFUNCTION("""COMPUTED_VALUE"""),0.0) -> 0 | G7: =IFERROR(__xludf.DUMMYFUNCTION("""COMPUTED_VALUE"""),0.0) -> 0
A8: =IFERROR(__xludf.DUMMYFUNCTION("""COMPUTED_VALUE"""),44725.0) -> 44725 | B8: =IFERROR(__xludf.DUMMYFUNCTION("""COMPUTED_VALUE"""),44731.0) -> 44731 | C8: =IFERROR(__xludf.DUMMYFUNCTION("""COMPUTED_VALUE"""),12.0) -> 12 | D8: =IFERROR(__xludf.DUMMYFUNCTION("""COMPUTED_VALUE"""),4.0) -> 4 | E8: =IFERROR(__xludf.DUMMYFUNCTION("""COMPUTED_VALUE"""),0.0) -> 0 | F8: =IFERROR(__xludf.DUMMYFUNCTION("""COMPUTED_VALUE"""),0.0) -> 0 | G8: =IFERROR(__xludf.DUMMYFUNCTION("""COMPUTED_VALUE"""),0.0) -> 0
A9: =IFERROR(__xludf.DUMMYFUNCTION("""COMPUTED_VALUE"""),44732.0) -> 44732 | B9: =IFERROR(__xludf.DUMMYFUNCTION("""COMPUTED_VALUE"""),44738.0) -> 44738 | C9: =IFERROR(__xludf.DUMMYFUNCTION("""COMPUTED_VALUE"""),4.0) -> 4 | D9: =IFERROR(__xludf.DUMMYFUNCTION("""COMPUTED_VALUE"""),2.0) -> 2 | E9: =IFERROR(__xludf.DUMMYFUNCTION("""COMPUTED_VALUE"""),0.0) -> 0 | F9: =IFERROR(__xludf.DUMMYFUNCTION("""COMPUTED_VALUE"""),0.0) -> 0 | G9: =IFERROR(__xludf.DUMMYFUNCTION("""COMPUTED_VALUE"""),0.0) -> 0
A10: =IFERROR(__xludf.DUMMYFUNCTION("""COMPUTED_VALUE"""),44739.0) -> 44739 | B10: =IFERROR(__xludf.DUMMYFUNCTION("""COMPUTED_VALUE"""),44745.0) -> 44745 | C10: =IFERROR(__xludf.DUMMYFUNCTION("""COMPUTED_VALUE"""),3.0) -> 3 | D10: =IFERROR(__xludf.DUMMYFUNCTION("""COMPUTED_VALUE"""),1.0) -> 1 | E10: =IFERROR(__xludf.DUMMYFUNCTION("""COMPUTED_VALUE"""),0.0) -> 0 | F10: =IFERROR(__xludf.DUMMYFUNCTION("""COMPUTED_VALUE"""),0.0) -> 0 | G10: =IFERROR(__xludf.DUMMYFUNCTION("""COMPUTED_VALUE"""),0.0) -> 0
A11: =IFERROR(__xludf.DUMMYFUNCTION("""COMPUTED_VALUE"""),44746.0) -> 44746 | B11: =IFERROR(__xludf.DUMMYFUNCTION("""COMPUTED_VALUE"""),44752.0) -> 44752 | C11: =IFERROR(__xludf.DUMMYFUNCTION("""COMPUTED_VALUE"""),0.0) -> 0 | D11: =IFERROR(__xludf.DUMMYFUNCTION("""COMPUTED_VALUE"""),0.0) -> 0 | E11: =IFERROR(__xludf.DUMMYFUNCTION("""COMPUTED_VALUE"""),0.0) -> 0 | F11: =IFERROR(__xludf.DUMMYFUNCTION("""COMPUTED_VALUE"""),0.0) -> 0
A12: =IFERROR(__xludf.DUMMYFUNCTION("""COMPUTED_VALUE"""),44753.0) -> 44753 | B12: =IFERROR(__xludf.DUMMYFUNCTION("""COMPUTED_VALUE"""),44759.0) -> 44759 | C12: =IFERROR(__xludf.DUMMYFUNCTION("""COMPUTED_VALUE"""),2.0) -> 2 | D12: =IFERROR(__xludf.DUMMYFUNCTION("""COMPUTED_VALUE"""),1.0) -> 1 | E12: =IFERROR(__xludf.DUMMYFUNCTION("""COMPUTED_VALUE"""),0.0) -> 0 | F12: =IFERROR(__xludf.DUMMYFUNCTION("""COMPUTED_VALUE"""),0.0) -> 0 | G12: =IFERROR(__xludf.DUMMYFUNCTION("""COMPUTED_VALUE"""),0.0) -> 0
A13: =IFERROR(__xludf.DUMMYFUNCTION("""COMPUTED_VALUE"""),44760.0) -> 44760 | B13: =IFERROR(__xludf.DUMMYFUNCTION("""COMPUTED_VALUE"""),44766.0) -> 44766 | C13: =IFERROR(__xludf.DUMMYFUNCTION("""COMPUTED_VALUE"""),2.0) -> 2 | D13: =IFERROR(__xludf.DUMMYFUNCTION("""COMPUTED_VALUE"""),1.0) -> 1 | E13: =IFERROR(__xludf.DUMMYFUNCTION("""COMPUTED_VALUE"""),0.0) -> 0 | F13: =IFERROR(__xludf.DUMMYFUNCTION("""COMPUTED_VALUE"""),0.0) -> 0 | G13: =IFERROR(__xludf.DUMMYFUNCTION("""COMPUTED_VALUE"""),0.0) -> 0
A14: =IFERROR(__xludf.DUMMYFUNCTION("""COMPUTED_VALUE"""),44767.0) -> 44767 | B14: =IFERROR(__xludf.DUMMYFUNCTION("""COMPUTED_VALUE"""),44773.0) -> 44773 | C14: =IFERROR(__xludf.DUMMYFUNCTION("""COMPUTED_VALUE"""),6.0) -> 6 | D14: =IFERROR(__xludf.DUMMYFUNCTION("""COMPUTED_VALUE"""),3.0) -> 3 | E14: =IFERROR(__xludf.DUMMYFUNCTION("""COMPUTED_VALUE"""),0.0) -> 0 | F14: =IFERROR(__xludf.DUMMYFUNCTION("""COMPUTED_VALUE"""),0.0) -> 0 | G14: =IFERROR(__xludf.DUMMYFUNCTION("""COMPUTED_VALUE"""),0.0) -> 0
A15: =IFERROR(__xludf.DUMMYFUNCTION("""COMPUTED_VALUE"""),44774.0) -> 44774 | B15: =IFERROR(__xludf.DUMMYFUNCTION("""COMPUTED_VALUE"""),44780.0) -> 44780 | C15: =IFERROR(__xludf.DUMMYFUNCTION("""COMPUTED_VALUE"""),3.0) -> 3 | D15: =IFERROR(__xludf.DUMMYFUNCTION("""COMPUTED_VALUE"""),1.0) -> 1 | E15: =IFERROR(__xludf.DUMMYFUNCTION("""COMPUTED_VALUE"""),0.0) -> 0 | F15: =IFERROR(__xludf.DUMMYFUNCTION("""COMPUTED_VALUE"""),0.0) -> 0 | G15: =IFERROR(__xludf.DUMMYFUNCTION("""COMPUTED_VALUE"""),0.0) -> 0
A16: =IFERROR(__xludf.DUMMYFUNCTION("""COMPUTED_VALUE"""),44781.0) -> 44781 | B16: =IFERROR(__xludf.DUMMYFUNCTION("""COMPUTED_VALUE"""),44787.0) -> 44787 | C16: =IFERROR(__xludf.DUMMYFUNCTION("""COMPUTED_VALUE"""),0.0) -> 0 | D16: =IFERROR(__xludf.DUMMYFUNCTION("""COMPUTED_VALUE"""),0.0) -> 0 | E16: =IFERROR(__xludf.DUMMYFUNCTION("""COMPUTED_VALUE"""),0.0) -> 0 | F16: =IFERROR(__xludf.DUMMYFUNCTION("""COMPUTED_VALUE"""),0.0) -> 0
A17: =IFERROR(__xludf.DUMMYFUNCTION("""COMPUTED_VALUE"""),44788.0) -> 44788 | B17: =IFERROR(__xludf.DUMMYFUNCTION("""COMPUTED_VALUE"""),44794.0) -> 44794 | C17: =IFERROR(__xludf.DUMMYFUNCTION("""COMPUTED_VALUE"""),0.0) -> 0 | D17: =IFERROR(__xludf.DUMMYFUNCTION("""COMPUTED_VALUE"""),0.0) -> 0 | E17: =IFERROR(__xludf.DUMMYFUNCTION("""COMPUTED_VALUE"""),0.0) -> 0 | F17: =IFERROR(__xludf.DUMMYFUNCTION("""COMPUTED_VALUE"""),0.0) -> 0
A18: =IFERROR(__xludf.DUMMYFUNCTION("""COMPUTED_VALUE"""),44795.0) -> 44795 | B18: =IFERROR(__xludf.DUMMYFUNCTION("""COMPUTED_VALUE"""),44801.0) -> 44801 | C18: =IFERROR(__xludf.DUMMYFUNCTION("""COMPUTED_VALUE"""),0.0) -> 0 | D18: =IFERROR(__xludf.DUMMYFUNCTION("""COMPUTED_VALUE"""),0.0) -> 0 | E18: =IFERROR(__xludf.DUMMYFUNCTION("""COMPUTED_VALUE"""),0.0) -> 0 | F18: =IFERROR(__xludf.DUMMYFUNCTION("""COMPUTED_VALUE"""),0.0) -> 0
A19: =IFERROR(__xludf.DUMMYFUNCTION("""COMPUTED_VALUE"""),44802.0) -> 44802 | B19: =IFERROR(__xludf.DUMMYFUNCTION("""COMPUTED_VALUE"""),44808.0) -> 44808 | C19: =IFERROR(__xludf.DUMMYFUNCTION("""COMPUTED_VALUE"""),0.0) -> 0 | D19: =IFERROR(__xludf.DUMMYFUNCTION("""COMPUTED_VALUE"""),0.0) -> 0 | E19: =IFERROR(__xludf.DUMMYFUNCTION("""COMPUTED_VALUE"""),0.0) -> 0 | F19: =IFERROR(__xludf.DUMMYFUNCTION("""COMPUTED_VALUE"""),0.0) -> 0
A20: =IFERROR(__xludf.DUMMYFUNCTION("""COMPUTED_VALUE"""),44809.0) -> 44809 | B20: =IFERROR(__xludf.DUMMYFUNCTION("""COMPUTED_VALUE"""),44815.0) -> 44815 | C20: =IFERROR(__xludf.DUMMYFUNCTION("""COMPUTED_VALUE"""),0.0) -> 0 | D20: =IFERROR(__xludf.DUMMYFUNCTION("""COMPUTED_VALUE"""),0.0) -> 0 | E20: =IFERROR(__xludf.DUMMYFUNCTION("""COMPUTED_VALUE"""),0.0) -> 0 | F20: =IFERROR(__xludf.DUMMYFUNCTION("""COMPUTED_VALUE"""),0.0) -> 0
A21: =IFERROR(__xludf.DUMMYFUNCTION("""COMPUTED_VALUE"""),44816.0) -> 44816 | B21: =IFERROR(__xludf.DUMMYFUNCTION("""COMPUTED_VALUE"""),44822.0) -> 44822 | C21: =IFERROR(__xludf.DUMMYFUNCTION("""COMPUTED_VALUE"""),4.0) -> 4 | D21: =IFERROR(__xludf.DUMMYFUNCTION("""COMPUTED_VALUE"""),1.0) -> 1 | E21: =IFERROR(__xludf.DUMMYFUNCTION("""COMPUTED_VALUE"""),0.0) -> 0 | F21: =IFERROR(__xludf.DUMMYFUNCTION("""COMPUTED_VALUE"""),0.0) -> 0 | G21: =IFERROR(__xludf.DUMMYFUNCTION("""COMPUTED_VALUE"""),0.0) -> 0
A22: =IFERROR(__xludf.DUMMYFUNCTION("""COMPUTED_VALUE"""),44823.0) -> 44823 | B22: =IFERROR(__xludf.DUMMYFUNCTION("""COMPUTED_VALUE"""),44829.0) -> 44829 | C22: =IFERROR(__xludf.DUMMYFUNCTION("""COMPUTED_VALUE"""),0.0) -> 0 | D22: =IFERROR(__xludf.DUMMYFUNCTION("""COMPUTED_VALUE"""),0.0) -> 0 | E22: =IFERROR(__xludf.DUMMYFUNCTION("""COMPUTED_VALUE"""),0.0) -> 0 | F22: =IFERROR(__xludf.DUMMYFUNCTION("""COMPUTED_VALUE"""),0.0) -> 0
A23: =IFERROR(__xludf.DUMMYFUNCTION("""COMPUTED_VALUE"""),44830.0) -> 44830 | B23: =IFERROR(__xludf.DUMMYFUNCTION("""COMPUTED_VALUE"""),44836.0) -> 44836 | C23: =IFERROR(__xludf.DUMMYFUNCTION("""COMPUTED_VALUE"""),0.0) -> 0 | D23: =IFERROR(__xludf.DUMMYFUNCTION("""COMPUTED_VALUE"""),0.0) -> 0 | E23: =IFERROR(__xludf.DUMMYFUNCTION("""COMPUTED_VALUE"""),0.0) -> 0 | F23: =IFERROR(__xludf.DUMMYFUNCTION("""COMPUTED_VALUE"""),0.0) -> 0
A24: =IFERROR(__xludf.DUMMYFUNCTION("""COMPUTED_VALUE"""),44837.0) -> 44837 | B24: =IFERROR(__xludf.DUMMYFUNCTION("""COMPUTED_VALUE"""),44843.0) -> 44843 | C24: =IFERROR(__xludf.DUMMYFUNCTION("""COMPUTED_VALUE"""),3.0) -> 3 | D24: =IFERROR(__xludf.DUMMYFUNCTION("""COMPUTED_VALUE"""),1.0) -> 1 | E24: =IFERROR(__xludf.DUMMYFUNCTION("""COMPUTED_VALUE"""),0.0) -> 0 | F24: =IFERROR(__xludf.DUMMYFUNCTION("""COMPUTED_VALUE"""),0.0) -> 0 | G24: =IFERROR(__xludf.DUMMYFUNCTION("""COMPUTED_VALUE"""),0.0) -> 0

Sheet Pos and Incl
A1: {='APS Tubes'!A1:O1} -> TUBE ID | B1: COLLECTION DATE | C1: COLLECTION TIME | D1: SPONSOR PERSON ID | E1: SPONSOR FIRSTNAME | F1: SPONSOR LASTNAME | G1: APP RESULT | H1: FINAL RESULT | I1: RESULT DATE | J1: RESULT TIME | K1: Result Correct Code | L1: Correction Notes | M1: NOTE | N1: NUM SAMPLES (Pool Level) | O1: Match Row in APS Data PHI - postDEL | P1: Sample Person1 | Q1: Sample Person2 | R1: Sample Person3 | S1: Sample Person4 | T1: CaseC ID | U1: First FL Positive of Case? | V1: Referral Test Result | W1: Referral Notes
Q2: {=IF($N2>1, INDEX(postDEL!$A$2:$AR4717,$O2+1,44),IFERROR(0/0,""))} | R2: {=IF($N2>2, INDEX(postDEL!$A$2:$AR4717,$O2+2,44),IFERROR(0/0,""))} | S2: {=IF($N2>3, INDEX(postDEL!$A$2:$AR4717,$O2+3,44),IFERROR(0/0,""))}
Q3: {=IF($N3>1, INDEX(postDEL!$A$2:$AR4717,$O3+1,44),IFERROR(0/0,""))} | R3: {=IF($N3>2, INDEX(postDEL!$A$2:$AR4717,$O3+2,44),IFERROR(0/0,""))} | S3: {=IF($N3>3, INDEX(postDEL!$A$2:$AR4717,$O3+3,44),IFERROR(0/0,""))}
Q4: {=IF($N4>1, INDEX(postDEL!$A$2:$AR4717,$O4+1,44),IFERROR(0/0,""))} | R4: {=IF($N4>2, INDEX(postDEL!$A$2:$AR4717,$O4+2,44),IFERROR(0/0,""))} | S4: {=IF($N4>3, INDEX(postDEL!$A$2:$AR4717,$O4+3,44),IFERROR(0/0,""))}
Q5: {=IF($N5>1, INDEX(postDEL!$A$2:$AR4717,$O5+1,44),IFERROR(0/0,""))} | R5: {=IF($N5>2, INDEX(postDEL!$A$2:$AR4717,$O5+2,44),IFERROR(0/0,""))} | S5: {=IF($N5>3, INDEX(postDEL!$A$2:$AR4717,$O5+3,44),IFERROR(0/0,""))}
Q6: {=IF($N6>1, INDEX(postDEL!$A$2:$AR4717,$O6+1,44),IFERROR(0/0,""))} | R6: {=IF($N6>2, INDEX(postDEL!$A$2:$AR4717,$O6+2,44),IFERROR(0/0,""))} | S6: {=IF($N6>3, INDEX(postDEL!$A$2:$AR4717,$O6+3,44),IFERROR(0/0,""))}
Q7: {=IF($N7>1, INDEX(postDEL!$A$2:$AR4717,$O7+1,44),IFERROR(0/0,""))} | R7: {=IF($N7>2, INDEX(postDEL!$A$2:$AR4717,$O7+2,44),IFERROR(0/0,""))} | S7: {=IF($N7>3, INDEX(postDEL!$A$2:$AR4717,$O7+3,44),IFERROR(0/0,""))}
A8: No Positive or Inconclusive tubes | Q8: {=IF($N8>1, INDEX(postDEL!$A$2:$AR4717,$O8+1,44),IFERROR(0/0,""))} | R8: {=IF($N8>2, INDEX(postDEL!$A$2:$AR4717,$O8+2,44),IFERROR(0/0,""))} | S8: {=IF($N8>3, INDEX(postDEL!$A$2:$AR4717,$O8+3,44),IFERROR(0/0,""))}
Q9: {=IF($N9>1, INDEX(postDEL!$A$2:$AR4717,$O9+1,44),IFERROR(0/0,""))} | R9: {=IF($N9>2, INDEX(postDEL!$A$2:$AR4717,$O9+2,44),IFERROR(0/0,""))} | S9: {=IF($N9>3, INDEX(postDEL!$A$2:$AR4717,$O9+3,44),IFERROR(0/0,""))}
Q10: {=IF($N10>1, INDEX(postDEL!$A$2:$AR4717,$O10+1,44),IFERROR(0/0,""))} | R10: {=IF($N10>2, INDEX(postDEL!$A$2:$AR4717,$O10+2,44),IFERROR(0/0,""))} | S10: {=IF($N10>3, INDEX(postDEL!$A$2:$AR4717,$O10+3,44),IFERROR(0/0,""))}
Q11: {=IF($N11>1, INDEX(postDEL!$A$2:$AR4717,$O11+1,44),IFERROR(0/0,""))} | R11: {=IF($N11>2, INDEX(postDEL!$A$2:$AR4717,$O11+2,44),IFERROR(0/0,""))} | S11: {=IF($N11>3, INDEX(postDEL!$A$2:$AR4717,$O11+3,44),IFERROR(0/0,""))}
Q12: {=IF($N12>1, INDEX(postDEL!$A$2:$AR4717,$O12+1,44),IFERROR(0/0,""))} | R12: {=IF($N12>2, INDEX(postDEL!$A$2:$AR4717,$O12+2,44),IFERROR(0/0,""))} | S12: {=IF($N12>3, INDEX(postDEL!$A$2:$AR4717,$O12+3,44),IFERROR(0/0,""))}
Q13: {=IF($N13>1, INDEX(postDEL!$A$2:$AR4717,$O13+1,44),IFERROR(0/0,""))} | R13: {=IF($N13>2, INDEX(postDEL!$A$2:$AR4717,$O13+2,44),IFERROR(0/0,""))} | S13: {=IF($N13>3, INDEX(postDEL!$A$2:$AR4717,$O13+3,44),IFERROR(0/0,""))}
Q14: {=IF($N14>1, INDEX(postDEL!$A$2:$AR4717,$O14+1,44),IFERROR(0/0,""))} | R14: {=IF($N14>2, INDEX(postDEL!$A$2:$AR4717,$O14+2,44),IFERROR(0/0,""))} | S14: {=IF($N14>3, INDEX(postDEL!$A$2:$AR4717,$O14+3,44),IFERROR(0/0,""))}
Q15: {=IF($N15>1, INDEX(postDEL!$A$2:$AR4717,$O15+1,44),IFERROR(0/0,""))} | R15: {=IF($N15>2, INDEX(postDEL!$A$2:$AR4717,$O15+2,44),IFERROR(0/0,""))} | S15: {=IF($N15>3, INDEX(postDEL!$A$2:$AR4717,$O15+3,44),IFERROR(0/0,""))}
Q16: {=IF($N16>1, INDEX(postDEL!$A$2:$AR4717,$O16+1,44),IFERROR(0/0,""))} | R16: {=IF($N16>2, INDEX(postDEL!$A$2:$AR4717,$O16+2,44),IFERROR(0/0,""))} | S16: {=IF($N16>3, INDEX(postDEL!$A$2:$AR4717,$O16+3,44),IFERROR(0/0,""))}
Q17: {=IF($N17>1, INDEX(postDEL!$A$2:$AR4717,$O17+1,44),IFERROR(0/0,""))} | R17: {=IF($N17>2, INDEX(postDEL!$A$2:$AR4717,$O17+2,44),IFERROR(0/0,""))} | S17: {=IF($N17>3, INDEX(postDEL!$A$2:$AR4717,$O17+3,44),IFERROR(0/0,""))}
Q18: {=IF($N18>1, INDEX(postDEL!$A$2:$AR4717,$O18+1,44),IFERROR(0/0,""))} | R18: {=IF($N18>2, INDEX(postDEL!$A$2:$AR4717,$O18+2,44),IFERROR(0/0,""))} | S18: {=IF($N18>3, INDEX(postDEL!$A$2:$AR4717,$O18+3,44),IFERROR(0/0,""))}
Q19: {=IF($N19>1, INDEX(postDEL!$A$2:$AR4717,$O19+1,44),IFERROR(0/0,""))} | R19: {=IF($N19>2, INDEX(postDEL!$A$2:$AR4717,$O19+2,44),IFERROR(0/0,""))} | S19: {=IF($N19>3, INDEX(postDEL!$A$2:$AR4717,$O19+3,44),IFERROR(0/0,""))}
Q20: {=IF($N20>1, INDEX(postDEL!$A$2:$AR4717,$O20+1,44),IFERROR(0/0,""))} | R20: {=IF($N20>2, INDEX(postDEL!$A$2:$AR4717,$O20+2,44),IFERROR(0/0,""))} | S20: {=IF($N20>3, INDEX(postDEL!$A$2:$AR4717,$O20+3,44),IFERROR(0/0,""))}
Q21: {=IF($N21>1, INDEX(postDEL!$A$2:$AR4717,$O21+1,44),IFERROR(0/0,""))} | R21: {=IF($N21>2, INDEX(postDEL!$A$2:$AR4717,$O21+2,44),IFERROR(0/0,""))} | S21: {=IF($N21>3, INDEX(postDEL!$A$2:$AR4717,$O21+3,44),IFERROR(0/0,""))}
Q22: {=IF($N22>1, INDEX(postDEL!$A$2:$AR4717,$O22+1,44),IFERROR(0/0,""))} | R22: {=IF($N22>2, INDEX(postDEL!$A$2:$AR4717,$O22+2,44),IFERROR(0/0,""))} | S22: {=IF($N22>3, INDEX(postDEL!$A$2:$AR4717,$O22+3,44),IFERROR(0/0,""))}
Q23: {=IF($N23>1, INDEX(postDEL!$A$2:$AR4717,$O23+1,44),IFERROR(0/0,""))} | R23: {=IF($N23>2, INDEX(postDEL!$A$2:$AR4717,$O23+2,44),IFERROR(0/0,""))} | S23: {=IF($N23>3, INDEX(postDEL!$A$2:$AR4717,$O23+3,44),IFERROR(0/0,""))}
Q24: {=IF($N24>1, INDEX(postDEL!$A$2:$AR4717,$O24+1,44),IFERROR(0/0,""))} | R24: {=IF($N24>2, INDEX(postDEL!$A$2:$AR4717,$O24+2,44),IFERROR(0/0,""))} | S24: {=IF($N24>3, INDEX(postDEL!$A$2:$AR4717,$O24+3,44),IFERROR(0/0,""))}
Q25: {=IF($N25>1, INDEX(postDEL!$A$2:$AR4717,$O25+1,44),IFERROR(0/0,""))} | R25: {=IF($N25>2, INDEX(postDEL!$A$2:$AR4717,$O25+2,44),IFERROR(0/0,""))} | S25: {=IF($N25>3, INDEX(postDEL!$A$2:$AR4717,$O25+3,44),IFERROR(0/0,""))}
Q26: {=IF($N26>1, INDEX(postDEL!$A$2:$AR4717,$O26+1,44),IFERROR(0/0,""))} | R26: {=IF($N26>2, INDEX(postDEL!$A$2:$AR4717,$O26+2,44),IFERROR(0/0,""))} | S26: {=IF($N26>3, INDEX(postDEL!$A$2:$AR4717,$O26+3,44),IFERROR(0/0,""))}
Q27: {=IF($N27>1, INDEX(postDEL!$A$2:$AR4717,$O27+1,44),IFERROR(0/0,""))} | R27: {=IF($N27>2, INDEX(postDEL!$A$2:$AR4717,$O27+2,44),IFERROR(0/0,""))} | S27: {=IF($N27>3, INDEX(postDEL!$A$2:$AR4717,$O27+3,44),IFERROR(0/0,""))}
Q28: {=IF($N28>1, INDEX(postDEL!$A$2:$AR4717,$O28+1,44),IFERROR(0/0,""))} | R28: {=IF($N28>2, INDEX(postDEL!$A$2:$AR4717,$O28+2,44),IFERROR(0/0,""))} | S28: {=IF($N28>3, INDEX(postDEL!$A$2:$AR4717,$O28+3,44),IFERROR(0/0,""))}
Q29: {=IF($N29>1, INDEX(postDEL!$A$2:$AR4717,$O29+1,44),IFERROR(0/0,""))} | R29: {=IF($N29>2, INDEX(postDEL!$A$2:$AR4717,$O29+2,44),IFERROR(0/0,""))} | S29: {=IF($N29>3, INDEX(postDEL!$A$2:$AR4717,$O29+3,44),IFERROR(0/0,""))}
Q30: {=IF($N30>1, INDEX(postDEL!$A$2:$AR4717,$O30+1,44),IFERROR(0/0,""))} | R30: {=IF($N30>2, INDEX(postDEL!$A$2:$AR4717,$O30+2,44),IFERROR(0/0,""))} | S30: {=IF($N30>3, INDEX(postDEL!$A$2:$AR4717,$O30+3,44),IFERROR(0/0,""))}
Q31: {=IF($N31>1, INDEX(postDEL!$A$2:$AR4717,$O31+1,44),IFERROR(0/0,""))} | R31: {=IF($N31>2, INDEX(postDEL!$A$2:$AR4717,$O31+2,44),IFERROR(0/0,""))} | S31: {=IF($N31>3, INDEX(postDEL!$A$2:$AR4717,$O31+3,44),IFERROR(0/0,""))}
Q32: {=IF($N32>1, INDEX(postDEL!$A$2:$AR4717,$O32+1,44),IFERROR(0/0,""))} | R32: {=IF($N32>2, INDEX(postDEL!$A$2:$AR4717,$O32+2,44),IFERROR(0/0,""))} | S32: {=IF($N32>3, INDEX(postDEL!$A$2:$AR4717,$O32+3,44),IFERROR(0/0,""))}
Q33: {=IF($N33>1, INDEX(postDEL!$A$2:$AR4717,$O33+1,44),IFERROR(0/0,""))} | R33: {=IF($N33>2, INDEX(postDEL!$A$2:$AR4717,$O33+2,44),IFERROR(0/0,""))} | S33: {=IF($N33>3, INDEX(postDEL!$A$2:$AR4717,$O33+3,44),IFERROR(0/0,""))}
Q34: {=IF($N34>1, INDEX(postDEL!$A$2:$AR4717,$O34+1,44),IFERROR(0/0,""))} | R34: {=IF($N34>2, INDEX(postDEL!$A$2:$AR4717,$O34+2,44),IFERROR(0/0,""))} | S34: {=IF($N34>3, INDEX(postDEL!$A$2:$AR4717,$O34+3,44),IFERROR(0/0,""))}
Q35: {=IF($N35>1, INDEX(postDEL!$A$2:$AR4717,$O35+1,44),IFERROR(0/0,""))} | R35: {=IF($N35>2, INDEX(postDEL!$A$2:$AR4717,$O35+2,44),IFERROR(0/0,""))} | S35: {=IF($N35>3, INDEX(postDEL!$A$2:$AR4717,$O35+3,44),IFERROR(0/0,""))}
Q36: {=IF($N36>1, INDEX(postDEL!$A$2:$AR4717,$O36+1,44),IFERROR(0/0,""))} | R36: {=IF($N36>2, INDEX(postDEL!$A$2:$AR4717,$O36+2,44),IFERROR(0/0,""))} | S36: {=IF($N36>3, INDEX(postDEL!$A$2:$AR4717,$O36+3,44),IFERROR(0/0,""))}
Q37: {=IF($N37>1, INDEX(postDEL!$A$2:$AR4717,$O37+1,44),IFERROR(0/0,""))} | R37: {=IF($N37>2, INDEX(postDEL!$A$2:$AR4717,$O37+2,44),IFERROR(0/0,""))} | S37: {=IF($N37>3, INDEX(postDEL!$A$2:$AR4717,$O37+3,44),IFERROR(0/0,""))}
Q38: {=IF($N38>1, INDEX(postDEL!$A$2:$AR4717,$O38+1,44),IFERROR(0/0,""))} | R38: {=IF($N38>2, INDEX(postDEL!$A$2:$AR4717,$O38+2,44),IFERROR(0/0,""))} | S38: {=IF($N38>3, INDEX(postDEL!$A$2:$AR4717,$O38+3,44),IFERROR(0/0,""))}
Q39: {=IF($N39>1, INDEX(postDEL!$A$2:$AR4717,$O39+1,44),IFERROR(0/0,""))} | R39: {=IF($N39>2, INDEX(postDEL!$A$2:$AR4717,$O39+2,44),IFERROR(0/0,""))} | S39: {=IF($N39>3, INDEX(postDEL!$A$2:$AR4717,$O39+3,44),IFERROR(0/0,""))}
Q40: {=IF($N40>1, INDEX(postDEL!$A$2:$AR4717,$O40+1,44),IFERROR(0/0,""))} | R40: {=IF($N40>2, INDEX(postDEL!$A$2:$AR4717,$O40+2,44),IFERROR(0/0,""))} | S40: {=IF($N40>3, INDEX(postDEL!$A$2:$AR4717,$O40+3,44),IFERROR(0/0,""))}
...

Sheet preDEL
A1: TUBE ID | B1: COLLECTION DATE | C1: COLLECTION TIME | D1: SPONSOR FIRSTNAME | E1: SPONSOR LASTNAME | F1: PARTICIPANT FIRSTNAME | G1: PARTICIPANT LASTNAME | H1: PARTICIPANT EMAIL | I1: MINOR FIRSTNAME | J1: MINOR LASTNAME | K1: APP RESULT | L1: RESULT DATE | M1: RESULT TIME | N1: APP GROUP | O1: NOTE | P1: REPS IN RAW_APT? | Q1: STATUS | R1: Tube ID First Row? | S1: Num Tube IDs | T1: Add N Names | U1: NOTE FIRSTNAME | V1: NOTE LASTNAME | W1: Names Adjust | X1: =IF(ISNA(MATCH("ER - LAST ONLY",$X$2:$X264,0)),"Note Name?","ERROR!! Note Name?") -> Note Name? | Y1: FRAN | Z1: >4 Samples | AA1: Has Note? | AB1: Preserve Note | AC1: Initial Order | AD1: Added from APT? | AE1: Minutes Col to Result | AF1: =IF(COUNTIF($AF2:$AF264,TRUE)=0,"Tube IDs w Diff Times?",CONCATENATE("ERROR!! Tube IDs w Diff Times? ",COUNTIF($AF2:$AF264,TRUE))) -> Tube IDs w Diff Times? | AG1: Delete? | AH1: Delete Code | AI1: Basic Correct Code | AJ1: Result Correct Code | AK1: FINAL RESULT | AL1: Correction Notes | AM1: Sponsor ID | AN1: Participant ID | AO1: Sponsor FullName | AP1: Combined Participant Firstname | AQ1: Combined Participant Lastname | AR1: Combined Participant Fullname | AS1: FINAL GROUP | AT1: =(IF(COUNTIF($AT2:$AT264,FALSE)=0,"NAME COLS CHECK?",CONCATENATE("ERROR!! NAME COLS CHECK? ",COUNTIF($AT2:$AT264,FALSE)))) -> ERROR!! NAME COLS CHECK? 182 | AU1: PARTCIP NAME COLS | AV1: MINOR NAME COLS | AW1: NOTE NAME COLS | AX1: Note Name Extras - Rows Added Not Orig Tube ID Row | AY1: =SUM($AX2:$AX264) -> 7 | AZ1: END | BA1: =CONCATENATE("CURRENT BOOL TRUE = ",COUNTIF(BA$2:BA264,TRUE)) -> CURRENT BOOL TRUE = 0 | BB1: CURRENT BOOL History1 | BC1: CURRENT BOOL History2 | BD1: Rep Cols | BE1: =CONCATENATE("Rep Tube IDs Sorted = ",COUNTA(BL3:BL264)) -> Rep Tube IDs Sorted = 0 | BF1: 3 Num Rep Rows | BG1: 1 Tube Samecols Not Deleted | BH1: 3 Tube ID in Reps? | BI1: 2 SORTED Tube Timestamp | BJ1: 2 TUBE ID ONLY | BK1: 2 Replicate Tube ID? (First Row) | BL1: 2 Rep Tube IDs Not Sorted | BM1: END | BN1: =CONCATENATE("Blank or Whitespace ", COUNTIF(BN2:BN264, TRUE)) -> Blank or Whitespace 190 | BO1: =CONCATENATE("Blank ", COUNTIF(BO2:BO264, TRUE)) -> Blank 0 | BP1: =CONCATENATE("Whitespace ", COUNTIF(BP2:BP264, TRUE)) -> Whitespace 190 | BR1: pre-Sync Values FINAL RESULT | BS1: =COUNTIF(BS2:BS264,FALSE) -> 0
A2: AH8765 | B2: 44659 | C2: 0.38612269 | K2: Null | P2: =IFNA(IF(VLOOKUP($A2,'Add from APT'!$AA$2:$AC264,3,FALSE)>0,TRUE,FALSE),"ER - NOT IN APT") -> FALSE | Q2: =IF(ISLOGICAL(P2),IF(P2,"ER - REPS IN APT", IFNA(VLOOKUP($A2,RAW_APT!$A$3:$M264,7,FALSE),"ER - NOT IN APT")),P2) -> Collected | R2: =IF(EXACT($A2,$A1),FALSE,TRUE) -> TRUE | S2: =COUNTIF($A$2:$A264,$A2) -> 1 | X2: =IF(ISBLANK($U2),IF(ISBLANK($V2),FALSE,"ER - LAST ONLY"),TRUE) -> FALSE | Z2: =IF($S2>4,TRUE,IFERROR(0/0,"")) | AA2: =IF(ISBLANK($O2),FALSE,TRUE) -> FALSE | AC2: 228 | AE2: =IFERROR(IF(EXACT($L2,$B2),(TIMEVALUE($M2)-TIMEVALUE($C2))*24*60,IFERROR(0/0,"")),IFERROR(0/0,"")) | AF2: =OR(AND(NOT($AG2),IFERROR(NOT($AG3),""),EXACT($A2,$A3),NOT(EXACT(CONCATENATE($B2,$C2),CONCATENATE($B3,$C3)))),AND(NOT($AG2),IFERROR(NOT($AG1),""),EXACT($A2,$A1),NOT(EXACT(CONCATENATE($B2,$C2),CONCATENATE($B1,$C1))))) -> FALSE | AG2: =IF($AH2>0,TRUE,FALSE) -> TRUE | AH2: 1 | AK2: =IFS(AND($AJ2>=2,$AJ2<3),"Negative",AND($AJ2>=3,$AJ2<4),"Positive",AND($AJ2>=4,$AJ2<5),"Inconclusive",$AJ2=5,"MANUAL FILL",$AG2,"DELETED",TRUE,$K2) -> DELETED | AM2: DELETED | AN2: DELETED | AO2: =IFERROR(__xludf.DUMMYFUNCTION("IF($AG2, ""DELETED"",TRIM(JOIN("" "",D2:E2)))"),"DELETED") -> DELETED | AP2: =IF($AG2, "DELETED", TRIM(CONCATENATE(F2,I2,U2))) -> DELETED | AQ2: =IF($AG2, "DELETED", TRIM(CONCATENATE(G2,J2,V2))) -> DELETED | AR2: =IFERROR(__xludf.DUMMYFUNCTION("IF($AG2, ""DELETED"", TRIM(JOIN("" "",AP2,AQ2)))"),"DELETED") -> DELETED | AT2: =IF(OR($AG2,SUM($AU2:$AW2)=1),TRUE,FALSE) -> TRUE | AU2: =IF($AG2,IFERROR(0/0,""),IF(ISBLANK($F2),IF(ISBLANK($G2),IFERROR(0/0,""),2),1)) | AV2: =IF($AG2,IFERROR(0/0,""),IF(ISBLANK($I2),IF(ISBLANK($J2),IFERROR(0/0,""),2),1)) | AW2: =IF($AG2,IFERROR(0/0,""),IF(ISBLANK($U2),IF(ISBLANK($V2),IFERROR(0/0,""),2),1)) | AX2: =IF(AND($X2,$A3=$A2),1,IFERROR(0/0,"")) | BA2: =IF(AG2,IFERROR(0/0,""),IF(EXACT(UPPER(A2),A2),IFERROR(0/0,""),TRUE)) | BE2: {=SORT(BL$2:BL264,1,TRUE)} | BF2: =IF(COUNTIF(BJ$2:BJ264,BE2)>0,COUNTIF(BJ$2:BJ264,BE2),IFERROR(0/0,"")) | BG2: =IF($AG2,IFERROR(0/0,""),CONCATENATE($A2,"__",$B2,"_",$C2,"_",$D2,"_",$E2,"_",$K2,"_",$L2,"_",$M2,"_",$O2)) | BH2: =IF(ISBLANK(IFERROR(MATCH(LEFT(BG2, FIND("__",BG2)-1),BE$2:BE264,0),"")),IFERROR(0/0,""),TRUE) | BI2: {=SORT(UNIQUE(BG$2:BG264),1,TRUE)} -> AG1103__44697_0.190300925925926___Negative_44697_0.361099537037037_ | BJ2: =IFERROR(LEFT(BI2, FIND("__",BI2)-1),"") -> AG1103 | BK2: =IFERROR(AND(EXACT(BJ3,BJ2),NOT(EXACT(BJ2,BJ1))),"") -> FALSE | BL2: =IF(BK2,BJ2,IFERROR(0/0,"")) | BN2: =OR(BO2,BP2) -> FALSE | BO2: =ISBLANK($AR2) -> FALSE | BP2: =IF(TRIM($AR2)="",TRUE,FALSE) -> FALSE | BR2: DELETED | BS2: =EXACT(BR2,$AK2) -> TRUE
A3: AH8073 | B3: 44659 | C3: 0.38662037 | K3: Null | L3: 44861 | M3: 0.48483796 | N3: primary | P3: =IFNA(IF(VLOOKUP($A3,'Add from APT'!$AA$2:$AC264,3,FALSE)>0,TRUE,FALSE),"ER - NOT IN APT") -> FALSE | Q3: =IF(ISLOGICAL(P3),IF(P3,"ER - REPS IN APT", IFNA(VLOOKUP($A3,RAW_APT!$A$3:$M264,7,FALSE),"ER - NOT IN APT")),P3) -> Collected | R3: =IF(EXACT($A3,$A2),FALSE,TRUE) -> TRUE | S3: =COUNTIF($A$2:$A265,$A3) -> 1 | X3: =IF(ISBLANK($U3),IF(ISBLANK($V3),FALSE,"ER - LAST ONLY"),TRUE) -> FALSE | Z3: =IF($S3>4,TRUE,IFERROR(0/0,"")) | AA3: =IF(ISBLANK($O3),FALSE,TRUE) -> FALSE | AC3: 229 | AE3: =IFERROR(IF(EXACT($L3,$B3),(TIMEVALUE($M3)-TIMEVALUE($C3))*24*60,IFERROR(0/0,"")),IFERROR(0/0,"")) | AF3: =OR(AND(NOT($AG3),IFERROR(NOT($AG4),""),EXACT($A3,$A4),NOT(EXACT(CONCATENATE($B3,$C3),CONCATENATE($B4,$C4)))),AND(NOT($AG3),IFERROR(NOT($AG2),""),EXACT($A3,$A2),NOT(EXACT(CONCATENATE($B3,$C3),CONCATENATE($B2,$C2))))) -> FALSE | AG3: =IF($AH3>0,TRUE,FALSE) -> TRUE | AH3: 1 | AK3: =IFS(AND($AJ3>=2,$AJ3<3),"Negative",AND($AJ3>=3,$AJ3<4),"Positive",AND($AJ3>=4,$AJ3<5),"Inconclusive",$AJ3=5,"MANUAL FILL",$AG3,"DELETED",TRUE,$K3) -> DELETED | AM3: DELETED | AN3: DELETED | AO3: =IFERROR(__xludf.DUMMYFUNCTION("IF($AG3, ""DELETED"",TRIM(JOIN("" "",D3:E3)))"),"DELETED") -> DELETED | AP3: =IF($AG3, "DELETED", TRIM(CONCATENATE(F3,I3,U3))) -> DELETED | AQ3: =IF($AG3, "DELETED", TRIM(CONCATENATE(G3,J3,V3))) -> DELETED | AR3: =IFERROR(__xludf.DUMMYFUNCTION("IF($AG3, ""DELETED"", TRIM(JOIN("" "",AP3,AQ3)))"),"DELETED") -> DELETED | AT3: =IF(OR($AG3,SUM($AU3:$AW3)=1),TRUE,FALSE) -> TRUE | AU3: =IF($AG3,IFERROR(0/0,""),IF(ISBLANK($F3),IF(ISBLANK($G3),IFERROR(0/0,""),2),1)) | AV3: =IF($AG3,IFERROR(0/0,""),IF(ISBLANK($I3),IF(ISBLANK($J3),IFERROR(0/0,""),2),1)) | AW3: =IF($AG3,IFERROR(0/0,""),IF(ISBLANK($U3),IF(ISBLANK($V3),IFERROR(0/0,""),2),1)) | AX3: =IF(AND($X3,$A4=$A3),1,IFERROR(0/0,"")) | BA3: =IF(AG3,IFERROR(0/0,""),IF(EXACT(UPPER(A3),A3),IFERROR(0/0,""),TRUE)) | BF3: =IF(COUNTIF(BJ$2:BJ265,BE3)>0,COUNTIF(BJ$2:BJ265,BE3),IFERROR(0/0,"")) | BG3: =IF($AG3,IFERROR(0/0,""),CONCATENATE($A3,"__",$B3,"_",$C3,"_",$D3,"_",$E3,"_",$K3,"_",$L3,"_",$M3,"_",$O3)) | BH3: =IF(ISBLANK(IFERROR(MATCH(LEFT(BG3, FIND("__",BG3)-1),BE$2:BE265,0),"")),IFERROR(0/0,""),TRUE) | BI3: AG1224__44767_0.378877314814815___Negative_44767_0.432939814814815_ | BJ3: =IFERROR(LEFT(BI3, FIND("__",BI3)-1),"") -> AG1224 | BK3: =IFERROR(AND(EXACT(BJ4,BJ3),NOT(EXACT(BJ3,BJ2))),"") -> FALSE | BL3: =IF(BK3,BJ3,IFERROR(0/0,"")) | BN3: =OR(BO3,BP3) -> FALSE | BO3: =ISBLANK($AR3) -> FALSE | BP3: =IF(TRIM($AR3)="",TRUE,FALSE) -> FALSE | BR3: DELETED | BS3: =EXACT(BR3,$AK3) -> TRUE
A4: 72782051679 | B4: 44659 | C4: 0.55017361 | K4: Null | P4: =IFNA(IF(VLOOKUP($A4,'Add from APT'!$AA$2:$AC264,3,FALSE)>0,TRUE,FALSE),"ER - NOT IN APT") -> ER - NOT IN APT | Q4: =IF(ISLOGICAL(P4),IF(P4,"ER - REPS IN APT", IFNA(VLOOKUP($A4,RAW_APT!$A$3:$M264,7,FALSE),"ER - NOT IN APT")),P4) -> ER - NOT IN APT | R4: =IF(EXACT($A4,$A3),FALSE,TRUE) -> TRUE | S4: =COUNTIF($A$2:$A266,$A4) -> 2 | X4: =IF(ISBLANK($U4),IF(ISBLANK($V4),FALSE,"ER - LAST ONLY"),TRUE) -> FALSE | Z4: =IF($S4>4,TRUE,IFERROR(0/0,"")) | AA4: =IF(ISBLANK($O4),FALSE,TRUE) -> FALSE | AC4: 231 | AE4: =IFERROR(IF(EXACT($L4,$B4),(TIMEVALUE($M4)-TIMEVALUE($C4))*24*60,IFERROR(0/0,"")),IFERROR(0/0,"")) | AF4: =OR(AND(NOT($AG4),IFERROR(NOT($AG5),""),EXACT($A4,$A5),NOT(EXACT(CONCATENATE($B4,$C4),CONCATENATE($B5,$C5)))),AND(NOT($AG4),IFERROR(NOT($AG3),""),EXACT($A4,$A3),NOT(EXACT(CONCATENATE($B4,$C4),CONCATENATE($B3,$C3))))) -> FALSE | AG4: =IF($AH4>0,TRUE,FALSE) -> TRUE | AH4: 1 | AK4: =IFS(AND($AJ4>=2,$AJ4<3),"Negative",AND($AJ4>=3,$AJ4<4),"Positive",AND($AJ4>=4,$AJ4<5),"Inconclusive",$AJ4=5,"MANUAL FILL",$AG4,"DELETED",TRUE,$K4) -> DELETED | AM4: DELETED | AN4: DELETED | AO4: =IFERROR(__xludf.DUMMYFUNCTION("IF($AG4, ""DELETED"",TRIM(JOIN("" "",D4:E4)))"),"DELETED") -> DELETED | AP4: =IF($AG4, "DELETED", TRIM(CONCATENATE(F4,I4,U4))) -> DELETED | AQ4: =IF($AG4, "DELETED", TRIM(CONCATENATE(G4,J4,V4))) -> DELETED | AR4: =IFERROR(__xludf.DUMMYFUNCTION("IF($AG4, ""DELETED"", TRIM(JOIN("" "",AP4,AQ4)))"),"DELETED") -> DELETED | AT4: =IF(OR($AG4,SUM($AU4:$AW4)=1),TRUE,FALSE) -> TRUE | AU4: =IF($AG4,IFERROR(0/0,""),IF(ISBLANK($F4),IF(ISBLANK($G4),IFERROR(0/0,""),2),1)) | AV4: =IF($AG4,IFERROR(0/0,""),IF(ISBLANK($I4),IF(ISBLANK($J4),IFERROR(0/0,""),2),1)) | AW4: =IF($AG4,IFERROR(0/0,""),IF(ISBLANK($U4),IF(ISBLANK($V4),IFERROR(0/0,""),2),1)) | AX4: =IF(AND($X4,$A5=$A4),1,IFERROR(0/0,"")) | BA4: =IF(AG4,IFERROR(0/0,""),IF(EXACT(UPPER(A4),A4),IFERROR(0/0,""),TRUE)) | BF4: =IF(COUNTIF(BJ$2:BJ266,BE4)>0,COUNTIF(BJ$2:BJ266,BE4),IFERROR(0/0,"")) | BG4: =IF($AG4,IFERROR(0/0,""),CONCATENATE($A4,"__",$B4,"_",$C4,"_",$D4,"_",$E4,"_",$K4,"_",$L4,"_",$M4,"_",$O4)) | BH4: =IF(ISBLANK(IFERROR(MATCH(LEFT(BG4, FIND("__",BG4)-1),BE$2:BE266,0),"")),IFERROR(0/0,""),TRUE) | BI4: AG1259__44753_0.252719907407407___Negative_44753_0.398402777777778_ | BJ4: =IFERROR(LEFT(BI4, FIND("__",BI4)-1),"") -> AG1259 | BK4: =IFERROR(AND(EXACT(BJ5,BJ4),NOT(EXACT(BJ4,BJ3))),"") -> FALSE | BL4: =IF(BK4,BJ4,IFERROR(0/0,"")) | BN4: =OR(BO4,BP4) -> FALSE | BO4: =ISBLANK($AR4) -> FALSE | BP4: =IF(TRIM($AR4)="",TRUE,FALSE) -> FALSE | BR4: DELETED | BS4: =EXACT(BR4,$AK4) -> TRUE
A5: 72782051679 | B5: 44659 | C5: 0.55017361 | K5: Null | P5: =IFNA(IF(VLOOKUP($A5,'Add from APT'!$AA$2:$AC264,3,FALSE)>0,TRUE,FALSE),"ER - NOT IN APT") -> ER - NOT IN APT | Q5: =IF(ISLOGICAL(P5),IF(P5,"ER - REPS IN APT", IFNA(VLOOKUP($A5,RAW_APT!$A$3:$M264,7,FALSE),"ER - NOT IN APT")),P5) -> ER - NOT IN APT | R5: =IF(EXACT($A5,$A4),FALSE,TRUE) -> FALSE | S5: =COUNTIF($A$2:$A267,$A5) -> 2 | X5: =IF(ISBLANK($U5),IF(ISBLANK($V5),FALSE,"ER - LAST ONLY"),TRUE) -> FALSE | Z5: =IF($S5>4,TRUE,IFERROR(0/0,"")) | AA5: =IF(ISBLANK($O5),FALSE,TRUE) -> FALSE | AC5: 230 | AE5: =IFERROR(IF(EXACT($L5,$B5),(TIMEVALUE($M5)-TIMEVALUE($C5))*24*60,IFERROR(0/0,"")),IFERROR(0/0,"")) | AF5: =OR(AND(NOT($AG5),IFERROR(NOT($AG6),""),EXACT($A5,$A6),NOT(EXACT(CONCATENATE($B5,$C5),CONCATENATE($B6,$C6)))),AND(NOT($AG5),IFERROR(NOT($AG4),""),EXACT($A5,$A4),NOT(EXACT(CONCATENATE($B5,$C5),CONCATENATE($B4,$C4))))) -> FALSE | AG5: =IF($AH5>0,TRUE,FALSE) -> TRUE | AH5: 1 | AK5: =IFS(AND($AJ5>=2,$AJ5<3),"Negative",AND($AJ5>=3,$AJ5<4),"Positive",AND($AJ5>=4,$AJ5<5),"Inconclusive",$AJ5=5,"MANUAL FILL",$AG5,"DELETED",TRUE,$K5) -> DELETED | AM5: DELETED | AN5: DELETED | AO5: =IFERROR(__xludf.DUMMYFUNCTION("IF($AG5, ""DELETED"",TRIM(JOIN("" "",D5:E5)))"),"DELETED") -> DELETED | AP5: =IF($AG5, "DELETED", TRIM(CONCATENATE(F5,I5,U5))) -> DELETED | AQ5: =IF($AG5, "DELETED", TRIM(CONCATENATE(G5,J5,V5))) -> DELETED | AR5: =IFERROR(__xludf.DUMMYFUNCTION("IF($AG5, ""DELETED"", TRIM(JOIN("" "",AP5,AQ5)))"),"DELETED") -> DELETED | AT5: =IF(OR($AG5,SUM($AU5:$AW5)=1),TRUE,FALSE) -> TRUE | AU5: =IF($AG5,IFERROR(0/0,""),IF(ISBLANK($F5),IF(ISBLANK($G5),IFERROR(0/0,""),2),1)) | AV5: =IF($AG5,IFERROR(0/0,""),IF(ISBLANK($I5),IF(ISBLANK($J5),IFERROR(0/0,""),2),1)) | AW5: =IF($AG5,IFERROR(0/0,""),IF(ISBLANK($U5),IF(ISBLANK($V5),IFERROR(0/0,""),2),1)) | AX5: =IF(AND($X5,$A6=$A5),1,IFERROR(0/0,"")) | BA5: =IF(AG5,IFERROR(0/0,""),IF(EXACT(UPPER(A5),A5),IFERROR(0/0,""),TRUE)) | BF5: =IF(COUNTIF(BJ$2:BJ267,BE5)>0,COUNTIF(BJ$2:BJ267,BE5),IFERROR(0/0,"")) | BG5: =IF($AG5,IFERROR(0/0,""),CONCATENATE($A5,"__",$B5,"_",$C5,"_",$D5,"_",$E5,"_",$K5,"_",$L5,"_",$M5,"_",$O5)) | BH5: =IF(ISBLANK(IFERROR(MATCH(LEFT(BG5, FIND("__",BG5)-1),BE$2:BE267,0),"")),IFERROR(0/0,""),TRUE) | BI5: AG1419__44683_0.17806712962963___Negative_44683_0.3578125_ | BJ5: =IFERROR(LEFT(BI5, FIND("__",BI5)-1),"") -> AG1419 | BK5: =IFERROR(AND(EXACT(BJ6,BJ5),NOT(EXACT(BJ5,BJ4))),"") -> FALSE | BL5: =IF(BK5,BJ5,IFERROR(0/0,"")) | BN5: =OR(BO5,BP5) -> FALSE | BO5: =ISBLANK($AR5) -> FALSE | BP5: =IF(TRIM($AR5)="",TRUE,FALSE) -> FALSE | BR5: DELETED | BS5: =EXACT(BR5,$AK5) -> TRUE
A6: AK5401 | B6: 44666 | C6: 0.496875 | K6: Null | P6: =IFNA(IF(VLOOKUP($A6,'Add from APT'!$AA$2:$AC264,3,FALSE)>0,TRUE,FALSE),"ER - NOT IN APT") -> FALSE | Q6: =IF(ISLOGICAL(P6),IF(P6,"ER - REPS IN APT", IFNA(VLOOKUP($A6,RAW_APT!$A$3:$M264,7,FALSE),"ER - NOT IN APT")),P6) -> Collected | R6: =IF(EXACT($A6,$A5),FALSE,TRUE) -> TRUE | S6: =COUNTIF($A$2:$A268,$A6) -> 1 | X6: =IF(ISBLANK($U6),IF(ISBLANK($V6),FALSE,"ER - LAST ONLY"),TRUE) -> FALSE | Z6: =IF($S6>4,TRUE,IFERROR(0/0,"")) | AA6: =IF(ISBLANK($O6),FALSE,TRUE) -> FALSE | AC6: 227 | AE6: =IFERROR(IF(EXACT($L6,$B6),(TIMEVALUE($M6)-TIMEVALUE($C6))*24*60,IFERROR(0/0,"")),IFERROR(0/0,"")) | AF6: =OR(AND(NOT($AG6),IFERROR(NOT($AG7),""),EXACT($A6,$A7),NOT(EXACT(CONCATENATE($B6,$C6),CONCATENATE($B7,$C7)))),AND(NOT($AG6),IFERROR(NOT($AG5),""),EXACT($A6,$A5),NOT(EXACT(CONCATENATE($B6,$C6),CONCATENATE($B5,$C5))))) -> FALSE | AG6: =IF($AH6>0,TRUE,FALSE) -> TRUE | AH6: 1 | AK6: =IFS(AND($AJ6>=2,$AJ6<3),"Negative",AND($AJ6>=3,$AJ6<4),"Positive",AND($AJ6>=4,$AJ6<5),"Inconclusive",$AJ6=5,"MANUAL FILL",$AG6,"DELETED",TRUE,$K6) -> DELETED | AM6: DELETED | AN6: DELETED | AO6: =IFERROR(__xludf.DUMMYFUNCTION("IF($AG6, ""DELETED"",TRIM(JOIN("" "",D6:E6)))"),"DELETED") -> DELETED | AP6: =IF($AG6, "DELETED", TRIM(CONCATENATE(F6,I6,U6))) -> DELETED | AQ6: =IF($AG6, "DELETED", TRIM(CONCATENATE(G6,J6,V6))) -> DELETED | AR6: =IFERROR(__xludf.DUMMYFUNCTION("IF($AG6, ""DELETED"", TRIM(JOIN("" "",AP6,AQ6)))"),"DELETED") -> DELETED | AT6: =IF(OR($AG6,SUM($AU6:$AW6)=1),TRUE,FALSE) -> TRUE | AU6: =IF($AG6,IFERROR(0/0,""),IF(ISBLANK($F6),IF(ISBLANK($G6),IFERROR(0/0,""),2),1)) | AV6: =IF($AG6,IFERROR(0/0,""),IF(ISBLANK($I6),IF(ISBLANK($J6),IFERROR(0/0,""),2),1)) | AW6: =IF($AG6,IFERROR(0/0,""),IF(ISBLANK($U6),IF(ISBLANK($V6),IFERROR(0/0,""),2),1)) | AX6: =IF(AND($X6,$A7=$A6),1,IFERROR(0/0,"")) | BA6: =IF(AG6,IFERROR(0/0,""),IF(EXACT(UPPER(A6),A6),IFERROR(0/0,""),TRUE)) | BF6: =IF(COUNTIF(BJ$2:BJ268,BE6)>0,COUNTIF(BJ$2:BJ268,BE6),IFERROR(0/0,"")) | BG6: =IF($AG6,IFERROR(0/0,""),CONCATENATE($A6,"__",$B6,"_",$C6,"_",$D6,"_",$E6,"_",$K6,"_",$L6,"_",$M6,"_",$O6)) | BH6: =IF(ISBLANK(IFERROR(MATCH(LEFT(BG6, FIND("__",BG6)-1),BE$2:BE268,0),"")),IFERROR(0/0,""),TRUE) | BI6: AG1523__44690_0.279513888888889___Negative_44690_0.323252314814815_ | BJ6: =IFERROR(LEFT(BI6, FIND("__",BI6)-1),"") -> AG1523 | BK6: =IFERROR(AND(EXACT(BJ7,BJ6),NOT(EXACT(BJ6,BJ5))),"") -> FALSE | BL6: =IF(BK6,BJ6,IFERROR(0/0,"")) | BN6: =OR(BO6,BP6) -> FALSE | BO6: =ISBLANK($AR6) -> FALSE | BP6: =IF(TRIM($AR6)="",TRUE,FALSE) -> FALSE | BR6: DELETED | BS6: =EXACT(BR6,$AK6) -> TRUE
A7: TEST_0419-1 | B7: 44670 | C7: 0.46875 | K7: Positive | L7: 44670 | M7: 0.50042824 | P7: =IFNA(IF(VLOOKUP($A7,'Add from APT'!$AA$2:$AC264,3,FALSE)>0,TRUE,FALSE),"ER - NOT IN APT") -> FALSE | Q7: =IF(ISLOGICAL(P7),IF(P7,"ER - REPS IN APT", IFNA(VLOOKUP($A7,RAW_APT!$A$3:$M264,7,FALSE),"ER - NOT IN APT")),P7) -> Result | R7: =IF(EXACT($A7,$A6),FALSE,TRUE) -> TRUE | S7: =COUNTIF($A$2:$A269,$A7) -> 3 | X7: =IF(ISBLANK($U7),IF(ISBLANK($V7),FALSE,"ER - LAST ONLY"),TRUE) -> FALSE | Z7: =IF($S7>4,TRUE,IFERROR(0/0,"")) | AA7: =IF(ISBLANK($O7),FALSE,TRUE) -> FALSE | AC7: 215 | AE7: =IFERROR(IF(EXACT($L7,$B7),(TIMEVALUE($M7)-TIMEVALUE($C7))*24*60,IFERROR(0/0,"")),IFERROR(0/0,"")) -> 45.616667 | AF7: =OR(AND(NOT($AG7),IFERROR(NOT($AG8),""),EXACT($A7,$A8),NOT(EXACT(CONCATENATE($B7,$C7),CONCATENATE($B8,$C8)))),AND(NOT($AG7),IFERROR(NOT($AG6),""),EXACT($A7,$A6),NOT(EXACT(CONCATENATE($B7,$C7),CONCATENATE($B6,$C6))))) -> FALSE | AG7: =IF($AH7>0,TRUE,FALSE) -> TRUE | AH7: 2 | AK7: =IFS(AND($AJ7>=2,$AJ7<3),"Negative",AND($AJ7>=3,$AJ7<4),"Positive",AND($AJ7>=4,$AJ7<5),"Inconclusive",$AJ7=5,"MANUAL FILL",$AG7,"DELETED",TRUE,$K7) -> DELETED | AM7: DELETED | AN7: DELETED | AO7: =IFERROR(__xludf.DUMMYFUNCTION("IF($AG7, ""DELETED"",TRIM(JOIN("" "",D7:E7)))"),"DELETED") -> DELETED | AP7: =IF($AG7, "DELETED", TRIM(CONCATENATE(F7,I7,U7))) -> DELETED | AQ7: =IF($AG7, "DELETED", TRIM(CONCATENATE(G7,J7,V7))) -> DELETED | AR7: =IFERROR(__xludf.DUMMYFUNCTION("IF($AG7, ""DELETED"", TRIM(JOIN("" "",AP7,AQ7)))"),"DELETED") -> DELETED | AT7: =IF(OR($AG7,SUM($AU7:$AW7)=1),TRUE,FALSE) -> TRUE | AU7: =IF($AG7,IFERROR(0/0,""),IF(ISBLANK($F7),IF(ISBLANK($G7),IFERROR(0/0,""),2),1)) | AV7: =IF($AG7,IFERROR(0/0,""),IF(ISBLANK($I7),IF(ISBLANK($J7),IFERROR(0/0,""),2),1)) | AW7: =IF($AG7,IFERROR(0/0,""),IF(ISBLANK($U7),IF(ISBLANK($V7),IFERROR(0/0,""),2),1)) | AX7: =IF(AND($X7,$A8=$A7),1,IFERROR(0/0,"")) | BA7: =IF(AG7,IFERROR(0/0,""),IF(EXACT(UPPER(A7),A7),IFERROR(0/0,""),TRUE)) | BF7: =IF(COUNTIF(BJ$2:BJ269,BE7)>0,COUNTIF(BJ$2:BJ269,BE7),IFERROR(0/0,"")) | BG7: =IF($AG7,IFERROR(0/0,""),CONCATENATE($A7,"__",$B7,"_",$C7,"_",$D7,"_",$E7,"_",$K7,"_",$L7,"_",$M7,"_",$O7)) | BH7: =IF(ISBLANK(IFERROR(MATCH(LEFT(BG7, FIND("__",BG7)-1),BE$2:BE269,0),"")),IFERROR(0/0,""),TRUE) | BI7: AG1608__44718_0.156921296296296___Negative_44718_0.364976851851852_ | BJ7: =IFERROR(LEFT(BI7, FIND("__",BI7)-1),"") -> AG1608 | BK7: =IFERROR(AND(EXACT(BJ8,BJ7),NOT(EXACT(BJ7,BJ6))),"") -> FALSE | BL7: =IF(BK7,BJ7,IFERROR(0/0,"")) | BN7: =OR(BO7,BP7) -> FALSE | BO7: =ISBLANK($AR7) -> FALSE | BP7: =IF(TRIM($AR7)="",TRUE,FALSE) -> FALSE | BR7: DELETED | BS7: =EXACT(BR7,$AK7) -> TRUE
A8: TEST_0419-1 | B8: 44670 | C8: 0.46875 | K8: Positive | L8: 44670 | M8: 0.50042824 | P8: =IFNA(IF(VLOOKUP($A8,'Add from APT'!$AA$2:$AC264,3,FALSE)>0,TRUE,FALSE),"ER - NOT IN APT") -> FALSE | Q8: =IF(ISLOGICAL(P8),IF(P8,"ER - REPS IN APT", IFNA(VLOOKUP($A8,RAW_APT!$A$3:$M264,7,FALSE),"ER - NOT IN APT")),P8) -> Result | R8: =IF(EXACT($A8,$A7),FALSE,TRUE) -> FALSE | S8: =COUNTIF($A$2:$A270,$A8) -> 3 | X8: =IF(ISBLANK($U8),IF(ISBLANK($V8),FALSE,"ER - LAST ONLY"),TRUE) -> FALSE | Z8: =IF($S8>4,TRUE,IFERROR(0/0,"")) | AA8: =IF(ISBLANK($O8),FALSE,TRUE) -> FALSE | AC8: 216 | AE8: =IFERROR(IF(EXACT($L8,$B8),(TIMEVALUE($M8)-TIMEVALUE($C8))*24*60,IFERROR(0/0,"")),IFERROR(0/0,"")) -> 45.616667 | AF8: =OR(AND(NOT($AG8),IFERROR(NOT($AG9),""),EXACT($A8,$A9),NOT(EXACT(CONCATENATE($B8,$C8),CONCATENATE($B9,$C9)))),AND(NOT($AG8),IFERROR(NOT($AG7),""),EXACT($A8,$A7),NOT(EXACT(CONCATENATE($B8,$C8),CONCATENATE($B7,$C7))))) -> FALSE | AG8: =IF($AH8>0,TRUE,FALSE) -> TRUE | AH8: 2 | AK8: =IFS(AND($AJ8>=2,$AJ8<3),"Negative",AND($AJ8>=3,$AJ8<4),"Positive",AND($AJ8>=4,$AJ8<5),"Inconclusive",$AJ8=5,"MANUAL FILL",$AG8,"DELETED",TRUE,$K8) -> DELETED | AM8: DELETED | AN8: DELETED | AO8: =IFERROR(__xludf.DUMMYFUNCTION("IF($AG8, ""DELETED"",TRIM(JOIN("" "",D8:E8)))"),"DELETED") -> DELETED | AP8: =IF($AG8, "DELETED", TRIM(CONCATENATE(F8,I8,U8))) -> DELETED | AQ8: =IF($AG8, "DELETED", TRIM(CONCATENATE(G8,J8,V8))) -> DELETED | AR8: =IFERROR(__xludf.DUMMYFUNCTION("IF($AG8, ""DELETED"", TRIM(JOIN("" "",AP8,AQ8)))"),"DELETED") -> DELETED | AT8: =IF(OR($AG8,SUM($AU8:$AW8)=1),TRUE,FALSE) -> TRUE | AU8: =IF($AG8,IFERROR(0/0,""),IF(ISBLANK($F8),IF(ISBLANK($G8),IFERROR(0/0,""),2),1)) | AV8: =IF($AG8,IFERROR(0/0,""),IF(ISBLANK($I8),IF(ISBLANK($J8),IFERROR(0/0,""),2),1)) | AW8: =IF($AG8,IFERROR(0/0,""),IF(ISBLANK($U8),IF(ISBLANK($V8),IFERROR(0/0,""),2),1)) | AX8: =IF(AND($X8,$A9=$A8),1,IFERROR(0/0,"")) | BA8: =IF(AG8,IFERROR(0/0,""),IF(EXACT(UPPER(A8),A8),IFERROR(0/0,""),TRUE)) | BF8: =IF(COUNTIF(BJ$2:BJ270,BE8)>0,COUNTIF(BJ$2:BJ270,BE8),IFERROR(0/0,"")) | BG8: =IF($AG8,IFERROR(0/0,""),CONCATENATE($A8,"__",$B8,"_",$C8,"_",$D8,"_",$E8,"_",$K8,"_",$L8,"_",$M8,"_",$O8)) | BH8: =IF(ISBLANK(IFERROR(MATCH(LEFT(BG8, FIND("__",BG8)-1),BE$2:BE270,0),"")),IFERROR(0/0,""),TRUE) | BI8: AG1637__44697_0.176759259259259___Negative_44697_0.361099537037037_ | BJ8: =IFERROR(LEFT(BI8, FIND("__",BI8)-1),"") -> AG1637 | BK8: =IFERROR(AND(EXACT(BJ9,BJ8),NOT(EXACT(BJ8,BJ7))),"") -> FALSE | BL8: =IF(BK8,BJ8,IFERROR(0/0,"")) | BN8: =OR(BO8,BP8) -> FALSE | BO8: =ISBLANK($AR8) -> FALSE | BP8: =IF(TRIM($AR8)="",TRUE,FALSE) -> FALSE | BR8: DELETED | BS8: =EXACT(BR8,$AK8) -> TRUE
A9: TEST_0419-1 | B9: 44670 | C9: 0.46875 | K9: Positive | L9: 44670 | M9: 0.50042824 | P9: =IFNA(IF(VLOOKUP($A9,'Add from APT'!$AA$2:$AC264,3,FALSE)>0,TRUE,FALSE),"ER - NOT IN APT") -> FALSE | Q9: =IF(ISLOGICAL(P9),IF(P9,"ER - REPS IN APT", IFNA(VLOOKUP($A9,RAW_APT!$A$3:$M264,7,FALSE),"ER - NOT IN APT")),P9) -> Result | R9: =IF(EXACT($A9,$A8),FALSE,TRUE) -> FALSE | S9: =COUNTIF($A$2:$A271,$A9) -> 3 | X9: =IF(ISBLANK($U9),IF(ISBLANK($V9),FALSE,"ER - LAST ONLY"),TRUE) -> FALSE | Z9: =IF($S9>4,TRUE,IFERROR(0/0,"")) | AA9: =IF(ISBLANK($O9),FALSE,TRUE) -> FALSE | AC9: 214 | AE9: =IFERROR(IF(EXACT($L9,$B9),(TIMEVALUE($M9)-TIMEVALUE($C9))*24*60,IFERROR(0/0,"")),IFERROR(0/0,"")) -> 45.616667 | AF9: =OR(AND(NOT($AG9),IFERROR(NOT($AG10),""),EXACT($A9,$A10),NOT(EXACT(CONCATENATE($B9,$C9),CONCATENATE($B10,$C10)))),AND(NOT($AG9),IFERROR(NOT($AG8),""),EXACT($A9,$A8),NOT(EXACT(CONCATENATE($B9,$C9),CONCATENATE($B8,$C8))))) -> FALSE | AG9: =IF($AH9>0,TRUE,FALSE) -> TRUE | AH9: 2 | AK9: =IFS(AND($AJ9>=2,$AJ9<3),"Negative",AND($AJ9>=3,$AJ9<4),"Positive",AND($AJ9>=4,$AJ9<5),"Inconclusive",$AJ9=5,"MANUAL FILL",$AG9,"DELETED",TRUE,$K9) -> DELETED | AM9: DELETED | AN9: DELETED | AO9: =IFERROR(__xludf.DUMMYFUNCTION("IF($AG9, ""DELETED"",TRIM(JOIN("" "",D9:E9)))"),"DELETED") -> DELETED | AP9: =IF($AG9, "DELETED", TRIM(CONCATENATE(F9,I9,U9))) -> DELETED | AQ9: =IF($AG9, "DELETED", TRIM(CONCATENATE(G9,J9,V9))) -> DELETED | AR9: =IFERROR(__xludf.DUMMYFUNCTION("IF($AG9, ""DELETED"", TRIM(JOIN("" "",AP9,AQ9)))"),"DELETED") -> DELETED | AT9: =IF(OR($AG9,SUM($AU9:$AW9)=1),TRUE,FALSE) -> TRUE | AU9: =IF($AG9,IFERROR(0/0,""),IF(ISBLANK($F9),IF(ISBLANK($G9),IFERROR(0/0,""),2),1)) | AV9: =IF($AG9,IFERROR(0/0,""),IF(ISBLANK($I9),IF(ISBLANK($J9),IFERROR(0/0,""),2),1)) | AW9: =IF($AG9,IFERROR(0/0,""),IF(ISBLANK($U9),IF(ISBLANK($V9),IFERROR(0/0,""),2),1)) | AX9: =IF(AND($X9,$A10=$A9),1,IFERROR(0/0,"")) | BA9: =IF(AG9,IFERROR(0/0,""),IF(EXACT(UPPER(A9),A9),IFERROR(0/0,""),TRUE)) | BF9: =IF(COUNTIF(BJ$2:BJ271,BE9)>0,COUNTIF(BJ$2:BJ271,BE9),IFERROR(0/0,"")) | BG9: =IF($AG9,IFERROR(0/0,""),CONCATENATE($A9,"__",$B9,"_",$C9,"_",$D9,"_",$E9,"_",$K9,"_",$L9,"_",$M9,"_",$O9)) | BH9: =IF(ISBLANK(IFERROR(MATCH(LEFT(BG9, FIND("__",BG9)-1),BE$2:BE271,0),"")),IFERROR(0/0,""),TRUE) | BI9: AG1640__44704_0.190543981481482___Negative_44704_0.394907407407407_ | BJ9: =IFERROR(LEFT(BI9, FIND("__",BI9)-1),"") -> AG1640 | BK9: =IFERROR(AND(EXACT(BJ10,BJ9),NOT(EXACT(BJ9,BJ8))),"") -> FALSE | BL9: =IF(BK9,BJ9,IFERROR(0/0,"")) | BN9: =OR(BO9,BP9) -> FALSE | BO9: =ISBLANK($AR9) -> FALSE | BP9: =IF(TRIM($AR9)="",TRUE,FALSE) -> FALSE | BR9: DELETED | BS9: =EXACT(BR9,$AK9) -> TRUE
A10: TEST_0419-2 | B10: 44670 | C10: 0.46928241 | K10: Null | P10: =IFNA(IF(VLOOKUP($A10,'Add from APT'!$AA$2:$AC264,3,FALSE)>0,TRUE,FALSE),"ER - NOT IN APT") -> FALSE | Q10: =IF(ISLOGICAL(P10),IF(P10,"ER - REPS IN APT", IFNA(VLOOKUP($A10,RAW_APT!$A$3:$M264,7,FALSE),"ER - NOT IN APT")),P10) -> Collected | R10: =IF(EXACT($A10,$A9),FALSE,TRUE) -> TRUE | S10: =COUNTIF($A$2:$A272,$A10) -> 3 | X10: =IF(ISBLANK($U10),IF(ISBLANK($V10),FALSE,"ER - LAST ONLY"),TRUE) -> FALSE | Z10: =IF($S10>4,TRUE,IFERROR(0/0,"")) | AA10: =IF(ISBLANK($O10),FALSE,TRUE) -> FALSE | AC10: 218 | AE10: =IFERROR(IF(EXACT($L10,$B10),(TIMEVALUE($M10)-TIMEVALUE($C10))*24*60,IFERROR(0/0,"")),IFERROR(0/0,"")) | AF10: =OR(AND(NOT($AG10),IFERROR(NOT($AG11),""),EXACT($A10,$A11),NOT(EXACT(CONCATENATE($B10,$C10),CONCATENATE($B11,$C11)))),AND(NOT($AG10),IFERROR(NOT($AG9),""),EXACT($A10,$A9),NOT(EXACT(CONCATENATE($B10,$C10),CONCATENATE($B9,$C9))))) -> FALSE | AG10: =IF($AH10>0,TRUE,FALSE) -> TRUE | AH10: 2 | AK10: =IFS(AND($AJ10>=2,$AJ10<3),"Negative",AND($AJ10>=3,$AJ10<4),"Positive",AND($AJ10>=4,$AJ10<5),"Inconclusive",$AJ10=5,"MANUAL FILL",$AG10,"DELETED",TRUE,$K10) -> DELETED | AM10: DELETED | AN10: DELETED | AO10: =IFERROR(__xludf.DUMMYFUNCTION("IF($AG10, ""DELETED"",TRIM(JOIN("" "",D10:E10)))"),"DELETED") -> DELETED | AP10: =IF($AG10, "DELETED", TRIM(CONCATENATE(F10,I10,U10))) -> DELETED | AQ10: =IF($AG10, "DELETED", TRIM(CONCATENATE(G10,J10,V10))) -> DELETED | AR10: =IFERROR(__xludf.DUMMYFUNCTION("IF($AG10, ""DELETED"", TRIM(JOIN("" "",AP10,AQ10)))"),"DELETED") -> DELETED | AT10: =IF(OR($AG10,SUM($AU10:$AW10)=1),TRUE,FALSE) -> TRUE | AU10: =IF($AG10,IFERROR(0/0,""),IF(ISBLANK($F10),IF(ISBLANK($G10),IFERROR(0/0,""),2),1)) | AV10: =IF($AG10,IFERROR(0/0,""),IF(ISBLANK($I10),IF(ISBLANK($J10),IFERROR(0/0,""),2),1)) | AW10: =IF($AG10,IFERROR(0/0,""),IF(ISBLANK($U10),IF(ISBLANK($V10),IFERROR(0/0,""),2),1)) | AX10: =IF(AND($X10,$A11=$A10),1,IFERROR(0/0,"")) | BA10: =IF(AG10,IFERROR(0/0,""),IF(EXACT(UPPER(A10),A10),IFERROR(0/0,""),TRUE)) | BF10: =IF(COUNTIF(BJ$2:BJ272,BE10)>0,COUNTIF(BJ$2:BJ272,BE10),IFERROR(0/0,"")) | BG10: =IF($AG10,IFERROR(0/0,""),CONCATENATE($A10,"__",$B10,"_",$C10,"_",$D10,"_",$E10,"_",$K10,"_",$L10,"_",$M10,"_",$O10)) | BH10: =IF(ISBLANK(IFERROR(MATCH(LEFT(BG10, FIND("__",BG10)-1),BE$2:BE272,0),"")),IFERROR(0/0,""),TRUE) | BI10: AG1713__44683_0.212569444444444___Negative_44683_0.357824074074074_ | BJ10: =IFERROR(LEFT(BI10, FIND("__",BI10)-1),"") -> AG1713 | BK10: =IFERROR(AND(EXACT(BJ11,BJ10),NOT(EXACT(BJ10,BJ9))),"") -> FALSE | BL10: =IF(BK10,BJ10,IFERROR(0/0,"")) | BN10: =OR(BO10,BP10) -> FALSE | BO10: =ISBLANK($AR10) -> FALSE | BP10: =IF(TRIM($AR10)="",TRUE,FALSE) -> FALSE | BR10: DELETED | BS10: =EXACT(BR10,$AK10) -> TRUE
A11: TEST_0419-2 | B11: 44670 | C11: 0.46928241 | K11: Null | P11: =IFNA(IF(VLOOKUP($A11,'Add from APT'!$AA$2:$AC264,3,FALSE)>0,TRUE,FALSE),"ER - NOT IN APT") -> FALSE | Q11: =IF(ISLOGICAL(P11),IF(P11,"ER - REPS IN APT", IFNA(VLOOKUP($A11,RAW_APT!$A$3:$M264,7,FALSE),"ER - NOT IN APT")),P11) -> Collected | R11: =IF(EXACT($A11,$A10),FALSE,TRUE) -> FALSE | S11: =COUNTIF($A$2:$A273,$A11) -> 3 | X11: =IF(ISBLANK($U11),IF(ISBLANK($V11),FALSE,"ER - LAST ONLY"),TRUE) -> FALSE | Z11: =IF($S11>4,TRUE,IFERROR(0/0,"")) | AA11: =IF(ISBLANK($O11),FALSE,TRUE) -> FALSE | AC11: 217 | AE11: =IFERROR(IF(EXACT($L11,$B11),(TIMEVALUE($M11)-TIMEVALUE($C11))*24*60,IFERROR(0/0,"")),IFERROR(0/0,"")) | AF11: =OR(AND(NOT($AG11),IFERROR(NOT($AG12),""),EXACT($A11,$A12),NOT(EXACT(CONCATENATE($B11,$C11),CONCATENATE($B12,$C12)))),AND(NOT($AG11),IFERROR(NOT($AG10),""),EXACT($A11,$A10),NOT(EXACT(CONCATENATE($B11,$C11),CONCATENATE($B10,$C10))))) -> FALSE | AG11: =IF($AH11>0,TRUE,FALSE) -> TRUE | AH11: 2 | AK11: =IFS(AND($AJ11>=2,$AJ11<3),"Negative",AND($AJ11>=3,$AJ11<4),"Positive",AND($AJ11>=4,$AJ11<5),"Inconclusive",$AJ11=5,"MANUAL FILL",$AG11,"DELETED",TRUE,$K11) -> DELETED | AM11: DELETED | AN11: DELETED | AO11: =IFERROR(__xludf.DUMMYFUNCTION("IF($AG11, ""DELETED"",TRIM(JOIN("" "",D11:E11)))"),"DELETED") -> DELETED | AP11: =IF($AG11, "DELETED", TRIM(CONCATENATE(F11,I11,U11))) -> DELETED | AQ11: =IF($AG11, "DELETED", TRIM(CONCATENATE(G11,J11,V11))) -> DELETED | AR11: =IFERROR(__xludf.DUMMYFUNCTION("IF($AG11, ""DELETED"", TRIM(JOIN("" "",AP11,AQ11)))"),"DELETED") -> DELETED | AT11: =IF(OR($AG11,SUM($AU11:$AW11)=1),TRUE,FALSE) -> TRUE | AU11: =IF($AG11,IFERROR(0/0,""),IF(ISBLANK($F11),IF(ISBLANK($G11),IFERROR(0/0,""),2),1)) | AV11: =IF($AG11,IFERROR(0/0,""),IF(ISBLANK($I11),IF(ISBLANK($J11),IFERROR(0/0,""),2),1)) | AW11: =IF($AG11,IFERROR(0/0,""),IF(ISBLANK($U11),IF(ISBLANK($V11),IFERROR(0/0,""),2),1)) | AX11: =IF(AND($X11,$A12=$A11),1,IFERROR(0/0,"")) | BA11: =IF(AG11,IFERROR(0/0,""),IF(EXACT(UPPER(A11),A11),IFERROR(0/0,""),TRUE)) | BF11: =IF(COUNTIF(BJ$2:BJ273,BE11)>0,COUNTIF(BJ$2:BJ273,BE11),IFERROR(0/0,"")) | BG11: =IF($AG11,IFERROR(0/0,""),CONCATENATE($A11,"__",$B11,"_",$C11,"_",$D11,"_",$E11,"_",$K11,"_",$L11,"_",$M11,"_",$O11)) | BH11: =IF(ISBLANK(IFERROR(MATCH(LEFT(BG11, FIND("__",BG11)-1),BE$2:BE273,0),"")),IFERROR(0/0,""),TRUE) | BI11: AG1821__44713_0.200763888888889___Negative_44713_0.341493055555556_ | BJ11: =IFERROR(LEFT(BI11, FIND("__",BI11)-1),"") -> AG1821 | BK11: =IFERROR(AND(EXACT(BJ12,BJ11),NOT(EXACT(BJ11,BJ10))),"") -> FALSE | BL11: =IF(BK11,BJ11,IFERROR(0/0,"")) | BN11: =OR(BO11,BP11) -> FALSE | BO11: =ISBLANK($AR11) -> FALSE | BP11: =IF(TRIM($AR11)="",TRUE,FALSE) -> FALSE | BR11: DELETED | BS11: =EXACT(BR11,$AK11) -> TRUE
A12: TEST_0419-2 | B12: 44670 | C12: 0.46928241 | K12: Null | P12: =IFNA(IF(VLOOKUP($A12,'Add from APT'!$AA$2:$AC264,3,FALSE)>0,TRUE,FALSE),"ER - NOT IN APT") -> FALSE | Q12: =IF(ISLOGICAL(P12),IF(P12,"ER - REPS IN APT", IFNA(VLOOKUP($A12,RAW_APT!$A$3:$M264,7,FALSE),"ER - NOT IN APT")),P12) -> Collected | R12: =IF(EXACT($A12,$A11),FALSE,TRUE) -> FALSE | S12: =COUNTIF($A$2:$A274,$A12) -> 3 | X12: =IF(ISBLANK($U12),IF(ISBLANK($V12),FALSE,"ER - LAST ONLY"),TRUE) -> FALSE | Z12: =IF($S12>4,TRUE,IFERROR(0/0,"")) | AA12: =IF(ISBLANK($O12),FALSE,TRUE) -> FALSE | AC12: 219 | AE12: =IFERROR(IF(EXACT($L12,$B12),(TIMEVALUE($M12)-TIMEVALUE($C12))*24*60,IFERROR(0/0,"")),IFERROR(0/0,"")) | AF12: =OR(AND(NOT($AG12),IFERROR(NOT($AG13),""),EXACT($A12,$A13),NOT(EXACT(CONCATENATE($B12,$C12),CONCATENATE($B13,$C13)))),AND(NOT($AG12),IFERROR(NOT($AG11),""),EXACT($A12,$A11),NOT(EXACT(CONCATENATE($B12,$C12),CONCATENATE($B11,$C11))))) -> FALSE | AG12: =IF($AH12>0,TRUE,FALSE) -> TRUE | AH12: 2 | AK12: =IFS(AND($AJ12>=2,$AJ12<3),"Negative",AND($AJ12>=3,$AJ12<4),"Positive",AND($AJ12>=4,$AJ12<5),"Inconclusive",$AJ12=5,"MANUAL FILL",$AG12,"DELETED",TRUE,$K12) -> DELETED | AM12: DELETED | AN12: DELETED | AO12: =IFERROR(__xludf.DUMMYFUNCTION("IF($AG12, ""DELETED"",TRIM(JOIN("" "",D12:E12)))"),"DELETED") -> DELETED | AP12: =IF($AG12, "DELETED", TRIM(CONCATENATE(F12,I12,U12))) -> DELETED | AQ12: =IF($AG12, "DELETED", TRIM(CONCATENATE(G12,J12,V12))) -> DELETED | AR12: =IFERROR(__xludf.DUMMYFUNCTION("IF($AG12, ""DELETED"", TRIM(JOIN("" "",AP12,AQ12)))"),"DELETED") -> DELETED | AT12: =IF(OR($AG12,SUM($AU12:$AW12)=1),TRUE,FALSE) -> TRUE | AU12: =IF($AG12,IFERROR(0/0,""),IF(ISBLANK($F12),IF(ISBLANK($G12),IFERROR(0/0,""),2),1)) | AV12: =IF($AG12,IFERROR(0/0,""),IF(ISBLANK($I12),IF(ISBLANK($J12),IFERROR(0/0,""),2),1)) | AW12: =IF($AG12,IFERROR(0/0,""),IF(ISBLANK($U12),IF(ISBLANK($V12),IFERROR(0/0,""),2),1)) | AX12: =IF(AND($X12,$A13=$A12),1,IFERROR(0/0,"")) | BA12: =IF(AG12,IFERROR(0/0,""),IF(EXACT(UPPER(A12),A12),IFERROR(0/0,""),TRUE)) | BF12: =IF(COUNTIF(BJ$2:BJ274,BE12)>0,COUNTIF(BJ$2:BJ274,BE12),IFERROR(0/0,"")) | BG12: =IF($AG12,IFERROR(0/0,""),CONCATENATE($A12,"__",$B12,"_",$C12,"_",$D12,"_",$E12,"_",$K12,"_",$L12,"_",$M12,"_",$O12)) | BH12: =IF(ISBLANK(IFERROR(MATCH(LEFT(BG12, FIND("__",BG12)-1),BE$2:BE274,0),"")),IFERROR(0/0,""),TRUE) | BI12: AG1828__44704_0.224467592592593___Negative_44704_0.394918981481481_ | BJ12: =IFERROR(LEFT(BI12, FIND("__",BI12)-1),"") -> AG1828 | BK12: =IFERROR(AND(EXACT(BJ13,BJ12),NOT(EXACT(BJ12,BJ11))),"") -> FALSE | BL12: =IF(BK12,BJ12,IFERROR(0/0,"")) | BN12: =OR(BO12,BP12) -> FALSE | BO12: =ISBLANK($AR12) -> FALSE | BP12: =IF(TRIM($AR12)="",TRUE,FALSE) -> FALSE | BR12: DELETED | BS12: =EXACT(BR12,$AK12) -> TRUE
