Workbook

Sheet ALL Tube Results
A1: =IFERROR(__xludf.DUMMYFUNCTION("QUERY({ 'APS Tubes IMPORT'!A1:A3212; 'ARF Tubes'!M2:M3212 }, ""SELECT Col1 WHERE Col1 IS NOT NULL"", 0)"),"TUBE ID") -> TUBE ID | B1: =IFERROR(__xludf.DUMMYFUNCTION("QUERY({ 'APS Tubes IMPORT'!V1:V3212; 'ARF Tubes'!N2:N3212 }, ""SELECT Col1 WHERE Col1 IS NOT NULL"", 0)"),"FINAL ASSIGNED RUN ID") -> FINAL ASSIGNED RUN ID | C1: ='Run Reconcile'!B1 -> RUN DATE | D1: ='APS Tubes IMPORT'!B1 -> COLLECTION DATE | E1: ='APS Tubes IMPORT'!C1 -> COLLECTION TIME | F1: =IFERROR(__xludf.DUMMYFUNCTION("QUERY({ 'APS Tubes IMPORT'!H1:H3212; 'ARF Tubes'!P2:P3212 }, ""SELECT Col1 WHERE Col1 IS NOT NULL"", 0)"),"FINAL RESULT") -> FINAL RESULT | G1: ='APS Tubes IMPORT'!N1 -> NUM SAMPLES (Pool Level)
A2: =IFERROR(__xludf.DUMMYFUNCTION("""COMPUTED_VALUE"""),"AH7429") -> AH7429 | B2: =IFERROR(__xludf.DUMMYFUNCTION("""COMPUTED_VALUE"""),"RUN-ABRM_2022-09-05_RFR-001") -> RUN-ABRM_2022-09-05_RFR-001 | C2: =VLOOKUP(B2,'Run Reconcile'!A$2:B3212,2,FALSE) -> 44809 | D2: =IFERROR(__xludf.DUMMYFUNCTION("QUERY({ 'APS Tubes IMPORT'!B2:B3212 }, ""SELECT Col1 WHERE Col1 IS NOT NULL"", 0)"),44809.0) -> 44809 | E2: =IFERROR(__xludf.DUMMYFUNCTION("QUERY({ 'APS Tubes IMPORT'!C2:C3212; 'ARF Tubes'!P2:P3212 }, ""SELECT Col1 WHERE Col1 IS NOT NULL"", 0)"),0.301898148147302) -> 0.30189815 | F2: =IFERROR(__xludf.DUMMYFUNCTION("""COMPUTED_VALUE"""),"Negative") -> Negative | G2: =IFERROR(__xludf.DUMMYFUNCTION("QUERY({ 'APS Tubes IMPORT'!N2:N3212 }, ""SELECT Col1 WHERE Col1 IS NOT NULL"", 0)"),2.0) -> 2
A3: =IFERROR(__xludf.DUMMYFUNCTION("""COMPUTED_VALUE"""),"AG448") -> AG448 | B3: =IFERROR(__xludf.DUMMYFUNCTION("""COMPUTED_VALUE"""),"RUN-ABRM_2022-09-05_RFR-001") -> RUN-ABRM_2022-09-05_RFR-001 | C3: =VLOOKUP(B3,'Run Reconcile'!A$2:B3212,2,FALSE) -> 44809 | D3: =IFERROR(__xludf.DUMMYFUNCTION("""COMPUTED_VALUE"""),44809.0) -> 44809 | E3: =IFERROR(__xludf.DUMMYFUNCTION("""COMPUTED_VALUE"""),0.35114583333415794) -> 0.35114583 | F3: =IFERROR(__xludf.DUMMYFUNCTION("""COMPUTED_VALUE"""),"Negative") -> Negative | G3: =IFERROR(__xludf.DUMMYFUNCTION("""COMPUTED_VALUE"""),4.0) -> 4
A4: =IFERROR(__xludf.DUMMYFUNCTION("""COMPUTED_VALUE"""),"AJ8004") -> AJ8004 | B4: =IFERROR(__xludf.DUMMYFUNCTION("""COMPUTED_VALUE"""),"RUN-ABRM_2022-09-05_RFR-001") -> RUN-ABRM_2022-09-05_RFR-001 | C4: =VLOOKUP(B4,'Run Reconcile'!A$2:B3212,2,FALSE) -> 44809 | D4: =IFERROR(__xludf.DUMMYFUNCTION("""COMPUTED_VALUE"""),44809.0) -> 44809 | E4: =IFERROR(__xludf.DUMMYFUNCTION("""COMPUTED_VALUE"""),0.375138888888614) -> 0.37513889 | F4: =IFERROR(__xludf.DUMMYFUNCTION("""COMPUTED_VALUE"""),"Negative") -> Negative | G4: =IFERROR(__xludf.DUMMYFUNCTION("""COMPUTED_VALUE"""),3.0) -> 3
A5: =IFERROR(__xludf.DUMMYFUNCTION("""COMPUTED_VALUE"""),"AH8068") -> AH8068 | B5: =IFERROR(__xludf.DUMMYFUNCTION("""COMPUTED_VALUE"""),"RUN-ABRM_2022-09-05_RFR-001") -> RUN-ABRM_2022-09-05_RFR-001 | C5: =VLOOKUP(B5,'Run Reconcile'!A$2:B3212,2,FALSE) -> 44809 | D5: =IFERROR(__xludf.DUMMYFUNCTION("""COMPUTED_VALUE"""),44809.0) -> 44809 | E5: =IFERROR(__xludf.DUMMYFUNCTION("""COMPUTED_VALUE"""),0.39384259259168175) -> 0.39384259 | F5: =IFERROR(__xludf.DUMMYFUNCTION("""COMPUTED_VALUE"""),"Negative") -> Negative | G5: =IFERROR(__xludf.DUMMYFUNCTION("""COMPUTED_VALUE"""),2.0) -> 2
A6: =IFERROR(__xludf.DUMMYFUNCTION("""COMPUTED_VALUE"""),"AH9257") -> AH9257 | B6: =IFERROR(__xludf.DUMMYFUNCTION("""COMPUTED_VALUE"""),"RUN-ABRM_2022-09-05_RFR-001") -> RUN-ABRM_2022-09-05_RFR-001 | C6: =VLOOKUP(B6,'Run Reconcile'!A$2:B3212,2,FALSE) -> 44809 | D6: =IFERROR(__xludf.DUMMYFUNCTION("""COMPUTED_VALUE"""),44809.0) -> 44809 | E6: =IFERROR(__xludf.DUMMYFUNCTION("""COMPUTED_VALUE"""),0.40921296296437504) -> 0.40921296 | F6: =IFERROR(__xludf.DUMMYFUNCTION("""COMPUTED_VALUE"""),"Negative") -> Negative | G6: =IFERROR(__xludf.DUMMYFUNCTION("""COMPUTED_VALUE"""),2.0) -> 2
A7: =IFERROR(__xludf.DUMMYFUNCTION("""COMPUTED_VALUE"""),"AG1276") -> AG1276 | B7: =IFERROR(__xludf.DUMMYFUNCTION("""COMPUTED_VALUE"""),"RUN-ABRM_2022-09-05_RFR-001") -> RUN-ABRM_2022-09-05_RFR-001 | C7: =VLOOKUP(B7,'Run Reconcile'!A$2:B3212,2,FALSE) -> 44809 | D7: =IFERROR(__xludf.DUMMYFUNCTION("""COMPUTED_VALUE"""),44809.0) -> 44809 | E7: =IFERROR(__xludf.DUMMYFUNCTION("""COMPUTED_VALUE"""),0.4484374999992724) -> 0.4484375 | F7: =IFERROR(__xludf.DUMMYFUNCTION("""COMPUTED_VALUE"""),"Negative") -> Negative | G7: =IFERROR(__xludf.DUMMYFUNCTION("""COMPUTED_VALUE"""),2.0) -> 2
A8: =IFERROR(__xludf.DUMMYFUNCTION("""COMPUTED_VALUE"""),"AG1434") -> AG1434 | B8: =IFERROR(__xludf.DUMMYFUNCTION("""COMPUTED_VALUE"""),"RUN-ABRM_2022-09-05_RFR-001") -> RUN-ABRM_2022-09-05_RFR-001 | C8: =VLOOKUP(B8,'Run Reconcile'!A$2:B3212,2,FALSE) -> 44809 | D8: =IFERROR(__xludf.DUMMYFUNCTION("""COMPUTED_VALUE"""),44809.0) -> 44809 | E8: =IFERROR(__xludf.DUMMYFUNCTION("""COMPUTED_VALUE"""),0.5504513888881775) -> 0.55045139 | F8: =IFERROR(__xludf.DUMMYFUNCTION("""COMPUTED_VALUE"""),"Negative") -> Negative | G8: =IFERROR(__xludf.DUMMYFUNCTION("""COMPUTED_VALUE"""),1.0) -> 1
A9: =IFERROR(__xludf.DUMMYFUNCTION("""COMPUTED_VALUE"""),"AG2096") -> AG2096 | B9: =IFERROR(__xludf.DUMMYFUNCTION("""COMPUTED_VALUE"""),"RUN-ABRM_2022-09-05_RFR-001") -> RUN-ABRM_2022-09-05_RFR-001 | C9: =VLOOKUP(B9,'Run Reconcile'!A$2:B3212,2,FALSE) -> 44809 | D9: =IFERROR(__xludf.DUMMYFUNCTION("""COMPUTED_VALUE"""),44809.0) -> 44809 | E9: =IFERROR(__xludf.DUMMYFUNCTION("""COMPUTED_VALUE"""),0.5509837962963502) -> 0.5509838 | F9: =IFERROR(__xludf.DUMMYFUNCTION("""COMPUTED_VALUE"""),"Negative") -> Negative | G9: =IFERROR(__xludf.DUMMYFUNCTION("""COMPUTED_VALUE"""),1.0) -> 1
A10: =IFERROR(__xludf.DUMMYFUNCTION("""COMPUTED_VALUE"""),"AH8397") -> AH8397 | B10: =IFERROR(__xludf.DUMMYFUNCTION("""COMPUTED_VALUE"""),"RUN-ABRM_2022-09-05_RFR-001") -> RUN-ABRM_2022-09-05_RFR-001 | C10: =VLOOKUP(B10,'Run Reconcile'!A$2:B3212,2,FALSE) -> 44809 | D10: =IFERROR(__xludf.DUMMYFUNCTION("""COMPUTED_VALUE"""),44809.0) -> 44809 | E10: =IFERROR(__xludf.DUMMYFUNCTION("""COMPUTED_VALUE"""),0.5515625000007276) -> 0.5515625 | F10: =IFERROR(__xludf.DUMMYFUNCTION("""COMPUTED_VALUE"""),"Negative") -> Negative | G10: =IFERROR(__xludf.DUMMYFUNCTION("""COMPUTED_VALUE"""),2.0) -> 2
A11: =IFERROR(__xludf.DUMMYFUNCTION("""COMPUTED_VALUE"""),"AG1056") -> AG1056 | B11: =IFERROR(__xludf.DUMMYFUNCTION("""COMPUTED_VALUE"""),"RUN-ABRM_2022-09-05_RFR-001") -> RUN-ABRM_2022-09-05_RFR-001 | C11: =VLOOKUP(B11,'Run Reconcile'!A$2:B3212,2,FALSE) -> 44809 | D11: =IFERROR(__xludf.DUMMYFUNCTION("""COMPUTED_VALUE"""),44809.0) -> 44809 | E11: =IFERROR(__xludf.DUMMYFUNCTION("""COMPUTED_VALUE"""),0.5518518518510973) -> 0.55185185 | F11: =IFERROR(__xludf.DUMMYFUNCTION("""COMPUTED_VALUE"""),"Negative") -> Negative | G11: =IFERROR(__xludf.DUMMYFUNCTION("""COMPUTED_VALUE"""),4.0) -> 4
A12: =IFERROR(__xludf.DUMMYFUNCTION("""COMPUTED_VALUE"""),"AH8238") -> AH8238 | B12: =IFERROR(__xludf.DUMMYFUNCTION("""COMPUTED_VALUE"""),"RUN-ABRM_2022-09-05_RFR-001") -> RUN-ABRM_2022-09-05_RFR-001 | C12: =VLOOKUP(B12,'Run Reconcile'!A$2:B3212,2,FALSE) -> 44809 | D12: =IFERROR(__xludf.DUMMYFUNCTION("""COMPUTED_VALUE"""),44809.0) -> 44809 | E12: =IFERROR(__xludf.DUMMYFUNCTION("""COMPUTED_VALUE"""),0.6387152777788287) -> 0.63871528 | F12: =IFERROR(__xludf.DUMMYFUNCTION("""COMPUTED_VALUE"""),"Negative") -> Negative | G12: =IFERROR(__xludf.DUMMYFUNCTION("""COMPUTED_VALUE"""),1.0) -> 1
A13: =IFERROR(__xludf.DUMMYFUNCTION("""COMPUTED_VALUE"""),"AH7722") -> AH7722 | B13: =IFERROR(__xludf.DUMMYFUNCTION("""COMPUTED_VALUE"""),"RUN-ABRM_2022-09-06_RFR-002") -> RUN-ABRM_2022-09-06_RFR-002 | C13: =VLOOKUP(B13,'Run Reconcile'!A$2:B3212,2,FALSE) -> 44810 | D13: =IFERROR(__xludf.DUMMYFUNCTION("""COMPUTED_VALUE"""),44810.0) -> 44810 | E13: =IFERROR(__xludf.DUMMYFUNCTION("""COMPUTED_VALUE"""),0.20773148148145992) -> 0.20773148 | F13: =IFERROR(__xludf.DUMMYFUNCTION("""COMPUTED_VALUE"""),"Negative") -> Negative | G13: =IFERROR(__xludf.DUMMYFUNCTION("""COMPUTED_VALUE"""),2.0) -> 2
A14: =IFERROR(__xludf.DUMMYFUNCTION("""COMPUTED_VALUE"""),"AH8567") -> AH8567 | B14: =IFERROR(__xludf.DUMMYFUNCTION("""COMPUTED_VALUE"""),"RUN-ABRM_2022-09-06_RFR-002") -> RUN-ABRM_2022-09-06_RFR-002 | C14: =VLOOKUP(B14,'Run Reconcile'!A$2:B3212,2,FALSE) -> 44810 | D14: =IFERROR(__xludf.DUMMYFUNCTION("""COMPUTED_VALUE"""),44810.0) -> 44810 | E14: =IFERROR(__xludf.DUMMYFUNCTION("""COMPUTED_VALUE"""),0.28258101851679385) -> 0.28258102 | F14: =IFERROR(__xludf.DUMMYFUNCTION("""COMPUTED_VALUE"""),"Negative") -> Negative | G14: =IFERROR(__xludf.DUMMYFUNCTION("""COMPUTED_VALUE"""),3.0) -> 3
A15: =IFERROR(__xludf.DUMMYFUNCTION("""COMPUTED_VALUE"""),"AH8614") -> AH8614 | B15: =IFERROR(__xludf.DUMMYFUNCTION("""COMPUTED_VALUE"""),"RUN-ABRM_2022-09-06_RFR-002") -> RUN-ABRM_2022-09-06_RFR-002 | C15: =VLOOKUP(B15,'Run Reconcile'!A$2:B3212,2,FALSE) -> 44810 | D15: =IFERROR(__xludf.DUMMYFUNCTION("""COMPUTED_VALUE"""),44810.0) -> 44810 | E15: =IFERROR(__xludf.DUMMYFUNCTION("""COMPUTED_VALUE"""),0.29910879629460396) -> 0.2991088 | F15: =IFERROR(__xludf.DUMMYFUNCTION("""COMPUTED_VALUE"""),"Negative") -> Negative | G15: =IFERROR(__xludf.DUMMYFUNCTION("""COMPUTED_VALUE"""),2.0) -> 2
A16: =IFERROR(__xludf.DUMMYFUNCTION("""COMPUTED_VALUE"""),"AK5855") -> AK5855 | B16: =IFERROR(__xludf.DUMMYFUNCTION("""COMPUTED_VALUE"""),"RUN-ABRM_2022-09-06_RFR-002") -> RUN-ABRM_2022-09-06_RFR-002 | C16: =VLOOKUP(B16,'Run Reconcile'!A$2:B3212,2,FALSE) -> 44810 | D16: =IFERROR(__xludf.DUMMYFUNCTION("""COMPUTED_VALUE"""),44810.0) -> 44810 | E16: =IFERROR(__xludf.DUMMYFUNCTION("""COMPUTED_VALUE"""),0.30761574074131204) -> 0.30761574 | F16: =IFERROR(__xludf.DUMMYFUNCTION("""COMPUTED_VALUE"""),"Negative") -> Negative | G16: =IFERROR(__xludf.DUMMYFUNCTION("""COMPUTED_VALUE"""),4.0) -> 4
A17: =IFERROR(__xludf.DUMMYFUNCTION("""COMPUTED_VALUE"""),"AG1798") -> AG1798 | B17: =IFERROR(__xludf.DUMMYFUNCTION("""COMPUTED_VALUE"""),"RUN-ABRM_2022-09-06_RFR-002") -> RUN-ABRM_2022-09-06_RFR-002 | C17: =VLOOKUP(B17,'Run Reconcile'!A$2:B3212,2,FALSE) -> 44810 | D17: =IFERROR(__xludf.DUMMYFUNCTION("""COMPUTED_VALUE"""),44810.0) -> 44810 | E17: =IFERROR(__xludf.DUMMYFUNCTION("""COMPUTED_VALUE"""),0.3100694444437977) -> 0.31006944 | F17: =IFERROR(__xludf.DUMMYFUNCTION("""COMPUTED_VALUE"""),"Negative") -> Negative | G17: =IFERROR(__xludf.DUMMYFUNCTION("""COMPUTED_VALUE"""),2.0) -> 2
A18: =IFERROR(__xludf.DUMMYFUNCTION("""COMPUTED_VALUE"""),"AH9538") -> AH9538 | B18: =IFERROR(__xludf.DUMMYFUNCTION("""COMPUTED_VALUE"""),"RUN-ABRM_2022-09-06_RFR-002") -> RUN-ABRM_2022-09-06_RFR-002 | C18: =VLOOKUP(B18,'Run Reconcile'!A$2:B3212,2,FALSE) -> 44810 | D18: =IFERROR(__xludf.DUMMYFUNCTION("""COMPUTED_VALUE"""),44810.0) -> 44810 | E18: =IFERROR(__xludf.DUMMYFUNCTION("""COMPUTED_VALUE"""),0.31447916666729725) -> 0.31447917 | F18: =IFERROR(__xludf.DUMMYFUNCTION("""COMPUTED_VALUE"""),"Negative") -> Negative | G18: =IFERROR(__xludf.DUMMYFUNCTION("""COMPUTED_VALUE"""),1.0) -> 1
A19: =IFERROR(__xludf.DUMMYFUNCTION("""COMPUTED_VALUE"""),"AH7857") -> AH7857 | B19: =IFERROR(__xludf.DUMMYFUNCTION("""COMPUTED_VALUE"""),"RUN-ABRM_2022-09-06_RFR-002") -> RUN-ABRM_2022-09-06_RFR-002 | C19: =VLOOKUP(B19,'Run Reconcile'!A$2:B3212,2,FALSE) -> 44810 | D19: =IFERROR(__xludf.DUMMYFUNCTION("""COMPUTED_VALUE"""),44810.0) -> 44810 | E19: =IFERROR(__xludf.DUMMYFUNCTION("""COMPUTED_VALUE"""),0.31672453703868086) -> 0.31672454 | F19: =IFERROR(__xludf.DUMMYFUNCTION("""COMPUTED_VALUE"""),"Negative") -> Negative | G19: =IFERROR(__xludf.DUMMYFUNCTION("""COMPUTED_VALUE"""),1.0) -> 1
A20: =IFERROR(__xludf.DUMMYFUNCTION("""COMPUTED_VALUE"""),"AH9830") -> AH9830 | B20: =IFERROR(__xludf.DUMMYFUNCTION("""COMPUTED_VALUE"""),"RUN-ABRM_2022-09-07_RFR-003") -> RUN-ABRM_2022-09-07_RFR-003 | C20: =VLOOKUP(B20,'Run Reconcile'!A$2:B3212,2,FALSE) -> 44811 | D20: =IFERROR(__xludf.DUMMYFUNCTION("""COMPUTED_VALUE"""),44811.0) -> 44811 | E20: =IFERROR(__xludf.DUMMYFUNCTION("""COMPUTED_VALUE"""),0.23423611111138598) -> 0.23423611 | F20: =IFERROR(__xludf.DUMMYFUNCTION("""COMPUTED_VALUE"""),"Negative") -> Negative | G20: =IFERROR(__xludf.DUMMYFUNCTION("""COMPUTED_VALUE"""),3.0) -> 3
A21: =IFERROR(__xludf.DUMMYFUNCTION("""COMPUTED_VALUE"""),"AH8447") -> AH8447 | B21: =IFERROR(__xludf.DUMMYFUNCTION("""COMPUTED_VALUE"""),"RUN-ABRM_2022-09-07_RFR-003") -> RUN-ABRM_2022-09-07_RFR-003 | C21: =VLOOKUP(B21,'Run Reconcile'!A$2:B3212,2,FALSE) -> 44811 | D21: =IFERROR(__xludf.DUMMYFUNCTION("""COMPUTED_VALUE"""),44811.0) -> 44811 | E21: =IFERROR(__xludf.DUMMYFUNCTION("""COMPUTED_VALUE"""),0.2401504629633564) -> 0.24015046 | F21: =IFERROR(__xludf.DUMMYFUNCTION("""COMPUTED_VALUE"""),"Negative") -> Negative | G21: =IFERROR(__xludf.DUMMYFUNCTION("""COMPUTED_VALUE"""),3.0) -> 3
A22: =IFERROR(__xludf.DUMMYFUNCTION("""COMPUTED_VALUE"""),"AK6001") -> AK6001 | B22: =IFERROR(__xludf.DUMMYFUNCTION("""COMPUTED_VALUE"""),"RUN-ABRM_2022-09-07_RFR-003") -> RUN-ABRM_2022-09-07_RFR-003 | C22: =VLOOKUP(B22,'Run Reconcile'!A$2:B3212,2,FALSE) -> 44811 | D22: =IFERROR(__xludf.DUMMYFUNCTION("""COMPUTED_VALUE"""),44811.0) -> 44811 | E22: =IFERROR(__xludf.DUMMYFUNCTION("""COMPUTED_VALUE"""),0.2798032407408755) -> 0.27980324 | F22: =IFERROR(__xludf.DUMMYFUNCTION("""COMPUTED_VALUE"""),"Negative") -> Negative | G22: =IFERROR(__xludf.DUMMYFUNCTION("""COMPUTED_VALUE"""),3.0) -> 3
A23: =IFERROR(__xludf.DUMMYFUNCTION("""COMPUTED_VALUE"""),"AG1741") -> AG1741 | B23: =IFERROR(__xludf.DUMMYFUNCTION("""COMPUTED_VALUE"""),"RUN-ABRM_2022-09-07_RFR-003") -> RUN-ABRM_2022-09-07_RFR-003 | C23: =VLOOKUP(B23,'Run Reconcile'!A$2:B3212,2,FALSE) -> 44811 | D23: =IFERROR(__xludf.DUMMYFUNCTION("""COMPUTED_VALUE"""),44811.0) -> 44811 | E23: =IFERROR(__xludf.DUMMYFUNCTION("""COMPUTED_VALUE"""),0.29594907407226856) -> 0.29594907 | F23: =IFERROR(__xludf.DUMMYFUNCTION("""COMPUTED_VALUE"""),"Negative") -> Negative | G23: =IFERROR(__xludf.DUMMYFUNCTION("""COMPUTED_VALUE"""),1.0) -> 1
A24: =IFERROR(__xludf.DUMMYFUNCTION("""COMPUTED_VALUE"""),"AG1355") -> AG1355 | B24: =IFERROR(__xludf.DUMMYFUNCTION("""COMPUTED_VALUE"""),"RUN-ABRM_2022-09-07_RFR-003") -> RUN-ABRM_2022-09-07_RFR-003 | C24: =VLOOKUP(B24,'Run Reconcile'!A$2:B3212,2,FALSE) -> 44811 | D24: =IFERROR(__xludf.DUMMYFUNCTION("""COMPUTED_VALUE"""),44811.0) -> 44811 | E24: =IFERROR(__xludf.DUMMYFUNCTION("""COMPUTED_VALUE"""),0.3039351851839456) -> 0.30393519 | F24: =IFERROR(__xludf.DUMMYFUNCTION("""COMPUTED_VALUE"""),"Negative") -> Negative | G24: =IFERROR(__xludf.DUMMYFUNCTION("""COMPUTED_VALUE"""),2.0) -> 2
A25: =IFERROR(__xludf.DUMMYFUNCTION("""COMPUTED_VALUE"""),"AH8245") -> AH8245 | B25: =IFERROR(__xludf.DUMMYFUNCTION("""COMPUTED_VALUE"""),"RUN-ABRM_2022-09-07_RFR-003") -> RUN-ABRM_2022-09-07_RFR-003 | C25: =VLOOKUP(B25,'Run Reconcile'!A$2:B3212,2,FALSE) -> 44811 | D25: =IFERROR(__xludf.DUMMYFUNCTION("""COMPUTED_VALUE"""),44811.0) -> 44811 | E25: =IFERROR(__xludf.DUMMYFUNCTION("""COMPUTED_VALUE"""),0.3564236111124046) -> 0.35642361 | F25: =IFERROR(__xludf.DUMMYFUNCTION("""COMPUTED_VALUE"""),"Negative") -> Negative | G25: =IFERROR(__xludf.DUMMYFUNCTION("""COMPUTED_VALUE"""),1.0) -> 1
A26: =IFERROR(__xludf.DUMMYFUNCTION("""COMPUTED_VALUE"""),"AH1291") -> AH1291 | B26: =IFERROR(__xludf.DUMMYFUNCTION("""COMPUTED_VALUE"""),"RUN-ABRM_2022-09-07_RFR-003") -> RUN-ABRM_2022-09-07_RFR-003 | C26: =VLOOKUP(B26,'Run Reconcile'!A$2:B3212,2,FALSE) -> 44811 | D26: =IFERROR(__xludf.DUMMYFUNCTION("""COMPUTED_VALUE"""),44811.0) -> 44811 | E26: =IFERROR(__xludf.DUMMYFUNCTION("""COMPUTED_VALUE"""),0.416782407406572) -> 0.41678241 | F26: =IFERROR(__xludf.DUMMYFUNCTION("""COMPUTED_VALUE"""),"Negative") -> Negative | G26: =IFERROR(__xludf.DUMMYFUNCTION("""COMPUTED_VALUE"""),1.0) -> 1
A27: =IFERROR(__xludf.DUMMYFUNCTION("""COMPUTED_VALUE"""),"AH8513") -> AH8513 | B27: =IFERROR(__xludf.DUMMYFUNCTION("""COMPUTED_VALUE"""),"RUN-ABRM_2022-09-07_RFR-003") -> RUN-ABRM_2022-09-07_RFR-003 | C27: =VLOOKUP(B27,'Run Reconcile'!A$2:B3212,2,FALSE) -> 44811 | D27: =IFERROR(__xludf.DUMMYFUNCTION("""COMPUTED_VALUE"""),44811.0) -> 44811 | E27: =IFERROR(__xludf.DUMMYFUNCTION("""COMPUTED_VALUE"""),0.4171990740724141) -> 0.41719907 | F27: =IFERROR(__xludf.DUMMYFUNCTION("""COMPUTED_VALUE"""),"Negative") -> Negative | G27: =IFERROR(__xludf.DUMMYFUNCTION("""COMPUTED_VALUE"""),2.0) -> 2
A28: =IFERROR(__xludf.DUMMYFUNCTION("""COMPUTED_VALUE"""),"AH7993") -> AH7993 | B28: =IFERROR(__xludf.DUMMYFUNCTION("""COMPUTED_VALUE"""),"RUN-ABRM_2022-09-07_RFR-003") -> RUN-ABRM_2022-09-07_RFR-003 | C28: =VLOOKUP(B28,'Run Reconcile'!A$2:B3212,2,FALSE) -> 44811 | D28: =IFERROR(__xludf.DUMMYFUNCTION("""COMPUTED_VALUE"""),44811.0) -> 44811 | E28: =IFERROR(__xludf.DUMMYFUNCTION("""COMPUTED_VALUE"""),0.4176967592575238) -> 0.41769676 | F28: =IFERROR(__xludf.DUMMYFUNCTION("""COMPUTED_VALUE"""),"Negative") -> Negative | G28: =IFERROR(__xludf.DUMMYFUNCTION("""COMPUTED_VALUE"""),3.0) -> 3
A29: =IFERROR(__xludf.DUMMYFUNCTION("""COMPUTED_VALUE"""),"AH7395") -> AH7395 | B29: =IFERROR(__xludf.DUMMYFUNCTION("""COMPUTED_VALUE"""),"RUN-ABRM_2022-09-07_RFR-003") -> RUN-ABRM_2022-09-07_RFR-003 | C29: =VLOOKUP(B29,'Run Reconcile'!A$2:B3212,2,FALSE) -> 44811 | D29: =IFERROR(__xludf.DUMMYFUNCTION("""COMPUTED_VALUE"""),44811.0) -> 44811 | E29: =IFERROR(__xludf.DUMMYFUNCTION("""COMPUTED_VALUE"""),0.41811342592700385) -> 0.41811343 | F29: =IFERROR(__xludf.DUMMYFUNCTION("""COMPUTED_VALUE"""),"Negative") -> Negative | G29: =IFERROR(__xludf.DUMMYFUNCTION("""COMPUTED_VALUE"""),1.0) -> 1
A30: =IFERROR(__xludf.DUMMYFUNCTION("""COMPUTED_VALUE"""),"AH9075") -> AH9075 | B30: =IFERROR(__xludf.DUMMYFUNCTION("""COMPUTED_VALUE"""),"RUN-ABRM_2022-09-07_RFR-003") -> RUN-ABRM_2022-09-07_RFR-003 | C30: =VLOOKUP(B30,'Run Reconcile'!A$2:B3212,2,FALSE) -> 44811 | D30: =IFERROR(__xludf.DUMMYFUNCTION("""COMPUTED_VALUE"""),44811.0) -> 44811 | E30: =IFERROR(__xludf.DUMMYFUNCTION("""COMPUTED_VALUE"""),0.41879629629693227) -> 0.4187963 | F30: =IFERROR(__xludf.DUMMYFUNCTION("""COMPUTED_VALUE"""),"Negative") -> Negative | G30: =IFERROR(__xludf.DUMMYFUNCTION("""COMPUTED_VALUE"""),5.0) -> 5
A31: =IFERROR(__xludf.DUMMYFUNCTION("""COMPUTED_VALUE"""),"AJ9638") -> AJ9638 | B31: =IFERROR(__xludf.DUMMYFUNCTION("""COMPUTED_VALUE"""),"RUN-ABRM_2022-09-08_RFR-004") -> RUN-ABRM_2022-09-08_RFR-004 | C31: =VLOOKUP(B31,'Run Reconcile'!A$2:B3212,2,FALSE) -> 44812 | D31: =IFERROR(__xludf.DUMMYFUNCTION("""COMPUTED_VALUE"""),44812.0) -> 44812 | E31: =IFERROR(__xludf.DUMMYFUNCTION("""COMPUTED_VALUE"""),0.23843750000014552) -> 0.2384375 | F31: =IFERROR(__xludf.DUMMYFUNCTION("""COMPUTED_VALUE"""),"Negative") -> Negative | G31: =IFERROR(__xludf.DUMMYFUNCTION("""COMPUTED_VALUE"""),1.0) -> 1
A32: =IFERROR(__xludf.DUMMYFUNCTION("""COMPUTED_VALUE"""),"AH9869") -> AH9869 | B32: =IFERROR(__xludf.DUMMYFUNCTION("""COMPUTED_VALUE"""),"RUN-ABRM_2022-09-08_RFR-004") -> RUN-ABRM_2022-09-08_RFR-004 | C32: =VLOOKUP(B32,'Run Reconcile'!A$2:B3212,2,FALSE) -> 44812 | D32: =IFERROR(__xludf.DUMMYFUNCTION("""COMPUTED_VALUE"""),44812.0) -> 44812 | E32: =IFERROR(__xludf.DUMMYFUNCTION("""COMPUTED_VALUE"""),0.2650694444455439) -> 0.26506944 | F32: =IFERROR(__xludf.DUMMYFUNCTION("""COMPUTED_VALUE"""),"Negative") -> Negative | G32: =IFERROR(__xludf.DUMMYFUNCTION("""COMPUTED_VALUE"""),3.0) -> 3
A33: =IFERROR(__xludf.DUMMYFUNCTION("""COMPUTED_VALUE"""),"AH8928") -> AH8928 | B33: =IFERROR(__xludf.DUMMYFUNCTION("""COMPUTED_VALUE"""),"RUN-ABRM_2022-09-08_RFR-004") -> RUN-ABRM_2022-09-08_RFR-004 | C33: =VLOOKUP(B33,'Run Reconcile'!A$2:B3212,2,FALSE) -> 44812 | D33: =IFERROR(__xludf.DUMMYFUNCTION("""COMPUTED_VALUE"""),44812.0) -> 44812 | E33: =IFERROR(__xludf.DUMMYFUNCTION("""COMPUTED_VALUE"""),0.2744097222239361) -> 0.27440972 | F33: =IFERROR(__xludf.DUMMYFUNCTION("""COMPUTED_VALUE"""),"Negative") -> Negative | G33: =IFERROR(__xludf.DUMMYFUNCTION("""COMPUTED_VALUE"""),2.0) -> 2
A34: =IFERROR(__xludf.DUMMYFUNCTION("""COMPUTED_VALUE"""),"AH9456") -> AH9456 | B34: =IFERROR(__xludf.DUMMYFUNCTION("""COMPUTED_VALUE"""),"RUN-ABRM_2022-09-08_RFR-004") -> RUN-ABRM_2022-09-08_RFR-004 | C34: =VLOOKUP(B34,'Run Reconcile'!A$2:B3212,2,FALSE) -> 44812 | D34: =IFERROR(__xludf.DUMMYFUNCTION("""COMPUTED_VALUE"""),44812.0) -> 44812 | E34: =IFERROR(__xludf.DUMMYFUNCTION("""COMPUTED_VALUE"""),0.2965046296303626) -> 0.29650463 | F34: =IFERROR(__xludf.DUMMYFUNCTION("""COMPUTED_VALUE"""),"Negative") -> Negative | G34: =IFERROR(__xludf.DUMMYFUNCTION("""COMPUTED_VALUE"""),2.0) -> 2
A35: =IFERROR(__xludf.DUMMYFUNCTION("""COMPUTED_VALUE"""),"AG1602") -> AG1602 | B35: =IFERROR(__xludf.DUMMYFUNCTION("""COMPUTED_VALUE"""),"RUN-ABRM_2022-09-08_RFR-004") -> RUN-ABRM_2022-09-08_RFR-004 | C35: =VLOOKUP(B35,'Run Reconcile'!A$2:B3212,2,FALSE) -> 44812 | D35: =IFERROR(__xludf.DUMMYFUNCTION("""COMPUTED_VALUE"""),44812.0) -> 44812 | E35: =IFERROR(__xludf.DUMMYFUNCTION("""COMPUTED_VALUE"""),0.299629629629635) -> 0.29962963 | F35: =IFERROR(__xludf.DUMMYFUNCTION("""COMPUTED_VALUE"""),"Negative") -> Negative | G35: =IFERROR(__xludf.DUMMYFUNCTION("""COMPUTED_VALUE"""),3.0) -> 3
A36: =IFERROR(__xludf.DUMMYFUNCTION("""COMPUTED_VALUE"""),"AH8945") -> AH8945 | B36: =IFERROR(__xludf.DUMMYFUNCTION("""COMPUTED_VALUE"""),"RUN-ABRM_2022-09-08_RFR-004") -> RUN-ABRM_2022-09-08_RFR-004 | C36: =VLOOKUP(B36,'Run Reconcile'!A$2:B3212,2,FALSE) -> 44812 | D36: =IFERROR(__xludf.DUMMYFUNCTION("""COMPUTED_VALUE"""),44812.0) -> 44812 | E36: =IFERROR(__xludf.DUMMYFUNCTION("""COMPUTED_VALUE"""),0.3060416666667152) -> 0.30604167 | F36: =IFERROR(__xludf.DUMMYFUNCTION("""COMPUTED_VALUE"""),"Negative") -> Negative | G36: =IFERROR(__xludf.DUMMYFUNCTION("""COMPUTED_VALUE"""),3.0) -> 3
A37: =IFERROR(__xludf.DUMMYFUNCTION("""COMPUTED_VALUE"""),"AG2192") -> AG2192 | B37: =IFERROR(__xludf.DUMMYFUNCTION("""COMPUTED_VALUE"""),"RUN-ABRM_2022-09-08_RFR-004") -> RUN-ABRM_2022-09-08_RFR-004 | C37: =VLOOKUP(B37,'Run Reconcile'!A$2:B3212,2,FALSE) -> 44812 | D37: =IFERROR(__xludf.DUMMYFUNCTION("""COMPUTED_VALUE"""),44812.0) -> 44812 | E37: =IFERROR(__xludf.DUMMYFUNCTION("""COMPUTED_VALUE"""),0.3097337962972233) -> 0.3097338 | F37: =IFERROR(__xludf.DUMMYFUNCTION("""COMPUTED_VALUE"""),"Negative") -> Negative | G37: =IFERROR(__xludf.DUMMYFUNCTION("""COMPUTED_VALUE"""),2.0) -> 2
A38: =IFERROR(__xludf.DUMMYFUNCTION("""COMPUTED_VALUE"""),"AH8930") -> AH8930 | B38: =IFERROR(__xludf.DUMMYFUNCTION("""COMPUTED_VALUE"""),"RUN-ABRM_2022-09-08_RFR-004") -> RUN-ABRM_2022-09-08_RFR-004 | C38: =VLOOKUP(B38,'Run Reconcile'!A$2:B3212,2,FALSE) -> 44812 | D38: =IFERROR(__xludf.DUMMYFUNCTION("""COMPUTED_VALUE"""),44812.0) -> 44812 | E38: =IFERROR(__xludf.DUMMYFUNCTION("""COMPUTED_VALUE"""),0.3197337962956226) -> 0.3197338 | F38: =IFERROR(__xludf.DUMMYFUNCTION("""COMPUTED_VALUE"""),"Negative") -> Negative | G38: =IFERROR(__xludf.DUMMYFUNCTION("""COMPUTED_VALUE"""),1.0) -> 1
A39: =IFERROR(__xludf.DUMMYFUNCTION("""COMPUTED_VALUE"""),"AH8554") -> AH8554 | B39: =IFERROR(__xludf.DUMMYFUNCTION("""COMPUTED_VALUE"""),"RUN-ABRM_2022-09-08_RFR-004") -> RUN-ABRM_2022-09-08_RFR-004 | C39: =VLOOKUP(B39,'Run Reconcile'!A$2:B3212,2,FALSE) -> 44812 | D39: =IFERROR(__xludf.DUMMYFUNCTION("""COMPUTED_VALUE"""),44812.0) -> 44812 | E39: =IFERROR(__xludf.DUMMYFUNCTION("""COMPUTED_VALUE"""),0.3210416666661331) -> 0.32104167 | F39: =IFERROR(__xludf.DUMMYFUNCTION("""COMPUTED_VALUE"""),"Negative") -> Negative | G39: =IFERROR(__xludf.DUMMYFUNCTION("""COMPUTED_VALUE"""),2.0) -> 2
A40: =IFERROR(__xludf.DUMMYFUNCTION("""COMPUTED_VALUE"""),"AG1115") -> AG1115 | B40: =IFERROR(__xludf.DUMMYFUNCTION("""COMPUTED_VALUE"""),"RUN-ABRM_2022-09-08_RFR-004") -> RUN-ABRM_2022-09-08_RFR-004 | C40: =VLOOKUP(B40,'Run Reconcile'!A$2:B3212,2,FALSE) -> 44812 | D40: =IFERROR(__xludf.DUMMYFUNCTION("""COMPUTED_VALUE"""),44812.0) -> 44812 | E40: =IFERROR(__xludf.DUMMYFUNCTION("""COMPUTED_VALUE"""),0.41913194444350665) -> 0.41913194 | F40: =IFERROR(__xludf.DUMMYFUNCTION("""COMPUTED_VALUE"""),"Negative") -> Negative | G40: =IFERROR(__xludf.DUMMYFUNCTION("""COMPUTED_VALUE"""),1.0) -> 1
...

Sheet Weekly
A1: Week Start Date | B1: Week End Date | C1: =CONCATENATE("Weekly Participants ",SUM(C2:C99)) -> Weekly Participants 2954 | D1: =CONCATENATE("Weekly Tubes Run ",SUM(D2:D99)) -> Weekly Tubes Run 1379 | E1: =CONCATENATE("Weekly Positive Tubes ",SUM(E2:E99)) -> Weekly Positive Tubes 9 | F1: =CONCATENATE("Weekly Inconclusive Tubes ",SUM(F2:F99)) -> Weekly Inconclusive Tubes 3 | G1: % Positive
A2: =MIN('ALL Tube Results'!C:C) - WEEKDAY(MIN('ALL Tube Results'!C:C), 3) -> 44809 | B2: =A2+6 -> 44815 | C2: =SUMIFS('ALL Tube Results'!$G$2:$G99, 'ALL Tube Results'!$C$2:$C99, ">="&A2, 'ALL Tube Results'!$C$2:$C99, "<="&B2) -> 113 | D2: =COUNTIFS('ALL Tube Results'!$C2:$C99, ">="&A2, 'ALL Tube Results'!$C2:$C99, "<="&B2) -> 61 | E2: =COUNTIFS('ALL Tube Results'!$C2:$C99, ">="&A2, 'ALL Tube Results'!$C2:$C99, "<="&B2, 'ALL Tube Results'!$F2:$F99, "Positive") -> 0 | F2: =COUNTIFS('ALL Tube Results'!$C2:$C99, ">="&A2, 'ALL Tube Results'!$C2:$C99, "<="&B2, 'ALL Tube Results'!$F2:$F99, "Inconclusive") -> 0 | G2: =IFERROR(E2/D2,IFERROR(0/0,"")) -> 0 | I2: =TEXT(A2,"ddd") -> Mon
A3: =B2+1 -> 44816 | B3: =A3+6 -> 44822 | C3: =SUMIFS('ALL Tube Results'!$G$2:$G99, 'ALL Tube Results'!$C$2:$C99, ">="&A3, 'ALL Tube Results'!$C$2:$C99, "<="&B3) -> 130 | D3: =COUNTIFS('ALL Tube Results'!$C3:$C99, ">="&A3, 'ALL Tube Results'!$C3:$C99, "<="&B3) -> 52 | E3: =COUNTIFS('ALL Tube Results'!$C3:$C99, ">="&A3, 'ALL Tube Results'!$C3:$C99, "<="&B3, 'ALL Tube Results'!$F3:$F99, "Positive") -> 0 | F3: =COUNTIFS('ALL Tube Results'!$C3:$C99, ">="&A3, 'ALL Tube Results'!$C3:$C99, "<="&B3, 'ALL Tube Results'!$F3:$F99, "Inconclusive") -> 0 | G3: =IFERROR(E3/D3,IFERROR(0/0,"")) -> 0
A4: =A3+7 -> 44823 | B4: =A4+6 -> 44829 | C4: =SUMIFS('ALL Tube Results'!$G$2:$G99, 'ALL Tube Results'!$C$2:$C99, ">="&A4, 'ALL Tube Results'!$C$2:$C99, "<="&B4) -> 108 | D4: =COUNTIFS('ALL Tube Results'!$C4:$C99, ">="&A4, 'ALL Tube Results'!$C4:$C99, "<="&B4) -> 48 | E4: =COUNTIFS('ALL Tube Results'!$C4:$C99, ">="&A4, 'ALL Tube Results'!$C4:$C99, "<="&B4, 'ALL Tube Results'!$F4:$F99, "Positive") -> 0 | F4: =COUNTIFS('ALL Tube Results'!$C4:$C99, ">="&A4, 'ALL Tube Results'!$C4:$C99, "<="&B4, 'ALL Tube Results'!$F4:$F99, "Inconclusive") -> 0 | G4: =IFERROR(E4/D4,IFERROR(0/0,"")) -> 0
A5: =A4+7 -> 44830 | B5: =A5+6 -> 44836 | C5: =SUMIFS('ALL Tube Results'!$G$2:$G99, 'ALL Tube Results'!$C$2:$C99, ">="&A5, 'ALL Tube Results'!$C$2:$C99, "<="&B5) -> 139 | D5: =COUNTIFS('ALL Tube Results'!$C5:$C99, ">="&A5, 'ALL Tube Results'!$C5:$C99, "<="&B5) -> 59 | E5: =COUNTIFS('ALL Tube Results'!$C5:$C99, ">="&A5, 'ALL Tube Results'!$C5:$C99, "<="&B5, 'ALL Tube Results'!$F5:$F99, "Positive") -> 0 | F5: =COUNTIFS('ALL Tube Results'!$C5:$C99, ">="&A5, 'ALL Tube Results'!$C5:$C99, "<="&B5, 'ALL Tube Results'!$F5:$F99, "Inconclusive") -> 0 | G5: =IFERROR(E5/D5,IFERROR(0/0,"")) -> 0
A6: =A5+7 -> 44837 | B6: =A6+6 -> 44843 | C6: =SUMIFS('ALL Tube Results'!$G$2:$G99, 'ALL Tube Results'!$C$2:$C99, ">="&A6, 'ALL Tube Results'!$C$2:$C99, "<="&B6) -> 138 | D6: =COUNTIFS('ALL Tube Results'!$C6:$C99, ">="&A6, 'ALL Tube Results'!$C6:$C99, "<="&B6) -> 59 | E6: =COUNTIFS('ALL Tube Results'!$C6:$C99, ">="&A6, 'ALL Tube Results'!$C6:$C99, "<="&B6, 'ALL Tube Results'!$F6:$F99, "Positive") -> 0 | F6: =COUNTIFS('ALL Tube Results'!$C6:$C99, ">="&A6, 'ALL Tube Results'!$C6:$C99, "<="&B6, 'ALL Tube Results'!$F6:$F99, "Inconclusive") -> 0 | G6: =IFERROR(E6/D6,IFERROR(0/0,"")) -> 0
A7: =A6+7 -> 44844 | B7: =A7+6 -> 44850 | C7: =SUMIFS('ALL Tube Results'!$G$2:$G99, 'ALL Tube Results'!$C$2:$C99, ">="&A7, 'ALL Tube Results'!$C$2:$C99, "<="&B7) -> 106 | D7: =COUNTIFS('ALL Tube Results'!$C7:$C99, ">="&A7, 'ALL Tube Results'!$C7:$C99, "<="&B7) -> 46 | E7: =COUNTIFS('ALL Tube Results'!$C7:$C99, ">="&A7, 'ALL Tube Results'!$C7:$C99, "<="&B7, 'ALL Tube Results'!$F7:$F99, "Positive") -> 0 | F7: =COUNTIFS('ALL Tube Results'!$C7:$C99, ">="&A7, 'ALL Tube Results'!$C7:$C99, "<="&B7, 'ALL Tube Results'!$F7:$F99, "Inconclusive") -> 0 | G7: =IFERROR(E7/D7,IFERROR(0/0,"")) -> 0
A8: =A7+7 -> 44851 | B8: =A8+6 -> 44857 | C8: =SUMIFS('ALL Tube Results'!$G$2:$G99, 'ALL Tube Results'!$C$2:$C99, ">="&A8, 'ALL Tube Results'!$C$2:$C99, "<="&B8) -> 99 | D8: =COUNTIFS('ALL Tube Results'!$C8:$C99, ">="&A8, 'ALL Tube Results'!$C8:$C99, "<="&B8) -> 46 | E8: =COUNTIFS('ALL Tube Results'!$C8:$C99, ">="&A8, 'ALL Tube Results'!$C8:$C99, "<="&B8, 'ALL Tube Results'!$F8:$F99, "Positive") -> 0 | F8: =COUNTIFS('ALL Tube Results'!$C8:$C99, ">="&A8, 'ALL Tube Results'!$C8:$C99, "<="&B8, 'ALL Tube Results'!$F8:$F99, "Inconclusive") -> 0 | G8: =IFERROR(E8/D8,IFERROR(0/0,"")) -> 0
A9: =A8+7 -> 44858 | B9: =A9+6 -> 44864 | C9: =SUMIFS('ALL Tube Results'!$G$2:$G99, 'ALL Tube Results'!$C$2:$C99, ">="&A9, 'ALL Tube Results'!$C$2:$C99, "<="&B9) -> 106 | D9: =COUNTIFS('ALL Tube Results'!$C9:$C99, ">="&A9, 'ALL Tube Results'!$C9:$C99, "<="&B9) -> 48 | E9: =COUNTIFS('ALL Tube Results'!$C9:$C99, ">="&A9, 'ALL Tube Results'!$C9:$C99, "<="&B9, 'ALL Tube Results'!$F9:$F99, "Positive") -> 0 | F9: =COUNTIFS('ALL Tube Results'!$C9:$C99, ">="&A9, 'ALL Tube Results'!$C9:$C99, "<="&B9, 'ALL Tube Results'!$F9:$F99, "Inconclusive") -> 0 | G9: =IFERROR(E9/D9,IFERROR(0/0,"")) -> 0
A10: =A9+7 -> 44865 | B10: =A10+6 -> 44871 | C10: =SUMIFS('ALL Tube Results'!$G$2:$G99, 'ALL Tube Results'!$C$2:$C99, ">="&A10, 'ALL Tube Results'!$C$2:$C99, "<="&B10) -> 73 | D10: =COUNTIFS('ALL Tube Results'!$C10:$C99, ">="&A10, 'ALL Tube Results'!$C10:$C99, "<="&B10) -> 34 | E10: =COUNTIFS('ALL Tube Results'!$C10:$C99, ">="&A10, 'ALL Tube Results'!$C10:$C99, "<="&B10, 'ALL Tube Results'!$F10:$F99, "Positive") -> 0 | F10: =COUNTIFS('ALL Tube Results'!$C10:$C99, ">="&A10, 'ALL Tube Results'!$C10:$C99, "<="&B10, 'ALL Tube Results'!$F10:$F99, "Inconclusive") -> 0 | G10: =IFERROR(E10/D10,IFERROR(0/0,"")) -> 0
A11: =A10+7 -> 44872 | B11: =A11+6 -> 44878 | C11: =SUMIFS('ALL Tube Results'!$G$2:$G99, 'ALL Tube Results'!$C$2:$C99, ">="&A11, 'ALL Tube Results'!$C$2:$C99, "<="&B11) -> 90 | D11: =COUNTIFS('ALL Tube Results'!$C11:$C99, ">="&A11, 'ALL Tube Results'!$C11:$C99, "<="&B11) -> 41 | E11: =COUNTIFS('ALL Tube Results'!$C11:$C99, ">="&A11, 'ALL Tube Results'!$C11:$C99, "<="&B11, 'ALL Tube Results'!$F11:$F99, "Positive") -> 0 | F11: =COUNTIFS('ALL Tube Results'!$C11:$C99, ">="&A11, 'ALL Tube Results'!$C11:$C99, "<="&B11, 'ALL Tube Results'!$F11:$F99, "Inconclusive") -> 0 | G11: =IFERROR(E11/D11,IFERROR(0/0,"")) -> 0
A12: =A11+7 -> 44879 | B12: =A12+6 -> 44885 | C12: =SUMIFS('ALL Tube Results'!$G$2:$G99, 'ALL Tube Results'!$C$2:$C99, ">="&A12, 'ALL Tube Results'!$C$2:$C99, "<="&B12) -> 81 | D12: =COUNTIFS('ALL Tube Results'!$C12:$C99, ">="&A12, 'ALL Tube Results'!$C12:$C99, "<="&B12) -> 41 | E12: =COUNTIFS('ALL Tube Results'!$C12:$C99, ">="&A12, 'ALL Tube Results'!$C12:$C99, "<="&B12, 'ALL Tube Results'!$F12:$F99, "Positive") -> 0 | F12: =COUNTIFS('ALL Tube Results'!$C12:$C99, ">="&A12, 'ALL Tube Results'!$C12:$C99, "<="&B12, 'ALL Tube Results'!$F12:$F99, "Inconclusive") -> 0 | G12: =IFERROR(E12/D12,IFERROR(0/0,"")) -> 0
A13: =A12+7 -> 44886 | B13: =A13+6 -> 44892 | C13: =SUMIFS('ALL Tube Results'!$G$2:$G99, 'ALL Tube Results'!$C$2:$C99, ">="&A13, 'ALL Tube Results'!$C$2:$C99, "<="&B13) -> 44 | D13: =COUNTIFS('ALL Tube Results'!$C13:$C99, ">="&A13, 'ALL Tube Results'!$C13:$C99, "<="&B13) -> 25 | E13: =COUNTIFS('ALL Tube Results'!$C13:$C99, ">="&A13, 'ALL Tube Results'!$C13:$C99, "<="&B13, 'ALL Tube Results'!$F13:$F99, "Positive") -> 0 | F13: =COUNTIFS('ALL Tube Results'!$C13:$C99, ">="&A13, 'ALL Tube Results'!$C13:$C99, "<="&B13, 'ALL Tube Results'!$F13:$F99, "Inconclusive") -> 0 | G13: =IFERROR(E13/D13,IFERROR(0/0,"")) -> 0
A14: =A13+7 -> 44893 | B14: =A14+6 -> 44899 | C14: =SUMIFS('ALL Tube Results'!$G$2:$G99, 'ALL Tube Results'!$C$2:$C99, ">="&A14, 'ALL Tube Results'!$C$2:$C99, "<="&B14) -> 101 | D14: =COUNTIFS('ALL Tube Results'!$C14:$C99, ">="&A14, 'ALL Tube Results'!$C14:$C99, "<="&B14) -> 43 | E14: =COUNTIFS('ALL Tube Results'!$C14:$C99, ">="&A14, 'ALL Tube Results'!$C14:$C99, "<="&B14, 'ALL Tube Results'!$F14:$F99, "Positive") -> 0 | F14: =COUNTIFS('ALL Tube Results'!$C14:$C99, ">="&A14, 'ALL Tube Results'!$C14:$C99, "<="&B14, 'ALL Tube Results'!$F14:$F99, "Inconclusive") -> 0 | G14: =IFERROR(E14/D14,IFERROR(0/0,"")) -> 0
A15: =A14+7 -> 44900 | B15: =A15+6 -> 44906 | C15: =SUMIFS('ALL Tube Results'!$G$2:$G99, 'ALL Tube Results'!$C$2:$C99, ">="&A15, 'ALL Tube Results'!$C$2:$C99, "<="&B15) -> 90 | D15: =COUNTIFS('ALL Tube Results'!$C15:$C99, ">="&A15, 'ALL Tube Results'!$C15:$C99, "<="&B15) -> 37 | E15: =COUNTIFS('ALL Tube Results'!$C15:$C99, ">="&A15, 'ALL Tube Results'!$C15:$C99, "<="&B15, 'ALL Tube Results'!$F15:$F99, "Positive") -> 1 | F15: =COUNTIFS('ALL Tube Results'!$C15:$C99, ">="&A15, 'ALL Tube Results'!$C15:$C99, "<="&B15, 'ALL Tube Results'!$F15:$F99, "Inconclusive") -> 0 | G15: =IFERROR(E15/D15,IFERROR(0/0,"")) -> 0.027027027
A16: =A15+7 -> 44907 | B16: =A16+6 -> 44913 | C16: =SUMIFS('ALL Tube Results'!$G$2:$G99, 'ALL Tube Results'!$C$2:$C99, ">="&A16, 'ALL Tube Results'!$C$2:$C99, "<="&B16) -> 19 | D16: =COUNTIFS('ALL Tube Results'!$C16:$C99, ">="&A16, 'ALL Tube Results'!$C16:$C99, "<="&B16) -> 13 | E16: =COUNTIFS('ALL Tube Results'!$C16:$C99, ">="&A16, 'ALL Tube Results'!$C16:$C99, "<="&B16, 'ALL Tube Results'!$F16:$F99, "Positive") -> 0 | F16: =COUNTIFS('ALL Tube Results'!$C16:$C99, ">="&A16, 'ALL Tube Results'!$C16:$C99, "<="&B16, 'ALL Tube Results'!$F16:$F99, "Inconclusive") -> 0 | G16: =IFERROR(E16/D16,IFERROR(0/0,"")) -> 0
A17: =A16+7 -> 44914 | B17: =A17+6 -> 44920 | C17: =SUMIFS('ALL Tube Results'!$G$2:$G99, 'ALL Tube Results'!$C$2:$C99, ">="&A17, 'ALL Tube Results'!$C$2:$C99, "<="&B17) -> 54 | D17: =COUNTIFS('ALL Tube Results'!$C17:$C99, ">="&A17, 'ALL Tube Results'!$C17:$C99, "<="&B17) -> 26 | E17: =COUNTIFS('ALL Tube Results'!$C17:$C99, ">="&A17, 'ALL Tube Results'!$C17:$C99, "<="&B17, 'ALL Tube Results'!$F17:$F99, "Positive") -> 2 | F17: =COUNTIFS('ALL Tube Results'!$C17:$C99, ">="&A17, 'ALL Tube Results'!$C17:$C99, "<="&B17, 'ALL Tube Results'!$F17:$F99, "Inconclusive") -> 0 | G17: =IFERROR(E17/D17,IFERROR(0/0,"")) -> 0.076923077
A18: =A17+7 -> 44921 | B18: =A18+6 -> 44927 | C18: =SUMIFS('ALL Tube Results'!$G$2:$G99, 'ALL Tube Results'!$C$2:$C99, ">="&A18, 'ALL Tube Results'!$C$2:$C99, "<="&B18) -> 0 | D18: =COUNTIFS('ALL Tube Results'!$C18:$C99, ">="&A18, 'ALL Tube Results'!$C18:$C99, "<="&B18) -> 0 | E18: =COUNTIFS('ALL Tube Results'!$C18:$C99, ">="&A18, 'ALL Tube Results'!$C18:$C99, "<="&B18, 'ALL Tube Results'!$F18:$F99, "Positive") -> 0 | F18: =COUNTIFS('ALL Tube Results'!$C18:$C99, ">="&A18, 'ALL Tube Results'!$C18:$C99, "<="&B18, 'ALL Tube Results'!$F18:$F99, "Inconclusive") -> 0 | G18: =IFERROR(E18/D18,IFERROR(0/0,""))
A19: =A18+7 -> 44928 | B19: =A19+6 -> 44934 | C19: =SUMIFS('ALL Tube Results'!$G$2:$G99, 'ALL Tube Results'!$C$2:$C99, ">="&A19, 'ALL Tube Results'!$C$2:$C99, "<="&B19) -> 93 | D19: =COUNTIFS('ALL Tube Results'!$C19:$C99, ">="&A19, 'ALL Tube Results'!$C19:$C99, "<="&B19) -> 38 | E19: =COUNTIFS('ALL Tube Results'!$C19:$C99, ">="&A19, 'ALL Tube Results'!$C19:$C99, "<="&B19, 'ALL Tube Results'!$F19:$F99, "Positive") -> 0 | F19: =COUNTIFS('ALL Tube Results'!$C19:$C99, ">="&A19, 'ALL Tube Results'!$C19:$C99, "<="&B19, 'ALL Tube Results'!$F19:$F99, "Inconclusive") -> 0 | G19: =IFERROR(E19/D19,IFERROR(0/0,"")) -> 0
A20: =A19+7 -> 44935 | B20: =A20+6 -> 44941 | C20: =SUMIFS('ALL Tube Results'!$G$2:$G99, 'ALL Tube Results'!$C$2:$C99, ">="&A20, 'ALL Tube Results'!$C$2:$C99, "<="&B20) -> 80 | D20: =COUNTIFS('ALL Tube Results'!$C20:$C99, ">="&A20, 'ALL Tube Results'!$C20:$C99, "<="&B20) -> 39 | E20: =COUNTIFS('ALL Tube Results'!$C20:$C99, ">="&A20, 'ALL Tube Results'!$C20:$C99, "<="&B20, 'ALL Tube Results'!$F20:$F99, "Positive") -> 0 | F20: =COUNTIFS('ALL Tube Results'!$C20:$C99, ">="&A20, 'ALL Tube Results'!$C20:$C99, "<="&B20, 'ALL Tube Results'!$F20:$F99, "Inconclusive") -> 2 | G20: =IFERROR(E20/D20,IFERROR(0/0,"")) -> 0
A21: =A20+7 -> 44942 | B21: =A21+6 -> 44948 | C21: =SUMIFS('ALL Tube Results'!$G$2:$G99, 'ALL Tube Results'!$C$2:$C99, ">="&A21, 'ALL Tube Results'!$C$2:$C99, "<="&B21) -> 86 | D21: =COUNTIFS('ALL Tube Results'!$C21:$C99, ">="&A21, 'ALL Tube Results'!$C21:$C99, "<="&B21) -> 40 | E21: =COUNTIFS('ALL Tube Results'!$C21:$C99, ">="&A21, 'ALL Tube Results'!$C21:$C99, "<="&B21, 'ALL Tube Results'!$F21:$F99, "Positive") -> 0 | F21: =COUNTIFS('ALL Tube Results'!$C21:$C99, ">="&A21, 'ALL Tube Results'!$C21:$C99, "<="&B21, 'ALL Tube Results'!$F21:$F99, "Inconclusive") -> 1 | G21: =IFERROR(E21/D21,IFERROR(0/0,"")) -> 0
A22: =A21+7 -> 44949 | B22: =A22+6 -> 44955 | C22: =SUMIFS('ALL Tube Results'!$G$2:$G99, 'ALL Tube Results'!$C$2:$C99, ">="&A22, 'ALL Tube Results'!$C$2:$C99, "<="&B22) -> 65 | D22: =COUNTIFS('ALL Tube Results'!$C22:$C99, ">="&A22, 'ALL Tube Results'!$C22:$C99, "<="&B22) -> 29 | E22: =COUNTIFS('ALL Tube Results'!$C22:$C99, ">="&A22, 'ALL Tube Results'!$C22:$C99, "<="&B22, 'ALL Tube Results'!$F22:$F99, "Positive") -> 0 | F22: =COUNTIFS('ALL Tube Results'!$C22:$C99, ">="&A22, 'ALL Tube Results'!$C22:$C99, "<="&B22, 'ALL Tube Results'!$F22:$F99, "Inconclusive") -> 0 | G22: =IFERROR(E22/D22,IFERROR(0/0,"")) -> 0
A23: =A22+7 -> 44956 | B23: =A23+6 -> 44962 | C23: =SUMIFS('ALL Tube Results'!$G$2:$G99, 'ALL Tube Results'!$C$2:$C99, ">="&A23, 'ALL Tube Results'!$C$2:$C99, "<="&B23) -> 13 | D23: =COUNTIFS('ALL Tube Results'!$C23:$C99, ">="&A23, 'ALL Tube Results'!$C23:$C99, "<="&B23) -> 7 | E23: =COUNTIFS('ALL Tube Results'!$C23:$C99, ">="&A23, 'ALL Tube Results'!$C23:$C99, "<="&B23, 'ALL Tube Results'!$F23:$F99, "Positive") -> 0 | F23: =COUNTIFS('ALL Tube Results'!$C23:$C99, ">="&A23, 'ALL Tube Results'!$C23:$C99, "<="&B23, 'ALL Tube Results'!$F23:$F99, "Inconclusive") -> 0 | G23: =IFERROR(E23/D23,IFERROR(0/0,"")) -> 0
A24: =A23+7 -> 44963 | B24: =A24+6 -> 44969 | C24: =SUMIFS('ALL Tube Results'!$G$2:$G99, 'ALL Tube Results'!$C$2:$C99, ">="&A24, 'ALL Tube Results'!$C$2:$C99, "<="&B24) -> 70 | D24: =COUNTIFS('ALL Tube Results'!$C24:$C99, ">="&A24, 'ALL Tube Results'!$C24:$C99, "<="&B24) -> 33 | E24: =COUNTIFS('ALL Tube Results'!$C24:$C99, ">="&A24, 'ALL Tube Results'!$C24:$C99, "<="&B24, 'ALL Tube Results'!$F24:$F99, "Positive") -> 0 | F24: =COUNTIFS('ALL Tube Results'!$C24:$C99, ">="&A24, 'ALL Tube Results'!$C24:$C99, "<="&B24, 'ALL Tube Results'!$F24:$F99, "Inconclusive") -> 0 | G24: =IFERROR(E24/D24,IFERROR(0/0,"")) -> 0
A25: =A24+7 -> 44970 | B25: =A25+6 -> 44976 | C25: =SUMIFS('ALL Tube Results'!$G$2:$G99, 'ALL Tube Results'!$C$2:$C99, ">="&A25, 'ALL Tube Results'!$C$2:$C99, "<="&B25) -> 87 | D25: =COUNTIFS('ALL Tube Results'!$C25:$C99, ">="&A25, 'ALL Tube Results'!$C25:$C99, "<="&B25) -> 39 | E25: =COUNTIFS('ALL Tube Results'!$C25:$C99, ">="&A25, 'ALL Tube Results'!$C25:$C99, "<="&B25, 'ALL Tube Results'!$F25:$F99, "Positive") -> 0 | F25: =COUNTIFS('ALL Tube Results'!$C25:$C99, ">="&A25, 'ALL Tube Results'!$C25:$C99, "<="&B25, 'ALL Tube Results'!$F25:$F99, "Inconclusive") -> 0 | G25: =IFERROR(E25/D25,IFERROR(0/0,"")) -> 0
A26: =A25+7 -> 44977 | B26: =A26+6 -> 44983 | C26: =SUMIFS('ALL Tube Results'!$G$2:$G99, 'ALL Tube Results'!$C$2:$C99, ">="&A26, 'ALL Tube Results'!$C$2:$C99, "<="&B26) -> 89 | D26: =COUNTIFS('ALL Tube Results'!$C26:$C99, ">="&A26, 'ALL Tube Results'!$C26:$C99, "<="&B26) -> 40 | E26: =COUNTIFS('ALL Tube Results'!$C26:$C99, ">="&A26, 'ALL Tube Results'!$C26:$C99, "<="&B26, 'ALL Tube Results'!$F26:$F99, "Positive") -> 0 | F26: =COUNTIFS('ALL Tube Results'!$C26:$C99, ">="&A26, 'ALL Tube Results'!$C26:$C99, "<="&B26, 'ALL Tube Results'!$F26:$F99, "Inconclusive") -> 0 | G26: =IFERROR(E26/D26,IFERROR(0/0,"")) -> 0
A27: =A26+7 -> 44984 | B27: =A27+6 -> 44990 | C27: =SUMIFS('ALL Tube Results'!$G$2:$G99, 'ALL Tube Results'!$C$2:$C99, ">="&A27, 'ALL Tube Results'!$C$2:$C99, "<="&B27) -> 81 | D27: =COUNTIFS('ALL Tube Results'!$C27:$C99, ">="&A27, 'ALL Tube Results'!$C27:$C99, "<="&B27) -> 37 | E27: =COUNTIFS('ALL Tube Results'!$C27:$C99, ">="&A27, 'ALL Tube Results'!$C27:$C99, "<="&B27, 'ALL Tube Results'!$F27:$F99, "Positive") -> 0 | F27: =COUNTIFS('ALL Tube Results'!$C27:$C99, ">="&A27, 'ALL Tube Results'!$C27:$C99, "<="&B27, 'ALL Tube Results'!$F27:$F99, "Inconclusive") -> 0 | G27: =IFERROR(E27/D27,IFERROR(0/0,"")) -> 0
A28: =A27+7 -> 44991 | B28: =A28+6 -> 44997 | C28: =SUMIFS('ALL Tube Results'!$G$2:$G99, 'ALL Tube Results'!$C$2:$C99, ">="&A28, 'ALL Tube Results'!$C$2:$C99, "<="&B28) -> 112 | D28: =COUNTIFS('ALL Tube Results'!$C28:$C99, ">="&A28, 'ALL Tube Results'!$C28:$C99, "<="&B28) -> 47 | E28: =COUNTIFS('ALL Tube Results'!$C28:$C99, ">="&A28, 'ALL Tube Results'!$C28:$C99, "<="&B28, 'ALL Tube Results'!$F28:$F99, "Positive") -> 0 | F28: =COUNTIFS('ALL Tube Results'!$C28:$C99, ">="&A28, 'ALL Tube Results'!$C28:$C99, "<="&B28, 'ALL Tube Results'!$F28:$F99, "Inconclusive") -> 0 | G28: =IFERROR(E28/D28,IFERROR(0/0,"")) -> 0
A29: =A28+7 -> 44998 | B29: =A29+6 -> 45004 | C29: =SUMIFS('ALL Tube Results'!$G$2:$G99, 'ALL Tube Results'!$C$2:$C99, ">="&A29, 'ALL Tube Results'!$C$2:$C99, "<="&B29) -> 0 | D29: =COUNTIFS('ALL Tube Results'!$C29:$C99, ">="&A29, 'ALL Tube Results'!$C29:$C99, "<="&B29) -> 0 | E29: =COUNTIFS('ALL Tube Results'!$C29:$C99, ">="&A29, 'ALL Tube Results'!$C29:$C99, "<="&B29, 'ALL Tube Results'!$F29:$F99, "Positive") -> 0 | F29: =COUNTIFS('ALL Tube Results'!$C29:$C99, ">="&A29, 'ALL Tube Results'!$C29:$C99, "<="&B29, 'ALL Tube Results'!$F29:$F99, "Inconclusive") -> 0 | G29: =IFERROR(E29/D29,IFERROR(0/0,""))
A30: =A29+7 -> 45005 | B30: =A30+6 -> 45011 | C30: =SUMIFS('ALL Tube Results'!$G$2:$G99, 'ALL Tube Results'!$C$2:$C99, ">="&A30, 'ALL Tube Results'!$C$2:$C99, "<="&B30) -> 84 | D30: =COUNTIFS('ALL Tube Results'!$C30:$C99, ">="&A30, 'ALL Tube Results'!$C30:$C99, "<="&B30) -> 37 | E30: =COUNTIFS('ALL Tube Results'!$C30:$C99, ">="&A30, 'ALL Tube Results'!$C30:$C99, "<="&B30, 'ALL Tube Results'!$F30:$F99, "Positive") -> 0 | F30: =COUNTIFS('ALL Tube Results'!$C30:$C99, ">="&A30, 'ALL Tube Results'!$C30:$C99, "<="&B30, 'ALL Tube Results'!$F30:$F99, "Inconclusive") -> 0 | G30: =IFERROR(E30/D30,IFERROR(0/0,"")) -> 0
A31: =A30+7 -> 45012 | B31: =A31+6 -> 45018 | C31: =SUMIFS('ALL Tube Results'!$G$2:$G99, 'ALL Tube Results'!$C$2:$C99, ">="&A31, 'ALL Tube Results'!$C$2:$C99, "<="&B31) -> 90 | D31: =COUNTIFS('ALL Tube Results'!$C31:$C99, ">="&A31, 'ALL Tube Results'!$C31:$C99, "<="&B31) -> 40 | E31: =COUNTIFS('ALL Tube Results'!$C31:$C99, ">="&A31, 'ALL Tube Results'!$C31:$C99, "<="&B31, 'ALL Tube Results'!$F31:$F99, "Positive") -> 1 | F31: =COUNTIFS('ALL Tube Results'!$C31:$C99, ">="&A31, 'ALL Tube Results'!$C31:$C99, "<="&B31, 'ALL Tube Results'!$F31:$F99, "Inconclusive") -> 0 | G31: =IFERROR(E31/D31,IFERROR(0/0,"")) -> 0.025
A32: =A31+7 -> 45019 | B32: =A32+6 -> 45025 | C32: =SUMIFS('ALL Tube Results'!$G$2:$G99, 'ALL Tube Results'!$C$2:$C99, ">="&A32, 'ALL Tube Results'!$C$2:$C99, "<="&B32) -> 54 | D32: =COUNTIFS('ALL Tube Results'!$C32:$C99, ">="&A32, 'ALL Tube Results'!$C32:$C99, "<="&B32) -> 28 | E32: =COUNTIFS('ALL Tube Results'!$C32:$C99, ">="&A32, 'ALL Tube Results'!$C32:$C99, "<="&B32, 'ALL Tube Results'!$F32:$F99, "Positive") -> 0 | F32: =COUNTIFS('ALL Tube Results'!$C32:$C99, ">="&A32, 'ALL Tube Results'!$C32:$C99, "<="&B32, 'ALL Tube Results'!$F32:$F99, "Inconclusive") -> 0 | G32: =IFERROR(E32/D32,IFERROR(0/0,"")) -> 0
A33: =A32+7 -> 45026 | B33: =A33+6 -> 45032 | C33: =SUMIFS('ALL Tube Results'!$G$2:$G99, 'ALL Tube Results'!$C$2:$C99, ">="&A33, 'ALL Tube Results'!$C$2:$C99, "<="&B33) -> 81 | D33: =COUNTIFS('ALL Tube Results'!$C33:$C99, ">="&A33, 'ALL Tube Results'!$C33:$C99, "<="&B33) -> 39 | E33: =COUNTIFS('ALL Tube Results'!$C33:$C99, ">="&A33, 'ALL Tube Results'!$C33:$C99, "<="&B33, 'ALL Tube Results'!$F33:$F99, "Positive") -> 0 | F33: =COUNTIFS('ALL Tube Results'!$C33:$C99, ">="&A33, 'ALL Tube Results'!$C33:$C99, "<="&B33, 'ALL Tube Results'!$F33:$F99, "Inconclusive") -> 0 | G33: =IFERROR(E33/D33,IFERROR(0/0,"")) -> 0
A34: =A33+7 -> 45033 | B34: =A34+6 -> 45039 | C34: =SUMIFS('ALL Tube Results'!$G$2:$G99, 'ALL Tube Results'!$C$2:$C99, ">="&A34, 'ALL Tube Results'!$C$2:$C99, "<="&B34) -> 67 | D34: =COUNTIFS('ALL Tube Results'!$C34:$C99, ">="&A34, 'ALL Tube Results'!$C34:$C99, "<="&B34) -> 39 | E34: =COUNTIFS('ALL Tube Results'!$C34:$C99, ">="&A34, 'ALL Tube Results'!$C34:$C99, "<="&B34, 'ALL Tube Results'!$F34:$F99, "Positive") -> 0 | F34: =COUNTIFS('ALL Tube Results'!$C34:$C99, ">="&A34, 'ALL Tube Results'!$C34:$C99, "<="&B34, 'ALL Tube Results'!$F34:$F99, "Inconclusive") -> 0 | G34: =IFERROR(E34/D34,IFERROR(0/0,"")) -> 0
A35: =A34+7 -> 45040 | B35: =A35+6 -> 45046 | C35: =SUMIFS('ALL Tube Results'!$G$2:$G99, 'ALL Tube Results'!$C$2:$C99, ">="&A35, 'ALL Tube Results'!$C$2:$C99, "<="&B35) -> 55 | D35: =COUNTIFS('ALL Tube Results'!$C35:$C99, ">="&A35, 'ALL Tube Results'!$C35:$C99, "<="&B35) -> 33 | E35: =COUNTIFS('ALL Tube Results'!$C35:$C99, ">="&A35, 'ALL Tube Results'!$C35:$C99, "<="&B35, 'ALL Tube Results'!$F35:$F99, "Positive") -> 0 | F35: =COUNTIFS('ALL Tube Results'!$C35:$C99, ">="&A35, 'ALL Tube Results'!$C35:$C99, "<="&B35, 'ALL Tube Results'!$F35:$F99, "Inconclusive") -> 0 | G35: =IFERROR(E35/D35,IFERROR(0/0,"")) -> 0
A36: =A35+7 -> 45047 | B36: =A36+6 -> 45053 | C36: =SUMIFS('ALL Tube Results'!$G$2:$G99, 'ALL Tube Results'!$C$2:$C99, ">="&A36, 'ALL Tube Results'!$C$2:$C99, "<="&B36) -> 43 | D36: =COUNTIFS('ALL Tube Results'!$C36:$C99, ">="&A36, 'ALL Tube Results'!$C36:$C99, "<="&B36) -> 22 | E36: =COUNTIFS('ALL Tube Results'!$C36:$C99, ">="&A36, 'ALL Tube Results'!$C36:$C99, "<="&B36, 'ALL Tube Results'!$F36:$F99, "Positive") -> 0 | F36: =COUNTIFS('ALL Tube Results'!$C36:$C99, ">="&A36, 'ALL Tube Results'!$C36:$C99, "<="&B36, 'ALL Tube Results'!$F36:$F99, "Inconclusive") -> 0 | G36: =IFERROR(E36/D36,IFERROR(0/0,"")) -> 0
A37: =A36+7 -> 45054 | B37: =A37+6 -> 45060 | C37: =SUMIFS('ALL Tube Results'!$G$2:$G99, 'ALL Tube Results'!$C$2:$C99, ">="&A37, 'ALL Tube Results'!$C$2:$C99, "<="&B37) -> 67 | D37: =COUNTIFS('ALL Tube Results'!$C37:$C99, ">="&A37, 'ALL Tube Results'!$C37:$C99, "<="&B37) -> 31 | E37: =COUNTIFS('ALL Tube Results'!$C37:$C99, ">="&A37, 'ALL Tube Results'!$C37:$C99, "<="&B37, 'ALL Tube Results'!$F37:$F99, "Positive") -> 0 | F37: =COUNTIFS('ALL Tube Results'!$C37:$C99, ">="&A37, 'ALL Tube Results'!$C37:$C99, "<="&B37, 'ALL Tube Results'!$F37:$F99, "Inconclusive") -> 0 | G37: =IFERROR(E37/D37,IFERROR(0/0,"")) -> 0
A38: =A37+7 -> 45061 | B38: =A38+6 -> 45067 | C38: =SUMIFS('ALL Tube Results'!$G$2:$G99, 'ALL Tube Results'!$C$2:$C99, ">="&A38, 'ALL Tube Results'!$C$2:$C99, "<="&B38) -> 54 | D38: =COUNTIFS('ALL Tube Results'!$C38:$C99, ">="&A38, 'ALL Tube Results'!$C38:$C99, "<="&B38) -> 31 | E38: =COUNTIFS('ALL Tube Results'!$C38:$C99, ">="&A38, 'ALL Tube Results'!$C38:$C99, "<="&B38, 'ALL Tube Results'!$F38:$F99, "Positive") -> 1 | F38: =COUNTIFS('ALL Tube Results'!$C38:$C99, ">="&A38, 'ALL Tube Results'!$C38:$C99, "<="&B38, 'ALL Tube Results'!$F38:$F99, "Inconclusive") -> 0 | G38: =IFERROR(E38/D38,IFERROR(0/0,"")) -> 0.032258065
A39: =A38+7 -> 45068 | B39: =A39+6 -> 45074 | C39: =SUMIFS('ALL Tube Results'!$G$2:$G99, 'ALL Tube Results'!$C$2:$C99, ">="&A39, 'ALL Tube Results'!$C$2:$C99, "<="&B39) -> 49 | D39: =COUNTIFS('ALL Tube Results'!$C39:$C99, ">="&A39, 'ALL Tube Results'!$C39:$C99, "<="&B39) -> 26 | E39: =COUNTIFS('ALL Tube Results'!$C39:$C99, ">="&A39, 'ALL Tube Results'!$C39:$C99, "<="&B39, 'ALL Tube Results'!$F39:$F99, "Positive") -> 4 | F39: =COUNTIFS('ALL Tube Results'!$C39:$C99, ">="&A39, 'ALL Tube Results'!$C39:$C99, "<="&B39, 'ALL Tube Results'!$F39:$F99, "Inconclusive") -> 0 | G39: =IFERROR(E39/D39,IFERROR(0/0,"")) -> 0.15384615
A40: =A39+7 -> 45075 | B40: =A40+6 -> 45081 | C40: =SUMIFS('ALL Tube Results'!$G$2:$G99, 'ALL Tube Results'!$C$2:$C99, ">="&A40, 'ALL Tube Results'!$C$2:$C99, "<="&B40) -> 43 | D40: =COUNTIFS('ALL Tube Results'!$C40:$C99, ">="&A40, 'ALL Tube Results'!$C40:$C99, "<="&B40) -> 25 | E40: =COUNTIFS('ALL Tube Results'!$C40:$C99, ">="&A40, 'ALL Tube Results'!$C40:$C99, "<="&B40, 'ALL Tube Results'!$F40:$F99, "Positive") -> 0 | F40: =COUNTIFS('ALL Tube Results'!$C40:$C99, ">="&A40, 'ALL Tube Results'!$C40:$C99, "<="&B40, 'ALL Tube Results'!$F40:$F99, "Inconclusive") -> 0 | G40: =IFERROR(E40/D40,IFERROR(0/0,"")) -> 0

Sheet Runs Compare
A1: ALL Tube RESULTS by Run ID | B1: =COUNT(B3:B259) -> 184 | C1: =SUM(C2:C259) -> 1379 | D1: =SUM(D2:D259) -> 1367 | E1: =SUM(E2:E259) -> 9 | F1: =SUM(F2:F259) -> 3 | H1: =SUM(H2:H259) -> 0 | L1: =SUM(L2:L259) -> 100 | M1: =SUM(M2:M259) -> 0 | N1: =SUM(N2:N259) -> 1 | P1: =SUM(P2:P259) -> 22 | R1: Run Reconciled RESULTS | S1: =CONCATENATE("Delta Run Reconciled to ALL Tubes ",T1-C1) -> Delta Run Reconciled to ALL Tubes 0 | T1: =SUM(T2:T259) -> 1379 | U1: =COUNTIF(U3:U259,FALSE) -> 0 | V1: =SUM(V2:V259) -> 0 | W1: =SUM(W2:W259) -> 0 | Y1: RFR Data - PreExcl RESULTS | AA1: =SUM(AA2:AA259) -> 1279 | AB1: =SUM(AB2:AB259) -> 1268 | AC1: =SUM(AC2:AC259) -> 9 | AD1: =SUM(AD2:AD259) -> 2 | AG1: APS Final RESULTS by Reconciled Run ID | AI1: =SUM(AI3:AI259) -> 1357 | AJ1: =SUM(AJ3:AJ259) -> 1346 | AK1: =SUM(AK3:AK259) -> 8 | AL1: =SUM(AL3:AL259) -> 3 | AM1: =SUM(AM3:AM259) -> 0 | AO1: APS Final RESULTS by Collect Date | AP1: =SUM(AP2:AP259) -> 660 | AQ1: =SUM(AQ2:AQ259) -> 506 | AR1: =SUM(AR2:AR259) -> 0 | AS1: =SUM(AS2:AS259) -> 0 | AT1: =SUM(AT2:AT259) -> 0
A2: Run ID | B2: Run Date | C2: Number of Tubes | D2: Negative | E2: Positive | F2: Inconclusive | H2: Delta to Run Reconciled Results | I2: T | J2: P | K2: I | L2: Delta to RFR preExcl Audit Num Run Tubes | M2: Delta to RFR preExcl Audit Num Positives | N2: Delta to RFR preExcl Audit Num Inconclusives | P2: Delta to APS | R2: Run ID | S2: Run Date | T2: Reconciled Tube Run Count | U2: Exact Run ID Match to ALL Tube Results (Col A) | Y2: Run ID - RFR Initial Only | Z2: Run Date | AA2: ='RFR Data - preExcl'!AK1 -> RFR Audit Num Run Tubes | AB2: Calculated Negs | AC2: ='RFR Data - preExcl'!AI1 -> Audit Pos Session Calls | AD2: ='RFR Data - preExcl'!AF1 -> Audit Inc Session Calls | AE2: preExcl Match Row | AG2: Final Assigned Run ID | AH2: Run Date | AI2: Number of Tubes | AJ2: Negative | AK2: Positive | AL2: Inconclusive | AM2: Null | AO2: ='APS Tubes by Date IMPORT'!B1 -> APS COLLECT DATE | AP2: Number of Tubes | AQ2: Negative | AR2: Positive | AS2: Inconclusive | AT2: Null
A3: {=SORT(UNIQUE('ALL Tube Results'!B2:B259))} -> RUN-ABRM_2022-09-05_RFR-001 | B3: =VLOOKUP(A3,'ALL Tube Results'!$B$2:$D259,2,FALSE) -> 44809 | C3: =COUNTIF('ALL Tube Results'!B2:B259, A3) -> 12 | D3: =COUNTIFS('ALL Tube Results'!$B2:$B259, $A3, 'ALL Tube Results'!$F2:$F259, "Negative") -> 12 | E3: =COUNTIFS('ALL Tube Results'!$B2:$B259, $A3, 'ALL Tube Results'!$F2:$F259, "Positive") -> 0 | F3: =COUNTIFS('ALL Tube Results'!$B2:$B259, $A3, 'ALL Tube Results'!$F2:$F259, "Inconclusive") -> 0 | G3: =IFERROR(VLOOKUP($A3,R$3:T259,3,FALSE),IFERROR(0/0,"") ) -> 12 | H3: =IF($C3=G3,IFERROR(0/0,""),$C3-G3) | I3: =IFERROR(VLOOKUP($A3,Y$3:AA259,3,FALSE),IFERROR(0/0,"") ) -> 12 | J3: =IFERROR(VLOOKUP($A3,Y$3:AD259,5,FALSE),IFERROR(0/0,"") ) -> 0 | K3: =IFERROR(VLOOKUP($A3,Y$3:AD259,6,FALSE),IFERROR(0/0,"")) -> 0 | L3: =IF($C3=I3,IFERROR(0/0,""),$C3-I3) | M3: =IF($E3=J3,IFERROR(0/0,""),$E3-J3) | N3: =IF($F3=K3,IFERROR(0/0,""),$F3-K3) | O3: =IFERROR(VLOOKUP($A3,AG$3:AI259,3,FALSE),IFERROR(0/0,"") ) -> 11 | P3: =IF($C3=O3,IFERROR(0/0,""),$C3-O3) -> 1 | R3: {=SORT('Run Reconcile'!A2:B259,1,TRUE)} -> RUN-ABRM_2022-09-05_RFR-001 | S3: 44809 | T3: =VLOOKUP(R3,'Run Reconcile'!$A$2:$L259,12,FALSE) -> 12 | U3: =IF(EXACT(A2,R2),IFERROR(0/0,""),FALSE) | Y3: =IFERROR(__xludf.DUMMYFUNCTION("SORT(FILTER('Run Reconcile'!A2:B259,'Run Reconcile'!A2:A259<>""*"",REGEXMATCH('Run Reconcile'!A2:A259,""RFR-"")),1,TRUE) "),"RUN-ABRM_2022-09-05_RFR-001") -> RUN-ABRM_2022-09-05_RFR-001 | Z3: =IFERROR(__xludf.DUMMYFUNCTION("""COMPUTED_VALUE"""),44809.0) -> 44809 | AA3: {=INDEX('RFR Data - preExcl'!AK$2:AK259,$AE3,1)} -> 12 | AB3: =AA3-AC3-AD3 -> 12 | AC3: {=INDEX('RFR Data - preExcl'!AI$2:AI259,$AE3,1)} -> 0 | AD3: {=INDEX('RFR Data - preExcl'!AF$2:AF259,$AE3,1)} -> 0 | AE3: =IFNA(MATCH(Y3,'RFR Data - preExcl'!A$2:A259,0),"") -> 1 | AG3: {=SORT(UNIQUE('APS Tubes IMPORT'!V2:V259))} -> RUN-ABRM_2022-09-05_RFR-001 | AH3: =VLOOKUP(AG3,'Run Reconcile'!A$2:B259,2,FALSE) -> 44809 | AI3: =COUNTIF('APS Tubes IMPORT'!$V$2:$V259, AG3) -> 11 | AJ3: =COUNTIFS('APS Tubes IMPORT'!V$2:V259, AG3, 'APS Tubes IMPORT'!H$2:H259, "Negative") -> 11 | AK3: =COUNTIFS('APS Tubes IMPORT'!V$2:V259, AG3, 'APS Tubes IMPORT'!H$2:H259, "Positive") -> 0 | AL3: =COUNTIFS('APS Tubes IMPORT'!V$2:V259, AG3, 'APS Tubes IMPORT'!H$2:H259, "Inconclusive") -> 0 | AM3: =COUNTIFS('APS Tubes IMPORT'!V$2:V259, AG3, 'APS Tubes IMPORT'!H$2:H259, "Null") -> 0 | AO3: ='APS Tubes by Date IMPORT'!B2 -> 44809 | AP3: ='APS Tubes by Date IMPORT'!C2 -> 11 | AQ3: ='APS Tubes by Date IMPORT'!D2 -> 11 | AR3: ='APS Tubes by Date IMPORT'!E2 -> 0 | AS3: ='APS Tubes by Date IMPORT'!F2 -> 0 | AT3: ='APS Tubes by Date IMPORT'!G2 -> 0
A4: RUN-ABRM_2022-09-06_RFR-002 | B4: =VLOOKUP(A4,'ALL Tube Results'!$B$2:$D259,2,FALSE) -> 44810 | C4: =COUNTIF('ALL Tube Results'!B3:B259, A4) -> 13 | D4: =COUNTIFS('ALL Tube Results'!$B3:$B259, $A4, 'ALL Tube Results'!$F3:$F259, "Negative") -> 13 | E4: =COUNTIFS('ALL Tube Results'!$B3:$B259, $A4, 'ALL Tube Results'!$F3:$F259, "Positive") -> 0 | F4: =COUNTIFS('ALL Tube Results'!$B3:$B259, $A4, 'ALL Tube Results'!$F3:$F259, "Inconclusive") -> 0 | G4: =IFERROR(VLOOKUP($A4,R$3:T260,3,FALSE),IFERROR(0/0,"") ) -> 13 | H4: =IF($C4=G4,IFERROR(0/0,""),$C4-G4) | I4: =IFERROR(VLOOKUP($A4,Y$3:AA260,3,FALSE),IFERROR(0/0,"") ) -> 13 | J4: =IFERROR(VLOOKUP($A4,Y$3:AD260,5,FALSE),IFERROR(0/0,"") ) -> 0 | K4: =IFERROR(VLOOKUP($A4,Y$3:AD260,6,FALSE),IFERROR(0/0,"")) -> 0 | L4: =IF($C4=I4,IFERROR(0/0,""),$C4-I4) | M4: =IF($E4=J4,IFERROR(0/0,""),$E4-J4) | N4: =IF($F4=K4,IFERROR(0/0,""),$F4-K4) | O4: =IFERROR(VLOOKUP($A4,AG$3:AI260,3,FALSE),IFERROR(0/0,"") ) -> 7 | P4: =IF($C4=O4,IFERROR(0/0,""),$C4-O4) -> 6 | R4: RUN-ABRM_2022-09-06_RFR-002 | S4: 44810 | T4: =VLOOKUP(R4,'Run Reconcile'!$A$2:$L259,12,FALSE) -> 13 | U4: =IF(EXACT(A3,R3),IFERROR(0/0,""),FALSE) | Y4: =IFERROR(__xludf.DUMMYFUNCTION("""COMPUTED_VALUE"""),"RUN-ABRM_2022-09-06_RFR-002") -> RUN-ABRM_2022-09-06_RFR-002 | Z4: =IFERROR(__xludf.DUMMYFUNCTION("""COMPUTED_VALUE"""),44810.0) -> 44810 | AA4: {=INDEX('RFR Data - preExcl'!AK$2:AK259,$AE4,1)} -> 13 | AB4: =AA4-AC4-AD4 -> 13 | AC4: {=INDEX('RFR Data - preExcl'!AI$2:AI259,$AE4,1)} -> 0 | AD4: {=INDEX('RFR Data - preExcl'!AF$2:AF259,$AE4,1)} -> 0 | AE4: =IFNA(MATCH(Y4,'RFR Data - preExcl'!A$2:A259,0),"") -> 2 | AG4: RUN-ABRM_2022-09-06_RFR-002 | AH4: =VLOOKUP(AG4,'Run Reconcile'!A$2:B259,2,FALSE) -> 44810 | AI4: =COUNTIF('APS Tubes IMPORT'!$V$2:$V259, AG4) -> 7 | AJ4: =COUNTIFS('APS Tubes IMPORT'!V$2:V259, AG4, 'APS Tubes IMPORT'!H$2:H259, "Negative") -> 7 | AK4: =COUNTIFS('APS Tubes IMPORT'!V3:V259, AG4, 'APS Tubes IMPORT'!H3:H259, "Positive") -> 0 | AL4: =COUNTIFS('APS Tubes IMPORT'!V3:V259, AG4, 'APS Tubes IMPORT'!H3:H259, "Inconclusive") -> 0 | AM4: =COUNTIFS('APS Tubes IMPORT'!V3:V259, AG4, 'APS Tubes IMPORT'!H3:H259, "Null") -> 0 | AO4: ='APS Tubes by Date IMPORT'!B3 -> 44810 | AP4: ='APS Tubes by Date IMPORT'!C3 -> 7 | AQ4: ='APS Tubes by Date IMPORT'!D3 -> 7 | AR4: ='APS Tubes by Date IMPORT'!E3 -> 0 | AS4: ='APS Tubes by Date IMPORT'!F3 -> 0 | AT4: ='APS Tubes by Date IMPORT'!G3 -> 0
A5: RUN-ABRM_2022-09-07_RFR-003 | B5: =VLOOKUP(A5,'ALL Tube Results'!$B$2:$D259,2,FALSE) -> 44811 | C5: =COUNTIF('ALL Tube Results'!B4:B259, A5) -> 11 | D5: =COUNTIFS('ALL Tube Results'!$B4:$B259, $A5, 'ALL Tube Results'!$F4:$F259, "Negative") -> 11 | E5: =COUNTIFS('ALL Tube Results'!$B4:$B259, $A5, 'ALL Tube Results'!$F4:$F259, "Positive") -> 0 | F5: =COUNTIFS('ALL Tube Results'!$B4:$B259, $A5, 'ALL Tube Results'!$F4:$F259, "Inconclusive") -> 0 | G5: =IFERROR(VLOOKUP($A5,R$3:T261,3,FALSE),IFERROR(0/0,"") ) -> 11 | H5: =IF($C5=G5,IFERROR(0/0,""),$C5-G5) | I5: =IFERROR(VLOOKUP($A5,Y$3:AA261,3,FALSE),IFERROR(0/0,"") ) -> 11 | J5: =IFERROR(VLOOKUP($A5,Y$3:AD261,5,FALSE),IFERROR(0/0,"") ) -> 0 | K5: =IFERROR(VLOOKUP($A5,Y$3:AD261,6,FALSE),IFERROR(0/0,"")) -> 0 | L5: =IF($C5=I5,IFERROR(0/0,""),$C5-I5) | M5: =IF($E5=J5,IFERROR(0/0,""),$E5-J5) | N5: =IF($F5=K5,IFERROR(0/0,""),$F5-K5) | O5: =IFERROR(VLOOKUP($A5,AG$3:AI261,3,FALSE),IFERROR(0/0,"") ) -> 11 | P5: =IF($C5=O5,IFERROR(0/0,""),$C5-O5) | R5: RUN-ABRM_2022-09-07_RFR-003 | S5: 44811 | T5: =VLOOKUP(R5,'Run Reconcile'!$A$2:$L259,12,FALSE) -> 11 | U5: =IF(EXACT(A4,R4),IFERROR(0/0,""),FALSE) | Y5: =IFERROR(__xludf.DUMMYFUNCTION("""COMPUTED_VALUE"""),"RUN-ABRM_2022-09-07_RFR-003") -> RUN-ABRM_2022-09-07_RFR-003 | Z5: =IFERROR(__xludf.DUMMYFUNCTION("""COMPUTED_VALUE"""),44811.0) -> 44811 | AA5: {=INDEX('RFR Data - preExcl'!AK$2:AK259,$AE5,1)} -> 11 | AB5: =AA5-AC5-AD5 -> 11 | AC5: {=INDEX('RFR Data - preExcl'!AI$2:AI259,$AE5,1)} -> 0 | AD5: {=INDEX('RFR Data - preExcl'!AF$2:AF259,$AE5,1)} -> 0 | AE5: =IFNA(MATCH(Y5,'RFR Data - preExcl'!A$2:A259,0),"") -> 3 | AG5: RUN-ABRM_2022-09-07_RFR-003 | AH5: =VLOOKUP(AG5,'Run Reconcile'!A$2:B259,2,FALSE) -> 44811 | AI5: =COUNTIF('APS Tubes IMPORT'!$V$2:$V259, AG5) -> 11 | AJ5: =COUNTIFS('APS Tubes IMPORT'!V$2:V259, AG5, 'APS Tubes IMPORT'!H$2:H259, "Negative") -> 11 | AK5: =COUNTIFS('APS Tubes IMPORT'!V4:V259, AG5, 'APS Tubes IMPORT'!H4:H259, "Positive") -> 0 | AL5: =COUNTIFS('APS Tubes IMPORT'!V4:V259, AG5, 'APS Tubes IMPORT'!H4:H259, "Inconclusive") -> 0 | AM5: =COUNTIFS('APS Tubes IMPORT'!V4:V259, AG5, 'APS Tubes IMPORT'!H4:H259, "Null") -> 0 | AO5: ='APS Tubes by Date IMPORT'!B4 -> 44811 | AP5: ='APS Tubes by Date IMPORT'!C4 -> 11 | AQ5: ='APS Tubes by Date IMPORT'!D4 -> 11 | AR5: ='APS Tubes by Date IMPORT'!E4 -> 0 | AS5: ='APS Tubes by Date IMPORT'!F4 -> 0 | AT5: ='APS Tubes by Date IMPORT'!G4 -> 0
