Workbook

Sheet ALL Tube Results
A1: =IFERROR(__xludf.DUMMYFUNCTION("QUERY({ 'APS Tubes IMPORT'!A1:A1579; 'ARF Tubes'!M2:M1579 }, ""SELECT Col1 WHERE Col1 IS NOT NULL"", 0)"),"TUBE ID") -> TUBE ID | B1: =IFERROR(__xludf.DUMMYFUNCTION("QUERY({ 'APS Tubes IMPORT'!V1:V1579; 'ARF Tubes'!N2:N1579 }, ""SELECT Col1 WHERE Col1 IS NOT NULL"", 0)"),"FINAL ASSIGNED RUN ID") -> FINAL ASSIGNED RUN ID | C1: ='Run Reconcile'!B1 -> RUN DATE | D1: ='APS Tubes IMPORT'!B1 -> COLLECTION DATE | E1: ='APS Tubes IMPORT'!C1 -> COLLECTION TIME | F1: =IFERROR(__xludf.DUMMYFUNCTION("QUERY({ 'APS Tubes IMPORT'!H1:H1579; 'ARF Tubes'!P2:P1579 }, ""SELECT Col1 WHERE Col1 IS NOT NULL"", 0)"),"FINAL RESULT") -> FINAL RESULT | G1: ='APS Tubes IMPORT'!N1 -> NUM SAMPLES (Pool Level) | H1: =IFERROR(__xludf.DUMMYFUNCTION("QUERY({ 'APS Tubes IMPORT'!AE1:AE1579 }, ""SELECT Col1 WHERE Col1 IS NOT NULL"", 0)"),"FINAL GROUP") -> FINAL GROUP | I1: FLSP | J1: CRLN | K1: =COUNTIF($H1:$H1579,#REF!) -> 0
A2: =IFERROR(__xludf.DUMMYFUNCTION("""COMPUTED_VALUE"""),"351390") -> 351390 | B2: =IFERROR(__xludf.DUMMYFUNCTION("""COMPUTED_VALUE"""),"RUN-FLMP_2020-12-11_APS-001") -> RUN-FLMP_2020-12-11_APS-001 | C2: =VLOOKUP(B2,'Run Reconcile'!A$2:B1579,2,FALSE) -> 44176 | D2: =IFERROR(__xludf.DUMMYFUNCTION("QUERY({ 'APS Tubes IMPORT'!B2:B1579 }, ""SELECT Col1 WHERE Col1 IS NOT NULL"", 0)"),44176.0) -> 44176 | E2: =IFERROR(__xludf.DUMMYFUNCTION("QUERY({ 'APS Tubes IMPORT'!C2:C1579; 'ARF Tubes'!P2:P1579 }, ""SELECT Col1 WHERE Col1 IS NOT NULL"", 0)"),0.356550925924239) -> 0.35655093 | F2: =IFERROR(__xludf.DUMMYFUNCTION("""COMPUTED_VALUE"""),"Negative") -> Negative | G2: =IFERROR(__xludf.DUMMYFUNCTION("QUERY({ 'APS Tubes IMPORT'!N2:N1579 }, ""SELECT Col1 WHERE Col1 IS NOT NULL"", 0)"),3.0) -> 3 | H2: =IFERROR(__xludf.DUMMYFUNCTION("""COMPUTED_VALUE"""),"FLSP") -> FLSP | I2: =COUNTIF($H2:$H1579,I1) -> 524 | J2: =COUNTIF($H2:$H1579,J1) -> 1016 | K2: =I2+J2 -> 1540
A3: =IFERROR(__xludf.DUMMYFUNCTION("""COMPUTED_VALUE"""),"351392") -> 351392 | B3: =IFERROR(__xludf.DUMMYFUNCTION("""COMPUTED_VALUE"""),"RUN-FLMP_2020-12-11_APS-001") -> RUN-FLMP_2020-12-11_APS-001 | C3: =VLOOKUP(B3,'Run Reconcile'!A$2:B1579,2,FALSE) -> 44176 | D3: =IFERROR(__xludf.DUMMYFUNCTION("""COMPUTED_VALUE"""),44176.0) -> 44176 | E3: =IFERROR(__xludf.DUMMYFUNCTION("""COMPUTED_VALUE"""),0.3628240740727051) -> 0.36282407 | F3: =IFERROR(__xludf.DUMMYFUNCTION("""COMPUTED_VALUE"""),"Negative") -> Negative | G3: =IFERROR(__xludf.DUMMYFUNCTION("""COMPUTED_VALUE"""),3.0) -> 3 | H3: =IFERROR(__xludf.DUMMYFUNCTION("""COMPUTED_VALUE"""),"FLSP") -> FLSP
A4: =IFERROR(__xludf.DUMMYFUNCTION("""COMPUTED_VALUE"""),"336361") -> 336361 | B4: =IFERROR(__xludf.DUMMYFUNCTION("""COMPUTED_VALUE"""),"RUN-FLMP_2020-12-19_APS-002") -> RUN-FLMP_2020-12-19_APS-002 | C4: =VLOOKUP(B4,'Run Reconcile'!A$2:B1579,2,FALSE) -> 44184 | D4: =IFERROR(__xludf.DUMMYFUNCTION("""COMPUTED_VALUE"""),44184.0) -> 44184 | E4: =IFERROR(__xludf.DUMMYFUNCTION("""COMPUTED_VALUE"""),0.4414351851846732) -> 0.44143519 | F4: =IFERROR(__xludf.DUMMYFUNCTION("""COMPUTED_VALUE"""),"Negative") -> Negative | G4: =IFERROR(__xludf.DUMMYFUNCTION("""COMPUTED_VALUE"""),3.0) -> 3 | H4: =IFERROR(__xludf.DUMMYFUNCTION("""COMPUTED_VALUE"""),"FLSP") -> FLSP | I4: 44528 | J4: =MATCH(I4,C$2:C1579,0)+1 -> 208
A5: =IFERROR(__xludf.DUMMYFUNCTION("""COMPUTED_VALUE"""),"425015") -> 425015 | B5: =IFERROR(__xludf.DUMMYFUNCTION("""COMPUTED_VALUE"""),"RUN-FLMP_2020-12-22_APS-003") -> RUN-FLMP_2020-12-22_APS-003 | C5: =VLOOKUP(B5,'Run Reconcile'!A$2:B1579,2,FALSE) -> 44187 | D5: =IFERROR(__xludf.DUMMYFUNCTION("""COMPUTED_VALUE"""),44187.0) -> 44187 | E5: =IFERROR(__xludf.DUMMYFUNCTION("""COMPUTED_VALUE"""),0.7623379629621923) -> 0.76233796 | F5: =IFERROR(__xludf.DUMMYFUNCTION("""COMPUTED_VALUE"""),"Negative") -> Negative | G5: =IFERROR(__xludf.DUMMYFUNCTION("""COMPUTED_VALUE"""),2.0) -> 2 | H5: =IFERROR(__xludf.DUMMYFUNCTION("""COMPUTED_VALUE"""),"FLSP") -> FLSP | I5: 44718 | J5: =MATCH(I5,C$2:C1580,0)+1 -> 1379 | K5: enter these below
A6: =IFERROR(__xludf.DUMMYFUNCTION("""COMPUTED_VALUE"""),"351402") -> 351402 | B6: =IFERROR(__xludf.DUMMYFUNCTION("""COMPUTED_VALUE"""),"RUN-FLMP_2020-12-28_APS-004") -> RUN-FLMP_2020-12-28_APS-004 | C6: =VLOOKUP(B6,'Run Reconcile'!A$2:B1579,2,FALSE) -> 44193 | D6: =IFERROR(__xludf.DUMMYFUNCTION("""COMPUTED_VALUE"""),44193.0) -> 44193 | E6: =IFERROR(__xludf.DUMMYFUNCTION("""COMPUTED_VALUE"""),0.4721643518532801) -> 0.47216435 | F6: =IFERROR(__xludf.DUMMYFUNCTION("""COMPUTED_VALUE"""),"Negative") -> Negative | G6: =IFERROR(__xludf.DUMMYFUNCTION("""COMPUTED_VALUE"""),4.0) -> 4 | H6: =IFERROR(__xludf.DUMMYFUNCTION("""COMPUTED_VALUE"""),"FLSP") -> FLSP | J6: =J5-J4+1 -> 1172
A7: =IFERROR(__xludf.DUMMYFUNCTION("""COMPUTED_VALUE"""),"336362") -> 336362 | B7: =IFERROR(__xludf.DUMMYFUNCTION("""COMPUTED_VALUE"""),"RUN-FLMP_2020-12-28_APS-004") -> RUN-FLMP_2020-12-28_APS-004 | C7: =VLOOKUP(B7,'Run Reconcile'!A$2:B1579,2,FALSE) -> 44193 | D7: =IFERROR(__xludf.DUMMYFUNCTION("""COMPUTED_VALUE"""),44193.0) -> 44193 | E7: =IFERROR(__xludf.DUMMYFUNCTION("""COMPUTED_VALUE"""),0.49696759259313694) -> 0.49696759 | F7: =IFERROR(__xludf.DUMMYFUNCTION("""COMPUTED_VALUE"""),"Negative") -> Negative | G7: =IFERROR(__xludf.DUMMYFUNCTION("""COMPUTED_VALUE"""),2.0) -> 2 | H7: =IFERROR(__xludf.DUMMYFUNCTION("""COMPUTED_VALUE"""),"FLSP") -> FLSP
A8: =IFERROR(__xludf.DUMMYFUNCTION("""COMPUTED_VALUE"""),"351429") -> 351429 | B8: =IFERROR(__xludf.DUMMYFUNCTION("""COMPUTED_VALUE"""),"RUN-FLMP_2021-01-11_APS-005") -> RUN-FLMP_2021-01-11_APS-005 | C8: =VLOOKUP(B8,'Run Reconcile'!A$2:B1579,2,FALSE) -> 44207 | D8: =IFERROR(__xludf.DUMMYFUNCTION("""COMPUTED_VALUE"""),44207.0) -> 44207 | E8: =IFERROR(__xludf.DUMMYFUNCTION("""COMPUTED_VALUE"""),0.3889467592598521) -> 0.38894676 | F8: =IFERROR(__xludf.DUMMYFUNCTION("""COMPUTED_VALUE"""),"Negative") -> Negative | G8: =IFERROR(__xludf.DUMMYFUNCTION("""COMPUTED_VALUE"""),4.0) -> 4 | H8: =IFERROR(__xludf.DUMMYFUNCTION("""COMPUTED_VALUE"""),"FLSP") -> FLSP
A9: =IFERROR(__xludf.DUMMYFUNCTION("""COMPUTED_VALUE"""),"351447") -> 351447 | B9: =IFERROR(__xludf.DUMMYFUNCTION("""COMPUTED_VALUE"""),"RUN-FLMP_2021-01-11_APS-005") -> RUN-FLMP_2021-01-11_APS-005 | C9: =VLOOKUP(B9,'Run Reconcile'!A$2:B1579,2,FALSE) -> 44207 | D9: =IFERROR(__xludf.DUMMYFUNCTION("""COMPUTED_VALUE"""),44207.0) -> 44207 | E9: =IFERROR(__xludf.DUMMYFUNCTION("""COMPUTED_VALUE"""),0.3952083333315386) -> 0.39520833 | F9: =IFERROR(__xludf.DUMMYFUNCTION("""COMPUTED_VALUE"""),"Negative") -> Negative | G9: =IFERROR(__xludf.DUMMYFUNCTION("""COMPUTED_VALUE"""),1.0) -> 1 | H9: =IFERROR(__xludf.DUMMYFUNCTION("""COMPUTED_VALUE"""),"FLSP") -> FLSP | I9: =COUNTIF($H$208:$H$1378,I1) -> 200 | J9: =COUNTIF($H$208:$H$1378,J1) -> 971 | K9: =I9+J9 -> 1171
A10: =IFERROR(__xludf.DUMMYFUNCTION("""COMPUTED_VALUE"""),"351450") -> 351450 | B10: =IFERROR(__xludf.DUMMYFUNCTION("""COMPUTED_VALUE"""),"RUN-FLMP_2021-01-11_APS-005") -> RUN-FLMP_2021-01-11_APS-005 | C10: =VLOOKUP(B10,'Run Reconcile'!A$2:B1579,2,FALSE) -> 44207 | D10: =IFERROR(__xludf.DUMMYFUNCTION("""COMPUTED_VALUE"""),44207.0) -> 44207 | E10: =IFERROR(__xludf.DUMMYFUNCTION("""COMPUTED_VALUE"""),0.3982523148151813) -> 0.39825231 | F10: =IFERROR(__xludf.DUMMYFUNCTION("""COMPUTED_VALUE"""),"Negative") -> Negative | G10: =IFERROR(__xludf.DUMMYFUNCTION("""COMPUTED_VALUE"""),4.0) -> 4 | H10: =IFERROR(__xludf.DUMMYFUNCTION("""COMPUTED_VALUE"""),"FLSP") -> FLSP | I10: =I9/K9 -> 0.17079419 | J10: =J9/K9 -> 0.82920581
A11: =IFERROR(__xludf.DUMMYFUNCTION("""COMPUTED_VALUE"""),"351448") -> 351448 | B11: =IFERROR(__xludf.DUMMYFUNCTION("""COMPUTED_VALUE"""),"RUN-FLMP_2021-01-11_APS-005") -> RUN-FLMP_2021-01-11_APS-005 | C11: =VLOOKUP(B11,'Run Reconcile'!A$2:B1579,2,FALSE) -> 44207 | D11: =IFERROR(__xludf.DUMMYFUNCTION("""COMPUTED_VALUE"""),44207.0) -> 44207 | E11: =IFERROR(__xludf.DUMMYFUNCTION("""COMPUTED_VALUE"""),0.3986574074078817) -> 0.39865741 | F11: =IFERROR(__xludf.DUMMYFUNCTION("""COMPUTED_VALUE"""),"Negative") -> Negative | G11: =IFERROR(__xludf.DUMMYFUNCTION("""COMPUTED_VALUE"""),4.0) -> 4 | H11: =IFERROR(__xludf.DUMMYFUNCTION("""COMPUTED_VALUE"""),"FLSP") -> FLSP
A12: =IFERROR(__xludf.DUMMYFUNCTION("""COMPUTED_VALUE"""),"351425") -> 351425 | B12: =IFERROR(__xludf.DUMMYFUNCTION("""COMPUTED_VALUE"""),"RUN-FLMP_2021-01-13_APS-006") -> RUN-FLMP_2021-01-13_APS-006 | C12: =VLOOKUP(B12,'Run Reconcile'!A$2:B1579,2,FALSE) -> 44209 | D12: =IFERROR(__xludf.DUMMYFUNCTION("""COMPUTED_VALUE"""),44209.0) -> 44209 | E12: =IFERROR(__xludf.DUMMYFUNCTION("""COMPUTED_VALUE"""),0.32501157407386927) -> 0.32501157 | F12: =IFERROR(__xludf.DUMMYFUNCTION("""COMPUTED_VALUE"""),"Negative") -> Negative | G12: =IFERROR(__xludf.DUMMYFUNCTION("""COMPUTED_VALUE"""),1.0) -> 1 | H12: =IFERROR(__xludf.DUMMYFUNCTION("""COMPUTED_VALUE"""),"FLSP") -> FLSP
A13: =IFERROR(__xludf.DUMMYFUNCTION("""COMPUTED_VALUE"""),"351427") -> 351427 | B13: =IFERROR(__xludf.DUMMYFUNCTION("""COMPUTED_VALUE"""),"RUN-FLMP_2021-01-13_APS-006") -> RUN-FLMP_2021-01-13_APS-006 | C13: =VLOOKUP(B13,'Run Reconcile'!A$2:B1579,2,FALSE) -> 44209 | D13: =IFERROR(__xludf.DUMMYFUNCTION("""COMPUTED_VALUE"""),44209.0) -> 44209 | E13: =IFERROR(__xludf.DUMMYFUNCTION("""COMPUTED_VALUE"""),0.32784722222277196) -> 0.32784722 | F13: =IFERROR(__xludf.DUMMYFUNCTION("""COMPUTED_VALUE"""),"Negative") -> Negative | G13: =IFERROR(__xludf.DUMMYFUNCTION("""COMPUTED_VALUE"""),2.0) -> 2 | H13: =IFERROR(__xludf.DUMMYFUNCTION("""COMPUTED_VALUE"""),"FLSP") -> FLSP
A14: =IFERROR(__xludf.DUMMYFUNCTION("""COMPUTED_VALUE"""),"351428") -> 351428 | B14: =IFERROR(__xludf.DUMMYFUNCTION("""COMPUTED_VALUE"""),"RUN-FLMP_2021-01-13_APS-006") -> RUN-FLMP_2021-01-13_APS-006 | C14: =VLOOKUP(B14,'Run Reconcile'!A$2:B1579,2,FALSE) -> 44209 | D14: =IFERROR(__xludf.DUMMYFUNCTION("""COMPUTED_VALUE"""),44209.0) -> 44209 | E14: =IFERROR(__xludf.DUMMYFUNCTION("""COMPUTED_VALUE"""),0.32894675925854244) -> 0.32894676 | F14: =IFERROR(__xludf.DUMMYFUNCTION("""COMPUTED_VALUE"""),"Negative") -> Negative | G14: =IFERROR(__xludf.DUMMYFUNCTION("""COMPUTED_VALUE"""),4.0) -> 4 | H14: =IFERROR(__xludf.DUMMYFUNCTION("""COMPUTED_VALUE"""),"FLSP") -> FLSP
A15: =IFERROR(__xludf.DUMMYFUNCTION("""COMPUTED_VALUE"""),"351441") -> 351441 | B15: =IFERROR(__xludf.DUMMYFUNCTION("""COMPUTED_VALUE"""),"RUN-FLMP_2021-01-13_APS-006") -> RUN-FLMP_2021-01-13_APS-006 | C15: =VLOOKUP(B15,'Run Reconcile'!A$2:B1579,2,FALSE) -> 44209 | D15: =IFERROR(__xludf.DUMMYFUNCTION("""COMPUTED_VALUE"""),44209.0) -> 44209 | E15: =IFERROR(__xludf.DUMMYFUNCTION("""COMPUTED_VALUE"""),0.47378472222044365) -> 0.47378472 | F15: =IFERROR(__xludf.DUMMYFUNCTION("""COMPUTED_VALUE"""),"Negative") -> Negative | G15: =IFERROR(__xludf.DUMMYFUNCTION("""COMPUTED_VALUE"""),4.0) -> 4 | H15: =IFERROR(__xludf.DUMMYFUNCTION("""COMPUTED_VALUE"""),"FLSP") -> FLSP
A16: =IFERROR(__xludf.DUMMYFUNCTION("""COMPUTED_VALUE"""),"351430") -> 351430 | B16: =IFERROR(__xludf.DUMMYFUNCTION("""COMPUTED_VALUE"""),"RUN-FLMP_2021-01-15_APS-007") -> RUN-FLMP_2021-01-15_APS-007 | C16: =VLOOKUP(B16,'Run Reconcile'!A$2:B1579,2,FALSE) -> 44211 | D16: =IFERROR(__xludf.DUMMYFUNCTION("""COMPUTED_VALUE"""),44211.0) -> 44211 | E16: =IFERROR(__xludf.DUMMYFUNCTION("""COMPUTED_VALUE"""),0.32527777777795563) -> 0.32527778 | F16: =IFERROR(__xludf.DUMMYFUNCTION("""COMPUTED_VALUE"""),"Positive") -> Positive | G16: =IFERROR(__xludf.DUMMYFUNCTION("""COMPUTED_VALUE"""),2.0) -> 2 | H16: =IFERROR(__xludf.DUMMYFUNCTION("""COMPUTED_VALUE"""),"FLSP") -> FLSP
A17: =IFERROR(__xludf.DUMMYFUNCTION("""COMPUTED_VALUE"""),"351426") -> 351426 | B17: =IFERROR(__xludf.DUMMYFUNCTION("""COMPUTED_VALUE"""),"RUN-FLMP_2021-01-15_APS-007") -> RUN-FLMP_2021-01-15_APS-007 | C17: =VLOOKUP(B17,'Run Reconcile'!A$2:B1579,2,FALSE) -> 44211 | D17: =IFERROR(__xludf.DUMMYFUNCTION("""COMPUTED_VALUE"""),44211.0) -> 44211 | E17: =IFERROR(__xludf.DUMMYFUNCTION("""COMPUTED_VALUE"""),0.3357175925921183) -> 0.33571759 | F17: =IFERROR(__xludf.DUMMYFUNCTION("""COMPUTED_VALUE"""),"Negative") -> Negative | G17: =IFERROR(__xludf.DUMMYFUNCTION("""COMPUTED_VALUE"""),2.0) -> 2 | H17: =IFERROR(__xludf.DUMMYFUNCTION("""COMPUTED_VALUE"""),"FLSP") -> FLSP
A18: =IFERROR(__xludf.DUMMYFUNCTION("""COMPUTED_VALUE"""),"424944") -> 424944 | B18: =IFERROR(__xludf.DUMMYFUNCTION("""COMPUTED_VALUE"""),"RUN-FLMP_2021-01-15_APS-007") -> RUN-FLMP_2021-01-15_APS-007 | C18: =VLOOKUP(B18,'Run Reconcile'!A$2:B1579,2,FALSE) -> 44211 | D18: =IFERROR(__xludf.DUMMYFUNCTION("""COMPUTED_VALUE"""),44211.0) -> 44211 | E18: =IFERROR(__xludf.DUMMYFUNCTION("""COMPUTED_VALUE"""),0.4014120370375167) -> 0.40141204 | F18: =IFERROR(__xludf.DUMMYFUNCTION("""COMPUTED_VALUE"""),"Negative") -> Negative | G18: =IFERROR(__xludf.DUMMYFUNCTION("""COMPUTED_VALUE"""),4.0) -> 4 | H18: =IFERROR(__xludf.DUMMYFUNCTION("""COMPUTED_VALUE"""),"FLSP") -> FLSP
A19: =IFERROR(__xludf.DUMMYFUNCTION("""COMPUTED_VALUE"""),"351430A") -> 351430A | B19: =IFERROR(__xludf.DUMMYFUNCTION("""COMPUTED_VALUE"""),"RUN-FLMP_2021-01-15_APS-007") -> RUN-FLMP_2021-01-15_APS-007 | C19: =VLOOKUP(B19,'Run Reconcile'!A$2:B1579,2,FALSE) -> 44211 | D19: =IFERROR(__xludf.DUMMYFUNCTION("""COMPUTED_VALUE"""),44211.0) -> 44211 | E19: =IFERROR(__xludf.DUMMYFUNCTION("""COMPUTED_VALUE"""),0.6666666666678793) -> 0.66666667 | F19: =IFERROR(__xludf.DUMMYFUNCTION("""COMPUTED_VALUE"""),"Negative") -> Negative | G19: =IFERROR(__xludf.DUMMYFUNCTION("""COMPUTED_VALUE"""),1.0) -> 1 | H19: =IFERROR(__xludf.DUMMYFUNCTION("""COMPUTED_VALUE"""),"FLSP") -> FLSP
A20: =IFERROR(__xludf.DUMMYFUNCTION("""COMPUTED_VALUE"""),"351430B") -> 351430B | B20: =IFERROR(__xludf.DUMMYFUNCTION("""COMPUTED_VALUE"""),"RUN-FLMP_2021-01-15_APS-007") -> RUN-FLMP_2021-01-15_APS-007 | C20: =VLOOKUP(B20,'Run Reconcile'!A$2:B1579,2,FALSE) -> 44211 | D20: =IFERROR(__xludf.DUMMYFUNCTION("""COMPUTED_VALUE"""),44211.0) -> 44211 | E20: =IFERROR(__xludf.DUMMYFUNCTION("""COMPUTED_VALUE"""),0.6666666666678793) -> 0.66666667 | F20: =IFERROR(__xludf.DUMMYFUNCTION("""COMPUTED_VALUE"""),"Positive") -> Positive | G20: =IFERROR(__xludf.DUMMYFUNCTION("""COMPUTED_VALUE"""),1.0) -> 1 | H20: =IFERROR(__xludf.DUMMYFUNCTION("""COMPUTED_VALUE"""),"FLSP") -> FLSP
A21: =IFERROR(__xludf.DUMMYFUNCTION("""COMPUTED_VALUE"""),"351430C") -> 351430C | B21: =IFERROR(__xludf.DUMMYFUNCTION("""COMPUTED_VALUE"""),"RUN-FLMP_2021-01-15_APS-007") -> RUN-FLMP_2021-01-15_APS-007 | C21: =VLOOKUP(B21,'Run Reconcile'!A$2:B1579,2,FALSE) -> 44211 | D21: =IFERROR(__xludf.DUMMYFUNCTION("""COMPUTED_VALUE"""),44211.0) -> 44211 | E21: =IFERROR(__xludf.DUMMYFUNCTION("""COMPUTED_VALUE"""),0.6666666666678793) -> 0.66666667 | F21: =IFERROR(__xludf.DUMMYFUNCTION("""COMPUTED_VALUE"""),"Negative") -> Negative | G21: =IFERROR(__xludf.DUMMYFUNCTION("""COMPUTED_VALUE"""),1.0) -> 1 | H21: =IFERROR(__xludf.DUMMYFUNCTION("""COMPUTED_VALUE"""),"FLSP") -> FLSP
A22: =IFERROR(__xludf.DUMMYFUNCTION("""COMPUTED_VALUE"""),"351430D") -> 351430D | B22: =IFERROR(__xludf.DUMMYFUNCTION("""COMPUTED_VALUE"""),"RUN-FLMP_2021-01-15_APS-007") -> RUN-FLMP_2021-01-15_APS-007 | C22: =VLOOKUP(B22,'Run Reconcile'!A$2:B1579,2,FALSE) -> 44211 | D22: =IFERROR(__xludf.DUMMYFUNCTION("""COMPUTED_VALUE"""),44211.0) -> 44211 | E22: =IFERROR(__xludf.DUMMYFUNCTION("""COMPUTED_VALUE"""),0.6666666666678793) -> 0.66666667 | F22: =IFERROR(__xludf.DUMMYFUNCTION("""COMPUTED_VALUE"""),"Positive") -> Positive | G22: =IFERROR(__xludf.DUMMYFUNCTION("""COMPUTED_VALUE"""),1.0) -> 1 | H22: =IFERROR(__xludf.DUMMYFUNCTION("""COMPUTED_VALUE"""),"FLSP") -> FLSP
A23: =IFERROR(__xludf.DUMMYFUNCTION("""COMPUTED_VALUE"""),"360044") -> 360044 | B23: =IFERROR(__xludf.DUMMYFUNCTION("""COMPUTED_VALUE"""),"RUN-FLMP_2021-01-18_APS-008") -> RUN-FLMP_2021-01-18_APS-008 | C23: =VLOOKUP(B23,'Run Reconcile'!A$2:B1579,2,FALSE) -> 44214 | D23: =IFERROR(__xludf.DUMMYFUNCTION("""COMPUTED_VALUE"""),44214.0) -> 44214 | E23: =IFERROR(__xludf.DUMMYFUNCTION("""COMPUTED_VALUE"""),0.3237615740727051) -> 0.32376157 | F23: =IFERROR(__xludf.DUMMYFUNCTION("""COMPUTED_VALUE"""),"Negative") -> Negative | G23: =IFERROR(__xludf.DUMMYFUNCTION("""COMPUTED_VALUE"""),3.0) -> 3 | H23: =IFERROR(__xludf.DUMMYFUNCTION("""COMPUTED_VALUE"""),"FLSP") -> FLSP
A24: =IFERROR(__xludf.DUMMYFUNCTION("""COMPUTED_VALUE"""),"360029") -> 360029 | B24: =IFERROR(__xludf.DUMMYFUNCTION("""COMPUTED_VALUE"""),"RUN-FLMP_2021-01-18_APS-008") -> RUN-FLMP_2021-01-18_APS-008 | C24: =VLOOKUP(B24,'Run Reconcile'!A$2:B1579,2,FALSE) -> 44214 | D24: =IFERROR(__xludf.DUMMYFUNCTION("""COMPUTED_VALUE"""),44214.0) -> 44214 | E24: =IFERROR(__xludf.DUMMYFUNCTION("""COMPUTED_VALUE"""),0.3262962962980964) -> 0.3262963 | F24: =IFERROR(__xludf.DUMMYFUNCTION("""COMPUTED_VALUE"""),"Negative") -> Negative | G24: =IFERROR(__xludf.DUMMYFUNCTION("""COMPUTED_VALUE"""),1.0) -> 1 | H24: =IFERROR(__xludf.DUMMYFUNCTION("""COMPUTED_VALUE"""),"FLSP") -> FLSP
A25: =IFERROR(__xludf.DUMMYFUNCTION("""COMPUTED_VALUE"""),"360030") -> 360030 | B25: =IFERROR(__xludf.DUMMYFUNCTION("""COMPUTED_VALUE"""),"RUN-FLMP_2021-01-18_APS-008") -> RUN-FLMP_2021-01-18_APS-008 | C25: =VLOOKUP(B25,'Run Reconcile'!A$2:B1579,2,FALSE) -> 44214 | D25: =IFERROR(__xludf.DUMMYFUNCTION("""COMPUTED_VALUE"""),44214.0) -> 44214 | E25: =IFERROR(__xludf.DUMMYFUNCTION("""COMPUTED_VALUE"""),0.3736226851870015) -> 0.37362269 | F25: =IFERROR(__xludf.DUMMYFUNCTION("""COMPUTED_VALUE"""),"Negative") -> Negative | G25: =IFERROR(__xludf.DUMMYFUNCTION("""COMPUTED_VALUE"""),2.0) -> 2 | H25: =IFERROR(__xludf.DUMMYFUNCTION("""COMPUTED_VALUE"""),"FLSP") -> FLSP
A26: =IFERROR(__xludf.DUMMYFUNCTION("""COMPUTED_VALUE"""),"360026") -> 360026 | B26: =IFERROR(__xludf.DUMMYFUNCTION("""COMPUTED_VALUE"""),"RUN-FLMP_2021-01-18_APS-008") -> RUN-FLMP_2021-01-18_APS-008 | C26: =VLOOKUP(B26,'Run Reconcile'!A$2:B1579,2,FALSE) -> 44214 | D26: =IFERROR(__xludf.DUMMYFUNCTION("""COMPUTED_VALUE"""),44214.0) -> 44214 | E26: =IFERROR(__xludf.DUMMYFUNCTION("""COMPUTED_VALUE"""),0.3761921296281798) -> 0.37619213 | F26: =IFERROR(__xludf.DUMMYFUNCTION("""COMPUTED_VALUE"""),"Negative") -> Negative | G26: =IFERROR(__xludf.DUMMYFUNCTION("""COMPUTED_VALUE"""),4.0) -> 4 | H26: =IFERROR(__xludf.DUMMYFUNCTION("""COMPUTED_VALUE"""),"FLSP") -> FLSP
A27: =IFERROR(__xludf.DUMMYFUNCTION("""COMPUTED_VALUE"""),"360028") -> 360028 | B27: =IFERROR(__xludf.DUMMYFUNCTION("""COMPUTED_VALUE"""),"RUN-FLMP_2021-01-18_APS-008") -> RUN-FLMP_2021-01-18_APS-008 | C27: =VLOOKUP(B27,'Run Reconcile'!A$2:B1579,2,FALSE) -> 44214 | D27: =IFERROR(__xludf.DUMMYFUNCTION("""COMPUTED_VALUE"""),44214.0) -> 44214 | E27: =IFERROR(__xludf.DUMMYFUNCTION("""COMPUTED_VALUE"""),0.37807870370306773) -> 0.3780787 | F27: =IFERROR(__xludf.DUMMYFUNCTION("""COMPUTED_VALUE"""),"Negative") -> Negative | G27: =IFERROR(__xludf.DUMMYFUNCTION("""COMPUTED_VALUE"""),1.0) -> 1 | H27: =IFERROR(__xludf.DUMMYFUNCTION("""COMPUTED_VALUE"""),"FLSP") -> FLSP
A28: =IFERROR(__xludf.DUMMYFUNCTION("""COMPUTED_VALUE"""),"360025") -> 360025 | B28: =IFERROR(__xludf.DUMMYFUNCTION("""COMPUTED_VALUE"""),"RUN-FLMP_2021-01-18_APS-008") -> RUN-FLMP_2021-01-18_APS-008 | C28: =VLOOKUP(B28,'Run Reconcile'!A$2:B1579,2,FALSE) -> 44214 | D28: =IFERROR(__xludf.DUMMYFUNCTION("""COMPUTED_VALUE"""),44214.0) -> 44214 | E28: =IFERROR(__xludf.DUMMYFUNCTION("""COMPUTED_VALUE"""),0.8198379629611736) -> 0.81983796 | F28: =IFERROR(__xludf.DUMMYFUNCTION("""COMPUTED_VALUE"""),"Null") -> Null | G28: =IFERROR(__xludf.DUMMYFUNCTION("""COMPUTED_VALUE"""),1.0) -> 1 | H28: =IFERROR(__xludf.DUMMYFUNCTION("""COMPUTED_VALUE"""),"FLSP") -> FLSP | K28: only run on EasyPCR
A29: =IFERROR(__xludf.DUMMYFUNCTION("""COMPUTED_VALUE"""),"360033") -> 360033 | B29: =IFERROR(__xludf.DUMMYFUNCTION("""COMPUTED_VALUE"""),"RUN-FLMP_2021-01-18_APS-008") -> RUN-FLMP_2021-01-18_APS-008 | C29: =VLOOKUP(B29,'Run Reconcile'!A$2:B1579,2,FALSE) -> 44214 | D29: =IFERROR(__xludf.DUMMYFUNCTION("""COMPUTED_VALUE"""),44214.0) -> 44214 | E29: =IFERROR(__xludf.DUMMYFUNCTION("""COMPUTED_VALUE"""),0.8248958333315386) -> 0.82489583 | F29: =IFERROR(__xludf.DUMMYFUNCTION("""COMPUTED_VALUE"""),"Null") -> Null | G29: =IFERROR(__xludf.DUMMYFUNCTION("""COMPUTED_VALUE"""),1.0) -> 1 | H29: =IFERROR(__xludf.DUMMYFUNCTION("""COMPUTED_VALUE"""),"FLSP") -> FLSP | K29: only run on EasyPCR
A30: =IFERROR(__xludf.DUMMYFUNCTION("""COMPUTED_VALUE"""),"360042") -> 360042 | B30: =IFERROR(__xludf.DUMMYFUNCTION("""COMPUTED_VALUE"""),"RUN-FLMP_2021-01-20_APS-009") -> RUN-FLMP_2021-01-20_APS-009 | C30: =VLOOKUP(B30,'Run Reconcile'!A$2:B1579,2,FALSE) -> 44216 | D30: =IFERROR(__xludf.DUMMYFUNCTION("""COMPUTED_VALUE"""),44216.0) -> 44216 | E30: =IFERROR(__xludf.DUMMYFUNCTION("""COMPUTED_VALUE"""),0.3248263888890506) -> 0.32482639 | F30: =IFERROR(__xludf.DUMMYFUNCTION("""COMPUTED_VALUE"""),"Negative") -> Negative | G30: =IFERROR(__xludf.DUMMYFUNCTION("""COMPUTED_VALUE"""),3.0) -> 3 | H30: =IFERROR(__xludf.DUMMYFUNCTION("""COMPUTED_VALUE"""),"FLSP") -> FLSP
A31: =IFERROR(__xludf.DUMMYFUNCTION("""COMPUTED_VALUE"""),"360031") -> 360031 | B31: =IFERROR(__xludf.DUMMYFUNCTION("""COMPUTED_VALUE"""),"RUN-FLMP_2021-01-20_APS-009") -> RUN-FLMP_2021-01-20_APS-009 | C31: =VLOOKUP(B31,'Run Reconcile'!A$2:B1579,2,FALSE) -> 44216 | D31: =IFERROR(__xludf.DUMMYFUNCTION("""COMPUTED_VALUE"""),44216.0) -> 44216 | E31: =IFERROR(__xludf.DUMMYFUNCTION("""COMPUTED_VALUE"""),0.325474537035916) -> 0.32547454 | F31: =IFERROR(__xludf.DUMMYFUNCTION("""COMPUTED_VALUE"""),"Negative") -> Negative | G31: =IFERROR(__xludf.DUMMYFUNCTION("""COMPUTED_VALUE"""),1.0) -> 1 | H31: =IFERROR(__xludf.DUMMYFUNCTION("""COMPUTED_VALUE"""),"FLSP") -> FLSP
A32: =IFERROR(__xludf.DUMMYFUNCTION("""COMPUTED_VALUE"""),"360039") -> 360039 | B32: =IFERROR(__xludf.DUMMYFUNCTION("""COMPUTED_VALUE"""),"RUN-FLMP_2021-01-20_APS-009") -> RUN-FLMP_2021-01-20_APS-009 | C32: =VLOOKUP(B32,'Run Reconcile'!A$2:B1579,2,FALSE) -> 44216 | D32: =IFERROR(__xludf.DUMMYFUNCTION("""COMPUTED_VALUE"""),44216.0) -> 44216 | E32: =IFERROR(__xludf.DUMMYFUNCTION("""COMPUTED_VALUE"""),0.33905092592613073) -> 0.33905093 | F32: =IFERROR(__xludf.DUMMYFUNCTION("""COMPUTED_VALUE"""),"Negative") -> Negative | G32: =IFERROR(__xludf.DUMMYFUNCTION("""COMPUTED_VALUE"""),2.0) -> 2 | H32: =IFERROR(__xludf.DUMMYFUNCTION("""COMPUTED_VALUE"""),"FLSP") -> FLSP
A33: =IFERROR(__xludf.DUMMYFUNCTION("""COMPUTED_VALUE"""),"360032") -> 360032 | B33: =IFERROR(__xludf.DUMMYFUNCTION("""COMPUTED_VALUE"""),"RUN-FLMP_2021-01-20_APS-009") -> RUN-FLMP_2021-01-20_APS-009 | C33: =VLOOKUP(B33,'Run Reconcile'!A$2:B1579,2,FALSE) -> 44216 | D33: =IFERROR(__xludf.DUMMYFUNCTION("""COMPUTED_VALUE"""),44216.0) -> 44216 | E33: =IFERROR(__xludf.DUMMYFUNCTION("""COMPUTED_VALUE"""),0.3561805555546016) -> 0.35618056 | F33: =IFERROR(__xludf.DUMMYFUNCTION("""COMPUTED_VALUE"""),"Negative") -> Negative | G33: =IFERROR(__xludf.DUMMYFUNCTION("""COMPUTED_VALUE"""),1.0) -> 1 | H33: =IFERROR(__xludf.DUMMYFUNCTION("""COMPUTED_VALUE"""),"FLSP") -> FLSP
A34: =IFERROR(__xludf.DUMMYFUNCTION("""COMPUTED_VALUE"""),"360017") -> 360017 | B34: =IFERROR(__xludf.DUMMYFUNCTION("""COMPUTED_VALUE"""),"RUN-FLMP_2021-01-20_APS-009") -> RUN-FLMP_2021-01-20_APS-009 | C34: =VLOOKUP(B34,'Run Reconcile'!A$2:B1579,2,FALSE) -> 44216 | D34: =IFERROR(__xludf.DUMMYFUNCTION("""COMPUTED_VALUE"""),44216.0) -> 44216 | E34: =IFERROR(__xludf.DUMMYFUNCTION("""COMPUTED_VALUE"""),0.3587962962956226) -> 0.3587963 | F34: =IFERROR(__xludf.DUMMYFUNCTION("""COMPUTED_VALUE"""),"Negative") -> Negative | G34: =IFERROR(__xludf.DUMMYFUNCTION("""COMPUTED_VALUE"""),3.0) -> 3 | H34: =IFERROR(__xludf.DUMMYFUNCTION("""COMPUTED_VALUE"""),"FLSP") -> FLSP
A35: =IFERROR(__xludf.DUMMYFUNCTION("""COMPUTED_VALUE"""),"6") -> 6 | B35: =IFERROR(__xludf.DUMMYFUNCTION("""COMPUTED_VALUE"""),"RUN-FLMP_2021-01-20_APS-009") -> RUN-FLMP_2021-01-20_APS-009 | C35: =VLOOKUP(B35,'Run Reconcile'!A$2:B1579,2,FALSE) -> 44216 | D35: =IFERROR(__xludf.DUMMYFUNCTION("""COMPUTED_VALUE"""),44216.0) -> 44216 | E35: =IFERROR(__xludf.DUMMYFUNCTION("""COMPUTED_VALUE"""),0.6091203703690553) -> 0.60912037 | F35: =IFERROR(__xludf.DUMMYFUNCTION("""COMPUTED_VALUE"""),"Negative") -> Negative | G35: =IFERROR(__xludf.DUMMYFUNCTION("""COMPUTED_VALUE"""),4.0) -> 4 | H35: =IFERROR(__xludf.DUMMYFUNCTION("""COMPUTED_VALUE"""),"FLSP") -> FLSP
A36: =IFERROR(__xludf.DUMMYFUNCTION("""COMPUTED_VALUE"""),"360023") -> 360023 | B36: =IFERROR(__xludf.DUMMYFUNCTION("""COMPUTED_VALUE"""),"RUN-FLMP_2021-01-20_APS-009") -> RUN-FLMP_2021-01-20_APS-009 | C36: =VLOOKUP(B36,'Run Reconcile'!A$2:B1579,2,FALSE) -> 44216 | D36: =IFERROR(__xludf.DUMMYFUNCTION("""COMPUTED_VALUE"""),44216.0) -> 44216 | E36: =IFERROR(__xludf.DUMMYFUNCTION("""COMPUTED_VALUE"""),0.8735185185178125) -> 0.87351852 | F36: =IFERROR(__xludf.DUMMYFUNCTION("""COMPUTED_VALUE"""),"Negative") -> Negative | G36: =IFERROR(__xludf.DUMMYFUNCTION("""COMPUTED_VALUE"""),1.0) -> 1 | H36: =IFERROR(__xludf.DUMMYFUNCTION("""COMPUTED_VALUE"""),"FLSP") -> FLSP
A37: =IFERROR(__xludf.DUMMYFUNCTION("""COMPUTED_VALUE"""),"6009") -> 6009 | B37: =IFERROR(__xludf.DUMMYFUNCTION("""COMPUTED_VALUE"""),"RUN-FLMP_2021-01-21_APS-010") -> RUN-FLMP_2021-01-21_APS-010 | C37: =VLOOKUP(B37,'Run Reconcile'!A$2:B1579,2,FALSE) -> 44217 | D37: =IFERROR(__xludf.DUMMYFUNCTION("""COMPUTED_VALUE"""),44217.0) -> 44217 | E37: =IFERROR(__xludf.DUMMYFUNCTION("""COMPUTED_VALUE"""),0.33932870370335877) -> 0.3393287 | F37: =IFERROR(__xludf.DUMMYFUNCTION("""COMPUTED_VALUE"""),"Negative") -> Negative | G37: =IFERROR(__xludf.DUMMYFUNCTION("""COMPUTED_VALUE"""),2.0) -> 2 | H37: =IFERROR(__xludf.DUMMYFUNCTION("""COMPUTED_VALUE"""),"FLSP") -> FLSP
A38: =IFERROR(__xludf.DUMMYFUNCTION("""COMPUTED_VALUE"""),"336378") -> 336378 | B38: =IFERROR(__xludf.DUMMYFUNCTION("""COMPUTED_VALUE"""),"RUN-FLMP_2021-01-21_APS-010") -> RUN-FLMP_2021-01-21_APS-010 | C38: =VLOOKUP(B38,'Run Reconcile'!A$2:B1579,2,FALSE) -> 44217 | D38: =IFERROR(__xludf.DUMMYFUNCTION("""COMPUTED_VALUE"""),44217.0) -> 44217 | E38: =IFERROR(__xludf.DUMMYFUNCTION("""COMPUTED_VALUE"""),0.6283680555570754) -> 0.62836806 | F38: =IFERROR(__xludf.DUMMYFUNCTION("""COMPUTED_VALUE"""),"Negative") -> Negative | G38: =IFERROR(__xludf.DUMMYFUNCTION("""COMPUTED_VALUE"""),1.0) -> 1 | H38: =IFERROR(__xludf.DUMMYFUNCTION("""COMPUTED_VALUE"""),"FLSP") -> FLSP
A39: =IFERROR(__xludf.DUMMYFUNCTION("""COMPUTED_VALUE"""),"632574") -> 632574 | B39: =IFERROR(__xludf.DUMMYFUNCTION("""COMPUTED_VALUE"""),"RUN-FLMP_2021-01-21_APS-010") -> RUN-FLMP_2021-01-21_APS-010 | C39: =VLOOKUP(B39,'Run Reconcile'!A$2:B1579,2,FALSE) -> 44217 | D39: =IFERROR(__xludf.DUMMYFUNCTION("""COMPUTED_VALUE"""),44217.0) -> 44217 | E39: =IFERROR(__xludf.DUMMYFUNCTION("""COMPUTED_VALUE"""),0.7206944444442343) -> 0.72069444 | F39: =IFERROR(__xludf.DUMMYFUNCTION("""COMPUTED_VALUE"""),"Negative") -> Negative | G39: =IFERROR(__xludf.DUMMYFUNCTION("""COMPUTED_VALUE"""),2.0) -> 2 | H39: =IFERROR(__xludf.DUMMYFUNCTION("""COMPUTED_VALUE"""),"FLSP") -> FLSP
A40: =IFERROR(__xludf.DUMMYFUNCTION("""COMPUTED_VALUE"""),"360018") -> 360018 | B40: =IFERROR(__xludf.DUMMYFUNCTION("""COMPUTED_VALUE"""),"RUN-FLMP_2021-01-21_APS-010") -> RUN-FLMP_2021-01-21_APS-010 | C40: =VLOOKUP(B40,'Run Reconcile'!A$2:B1579,2,FALSE) -> 44217 | D40: =IFERROR(__xludf.DUMMYFUNCTION("""COMPUTED_VALUE"""),44217.0) -> 44217 | E40: =IFERROR(__xludf.DUMMYFUNCTION("""COMPUTED_VALUE"""),0.885289351852407) -> 0.88528935 | F40: =IFERROR(__xludf.DUMMYFUNCTION("""COMPUTED_VALUE"""),"Negative") -> Negative | G40: =IFERROR(__xludf.DUMMYFUNCTION("""COMPUTED_VALUE"""),4.0) -> 4 | H40: =IFERROR(__xludf.DUMMYFUNCTION("""COMPUTED_VALUE"""),"FLSP") -> FLSP
...

Sheet Weekly
A1: Week Start Date | B1: Week End Date | C1: =CONCATENATE("Weekly Participants ",SUM(C2:C199)) -> Weekly Participants 3399 | D1: =CONCATENATE("Weekly Tubes Run ",SUM(D2:D199)) -> Weekly Tubes Run 1540 | E1: =CONCATENATE("Weekly Positive Tubes ",SUM(E2:E199)) -> Weekly Positive Tubes 57 | F1: =CONCATENATE("Weekly Inconclusive Tubes ",SUM(F2:F199)) -> Weekly Inconclusive Tubes 4 | G1: % Positive
A2: =MIN('ALL Tube Results'!C:C) - WEEKDAY(MIN('ALL Tube Results'!C:C), 3) -> 44172 | B2: =A2+6 -> 44178 | C2: =SUMIFS('ALL Tube Results'!$G$2:$G199, 'ALL Tube Results'!$C$2:$C199, ">="&A2, 'ALL Tube Results'!$C$2:$C199, "<="&B2) -> 6 | D2: =COUNTIFS('ALL Tube Results'!$C2:$C199, ">="&A2, 'ALL Tube Results'!$C2:$C199, "<="&B2) -> 2 | E2: =COUNTIFS('ALL Tube Results'!$C2:$C199, ">="&A2, 'ALL Tube Results'!$C2:$C199, "<="&B2, 'ALL Tube Results'!$F2:$F199, "Positive") -> 0 | F2: =COUNTIFS('ALL Tube Results'!$C2:$C199, ">="&A2, 'ALL Tube Results'!$C2:$C199, "<="&B2, 'ALL Tube Results'!$F2:$F199, "Inconclusive") -> 0 | G2: =IFERROR(E2/D2,IFERROR(0/0,"")) -> 0
A3: =B2+1 -> 44179 | B3: =A3+6 -> 44185 | C3: =SUMIFS('ALL Tube Results'!$G$2:$G199, 'ALL Tube Results'!$C$2:$C199, ">="&A3, 'ALL Tube Results'!$C$2:$C199, "<="&B3) -> 3 | D3: =COUNTIFS('ALL Tube Results'!$C3:$C199, ">="&A3, 'ALL Tube Results'!$C3:$C199, "<="&B3) -> 1 | E3: =COUNTIFS('ALL Tube Results'!$C3:$C199, ">="&A3, 'ALL Tube Results'!$C3:$C199, "<="&B3, 'ALL Tube Results'!$F3:$F199, "Positive") -> 0 | F3: =COUNTIFS('ALL Tube Results'!$C3:$C199, ">="&A3, 'ALL Tube Results'!$C3:$C199, "<="&B3, 'ALL Tube Results'!$F3:$F199, "Inconclusive") -> 0 | G3: =IFERROR(E3/D3,IFERROR(0/0,"")) -> 0
A4: =A3+7 -> 44186 | B4: =A4+6 -> 44192 | C4: =SUMIFS('ALL Tube Results'!$G$2:$G199, 'ALL Tube Results'!$C$2:$C199, ">="&A4, 'ALL Tube Results'!$C$2:$C199, "<="&B4) -> 2 | D4: =COUNTIFS('ALL Tube Results'!$C4:$C199, ">="&A4, 'ALL Tube Results'!$C4:$C199, "<="&B4) -> 1 | E4: =COUNTIFS('ALL Tube Results'!$C4:$C199, ">="&A4, 'ALL Tube Results'!$C4:$C199, "<="&B4, 'ALL Tube Results'!$F4:$F199, "Positive") -> 0 | F4: =COUNTIFS('ALL Tube Results'!$C4:$C199, ">="&A4, 'ALL Tube Results'!$C4:$C199, "<="&B4, 'ALL Tube Results'!$F4:$F199, "Inconclusive") -> 0 | G4: =IFERROR(E4/D4,IFERROR(0/0,"")) -> 0
A5: =A4+7 -> 44193 | B5: =A5+6 -> 44199 | C5: =SUMIFS('ALL Tube Results'!$G$2:$G199, 'ALL Tube Results'!$C$2:$C199, ">="&A5, 'ALL Tube Results'!$C$2:$C199, "<="&B5) -> 6 | D5: =COUNTIFS('ALL Tube Results'!$C5:$C199, ">="&A5, 'ALL Tube Results'!$C5:$C199, "<="&B5) -> 2 | E5: =COUNTIFS('ALL Tube Results'!$C5:$C199, ">="&A5, 'ALL Tube Results'!$C5:$C199, "<="&B5, 'ALL Tube Results'!$F5:$F199, "Positive") -> 0 | F5: =COUNTIFS('ALL Tube Results'!$C5:$C199, ">="&A5, 'ALL Tube Results'!$C5:$C199, "<="&B5, 'ALL Tube Results'!$F5:$F199, "Inconclusive") -> 0 | G5: =IFERROR(E5/D5,IFERROR(0/0,"")) -> 0
A6: =A5+7 -> 44200 | B6: =A6+6 -> 44206 | C6: =SUMIFS('ALL Tube Results'!$G$2:$G199, 'ALL Tube Results'!$C$2:$C199, ">="&A6, 'ALL Tube Results'!$C$2:$C199, "<="&B6) -> 0 | D6: =COUNTIFS('ALL Tube Results'!$C6:$C199, ">="&A6, 'ALL Tube Results'!$C6:$C199, "<="&B6) -> 0 | E6: =COUNTIFS('ALL Tube Results'!$C6:$C199, ">="&A6, 'ALL Tube Results'!$C6:$C199, "<="&B6, 'ALL Tube Results'!$F6:$F199, "Positive") -> 0 | F6: =COUNTIFS('ALL Tube Results'!$C6:$C199, ">="&A6, 'ALL Tube Results'!$C6:$C199, "<="&B6, 'ALL Tube Results'!$F6:$F199, "Inconclusive") -> 0 | G6: =IFERROR(E6/D6,IFERROR(0/0,""))
A7: =A6+7 -> 44207 | B7: =A7+6 -> 44213 | C7: =SUMIFS('ALL Tube Results'!$G$2:$G199, 'ALL Tube Results'!$C$2:$C199, ">="&A7, 'ALL Tube Results'!$C$2:$C199, "<="&B7) -> 36 | D7: =COUNTIFS('ALL Tube Results'!$C7:$C199, ">="&A7, 'ALL Tube Results'!$C7:$C199, "<="&B7) -> 15 | E7: =COUNTIFS('ALL Tube Results'!$C7:$C199, ">="&A7, 'ALL Tube Results'!$C7:$C199, "<="&B7, 'ALL Tube Results'!$F7:$F199, "Positive") -> 3 | F7: =COUNTIFS('ALL Tube Results'!$C7:$C199, ">="&A7, 'ALL Tube Results'!$C7:$C199, "<="&B7, 'ALL Tube Results'!$F7:$F199, "Inconclusive") -> 0 | G7: =IFERROR(E7/D7,IFERROR(0/0,"")) -> 0.2
A8: =A7+7 -> 44214 | B8: =A8+6 -> 44220 | C8: =SUMIFS('ALL Tube Results'!$G$2:$G199, 'ALL Tube Results'!$C$2:$C199, ">="&A8, 'ALL Tube Results'!$C$2:$C199, "<="&B8) -> 49 | D8: =COUNTIFS('ALL Tube Results'!$C8:$C199, ">="&A8, 'ALL Tube Results'!$C8:$C199, "<="&B8) -> 24 | E8: =COUNTIFS('ALL Tube Results'!$C8:$C199, ">="&A8, 'ALL Tube Results'!$C8:$C199, "<="&B8, 'ALL Tube Results'!$F8:$F199, "Positive") -> 0 | F8: =COUNTIFS('ALL Tube Results'!$C8:$C199, ">="&A8, 'ALL Tube Results'!$C8:$C199, "<="&B8, 'ALL Tube Results'!$F8:$F199, "Inconclusive") -> 0 | G8: =IFERROR(E8/D8,IFERROR(0/0,"")) -> 0
A9: =A8+7 -> 44221 | B9: =A9+6 -> 44227 | C9: =SUMIFS('ALL Tube Results'!$G$2:$G199, 'ALL Tube Results'!$C$2:$C199, ">="&A9, 'ALL Tube Results'!$C$2:$C199, "<="&B9) -> 45 | D9: =COUNTIFS('ALL Tube Results'!$C9:$C199, ">="&A9, 'ALL Tube Results'!$C9:$C199, "<="&B9) -> 19 | E9: =COUNTIFS('ALL Tube Results'!$C9:$C199, ">="&A9, 'ALL Tube Results'!$C9:$C199, "<="&B9, 'ALL Tube Results'!$F9:$F199, "Positive") -> 0 | F9: =COUNTIFS('ALL Tube Results'!$C9:$C199, ">="&A9, 'ALL Tube Results'!$C9:$C199, "<="&B9, 'ALL Tube Results'!$F9:$F199, "Inconclusive") -> 0 | G9: =IFERROR(E9/D9,IFERROR(0/0,"")) -> 0
A10: =A9+7 -> 44228 | B10: =A10+6 -> 44234 | C10: =SUMIFS('ALL Tube Results'!$G$2:$G199, 'ALL Tube Results'!$C$2:$C199, ">="&A10, 'ALL Tube Results'!$C$2:$C199, "<="&B10) -> 31 | D10: =COUNTIFS('ALL Tube Results'!$C10:$C199, ">="&A10, 'ALL Tube Results'!$C10:$C199, "<="&B10) -> 11 | E10: =COUNTIFS('ALL Tube Results'!$C10:$C199, ">="&A10, 'ALL Tube Results'!$C10:$C199, "<="&B10, 'ALL Tube Results'!$F10:$F199, "Positive") -> 0 | F10: =COUNTIFS('ALL Tube Results'!$C10:$C199, ">="&A10, 'ALL Tube Results'!$C10:$C199, "<="&B10, 'ALL Tube Results'!$F10:$F199, "Inconclusive") -> 0 | G10: =IFERROR(E10/D10,IFERROR(0/0,"")) -> 0
A11: =A10+7 -> 44235 | B11: =A11+6 -> 44241 | C11: =SUMIFS('ALL Tube Results'!$G$2:$G199, 'ALL Tube Results'!$C$2:$C199, ">="&A11, 'ALL Tube Results'!$C$2:$C199, "<="&B11) -> 40 | D11: =COUNTIFS('ALL Tube Results'!$C11:$C199, ">="&A11, 'ALL Tube Results'!$C11:$C199, "<="&B11) -> 13 | E11: =COUNTIFS('ALL Tube Results'!$C11:$C199, ">="&A11, 'ALL Tube Results'!$C11:$C199, "<="&B11, 'ALL Tube Results'!$F11:$F199, "Positive") -> 0 | F11: =COUNTIFS('ALL Tube Results'!$C11:$C199, ">="&A11, 'ALL Tube Results'!$C11:$C199, "<="&B11, 'ALL Tube Results'!$F11:$F199, "Inconclusive") -> 0 | G11: =IFERROR(E11/D11,IFERROR(0/0,"")) -> 0
A12: =A11+7 -> 44242 | B12: =A12+6 -> 44248 | C12: =SUMIFS('ALL Tube Results'!$G$2:$G199, 'ALL Tube Results'!$C$2:$C199, ">="&A12, 'ALL Tube Results'!$C$2:$C199, "<="&B12) -> 14 | D12: =COUNTIFS('ALL Tube Results'!$C12:$C199, ">="&A12, 'ALL Tube Results'!$C12:$C199, "<="&B12) -> 4 | E12: =COUNTIFS('ALL Tube Results'!$C12:$C199, ">="&A12, 'ALL Tube Results'!$C12:$C199, "<="&B12, 'ALL Tube Results'!$F12:$F199, "Positive") -> 0 | F12: =COUNTIFS('ALL Tube Results'!$C12:$C199, ">="&A12, 'ALL Tube Results'!$C12:$C199, "<="&B12, 'ALL Tube Results'!$F12:$F199, "Inconclusive") -> 0 | G12: =IFERROR(E12/D12,IFERROR(0/0,"")) -> 0
A13: =A12+7 -> 44249 | B13: =A13+6 -> 44255 | C13: =SUMIFS('ALL Tube Results'!$G$2:$G199, 'ALL Tube Results'!$C$2:$C199, ">="&A13, 'ALL Tube Results'!$C$2:$C199, "<="&B13) -> 24 | D13: =COUNTIFS('ALL Tube Results'!$C13:$C199, ">="&A13, 'ALL Tube Results'!$C13:$C199, "<="&B13) -> 9 | E13: =COUNTIFS('ALL Tube Results'!$C13:$C199, ">="&A13, 'ALL Tube Results'!$C13:$C199, "<="&B13, 'ALL Tube Results'!$F13:$F199, "Positive") -> 0 | F13: =COUNTIFS('ALL Tube Results'!$C13:$C199, ">="&A13, 'ALL Tube Results'!$C13:$C199, "<="&B13, 'ALL Tube Results'!$F13:$F199, "Inconclusive") -> 0 | G13: =IFERROR(E13/D13,IFERROR(0/0,"")) -> 0
A14: =A13+7 -> 44256 | B14: =A14+6 -> 44262 | C14: =SUMIFS('ALL Tube Results'!$G$2:$G199, 'ALL Tube Results'!$C$2:$C199, ">="&A14, 'ALL Tube Results'!$C$2:$C199, "<="&B14) -> 35 | D14: =COUNTIFS('ALL Tube Results'!$C14:$C199, ">="&A14, 'ALL Tube Results'!$C14:$C199, "<="&B14) -> 11 | E14: =COUNTIFS('ALL Tube Results'!$C14:$C199, ">="&A14, 'ALL Tube Results'!$C14:$C199, "<="&B14, 'ALL Tube Results'!$F14:$F199, "Positive") -> 0 | F14: =COUNTIFS('ALL Tube Results'!$C14:$C199, ">="&A14, 'ALL Tube Results'!$C14:$C199, "<="&B14, 'ALL Tube Results'!$F14:$F199, "Inconclusive") -> 0 | G14: =IFERROR(E14/D14,IFERROR(0/0,"")) -> 0
A15: =A14+7 -> 44263 | B15: =A15+6 -> 44269 | C15: =SUMIFS('ALL Tube Results'!$G$2:$G199, 'ALL Tube Results'!$C$2:$C199, ">="&A15, 'ALL Tube Results'!$C$2:$C199, "<="&B15) -> 30 | D15: =COUNTIFS('ALL Tube Results'!$C15:$C199, ">="&A15, 'ALL Tube Results'!$C15:$C199, "<="&B15) -> 9 | E15: =COUNTIFS('ALL Tube Results'!$C15:$C199, ">="&A15, 'ALL Tube Results'!$C15:$C199, "<="&B15, 'ALL Tube Results'!$F15:$F199, "Positive") -> 0 | F15: =COUNTIFS('ALL Tube Results'!$C15:$C199, ">="&A15, 'ALL Tube Results'!$C15:$C199, "<="&B15, 'ALL Tube Results'!$F15:$F199, "Inconclusive") -> 0 | G15: =IFERROR(E15/D15,IFERROR(0/0,"")) -> 0
A16: =A15+7 -> 44270 | B16: =A16+6 -> 44276 | C16: =SUMIFS('ALL Tube Results'!$G$2:$G199, 'ALL Tube Results'!$C$2:$C199, ">="&A16, 'ALL Tube Results'!$C$2:$C199, "<="&B16) -> 16 | D16: =COUNTIFS('ALL Tube Results'!$C16:$C199, ">="&A16, 'ALL Tube Results'!$C16:$C199, "<="&B16) -> 6 | E16: =COUNTIFS('ALL Tube Results'!$C16:$C199, ">="&A16, 'ALL Tube Results'!$C16:$C199, "<="&B16, 'ALL Tube Results'!$F16:$F199, "Positive") -> 0 | F16: =COUNTIFS('ALL Tube Results'!$C16:$C199, ">="&A16, 'ALL Tube Results'!$C16:$C199, "<="&B16, 'ALL Tube Results'!$F16:$F199, "Inconclusive") -> 0 | G16: =IFERROR(E16/D16,IFERROR(0/0,"")) -> 0
A17: =A16+7 -> 44277 | B17: =A17+6 -> 44283 | C17: =SUMIFS('ALL Tube Results'!$G$2:$G199, 'ALL Tube Results'!$C$2:$C199, ">="&A17, 'ALL Tube Results'!$C$2:$C199, "<="&B17) -> 6 | D17: =COUNTIFS('ALL Tube Results'!$C17:$C199, ">="&A17, 'ALL Tube Results'!$C17:$C199, "<="&B17) -> 2 | E17: =COUNTIFS('ALL Tube Results'!$C17:$C199, ">="&A17, 'ALL Tube Results'!$C17:$C199, "<="&B17, 'ALL Tube Results'!$F17:$F199, "Positive") -> 0 | F17: =COUNTIFS('ALL Tube Results'!$C17:$C199, ">="&A17, 'ALL Tube Results'!$C17:$C199, "<="&B17, 'ALL Tube Results'!$F17:$F199, "Inconclusive") -> 0 | G17: =IFERROR(E17/D17,IFERROR(0/0,"")) -> 0
A18: =A17+7 -> 44284 | B18: =A18+6 -> 44290 | C18: =SUMIFS('ALL Tube Results'!$G$2:$G199, 'ALL Tube Results'!$C$2:$C199, ">="&A18, 'ALL Tube Results'!$C$2:$C199, "<="&B18) -> 6 | D18: =COUNTIFS('ALL Tube Results'!$C18:$C199, ">="&A18, 'ALL Tube Results'!$C18:$C199, "<="&B18) -> 2 | E18: =COUNTIFS('ALL Tube Results'!$C18:$C199, ">="&A18, 'ALL Tube Results'!$C18:$C199, "<="&B18, 'ALL Tube Results'!$F18:$F199, "Positive") -> 0 | F18: =COUNTIFS('ALL Tube Results'!$C18:$C199, ">="&A18, 'ALL Tube Results'!$C18:$C199, "<="&B18, 'ALL Tube Results'!$F18:$F199, "Inconclusive") -> 0 | G18: =IFERROR(E18/D18,IFERROR(0/0,"")) -> 0
A19: =A18+7 -> 44291 | B19: =A19+6 -> 44297 | C19: =SUMIFS('ALL Tube Results'!$G$2:$G199, 'ALL Tube Results'!$C$2:$C199, ">="&A19, 'ALL Tube Results'!$C$2:$C199, "<="&B19) -> 0 | D19: =COUNTIFS('ALL Tube Results'!$C19:$C199, ">="&A19, 'ALL Tube Results'!$C19:$C199, "<="&B19) -> 0 | E19: =COUNTIFS('ALL Tube Results'!$C19:$C199, ">="&A19, 'ALL Tube Results'!$C19:$C199, "<="&B19, 'ALL Tube Results'!$F19:$F199, "Positive") -> 0 | F19: =COUNTIFS('ALL Tube Results'!$C19:$C199, ">="&A19, 'ALL Tube Results'!$C19:$C199, "<="&B19, 'ALL Tube Results'!$F19:$F199, "Inconclusive") -> 0 | G19: =IFERROR(E19/D19,IFERROR(0/0,""))
A20: =A19+7 -> 44298 | B20: =A20+6 -> 44304 | C20: =SUMIFS('ALL Tube Results'!$G$2:$G199, 'ALL Tube Results'!$C$2:$C199, ">="&A20, 'ALL Tube Results'!$C$2:$C199, "<="&B20) -> 8 | D20: =COUNTIFS('ALL Tube Results'!$C20:$C199, ">="&A20, 'ALL Tube Results'!$C20:$C199, "<="&B20) -> 3 | E20: =COUNTIFS('ALL Tube Results'!$C20:$C199, ">="&A20, 'ALL Tube Results'!$C20:$C199, "<="&B20, 'ALL Tube Results'!$F20:$F199, "Positive") -> 0 | F20: =COUNTIFS('ALL Tube Results'!$C20:$C199, ">="&A20, 'ALL Tube Results'!$C20:$C199, "<="&B20, 'ALL Tube Results'!$F20:$F199, "Inconclusive") -> 0 | G20: =IFERROR(E20/D20,IFERROR(0/0,"")) -> 0
A21: =A20+7 -> 44305 | B21: =A21+6 -> 44311 | C21: =SUMIFS('ALL Tube Results'!$G$2:$G199, 'ALL Tube Results'!$C$2:$C199, ">="&A21, 'ALL Tube Results'!$C$2:$C199, "<="&B21) -> 0 | D21: =COUNTIFS('ALL Tube Results'!$C21:$C199, ">="&A21, 'ALL Tube Results'!$C21:$C199, "<="&B21) -> 0 | E21: =COUNTIFS('ALL Tube Results'!$C21:$C199, ">="&A21, 'ALL Tube Results'!$C21:$C199, "<="&B21, 'ALL Tube Results'!$F21:$F199, "Positive") -> 0 | F21: =COUNTIFS('ALL Tube Results'!$C21:$C199, ">="&A21, 'ALL Tube Results'!$C21:$C199, "<="&B21, 'ALL Tube Results'!$F21:$F199, "Inconclusive") -> 0 | G21: =IFERROR(E21/D21,IFERROR(0/0,""))
A22: =A21+7 -> 44312 | B22: =A22+6 -> 44318 | C22: =SUMIFS('ALL Tube Results'!$G$2:$G199, 'ALL Tube Results'!$C$2:$C199, ">="&A22, 'ALL Tube Results'!$C$2:$C199, "<="&B22) -> 0 | D22: =COUNTIFS('ALL Tube Results'!$C22:$C199, ">="&A22, 'ALL Tube Results'!$C22:$C199, "<="&B22) -> 0 | E22: =COUNTIFS('ALL Tube Results'!$C22:$C199, ">="&A22, 'ALL Tube Results'!$C22:$C199, "<="&B22, 'ALL Tube Results'!$F22:$F199, "Positive") -> 0 | F22: =COUNTIFS('ALL Tube Results'!$C22:$C199, ">="&A22, 'ALL Tube Results'!$C22:$C199, "<="&B22, 'ALL Tube Results'!$F22:$F199, "Inconclusive") -> 0 | G22: =IFERROR(E22/D22,IFERROR(0/0,""))
A23: =A22+7 -> 44319 | B23: =A23+6 -> 44325 | C23: =SUMIFS('ALL Tube Results'!$G$2:$G199, 'ALL Tube Results'!$C$2:$C199, ">="&A23, 'ALL Tube Results'!$C$2:$C199, "<="&B23) -> 1 | D23: =COUNTIFS('ALL Tube Results'!$C23:$C199, ">="&A23, 'ALL Tube Results'!$C23:$C199, "<="&B23) -> 1 | E23: =COUNTIFS('ALL Tube Results'!$C23:$C199, ">="&A23, 'ALL Tube Results'!$C23:$C199, "<="&B23, 'ALL Tube Results'!$F23:$F199, "Positive") -> 0 | F23: =COUNTIFS('ALL Tube Results'!$C23:$C199, ">="&A23, 'ALL Tube Results'!$C23:$C199, "<="&B23, 'ALL Tube Results'!$F23:$F199, "Inconclusive") -> 0 | G23: =IFERROR(E23/D23,IFERROR(0/0,"")) -> 0
A24: =A23+7 -> 44326 | B24: =A24+6 -> 44332 | C24: =SUMIFS('ALL Tube Results'!$G$2:$G199, 'ALL Tube Results'!$C$2:$C199, ">="&A24, 'ALL Tube Results'!$C$2:$C199, "<="&B24) -> 5 | D24: =COUNTIFS('ALL Tube Results'!$C24:$C199, ">="&A24, 'ALL Tube Results'!$C24:$C199, "<="&B24) -> 2 | E24: =COUNTIFS('ALL Tube Results'!$C24:$C199, ">="&A24, 'ALL Tube Results'!$C24:$C199, "<="&B24, 'ALL Tube Results'!$F24:$F199, "Positive") -> 0 | F24: =COUNTIFS('ALL Tube Results'!$C24:$C199, ">="&A24, 'ALL Tube Results'!$C24:$C199, "<="&B24, 'ALL Tube Results'!$F24:$F199, "Inconclusive") -> 0 | G24: =IFERROR(E24/D24,IFERROR(0/0,"")) -> 0
A25: =A24+7 -> 44333 | B25: =A25+6 -> 44339 | C25: =SUMIFS('ALL Tube Results'!$G$2:$G199, 'ALL Tube Results'!$C$2:$C199, ">="&A25, 'ALL Tube Results'!$C$2:$C199, "<="&B25) -> 6 | D25: =COUNTIFS('ALL Tube Results'!$C25:$C199, ">="&A25, 'ALL Tube Results'!$C25:$C199, "<="&B25) -> 6 | E25: =COUNTIFS('ALL Tube Results'!$C25:$C199, ">="&A25, 'ALL Tube Results'!$C25:$C199, "<="&B25, 'ALL Tube Results'!$F25:$F199, "Positive") -> 0 | F25: =COUNTIFS('ALL Tube Results'!$C25:$C199, ">="&A25, 'ALL Tube Results'!$C25:$C199, "<="&B25, 'ALL Tube Results'!$F25:$F199, "Inconclusive") -> 0 | G25: =IFERROR(E25/D25,IFERROR(0/0,"")) -> 0
A26: =A25+7 -> 44340 | B26: =A26+6 -> 44346 | C26: =SUMIFS('ALL Tube Results'!$G$2:$G199, 'ALL Tube Results'!$C$2:$C199, ">="&A26, 'ALL Tube Results'!$C$2:$C199, "<="&B26) -> 0 | D26: =COUNTIFS('ALL Tube Results'!$C26:$C199, ">="&A26, 'ALL Tube Results'!$C26:$C199, "<="&B26) -> 0 | E26: =COUNTIFS('ALL Tube Results'!$C26:$C199, ">="&A26, 'ALL Tube Results'!$C26:$C199, "<="&B26, 'ALL Tube Results'!$F26:$F199, "Positive") -> 0 | F26: =COUNTIFS('ALL Tube Results'!$C26:$C199, ">="&A26, 'ALL Tube Results'!$C26:$C199, "<="&B26, 'ALL Tube Results'!$F26:$F199, "Inconclusive") -> 0 | G26: =IFERROR(E26/D26,IFERROR(0/0,""))
A27: =A26+7 -> 44347 | B27: =A27+6 -> 44353 | C27: =SUMIFS('ALL Tube Results'!$G$2:$G199, 'ALL Tube Results'!$C$2:$C199, ">="&A27, 'ALL Tube Results'!$C$2:$C199, "<="&B27) -> 0 | D27: =COUNTIFS('ALL Tube Results'!$C27:$C199, ">="&A27, 'ALL Tube Results'!$C27:$C199, "<="&B27) -> 0 | E27: =COUNTIFS('ALL Tube Results'!$C27:$C199, ">="&A27, 'ALL Tube Results'!$C27:$C199, "<="&B27, 'ALL Tube Results'!$F27:$F199, "Positive") -> 0 | F27: =COUNTIFS('ALL Tube Results'!$C27:$C199, ">="&A27, 'ALL Tube Results'!$C27:$C199, "<="&B27, 'ALL Tube Results'!$F27:$F199, "Inconclusive") -> 0 | G27: =IFERROR(E27/D27,IFERROR(0/0,""))
A28: =A27+7 -> 44354 | B28: =A28+6 -> 44360 | C28: =SUMIFS('ALL Tube Results'!$G$2:$G199, 'ALL Tube Results'!$C$2:$C199, ">="&A28, 'ALL Tube Results'!$C$2:$C199, "<="&B28) -> 0 | D28: =COUNTIFS('ALL Tube Results'!$C28:$C199, ">="&A28, 'ALL Tube Results'!$C28:$C199, "<="&B28) -> 0 | E28: =COUNTIFS('ALL Tube Results'!$C28:$C199, ">="&A28, 'ALL Tube Results'!$C28:$C199, "<="&B28, 'ALL Tube Results'!$F28:$F199, "Positive") -> 0 | F28: =COUNTIFS('ALL Tube Results'!$C28:$C199, ">="&A28, 'ALL Tube Results'!$C28:$C199, "<="&B28, 'ALL Tube Results'!$F28:$F199, "Inconclusive") -> 0 | G28: =IFERROR(E28/D28,IFERROR(0/0,""))
A29: =A28+7 -> 44361 | B29: =A29+6 -> 44367 | C29: =SUMIFS('ALL Tube Results'!$G$2:$G199, 'ALL Tube Results'!$C$2:$C199, ">="&A29, 'ALL Tube Results'!$C$2:$C199, "<="&B29) -> 2 | D29: =COUNTIFS('ALL Tube Results'!$C29:$C199, ">="&A29, 'ALL Tube Results'!$C29:$C199, "<="&B29) -> 2 | E29: =COUNTIFS('ALL Tube Results'!$C29:$C199, ">="&A29, 'ALL Tube Results'!$C29:$C199, "<="&B29, 'ALL Tube Results'!$F29:$F199, "Positive") -> 0 | F29: =COUNTIFS('ALL Tube Results'!$C29:$C199, ">="&A29, 'ALL Tube Results'!$C29:$C199, "<="&B29, 'ALL Tube Results'!$F29:$F199, "Inconclusive") -> 0 | G29: =IFERROR(E29/D29,IFERROR(0/0,"")) -> 0
A30: =A29+7 -> 44368 | B30: =A30+6 -> 44374 | C30: =SUMIFS('ALL Tube Results'!$G$2:$G199, 'ALL Tube Results'!$C$2:$C199, ">="&A30, 'ALL Tube Results'!$C$2:$C199, "<="&B30) -> 0 | D30: =COUNTIFS('ALL Tube Results'!$C30:$C199, ">="&A30, 'ALL Tube Results'!$C30:$C199, "<="&B30) -> 0 | E30: =COUNTIFS('ALL Tube Results'!$C30:$C199, ">="&A30, 'ALL Tube Results'!$C30:$C199, "<="&B30, 'ALL Tube Results'!$F30:$F199, "Positive") -> 0 | F30: =COUNTIFS('ALL Tube Results'!$C30:$C199, ">="&A30, 'ALL Tube Results'!$C30:$C199, "<="&B30, 'ALL Tube Results'!$F30:$F199, "Inconclusive") -> 0 | G30: =IFERROR(E30/D30,IFERROR(0/0,""))
A31: =A30+7 -> 44375 | B31: =A31+6 -> 44381 | C31: =SUMIFS('ALL Tube Results'!$G$2:$G199, 'ALL Tube Results'!$C$2:$C199, ">="&A31, 'ALL Tube Results'!$C$2:$C199, "<="&B31) -> 0 | D31: =COUNTIFS('ALL Tube Results'!$C31:$C199, ">="&A31, 'ALL Tube Results'!$C31:$C199, "<="&B31) -> 0 | E31: =COUNTIFS('ALL Tube Results'!$C31:$C199, ">="&A31, 'ALL Tube Results'!$C31:$C199, "<="&B31, 'ALL Tube Results'!$F31:$F199, "Positive") -> 0 | F31: =COUNTIFS('ALL Tube Results'!$C31:$C199, ">="&A31, 'ALL Tube Results'!$C31:$C199, "<="&B31, 'ALL Tube Results'!$F31:$F199, "Inconclusive") -> 0 | G31: =IFERROR(E31/D31,IFERROR(0/0,""))
A32: =A31+7 -> 44382 | B32: =A32+6 -> 44388 | C32: =SUMIFS('ALL Tube Results'!$G$2:$G199, 'ALL Tube Results'!$C$2:$C199, ">="&A32, 'ALL Tube Results'!$C$2:$C199, "<="&B32) -> 0 | D32: =COUNTIFS('ALL Tube Results'!$C32:$C199, ">="&A32, 'ALL Tube Results'!$C32:$C199, "<="&B32) -> 0 | E32: =COUNTIFS('ALL Tube Results'!$C32:$C199, ">="&A32, 'ALL Tube Results'!$C32:$C199, "<="&B32, 'ALL Tube Results'!$F32:$F199, "Positive") -> 0 | F32: =COUNTIFS('ALL Tube Results'!$C32:$C199, ">="&A32, 'ALL Tube Results'!$C32:$C199, "<="&B32, 'ALL Tube Results'!$F32:$F199, "Inconclusive") -> 0 | G32: =IFERROR(E32/D32,IFERROR(0/0,""))
A33: =A32+7 -> 44389 | B33: =A33+6 -> 44395 | C33: =SUMIFS('ALL Tube Results'!$G$2:$G199, 'ALL Tube Results'!$C$2:$C199, ">="&A33, 'ALL Tube Results'!$C$2:$C199, "<="&B33) -> 0 | D33: =COUNTIFS('ALL Tube Results'!$C33:$C199, ">="&A33, 'ALL Tube Results'!$C33:$C199, "<="&B33) -> 0 | E33: =COUNTIFS('ALL Tube Results'!$C33:$C199, ">="&A33, 'ALL Tube Results'!$C33:$C199, "<="&B33, 'ALL Tube Results'!$F33:$F199, "Positive") -> 0 | F33: =COUNTIFS('ALL Tube Results'!$C33:$C199, ">="&A33, 'ALL Tube Results'!$C33:$C199, "<="&B33, 'ALL Tube Results'!$F33:$F199, "Inconclusive") -> 0 | G33: =IFERROR(E33/D33,IFERROR(0/0,""))
A34: =A33+7 -> 44396 | B34: =A34+6 -> 44402 | C34: =SUMIFS('ALL Tube Results'!$G$2:$G199, 'ALL Tube Results'!$C$2:$C199, ">="&A34, 'ALL Tube Results'!$C$2:$C199, "<="&B34) -> 0 | D34: =COUNTIFS('ALL Tube Results'!$C34:$C199, ">="&A34, 'ALL Tube Results'!$C34:$C199, "<="&B34) -> 0 | E34: =COUNTIFS('ALL Tube Results'!$C34:$C199, ">="&A34, 'ALL Tube Results'!$C34:$C199, "<="&B34, 'ALL Tube Results'!$F34:$F199, "Positive") -> 0 | F34: =COUNTIFS('ALL Tube Results'!$C34:$C199, ">="&A34, 'ALL Tube Results'!$C34:$C199, "<="&B34, 'ALL Tube Results'!$F34:$F199, "Inconclusive") -> 0 | G34: =IFERROR(E34/D34,IFERROR(0/0,""))
A35: =A34+7 -> 44403 | B35: =A35+6 -> 44409 | C35: =SUMIFS('ALL Tube Results'!$G$2:$G199, 'ALL Tube Results'!$C$2:$C199, ">="&A35, 'ALL Tube Results'!$C$2:$C199, "<="&B35) -> 0 | D35: =COUNTIFS('ALL Tube Results'!$C35:$C199, ">="&A35, 'ALL Tube Results'!$C35:$C199, "<="&B35) -> 0 | E35: =COUNTIFS('ALL Tube Results'!$C35:$C199, ">="&A35, 'ALL Tube Results'!$C35:$C199, "<="&B35, 'ALL Tube Results'!$F35:$F199, "Positive") -> 0 | F35: =COUNTIFS('ALL Tube Results'!$C35:$C199, ">="&A35, 'ALL Tube Results'!$C35:$C199, "<="&B35, 'ALL Tube Results'!$F35:$F199, "Inconclusive") -> 0 | G35: =IFERROR(E35/D35,IFERROR(0/0,""))
A36: =A35+7 -> 44410 | B36: =A36+6 -> 44416 | C36: =SUMIFS('ALL Tube Results'!$G$2:$G199, 'ALL Tube Results'!$C$2:$C199, ">="&A36, 'ALL Tube Results'!$C$2:$C199, "<="&B36) -> 0 | D36: =COUNTIFS('ALL Tube Results'!$C36:$C199, ">="&A36, 'ALL Tube Results'!$C36:$C199, "<="&B36) -> 0 | E36: =COUNTIFS('ALL Tube Results'!$C36:$C199, ">="&A36, 'ALL Tube Results'!$C36:$C199, "<="&B36, 'ALL Tube Results'!$F36:$F199, "Positive") -> 0 | F36: =COUNTIFS('ALL Tube Results'!$C36:$C199, ">="&A36, 'ALL Tube Results'!$C36:$C199, "<="&B36, 'ALL Tube Results'!$F36:$F199, "Inconclusive") -> 0 | G36: =IFERROR(E36/D36,IFERROR(0/0,""))
A37: =A36+7 -> 44417 | B37: =A37+6 -> 44423 | C37: =SUMIFS('ALL Tube Results'!$G$2:$G199, 'ALL Tube Results'!$C$2:$C199, ">="&A37, 'ALL Tube Results'!$C$2:$C199, "<="&B37) -> 0 | D37: =COUNTIFS('ALL Tube Results'!$C37:$C199, ">="&A37, 'ALL Tube Results'!$C37:$C199, "<="&B37) -> 0 | E37: =COUNTIFS('ALL Tube Results'!$C37:$C199, ">="&A37, 'ALL Tube Results'!$C37:$C199, "<="&B37, 'ALL Tube Results'!$F37:$F199, "Positive") -> 0 | F37: =COUNTIFS('ALL Tube Results'!$C37:$C199, ">="&A37, 'ALL Tube Results'!$C37:$C199, "<="&B37, 'ALL Tube Results'!$F37:$F199, "Inconclusive") -> 0 | G37: =IFERROR(E37/D37,IFERROR(0/0,""))
A38: =A37+7 -> 44424 | B38: =A38+6 -> 44430 | C38: =SUMIFS('ALL Tube Results'!$G$2:$G199, 'ALL Tube Results'!$C$2:$C199, ">="&A38, 'ALL Tube Results'!$C$2:$C199, "<="&B38) -> 0 | D38: =COUNTIFS('ALL Tube Results'!$C38:$C199, ">="&A38, 'ALL Tube Results'!$C38:$C199, "<="&B38) -> 0 | E38: =COUNTIFS('ALL Tube Results'!$C38:$C199, ">="&A38, 'ALL Tube Results'!$C38:$C199, "<="&B38, 'ALL Tube Results'!$F38:$F199, "Positive") -> 0 | F38: =COUNTIFS('ALL Tube Results'!$C38:$C199, ">="&A38, 'ALL Tube Results'!$C38:$C199, "<="&B38, 'ALL Tube Results'!$F38:$F199, "Inconclusive") -> 0 | G38: =IFERROR(E38/D38,IFERROR(0/0,""))
A39: =A38+7 -> 44431 | B39: =A39+6 -> 44437 | C39: =SUMIFS('ALL Tube Results'!$G$2:$G199, 'ALL Tube Results'!$C$2:$C199, ">="&A39, 'ALL Tube Results'!$C$2:$C199, "<="&B39) -> 0 | D39: =COUNTIFS('ALL Tube Results'!$C39:$C199, ">="&A39, 'ALL Tube Results'!$C39:$C199, "<="&B39) -> 0 | E39: =COUNTIFS('ALL Tube Results'!$C39:$C199, ">="&A39, 'ALL Tube Results'!$C39:$C199, "<="&B39, 'ALL Tube Results'!$F39:$F199, "Positive") -> 0 | F39: =COUNTIFS('ALL Tube Results'!$C39:$C199, ">="&A39, 'ALL Tube Results'!$C39:$C199, "<="&B39, 'ALL Tube Results'!$F39:$F199, "Inconclusive") -> 0 | G39: =IFERROR(E39/D39,IFERROR(0/0,""))
A40: =A39+7 -> 44438 | B40: =A40+6 -> 44444 | C40: =SUMIFS('ALL Tube Results'!$G$2:$G199, 'ALL Tube Results'!$C$2:$C199, ">="&A40, 'ALL Tube Results'!$C$2:$C199, "<="&B40) -> 7 | D40: =COUNTIFS('ALL Tube Results'!$C40:$C199, ">="&A40, 'ALL Tube Results'!$C40:$C199, "<="&B40) -> 4 | E40: =COUNTIFS('ALL Tube Results'!$C40:$C199, ">="&A40, 'ALL Tube Results'!$C40:$C199, "<="&B40, 'ALL Tube Results'!$F40:$F199, "Positive") -> 0 | F40: =COUNTIFS('ALL Tube Results'!$C40:$C199, ">="&A40, 'ALL Tube Results'!$C40:$C199, "<="&B40, 'ALL Tube Results'!$F40:$F199, "Inconclusive") -> 0 | G40: =IFERROR(E40/D40,IFERROR(0/0,"")) -> 0
...

Sheet Weekly CRLN
A1: Week Start Date | B1: Week End Date | C1: =CONCATENATE("Weekly Participants ",SUM(C2:C114)) -> Weekly Participants 2338 | D1: =CONCATENATE("Weekly Tubes Run ",SUM(D2:D114)) -> Weekly Tubes Run 1016 | E1: =CONCATENATE("Weekly Positive Tubes ",SUM(E2:E114)) -> Weekly Positive Tubes 32 | F1: =CONCATENATE("Weekly Inconclusive Tubes ",SUM(F2:F114)) -> Weekly Inconclusive Tubes 4 | G1: % Positive
A2: 44550 | B2: 44556 | C2: =SUMIFS('ALL Tube Results'!$G$2:$G114, 'ALL Tube Results'!$C$2:$C114, ">="&A2, 'ALL Tube Results'!$C$2:$C114, "<="&B2, 'ALL Tube Results'!$H$2:$H114, "CRLN") -> 4 | D2: =COUNTIFS('ALL Tube Results'!$C$2:$C114, ">="&A2, 'ALL Tube Results'!$C$2:$C114, "<="&B2, 'ALL Tube Results'!$H$2:$H114, "CRLN") -> 1 | E2: =COUNTIFS('ALL Tube Results'!$C$2:$C114, ">="&A2, 'ALL Tube Results'!$C$2:$C114, "<="&B2, 'ALL Tube Results'!$F$2:$F114, "Positive", 'ALL Tube Results'!$H$2:$H114, "CRLN") -> 0 | F2: =COUNTIFS('ALL Tube Results'!$C$2:$C114, ">="&A2, 'ALL Tube Results'!$C$2:$C114, "<="&B2, 'ALL Tube Results'!$F$2:$F114, "Inconclusive", 'ALL Tube Results'!$H$2:$H114, "CRLN") -> 0 | G2: =IFERROR(E2/D2,IFERROR(0/0,"")) -> 0
A3: 44557 | B3: 44563 | C3: =SUMIFS('ALL Tube Results'!$G$2:$G114, 'ALL Tube Results'!$C$2:$C114, ">="&A3, 'ALL Tube Results'!$C$2:$C114, "<="&B3, 'ALL Tube Results'!$H$2:$H114, "CRLN") -> 34 | D3: =COUNTIFS('ALL Tube Results'!$C$2:$C114, ">="&A3, 'ALL Tube Results'!$C$2:$C114, "<="&B3, 'ALL Tube Results'!$H$2:$H114, "CRLN") -> 12 | E3: =COUNTIFS('ALL Tube Results'!$C$2:$C114, ">="&A3, 'ALL Tube Results'!$C$2:$C114, "<="&B3, 'ALL Tube Results'!$F$2:$F114, "Positive", 'ALL Tube Results'!$H$2:$H114, "CRLN") -> 2 | F3: =COUNTIFS('ALL Tube Results'!$C$2:$C114, ">="&A3, 'ALL Tube Results'!$C$2:$C114, "<="&B3, 'ALL Tube Results'!$F$2:$F114, "Inconclusive", 'ALL Tube Results'!$H$2:$H114, "CRLN") -> 0 | G3: =IFERROR(E3/D3,IFERROR(0/0,"")) -> 0.16666667
A4: 44564 | B4: 44570 | C4: =SUMIFS('ALL Tube Results'!$G$2:$G114, 'ALL Tube Results'!$C$2:$C114, ">="&A4, 'ALL Tube Results'!$C$2:$C114, "<="&B4, 'ALL Tube Results'!$H$2:$H114, "CRLN") -> 85 | D4: =COUNTIFS('ALL Tube Results'!$C$2:$C114, ">="&A4, 'ALL Tube Results'!$C$2:$C114, "<="&B4, 'ALL Tube Results'!$H$2:$H114, "CRLN") -> 37 | E4: =COUNTIFS('ALL Tube Results'!$C$2:$C114, ">="&A4, 'ALL Tube Results'!$C$2:$C114, "<="&B4, 'ALL Tube Results'!$F$2:$F114, "Positive", 'ALL Tube Results'!$H$2:$H114, "CRLN") -> 6 | F4: =COUNTIFS('ALL Tube Results'!$C$2:$C114, ">="&A4, 'ALL Tube Results'!$C$2:$C114, "<="&B4, 'ALL Tube Results'!$F$2:$F114, "Inconclusive", 'ALL Tube Results'!$H$2:$H114, "CRLN") -> 0 | G4: =IFERROR(E4/D4,IFERROR(0/0,"")) -> 0.16216216
A5: 44571 | B5: 44577 | C5: =SUMIFS('ALL Tube Results'!$G$2:$G114, 'ALL Tube Results'!$C$2:$C114, ">="&A5, 'ALL Tube Results'!$C$2:$C114, "<="&B5, 'ALL Tube Results'!$H$2:$H114, "CRLN") -> 173 | D5: =COUNTIFS('ALL Tube Results'!$C$2:$C114, ">="&A5, 'ALL Tube Results'!$C$2:$C114, "<="&B5, 'ALL Tube Results'!$H$2:$H114, "CRLN") -> 83 | E5: =COUNTIFS('ALL Tube Results'!$C$2:$C114, ">="&A5, 'ALL Tube Results'!$C$2:$C114, "<="&B5, 'ALL Tube Results'!$F$2:$F114, "Positive", 'ALL Tube Results'!$H$2:$H114, "CRLN") -> 11 | F5: =COUNTIFS('ALL Tube Results'!$C$2:$C114, ">="&A5, 'ALL Tube Results'!$C$2:$C114, "<="&B5, 'ALL Tube Results'!$F$2:$F114, "Inconclusive", 'ALL Tube Results'!$H$2:$H114, "CRLN") -> 1 | G5: =IFERROR(E5/D5,IFERROR(0/0,"")) -> 0.13253012
A6: 44578 | B6: 44584 | C6: =SUMIFS('ALL Tube Results'!$G$2:$G114, 'ALL Tube Results'!$C$2:$C114, ">="&A6, 'ALL Tube Results'!$C$2:$C114, "<="&B6, 'ALL Tube Results'!$H$2:$H114, "CRLN") -> 162 | D6: =COUNTIFS('ALL Tube Results'!$C$2:$C114, ">="&A6, 'ALL Tube Results'!$C$2:$C114, "<="&B6, 'ALL Tube Results'!$H$2:$H114, "CRLN") -> 71 | E6: =COUNTIFS('ALL Tube Results'!$C$2:$C114, ">="&A6, 'ALL Tube Results'!$C$2:$C114, "<="&B6, 'ALL Tube Results'!$F$2:$F114, "Positive", 'ALL Tube Results'!$H$2:$H114, "CRLN") -> 5 | F6: =COUNTIFS('ALL Tube Results'!$C$2:$C114, ">="&A6, 'ALL Tube Results'!$C$2:$C114, "<="&B6, 'ALL Tube Results'!$F$2:$F114, "Inconclusive", 'ALL Tube Results'!$H$2:$H114, "CRLN") -> 0 | G6: =IFERROR(E6/D6,IFERROR(0/0,"")) -> 0.070422535
A7: 44585 | B7: 44591 | C7: =SUMIFS('ALL Tube Results'!$G$2:$G114, 'ALL Tube Results'!$C$2:$C114, ">="&A7, 'ALL Tube Results'!$C$2:$C114, "<="&B7, 'ALL Tube Results'!$H$2:$H114, "CRLN") -> 150 | D7: =COUNTIFS('ALL Tube Results'!$C$2:$C114, ">="&A7, 'ALL Tube Results'!$C$2:$C114, "<="&B7, 'ALL Tube Results'!$H$2:$H114, "CRLN") -> 62 | E7: =COUNTIFS('ALL Tube Results'!$C$2:$C114, ">="&A7, 'ALL Tube Results'!$C$2:$C114, "<="&B7, 'ALL Tube Results'!$F$2:$F114, "Positive", 'ALL Tube Results'!$H$2:$H114, "CRLN") -> 0 | F7: =COUNTIFS('ALL Tube Results'!$C$2:$C114, ">="&A7, 'ALL Tube Results'!$C$2:$C114, "<="&B7, 'ALL Tube Results'!$F$2:$F114, "Inconclusive", 'ALL Tube Results'!$H$2:$H114, "CRLN") -> 0 | G7: =IFERROR(E7/D7,IFERROR(0/0,"")) -> 0
A8: 44592 | B8: 44598 | C8: =SUMIFS('ALL Tube Results'!$G$2:$G114, 'ALL Tube Results'!$C$2:$C114, ">="&A8, 'ALL Tube Results'!$C$2:$C114, "<="&B8, 'ALL Tube Results'!$H$2:$H114, "CRLN") -> 143 | D8: =COUNTIFS('ALL Tube Results'!$C$2:$C114, ">="&A8, 'ALL Tube Results'!$C$2:$C114, "<="&B8, 'ALL Tube Results'!$H$2:$H114, "CRLN") -> 58 | E8: =COUNTIFS('ALL Tube Results'!$C$2:$C114, ">="&A8, 'ALL Tube Results'!$C$2:$C114, "<="&B8, 'ALL Tube Results'!$F$2:$F114, "Positive", 'ALL Tube Results'!$H$2:$H114, "CRLN") -> 0 | F8: =COUNTIFS('ALL Tube Results'!$C$2:$C114, ">="&A8, 'ALL Tube Results'!$C$2:$C114, "<="&B8, 'ALL Tube Results'!$F$2:$F114, "Inconclusive", 'ALL Tube Results'!$H$2:$H114, "CRLN") -> 0 | G8: =IFERROR(E8/D8,IFERROR(0/0,"")) -> 0
A9: 44599 | B9: 44605 | C9: =SUMIFS('ALL Tube Results'!$G$2:$G114, 'ALL Tube Results'!$C$2:$C114, ">="&A9, 'ALL Tube Results'!$C$2:$C114, "<="&B9, 'ALL Tube Results'!$H$2:$H114, "CRLN") -> 148 | D9: =COUNTIFS('ALL Tube Results'!$C$2:$C114, ">="&A9, 'ALL Tube Results'!$C$2:$C114, "<="&B9, 'ALL Tube Results'!$H$2:$H114, "CRLN") -> 60 | E9: =COUNTIFS('ALL Tube Results'!$C$2:$C114, ">="&A9, 'ALL Tube Results'!$C$2:$C114, "<="&B9, 'ALL Tube Results'!$F$2:$F114, "Positive", 'ALL Tube Results'!$H$2:$H114, "CRLN") -> 0 | F9: =COUNTIFS('ALL Tube Results'!$C$2:$C114, ">="&A9, 'ALL Tube Results'!$C$2:$C114, "<="&B9, 'ALL Tube Results'!$F$2:$F114, "Inconclusive", 'ALL Tube Results'!$H$2:$H114, "CRLN") -> 0 | G9: =IFERROR(E9/D9,IFERROR(0/0,"")) -> 0
A10: 44606 | B10: 44612 | C10: =SUMIFS('ALL Tube Results'!$G$2:$G114, 'ALL Tube Results'!$C$2:$C114, ">="&A10, 'ALL Tube Results'!$C$2:$C114, "<="&B10, 'ALL Tube Results'!$H$2:$H114, "CRLN") -> 128 | D10: =COUNTIFS('ALL Tube Results'!$C$2:$C114, ">="&A10, 'ALL Tube Results'!$C$2:$C114, "<="&B10, 'ALL Tube Results'!$H$2:$H114, "CRLN") -> 54 | E10: =COUNTIFS('ALL Tube Results'!$C$2:$C114, ">="&A10, 'ALL Tube Results'!$C$2:$C114, "<="&B10, 'ALL Tube Results'!$F$2:$F114, "Positive", 'ALL Tube Results'!$H$2:$H114, "CRLN") -> 0 | F10: =COUNTIFS('ALL Tube Results'!$C$2:$C114, ">="&A10, 'ALL Tube Results'!$C$2:$C114, "<="&B10, 'ALL Tube Results'!$F$2:$F114, "Inconclusive", 'ALL Tube Results'!$H$2:$H114, "CRLN") -> 1 | G10: =IFERROR(E10/D10,IFERROR(0/0,"")) -> 0
