Workbook

Sheet Referral Tests by Person CRLN
A1: PARTICIPANT FIRSTNAME | B1: PARTICIPANT LASTNAME | C1: PARTICIPANT FULLNAME | D1: PARTICIPANT ID | E1: Referral Match Row | F1: =CONCATENATE(SUM(F2:F83), " Num Sequential Referral Tests") -> 85 Num Sequential Referral Tests | G1: Num FloodLAMP Results Pos or Incl | H1: FloodLAMP Match Row | I1: FloodLAMP Tube ID | J1: Lookup Indiv or Pool? | K1: FloodLAMP Test Result | L1: FloodLAMP Test Date | M1: 1st Referral Test Date | N1: Antigen Neg with Other Positive | O1: Referral Overall Result | P1: 1st Referral Test Type | Q1: 1st Referral Test Result | R1: 2nd Referral Test Type | S1: 2nd Referral Test Result | T1: 3rd Referral Test Type | U1: 3rd Referral Test Result | V1: ID | X1: =CONCATENATE(COUNTIF(X2:X83,TRUE), " Included in APS Pos and Incl?") -> 30 Included in APS Pos and Incl? | Y1: INDIV or +Pool & Antigen | Z1: Antigen Result for FL Pos | AA1: Referral Eval
D2: =IFERROR(__xludf.DUMMYFUNCTION("FILTER('Referral Test Data CRLN'!D2:D100, ('Referral Test Data CRLN'!D2:D100 <> 'Referral Test Data CRLN'!D1:D99)) "),"FLMP858721") -> FLMP858721 | E2: =MATCH(D2,'Referral Test Data CRLN'!D$1:D83,0) -> 2 | F2: =IF(ISBLANK(E3),COUNTA('Referral Test Data CRLN'!D$2:D83)-SUM(F1:F$2),E3-E2) -> 1 | G2: =IFERROR(VLOOKUP(D2,'ALL Pos and Incl IMPORT'!Q$2:U83,5,FALSE),0) -> 1 | I2: FLT1136 | J2: =VLOOKUP(I2,'Pos and Incl IMPORT'!B$2:U$83,20,FALSE) -> INDIV | K2: =IFERROR(__xludf.DUMMYFUNCTION("VLOOKUP(I2,IMPORTRANGE('ALL Pos and Incl IMPORT'!$A$2,""ALL Tube Results!A2:F""),6,FALSE)"),"Positive") -> Positive | L2: =IFERROR(__xludf.DUMMYFUNCTION("VLOOKUP(I2,IMPORTRANGE('ALL Pos and Incl IMPORT'!$A$2,""ALL Tube Results!A2:F""),3,FALSE)"),44567.0) -> 44567 | M2: {=INDEX('Referral Test Data CRLN'!$C$1:$P83,$E2,3)} -> 44924 | N2: NA - Return Test | O2: NA - Return Test | P2: {=INDEX('Referral Test Data CRLN'!$C$1:$P83,$E2,7)} -> Antigen | Q2: {=INDEX('Referral Test Data CRLN'!$C$1:$P83,$E2,9)} -> Positive | R2: {=IF(OR($E2+1<$E3, AND(ISBLANK($E3), ($E2-1)<COUNT(#REF!))), INDEX('Referral Test Data CRLN'!$C$1:$P83,$E2+1,7), IFERROR(0/0,""))} | S2: {=IF(OR($E2+1<$E3, AND(ISBLANK($E3), ($E2-1)<COUNT(#REF!))), INDEX('Referral Test Data CRLN'!$C$1:$P83,$E2+1,9),IFERROR(0/0,""))} | T2: {=IF(OR($E2+2<$E3, AND(ISBLANK($E3), ($E2-1)<COUNT(#REF!))), INDEX('Referral Test Data CRLN'!$C$1:$P83,$E2+2,7),IFERROR(0/0,""))} | U2: {=IF(OR($E2+2<$E3, AND(ISBLANK($E3), ($E2-1)<COUNT(#REF!))), INDEX('Referral Test Data CRLN'!$C$1:$P83,$E2+2,9),IFERROR(0/0,""))} | V2: 1 | X2: TRUE | Y2: NA | AA2: FL test (pos) was test to return after anitgen pos test 8 days prior
D3: =IFERROR(__xludf.DUMMYFUNCTION("""COMPUTED_VALUE"""),"FLMP939793") -> FLMP939793 | E3: {=IFERROR( MATCH(D3, INDIRECT("'Referral Test Data CRLN'!D" & E2 + 1 & ":D"), 0) + E2, MATCH(D3, 'Referral Test Data CRLN'!D3:D83, 0) )} -> 3 | F3: =IF(ISBLANK(E4),COUNTA('Referral Test Data CRLN'!D$2:D83)-SUM(F2:F$2),E4-E3) -> 1 | G3: =IFERROR(VLOOKUP(D3,'ALL Pos and Incl IMPORT'!Q$2:U83,5,FALSE),0) -> 0 | I3: FLB5852 | J3: INDIV | K3: =IFERROR(__xludf.DUMMYFUNCTION("VLOOKUP(I3,IMPORTRANGE('ALL Pos and Incl IMPORT'!$A$2,""ALL Tube Results!A2:F""),6,FALSE)"),"Negative") -> Negative | L3: =IFERROR(__xludf.DUMMYFUNCTION("VLOOKUP(I3,IMPORTRANGE('ALL Pos and Incl IMPORT'!$A$2,""ALL Tube Results!A2:F""),3,FALSE)"),44567.0) -> 44567 | M3: {=INDEX('Referral Test Data CRLN'!$C$1:$P83,$E3,3)} -> 44925 | N3: NA - Return Test | O3: NA - Return Test | P3: {=INDEX('Referral Test Data CRLN'!$C$1:$P83,$E3,7)} -> Antigen | Q3: {=INDEX('Referral Test Data CRLN'!$C$1:$P83,$E3,9)} -> Positive | R3: {=IF(OR($E3+1<$E4, AND(ISBLANK($E4), ($E3-1)<COUNT(#REF!))), INDEX('Referral Test Data CRLN'!$C$1:$P83,$E3+1,7), IFERROR(0/0,""))} | S3: {=IF(OR($E3+1<$E4, AND(ISBLANK($E4), ($E3-1)<COUNT(#REF!))), INDEX('Referral Test Data CRLN'!$C$1:$P83,$E3+1,9),IFERROR(0/0,""))} | T3: {=IF(OR($E3+2<$E4, AND(ISBLANK($E4), ($E3-1)<COUNT(#REF!))), INDEX('Referral Test Data CRLN'!$C$1:$P83,$E3+2,7),IFERROR(0/0,""))} | U3: {=IF(OR($E3+2<$E4, AND(ISBLANK($E4), ($E3-1)<COUNT(#REF!))), INDEX('Referral Test Data CRLN'!$C$1:$P83,$E3+2,9),IFERROR(0/0,""))} | V3: 2 | X3: FL NEG | Y3: NA | AA3: FL test (neg) was test to return after anitgen pos test 7 days prior
D4: =IFERROR(__xludf.DUMMYFUNCTION("""COMPUTED_VALUE"""),"FLMP172687") -> FLMP172687 | E4: {=IFERROR( MATCH(D4, INDIRECT("'Referral Test Data CRLN'!D" & E3 + 1 & ":D"), 0) + E3, MATCH(D4, 'Referral Test Data CRLN'!D4:D83, 0) )} -> 4 | F4: =IF(ISBLANK(E5),COUNTA('Referral Test Data CRLN'!D$2:D83)-SUM(F$2:F3),E5-E4) -> 1 | G4: =IFERROR(VLOOKUP(D4,'ALL Pos and Incl IMPORT'!Q$2:U83,5,FALSE),0) -> 1 | I4: FLB5889 | J4: =VLOOKUP(I4,'Pos and Incl IMPORT'!B$2:U$83,20,FALSE) -> INDIV | K4: =IFERROR(__xludf.DUMMYFUNCTION("VLOOKUP(I4,IMPORTRANGE('ALL Pos and Incl IMPORT'!$A$2,""ALL Tube Results!A2:F""),6,FALSE)"),"Positive") -> Positive | L4: =IFERROR(__xludf.DUMMYFUNCTION("VLOOKUP(I4,IMPORTRANGE('ALL Pos and Incl IMPORT'!$A$2,""ALL Tube Results!A2:F""),3,FALSE)"),44567.0) -> 44567 | M4: {=INDEX('Referral Test Data CRLN'!$C$1:$P83,$E4,3)} -> 44925 | N4: NA - Return Test | O4: NA - Return Test | P4: {=INDEX('Referral Test Data CRLN'!$C$1:$P83,$E4,7)} -> Antigen | Q4: {=INDEX('Referral Test Data CRLN'!$C$1:$P83,$E4,9)} -> Positive | R4: {=IF(OR($E4+1<$E5, AND(ISBLANK($E5), ($E4-1)<COUNT(#REF!))), INDEX('Referral Test Data CRLN'!$C$1:$P83,$E4+1,7), IFERROR(0/0,""))} | S4: {=IF(OR($E4+1<$E5, AND(ISBLANK($E5), ($E4-1)<COUNT(#REF!))), INDEX('Referral Test Data CRLN'!$C$1:$P83,$E4+1,9),IFERROR(0/0,""))} | T4: {=IF(OR($E4+2<$E5, AND(ISBLANK($E5), ($E4-1)<COUNT(#REF!))), INDEX('Referral Test Data CRLN'!$C$1:$P83,$E4+2,7),IFERROR(0/0,""))} | U4: {=IF(OR($E4+2<$E5, AND(ISBLANK($E5), ($E4-1)<COUNT(#REF!))), INDEX('Referral Test Data CRLN'!$C$1:$P83,$E4+2,9),IFERROR(0/0,""))} | V4: 3 | X4: TRUE | Y4: NA | AA4: FL test (pos) was test to return after anitgen pos test 7 days prior
D5: =IFERROR(__xludf.DUMMYFUNCTION("""COMPUTED_VALUE"""),"FLMP549529") -> FLMP549529 | E5: {=IFERROR( MATCH(D5, INDIRECT("'Referral Test Data CRLN'!D" & E4 + 1 & ":D"), 0) + E4, MATCH(D5, 'Referral Test Data CRLN'!D5:D83, 0) )} -> 5 | F5: =IF(ISBLANK(E6),COUNTA('Referral Test Data CRLN'!D$2:D83)-SUM(F$2:F4),E6-E5) -> 1 | G5: =IFERROR(VLOOKUP(D5,'ALL Pos and Incl IMPORT'!Q$2:U83,5,FALSE),0) -> 1 | I5: FLB5830 | J5: =VLOOKUP(I5,'Pos and Incl IMPORT'!B$2:U$83,20,FALSE) -> INDIV | K5: =IFERROR(__xludf.DUMMYFUNCTION("VLOOKUP(I5,IMPORTRANGE('ALL Pos and Incl IMPORT'!$A$2,""ALL Tube Results!A2:F""),6,FALSE)"),"Positive") -> Positive | L5: =IFERROR(__xludf.DUMMYFUNCTION("VLOOKUP(I5,IMPORTRANGE('ALL Pos and Incl IMPORT'!$A$2,""ALL Tube Results!A2:F""),3,FALSE)"),44567.0) -> 44567 | M5: {=INDEX('Referral Test Data CRLN'!$C$1:$P83,$E5,3)} -> 44562 | N5: NA - Return Test | O5: NA - Return Test | P5: {=INDEX('Referral Test Data CRLN'!$C$1:$P83,$E5,7)} -> Antigen | Q5: {=INDEX('Referral Test Data CRLN'!$C$1:$P83,$E5,9)} -> Positive | R5: {=IF(OR($E5+1<$E6, AND(ISBLANK($E6), ($E5-1)<COUNT(#REF!))), INDEX('Referral Test Data CRLN'!$C$1:$P83,$E5+1,7), IFERROR(0/0,""))} | S5: {=IF(OR($E5+1<$E6, AND(ISBLANK($E6), ($E5-1)<COUNT(#REF!))), INDEX('Referral Test Data CRLN'!$C$1:$P83,$E5+1,9),IFERROR(0/0,""))} | T5: {=IF(OR($E5+2<$E6, AND(ISBLANK($E6), ($E5-1)<COUNT(#REF!))), INDEX('Referral Test Data CRLN'!$C$1:$P83,$E5+2,7),IFERROR(0/0,""))} | U5: {=IF(OR($E5+2<$E6, AND(ISBLANK($E6), ($E5-1)<COUNT(#REF!))), INDEX('Referral Test Data CRLN'!$C$1:$P83,$E5+2,9),IFERROR(0/0,""))} | V5: 4 | X5: TRUE | Y5: NA | AA5: FL test (pos) was test to return after anitgen pos test 5 days prior
D6: =IFERROR(__xludf.DUMMYFUNCTION("""COMPUTED_VALUE"""),"FLMP915544") -> FLMP915544 | E6: {=IFERROR( MATCH(D6, INDIRECT("'Referral Test Data CRLN'!D" & E5 + 1 & ":D"), 0) + E5, MATCH(D6, 'Referral Test Data CRLN'!D6:D83, 0) )} -> 6 | F6: =IF(ISBLANK(E7),COUNTA('Referral Test Data CRLN'!D$2:D83)-SUM(F$2:F5),E7-E6) -> 2 | G6: =IFERROR(VLOOKUP(D6,'ALL Pos and Incl IMPORT'!Q$2:U83,5,FALSE),0) -> 0 | I6: FLB6845 | J6: =VLOOKUP(I6,'Pos and Incl IMPORT'!B$2:U$83,20,FALSE) -> POOL | K6: =IFERROR(__xludf.DUMMYFUNCTION("VLOOKUP(I6,IMPORTRANGE('ALL Pos and Incl IMPORT'!$A$2,""ALL Tube Results!A2:F""),6,FALSE)"),"Positive") -> Positive | L6: =IFERROR(__xludf.DUMMYFUNCTION("VLOOKUP(I6,IMPORTRANGE('ALL Pos and Incl IMPORT'!$A$2,""ALL Tube Results!A2:F""),3,FALSE)"),44563.0) -> 44563 | M6: {=INDEX('Referral Test Data CRLN'!$C$1:$P83,$E6,3)} -> 44564 | N6: =IF(AND(EXACT(P6,"Antigen"),EXACT(Q6,"Negative"),OR(EXACT(S6,"Positive"),EXACT(U6,"Positive"))),TRUE,FALSE) -> FALSE | O6: Positive | P6: {=INDEX('Referral Test Data CRLN'!$C$1:$P83,$E6,7)} -> Antigen | Q6: {=INDEX('Referral Test Data CRLN'!$C$1:$P83,$E6,9)} -> Positive | R6: {=IF(OR($E6+1<$E7, AND(ISBLANK($E7), ($E6-1)<COUNT(#REF!))), INDEX('Referral Test Data CRLN'!$C$1:$P83,$E6+1,7), IFERROR(0/0,""))} -> PCR | S6: {=IF(OR($E6+1<$E7, AND(ISBLANK($E7), ($E6-1)<COUNT(#REF!))), INDEX('Referral Test Data CRLN'!$C$1:$P83,$E6+1,9),IFERROR(0/0,""))} -> Positive | T6: {=IF(OR($E6+2<$E7, AND(ISBLANK($E7), ($E6-1)<COUNT(#REF!))), INDEX('Referral Test Data CRLN'!$C$1:$P83,$E6+2,7),IFERROR(0/0,""))} | U6: {=IF(OR($E6+2<$E7, AND(ISBLANK($E7), ($E6-1)<COUNT(#REF!))), INDEX('Referral Test Data CRLN'!$C$1:$P83,$E6+2,9),IFERROR(0/0,""))} | V6: 5 | X6: TRUE | Y6: TRUE | Z6: POS | AA6: Only initial FL positive pool - no indiv deconv
D7: =IFERROR(__xludf.DUMMYFUNCTION("""COMPUTED_VALUE"""),"FLMP652238") -> FLMP652238 | E7: {=IFERROR( MATCH(D7, INDIRECT("'Referral Test Data CRLN'!D" & E6 + 1 & ":D"), 0) + E6, MATCH(D7, 'Referral Test Data CRLN'!D7:D83, 0) )} -> 8 | F7: =IF(ISBLANK(E8),COUNTA('Referral Test Data CRLN'!D$2:D83)-SUM(F$2:F6),E8-E7) -> 2 | G7: =IFERROR(VLOOKUP(D7,'ALL Pos and Incl IMPORT'!Q$2:U83,5,FALSE),0) -> 1 | I7: {=INDEX('Referral Test Data CRLN'!$C$1:$Q83,$E7,15)} -> FLB6845 | J7: =VLOOKUP(I7,'Pos and Incl IMPORT'!B$2:U$83,20,FALSE) -> POOL | K7: =IFERROR(__xludf.DUMMYFUNCTION("VLOOKUP(I7,IMPORTRANGE('ALL Pos and Incl IMPORT'!$A$2,""ALL Tube Results!A2:F""),6,FALSE)"),"Positive") -> Positive | L7: =IFERROR(__xludf.DUMMYFUNCTION("VLOOKUP(I7,IMPORTRANGE('ALL Pos and Incl IMPORT'!$A$2,""ALL Tube Results!A2:F""),3,FALSE)"),44563.0) -> 44563 | M7: {=INDEX('Referral Test Data CRLN'!$C$1:$P83,$E7,3)} -> 44564 | N7: =IF(AND(EXACT(P7,"Antigen"),EXACT(Q7,"Negative"),OR(EXACT(S7,"Positive"),EXACT(U7,"Positive"))),TRUE,FALSE) -> FALSE | O7: =Q7 -> Negative | P7: {=INDEX('Referral Test Data CRLN'!$C$1:$P83,$E7,7)} -> Antigen | Q7: {=INDEX('Referral Test Data CRLN'!$C$1:$P83,$E7,9)} -> Negative | R7: {=IF(OR($E7+1<$E8, AND(ISBLANK($E8), ($E7-1)<COUNT(#REF!))), INDEX('Referral Test Data CRLN'!$C$1:$P83,$E7+1,7), IFERROR(0/0,""))} -> PCR | S7: {=IF(OR($E7+1<$E8, AND(ISBLANK($E8), ($E7-1)<COUNT(#REF!))), INDEX('Referral Test Data CRLN'!$C$1:$P83,$E7+1,9),IFERROR(0/0,""))} -> Negative | T7: {=IF(OR($E7+2<$E8, AND(ISBLANK($E8), ($E7-1)<COUNT(#REF!))), INDEX('Referral Test Data CRLN'!$C$1:$P83,$E7+2,7),IFERROR(0/0,""))} | U7: {=IF(OR($E7+2<$E8, AND(ISBLANK($E8), ($E7-1)<COUNT(#REF!))), INDEX('Referral Test Data CRLN'!$C$1:$P83,$E7+2,9),IFERROR(0/0,""))} | V7: 6 | X7: TRUE | AA7: Only initial FL positive pool - no indiv deconv
D8: =IFERROR(__xludf.DUMMYFUNCTION("""COMPUTED_VALUE"""),"FLMP473007") -> FLMP473007 | E8: {=IFERROR( MATCH(D8, INDIRECT("'Referral Test Data CRLN'!D" & E7 + 1 & ":D"), 0) + E7, MATCH(D8, 'Referral Test Data CRLN'!D8:D83, 0) )} -> 10 | F8: =IF(ISBLANK(E9),COUNTA('Referral Test Data CRLN'!D$2:D83)-SUM(F$2:F7),E9-E8) -> 2 | G8: =IFERROR(VLOOKUP(D8,'ALL Pos and Incl IMPORT'!Q$2:U83,5,FALSE),0) -> 0 | I8: {=INDEX('Referral Test Data CRLN'!$C$1:$Q83,$E8,15)} -> FLB6845 | J8: =VLOOKUP(I8,'Pos and Incl IMPORT'!B$2:U$83,20,FALSE) -> POOL | K8: =IFERROR(__xludf.DUMMYFUNCTION("VLOOKUP(I8,IMPORTRANGE('ALL Pos and Incl IMPORT'!$A$2,""ALL Tube Results!A2:F""),6,FALSE)"),"Positive") -> Positive | L8: =IFERROR(__xludf.DUMMYFUNCTION("VLOOKUP(I8,IMPORTRANGE('ALL Pos and Incl IMPORT'!$A$2,""ALL Tube Results!A2:F""),3,FALSE)"),44563.0) -> 44563 | M8: {=INDEX('Referral Test Data CRLN'!$C$1:$P83,$E8,3)} -> 44564 | N8: =IF(AND(EXACT(P8,"Antigen"),EXACT(Q8,"Negative"),OR(EXACT(S8,"Positive"),EXACT(U8,"Positive"))),TRUE,FALSE) -> FALSE | O8: Positive | P8: {=INDEX('Referral Test Data CRLN'!$C$1:$P83,$E8,7)} -> Antigen | Q8: {=INDEX('Referral Test Data CRLN'!$C$1:$P83,$E8,9)} -> Positive | R8: {=IF(OR($E8+1<$E9, AND(ISBLANK($E9), ($E8-1)<COUNT(#REF!))), INDEX('Referral Test Data CRLN'!$C$1:$P83,$E8+1,7), IFERROR(0/0,""))} -> PCR | S8: {=IF(OR($E8+1<$E9, AND(ISBLANK($E9), ($E8-1)<COUNT(#REF!))), INDEX('Referral Test Data CRLN'!$C$1:$P83,$E8+1,9),IFERROR(0/0,""))} -> Positive | T8: {=IF(OR($E8+2<$E9, AND(ISBLANK($E9), ($E8-1)<COUNT(#REF!))), INDEX('Referral Test Data CRLN'!$C$1:$P83,$E8+2,7),IFERROR(0/0,""))} | U8: {=IF(OR($E8+2<$E9, AND(ISBLANK($E9), ($E8-1)<COUNT(#REF!))), INDEX('Referral Test Data CRLN'!$C$1:$P83,$E8+2,9),IFERROR(0/0,""))} | V8: 7 | X8: TRUE | AA8: Only initial FL positive pool - no indiv deconv
D9: =IFERROR(__xludf.DUMMYFUNCTION("""COMPUTED_VALUE"""),"FLMP776278") -> FLMP776278 | E9: {=IFERROR( MATCH(D9, INDIRECT("'Referral Test Data CRLN'!D" & E8 + 1 & ":D"), 0) + E8, MATCH(D9, 'Referral Test Data CRLN'!D9:D83, 0) )} -> 12 | F9: =IF(ISBLANK(E10),COUNTA('Referral Test Data CRLN'!D$2:D83)-SUM(F$2:F8),E10-E9) -> 3 | G9: =IFERROR(VLOOKUP(D9,'ALL Pos and Incl IMPORT'!Q$2:U83,5,FALSE),0) -> 3 | I9: {=INDEX('Referral Test Data CRLN'!$C$1:$Q83,$E9,15)} -> FLT1433 | J9: =VLOOKUP(I9,'Pos and Incl IMPORT'!B$2:U$83,20,FALSE) -> POOL | K9: =IFERROR(__xludf.DUMMYFUNCTION("VLOOKUP(I9,IMPORTRANGE('ALL Pos and Incl IMPORT'!$A$2,""ALL Tube Results!A2:F""),6,FALSE)"),"Positive") -> Positive | L9: =IFERROR(__xludf.DUMMYFUNCTION("VLOOKUP(I9,IMPORTRANGE('ALL Pos and Incl IMPORT'!$A$2,""ALL Tube Results!A2:F""),3,FALSE)"),44563.0) -> 44563 | M9: {=INDEX('Referral Test Data CRLN'!$C$1:$P83,$E9,3)} -> 44565 | N9: =IF(AND(EXACT(P9,"Antigen"),EXACT(Q9,"Negative"),OR(EXACT(S9,"Positive"),EXACT(U9,"Positive"))),TRUE,FALSE) -> FALSE | O9: Positive | P9: {=INDEX('Referral Test Data CRLN'!$C$1:$P83,$E9,7)} -> Antigen | Q9: {=INDEX('Referral Test Data CRLN'!$C$1:$P83,$E9,9)} -> Positive | R9: {=IF(OR($E9+1<$E10, AND(ISBLANK($E10), ($E9-1)<COUNT(#REF!))), INDEX('Referral Test Data CRLN'!$C$1:$P83,$E9+1,7), IFERROR(0/0,""))} -> PCR | S9: {=IF(OR($E9+1<$E10, AND(ISBLANK($E10), ($E9-1)<COUNT(#REF!))), INDEX('Referral Test Data CRLN'!$C$1:$P83,$E9+1,9),IFERROR(0/0,""))} -> Positive | V9: 8 | X9: TRUE | Y9: NO I FL | AA9: Non-CRLN child that test pos by antigen so no indiv deconv FL test
D10: =IFERROR(__xludf.DUMMYFUNCTION("""COMPUTED_VALUE"""),"FLMP828735") -> FLMP828735 | E10: {=IFERROR( MATCH(D10, INDIRECT("'Referral Test Data CRLN'!D" & E9 + 1 & ":D"), 0) + E9, MATCH(D10, 'Referral Test Data CRLN'!D10:D83, 0) )} -> 15 | F10: =IF(ISBLANK(E11),COUNTA('Referral Test Data CRLN'!D$2:D83)-SUM(F$2:F9),E11-E10) -> 4 | G10: =IFERROR(VLOOKUP(D10,'ALL Pos and Incl IMPORT'!Q$2:U83,5,FALSE),0) -> 3 | I10: {=INDEX('Referral Test Data CRLN'!$C$1:$Q83,$E10,15)} -> FLT1433 | J10: =VLOOKUP(I10,'Pos and Incl IMPORT'!B$2:U$83,20,FALSE) -> POOL | K10: =IFERROR(__xludf.DUMMYFUNCTION("VLOOKUP(I10,IMPORTRANGE('ALL Pos and Incl IMPORT'!$A$2,""ALL Tube Results!A2:F""),6,FALSE)"),"Positive") -> Positive | L10: =IFERROR(__xludf.DUMMYFUNCTION("VLOOKUP(I10,IMPORTRANGE('ALL Pos and Incl IMPORT'!$A$2,""ALL Tube Results!A2:F""),3,FALSE)"),44563.0) -> 44563 | M10: {=INDEX('Referral Test Data CRLN'!$C$1:$P83,$E10,3)} -> 44565 | N10: =IF(AND(EXACT(P10,"Antigen"),EXACT(Q10,"Negative"),OR(EXACT(S10,"Positive"),EXACT(U10,"Positive"))),TRUE,FALSE) -> FALSE | O10: Positive | P10: {=INDEX('Referral Test Data CRLN'!$C$1:$P83,$E10,7)} -> Antigen | Q10: {=INDEX('Referral Test Data CRLN'!$C$1:$P83,$E10,9)} -> Positive | R10: {=IF(OR($E10+1<$E11, AND(ISBLANK($E11), ($E10-1)<COUNT(#REF!))), INDEX('Referral Test Data CRLN'!$C$1:$P83,$E10+1,7), IFERROR(0/0,""))} -> PCR | S10: {=IF(OR($E10+1<$E11, AND(ISBLANK($E11), ($E10-1)<COUNT(#REF!))), INDEX('Referral Test Data CRLN'!$C$1:$P83,$E10+1,9),IFERROR(0/0,""))} -> Positive | V10: 9 | X10: TRUE | Y10: NO I FL | AA10: CRLN child that test pos by antigen so no indiv deconv FL test
D11: =IFERROR(__xludf.DUMMYFUNCTION("""COMPUTED_VALUE"""),"FLMP302189") -> FLMP302189 | E11: {=IFERROR( MATCH(D11, INDIRECT("'Referral Test Data CRLN'!D" & E10 + 1 & ":D"), 0) + E10, MATCH(D11, 'Referral Test Data CRLN'!D11:D83, 0) )} -> 19 | F11: =IF(ISBLANK(E12),COUNTA('Referral Test Data CRLN'!D$2:D83)-SUM(F$2:F10),E12-E11) -> 3 | G11: =IFERROR(VLOOKUP(D11,'ALL Pos and Incl IMPORT'!Q$2:U83,5,FALSE),0) -> 4 | I11: {=INDEX('Referral Test Data CRLN'!$C$1:$Q83,$E11,15)} -> FLT1433 | J11: =VLOOKUP(I11,'Pos and Incl IMPORT'!B$2:U$83,20,FALSE) -> POOL | K11: =IFERROR(__xludf.DUMMYFUNCTION("VLOOKUP(I11,IMPORTRANGE('ALL Pos and Incl IMPORT'!$A$2,""ALL Tube Results!A2:F""),6,FALSE)"),"Positive") -> Positive | L11: =IFERROR(__xludf.DUMMYFUNCTION("VLOOKUP(I11,IMPORTRANGE('ALL Pos and Incl IMPORT'!$A$2,""ALL Tube Results!A2:F""),3,FALSE)"),44563.0) -> 44563 | M11: {=INDEX('Referral Test Data CRLN'!$C$1:$P83,$E11,3)} -> 44563 | N11: =IF(AND(EXACT(P11,"Antigen"),EXACT(Q11,"Negative"),OR(EXACT(S11,"Positive"),EXACT(U11,"Positive"))),TRUE,FALSE) -> TRUE | O11: Positive | P11: {=INDEX('Referral Test Data CRLN'!$C$1:$P83,$E11,7)} -> Antigen | Q11: {=INDEX('Referral Test Data CRLN'!$C$1:$P83,$E11,9)} -> Negative | R11: {=IF(OR($E11+1<$E12, AND(ISBLANK($E12), ($E11-1)<COUNT(#REF!))), INDEX('Referral Test Data CRLN'!$C$1:$P83,$E11+1,7), IFERROR(0/0,""))} -> PCR | S11: {=IF(OR($E11+1<$E12, AND(ISBLANK($E12), ($E11-1)<COUNT(#REF!))), INDEX('Referral Test Data CRLN'!$C$1:$P83,$E11+1,9),IFERROR(0/0,""))} -> Positive | V11: 10 | X11: TRUE | Y11: TRUE | Z11: NEG | AA11: parent tested neg by antigen so did indiv deconv FL test and was pos
D12: =IFERROR(__xludf.DUMMYFUNCTION("""COMPUTED_VALUE"""),"FLMP857562") -> FLMP857562 | E12: {=IFERROR( MATCH(D12, INDIRECT("'Referral Test Data CRLN'!D" & E11 + 1 & ":D"), 0) + E11, MATCH(D12, 'Referral Test Data CRLN'!D12:D83, 0) )} -> 22 | F12: =IF(ISBLANK(E13),COUNTA('Referral Test Data CRLN'!D$2:D83)-SUM(F$2:F11),E13-E12) -> 3 | G12: =IFERROR(VLOOKUP(D12,'ALL Pos and Incl IMPORT'!Q$2:U83,5,FALSE),0) -> 2 | I12: {=INDEX('Referral Test Data CRLN'!$C$1:$Q83,$E12,15)} -> FLT1433 | J12: =VLOOKUP(I12,'Pos and Incl IMPORT'!B$2:U$83,20,FALSE) -> POOL | K12: =IFERROR(__xludf.DUMMYFUNCTION("VLOOKUP(I12,IMPORTRANGE('ALL Pos and Incl IMPORT'!$A$2,""ALL Tube Results!A2:F""),6,FALSE)"),"Positive") -> Positive | L12: =IFERROR(__xludf.DUMMYFUNCTION("VLOOKUP(I12,IMPORTRANGE('ALL Pos and Incl IMPORT'!$A$2,""ALL Tube Results!A2:F""),3,FALSE)"),44563.0) -> 44563 | M12: {=INDEX('Referral Test Data CRLN'!$C$1:$P83,$E12,3)} -> 44563 | N12: =IF(AND(EXACT(P12,"Antigen"),EXACT(Q12,"Negative"),OR(EXACT(S12,"Positive"),EXACT(U12,"Positive"))),TRUE,FALSE) -> TRUE | O12: Positive | P12: {=INDEX('Referral Test Data CRLN'!$C$1:$P83,$E12,7)} -> Antigen | Q12: {=INDEX('Referral Test Data CRLN'!$C$1:$P83,$E12,9)} -> Negative | R12: {=IF(OR($E12+1<$E13, AND(ISBLANK($E13), ($E12-1)<COUNT(#REF!))), INDEX('Referral Test Data CRLN'!$C$1:$P83,$E12+1,7), IFERROR(0/0,""))} -> PCR | S12: {=IF(OR($E12+1<$E13, AND(ISBLANK($E13), ($E12-1)<COUNT(#REF!))), INDEX('Referral Test Data CRLN'!$C$1:$P83,$E12+1,9),IFERROR(0/0,""))} -> Positive | V12: 11 | X12: TRUE | Y12: TRUE | Z12: NEG | AA12: parent tested neg by antigen so did indiv deconv FL test and was pos
D13: =IFERROR(__xludf.DUMMYFUNCTION("""COMPUTED_VALUE"""),"FLMP147333") -> FLMP147333 | E13: {=IFERROR( MATCH(D13, INDIRECT("'Referral Test Data CRLN'!D" & E12 + 1 & ":D"), 0) + E12, MATCH(D13, 'Referral Test Data CRLN'!D13:D83, 0) )} -> 25 | F13: =IF(ISBLANK(E14),COUNTA('Referral Test Data CRLN'!D$2:D83)-SUM(F$2:F12),E14-E13) -> 6 | G13: =IFERROR(VLOOKUP(D13,'ALL Pos and Incl IMPORT'!Q$2:U83,5,FALSE),0) -> 2 | I13: {=INDEX('Referral Test Data CRLN'!$C$1:$Q83,$E13,15)} -> FLT1465 | J13: =VLOOKUP(I13,'Pos and Incl IMPORT'!B$2:U$83,20,FALSE) -> INDIV | K13: =IFERROR(__xludf.DUMMYFUNCTION("VLOOKUP(I13,IMPORTRANGE('ALL Pos and Incl IMPORT'!$A$2,""ALL Tube Results!A2:F""),6,FALSE)"),"Positive") -> Positive | L13: =IFERROR(__xludf.DUMMYFUNCTION("VLOOKUP(I13,IMPORTRANGE('ALL Pos and Incl IMPORT'!$A$2,""ALL Tube Results!A2:F""),3,FALSE)"),44571.0) -> 44571 | M13: 44570 | N13: =IF(AND(EXACT(P13,"Antigen"),EXACT(Q13,"Negative"),OR(EXACT(S13,"Positive"),EXACT(U13,"Positive"))),TRUE,FALSE) -> FALSE | O13: Positive | P13: Antigen | Q13: Positive | R13: PCR | S13: Positive | V13: 12 | X13: TRUE | Y13: =AND(OR(EXACT("Antigen",P13),EXACT("Antigen",R13),EXACT("Antigen",T13)),EXACT(J13,"INDIV")) -> TRUE | Z13: POS | AA13: known pos that tested pos by FL - not sure if they told us about antigen result before FL test
D14: =IFERROR(__xludf.DUMMYFUNCTION("""COMPUTED_VALUE"""),"FLMP601970") -> FLMP601970 | E14: {=IFERROR( MATCH(D14, INDIRECT("'Referral Test Data CRLN'!D" & E13 + 1 & ":D"), 0) + E13, MATCH(D14, 'Referral Test Data CRLN'!D14:D83, 0) )} -> 31 | F14: =IF(ISBLANK(E15),COUNTA('Referral Test Data CRLN'!D$2:D83)-SUM(F$2:F13),E15-E14) -> 1 | G14: =IFERROR(VLOOKUP(D14,'ALL Pos and Incl IMPORT'!Q$2:U83,5,FALSE),0) -> 1 | I14: {=INDEX('Referral Test Data CRLN'!$C$1:$Q83,$E14,15)} -> FLT1129 | J14: =VLOOKUP(I14,'Pos and Incl IMPORT'!B$2:U$83,20,FALSE) -> INDIV | K14: =IFERROR(__xludf.DUMMYFUNCTION("VLOOKUP(I14,IMPORTRANGE('ALL Pos and Incl IMPORT'!$A$2,""ALL Tube Results!A2:F""),6,FALSE)"),"Positive") -> Positive | L14: =IFERROR(__xludf.DUMMYFUNCTION("VLOOKUP(I14,IMPORTRANGE('ALL Pos and Incl IMPORT'!$A$2,""ALL Tube Results!A2:F""),3,FALSE)"),44578.0) -> 44578 | M14: {=INDEX('Referral Test Data CRLN'!$C$1:$P83,$E14,3)} -> 44579 | N14: =IF(AND(EXACT(P14,"Antigen"),EXACT(Q14,"Negative"),OR(EXACT(S14,"Positive"),EXACT(U14,"Positive"))),TRUE,FALSE) -> FALSE | O14: =Q14 -> Positive | P14: {=INDEX('Referral Test Data CRLN'!$C$1:$P83,$E14,7)} -> Antigen | Q14: {=INDEX('Referral Test Data CRLN'!$C$1:$P83,$E14,9)} -> Positive | R14: {=IF(OR($E14+1<$E15, AND(ISBLANK($E15), ($E14-1)<COUNT(#REF!))), INDEX('Referral Test Data CRLN'!$C$1:$P83,$E14+1,7), IFERROR(0/0,""))} | S14: {=IF(OR($E14+1<$E15, AND(ISBLANK($E15), ($E14-1)<COUNT(#REF!))), INDEX('Referral Test Data CRLN'!$C$1:$P83,$E14+1,9),IFERROR(0/0,""))} | T14: {=IF(OR($E14+2<$E15, AND(ISBLANK($E15), ($E14-1)<COUNT(#REF!))), INDEX('Referral Test Data CRLN'!$C$1:$P83,$E14+2,7),IFERROR(0/0,""))} | U14: {=IF(OR($E14+2<$E15, AND(ISBLANK($E15), ($E14-1)<COUNT(#REF!))), INDEX('Referral Test Data CRLN'!$C$1:$P83,$E14+2,9),IFERROR(0/0,""))} | V14: 13 | X14: TRUE | Y14: NO I FL | AA14: this was a later return test - the CRLN child did not test on 1-10 with parents
D15: =IFERROR(__xludf.DUMMYFUNCTION("""COMPUTED_VALUE"""),"FLMP330127") -> FLMP330127 | E15: {=IFERROR( MATCH(D15, INDIRECT("'Referral Test Data CRLN'!D" & E14 + 1 & ":D"), 0) + E14, MATCH(D15, 'Referral Test Data CRLN'!D15:D83, 0) )} -> 32 | F15: =IF(ISBLANK(E16),COUNTA('Referral Test Data CRLN'!D$2:D83)-SUM(F$2:F14),E16-E15) -> 4 | G15: =IFERROR(VLOOKUP(D15,'ALL Pos and Incl IMPORT'!Q$2:U83,5,FALSE),0) -> 2 | I15: {=INDEX('Referral Test Data CRLN'!$C$1:$Q83,$E15,15)} -> FLT1400 | J15: =VLOOKUP(I15,'Pos and Incl IMPORT'!B$2:U$83,20,FALSE) -> INDIV | K15: =IFERROR(__xludf.DUMMYFUNCTION("VLOOKUP(I15,IMPORTRANGE('ALL Pos and Incl IMPORT'!$A$2,""ALL Tube Results!A2:F""),6,FALSE)"),"Positive") -> Positive | L15: =IFERROR(__xludf.DUMMYFUNCTION("VLOOKUP(I15,IMPORTRANGE('ALL Pos and Incl IMPORT'!$A$2,""ALL Tube Results!A2:F""),3,FALSE)"),44571.0) -> 44571 | M15: 44568 | N15: =IF(AND(EXACT(P15,"Antigen"),EXACT(Q15,"Negative"),OR(EXACT(S15,"Positive"),EXACT(U15,"Positive"))),TRUE,FALSE) -> FALSE | O15: =S15 -> Positive | P15: Antigen | Q15: Positive | R15: PCR | S15: Positive | V15: 14 | X15: TRUE | Y15: =AND(OR(EXACT("Antigen",P15),EXACT("Antigen",R15),EXACT("Antigen",T15)),EXACT(J15,"INDIV")) -> TRUE | Z15: POS | AA15: known pos that tested pos by FL - not sure if they told us about antigen result before FL test
D16: =IFERROR(__xludf.DUMMYFUNCTION("""COMPUTED_VALUE"""),"FLMP969044") -> FLMP969044 | E16: {=IFERROR( MATCH(D16, INDIRECT("'Referral Test Data CRLN'!D" & E15 + 1 & ":D"), 0) + E15, MATCH(D16, 'Referral Test Data CRLN'!D16:D83, 0) )} -> 36 | F16: =IF(ISBLANK(E17),COUNTA('Referral Test Data CRLN'!D$2:D83)-SUM(F$2:F15),E17-E16) -> 1 | G16: =IFERROR(VLOOKUP(D16,'ALL Pos and Incl IMPORT'!Q$2:U83,5,FALSE),0) -> 0 | I16: {=INDEX('Referral Test Data CRLN'!$C$1:$Q83,$E16,15)} -> FLT1161 | J16: =VLOOKUP(I16,'Pos and Incl IMPORT'!B$2:U$83,20,FALSE) -> POOL | K16: =IFERROR(__xludf.DUMMYFUNCTION("VLOOKUP(I16,IMPORTRANGE('ALL Pos and Incl IMPORT'!$A$2,""ALL Tube Results!A2:F""),6,FALSE)"),"Positive") -> Positive | L16: =IFERROR(__xludf.DUMMYFUNCTION("VLOOKUP(I16,IMPORTRANGE('ALL Pos and Incl IMPORT'!$A$2,""ALL Tube Results!A2:F""),3,FALSE)"),44571.0) -> 44571 | M16: {=INDEX('Referral Test Data CRLN'!$C$1:$P83,$E16,3)} -> 44573 | N16: =IF(AND(EXACT(P16,"Antigen"),EXACT(Q16,"Negative"),OR(EXACT(S16,"Positive"),EXACT(U16,"Positive"))),TRUE,FALSE) -> FALSE | O16: =Q16 -> Negative | P16: {=INDEX('Referral Test Data CRLN'!$C$1:$P83,$E16,7)} -> PCR | Q16: {=INDEX('Referral Test Data CRLN'!$C$1:$P83,$E16,9)} -> Negative | R16: {=IF(OR($E16+1<$E17, AND(ISBLANK($E17), ($E16-1)<COUNT(#REF!))), INDEX('Referral Test Data CRLN'!$C$1:$P83,$E16+1,7), IFERROR(0/0,""))} | S16: {=IF(OR($E16+1<$E17, AND(ISBLANK($E17), ($E16-1)<COUNT(#REF!))), INDEX('Referral Test Data CRLN'!$C$1:$P83,$E16+1,9),IFERROR(0/0,""))} | T16: {=IF(OR($E16+2<$E17, AND(ISBLANK($E17), ($E16-1)<COUNT(#REF!))), INDEX('Referral Test Data CRLN'!$C$1:$P83,$E16+2,7),IFERROR(0/0,""))} | U16: {=IF(OR($E16+2<$E17, AND(ISBLANK($E17), ($E16-1)<COUNT(#REF!))), INDEX('Referral Test Data CRLN'!$C$1:$P83,$E16+2,9),IFERROR(0/0,""))} | V16: 15 | X16: TRUE | Y16: =AND(OR(EXACT("Antigen",P16),EXACT("Antigen",R16),EXACT("Antigen",T16)),EXACT(J16,"INDIV")) -> FALSE | AA16: FL pos pool of 3 in morning then indiv deconvl with FL and this person was neg along with one other both by PCR, and 3rd pool person was PCR pos
D17: =IFERROR(__xludf.DUMMYFUNCTION("""COMPUTED_VALUE"""),"FLMP887888") -> FLMP887888 | E17: {=IFERROR( MATCH(D17, INDIRECT("'Referral Test Data CRLN'!D" & E16 + 1 & ":D"), 0) + E16, MATCH(D17, 'Referral Test Data CRLN'!D17:D83, 0) )} -> 37 | F17: =IF(ISBLANK(E18),COUNTA('Referral Test Data CRLN'!D$2:D83)-SUM(F$2:F16),E18-E17) -> 4 | G17: =IFERROR(VLOOKUP(D17,'ALL Pos and Incl IMPORT'!Q$2:U83,5,FALSE),0) -> 2 | I17: {=INDEX('Referral Test Data CRLN'!$C$1:$Q83,$E17,15)} -> FLT1161 | J17: =VLOOKUP(I17,'Pos and Incl IMPORT'!B$2:U$83,20,FALSE) -> POOL | K17: =IFERROR(__xludf.DUMMYFUNCTION("VLOOKUP(I17,IMPORTRANGE('ALL Pos and Incl IMPORT'!$A$2,""ALL Tube Results!A2:F""),6,FALSE)"),"Positive") -> Positive | L17: =IFERROR(__xludf.DUMMYFUNCTION("VLOOKUP(I17,IMPORTRANGE('ALL Pos and Incl IMPORT'!$A$2,""ALL Tube Results!A2:F""),3,FALSE)"),44571.0) -> 44571 | M17: {=INDEX('Referral Test Data CRLN'!$C$1:$P83,$E17,3)} -> 44565 | N17: =IF(AND(EXACT(P17,"Antigen"),EXACT(Q17,"Negative"),OR(EXACT(S17,"Positive"),EXACT(U17,"Positive"))),TRUE,FALSE) -> FALSE | O17: =Q17 -> Positive | P17: PCR | Q17: Positive | V17: 16 | X17: TRUE | Y17: =AND(OR(EXACT("Antigen",P17),EXACT("Antigen",R17),EXACT("Antigen",T17)),EXACT(J17,"INDIV")) -> FALSE | AA17: FL pos pool of 3 in morning then indiv deconvl with FL and only this person was pos (other 2 FL and the referral PCR neg) - ignore neg antigen tests for analysis because they were 6 days before and 5 days after FL tests
D18: =IFERROR(__xludf.DUMMYFUNCTION("""COMPUTED_VALUE"""),"FLMP876455") -> FLMP876455 | E18: {=IFERROR( MATCH(D18, INDIRECT("'Referral Test Data CRLN'!D" & E17 + 1 & ":D"), 0) + E17, MATCH(D18, 'Referral Test Data CRLN'!D18:D83, 0) )} -> 41 | F18: =IF(ISBLANK(E19),COUNTA('Referral Test Data CRLN'!D$2:D83)-SUM(F$2:F17),E19-E18) -> 1 | G18: =IFERROR(VLOOKUP(D18,'ALL Pos and Incl IMPORT'!Q$2:U83,5,FALSE),0) -> 0 | I18: {=INDEX('Referral Test Data CRLN'!$C$1:$Q83,$E18,15)} -> FLT1161 | J18: =VLOOKUP(I18,'Pos and Incl IMPORT'!B$2:U$83,20,FALSE) -> POOL | K18: =IFERROR(__xludf.DUMMYFUNCTION("VLOOKUP(I18,IMPORTRANGE('ALL Pos and Incl IMPORT'!$A$2,""ALL Tube Results!A2:F""),6,FALSE)"),"Positive") -> Positive | L18: =IFERROR(__xludf.DUMMYFUNCTION("VLOOKUP(I18,IMPORTRANGE('ALL Pos and Incl IMPORT'!$A$2,""ALL Tube Results!A2:F""),3,FALSE)"),44571.0) -> 44571 | M18: {=INDEX('Referral Test Data CRLN'!$C$1:$P83,$E18,3)} -> 44573 | N18: =IF(AND(EXACT(P18,"Antigen"),EXACT(Q18,"Negative"),OR(EXACT(S18,"Positive"),EXACT(U18,"Positive"))),TRUE,FALSE) -> FALSE | O18: =Q18 -> Negative | P18: {=INDEX('Referral Test Data CRLN'!$C$1:$P83,$E18,7)} -> PCR | Q18: {=INDEX('Referral Test Data CRLN'!$C$1:$P83,$E18,9)} -> Negative | R18: {=IF(OR($E18+1<$E19, AND(ISBLANK($E19), ($E18-1)<COUNT(#REF!))), INDEX('Referral Test Data CRLN'!$C$1:$P83,$E18+1,7), IFERROR(0/0,""))} | S18: {=IF(OR($E18+1<$E19, AND(ISBLANK($E19), ($E18-1)<COUNT(#REF!))), INDEX('Referral Test Data CRLN'!$C$1:$P83,$E18+1,9),IFERROR(0/0,""))} | T18: {=IF(OR($E18+2<$E19, AND(ISBLANK($E19), ($E18-1)<COUNT(#REF!))), INDEX('Referral Test Data CRLN'!$C$1:$P83,$E18+2,7),IFERROR(0/0,""))} | U18: {=IF(OR($E18+2<$E19, AND(ISBLANK($E19), ($E18-1)<COUNT(#REF!))), INDEX('Referral Test Data CRLN'!$C$1:$P83,$E18+2,9),IFERROR(0/0,""))} | V18: 17 | X18: TRUE | Y18: =AND(OR(EXACT("Antigen",P18),EXACT("Antigen",R18),EXACT("Antigen",T18)),EXACT(J18,"INDIV")) -> FALSE | AA18: FL pos pool of 3 in morning then indiv deconvl with FL and this person was neg along with one other both by PCR, and 3rd pool person was PCR pos
D19: =IFERROR(__xludf.DUMMYFUNCTION("""COMPUTED_VALUE"""),"FLMP472803") -> FLMP472803 | E19: {=IFERROR( MATCH(D19, INDIRECT("'Referral Test Data CRLN'!D" & E18 + 1 & ":D"), 0) + E18, MATCH(D19, 'Referral Test Data CRLN'!D19:D83, 0) )} -> 42 | F19: =IF(ISBLANK(E20),COUNTA('Referral Test Data CRLN'!D$2:D83)-SUM(F$2:F18),E20-E19) -> 7 | G19: =IFERROR(VLOOKUP(D19,'ALL Pos and Incl IMPORT'!Q$2:U83,5,FALSE),0) -> 1 | I19: MA57 | J19: INDIV | K19: =IFERROR(__xludf.DUMMYFUNCTION("VLOOKUP(I19,IMPORTRANGE('ALL Pos and Incl IMPORT'!$A$2,""ALL Tube Results!A2:F""),6,FALSE)"),"Negative") -> Negative | L19: =IFERROR(__xludf.DUMMYFUNCTION("VLOOKUP(I19,IMPORTRANGE('ALL Pos and Incl IMPORT'!$A$2,""ALL Tube Results!A2:F""),3,FALSE)"),44683.0) -> 44683 | M19: {=INDEX('Referral Test Data CRLN'!$C$1:$P83,$E19,3)} -> 44683 | N19: =IF(AND(EXACT(P19,"Antigen"),EXACT(Q19,"Negative"),OR(EXACT(S19,"Positive"),EXACT(U19,"Positive"))),TRUE,FALSE) -> FALSE | O19: =Q19 -> Negative | P19: {=INDEX('Referral Test Data CRLN'!$C$1:$P83,$E19,7)} -> PCR | Q19: {=INDEX('Referral Test Data CRLN'!$C$1:$P83,$E19,9)} -> Negative | R19: {=IF(OR($E19+1<$E20, AND(ISBLANK($E20), ($E19-1)<COUNT(#REF!))), INDEX('Referral Test Data CRLN'!$C$1:$P83,$E19+1,7), IFERROR(0/0,""))} -> Antigen | S19: {=IF(OR($E19+1<$E20, AND(ISBLANK($E20), ($E19-1)<COUNT(#REF!))), INDEX('Referral Test Data CRLN'!$C$1:$P83,$E19+1,9),IFERROR(0/0,""))} -> Negative | T19: {=IF(OR($E19+2<$E20, AND(ISBLANK($E20), ($E19-1)<COUNT(#REF!))), INDEX('Referral Test Data CRLN'!$C$1:$P83,$E19+2,7),IFERROR(0/0,""))} -> Antigen | U19: {=IF(OR($E19+2<$E20, AND(ISBLANK($E20), ($E19-1)<COUNT(#REF!))), INDEX('Referral Test Data CRLN'!$C$1:$P83,$E19+2,9),IFERROR(0/0,""))} -> Negative | V19: 18 | X19: TRUE | Y19: TRUE | AA19: FL pos pool of 3 in morning then indiv deconvl with FL and this person was neg but there was 1 FL deconv pos that was confirmed by PCR (neg by antigen initally then pos 2 days later)
D20: =IFERROR(__xludf.DUMMYFUNCTION("""COMPUTED_VALUE"""),"FLMP687722") -> FLMP687722 | E20: {=IFERROR( MATCH(D20, INDIRECT("'Referral Test Data CRLN'!D" & E19 + 1 & ":D"), 0) + E19, MATCH(D20, 'Referral Test Data CRLN'!D20:D83, 0) )} -> 49 | F20: =IF(ISBLANK(E21),COUNTA('Referral Test Data CRLN'!D$2:D83)-SUM(F$2:F19),E21-E20) -> 8 | G20: =IFERROR(VLOOKUP(D20,'ALL Pos and Incl IMPORT'!Q$2:U83,5,FALSE),0) -> 2 | I20: MA108 | J20: =VLOOKUP(I20,'Pos and Incl IMPORT'!B$2:U$83,20,FALSE) -> INDIV | K20: =IFERROR(__xludf.DUMMYFUNCTION("VLOOKUP(I20,IMPORTRANGE('ALL Pos and Incl IMPORT'!$A$2,""ALL Tube Results!A2:F""),6,FALSE)"),"Positive") -> Positive | L20: =IFERROR(__xludf.DUMMYFUNCTION("VLOOKUP(I20,IMPORTRANGE('ALL Pos and Incl IMPORT'!$A$2,""ALL Tube Results!A2:F""),3,FALSE)"),44683.0) -> 44683 | M20: {=INDEX('Referral Test Data CRLN'!$C$1:$P83,$E20,3)} -> 44683 | N20: TRUE | O20: =S20 -> Positive | P20: {=INDEX('Referral Test Data CRLN'!$C$1:$P83,$E20,7)} -> Antigen | Q20: {=INDEX('Referral Test Data CRLN'!$C$1:$P83,$E20,9)} -> Negative | R20: {=IF(OR($E20+1<$E21, AND(ISBLANK($E21), ($E20-1)<COUNT(#REF!))), INDEX('Referral Test Data CRLN'!$C$1:$P83,$E20+1,7), IFERROR(0/0,""))} -> PCR | S20: {=IF(OR($E20+1<$E21, AND(ISBLANK($E21), ($E20-1)<COUNT(#REF!))), INDEX('Referral Test Data CRLN'!$C$1:$P83,$E20+1,9),IFERROR(0/0,""))} -> Positive | T20: {=IF(OR($E20+2<$E21, AND(ISBLANK($E21), ($E20-1)<COUNT(#REF!))), INDEX('Referral Test Data CRLN'!$C$1:$P83,$E20+2,7),IFERROR(0/0,""))} -> Antigen | U20: {=IF(OR($E20+2<$E21, AND(ISBLANK($E21), ($E20-1)<COUNT(#REF!))), INDEX('Referral Test Data CRLN'!$C$1:$P83,$E20+2,9),IFERROR(0/0,""))} -> Positive | V20: 19 | X20: TRUE | Y20: TRUE | Z20: NEG | AA20: FL pos pool of 3 in morning then indiv deconvl with FL and this person was pos that was confirmed by PCR (neg by antigen initally then pos 2 days later) - other 3 in pool neg by PCR and antigen
D21: =IFERROR(__xludf.DUMMYFUNCTION("""COMPUTED_VALUE"""),"FLMP464138") -> FLMP464138 | E21: {=IFERROR( MATCH(D21, INDIRECT("'Referral Test Data CRLN'!D" & E20 + 1 & ":D"), 0) + E20, MATCH(D21, 'Referral Test Data CRLN'!D21:D83, 0) )} -> 57 | F21: =IF(ISBLANK(E22),COUNTA('Referral Test Data CRLN'!D$2:D83)-SUM(F$2:F20),E22-E21) -> 7 | G21: =IFERROR(VLOOKUP(D21,'ALL Pos and Incl IMPORT'!Q$2:U83,5,FALSE),0) -> 0 | I21: MA82 | J21: INDIV | K21: =IFERROR(__xludf.DUMMYFUNCTION("VLOOKUP(I21,IMPORTRANGE('ALL Pos and Incl IMPORT'!$A$2,""ALL Tube Results!A2:F""),6,FALSE)"),"Negative") -> Negative | L21: =IFERROR(__xludf.DUMMYFUNCTION("VLOOKUP(I21,IMPORTRANGE('ALL Pos and Incl IMPORT'!$A$2,""ALL Tube Results!A2:F""),3,FALSE)"),44683.0) -> 44683 | M21: {=INDEX('Referral Test Data CRLN'!$C$1:$P83,$E21,3)} -> 44683 | N21: =IF(AND(EXACT(P21,"Antigen"),EXACT(Q21,"Negative"),OR(EXACT(S21,"Positive"),EXACT(U21,"Positive"))),TRUE,FALSE) -> FALSE | O21: =Q21 -> Negative | P21: {=INDEX('Referral Test Data CRLN'!$C$1:$P83,$E21,7)} -> PCR | Q21: {=INDEX('Referral Test Data CRLN'!$C$1:$P83,$E21,9)} -> Negative | R21: {=IF(OR($E21+1<$E22, AND(ISBLANK($E22), ($E21-1)<COUNT(#REF!))), INDEX('Referral Test Data CRLN'!$C$1:$P83,$E21+1,7), IFERROR(0/0,""))} -> Antigen | S21: {=IF(OR($E21+1<$E22, AND(ISBLANK($E22), ($E21-1)<COUNT(#REF!))), INDEX('Referral Test Data CRLN'!$C$1:$P83,$E21+1,9),IFERROR(0/0,""))} -> Negative | T21: {=IF(OR($E21+2<$E22, AND(ISBLANK($E22), ($E21-1)<COUNT(#REF!))), INDEX('Referral Test Data CRLN'!$C$1:$P83,$E21+2,7),IFERROR(0/0,""))} -> Antigen | U21: {=IF(OR($E21+2<$E22, AND(ISBLANK($E22), ($E21-1)<COUNT(#REF!))), INDEX('Referral Test Data CRLN'!$C$1:$P83,$E21+2,9),IFERROR(0/0,""))} -> Negative | V21: 20 | X21: TRUE | Y21: TRUE | AA21: FL pos pool of 3 in morning then indiv deconvl with FL and this person was neg but there was 1 FL deconv pos that was confirmed by PCR (neg by antigen initally then pos 2 days later)
D22: =IFERROR(__xludf.DUMMYFUNCTION("""COMPUTED_VALUE"""),"FLMP132170") -> FLMP132170 | E22: {=IFERROR( MATCH(D22, INDIRECT("'Referral Test Data CRLN'!D" & E21 + 1 & ":D"), 0) + E21, MATCH(D22, 'Referral Test Data CRLN'!D22:D83, 0) )} -> 64 | F22: =IF(ISBLANK(E23),COUNTA('Referral Test Data CRLN'!D$2:D83)-SUM(F$2:F21),E23-E22) -> 7 | G22: =IFERROR(VLOOKUP(D22,'ALL Pos and Incl IMPORT'!Q$2:U83,5,FALSE),0) -> 0 | I22: MA100A | J22: INDIV | K22: =IFERROR(__xludf.DUMMYFUNCTION("VLOOKUP(I22,IMPORTRANGE('ALL Pos and Incl IMPORT'!$A$2,""ALL Tube Results!A2:F""),6,FALSE)"),"Negative") -> Negative | L22: =IFERROR(__xludf.DUMMYFUNCTION("VLOOKUP(I22,IMPORTRANGE('ALL Pos and Incl IMPORT'!$A$2,""ALL Tube Results!A2:F""),3,FALSE)"),44683.0) -> 44683 | M22: {=INDEX('Referral Test Data CRLN'!$C$1:$P83,$E22,3)} -> 44683 | N22: =IF(AND(EXACT(P22,"Antigen"),EXACT(Q22,"Negative"),OR(EXACT(S22,"Positive"),EXACT(U22,"Positive"))),TRUE,FALSE) -> FALSE | O22: =Q22 -> Negative | P22: {=INDEX('Referral Test Data CRLN'!$C$1:$P83,$E22,7)} -> PCR | Q22: {=INDEX('Referral Test Data CRLN'!$C$1:$P83,$E22,9)} -> Negative | R22: {=IF(OR($E22+1<$E23, AND(ISBLANK($E23), ($E22-1)<COUNT(#REF!))), INDEX('Referral Test Data CRLN'!$C$1:$P83,$E22+1,7), IFERROR(0/0,""))} -> Antigen | S22: {=IF(OR($E22+1<$E23, AND(ISBLANK($E23), ($E22-1)<COUNT(#REF!))), INDEX('Referral Test Data CRLN'!$C$1:$P83,$E22+1,9),IFERROR(0/0,""))} -> Negative | T22: {=IF(OR($E22+2<$E23, AND(ISBLANK($E23), ($E22-1)<COUNT(#REF!))), INDEX('Referral Test Data CRLN'!$C$1:$P83,$E22+2,7),IFERROR(0/0,""))} -> Antigen | U22: {=IF(OR($E22+2<$E23, AND(ISBLANK($E23), ($E22-1)<COUNT(#REF!))), INDEX('Referral Test Data CRLN'!$C$1:$P83,$E22+2,9),IFERROR(0/0,""))} -> Negative | V22: 21 | X22: TRUE | Y22: TRUE | AA22: FL pos pool of 3 in morning then indiv deconvl with FL and this person was neg but there was 1 FL deconv pos that was confirmed by PCR (neg by antigen initally then pos 2 days later)
D23: =IFERROR(__xludf.DUMMYFUNCTION("""COMPUTED_VALUE"""),"FLMP552537") -> FLMP552537 | E23: {=IFERROR( MATCH(D23, INDIRECT("'Referral Test Data CRLN'!D" & E22 + 1 & ":D"), 0) + E22, MATCH(D23, 'Referral Test Data CRLN'!D23:D83, 0) )} -> 71 | F23: =IF(ISBLANK(E24),COUNTA('Referral Test Data CRLN'!D$2:D83)-SUM(F$2:F22),E24-E23) -> 2 | G23: =IFERROR(VLOOKUP(D23,'ALL Pos and Incl IMPORT'!Q$2:U83,5,FALSE),0) -> 2 | I23: FLE202 | J23: =VLOOKUP(I23,'Pos and Incl IMPORT'!B$2:U$83,20,FALSE) -> INDIV | K23: =IFERROR(__xludf.DUMMYFUNCTION("VLOOKUP(I23,IMPORTRANGE('ALL Pos and Incl IMPORT'!$A$2,""ALL Tube Results!A2:F""),6,FALSE)"),"Positive") -> Positive | L23: =IFERROR(__xludf.DUMMYFUNCTION("VLOOKUP(I23,IMPORTRANGE('ALL Pos and Incl IMPORT'!$A$2,""ALL Tube Results!A2:F""),3,FALSE)"),44690.0) -> 44690 | M23: {=INDEX('Referral Test Data CRLN'!$C$1:$P83,$E23,3)} -> 44690 | N23: =IF(AND(EXACT(P23,"Antigen"),EXACT(Q23,"Negative"),OR(EXACT(S23,"Positive"),EXACT(U23,"Positive"))),TRUE,FALSE) -> FALSE | O23: =S23 -> Positive | P23: {=INDEX('Referral Test Data CRLN'!$C$1:$P83,$E23,7)} -> Antigen | Q23: {=INDEX('Referral Test Data CRLN'!$C$1:$P83,$E23,9)} -> Positive | R23: {=IF(OR($E23+1<$E24, AND(ISBLANK($E24), ($E23-1)<COUNT(#REF!))), INDEX('Referral Test Data CRLN'!$C$1:$P83,$E23+1,7), IFERROR(0/0,""))} -> PCR | S23: {=IF(OR($E23+1<$E24, AND(ISBLANK($E24), ($E23-1)<COUNT(#REF!))), INDEX('Referral Test Data CRLN'!$C$1:$P83,$E23+1,9),IFERROR(0/0,""))} -> Positive | T23: {=IF(OR($E23+2<$E24, AND(ISBLANK($E24), ($E23-1)<COUNT(#REF!))), INDEX('Referral Test Data CRLN'!$C$1:$P83,$E23+2,7),IFERROR(0/0,""))} | U23: {=IF(OR($E23+2<$E24, AND(ISBLANK($E24), ($E23-1)<COUNT(#REF!))), INDEX('Referral Test Data CRLN'!$C$1:$P83,$E23+2,9),IFERROR(0/0,""))} | V23: 22 | X23: TRUE | Y23: =AND(OR(EXACT("Antigen",P23),EXACT("Antigen",R23),EXACT("Antigen",T23)),EXACT(J23,"INDIV")) -> TRUE | Z23: POS | AA23: FL incl pool of 3, then indiv deconv and 1 of 3 pos, this one was confrimed by PCR and antigen
D24: =IFERROR(__xludf.DUMMYFUNCTION("""COMPUTED_VALUE"""),"FLMP254321") -> FLMP254321 | E24: {=IFERROR( MATCH(D24, INDIRECT("'Referral Test Data CRLN'!D" & E23 + 1 & ":D"), 0) + E23, MATCH(D24, 'Referral Test Data CRLN'!D24:D83, 0) )} -> 73 | F24: =IF(ISBLANK(E25),COUNTA('Referral Test Data CRLN'!D$2:D83)-SUM(F$2:F23),E25-E24) -> 2 | G24: =IFERROR(VLOOKUP(D24,'ALL Pos and Incl IMPORT'!Q$2:U83,5,FALSE),0) -> 0 | I24: FLE269 | J24: INDIV | K24: =IFERROR(__xludf.DUMMYFUNCTION("VLOOKUP(I24,IMPORTRANGE('ALL Pos and Incl IMPORT'!$A$2,""ALL Tube Results!A2:F""),6,FALSE)"),"Negative") -> Negative | L24: =IFERROR(__xludf.DUMMYFUNCTION("VLOOKUP(I24,IMPORTRANGE('ALL Pos and Incl IMPORT'!$A$2,""ALL Tube Results!A2:F""),3,FALSE)"),44690.0) -> 44690 | M24: {=INDEX('Referral Test Data CRLN'!$C$1:$P83,$E24,3)} -> 44690 | N24: =IF(AND(EXACT(P24,"Antigen"),EXACT(Q24,"Negative"),OR(EXACT(S24,"Positive"),EXACT(U24,"Positive"))),TRUE,FALSE) -> FALSE | O24: =S24 -> Negative | P24: {=INDEX('Referral Test Data CRLN'!$C$1:$P83,$E24,7)} -> Antigen | Q24: {=INDEX('Referral Test Data CRLN'!$C$1:$P83,$E24,9)} -> Negative | R24: {=IF(OR($E24+1<$E25, AND(ISBLANK($E25), ($E24-1)<COUNT(#REF!))), INDEX('Referral Test Data CRLN'!$C$1:$P83,$E24+1,7), IFERROR(0/0,""))} -> PCR | S24: {=IF(OR($E24+1<$E25, AND(ISBLANK($E25), ($E24-1)<COUNT(#REF!))), INDEX('Referral Test Data CRLN'!$C$1:$P83,$E24+1,9),IFERROR(0/0,""))} -> Negative | T24: {=IF(OR($E24+2<$E25, AND(ISBLANK($E25), ($E24-1)<COUNT(#REF!))), INDEX('Referral Test Data CRLN'!$C$1:$P83,$E24+2,7),IFERROR(0/0,""))} | U24: {=IF(OR($E24+2<$E25, AND(ISBLANK($E25), ($E24-1)<COUNT(#REF!))), INDEX('Referral Test Data CRLN'!$C$1:$P83,$E24+2,9),IFERROR(0/0,""))} | V24: 23 | X24: TRUE | Y24: =AND(OR(EXACT("Antigen",P24),EXACT("Antigen",R24),EXACT("Antigen",T24)),EXACT(J24,"INDIV")) -> TRUE | AA24: FL incl pool of 3, then indiv deconv and 1 of 3 pos, this one was FL neg and also neg by PCR and antigen
D25: =IFERROR(__xludf.DUMMYFUNCTION("""COMPUTED_VALUE"""),"FLMP705416") -> FLMP705416 | E25: {=IFERROR( MATCH(D25, INDIRECT("'Referral Test Data CRLN'!D" & E24 + 1 & ":D"), 0) + E24, MATCH(D25, 'Referral Test Data CRLN'!D25:D83, 0) )} -> 75 | F25: =IF(ISBLANK(E26),COUNTA('Referral Test Data CRLN'!D$2:D83)-SUM(F$2:F24),E26-E25) -> 2 | G25: =IFERROR(VLOOKUP(D25,'ALL Pos and Incl IMPORT'!Q$2:U83,5,FALSE),0) -> 0 | I25: FLB5969 | J25: INDIV | K25: =IFERROR(__xludf.DUMMYFUNCTION("VLOOKUP(I25,IMPORTRANGE('ALL Pos and Incl IMPORT'!$A$2,""ALL Tube Results!A2:F""),6,FALSE)"),"Negative") -> Negative | L25: =IFERROR(__xludf.DUMMYFUNCTION("VLOOKUP(I25,IMPORTRANGE('ALL Pos and Incl IMPORT'!$A$2,""ALL Tube Results!A2:F""),3,FALSE)"),44690.0) -> 44690 | M25: {=INDEX('Referral Test Data CRLN'!$C$1:$P83,$E25,3)} -> 44690 | N25: =IF(AND(EXACT(P25,"Antigen"),EXACT(Q25,"Negative"),OR(EXACT(S25,"Positive"),EXACT(U25,"Positive"))),TRUE,FALSE) -> TRUE | O25: =S25 -> Positive | P25: {=INDEX('Referral Test Data CRLN'!$C$1:$P83,$E25,7)} -> Antigen | Q25: {=INDEX('Referral Test Data CRLN'!$C$1:$P83,$E25,9)} -> Negative | R25: {=IF(OR($E25+1<$E26, AND(ISBLANK($E26), ($E25-1)<COUNT(#REF!))), INDEX('Referral Test Data CRLN'!$C$1:$P83,$E25+1,7), IFERROR(0/0,""))} -> PCR | S25: {=IF(OR($E25+1<$E26, AND(ISBLANK($E26), ($E25-1)<COUNT(#REF!))), INDEX('Referral Test Data CRLN'!$C$1:$P83,$E25+1,9),IFERROR(0/0,""))} -> Positive | T25: {=IF(OR($E25+2<$E26, AND(ISBLANK($E26), ($E25-1)<COUNT(#REF!))), INDEX('Referral Test Data CRLN'!$C$1:$P83,$E25+2,7),IFERROR(0/0,""))} | U25: {=IF(OR($E25+2<$E26, AND(ISBLANK($E26), ($E25-1)<COUNT(#REF!))), INDEX('Referral Test Data CRLN'!$C$1:$P83,$E25+2,9),IFERROR(0/0,""))} | V25: 24 | X25: TRUE | Y25: =AND(OR(EXACT("Antigen",P25),EXACT("Antigen",R25),EXACT("Antigen",T25)),EXACT(J25,"INDIV")) -> TRUE | AA25: FL incl pool of 3, then indiv deconv and 1 of 3 pos, this one was FL neg and also neg by antigen byt pos by PCR
D26: =IFERROR(__xludf.DUMMYFUNCTION("""COMPUTED_VALUE"""),"FLMP608363") -> FLMP608363 | E26: {=IFERROR( MATCH(D26, INDIRECT("'Referral Test Data CRLN'!D" & E25 + 1 & ":D"), 0) + E25, MATCH(D26, 'Referral Test Data CRLN'!D26:D83, 0) )} -> 77 | F26: =IF(ISBLANK(E27),COUNTA('Referral Test Data CRLN'!D$2:D83)-SUM(F$2:F25),E27-E26) -> 1 | G26: =IFERROR(VLOOKUP(D26,'ALL Pos and Incl IMPORT'!Q$2:U83,5,FALSE),0) -> 2 | I26: AH365 | J26: =VLOOKUP(I26,'Pos and Incl IMPORT'!B$2:U$83,20,FALSE) -> INDIV | K26: =IFERROR(__xludf.DUMMYFUNCTION("VLOOKUP(I26,IMPORTRANGE('ALL Pos and Incl IMPORT'!$A$2,""ALL Tube Results!A2:F""),6,FALSE)"),"Positive") -> Positive | L26: =IFERROR(__xludf.DUMMYFUNCTION("VLOOKUP(I26,IMPORTRANGE('ALL Pos and Incl IMPORT'!$A$2,""ALL Tube Results!A2:F""),3,FALSE)"),44690.0) -> 44690 | M26: {=INDEX('Referral Test Data CRLN'!$C$1:$P83,$E26,3)} -> 44690 | N26: =IF(AND(EXACT(P26,"Antigen"),EXACT(Q26,"Negative"),OR(EXACT(S26,"Positive"),EXACT(U26,"Positive"))),TRUE,FALSE) -> FALSE | O26: =Q26 -> Positive | P26: {=INDEX('Referral Test Data CRLN'!$C$1:$P83,$E26,7)} -> PCR | Q26: {=INDEX('Referral Test Data CRLN'!$C$1:$P83,$E26,9)} -> Positive | R26: {=IF(OR($E26+1<$E27, AND(ISBLANK($E27), ($E26-1)<COUNT(#REF!))), INDEX('Referral Test Data CRLN'!$C$1:$P83,$E26+1,7), IFERROR(0/0,""))} | S26: {=IF(OR($E26+1<$E27, AND(ISBLANK($E27), ($E26-1)<COUNT(#REF!))), INDEX('Referral Test Data CRLN'!$C$1:$P83,$E26+1,9),IFERROR(0/0,""))} | T26: {=IF(OR($E26+2<$E27, AND(ISBLANK($E27), ($E26-1)<COUNT(#REF!))), INDEX('Referral Test Data CRLN'!$C$1:$P83,$E26+2,7),IFERROR(0/0,""))} | U26: {=IF(OR($E26+2<$E27, AND(ISBLANK($E27), ($E26-1)<COUNT(#REF!))), INDEX('Referral Test Data CRLN'!$C$1:$P83,$E26+2,9),IFERROR(0/0,""))} | V26: 25 | X26: TRUE | Y26: =AND(OR(EXACT("Antigen",P26),EXACT("Antigen",R26),EXACT("Antigen",T26)),EXACT(J26,"INDIV")) -> FALSE | AA26: CRLN child (no symptomys) - FL pos pool of 4 then indiv deconv by FL with 1 of 4 pos and this one confimed by PCR
D27: =IFERROR(__xludf.DUMMYFUNCTION("""COMPUTED_VALUE"""),"FLMP325595") -> FLMP325595 | E27: {=IFERROR( MATCH(D27, INDIRECT("'Referral Test Data CRLN'!D" & E26 + 1 & ":D"), 0) + E26, MATCH(D27, 'Referral Test Data CRLN'!D27:D83, 0) )} -> 78 | F27: =IF(ISBLANK(E28),COUNTA('Referral Test Data CRLN'!D$2:D83)-SUM(F$2:F26),E28-E27) -> 1 | G27: =IFERROR(VLOOKUP(D27,'ALL Pos and Incl IMPORT'!Q$2:U83,5,FALSE),0) -> 0 | I27: AH245 | J27: INDIV | K27: =IFERROR(__xludf.DUMMYFUNCTION("VLOOKUP(I27,IMPORTRANGE('ALL Pos and Incl IMPORT'!$A$2,""ALL Tube Results!A2:F""),6,FALSE)"),"Negative") -> Negative | L27: =IFERROR(__xludf.DUMMYFUNCTION("VLOOKUP(I27,IMPORTRANGE('ALL Pos and Incl IMPORT'!$A$2,""ALL Tube Results!A2:F""),3,FALSE)"),44690.0) -> 44690 | M27: {=INDEX('Referral Test Data CRLN'!$C$1:$P83,$E27,3)} -> 44690 | N27: =IF(AND(EXACT(P27,"Antigen"),EXACT(Q27,"Negative"),OR(EXACT(S27,"Positive"),EXACT(U27,"Positive"))),TRUE,FALSE) -> FALSE | O27: =Q27 -> Negative | P27: {=INDEX('Referral Test Data CRLN'!$C$1:$P83,$E27,7)} -> PCR | Q27: {=INDEX('Referral Test Data CRLN'!$C$1:$P83,$E27,9)} -> Negative | R27: {=IF(OR($E27+1<$E28, AND(ISBLANK($E28), ($E27-1)<COUNT(#REF!))), INDEX('Referral Test Data CRLN'!$C$1:$P83,$E27+1,7), IFERROR(0/0,""))} | S27: {=IF(OR($E27+1<$E28, AND(ISBLANK($E28), ($E27-1)<COUNT(#REF!))), INDEX('Referral Test Data CRLN'!$C$1:$P83,$E27+1,9),IFERROR(0/0,""))} | T27: {=IF(OR($E27+2<$E28, AND(ISBLANK($E28), ($E27-1)<COUNT(#REF!))), INDEX('Referral Test Data CRLN'!$C$1:$P83,$E27+2,7),IFERROR(0/0,""))} | U27: {=IF(OR($E27+2<$E28, AND(ISBLANK($E28), ($E27-1)<COUNT(#REF!))), INDEX('Referral Test Data CRLN'!$C$1:$P83,$E27+2,9),IFERROR(0/0,""))} | V27: 26 | X27: TRUE | Y27: =AND(OR(EXACT("Antigen",P27),EXACT("Antigen",R27),EXACT("Antigen",T27)),EXACT(J27,"INDIV")) -> FALSE
D28: =IFERROR(__xludf.DUMMYFUNCTION("""COMPUTED_VALUE"""),"FLMP779627") -> FLMP779627 | E28: {=IFERROR( MATCH(D28, INDIRECT("'Referral Test Data CRLN'!D" & E27 + 1 & ":D"), 0) + E27, MATCH(D28, 'Referral Test Data CRLN'!D28:D83, 0) )} -> 79 | F28: =IF(ISBLANK(E29),COUNTA('Referral Test Data CRLN'!D$2:D83)-SUM(F$2:F27),E29-E28) -> 1 | G28: =IFERROR(VLOOKUP(D28,'ALL Pos and Incl IMPORT'!Q$2:U83,5,FALSE),0) -> 0 | I28: AJ9253 | J28: INDIV | K28: =IFERROR(__xludf.DUMMYFUNCTION("VLOOKUP(I28,IMPORTRANGE('ALL Pos and Incl IMPORT'!$A$2,""ALL Tube Results!A2:F""),6,FALSE)"),"Negative") -> Negative | L28: =IFERROR(__xludf.DUMMYFUNCTION("VLOOKUP(I28,IMPORTRANGE('ALL Pos and Incl IMPORT'!$A$2,""ALL Tube Results!A2:F""),3,FALSE)"),44690.0) -> 44690 | M28: {=INDEX('Referral Test Data CRLN'!$C$1:$P83,$E28,3)} -> 44690 | N28: =IF(AND(EXACT(P28,"Antigen"),EXACT(Q28,"Negative"),OR(EXACT(S28,"Positive"),EXACT(U28,"Positive"))),TRUE,FALSE) -> FALSE | O28: =Q28 -> Negative | P28: {=INDEX('Referral Test Data CRLN'!$C$1:$P83,$E28,7)} -> PCR | Q28: {=INDEX('Referral Test Data CRLN'!$C$1:$P83,$E28,9)} -> Negative | R28: {=IF(OR($E28+1<$E29, AND(ISBLANK($E29), ($E28-1)<COUNT(#REF!))), INDEX('Referral Test Data CRLN'!$C$1:$P83,$E28+1,7), IFERROR(0/0,""))} | S28: {=IF(OR($E28+1<$E29, AND(ISBLANK($E29), ($E28-1)<COUNT(#REF!))), INDEX('Referral Test Data CRLN'!$C$1:$P83,$E28+1,9),IFERROR(0/0,""))} | T28: {=IF(OR($E28+2<$E29, AND(ISBLANK($E29), ($E28-1)<COUNT(#REF!))), INDEX('Referral Test Data CRLN'!$C$1:$P83,$E28+2,7),IFERROR(0/0,""))} | U28: {=IF(OR($E28+2<$E29, AND(ISBLANK($E29), ($E28-1)<COUNT(#REF!))), INDEX('Referral Test Data CRLN'!$C$1:$P83,$E28+2,9),IFERROR(0/0,""))} | V28: 27 | X28: TRUE | Y28: =AND(OR(EXACT("Antigen",P28),EXACT("Antigen",R28),EXACT("Antigen",T28)),EXACT(J28,"INDIV")) -> FALSE
D29: =IFERROR(__xludf.DUMMYFUNCTION("""COMPUTED_VALUE"""),"FLMP322473") -> FLMP322473 | E29: {=IFERROR( MATCH(D29, INDIRECT("'Referral Test Data CRLN'!D" & E28 + 1 & ":D"), 0) + E28, MATCH(D29, 'Referral Test Data CRLN'!D29:D83, 0) )} -> 80 | F29: =IF(ISBLANK(E30),COUNTA('Referral Test Data CRLN'!D$2:D83)-SUM(F$2:F28),E30-E29) -> 1 | G29: =IFERROR(VLOOKUP(D29,'ALL Pos and Incl IMPORT'!Q$2:U83,5,FALSE),0) -> 0 | I29: AH679 | J29: INDIV | K29: =IFERROR(__xludf.DUMMYFUNCTION("VLOOKUP(I29,IMPORTRANGE('ALL Pos and Incl IMPORT'!$A$2,""ALL Tube Results!A2:F""),6,FALSE)"),"Negative") -> Negative | L29: =IFERROR(__xludf.DUMMYFUNCTION("VLOOKUP(I29,IMPORTRANGE('ALL Pos and Incl IMPORT'!$A$2,""ALL Tube Results!A2:F""),3,FALSE)"),44690.0) -> 44690 | M29: {=INDEX('Referral Test Data CRLN'!$C$1:$P83,$E29,3)} -> 44690 | N29: =IF(AND(EXACT(P29,"Antigen"),EXACT(Q29,"Negative"),OR(EXACT(S29,"Positive"),EXACT(U29,"Positive"))),TRUE,FALSE) -> FALSE | O29: =Q29 -> Negative | P29: {=INDEX('Referral Test Data CRLN'!$C$1:$P83,$E29,7)} -> PCR | Q29: {=INDEX('Referral Test Data CRLN'!$C$1:$P83,$E29,9)} -> Negative | R29: {=IF(OR($E29+1<$E30, AND(ISBLANK($E30), ($E29-1)<COUNT(#REF!))), INDEX('Referral Test Data CRLN'!$C$1:$P83,$E29+1,7), IFERROR(0/0,""))} | S29: {=IF(OR($E29+1<$E30, AND(ISBLANK($E30), ($E29-1)<COUNT(#REF!))), INDEX('Referral Test Data CRLN'!$C$1:$P83,$E29+1,9),IFERROR(0/0,""))} | T29: {=IF(OR($E29+2<$E30, AND(ISBLANK($E30), ($E29-1)<COUNT(#REF!))), INDEX('Referral Test Data CRLN'!$C$1:$P83,$E29+2,7),IFERROR(0/0,""))} | U29: {=IF(OR($E29+2<$E30, AND(ISBLANK($E30), ($E29-1)<COUNT(#REF!))), INDEX('Referral Test Data CRLN'!$C$1:$P83,$E29+2,9),IFERROR(0/0,""))} | V29: 28 | X29: TRUE | Y29: =AND(OR(EXACT("Antigen",P29),EXACT("Antigen",R29),EXACT("Antigen",T29)),EXACT(J29,"INDIV")) -> FALSE
D30: =IFERROR(__xludf.DUMMYFUNCTION("""COMPUTED_VALUE"""),"FLMP987142") -> FLMP987142 | E30: {=IFERROR( MATCH(D30, INDIRECT("'Referral Test Data CRLN'!D" & E29 + 1 & ":D"), 0) + E29, MATCH(D30, 'Referral Test Data CRLN'!D30:D83, 0) )} -> 81 | F30: =IF(ISBLANK(E31),COUNTA('Referral Test Data CRLN'!D$2:D83)-SUM(F$2:F29),E31-E30) -> 4 | G30: =IFERROR(VLOOKUP(D30,'ALL Pos and Incl IMPORT'!Q$2:U83,5,FALSE),0) -> 2 | I30: {=INDEX('Referral Test Data CRLN'!$C$1:$Q83,$E30,15)} -> FLB6807 | J30: =VLOOKUP(I30,'Pos and Incl IMPORT'!B$2:U$83,20,FALSE) -> INDIV | K30: =IFERROR(__xludf.DUMMYFUNCTION("VLOOKUP(I30,IMPORTRANGE('ALL Pos and Incl IMPORT'!$A$2,""ALL Tube Results!A2:F""),6,FALSE)"),"Positive") -> Positive | L30: =IFERROR(__xludf.DUMMYFUNCTION("VLOOKUP(I30,IMPORTRANGE('ALL Pos and Incl IMPORT'!$A$2,""ALL Tube Results!A2:F""),3,FALSE)"),44700.0) -> 44700 | M30: {=INDEX('Referral Test Data CRLN'!$C$1:$P83,$E30,3)} -> 44697 | N30: TRUE | O30: =U30 -> Positive | P30: {=INDEX('Referral Test Data CRLN'!$C$1:$P83,$E30,7)} -> Antigen | Q30: {=INDEX('Referral Test Data CRLN'!$C$1:$P83,$E30,9)} -> Negative | R30: {=IF(OR($E30+1<$E31, AND(ISBLANK($E31), ($E30-1)<COUNT(#REF!))), INDEX('Referral Test Data CRLN'!$C$1:$P83,$E30+1,7), IFERROR(0/0,""))} -> Antigen | S30: {=IF(OR($E30+1<$E31, AND(ISBLANK($E31), ($E30-1)<COUNT(#REF!))), INDEX('Referral Test Data CRLN'!$C$1:$P83,$E30+1,9),IFERROR(0/0,""))} -> Negative | T30: PCR | U30: Positive | V30: 29 | X30: TRUE | Y30: =AND(OR(EXACT("Antigen",P30),EXACT("Antigen",R30),EXACT("Antigen",T30)),EXACT(J30,"INDIV")) -> TRUE | Z30: NEG | AA30: Partner tested pos by antigen then this partner tested neg by antigen 3 days in a row then next day was FL pos, which was confirmed by PCR collected same day and resulted 2 days later (this was a teacher - so FL screening likely stopped spread!)
D31: =IFERROR(__xludf.DUMMYFUNCTION("""COMPUTED_VALUE"""),"FLMP942437") -> FLMP942437 | E31: {=IFERROR( MATCH(D31, INDIRECT("'Referral Test Data CRLN'!D" & E30 + 1 & ":D"), 0) + E30, MATCH(D31, 'Referral Test Data CRLN'!D31:D83, 0) )} -> 85 | F31: =IF(ISBLANK(E32),COUNTA('Referral Test Data CRLN'!D$2:D83)-SUM(F$2:F30),E32-E31) -> 1 | G31: =IFERROR(VLOOKUP(D31,'ALL Pos and Incl IMPORT'!Q$2:U83,5,FALSE),0) -> 0 | I31: NO FL testing | M31: {=INDEX('Referral Test Data CRLN'!$C$1:$P83,$E31,3)} -> 44697 | N31: =IF(AND(EXACT(P31,"Antigen"),EXACT(Q31,"Negative"),OR(EXACT(S31,"Positive"),EXACT(U31,"Positive"))),TRUE,FALSE) -> FALSE | O31: =Q31 -> Positive | P31: {=INDEX('Referral Test Data CRLN'!$C$1:$P83,$E31,7)} -> Antigen | Q31: {=INDEX('Referral Test Data CRLN'!$C$1:$P83,$E31,9)} -> Positive | R31: {=IF(OR($E31+1<$E32, AND(ISBLANK($E32), ($E31-1)<COUNT(#REF!))), INDEX('Referral Test Data CRLN'!$C$1:$P83,$E31+1,7), IFERROR(0/0,""))} | S31: {=IF(OR($E31+1<$E32, AND(ISBLANK($E32), ($E31-1)<COUNT(#REF!))), INDEX('Referral Test Data CRLN'!$C$1:$P83,$E31+1,9),IFERROR(0/0,""))} | T31: {=IF(OR($E31+2<$E32, AND(ISBLANK($E32), ($E31-1)<COUNT(#REF!))), INDEX('Referral Test Data CRLN'!$C$1:$P83,$E31+2,7),IFERROR(0/0,""))} | U31: {=IF(OR($E31+2<$E32, AND(ISBLANK($E32), ($E31-1)<COUNT(#REF!))), INDEX('Referral Test Data CRLN'!$C$1:$P83,$E31+2,9),IFERROR(0/0,""))} | V31: 30 | X31: TRUE | Y31: =AND(OR(EXACT("Antigen",P31),EXACT("Antigen",R31),EXACT("Antigen",T31)),EXACT(J31,"INDIV")) -> FALSE
D32: =IFERROR(__xludf.DUMMYFUNCTION("""COMPUTED_VALUE"""),"FLMP290315") -> FLMP290315 | E32: {=IFERROR( MATCH(D32, INDIRECT("'Referral Test Data CRLN'!D" & E31 + 1 & ":D"), 0) + E31, MATCH(D32, 'Referral Test Data CRLN'!D32:D83, 0) )} -> 86 | F32: =IF(ISBLANK(E33),COUNTA('Referral Test Data CRLN'!D$2:D83)-SUM(F$2:F31),E33-E32) -> 1 | G32: =IFERROR(VLOOKUP(D32,'ALL Pos and Incl IMPORT'!Q$2:U83,5,FALSE),0) -> 0 | I32: NO FL testing | M32: {=INDEX('Referral Test Data CRLN'!$C$1:$P83,$E32,3)} -> 44697 | N32: =IF(AND(EXACT(P32,"Antigen"),EXACT(Q32,"Negative"),OR(EXACT(S32,"Positive"),EXACT(U32,"Positive"))),TRUE,FALSE) -> FALSE | O32: =Q32 -> Negative | P32: {=INDEX('Referral Test Data CRLN'!$C$1:$P83,$E32,7)} -> Antigen | Q32: {=INDEX('Referral Test Data CRLN'!$C$1:$P83,$E32,9)} -> Negative | R32: {=IF(OR($E32+1<$E33, AND(ISBLANK($E33), ($E32-1)<COUNT(#REF!))), INDEX('Referral Test Data CRLN'!$C$1:$P83,$E32+1,7), IFERROR(0/0,""))} | S32: {=IF(OR($E32+1<$E33, AND(ISBLANK($E33), ($E32-1)<COUNT(#REF!))), INDEX('Referral Test Data CRLN'!$C$1:$P83,$E32+1,9),IFERROR(0/0,""))} | T32: {=IF(OR($E32+2<$E33, AND(ISBLANK($E33), ($E32-1)<COUNT(#REF!))), INDEX('Referral Test Data CRLN'!$C$1:$P83,$E32+2,7),IFERROR(0/0,""))} | U32: {=IF(OR($E32+2<$E33, AND(ISBLANK($E33), ($E32-1)<COUNT(#REF!))), INDEX('Referral Test Data CRLN'!$C$1:$P83,$E32+2,9),IFERROR(0/0,""))} | V32: 31 | X32: TRUE | Y32: =AND(OR(EXACT("Antigen",P32),EXACT("Antigen",R32),EXACT("Antigen",T32)),EXACT(J32,"INDIV")) -> FALSE
Y36: IDs Included | Z36: Count
Z37: 8 | AA37: Number of FloodLAMP Test Person Cases with Referral Antigen Tests
Y38: 10,11,19,29 | Z38: 4 | AA38: Number of FloodLAMP Positive Test Person Cases with Antigen Negative - Agree with Referral Test Positive (usually PCR or later aAntigen) but Initial Antigen Negative
H39: MANUAL is used when the person's name appears more than once in the Positives and Inconclusives list | Y39: 5,12,14,22 | Z39: 4 | AA39: Number of FloodLAMP Positive Test Person Cases with Antigen Positive
H40: Fill in the TubeID manually by matching the date and make cell white | Z40: 0 | AA40: Number of FloodLAMP Positive Test Person Cases confirmed with Referral Tests but Other Non-Antigen Test Negative
H41: Change col I and J formula to use VLOOKUP
C51: MUST CLEAR EXTRA ROWS AT BOTTOM | K51: =IF(G2=1, IFERROR(VLOOKUP(C2, #REF!, 6, FALSE), IFERROR(VLOOKUP(C2, #REF!, 5, FALSE), IFERROR(VLOOKUP(C2, #REF!, 4, FALSE), IFERROR(VLOOKUP(C2, #REF!, 3, FALSE), "error - 1 but not found")))),"LOOKUP") -> error - 1 but not found

Sheet Referral Test Data CRLN
A1: PARTICIPANT FIRSTNAME | B1: PARTICIPANT LASTNAME | C1: PARTICIPANT LASTNAME | D1: PARTICIPANT ID | E1: REFERRAL TEST COLLECTION DATE | F1: REFERRAL TEST COLLECTION TIME | G1: REFERRAL TEST RESULT DATE | H1: REFERRAL TEST RESULT TIME | I1: REFERRAL TEST TYPE | J1: REFERRAL TEST MODEL | K1: REFERRAL TEST RESULT | L1: REFERRAL TEST CT (IF PCR) | M1: SYMPTOMS? | N1: VACCINATED? | O1: NOTES | P1: SOURCE NOTES | Q1: INIT FL POS TUBE ID FROM CASE CLUSTER
D2: FLMP858721 | E2: 44924 | G2: 44924 | I2: Antigen | K2: Positive | Q2: FLT1136
D3: FLMP939793 | E3: 44925 | G3: 44925 | I3: Antigen | K3: Positive | O3: Collection date may have been 12/31/2022 | P3: Positive before FL test, FL test was return testing. (NOT false Neg) | Q3: FLB5852
D4: FLMP172687 | E4: 44925 | G4: 44925 | I4: Antigen | K4: Positive | O4: Collection date may have been 12/31/2022 | Q4: FLB5889
D5: FLMP549529 | E5: 44562 | G5: 44562 | I5: Antigen | K5: Positive | Q5: FLB5830
D6: FLMP915544 | E6: 44564 | G6: 44564 | I6: Antigen | K6: Positive | O6: Uncertainty as to exact collection/result date - stated to be "a few days before 1/6/2022" | Q6: FLB6845
D7: FLMP915544 | E7: 44567 | G7: 44567 | I7: PCR | K7: Positive | Q7: FLB6845
D8: FLMP652238 | E8: 44564 | G8: 44564 | I8: Antigen | K8: Negative | O8: Uncertainty as to exact collection/result date - stated to be "a few days before 1/6/2022" | Q8: FLB6845
D9: FLMP652238 | E9: 44567 | G9: 44567 | I9: PCR | K9: Negative | Q9: FLB6845
D10: FLMP473007 | E10: 44564 | G10: 44564 | I10: Antigen | K10: Positive | O10: Uncertainty as to exact collection/result date - stated to be "a few days before 1/6/2022" | Q10: FLB6845
D11: FLMP473007 | E11: 44567 | G11: 44567 | I11: PCR | K11: Positive | Q11: FLB6845
D12: FLMP776278 | E12: 44565 | G12: 44565 | I12: Antigen | K12: Positive | M12: TRUE | Q12: FLT1433
D13: FLMP776278 | E13: 44568 | G13: 44569 | I13: PCR | K13: Positive | M13: FALSE | Q13: FLT1433
D14: FLMP776278 | E14: 44575 | G14: 44575 | I14: Antigen | K14: Negative | M14: FALSE | Q14: FLT1433
D15: FLMP828735 | E15: 44565 | G15: 44565 | I15: Antigen | K15: Positive | M15: TRUE | Q15: FLT1433
D16: FLMP828735 | E16: 44567 | G16: 44568 | I16: PCR | K16: Positive | M16: FALSE | Q16: FLT1433
D17: FLMP828735 | E17: 44574 | G17: 44574 | I17: Antigen | K17: Negative | M17: FALSE | Q17: FLT1433
D18: FLMP828735 | E18: 44575 | G18: 44575 | I18: Antigen | K18: Negative | M18: FALSE | Q18: FLT1433
D19: FLMP302189 | E19: 44563 | G19: 44563 | I19: Antigen | J19: BinaxNow | K19: Negative | Q19: FLT1433
D20: FLMP302189 | E20: 44564 | G20: 44565 | I20: PCR | K20: Positive | M20: TRUE | Q20: FLT1433
D21: FLMP302189 | E21: 44575 | G21: 44575 | I21: Antigen | K21: Negative | M21: TRUE | Q21: FLT1433
D22: FLMP857562 | E22: 44563 | G22: 44563 | I22: Antigen | J22: BinaxNow | K22: Negative | Q22: FLT1433
D23: FLMP857562 | E23: 44565 | G23: 44568 | I23: PCR | K23: Positive | Q23: FLT1433
D24: FLMP857562 | E24: 44575 | G24: 44575 | I24: Antigen | K24: Negative | Q24: FLT1433
D25: FLMP147333 | E25: 44566 | G25: 44566 | I25: Antigen | J25: BinaxNow | K25: Negative | M25: FALSE | Q25: FLT1465
D26: FLMP147333 | E26: 44568 | G26: 44568 | I26: Antigen | K26: Negative | M26: FALSE | Q26: FLT1465
D27: FLMP147333 | E27: 44570 | G27: 44570 | I27: Antigen | K27: Positive | M27: TRUE | Q27: FLT1465
