Workbook

Sheet ALL Tube Results
A1: =IFERROR(__xludf.DUMMYFUNCTION("QUERY({ 'APS Tubes Import'!A1:A3090; 'ARF Tubes'!M2:M3090 }, ""SELECT Col1 WHERE Col1 IS NOT NULL"", 0)"),"TUBE ID") -> TUBE ID | B1: =IFERROR(__xludf.DUMMYFUNCTION("QUERY({ 'APS Tubes Import'!V1:V3090; 'ARF Tubes'!N2:N3090 }, ""SELECT Col1 WHERE Col1 IS NOT NULL"", 0)"),"FINAL ASSIGNED RUN ID") -> FINAL ASSIGNED RUN ID | C1: ='Run Reconcile'!B1 -> RUN DATE | D1: ='APS Tubes Import'!B1 -> COLLECTION DATE | E1: ='APS Tubes Import'!C1 -> COLLECTION TIME | F1: =IFERROR(__xludf.DUMMYFUNCTION("QUERY({ 'APS Tubes Import'!H1:H3090; 'ARF Tubes'!P2:P3090 }, ""SELECT Col1 WHERE Col1 IS NOT NULL"", 0)"),"FINAL RESULT") -> FINAL RESULT | G1: ='APS Tubes Import'!N1 -> NUM SAMPLES (Pool Level)
A2: =IFERROR(__xludf.DUMMYFUNCTION("""COMPUTED_VALUE"""),"MA124") -> MA124 | B2: =IFERROR(__xludf.DUMMYFUNCTION("""COMPUTED_VALUE"""),"RUN-COMB_2022-03-20_RFR-001") -> RUN-COMB_2022-03-20_RFR-001 | C2: =VLOOKUP(B2,'Run Reconcile'!A$2:B3090,2,FALSE) -> 44640 | D2: =IFERROR(__xludf.DUMMYFUNCTION("QUERY({ 'APS Tubes Import'!B2:B3090 }, ""SELECT Col1 WHERE Col1 IS NOT NULL"", 0)"),44640.0) -> 44640 | E2: =IFERROR(__xludf.DUMMYFUNCTION("QUERY({ 'APS Tubes Import'!C2:C3090; 'ARF Tubes'!P2:P3090 }, ""SELECT Col1 WHERE Col1 IS NOT NULL"", 0)"),0.669537037036207) -> 0.66953704 | F2: =IFERROR(__xludf.DUMMYFUNCTION("""COMPUTED_VALUE"""),"Negative") -> Negative | G2: =IFERROR(__xludf.DUMMYFUNCTION("QUERY({ 'APS Tubes Import'!N2:N3090 }, ""SELECT Col1 WHERE Col1 IS NOT NULL"", 0)"),1.0) -> 1
A3: =IFERROR(__xludf.DUMMYFUNCTION("""COMPUTED_VALUE"""),"MA212") -> MA212 | B3: =IFERROR(__xludf.DUMMYFUNCTION("""COMPUTED_VALUE"""),"RUN-COMB_2022-03-20_RFR-001") -> RUN-COMB_2022-03-20_RFR-001 | C3: =VLOOKUP(B3,'Run Reconcile'!A$2:B3090,2,FALSE) -> 44640 | D3: =IFERROR(__xludf.DUMMYFUNCTION("""COMPUTED_VALUE"""),44640.0) -> 44640 | E3: =IFERROR(__xludf.DUMMYFUNCTION("""COMPUTED_VALUE"""),0.6711689814801503) -> 0.67116898 | F3: =IFERROR(__xludf.DUMMYFUNCTION("""COMPUTED_VALUE"""),"Negative") -> Negative | G3: =IFERROR(__xludf.DUMMYFUNCTION("""COMPUTED_VALUE"""),1.0) -> 1
A4: =IFERROR(__xludf.DUMMYFUNCTION("""COMPUTED_VALUE"""),"MA145") -> MA145 | B4: =IFERROR(__xludf.DUMMYFUNCTION("""COMPUTED_VALUE"""),"RUN-COMB_2022-03-20_RFR-001") -> RUN-COMB_2022-03-20_RFR-001 | C4: =VLOOKUP(B4,'Run Reconcile'!A$2:B3090,2,FALSE) -> 44640 | D4: =IFERROR(__xludf.DUMMYFUNCTION("""COMPUTED_VALUE"""),44640.0) -> 44640 | E4: =IFERROR(__xludf.DUMMYFUNCTION("""COMPUTED_VALUE"""),0.677280092593719) -> 0.67728009 | F4: =IFERROR(__xludf.DUMMYFUNCTION("""COMPUTED_VALUE"""),"Negative") -> Negative | G4: =IFERROR(__xludf.DUMMYFUNCTION("""COMPUTED_VALUE"""),1.0) -> 1
A5: =IFERROR(__xludf.DUMMYFUNCTION("""COMPUTED_VALUE"""),"MA61") -> MA61 | B5: =IFERROR(__xludf.DUMMYFUNCTION("""COMPUTED_VALUE"""),"RUN-COMB_2022-03-20_RFR-001") -> RUN-COMB_2022-03-20_RFR-001 | C5: =VLOOKUP(B5,'Run Reconcile'!A$2:B3090,2,FALSE) -> 44640 | D5: =IFERROR(__xludf.DUMMYFUNCTION("""COMPUTED_VALUE"""),44640.0) -> 44640 | E5: =IFERROR(__xludf.DUMMYFUNCTION("""COMPUTED_VALUE"""),0.6777893518519704) -> 0.67778935 | F5: =IFERROR(__xludf.DUMMYFUNCTION("""COMPUTED_VALUE"""),"Negative") -> Negative | G5: =IFERROR(__xludf.DUMMYFUNCTION("""COMPUTED_VALUE"""),1.0) -> 1
A6: =IFERROR(__xludf.DUMMYFUNCTION("""COMPUTED_VALUE"""),"MA236") -> MA236 | B6: =IFERROR(__xludf.DUMMYFUNCTION("""COMPUTED_VALUE"""),"RUN-COMB_2022-03-20_RFR-001") -> RUN-COMB_2022-03-20_RFR-001 | C6: =VLOOKUP(B6,'Run Reconcile'!A$2:B3090,2,FALSE) -> 44640 | D6: =IFERROR(__xludf.DUMMYFUNCTION("""COMPUTED_VALUE"""),44640.0) -> 44640 | E6: =IFERROR(__xludf.DUMMYFUNCTION("""COMPUTED_VALUE"""),0.6791898148148903) -> 0.67918981 | F6: =IFERROR(__xludf.DUMMYFUNCTION("""COMPUTED_VALUE"""),"Negative") -> Negative | G6: =IFERROR(__xludf.DUMMYFUNCTION("""COMPUTED_VALUE"""),1.0) -> 1
A7: =IFERROR(__xludf.DUMMYFUNCTION("""COMPUTED_VALUE"""),"MA232") -> MA232 | B7: =IFERROR(__xludf.DUMMYFUNCTION("""COMPUTED_VALUE"""),"RUN-COMB_2022-03-20_RFR-001") -> RUN-COMB_2022-03-20_RFR-001 | C7: =VLOOKUP(B7,'Run Reconcile'!A$2:B3090,2,FALSE) -> 44640 | D7: =IFERROR(__xludf.DUMMYFUNCTION("""COMPUTED_VALUE"""),44640.0) -> 44640 | E7: =IFERROR(__xludf.DUMMYFUNCTION("""COMPUTED_VALUE"""),0.6806250000008731) -> 0.680625 | F7: =IFERROR(__xludf.DUMMYFUNCTION("""COMPUTED_VALUE"""),"Negative") -> Negative | G7: =IFERROR(__xludf.DUMMYFUNCTION("""COMPUTED_VALUE"""),1.0) -> 1
A8: =IFERROR(__xludf.DUMMYFUNCTION("""COMPUTED_VALUE"""),"MA138") -> MA138 | B8: =IFERROR(__xludf.DUMMYFUNCTION("""COMPUTED_VALUE"""),"RUN-COMB_2022-03-20_RFR-001") -> RUN-COMB_2022-03-20_RFR-001 | C8: =VLOOKUP(B8,'Run Reconcile'!A$2:B3090,2,FALSE) -> 44640 | D8: =IFERROR(__xludf.DUMMYFUNCTION("""COMPUTED_VALUE"""),44640.0) -> 44640 | E8: =IFERROR(__xludf.DUMMYFUNCTION("""COMPUTED_VALUE"""),0.682129629629344) -> 0.68212963 | F8: =IFERROR(__xludf.DUMMYFUNCTION("""COMPUTED_VALUE"""),"Negative") -> Negative | G8: =IFERROR(__xludf.DUMMYFUNCTION("""COMPUTED_VALUE"""),1.0) -> 1
A9: =IFERROR(__xludf.DUMMYFUNCTION("""COMPUTED_VALUE"""),"MA73") -> MA73 | B9: =IFERROR(__xludf.DUMMYFUNCTION("""COMPUTED_VALUE"""),"RUN-COMB_2022-03-20_RFR-001") -> RUN-COMB_2022-03-20_RFR-001 | C9: =VLOOKUP(B9,'Run Reconcile'!A$2:B3090,2,FALSE) -> 44640 | D9: =IFERROR(__xludf.DUMMYFUNCTION("""COMPUTED_VALUE"""),44640.0) -> 44640 | E9: =IFERROR(__xludf.DUMMYFUNCTION("""COMPUTED_VALUE"""),0.684953703705105) -> 0.6849537 | F9: =IFERROR(__xludf.DUMMYFUNCTION("""COMPUTED_VALUE"""),"Negative") -> Negative | G9: =IFERROR(__xludf.DUMMYFUNCTION("""COMPUTED_VALUE"""),1.0) -> 1
A10: =IFERROR(__xludf.DUMMYFUNCTION("""COMPUTED_VALUE"""),"MA147") -> MA147 | B10: =IFERROR(__xludf.DUMMYFUNCTION("""COMPUTED_VALUE"""),"RUN-COMB_2022-03-20_RFR-001") -> RUN-COMB_2022-03-20_RFR-001 | C10: =VLOOKUP(B10,'Run Reconcile'!A$2:B3090,2,FALSE) -> 44640 | D10: =IFERROR(__xludf.DUMMYFUNCTION("""COMPUTED_VALUE"""),44640.0) -> 44640 | E10: =IFERROR(__xludf.DUMMYFUNCTION("""COMPUTED_VALUE"""),0.6864004629642295) -> 0.68640046 | F10: =IFERROR(__xludf.DUMMYFUNCTION("""COMPUTED_VALUE"""),"Negative") -> Negative | G10: =IFERROR(__xludf.DUMMYFUNCTION("""COMPUTED_VALUE"""),1.0) -> 1
A11: =IFERROR(__xludf.DUMMYFUNCTION("""COMPUTED_VALUE"""),"MA160") -> MA160 | B11: =IFERROR(__xludf.DUMMYFUNCTION("""COMPUTED_VALUE"""),"RUN-COMB_2022-03-20_RFR-001") -> RUN-COMB_2022-03-20_RFR-001 | C11: =VLOOKUP(B11,'Run Reconcile'!A$2:B3090,2,FALSE) -> 44640 | D11: =IFERROR(__xludf.DUMMYFUNCTION("""COMPUTED_VALUE"""),44640.0) -> 44640 | E11: =IFERROR(__xludf.DUMMYFUNCTION("""COMPUTED_VALUE"""),0.6880208333350311) -> 0.68802083 | F11: =IFERROR(__xludf.DUMMYFUNCTION("""COMPUTED_VALUE"""),"Negative") -> Negative | G11: =IFERROR(__xludf.DUMMYFUNCTION("""COMPUTED_VALUE"""),1.0) -> 1
A12: =IFERROR(__xludf.DUMMYFUNCTION("""COMPUTED_VALUE"""),"MA179") -> MA179 | B12: =IFERROR(__xludf.DUMMYFUNCTION("""COMPUTED_VALUE"""),"RUN-COMB_2022-03-20_RFR-001") -> RUN-COMB_2022-03-20_RFR-001 | C12: =VLOOKUP(B12,'Run Reconcile'!A$2:B3090,2,FALSE) -> 44640 | D12: =IFERROR(__xludf.DUMMYFUNCTION("""COMPUTED_VALUE"""),44640.0) -> 44640 | E12: =IFERROR(__xludf.DUMMYFUNCTION("""COMPUTED_VALUE"""),0.6901273148141627) -> 0.69012731 | F12: =IFERROR(__xludf.DUMMYFUNCTION("""COMPUTED_VALUE"""),"Negative") -> Negative | G12: =IFERROR(__xludf.DUMMYFUNCTION("""COMPUTED_VALUE"""),1.0) -> 1
A13: =IFERROR(__xludf.DUMMYFUNCTION("""COMPUTED_VALUE"""),"MA149") -> MA149 | B13: =IFERROR(__xludf.DUMMYFUNCTION("""COMPUTED_VALUE"""),"RUN-COMB_2022-03-20_RFR-001") -> RUN-COMB_2022-03-20_RFR-001 | C13: =VLOOKUP(B13,'Run Reconcile'!A$2:B3090,2,FALSE) -> 44640 | D13: =IFERROR(__xludf.DUMMYFUNCTION("""COMPUTED_VALUE"""),44640.0) -> 44640 | E13: =IFERROR(__xludf.DUMMYFUNCTION("""COMPUTED_VALUE"""),0.6930671296286164) -> 0.69306713 | F13: =IFERROR(__xludf.DUMMYFUNCTION("""COMPUTED_VALUE"""),"Negative") -> Negative | G13: =IFERROR(__xludf.DUMMYFUNCTION("""COMPUTED_VALUE"""),1.0) -> 1
A14: =IFERROR(__xludf.DUMMYFUNCTION("""COMPUTED_VALUE"""),"MA126") -> MA126 | B14: =IFERROR(__xludf.DUMMYFUNCTION("""COMPUTED_VALUE"""),"RUN-COMB_2022-03-20_RFR-001") -> RUN-COMB_2022-03-20_RFR-001 | C14: =VLOOKUP(B14,'Run Reconcile'!A$2:B3090,2,FALSE) -> 44640 | D14: =IFERROR(__xludf.DUMMYFUNCTION("""COMPUTED_VALUE"""),44640.0) -> 44640 | E14: =IFERROR(__xludf.DUMMYFUNCTION("""COMPUTED_VALUE"""),0.6937962962947495) -> 0.6937963 | F14: =IFERROR(__xludf.DUMMYFUNCTION("""COMPUTED_VALUE"""),"Negative") -> Negative | G14: =IFERROR(__xludf.DUMMYFUNCTION("""COMPUTED_VALUE"""),1.0) -> 1
A15: =IFERROR(__xludf.DUMMYFUNCTION("""COMPUTED_VALUE"""),"MA137") -> MA137 | B15: =IFERROR(__xludf.DUMMYFUNCTION("""COMPUTED_VALUE"""),"RUN-COMB_2022-03-20_RFR-001") -> RUN-COMB_2022-03-20_RFR-001 | C15: =VLOOKUP(B15,'Run Reconcile'!A$2:B3090,2,FALSE) -> 44640 | D15: =IFERROR(__xludf.DUMMYFUNCTION("""COMPUTED_VALUE"""),44640.0) -> 44640 | E15: =IFERROR(__xludf.DUMMYFUNCTION("""COMPUTED_VALUE"""),0.695243055553874) -> 0.69524306 | F15: =IFERROR(__xludf.DUMMYFUNCTION("""COMPUTED_VALUE"""),"Negative") -> Negative | G15: =IFERROR(__xludf.DUMMYFUNCTION("""COMPUTED_VALUE"""),1.0) -> 1
A16: =IFERROR(__xludf.DUMMYFUNCTION("""COMPUTED_VALUE"""),"MA161") -> MA161 | B16: =IFERROR(__xludf.DUMMYFUNCTION("""COMPUTED_VALUE"""),"RUN-COMB_2022-03-20_RFR-001") -> RUN-COMB_2022-03-20_RFR-001 | C16: =VLOOKUP(B16,'Run Reconcile'!A$2:B3090,2,FALSE) -> 44640 | D16: =IFERROR(__xludf.DUMMYFUNCTION("""COMPUTED_VALUE"""),44640.0) -> 44640 | E16: =IFERROR(__xludf.DUMMYFUNCTION("""COMPUTED_VALUE"""),0.6975115740751789) -> 0.69751157 | F16: =IFERROR(__xludf.DUMMYFUNCTION("""COMPUTED_VALUE"""),"Negative") -> Negative | G16: =IFERROR(__xludf.DUMMYFUNCTION("""COMPUTED_VALUE"""),1.0) -> 1
A17: =IFERROR(__xludf.DUMMYFUNCTION("""COMPUTED_VALUE"""),"MA121") -> MA121 | B17: =IFERROR(__xludf.DUMMYFUNCTION("""COMPUTED_VALUE"""),"RUN-COMB_2022-03-20_RFR-001") -> RUN-COMB_2022-03-20_RFR-001 | C17: =VLOOKUP(B17,'Run Reconcile'!A$2:B3090,2,FALSE) -> 44640 | D17: =IFERROR(__xludf.DUMMYFUNCTION("""COMPUTED_VALUE"""),44640.0) -> 44640 | E17: =IFERROR(__xludf.DUMMYFUNCTION("""COMPUTED_VALUE"""),0.7017476851870015) -> 0.70174769 | F17: =IFERROR(__xludf.DUMMYFUNCTION("""COMPUTED_VALUE"""),"Negative") -> Negative | G17: =IFERROR(__xludf.DUMMYFUNCTION("""COMPUTED_VALUE"""),1.0) -> 1
A18: =IFERROR(__xludf.DUMMYFUNCTION("""COMPUTED_VALUE"""),"MA188") -> MA188 | B18: =IFERROR(__xludf.DUMMYFUNCTION("""COMPUTED_VALUE"""),"RUN-COMB_2022-03-20_RFR-001") -> RUN-COMB_2022-03-20_RFR-001 | C18: =VLOOKUP(B18,'Run Reconcile'!A$2:B3090,2,FALSE) -> 44640 | D18: =IFERROR(__xludf.DUMMYFUNCTION("""COMPUTED_VALUE"""),44640.0) -> 44640 | E18: =IFERROR(__xludf.DUMMYFUNCTION("""COMPUTED_VALUE"""),0.7490277777760639) -> 0.74902778 | F18: =IFERROR(__xludf.DUMMYFUNCTION("""COMPUTED_VALUE"""),"Negative") -> Negative | G18: =IFERROR(__xludf.DUMMYFUNCTION("""COMPUTED_VALUE"""),1.0) -> 1
A19: =IFERROR(__xludf.DUMMYFUNCTION("""COMPUTED_VALUE"""),"MA127") -> MA127 | B19: =IFERROR(__xludf.DUMMYFUNCTION("""COMPUTED_VALUE"""),"RUN-COMB_2022-03-20_RFR-001") -> RUN-COMB_2022-03-20_RFR-001 | C19: =VLOOKUP(B19,'Run Reconcile'!A$2:B3090,2,FALSE) -> 44640 | D19: =IFERROR(__xludf.DUMMYFUNCTION("""COMPUTED_VALUE"""),44640.0) -> 44640 | E19: =IFERROR(__xludf.DUMMYFUNCTION("""COMPUTED_VALUE"""),0.7511921296281798) -> 0.75119213 | F19: =IFERROR(__xludf.DUMMYFUNCTION("""COMPUTED_VALUE"""),"Negative") -> Negative | G19: =IFERROR(__xludf.DUMMYFUNCTION("""COMPUTED_VALUE"""),1.0) -> 1
A20: =IFERROR(__xludf.DUMMYFUNCTION("""COMPUTED_VALUE"""),"MA220A") -> MA220A | B20: =IFERROR(__xludf.DUMMYFUNCTION("""COMPUTED_VALUE"""),"RUN-COMB_2022-03-21_RFR-002") -> RUN-COMB_2022-03-21_RFR-002 | C20: =VLOOKUP(B20,'Run Reconcile'!A$2:B3090,2,FALSE) -> 44641 | D20: =IFERROR(__xludf.DUMMYFUNCTION("""COMPUTED_VALUE"""),44641.0) -> 44641 | E20: =IFERROR(__xludf.DUMMYFUNCTION("""COMPUTED_VALUE"""),0.2567939814798592) -> 0.25679398 | F20: =IFERROR(__xludf.DUMMYFUNCTION("""COMPUTED_VALUE"""),"Negative") -> Negative | G20: =IFERROR(__xludf.DUMMYFUNCTION("""COMPUTED_VALUE"""),1.0) -> 1
A21: =IFERROR(__xludf.DUMMYFUNCTION("""COMPUTED_VALUE"""),"MA220") -> MA220 | B21: =IFERROR(__xludf.DUMMYFUNCTION("""COMPUTED_VALUE"""),"RUN-COMB_2022-03-21_RFR-002") -> RUN-COMB_2022-03-21_RFR-002 | C21: =VLOOKUP(B21,'Run Reconcile'!A$2:B3090,2,FALSE) -> 44641 | D21: =IFERROR(__xludf.DUMMYFUNCTION("""COMPUTED_VALUE"""),44641.0) -> 44641 | E21: =IFERROR(__xludf.DUMMYFUNCTION("""COMPUTED_VALUE"""),0.2574884259265673) -> 0.25748843 | F21: =IFERROR(__xludf.DUMMYFUNCTION("""COMPUTED_VALUE"""),"Negative") -> Negative | G21: =IFERROR(__xludf.DUMMYFUNCTION("""COMPUTED_VALUE"""),1.0) -> 1
A22: =IFERROR(__xludf.DUMMYFUNCTION("""COMPUTED_VALUE"""),"MA208") -> MA208 | B22: =IFERROR(__xludf.DUMMYFUNCTION("""COMPUTED_VALUE"""),"RUN-COMB_2022-03-21_RFR-002") -> RUN-COMB_2022-03-21_RFR-002 | C22: =VLOOKUP(B22,'Run Reconcile'!A$2:B3090,2,FALSE) -> 44641 | D22: =IFERROR(__xludf.DUMMYFUNCTION("""COMPUTED_VALUE"""),44641.0) -> 44641 | E22: =IFERROR(__xludf.DUMMYFUNCTION("""COMPUTED_VALUE"""),0.25802083333474) -> 0.25802083 | F22: =IFERROR(__xludf.DUMMYFUNCTION("""COMPUTED_VALUE"""),"Negative") -> Negative | G22: =IFERROR(__xludf.DUMMYFUNCTION("""COMPUTED_VALUE"""),1.0) -> 1
A23: =IFERROR(__xludf.DUMMYFUNCTION("""COMPUTED_VALUE"""),"MA89") -> MA89 | B23: =IFERROR(__xludf.DUMMYFUNCTION("""COMPUTED_VALUE"""),"RUN-COMB_2022-03-21_RFR-002") -> RUN-COMB_2022-03-21_RFR-002 | C23: =VLOOKUP(B23,'Run Reconcile'!A$2:B3090,2,FALSE) -> 44641 | D23: =IFERROR(__xludf.DUMMYFUNCTION("""COMPUTED_VALUE"""),44641.0) -> 44641 | E23: =IFERROR(__xludf.DUMMYFUNCTION("""COMPUTED_VALUE"""),0.26012731481387164) -> 0.26012731 | F23: =IFERROR(__xludf.DUMMYFUNCTION("""COMPUTED_VALUE"""),"Negative") -> Negative | G23: =IFERROR(__xludf.DUMMYFUNCTION("""COMPUTED_VALUE"""),1.0) -> 1
A24: =IFERROR(__xludf.DUMMYFUNCTION("""COMPUTED_VALUE"""),"MA26") -> MA26 | B24: =IFERROR(__xludf.DUMMYFUNCTION("""COMPUTED_VALUE"""),"RUN-COMB_2022-03-21_RFR-002") -> RUN-COMB_2022-03-21_RFR-002 | C24: =VLOOKUP(B24,'Run Reconcile'!A$2:B3090,2,FALSE) -> 44641 | D24: =IFERROR(__xludf.DUMMYFUNCTION("""COMPUTED_VALUE"""),44641.0) -> 44641 | E24: =IFERROR(__xludf.DUMMYFUNCTION("""COMPUTED_VALUE"""),0.26103009259168175) -> 0.26103009 | F24: =IFERROR(__xludf.DUMMYFUNCTION("""COMPUTED_VALUE"""),"Negative") -> Negative | G24: =IFERROR(__xludf.DUMMYFUNCTION("""COMPUTED_VALUE"""),1.0) -> 1
A25: =IFERROR(__xludf.DUMMYFUNCTION("""COMPUTED_VALUE"""),"MA109") -> MA109 | B25: =IFERROR(__xludf.DUMMYFUNCTION("""COMPUTED_VALUE"""),"RUN-COMB_2022-03-21_RFR-002") -> RUN-COMB_2022-03-21_RFR-002 | C25: =VLOOKUP(B25,'Run Reconcile'!A$2:B3090,2,FALSE) -> 44641 | D25: =IFERROR(__xludf.DUMMYFUNCTION("""COMPUTED_VALUE"""),44641.0) -> 44641 | E25: =IFERROR(__xludf.DUMMYFUNCTION("""COMPUTED_VALUE"""),0.263043981482042) -> 0.26304398 | F25: =IFERROR(__xludf.DUMMYFUNCTION("""COMPUTED_VALUE"""),"Negative") -> Negative | G25: =IFERROR(__xludf.DUMMYFUNCTION("""COMPUTED_VALUE"""),1.0) -> 1
A26: =IFERROR(__xludf.DUMMYFUNCTION("""COMPUTED_VALUE"""),"MA134") -> MA134 | B26: =IFERROR(__xludf.DUMMYFUNCTION("""COMPUTED_VALUE"""),"RUN-COMB_2022-03-21_RFR-002") -> RUN-COMB_2022-03-21_RFR-002 | C26: =VLOOKUP(B26,'Run Reconcile'!A$2:B3090,2,FALSE) -> 44641 | D26: =IFERROR(__xludf.DUMMYFUNCTION("""COMPUTED_VALUE"""),44641.0) -> 44641 | E26: =IFERROR(__xludf.DUMMYFUNCTION("""COMPUTED_VALUE"""),0.2639814814829151) -> 0.26398148 | F26: =IFERROR(__xludf.DUMMYFUNCTION("""COMPUTED_VALUE"""),"Negative") -> Negative | G26: =IFERROR(__xludf.DUMMYFUNCTION("""COMPUTED_VALUE"""),1.0) -> 1
A27: =IFERROR(__xludf.DUMMYFUNCTION("""COMPUTED_VALUE"""),"MA168") -> MA168 | B27: =IFERROR(__xludf.DUMMYFUNCTION("""COMPUTED_VALUE"""),"RUN-COMB_2022-03-21_RFR-002") -> RUN-COMB_2022-03-21_RFR-002 | C27: =VLOOKUP(B27,'Run Reconcile'!A$2:B3090,2,FALSE) -> 44641 | D27: =IFERROR(__xludf.DUMMYFUNCTION("""COMPUTED_VALUE"""),44641.0) -> 44641 | E27: =IFERROR(__xludf.DUMMYFUNCTION("""COMPUTED_VALUE"""),0.2649421296300716) -> 0.26494213 | F27: =IFERROR(__xludf.DUMMYFUNCTION("""COMPUTED_VALUE"""),"Negative") -> Negative | G27: =IFERROR(__xludf.DUMMYFUNCTION("""COMPUTED_VALUE"""),1.0) -> 1
A28: =IFERROR(__xludf.DUMMYFUNCTION("""COMPUTED_VALUE"""),"MA148") -> MA148 | B28: =IFERROR(__xludf.DUMMYFUNCTION("""COMPUTED_VALUE"""),"RUN-COMB_2022-03-21_RFR-002") -> RUN-COMB_2022-03-21_RFR-002 | C28: =VLOOKUP(B28,'Run Reconcile'!A$2:B3090,2,FALSE) -> 44641 | D28: =IFERROR(__xludf.DUMMYFUNCTION("""COMPUTED_VALUE"""),44641.0) -> 44641 | E28: =IFERROR(__xludf.DUMMYFUNCTION("""COMPUTED_VALUE"""),0.2669097222205892) -> 0.26690972 | F28: =IFERROR(__xludf.DUMMYFUNCTION("""COMPUTED_VALUE"""),"Negative") -> Negative | G28: =IFERROR(__xludf.DUMMYFUNCTION("""COMPUTED_VALUE"""),1.0) -> 1
A29: =IFERROR(__xludf.DUMMYFUNCTION("""COMPUTED_VALUE"""),"MA140") -> MA140 | B29: =IFERROR(__xludf.DUMMYFUNCTION("""COMPUTED_VALUE"""),"RUN-COMB_2022-03-21_RFR-002") -> RUN-COMB_2022-03-21_RFR-002 | C29: =VLOOKUP(B29,'Run Reconcile'!A$2:B3090,2,FALSE) -> 44641 | D29: =IFERROR(__xludf.DUMMYFUNCTION("""COMPUTED_VALUE"""),44641.0) -> 44641 | E29: =IFERROR(__xludf.DUMMYFUNCTION("""COMPUTED_VALUE"""),0.26829861111036735) -> 0.26829861 | F29: =IFERROR(__xludf.DUMMYFUNCTION("""COMPUTED_VALUE"""),"Negative") -> Negative | G29: =IFERROR(__xludf.DUMMYFUNCTION("""COMPUTED_VALUE"""),1.0) -> 1
A30: =IFERROR(__xludf.DUMMYFUNCTION("""COMPUTED_VALUE"""),"MA183") -> MA183 | B30: =IFERROR(__xludf.DUMMYFUNCTION("""COMPUTED_VALUE"""),"RUN-COMB_2022-03-21_RFR-002") -> RUN-COMB_2022-03-21_RFR-002 | C30: =VLOOKUP(B30,'Run Reconcile'!A$2:B3090,2,FALSE) -> 44641 | D30: =IFERROR(__xludf.DUMMYFUNCTION("""COMPUTED_VALUE"""),44641.0) -> 44641 | E30: =IFERROR(__xludf.DUMMYFUNCTION("""COMPUTED_VALUE"""),0.26921296296131914) -> 0.26921296 | F30: =IFERROR(__xludf.DUMMYFUNCTION("""COMPUTED_VALUE"""),"Negative") -> Negative | G30: =IFERROR(__xludf.DUMMYFUNCTION("""COMPUTED_VALUE"""),1.0) -> 1
A31: =IFERROR(__xludf.DUMMYFUNCTION("""COMPUTED_VALUE"""),"MA81") -> MA81 | B31: =IFERROR(__xludf.DUMMYFUNCTION("""COMPUTED_VALUE"""),"RUN-COMB_2022-03-21_RFR-002") -> RUN-COMB_2022-03-21_RFR-002 | C31: =VLOOKUP(B31,'Run Reconcile'!A$2:B3090,2,FALSE) -> 44641 | D31: =IFERROR(__xludf.DUMMYFUNCTION("""COMPUTED_VALUE"""),44641.0) -> 44641 | E31: =IFERROR(__xludf.DUMMYFUNCTION("""COMPUTED_VALUE"""),0.27039351851999527) -> 0.27039352 | F31: =IFERROR(__xludf.DUMMYFUNCTION("""COMPUTED_VALUE"""),"Negative") -> Negative | G31: =IFERROR(__xludf.DUMMYFUNCTION("""COMPUTED_VALUE"""),1.0) -> 1
A32: =IFERROR(__xludf.DUMMYFUNCTION("""COMPUTED_VALUE"""),"MA159") -> MA159 | B32: =IFERROR(__xludf.DUMMYFUNCTION("""COMPUTED_VALUE"""),"RUN-COMB_2022-03-21_RFR-002") -> RUN-COMB_2022-03-21_RFR-002 | C32: =VLOOKUP(B32,'Run Reconcile'!A$2:B3090,2,FALSE) -> 44641 | D32: =IFERROR(__xludf.DUMMYFUNCTION("""COMPUTED_VALUE"""),44641.0) -> 44641 | E32: =IFERROR(__xludf.DUMMYFUNCTION("""COMPUTED_VALUE"""),0.2714351851864194) -> 0.27143519 | F32: =IFERROR(__xludf.DUMMYFUNCTION("""COMPUTED_VALUE"""),"Negative") -> Negative | G32: =IFERROR(__xludf.DUMMYFUNCTION("""COMPUTED_VALUE"""),1.0) -> 1
A33: =IFERROR(__xludf.DUMMYFUNCTION("""COMPUTED_VALUE"""),"MA93") -> MA93 | B33: =IFERROR(__xludf.DUMMYFUNCTION("""COMPUTED_VALUE"""),"RUN-COMB_2022-03-21_RFR-002") -> RUN-COMB_2022-03-21_RFR-002 | C33: =VLOOKUP(B33,'Run Reconcile'!A$2:B3090,2,FALSE) -> 44641 | D33: =IFERROR(__xludf.DUMMYFUNCTION("""COMPUTED_VALUE"""),44641.0) -> 44641 | E33: =IFERROR(__xludf.DUMMYFUNCTION("""COMPUTED_VALUE"""),0.2725578703721112) -> 0.27255787 | F33: =IFERROR(__xludf.DUMMYFUNCTION("""COMPUTED_VALUE"""),"Negative") -> Negative | G33: =IFERROR(__xludf.DUMMYFUNCTION("""COMPUTED_VALUE"""),1.0) -> 1
A34: =IFERROR(__xludf.DUMMYFUNCTION("""COMPUTED_VALUE"""),"MA153") -> MA153 | B34: =IFERROR(__xludf.DUMMYFUNCTION("""COMPUTED_VALUE"""),"RUN-COMB_2022-03-21_RFR-002") -> RUN-COMB_2022-03-21_RFR-002 | C34: =VLOOKUP(B34,'Run Reconcile'!A$2:B3090,2,FALSE) -> 44641 | D34: =IFERROR(__xludf.DUMMYFUNCTION("""COMPUTED_VALUE"""),44641.0) -> 44641 | E34: =IFERROR(__xludf.DUMMYFUNCTION("""COMPUTED_VALUE"""),0.27534722222117125) -> 0.27534722 | F34: =IFERROR(__xludf.DUMMYFUNCTION("""COMPUTED_VALUE"""),"Negative") -> Negative | G34: =IFERROR(__xludf.DUMMYFUNCTION("""COMPUTED_VALUE"""),1.0) -> 1
A35: =IFERROR(__xludf.DUMMYFUNCTION("""COMPUTED_VALUE"""),"MA105") -> MA105 | B35: =IFERROR(__xludf.DUMMYFUNCTION("""COMPUTED_VALUE"""),"RUN-COMB_2022-03-21_RFR-002") -> RUN-COMB_2022-03-21_RFR-002 | C35: =VLOOKUP(B35,'Run Reconcile'!A$2:B3090,2,FALSE) -> 44641 | D35: =IFERROR(__xludf.DUMMYFUNCTION("""COMPUTED_VALUE"""),44641.0) -> 44641 | E35: =IFERROR(__xludf.DUMMYFUNCTION("""COMPUTED_VALUE"""),0.2763078703719657) -> 0.27630787 | F35: =IFERROR(__xludf.DUMMYFUNCTION("""COMPUTED_VALUE"""),"Negative") -> Negative | G35: =IFERROR(__xludf.DUMMYFUNCTION("""COMPUTED_VALUE"""),1.0) -> 1
A36: =IFERROR(__xludf.DUMMYFUNCTION("""COMPUTED_VALUE"""),"MA200") -> MA200 | B36: =IFERROR(__xludf.DUMMYFUNCTION("""COMPUTED_VALUE"""),"RUN-COMB_2022-03-21_RFR-002") -> RUN-COMB_2022-03-21_RFR-002 | C36: =VLOOKUP(B36,'Run Reconcile'!A$2:B3090,2,FALSE) -> 44641 | D36: =IFERROR(__xludf.DUMMYFUNCTION("""COMPUTED_VALUE"""),44641.0) -> 44641 | E36: =IFERROR(__xludf.DUMMYFUNCTION("""COMPUTED_VALUE"""),0.2772800925922638) -> 0.27728009 | F36: =IFERROR(__xludf.DUMMYFUNCTION("""COMPUTED_VALUE"""),"Negative") -> Negative | G36: =IFERROR(__xludf.DUMMYFUNCTION("""COMPUTED_VALUE"""),1.0) -> 1
A37: =IFERROR(__xludf.DUMMYFUNCTION("""COMPUTED_VALUE"""),"MA199") -> MA199 | B37: =IFERROR(__xludf.DUMMYFUNCTION("""COMPUTED_VALUE"""),"RUN-COMB_2022-03-21_RFR-002") -> RUN-COMB_2022-03-21_RFR-002 | C37: =VLOOKUP(B37,'Run Reconcile'!A$2:B3090,2,FALSE) -> 44641 | D37: =IFERROR(__xludf.DUMMYFUNCTION("""COMPUTED_VALUE"""),44641.0) -> 44641 | E37: =IFERROR(__xludf.DUMMYFUNCTION("""COMPUTED_VALUE"""),0.27901620370539604) -> 0.2790162 | F37: =IFERROR(__xludf.DUMMYFUNCTION("""COMPUTED_VALUE"""),"Positive") -> Positive | G37: =IFERROR(__xludf.DUMMYFUNCTION("""COMPUTED_VALUE"""),1.0) -> 1
A38: =IFERROR(__xludf.DUMMYFUNCTION("""COMPUTED_VALUE"""),"MA131") -> MA131 | B38: =IFERROR(__xludf.DUMMYFUNCTION("""COMPUTED_VALUE"""),"RUN-COMB_2022-03-21_RFR-002") -> RUN-COMB_2022-03-21_RFR-002 | C38: =VLOOKUP(B38,'Run Reconcile'!A$2:B3090,2,FALSE) -> 44641 | D38: =IFERROR(__xludf.DUMMYFUNCTION("""COMPUTED_VALUE"""),44641.0) -> 44641 | E38: =IFERROR(__xludf.DUMMYFUNCTION("""COMPUTED_VALUE"""),0.2806018518531346) -> 0.28060185 | F38: =IFERROR(__xludf.DUMMYFUNCTION("""COMPUTED_VALUE"""),"Negative") -> Negative | G38: =IFERROR(__xludf.DUMMYFUNCTION("""COMPUTED_VALUE"""),1.0) -> 1
A39: =IFERROR(__xludf.DUMMYFUNCTION("""COMPUTED_VALUE"""),"MA133") -> MA133 | B39: =IFERROR(__xludf.DUMMYFUNCTION("""COMPUTED_VALUE"""),"RUN-COMB_2022-03-21_RFR-002") -> RUN-COMB_2022-03-21_RFR-002 | C39: =VLOOKUP(B39,'Run Reconcile'!A$2:B3090,2,FALSE) -> 44641 | D39: =IFERROR(__xludf.DUMMYFUNCTION("""COMPUTED_VALUE"""),44641.0) -> 44641 | E39: =IFERROR(__xludf.DUMMYFUNCTION("""COMPUTED_VALUE"""),0.2829282407401479) -> 0.28292824 | F39: =IFERROR(__xludf.DUMMYFUNCTION("""COMPUTED_VALUE"""),"Negative") -> Negative | G39: =IFERROR(__xludf.DUMMYFUNCTION("""COMPUTED_VALUE"""),1.0) -> 1
A40: =IFERROR(__xludf.DUMMYFUNCTION("""COMPUTED_VALUE"""),"MA167") -> MA167 | B40: =IFERROR(__xludf.DUMMYFUNCTION("""COMPUTED_VALUE"""),"RUN-COMB_2022-03-21_RFR-002") -> RUN-COMB_2022-03-21_RFR-002 | C40: =VLOOKUP(B40,'Run Reconcile'!A$2:B3090,2,FALSE) -> 44641 | D40: =IFERROR(__xludf.DUMMYFUNCTION("""COMPUTED_VALUE"""),44641.0) -> 44641 | E40: =IFERROR(__xludf.DUMMYFUNCTION("""COMPUTED_VALUE"""),0.28432870370306773) -> 0.2843287 | F40: =IFERROR(__xludf.DUMMYFUNCTION("""COMPUTED_VALUE"""),"Negative") -> Negative | G40: =IFERROR(__xludf.DUMMYFUNCTION("""COMPUTED_VALUE"""),1.0) -> 1
...

Sheet Weekly
A1: Week Start Date | B1: Week End Date | C1: =CONCATENATE("Weekly Participants ",SUM(C2:C99)) -> Weekly Participants 1672 | D1: =CONCATENATE("Weekly Tubes Run ",SUM(D2:D99)) -> Weekly Tubes Run 1981 | E1: =CONCATENATE("Weekly Positive Tubes ",SUM(E2:E99)) -> Weekly Positive Tubes 18 | F1: =CONCATENATE("Weekly Inconclusive Tubes ",SUM(F2:F99)) -> Weekly Inconclusive Tubes 3 | G1: % Positive
A2: =MIN('ALL Tube Results'!C:C) - WEEKDAY(MIN('ALL Tube Results'!C:C), 3) -> 44634 | B2: =A2+6 -> 44640 | C2: =SUMIFS('ALL Tube Results'!$G$2:$G99, 'ALL Tube Results'!$C$2:$C99, ">="&A2, 'ALL Tube Results'!$C$2:$C99, "<="&B2) -> 18 | D2: =COUNTIFS('ALL Tube Results'!$C2:$C99, ">="&A2, 'ALL Tube Results'!$C2:$C99, "<="&B2) -> 18 | E2: =COUNTIFS('ALL Tube Results'!$C2:$C99, ">="&A2, 'ALL Tube Results'!$C2:$C99, "<="&B2, 'ALL Tube Results'!$F2:$F99, "Positive") -> 0 | F2: =COUNTIFS('ALL Tube Results'!$C2:$C99, ">="&A2, 'ALL Tube Results'!$C2:$C99, "<="&B2, 'ALL Tube Results'!$F2:$F99, "Inconclusive") -> 0 | G2: =IFERROR(E2/D2,IFERROR(0/0,"")) -> 0 | I2: =TEXT(A2,"ddd") -> Mon
A3: =B2+1 -> 44641 | B3: =A3+6 -> 44647 | C3: =SUMIFS('ALL Tube Results'!$G$2:$G99, 'ALL Tube Results'!$C$2:$C99, ">="&A3, 'ALL Tube Results'!$C$2:$C99, "<="&B3) -> 99 | D3: =COUNTIFS('ALL Tube Results'!$C3:$C99, ">="&A3, 'ALL Tube Results'!$C3:$C99, "<="&B3) -> 100 | E3: =COUNTIFS('ALL Tube Results'!$C3:$C99, ">="&A3, 'ALL Tube Results'!$C3:$C99, "<="&B3, 'ALL Tube Results'!$F3:$F99, "Positive") -> 1 | F3: =COUNTIFS('ALL Tube Results'!$C3:$C99, ">="&A3, 'ALL Tube Results'!$C3:$C99, "<="&B3, 'ALL Tube Results'!$F3:$F99, "Inconclusive") -> 0 | G3: =IFERROR(E3/D3,IFERROR(0/0,"")) -> 0.01
A4: =A3+7 -> 44648 | B4: =A4+6 -> 44654 | C4: =SUMIFS('ALL Tube Results'!$G$2:$G99, 'ALL Tube Results'!$C$2:$C99, ">="&A4, 'ALL Tube Results'!$C$2:$C99, "<="&B4) -> 2 | D4: =COUNTIFS('ALL Tube Results'!$C4:$C99, ">="&A4, 'ALL Tube Results'!$C4:$C99, "<="&B4) -> 2 | E4: =COUNTIFS('ALL Tube Results'!$C4:$C99, ">="&A4, 'ALL Tube Results'!$C4:$C99, "<="&B4, 'ALL Tube Results'!$F4:$F99, "Positive") -> 0 | F4: =COUNTIFS('ALL Tube Results'!$C4:$C99, ">="&A4, 'ALL Tube Results'!$C4:$C99, "<="&B4, 'ALL Tube Results'!$F4:$F99, "Inconclusive") -> 0 | G4: =IFERROR(E4/D4,IFERROR(0/0,"")) -> 0
A5: =A4+7 -> 44655 | B5: =A5+6 -> 44661 | C5: =SUMIFS('ALL Tube Results'!$G$2:$G99, 'ALL Tube Results'!$C$2:$C99, ">="&A5, 'ALL Tube Results'!$C$2:$C99, "<="&B5) -> 127 | D5: =COUNTIFS('ALL Tube Results'!$C5:$C99, ">="&A5, 'ALL Tube Results'!$C5:$C99, "<="&B5) -> 142 | E5: =COUNTIFS('ALL Tube Results'!$C5:$C99, ">="&A5, 'ALL Tube Results'!$C5:$C99, "<="&B5, 'ALL Tube Results'!$F5:$F99, "Positive") -> 0 | F5: =COUNTIFS('ALL Tube Results'!$C5:$C99, ">="&A5, 'ALL Tube Results'!$C5:$C99, "<="&B5, 'ALL Tube Results'!$F5:$F99, "Inconclusive") -> 0 | G5: =IFERROR(E5/D5,IFERROR(0/0,"")) -> 0
A6: =A5+7 -> 44662 | B6: =A6+6 -> 44668 | C6: =SUMIFS('ALL Tube Results'!$G$2:$G99, 'ALL Tube Results'!$C$2:$C99, ">="&A6, 'ALL Tube Results'!$C$2:$C99, "<="&B6) -> 120 | D6: =COUNTIFS('ALL Tube Results'!$C6:$C99, ">="&A6, 'ALL Tube Results'!$C6:$C99, "<="&B6) -> 120 | E6: =COUNTIFS('ALL Tube Results'!$C6:$C99, ">="&A6, 'ALL Tube Results'!$C6:$C99, "<="&B6, 'ALL Tube Results'!$F6:$F99, "Positive") -> 0 | F6: =COUNTIFS('ALL Tube Results'!$C6:$C99, ">="&A6, 'ALL Tube Results'!$C6:$C99, "<="&B6, 'ALL Tube Results'!$F6:$F99, "Inconclusive") -> 0 | G6: =IFERROR(E6/D6,IFERROR(0/0,"")) -> 0
A7: =A6+7 -> 44669 | B7: =A7+6 -> 44675 | C7: =SUMIFS('ALL Tube Results'!$G$2:$G99, 'ALL Tube Results'!$C$2:$C99, ">="&A7, 'ALL Tube Results'!$C$2:$C99, "<="&B7) -> 134 | D7: =COUNTIFS('ALL Tube Results'!$C7:$C99, ">="&A7, 'ALL Tube Results'!$C7:$C99, "<="&B7) -> 134 | E7: =COUNTIFS('ALL Tube Results'!$C7:$C99, ">="&A7, 'ALL Tube Results'!$C7:$C99, "<="&B7, 'ALL Tube Results'!$F7:$F99, "Positive") -> 1 | F7: =COUNTIFS('ALL Tube Results'!$C7:$C99, ">="&A7, 'ALL Tube Results'!$C7:$C99, "<="&B7, 'ALL Tube Results'!$F7:$F99, "Inconclusive") -> 0 | G7: =IFERROR(E7/D7,IFERROR(0/0,"")) -> 0.0074626866
A8: =A7+7 -> 44676 | B8: =A8+6 -> 44682 | C8: =SUMIFS('ALL Tube Results'!$G$2:$G99, 'ALL Tube Results'!$C$2:$C99, ">="&A8, 'ALL Tube Results'!$C$2:$C99, "<="&B8) -> 108 | D8: =COUNTIFS('ALL Tube Results'!$C8:$C99, ">="&A8, 'ALL Tube Results'!$C8:$C99, "<="&B8) -> 108 | E8: =COUNTIFS('ALL Tube Results'!$C8:$C99, ">="&A8, 'ALL Tube Results'!$C8:$C99, "<="&B8, 'ALL Tube Results'!$F8:$F99, "Positive") -> 2 | F8: =COUNTIFS('ALL Tube Results'!$C8:$C99, ">="&A8, 'ALL Tube Results'!$C8:$C99, "<="&B8, 'ALL Tube Results'!$F8:$F99, "Inconclusive") -> 0 | G8: =IFERROR(E8/D8,IFERROR(0/0,"")) -> 0.018518519
A9: =A8+7 -> 44683 | B9: =A9+6 -> 44689 | C9: =SUMIFS('ALL Tube Results'!$G$2:$G99, 'ALL Tube Results'!$C$2:$C99, ">="&A9, 'ALL Tube Results'!$C$2:$C99, "<="&B9) -> 0 | D9: =COUNTIFS('ALL Tube Results'!$C9:$C99, ">="&A9, 'ALL Tube Results'!$C9:$C99, "<="&B9) -> 0 | E9: =COUNTIFS('ALL Tube Results'!$C9:$C99, ">="&A9, 'ALL Tube Results'!$C9:$C99, "<="&B9, 'ALL Tube Results'!$F9:$F99, "Positive") -> 0 | F9: =COUNTIFS('ALL Tube Results'!$C9:$C99, ">="&A9, 'ALL Tube Results'!$C9:$C99, "<="&B9, 'ALL Tube Results'!$F9:$F99, "Inconclusive") -> 0 | G9: =IFERROR(E9/D9,IFERROR(0/0,""))
A10: =A9+7 -> 44690 | B10: =A10+6 -> 44696 | C10: =SUMIFS('ALL Tube Results'!$G$2:$G99, 'ALL Tube Results'!$C$2:$C99, ">="&A10, 'ALL Tube Results'!$C$2:$C99, "<="&B10) -> 112 | D10: =COUNTIFS('ALL Tube Results'!$C10:$C99, ">="&A10, 'ALL Tube Results'!$C10:$C99, "<="&B10) -> 112 | E10: =COUNTIFS('ALL Tube Results'!$C10:$C99, ">="&A10, 'ALL Tube Results'!$C10:$C99, "<="&B10, 'ALL Tube Results'!$F10:$F99, "Positive") -> 0 | F10: =COUNTIFS('ALL Tube Results'!$C10:$C99, ">="&A10, 'ALL Tube Results'!$C10:$C99, "<="&B10, 'ALL Tube Results'!$F10:$F99, "Inconclusive") -> 0 | G10: =IFERROR(E10/D10,IFERROR(0/0,"")) -> 0
A11: =A10+7 -> 44697 | B11: =A11+6 -> 44703 | C11: =SUMIFS('ALL Tube Results'!$G$2:$G99, 'ALL Tube Results'!$C$2:$C99, ">="&A11, 'ALL Tube Results'!$C$2:$C99, "<="&B11) -> 99 | D11: =COUNTIFS('ALL Tube Results'!$C11:$C99, ">="&A11, 'ALL Tube Results'!$C11:$C99, "<="&B11) -> 99 | E11: =COUNTIFS('ALL Tube Results'!$C11:$C99, ">="&A11, 'ALL Tube Results'!$C11:$C99, "<="&B11, 'ALL Tube Results'!$F11:$F99, "Positive") -> 0 | F11: =COUNTIFS('ALL Tube Results'!$C11:$C99, ">="&A11, 'ALL Tube Results'!$C11:$C99, "<="&B11, 'ALL Tube Results'!$F11:$F99, "Inconclusive") -> 0 | G11: =IFERROR(E11/D11,IFERROR(0/0,"")) -> 0
A12: =A11+7 -> 44704 | B12: =A12+6 -> 44710 | C12: =SUMIFS('ALL Tube Results'!$G$2:$G99, 'ALL Tube Results'!$C$2:$C99, ">="&A12, 'ALL Tube Results'!$C$2:$C99, "<="&B12) -> 128 | D12: =COUNTIFS('ALL Tube Results'!$C12:$C99, ">="&A12, 'ALL Tube Results'!$C12:$C99, "<="&B12) -> 137 | E12: =COUNTIFS('ALL Tube Results'!$C12:$C99, ">="&A12, 'ALL Tube Results'!$C12:$C99, "<="&B12, 'ALL Tube Results'!$F12:$F99, "Positive") -> 0 | F12: =COUNTIFS('ALL Tube Results'!$C12:$C99, ">="&A12, 'ALL Tube Results'!$C12:$C99, "<="&B12, 'ALL Tube Results'!$F12:$F99, "Inconclusive") -> 0 | G12: =IFERROR(E12/D12,IFERROR(0/0,"")) -> 0
A13: =A12+7 -> 44711 | B13: =A13+6 -> 44717 | C13: =SUMIFS('ALL Tube Results'!$G$2:$G99, 'ALL Tube Results'!$C$2:$C99, ">="&A13, 'ALL Tube Results'!$C$2:$C99, "<="&B13) -> 114 | D13: =COUNTIFS('ALL Tube Results'!$C13:$C99, ">="&A13, 'ALL Tube Results'!$C13:$C99, "<="&B13) -> 114 | E13: =COUNTIFS('ALL Tube Results'!$C13:$C99, ">="&A13, 'ALL Tube Results'!$C13:$C99, "<="&B13, 'ALL Tube Results'!$F13:$F99, "Positive") -> 1 | F13: =COUNTIFS('ALL Tube Results'!$C13:$C99, ">="&A13, 'ALL Tube Results'!$C13:$C99, "<="&B13, 'ALL Tube Results'!$F13:$F99, "Inconclusive") -> 0 | G13: =IFERROR(E13/D13,IFERROR(0/0,"")) -> 0.0087719298
A14: =A13+7 -> 44718 | B14: =A14+6 -> 44724 | C14: =SUMIFS('ALL Tube Results'!$G$2:$G99, 'ALL Tube Results'!$C$2:$C99, ">="&A14, 'ALL Tube Results'!$C$2:$C99, "<="&B14) -> 55 | D14: =COUNTIFS('ALL Tube Results'!$C14:$C99, ">="&A14, 'ALL Tube Results'!$C14:$C99, "<="&B14) -> 130 | E14: =COUNTIFS('ALL Tube Results'!$C14:$C99, ">="&A14, 'ALL Tube Results'!$C14:$C99, "<="&B14, 'ALL Tube Results'!$F14:$F99, "Positive") -> 3 | F14: =COUNTIFS('ALL Tube Results'!$C14:$C99, ">="&A14, 'ALL Tube Results'!$C14:$C99, "<="&B14, 'ALL Tube Results'!$F14:$F99, "Inconclusive") -> 0 | G14: =IFERROR(E14/D14,IFERROR(0/0,"")) -> 0.023076923
A15: =A14+7 -> 44725 | B15: =A15+6 -> 44731 | C15: =SUMIFS('ALL Tube Results'!$G$2:$G99, 'ALL Tube Results'!$C$2:$C99, ">="&A15, 'ALL Tube Results'!$C$2:$C99, "<="&B15) -> 0 | D15: =COUNTIFS('ALL Tube Results'!$C15:$C99, ">="&A15, 'ALL Tube Results'!$C15:$C99, "<="&B15) -> 0 | E15: =COUNTIFS('ALL Tube Results'!$C15:$C99, ">="&A15, 'ALL Tube Results'!$C15:$C99, "<="&B15, 'ALL Tube Results'!$F15:$F99, "Positive") -> 0 | F15: =COUNTIFS('ALL Tube Results'!$C15:$C99, ">="&A15, 'ALL Tube Results'!$C15:$C99, "<="&B15, 'ALL Tube Results'!$F15:$F99, "Inconclusive") -> 0 | G15: =IFERROR(E15/D15,IFERROR(0/0,""))
A16: =A15+7 -> 44732 | B16: =A16+6 -> 44738 | C16: =SUMIFS('ALL Tube Results'!$G$2:$G99, 'ALL Tube Results'!$C$2:$C99, ">="&A16, 'ALL Tube Results'!$C$2:$C99, "<="&B16) -> 0 | D16: =COUNTIFS('ALL Tube Results'!$C16:$C99, ">="&A16, 'ALL Tube Results'!$C16:$C99, "<="&B16) -> 0 | E16: =COUNTIFS('ALL Tube Results'!$C16:$C99, ">="&A16, 'ALL Tube Results'!$C16:$C99, "<="&B16, 'ALL Tube Results'!$F16:$F99, "Positive") -> 0 | F16: =COUNTIFS('ALL Tube Results'!$C16:$C99, ">="&A16, 'ALL Tube Results'!$C16:$C99, "<="&B16, 'ALL Tube Results'!$F16:$F99, "Inconclusive") -> 0 | G16: =IFERROR(E16/D16,IFERROR(0/0,""))
A17: =A16+7 -> 44739 | B17: =A17+6 -> 44745 | C17: =SUMIFS('ALL Tube Results'!$G$2:$G99, 'ALL Tube Results'!$C$2:$C99, ">="&A17, 'ALL Tube Results'!$C$2:$C99, "<="&B17) -> 90 | D17: =COUNTIFS('ALL Tube Results'!$C17:$C99, ">="&A17, 'ALL Tube Results'!$C17:$C99, "<="&B17) -> 125 | E17: =COUNTIFS('ALL Tube Results'!$C17:$C99, ">="&A17, 'ALL Tube Results'!$C17:$C99, "<="&B17, 'ALL Tube Results'!$F17:$F99, "Positive") -> 4 | F17: =COUNTIFS('ALL Tube Results'!$C17:$C99, ">="&A17, 'ALL Tube Results'!$C17:$C99, "<="&B17, 'ALL Tube Results'!$F17:$F99, "Inconclusive") -> 3 | G17: =IFERROR(E17/D17,IFERROR(0/0,"")) -> 0.032
A18: =A17+7 -> 44746 | B18: =A18+6 -> 44752 | C18: =SUMIFS('ALL Tube Results'!$G$2:$G99, 'ALL Tube Results'!$C$2:$C99, ">="&A18, 'ALL Tube Results'!$C$2:$C99, "<="&B18) -> 131 | D18: =COUNTIFS('ALL Tube Results'!$C18:$C99, ">="&A18, 'ALL Tube Results'!$C18:$C99, "<="&B18) -> 132 | E18: =COUNTIFS('ALL Tube Results'!$C18:$C99, ">="&A18, 'ALL Tube Results'!$C18:$C99, "<="&B18, 'ALL Tube Results'!$F18:$F99, "Positive") -> 1 | F18: =COUNTIFS('ALL Tube Results'!$C18:$C99, ">="&A18, 'ALL Tube Results'!$C18:$C99, "<="&B18, 'ALL Tube Results'!$F18:$F99, "Inconclusive") -> 0 | G18: =IFERROR(E18/D18,IFERROR(0/0,"")) -> 0.0075757576
A19: =A18+7 -> 44753 | B19: =A19+6 -> 44759 | C19: =SUMIFS('ALL Tube Results'!$G$2:$G99, 'ALL Tube Results'!$C$2:$C99, ">="&A19, 'ALL Tube Results'!$C$2:$C99, "<="&B19) -> 122 | D19: =COUNTIFS('ALL Tube Results'!$C19:$C99, ">="&A19, 'ALL Tube Results'!$C19:$C99, "<="&B19) -> 123 | E19: =COUNTIFS('ALL Tube Results'!$C19:$C99, ">="&A19, 'ALL Tube Results'!$C19:$C99, "<="&B19, 'ALL Tube Results'!$F19:$F99, "Positive") -> 0 | F19: =COUNTIFS('ALL Tube Results'!$C19:$C99, ">="&A19, 'ALL Tube Results'!$C19:$C99, "<="&B19, 'ALL Tube Results'!$F19:$F99, "Inconclusive") -> 0 | G19: =IFERROR(E19/D19,IFERROR(0/0,"")) -> 0
A20: =A19+7 -> 44760 | B20: =A20+6 -> 44766 | C20: =SUMIFS('ALL Tube Results'!$G$2:$G99, 'ALL Tube Results'!$C$2:$C99, ">="&A20, 'ALL Tube Results'!$C$2:$C99, "<="&B20) -> 97 | D20: =COUNTIFS('ALL Tube Results'!$C20:$C99, ">="&A20, 'ALL Tube Results'!$C20:$C99, "<="&B20) -> 200 | E20: =COUNTIFS('ALL Tube Results'!$C20:$C99, ">="&A20, 'ALL Tube Results'!$C20:$C99, "<="&B20, 'ALL Tube Results'!$F20:$F99, "Positive") -> 4 | F20: =COUNTIFS('ALL Tube Results'!$C20:$C99, ">="&A20, 'ALL Tube Results'!$C20:$C99, "<="&B20, 'ALL Tube Results'!$F20:$F99, "Inconclusive") -> 0 | G20: =IFERROR(E20/D20,IFERROR(0/0,"")) -> 0.02
A21: =A20+7 -> 44767 | B21: =A21+6 -> 44773 | C21: =SUMIFS('ALL Tube Results'!$G$2:$G99, 'ALL Tube Results'!$C$2:$C99, ">="&A21, 'ALL Tube Results'!$C$2:$C99, "<="&B21) -> 0 | D21: =COUNTIFS('ALL Tube Results'!$C21:$C99, ">="&A21, 'ALL Tube Results'!$C21:$C99, "<="&B21) -> 0 | E21: =COUNTIFS('ALL Tube Results'!$C21:$C99, ">="&A21, 'ALL Tube Results'!$C21:$C99, "<="&B21, 'ALL Tube Results'!$F21:$F99, "Positive") -> 0 | F21: =COUNTIFS('ALL Tube Results'!$C21:$C99, ">="&A21, 'ALL Tube Results'!$C21:$C99, "<="&B21, 'ALL Tube Results'!$F21:$F99, "Inconclusive") -> 0 | G21: =IFERROR(E21/D21,IFERROR(0/0,""))
A22: =A21+7 -> 44774 | B22: =A22+6 -> 44780 | C22: =SUMIFS('ALL Tube Results'!$G$2:$G99, 'ALL Tube Results'!$C$2:$C99, ">="&A22, 'ALL Tube Results'!$C$2:$C99, "<="&B22) -> 54 | D22: =COUNTIFS('ALL Tube Results'!$C22:$C99, ">="&A22, 'ALL Tube Results'!$C22:$C99, "<="&B22) -> 86 | E22: =COUNTIFS('ALL Tube Results'!$C22:$C99, ">="&A22, 'ALL Tube Results'!$C22:$C99, "<="&B22, 'ALL Tube Results'!$F22:$F99, "Positive") -> 0 | F22: =COUNTIFS('ALL Tube Results'!$C22:$C99, ">="&A22, 'ALL Tube Results'!$C22:$C99, "<="&B22, 'ALL Tube Results'!$F22:$F99, "Inconclusive") -> 0 | G22: =IFERROR(E22/D22,IFERROR(0/0,"")) -> 0
A23: =A22+7 -> 44781 | B23: =A23+6 -> 44787 | C23: =SUMIFS('ALL Tube Results'!$G$2:$G99, 'ALL Tube Results'!$C$2:$C99, ">="&A23, 'ALL Tube Results'!$C$2:$C99, "<="&B23) -> 62 | D23: =COUNTIFS('ALL Tube Results'!$C23:$C99, ">="&A23, 'ALL Tube Results'!$C23:$C99, "<="&B23) -> 62 | E23: =COUNTIFS('ALL Tube Results'!$C23:$C99, ">="&A23, 'ALL Tube Results'!$C23:$C99, "<="&B23, 'ALL Tube Results'!$F23:$F99, "Positive") -> 1 | F23: =COUNTIFS('ALL Tube Results'!$C23:$C99, ">="&A23, 'ALL Tube Results'!$C23:$C99, "<="&B23, 'ALL Tube Results'!$F23:$F99, "Inconclusive") -> 0 | G23: =IFERROR(E23/D23,IFERROR(0/0,"")) -> 0.016129032
A24: =A23+7 -> 44788 | B24: =A24+6 -> 44794 | C24: =SUMIFS('ALL Tube Results'!$G$2:$G99, 'ALL Tube Results'!$C$2:$C99, ">="&A24, 'ALL Tube Results'!$C$2:$C99, "<="&B24) -> 0 | D24: =COUNTIFS('ALL Tube Results'!$C24:$C99, ">="&A24, 'ALL Tube Results'!$C24:$C99, "<="&B24) -> 37 | E24: =COUNTIFS('ALL Tube Results'!$C24:$C99, ">="&A24, 'ALL Tube Results'!$C24:$C99, "<="&B24, 'ALL Tube Results'!$F24:$F99, "Positive") -> 0 | F24: =COUNTIFS('ALL Tube Results'!$C24:$C99, ">="&A24, 'ALL Tube Results'!$C24:$C99, "<="&B24, 'ALL Tube Results'!$F24:$F99, "Inconclusive") -> 0 | G24: =IFERROR(E24/D24,IFERROR(0/0,"")) -> 0

Sheet Runs Compare
A1: ALL Tube RESULTS by Run ID | B1: =COUNT(B3:B672) -> 80 | C1: =SUM(C2:C672) -> 1981 | D1: =SUM(D2:D672) -> 1960 | E1: =SUM(E2:E672) -> 18 | F1: =SUM(F2:F672) -> 3 | H1: =SUM(H2:H672) -> 0 | L1: =SUM(L2:L672) -> 84 | M1: =SUM(M2:M672) -> 0 | N1: =SUM(N2:N672) -> 0 | P1: =SUM(P2:P672) -> 309 | R1: Run Reconciled RESULTS | S1: =CONCATENATE("Delta Run Reconciled to ALL Tubes ",T1-C1) -> Delta Run Reconciled to ALL Tubes 0 | T1: =SUM(T2:T672) -> 1981 | U1: =COUNTIF(U3:U672,FALSE) -> 0 | V1: =SUM(V2:V672) -> 0 | W1: =SUM(W2:W672) -> 0 | Y1: RFR Data - PreExcl RESULTS | AA1: =SUM(AA2:AA672) -> 1897 | AB1: =SUM(AB2:AB672) -> 1876 | AC1: =SUM(AC2:AC672) -> 18 | AD1: =SUM(AD2:AD672) -> 3 | AG1: APS Final RESULTS by Reconciled Run ID | AI1: =SUM(AI3:AI672) -> 1672 | AJ1: =SUM(AJ3:AJ672) -> 1655 | AK1: =SUM(AK3:AK672) -> 14 | AL1: =SUM(AL3:AL672) -> 3 | AM1: =SUM(AM3:AM672) -> 0 | AO1: APS Final RESULTS by Collect Date | AP1: =SUM(AP2:AP672) -> 1666 | AQ1: =SUM(AQ2:AQ672) -> 1159 | AR1: =SUM(AR2:AR672) -> 10 | AS1: =SUM(AS2:AS672) -> 2 | AT1: =SUM(AT2:AT672) -> 0
A2: Run ID | B2: Run Date | C2: Number of Tubes | D2: Negative | E2: Positive | F2: Inconclusive | H2: Delta to Run Reconciled Results | I2: T | J2: P | K2: I | L2: Delta to RFR preExcl Audit Num Run Tubes | M2: Delta to RFR preExcl Audit Num Positives | N2: Delta to RFR preExcl Audit Num Inconclusives | P2: Delta to APS | R2: Run ID | S2: Run Date | T2: Reconciled Tube Run Count | U2: Exact Run ID Match to ALL Tube Results (Col A) | Y2: Run ID - RFR Initial Only | Z2: Run Date | AA2: ='RFR Data - preExcl'!AK1 -> RFR Audit Num Run Tubes | AB2: Calculated Negs | AC2: ='RFR Data - preExcl'!AI1 -> Audit Pos Session Calls | AD2: ='RFR Data - preExcl'!AF1 -> Audit Inc Session Calls | AE2: preExcl Match Row | AG2: Final Assigned Run ID | AH2: Run Date | AI2: Number of Tubes | AJ2: Negative | AK2: Positive | AL2: Inconclusive | AM2: Null | AO2: ='APS Tubes by Date Import'!B1 -> APS COLLECT DATE | AP2: Number of Tubes | AQ2: Negative | AR2: Positive | AS2: Inconclusive | AT2: Null
A3: {=SORT(UNIQUE('ALL Tube Results'!B2:B672))} -> RUN-COMB_2022-03-20_RFR-001 | B3: =VLOOKUP(A3,'Run Reconcile'!A$2:B672,2,FALSE) -> 44640 | C3: =COUNTIF('ALL Tube Results'!B2:B672, A3) -> 18 | D3: =COUNTIFS('ALL Tube Results'!$B2:$B672, $A3, 'ALL Tube Results'!$F2:$F672, "Negative") -> 18 | E3: =COUNTIFS('ALL Tube Results'!$B2:$B672, $A3, 'ALL Tube Results'!$F2:$F672, "Positive") -> 0 | F3: =COUNTIFS('ALL Tube Results'!$B2:$B672, $A3, 'ALL Tube Results'!$F2:$F672, "Inconclusive") -> 0 | G3: =IFERROR(VLOOKUP($A3,R$3:T672,3,FALSE),IFERROR(0/0,"") ) -> 18 | H3: =IF($C3=G3,IFERROR(0/0,""),$C3-G3) | I3: =IFERROR(VLOOKUP($A3,Y$3:AA672,3,FALSE),IFERROR(0/0,"") ) -> 18 | J3: =IFERROR(VLOOKUP($A3,Y$3:AD672,5,FALSE),IFERROR(0/0,"") ) -> 0 | K3: =IFERROR(VLOOKUP($A3,Y$3:AD672,6,FALSE),IFERROR(0/0,"")) -> 0 | L3: =IF($C3=I3,IFERROR(0/0,""),$C3-I3) | M3: =IF($E3=J3,IFERROR(0/0,""),$E3-J3) | N3: =IF($F3=K3,IFERROR(0/0,""),$F3-K3) | O3: =IFERROR(VLOOKUP($A3,AG$3:AI672,3,FALSE),IFERROR(0/0,"") ) -> 18 | P3: =IF($C3=O3,IFERROR(0/0,""),$C3-O3) | R3: {=SORT('Run Reconcile'!A2:B672,1,TRUE)} -> RUN-COMB_2022-03-20_RFR-001 | S3: 44640 | T3: =VLOOKUP(R3,'Run Reconcile'!$A$2:$M672,13,FALSE) -> 18 | U3: =IF(EXACT(A2,R2),IFERROR(0/0,""),FALSE) | Y3: =IFERROR(__xludf.DUMMYFUNCTION("SORT(FILTER('Run Reconcile'!A2:B672,'Run Reconcile'!A2:A672<>""*"",REGEXMATCH('Run Reconcile'!A2:A672,""RFR-"")),1,TRUE) "),"RUN-COMB_2022-03-20_RFR-001") -> RUN-COMB_2022-03-20_RFR-001 | Z3: =IFERROR(__xludf.DUMMYFUNCTION("""COMPUTED_VALUE"""),44640.0) -> 44640 | AA3: {=INDEX('RFR Data - preExcl'!AK$2:AK672,$AE3,1)} -> 18 | AB3: =AA3-AC3-AD3 -> 18 | AC3: {=INDEX('RFR Data - preExcl'!AI$2:AI672,$AE3,1)} -> 0 | AD3: {=INDEX('RFR Data - preExcl'!AF$2:AF672,$AE3,1)} -> 0 | AE3: =IFNA(MATCH(Y3,'RFR Data - preExcl'!A$2:A672,0),"") -> 1 | AG3: {=SORT(UNIQUE('APS Tubes Import'!V2:V672))} -> RUN-COMB_2022-03-20_RFR-001 | AH3: =VLOOKUP(AG3,'Run Reconcile'!A$2:B672,2,FALSE) -> 44640 | AI3: =COUNTIF('APS Tubes Import'!$V$2:$V672, AG3) -> 18 | AJ3: =COUNTIFS('APS Tubes Import'!V$2:V672, AG3, 'APS Tubes Import'!H$2:H672, "Negative") -> 18 | AK3: =COUNTIFS('APS Tubes Import'!V$2:V672, AG3, 'APS Tubes Import'!H$2:H672, "Positive") -> 0 | AL3: =COUNTIFS('APS Tubes Import'!V$2:V672, AG3, 'APS Tubes Import'!H$2:H672, "Inconclusive") -> 0 | AM3: =COUNTIFS('APS Tubes Import'!V$2:V672, AG3, 'APS Tubes Import'!H$2:H672, "Null") -> 0 | AO3: ='APS Tubes by Date Import'!B2 -> 44640 | AP3: ='APS Tubes by Date Import'!C2 -> 18 | AQ3: ='APS Tubes by Date Import'!D2 -> 18 | AR3: ='APS Tubes by Date Import'!E2 -> 0 | AS3: ='APS Tubes by Date Import'!F2 -> 0 | AT3: ='APS Tubes by Date Import'!G2 -> 0
A4: RUN-COMB_2022-03-21_RFR-002 | B4: =VLOOKUP(A4,'Run Reconcile'!A$2:B672,2,FALSE) -> 44641 | C4: =COUNTIF('ALL Tube Results'!B3:B672, A4) -> 27 | D4: =COUNTIFS('ALL Tube Results'!$B3:$B672, $A4, 'ALL Tube Results'!$F3:$F672, "Negative") -> 26 | E4: =COUNTIFS('ALL Tube Results'!$B3:$B672, $A4, 'ALL Tube Results'!$F3:$F672, "Positive") -> 1 | F4: =COUNTIFS('ALL Tube Results'!$B3:$B672, $A4, 'ALL Tube Results'!$F3:$F672, "Inconclusive") -> 0 | G4: =IFERROR(VLOOKUP($A4,R$3:T673,3,FALSE),IFERROR(0/0,"") ) -> 27 | H4: =IF($C4=G4,IFERROR(0/0,""),$C4-G4) | I4: =IFERROR(VLOOKUP($A4,Y$3:AA673,3,FALSE),IFERROR(0/0,"") ) -> 27 | J4: =IFERROR(VLOOKUP($A4,Y$3:AD673,5,FALSE),IFERROR(0/0,"") ) -> 1 | K4: =IFERROR(VLOOKUP($A4,Y$3:AD673,6,FALSE),IFERROR(0/0,"")) -> 0 | L4: =IF($C4=I4,IFERROR(0/0,""),$C4-I4) | M4: =IF($E4=J4,IFERROR(0/0,""),$E4-J4) | N4: =IF($F4=K4,IFERROR(0/0,""),$F4-K4) | O4: =IFERROR(VLOOKUP($A4,AG$3:AI673,3,FALSE),IFERROR(0/0,"") ) -> 26 | P4: =IF($C4=O4,IFERROR(0/0,""),$C4-O4) -> 1 | R4: RUN-COMB_2022-03-21_RFR-002 | S4: 44641 | T4: =VLOOKUP(R4,'Run Reconcile'!$A$2:$M672,13,FALSE) -> 27 | U4: =IF(EXACT(A3,R3),IFERROR(0/0,""),FALSE) | Y4: =IFERROR(__xludf.DUMMYFUNCTION("""COMPUTED_VALUE"""),"RUN-COMB_2022-03-21_RFR-002") -> RUN-COMB_2022-03-21_RFR-002 | Z4: =IFERROR(__xludf.DUMMYFUNCTION("""COMPUTED_VALUE"""),44641.0) -> 44641 | AA4: {=INDEX('RFR Data - preExcl'!AK$2:AK672,$AE4,1)} -> 27 | AB4: =AA4-AC4-AD4 -> 26 | AC4: {=INDEX('RFR Data - preExcl'!AI$2:AI672,$AE4,1)} -> 1 | AD4: {=INDEX('RFR Data - preExcl'!AF$2:AF672,$AE4,1)} -> 0 | AE4: =IFNA(MATCH(Y4,'RFR Data - preExcl'!A$2:A672,0),"") -> 2 | AG4: RUN-COMB_2022-03-21_RFR-002 | AH4: =VLOOKUP(AG4,'Run Reconcile'!A$2:B672,2,FALSE) -> 44641 | AI4: =COUNTIF('APS Tubes Import'!$V$2:$V672, AG4) -> 26 | AJ4: =COUNTIFS('APS Tubes Import'!V$2:V672, AG4, 'APS Tubes Import'!H$2:H672, "Negative") -> 25 | AK4: =COUNTIFS('APS Tubes Import'!V$2:V672, AG4, 'APS Tubes Import'!H$2:H672, "Positive") -> 1 | AL4: =COUNTIFS('APS Tubes Import'!V$2:V672, AG4, 'APS Tubes Import'!H$2:H672, "Inconclusive") -> 0 | AM4: =COUNTIFS('APS Tubes Import'!V$2:V672, AG4, 'APS Tubes Import'!H$2:H672, "Null") -> 0 | AO4: ='APS Tubes by Date Import'!B3 -> 44641 | AP4: ='APS Tubes by Date Import'!C3 -> 26 | AQ4: ='APS Tubes by Date Import'!D3 -> 25 | AR4: ='APS Tubes by Date Import'!E3 -> 1 | AS4: ='APS Tubes by Date Import'!F3 -> 0 | AT4: ='APS Tubes by Date Import'!G3 -> 0
A5: RUN-COMB_2022-03-22_RFR-004 | B5: =VLOOKUP(A5,'Run Reconcile'!A$2:B672,2,FALSE) -> 44642 | C5: =COUNTIF('ALL Tube Results'!B4:B672, A5) -> 18 | D5: =COUNTIFS('ALL Tube Results'!$B4:$B672, $A5, 'ALL Tube Results'!$F4:$F672, "Negative") -> 18 | E5: =COUNTIFS('ALL Tube Results'!$B4:$B672, $A5, 'ALL Tube Results'!$F4:$F672, "Positive") -> 0 | F5: =COUNTIFS('ALL Tube Results'!$B4:$B672, $A5, 'ALL Tube Results'!$F4:$F672, "Inconclusive") -> 0 | G5: =IFERROR(VLOOKUP($A5,R$3:T674,3,FALSE),IFERROR(0/0,"") ) -> 18 | H5: =IF($C5=G5,IFERROR(0/0,""),$C5-G5) | I5: =IFERROR(VLOOKUP($A5,Y$3:AA674,3,FALSE),IFERROR(0/0,"") ) -> 18 | J5: =IFERROR(VLOOKUP($A5,Y$3:AD674,5,FALSE),IFERROR(0/0,"") ) -> 0 | K5: =IFERROR(VLOOKUP($A5,Y$3:AD674,6,FALSE),IFERROR(0/0,"")) -> 0 | L5: =IF($C5=I5,IFERROR(0/0,""),$C5-I5) | M5: =IF($E5=J5,IFERROR(0/0,""),$E5-J5) | N5: =IF($F5=K5,IFERROR(0/0,""),$F5-K5) | O5: =IFERROR(VLOOKUP($A5,AG$3:AI674,3,FALSE),IFERROR(0/0,"") ) -> 18 | P5: =IF($C5=O5,IFERROR(0/0,""),$C5-O5) | R5: RUN-COMB_2022-03-22_RFR-004 | S5: 44642 | T5: =VLOOKUP(R5,'Run Reconcile'!$A$2:$M672,13,FALSE) -> 18 | U5: =IF(EXACT(A4,R4),IFERROR(0/0,""),FALSE) | Y5: =IFERROR(__xludf.DUMMYFUNCTION("""COMPUTED_VALUE"""),"RUN-COMB_2022-03-22_RFR-004") -> RUN-COMB_2022-03-22_RFR-004 | Z5: =IFERROR(__xludf.DUMMYFUNCTION("""COMPUTED_VALUE"""),44642.0) -> 44642 | AA5: {=INDEX('RFR Data - preExcl'!AK$2:AK672,$AE5,1)} -> 18 | AB5: =AA5-AC5-AD5 -> 18 | AC5: {=INDEX('RFR Data - preExcl'!AI$2:AI672,$AE5,1)} -> 0 | AD5: {=INDEX('RFR Data - preExcl'!AF$2:AF672,$AE5,1)} -> 0 | AE5: =IFNA(MATCH(Y5,'RFR Data - preExcl'!A$2:A672,0),"") -> 4 | AG5: RUN-COMB_2022-03-22_RFR-004 | AH5: =VLOOKUP(AG5,'Run Reconcile'!A$2:B672,2,FALSE) -> 44642 | AI5: =COUNTIF('APS Tubes Import'!$V$2:$V672, AG5) -> 18 | AJ5: =COUNTIFS('APS Tubes Import'!V$2:V672, AG5, 'APS Tubes Import'!H$2:H672, "Negative") -> 18 | AK5: =COUNTIFS('APS Tubes Import'!V$2:V672, AG5, 'APS Tubes Import'!H$2:H672, "Positive") -> 0 | AL5: =COUNTIFS('APS Tubes Import'!V$2:V672, AG5, 'APS Tubes Import'!H$2:H672, "Inconclusive") -> 0 | AM5: =COUNTIFS('APS Tubes Import'!V$2:V672, AG5, 'APS Tubes Import'!H$2:H672, "Null") -> 0 | AO5: ='APS Tubes by Date Import'!B4 -> 44642 | AP5: ='APS Tubes by Date Import'!C4 -> 18 | AQ5: ='APS Tubes by Date Import'!D4 -> 18 | AR5: ='APS Tubes by Date Import'!E4 -> 0 | AS5: ='APS Tubes by Date Import'!F4 -> 0 | AT5: ='APS Tubes by Date Import'!G4 -> 0
A6: RUN-COMB_2022-03-23_RFR-006 | B6: =VLOOKUP(A6,'Run Reconcile'!A$2:B672,2,FALSE) -> 44643 | C6: =COUNTIF('ALL Tube Results'!B5:B672, A6) -> 32 | D6: =COUNTIFS('ALL Tube Results'!$B5:$B672, $A6, 'ALL Tube Results'!$F5:$F672, "Negative") -> 32 | E6: =COUNTIFS('ALL Tube Results'!$B5:$B672, $A6, 'ALL Tube Results'!$F5:$F672, "Positive") -> 0 | F6: =COUNTIFS('ALL Tube Results'!$B5:$B672, $A6, 'ALL Tube Results'!$F5:$F672, "Inconclusive") -> 0 | G6: =IFERROR(VLOOKUP($A6,R$3:T675,3,FALSE),IFERROR(0/0,"") ) -> 32 | H6: =IF($C6=G6,IFERROR(0/0,""),$C6-G6) | I6: =IFERROR(VLOOKUP($A6,Y$3:AA675,3,FALSE),IFERROR(0/0,"") ) -> 32 | J6: =IFERROR(VLOOKUP($A6,Y$3:AD675,5,FALSE),IFERROR(0/0,"") ) -> 0 | K6: =IFERROR(VLOOKUP($A6,Y$3:AD675,6,FALSE),IFERROR(0/0,"")) -> 0 | L6: =IF($C6=I6,IFERROR(0/0,""),$C6-I6) | M6: =IF($E6=J6,IFERROR(0/0,""),$E6-J6) | N6: =IF($F6=K6,IFERROR(0/0,""),$F6-K6) | O6: =IFERROR(VLOOKUP($A6,AG$3:AI675,3,FALSE),IFERROR(0/0,"") ) -> 32 | P6: =IF($C6=O6,IFERROR(0/0,""),$C6-O6) | R6: RUN-COMB_2022-03-23_RFR-006 | S6: 44643 | T6: =VLOOKUP(R6,'Run Reconcile'!$A$2:$M672,13,FALSE) -> 32 | U6: =IF(EXACT(A5,R5),IFERROR(0/0,""),FALSE) | Y6: =IFERROR(__xludf.DUMMYFUNCTION("""COMPUTED_VALUE"""),"RUN-COMB_2022-03-23_RFR-006") -> RUN-COMB_2022-03-23_RFR-006 | Z6: =IFERROR(__xludf.DUMMYFUNCTION("""COMPUTED_VALUE"""),44643.0) -> 44643 | AA6: {=INDEX('RFR Data - preExcl'!AK$2:AK672,$AE6,1)} -> 32 | AB6: =AA6-AC6-AD6 -> 32 | AC6: {=INDEX('RFR Data - preExcl'!AI$2:AI672,$AE6,1)} -> 0 | AD6: {=INDEX('RFR Data - preExcl'!AF$2:AF672,$AE6,1)} -> 0 | AE6: =IFNA(MATCH(Y6,'RFR Data - preExcl'!A$2:A672,0),"") -> 6 | AG6: RUN-COMB_2022-03-23_RFR-006 | AH6: =VLOOKUP(AG6,'Run Reconcile'!A$2:B672,2,FALSE) -> 44643 | AI6: =COUNTIF('APS Tubes Import'!$V$2:$V672, AG6) -> 32 | AJ6: =COUNTIFS('APS Tubes Import'!V$2:V672, AG6, 'APS Tubes Import'!H$2:H672, "Negative") -> 32 | AK6: =COUNTIFS('APS Tubes Import'!V$2:V672, AG6, 'APS Tubes Import'!H$2:H672, "Positive") -> 0 | AL6: =COUNTIFS('APS Tubes Import'!V$2:V672, AG6, 'APS Tubes Import'!H$2:H672, "Inconclusive") -> 0 | AM6: =COUNTIFS('APS Tubes Import'!V$2:V672, AG6, 'APS Tubes Import'!H$2:H672, "Null") -> 0 | AO6: ='APS Tubes by Date Import'!B5 -> 44643 | AP6: ='APS Tubes by Date Import'!C5 -> 32 | AQ6: ='APS Tubes by Date Import'!D5 -> 32 | AR6: ='APS Tubes by Date Import'!E5 -> 0 | AS6: ='APS Tubes by Date Import'!F5 -> 0 | AT6: ='APS Tubes by Date Import'!G5 -> 0
A7: RUN-COMB_2022-03-24_RFR-007 | B7: =VLOOKUP(A7,'Run Reconcile'!A$2:B672,2,FALSE) -> 44644 | C7: =COUNTIF('ALL Tube Results'!B6:B672, A7) -> 23 | D7: =COUNTIFS('ALL Tube Results'!$B6:$B672, $A7, 'ALL Tube Results'!$F6:$F672, "Negative") -> 23 | E7: =COUNTIFS('ALL Tube Results'!$B6:$B672, $A7, 'ALL Tube Results'!$F6:$F672, "Positive") -> 0 | F7: =COUNTIFS('ALL Tube Results'!$B6:$B672, $A7, 'ALL Tube Results'!$F6:$F672, "Inconclusive") -> 0 | G7: =IFERROR(VLOOKUP($A7,R$3:T676,3,FALSE),IFERROR(0/0,"") ) -> 23 | H7: =IF($C7=G7,IFERROR(0/0,""),$C7-G7) | I7: =IFERROR(VLOOKUP($A7,Y$3:AA676,3,FALSE),IFERROR(0/0,"") ) -> 23 | J7: =IFERROR(VLOOKUP($A7,Y$3:AD676,5,FALSE),IFERROR(0/0,"") ) -> 0 | K7: =IFERROR(VLOOKUP($A7,Y$3:AD676,6,FALSE),IFERROR(0/0,"")) -> 0 | L7: =IF($C7=I7,IFERROR(0/0,""),$C7-I7) | M7: =IF($E7=J7,IFERROR(0/0,""),$E7-J7) | N7: =IF($F7=K7,IFERROR(0/0,""),$F7-K7) | O7: =IFERROR(VLOOKUP($A7,AG$3:AI676,3,FALSE),IFERROR(0/0,"") ) -> 23 | P7: =IF($C7=O7,IFERROR(0/0,""),$C7-O7) | R7: RUN-COMB_2022-03-24_RFR-007 | S7: 44644 | T7: =VLOOKUP(R7,'Run Reconcile'!$A$2:$M672,13,FALSE) -> 23 | U7: =IF(EXACT(A6,R6),IFERROR(0/0,""),FALSE) | Y7: =IFERROR(__xludf.DUMMYFUNCTION("""COMPUTED_VALUE"""),"RUN-COMB_2022-03-24_RFR-007") -> RUN-COMB_2022-03-24_RFR-007 | Z7: =IFERROR(__xludf.DUMMYFUNCTION("""COMPUTED_VALUE"""),44644.0) -> 44644 | AA7: {=INDEX('RFR Data - preExcl'!AK$2:AK672,$AE7,1)} -> 23 | AB7: =AA7-AC7-AD7 -> 23 | AC7: {=INDEX('RFR Data - preExcl'!AI$2:AI672,$AE7,1)} -> 0 | AD7: {=INDEX('RFR Data - preExcl'!AF$2:AF672,$AE7,1)} -> 0 | AE7: =IFNA(MATCH(Y7,'RFR Data - preExcl'!A$2:A672,0),"") -> 7 | AG7: RUN-COMB_2022-03-24_RFR-007 | AH7: =VLOOKUP(AG7,'Run Reconcile'!A$2:B672,2,FALSE) -> 44644 | AI7: =COUNTIF('APS Tubes Import'!$V$2:$V672, AG7) -> 23 | AJ7: =COUNTIFS('APS Tubes Import'!V$2:V672, AG7, 'APS Tubes Import'!H$2:H672, "Negative") -> 23 | AK7: =COUNTIFS('APS Tubes Import'!V$2:V672, AG7, 'APS Tubes Import'!H$2:H672, "Positive") -> 0 | AL7: =COUNTIFS('APS Tubes Import'!V$2:V672, AG7, 'APS Tubes Import'!H$2:H672, "Inconclusive") -> 0 | AM7: =COUNTIFS('APS Tubes Import'!V$2:V672, AG7, 'APS Tubes Import'!H$2:H672, "Null") -> 0 | AO7: ='APS Tubes by Date Import'!B6 -> 44644 | AP7: ='APS Tubes by Date Import'!C6 -> 23 | AQ7: ='APS Tubes by Date Import'!D6 -> 23 | AR7: ='APS Tubes by Date Import'!E6 -> 0 | AS7: ='APS Tubes by Date Import'!F6 -> 0 | AT7: ='APS Tubes by Date Import'!G6 -> 0
A8: RUN-COMB_2022-04-02_RFR-008 | B8: =VLOOKUP(A8,'Run Reconcile'!A$2:B672,2,FALSE) -> 44653 | C8: =COUNTIF('ALL Tube Results'!B7:B672, A8) -> 2 | D8: =COUNTIFS('ALL Tube Results'!$B7:$B672, $A8, 'ALL Tube Results'!$F7:$F672, "Negative") -> 2 | E8: =COUNTIFS('ALL Tube Results'!$B7:$B672, $A8, 'ALL Tube Results'!$F7:$F672, "Positive") -> 0 | F8: =COUNTIFS('ALL Tube Results'!$B7:$B672, $A8, 'ALL Tube Results'!$F7:$F672, "Inconclusive") -> 0 | G8: =IFERROR(VLOOKUP($A8,R$3:T677,3,FALSE),IFERROR(0/0,"") ) -> 2 | H8: =IF($C8=G8,IFERROR(0/0,""),$C8-G8) | I8: =IFERROR(VLOOKUP($A8,Y$3:AA677,3,FALSE),IFERROR(0/0,"") ) -> 6 | J8: =IFERROR(VLOOKUP($A8,Y$3:AD677,5,FALSE),IFERROR(0/0,"") ) -> 0 | K8: =IFERROR(VLOOKUP($A8,Y$3:AD677,6,FALSE),IFERROR(0/0,"")) -> 0 | L8: =IF($C8=I8,IFERROR(0/0,""),$C8-I8) -> -4 | M8: =IF($E8=J8,IFERROR(0/0,""),$E8-J8) | N8: =IF($F8=K8,IFERROR(0/0,""),$F8-K8) | O8: =IFERROR(VLOOKUP($A8,AG$3:AI677,3,FALSE),IFERROR(0/0,"") ) -> 2 | P8: =IF($C8=O8,IFERROR(0/0,""),$C8-O8) | R8: RUN-COMB_2022-04-02_RFR-008 | S8: 44653 | T8: =VLOOKUP(R8,'Run Reconcile'!$A$2:$M672,13,FALSE) -> 2 | U8: =IF(EXACT(A7,R7),IFERROR(0/0,""),FALSE) | Y8: =IFERROR(__xludf.DUMMYFUNCTION("""COMPUTED_VALUE"""),"RUN-COMB_2022-04-02_RFR-008") -> RUN-COMB_2022-04-02_RFR-008 | Z8: =IFERROR(__xludf.DUMMYFUNCTION("""COMPUTED_VALUE"""),44653.0) -> 44653 | AA8: {=INDEX('RFR Data - preExcl'!AK$2:AK672,$AE8,1)} -> 6 | AB8: =AA8-AC8-AD8 -> 6 | AC8: {=INDEX('RFR Data - preExcl'!AI$2:AI672,$AE8,1)} -> 0 | AD8: {=INDEX('RFR Data - preExcl'!AF$2:AF672,$AE8,1)} -> 0 | AE8: =IFNA(MATCH(Y8,'RFR Data - preExcl'!A$2:A672,0),"") -> 8 | AG8: RUN-COMB_2022-04-02_RFR-008 | AH8: =VLOOKUP(AG8,'Run Reconcile'!A$2:B672,2,FALSE) -> 44653 | AI8: =COUNTIF('APS Tubes Import'!$V$2:$V672, AG8) -> 2 | AJ8: =COUNTIFS('APS Tubes Import'!V$2:V672, AG8, 'APS Tubes Import'!H$2:H672, "Negative") -> 2 | AK8: =COUNTIFS('APS Tubes Import'!V$2:V672, AG8, 'APS Tubes Import'!H$2:H672, "Positive") -> 0 | AL8: =COUNTIFS('APS Tubes Import'!V$2:V672, AG8, 'APS Tubes Import'!H$2:H672, "Inconclusive") -> 0 | AM8: =COUNTIFS('APS Tubes Import'!V$2:V672, AG8, 'APS Tubes Import'!H$2:H672, "Null") -> 0 | AO8: ='APS Tubes by Date Import'!B7 -> 44653 | AP8: ='APS Tubes by Date Import'!C7 -> 2 | AQ8: ='APS Tubes by Date Import'!D7 -> 2 | AR8: ='APS Tubes by Date Import'!E7 -> 0 | AS8: ='APS Tubes by Date Import'!F7 -> 0 | AT8: ='APS Tubes by Date Import'!G7 -> 0
A9: RUN-COMB_2022-04-04_RFR-009 | B9: =VLOOKUP(A9,'Run Reconcile'!A$2:B672,2,FALSE) -> 44655 | C9: =COUNTIF('ALL Tube Results'!B8:B672, A9) -> 27 | D9: =COUNTIFS('ALL Tube Results'!$B8:$B672, $A9, 'ALL Tube Results'!$F8:$F672, "Negative") -> 27 | E9: =COUNTIFS('ALL Tube Results'!$B8:$B672, $A9, 'ALL Tube Results'!$F8:$F672, "Positive") -> 0 | F9: =COUNTIFS('ALL Tube Results'!$B8:$B672, $A9, 'ALL Tube Results'!$F8:$F672, "Inconclusive") -> 0 | G9: =IFERROR(VLOOKUP($A9,R$3:T678,3,FALSE),IFERROR(0/0,"") ) -> 27 | H9: =IF($C9=G9,IFERROR(0/0,""),$C9-G9) | I9: =IFERROR(VLOOKUP($A9,Y$3:AA678,3,FALSE),IFERROR(0/0,"") ) -> 27 | J9: =IFERROR(VLOOKUP($A9,Y$3:AD678,5,FALSE),IFERROR(0/0,"") ) -> 0 | K9: =IFERROR(VLOOKUP($A9,Y$3:AD678,6,FALSE),IFERROR(0/0,"")) -> 0 | L9: =IF($C9=I9,IFERROR(0/0,""),$C9-I9) | M9: =IF($E9=J9,IFERROR(0/0,""),$E9-J9) | N9: =IF($F9=K9,IFERROR(0/0,""),$F9-K9) | O9: =IFERROR(VLOOKUP($A9,AG$3:AI678,3,FALSE),IFERROR(0/0,"") ) -> 24 | P9: =IF($C9=O9,IFERROR(0/0,""),$C9-O9) -> 3 | R9: RUN-COMB_2022-04-04_RFR-009 | S9: 44655 | T9: =VLOOKUP(R9,'Run Reconcile'!$A$2:$M672,13,FALSE) -> 27 | U9: =IF(EXACT(A8,R8),IFERROR(0/0,""),FALSE) | Y9: =IFERROR(__xludf.DUMMYFUNCTION("""COMPUTED_VALUE"""),"RUN-COMB_2022-04-04_RFR-009") -> RUN-COMB_2022-04-04_RFR-009 | Z9: =IFERROR(__xludf.DUMMYFUNCTION("""COMPUTED_VALUE"""),44655.0) -> 44655 | AA9: {=INDEX('RFR Data - preExcl'!AK$2:AK672,$AE9,1)} -> 27 | AB9: =AA9-AC9-AD9 -> 27 | AC9: {=INDEX('RFR Data - preExcl'!AI$2:AI672,$AE9,1)} -> 0 | AD9: {=INDEX('RFR Data - preExcl'!AF$2:AF672,$AE9,1)} -> 0 | AE9: =IFNA(MATCH(Y9,'RFR Data - preExcl'!A$2:A672,0),"") -> 9 | AG9: RUN-COMB_2022-04-04_RFR-009 | AH9: =VLOOKUP(AG9,'Run Reconcile'!A$2:B672,2,FALSE) -> 44655 | AI9: =COUNTIF('APS Tubes Import'!$V$2:$V672, AG9) -> 24 | AJ9: =COUNTIFS('APS Tubes Import'!V$2:V672, AG9, 'APS Tubes Import'!H$2:H672, "Negative") -> 24 | AK9: =COUNTIFS('APS Tubes Import'!V$2:V672, AG9, 'APS Tubes Import'!H$2:H672, "Positive") -> 0 | AL9: =COUNTIFS('APS Tubes Import'!V$2:V672, AG9, 'APS Tubes Import'!H$2:H672, "Inconclusive") -> 0 | AM9: =COUNTIFS('APS Tubes Import'!V$2:V672, AG9, 'APS Tubes Import'!H$2:H672, "Null") -> 0 | AO9: ='APS Tubes by Date Import'!B8 -> 44655 | AP9: ='APS Tubes by Date Import'!C8 -> 24 | AQ9: ='APS Tubes by Date Import'!D8 -> 24 | AR9: ='APS Tubes by Date Import'!E8 -> 0 | AS9: ='APS Tubes by Date Import'!F8 -> 0 | AT9: ='APS Tubes by Date Import'!G8 -> 0
