Workbook
Name nondeleteRange: #REF!

Sheet Stats
A1: NONE | B1: RFR File
A2: NONE | B2: RTR File
A3: ROSA_RSR_deID_PUB | B3: RSR File | N3: 46036.529
B4: Overall | C4: Details | D4: Comments | M4: =COUNTIF(M5:M1032, FALSE) -> 2 | N4: VALUES
A5: =COUNTA('APS Tubes'!A2:A1032) -> 781 | B5: Number of Tubes Tested (initial only - no re-runs) | C5: initial run tubes only so excludes re-runs | D5: only indiv testing - no pools. total 785 from RSR - Run Summary Report that draws from google form of weekly testing summary provided by test Admin | M5: =IF(NOT(ISBLANK(N5)),A5=N5,IFERROR(0/0,"")) -> TRUE | N5: 781
A6: =A5 -> 781 | B6: Number of Tube Tests Run (includes re-runs) | C6: includes re-runs | D6: no RFR so no info on re-runs | M6: =IF(NOT(ISBLANK(N6)),A6=N6,IFERROR(0/0,"")) -> TRUE | N6: 781
A7: =COUNTA('APS Tubes by Date'!A2:A1032) -> 53 | B7: Number of Initial Runs | D7: use collection date assuming all tubes run same day | M7: =IF(NOT(ISBLANK(N7)),A7=N7,IFERROR(0/0,"")) -> TRUE | N7: 53
A8: =A5 -> 781 | B8: Number of APS Only Tubes run | D8: No RFR so all tubes are APS Only | M8: =IF(NOT(ISBLANK(N8)),A8=N8,IFERROR(0/0,"")) -> TRUE | N8: 781
A9: =A5 -> 781 | B9: Number of Test Reactions (RFR plus APS only tubes run) | C9: includes technical replicates (the same tube sample in multiple reactions in the same run) | M9: =IF(NOT(ISBLANK(N9)),A9=N9,IFERROR(0/0,"")) -> TRUE | N9: 781
M10: =IF(NOT(ISBLANK(N10)),A10=N10,IFERROR(0/0,""))
A11: =COUNTA(postDEL!A2:A1032) -> 781 | B11: Number of Participant Results | C11: counts individual samples in pools and excludes re-runs | M11: =IF(NOT(ISBLANK(N11)),A11=N11,IFERROR(0/0,"")) -> TRUE | N11: 781
A12: 0 | B12: Number of ARF Tubes | C12: tubes run and present in RFR but not in Appivo - created tube IDs that start with ARF | M12: =IF(NOT(ISBLANK(N12)),A12=N12,IFERROR(0/0,"")) -> TRUE | N12: 0
A13: =A12+A11 -> 781 | B13: Sum of Participant Results plus ARF Tubes | C13: Will be equal to the number of tubes tested if no pooling. | M13: =IF(NOT(ISBLANK(N13)),A13=N13,IFERROR(0/0,"")) -> TRUE | N13: 781
A14: 1 | B14: Average Pool Level (excludes ARF) | M14: =IF(NOT(ISBLANK(N14)),A14=N14,IFERROR(0/0,"")) -> TRUE | N14: 1
M15: =IF(NOT(ISBLANK(N15)),A15=N15,IFERROR(0/0,""))
B16: Re-runs | C16: section | M16: =IF(NOT(ISBLANK(N16)),A16=N16,IFERROR(0/0,""))
B17: Number of Run Tubes (re-runs only) | C17: from RFR Audit Num Run Tubes | M17: =IF(NOT(ISBLANK(N17)),A17=N17,IFERROR(0/0,""))
B18: Number of Reactions (re-runs only) | C18: from RFR Audit Num rxns (excl ctrls) | M18: =IF(NOT(ISBLANK(N18)),A18=N18,IFERROR(0/0,""))
B19: Re-run % of Tubes | C19: re-run / initial | M19: =IF(NOT(ISBLANK(N19)),A19=N19,IFERROR(0/0,""))
B20: Number of Initial Runs with Re-runs | M20: =IF(NOT(ISBLANK(N20)),A20=N20,IFERROR(0/0,""))
B21: % Initial Runs with Re-runs | M21: =IF(NOT(ISBLANK(N21)),A21=N21,IFERROR(0/0,""))
M22: =IF(NOT(ISBLANK(N22)),A22=N22,IFERROR(0/0,""))
B23: Positives | C23: section | F23: Number of Tubes with FL Result | G23: Number of Test Person Cases | H23: Number with Ref or Corresp | I23: Agree with Ref or Corresp | J23: % Agree | K23: Disagree with Ref or Corresp | L23: % Disagree | M23: =IF(NOT(ISBLANK(N23)),A23=N23,IFERROR(0/0,""))
A24: =COUNTIF('Pos and Incl'!H$2:H1032,"Positive") -> 1 | B24: Number of Tubes with Final Result Positive | E24: Positive | F24: 1 | G24: =A26 -> 1 | H24: 1 | I24: =A45 -> 1 | J24: =IF(H24<>0,I24/H24,IFERROR(0/0,"")) -> 1 | K24: 0 | L24: =IF(H24<>0,K24/H24,IFERROR(0/0,"")) -> 0 | M24: =IF(NOT(ISBLANK(N24)),A24=N24,IFERROR(0/0,"")) -> TRUE | N24: 1
A25: =A24/A$5 -> 0.0012804097 | B25: % of Tubes Positives (Final Result) | M25: =IF(NOT(ISBLANK(N25)),A25=N25,IFERROR(0/0,"")) -> TRUE | N25: 0.0012804097
A26: =A24-'Pos and Incl'!Z36 -> 1 | B26: Number of Cases with Final Result Positive (Indiv or Pool) | C26: Subtract off Re-tests | I26: Ref/Cor Pos | J26: % Incl > Pos | K26: Ref/Cor Neg | L26: % Incl > Neg | M26: =IF(NOT(ISBLANK(N26)),A26=N26,IFERROR(0/0,"")) -> TRUE | N26: 1
A27: =COUNTIF('Pos and Incl'!Y$2:Y$20,TRUE) -> 0 | B27: Known Positive Cases | C27: Previous tested (including by FloodLAMP test) or reported positive | E27: Inconclusive | F27: =A33 -> 0 | G27: =F27 -> 0 | H27: =G27-'Pos and Incl'!Z33 -> 0 | I27: =A46 -> 0 | J27: =IF(H27<>0,I27/H27,IFERROR(0/0,"")) | K27: 0 | L27: =IF(H27<>0,K27/H27,IFERROR(0/0,"")) | M27: =IF(NOT(ISBLANK(N27)),A27=N27,IFERROR(0/0,"")) -> TRUE | N27: 0
A28: =A26-A27 -> 1 | B28: Unknown Positive Cases | M28: =IF(NOT(ISBLANK(N28)),A28=N28,IFERROR(0/0,"")) -> TRUE | N28: 1
M29: =IF(NOT(ISBLANK(N29)),A29=N29,IFERROR(0/0,""))
B30: Inconclusives | C30: section | M30: =IF(NOT(ISBLANK(N30)),A30=N30,IFERROR(0/0,""))
A31: =COUNTIF('Pos and Incl'!H$2:H1032,"Inconclusive") -> 0 | B31: Number of Tubes with Final Result Inconclusive | D31: from RSR - Run Summary Report that draws from google form of weekly testing summary provided by test Admin | M31: =IF(NOT(ISBLANK(N31)),A31=N31,IFERROR(0/0,"")) -> TRUE | N31: 0
B32: Number of Tubes in RFR Audit Inconclusive not in Appivo Final Results | D32: Not Applicable - No RFR | M32: =IF(NOT(ISBLANK(N32)),A32=N32,IFERROR(0/0,""))
A33: =A32+A31 -> 0 | B33: Total Number of Inconclusive Tubes | M33: =IF(NOT(ISBLANK(N33)),A33=N33,IFERROR(0/0,"")) -> TRUE | N33: 0
A34: =A33/A$5 -> 0 | B34: % of Tubes Inconclusive | M34: =IF(NOT(ISBLANK(N34)),A34=N34,IFERROR(0/0,"")) -> TRUE | N34: 0
A35: 0 | B35: Number of Inconclusive Tubes resolved Positive by Referral Test or Correspondence | M35: =IF(NOT(ISBLANK(N35)),A35=N35,IFERROR(0/0,"")) -> TRUE | N35: 0
A36: =IF(A33<>0,A35/A33,IFERROR(0/0,"")) | B36: % Inconclusives resolved Positive by Referral Tests | D36: denom zero | M36: =IF(NOT(ISBLANK(N36)),A36=N36,IFERROR(0/0,""))
A37: 0 | B37: Number of Inconclusive Tubes with Referral Test or Correspondence Negative | M37: =IF(NOT(ISBLANK(N37)),A37=N37,IFERROR(0/0,"")) -> TRUE | N37: 0
A38: =A33-A35-A37 -> 0 | B38: Number of Inconclusive Tubes with no Referral Test result or Correspondence | M38: =IF(NOT(ISBLANK(N38)),A38=N38,IFERROR(0/0,"")) -> TRUE | N38: 0
A39: =Weekly!R16 -> 1 | B39: Number of Tubes with Initial Inconclusives and Re-run Negative | C39: Count Result Correction Code=2.5 in preDel col AJ, or from RFR preExcl if not resulted as Incl in App | M39: =IF(NOT(ISBLANK(N39)),A39=N39,IFERROR(0/0,"")) -> TRUE | N39: 1
A40: =A39 -> 1 | B40: Number of Inconclusive Test Run Calls | C40: includes re-runs - from RFR Audit only and excludes any APS only resulted inconclusives | M40: =IF(NOT(ISBLANK(N40)),A40=N40,IFERROR(0/0,"")) -> TRUE | N40: 1
...

Sheet Weekly
A1: Week Start Date | B1: Week End Date | C1: =CONCATENATE("Weekly Participants ",SUM(C2:C14)) -> Weekly Participants 781 | D1: =CONCATENATE("Weekly Tubes Run ",SUM(D2:D14)) -> Weekly Tubes Run 781 | E1: =CONCATENATE("Weekly Positive Tubes ",SUM(E2:E14)) -> Weekly Positive Tubes 1 | F1: =CONCATENATE("Weekly Inconclusive Tubes ",SUM(F2:F14)) -> Weekly Inconclusive Tubes 0 | G1: % Positive | H1: Delta Participants | I1: Delta Tubes (Pools) | J1: Delta Positives | K1: Delta Inconclusives | L1: Date Start | M1: Date End | N1: Participants Tested | O1: Sample Tubes Run (Pools) | P1: Unknown Positives | Q1: Known Positives | R1: Inconclusives on 1st Run | S1: Inconclusives Final | T1: Use App for Collection? | U1: Comments
A2: =MIN('APS Tubes'!B:B) - WEEKDAY(MIN('APS Tubes'!B:B), 3) -> 44466 | B2: =A2+6 -> 44472 | C2: =SUMIFS('APS Tubes'!$N$2:$N99, 'APS Tubes'!B$2:B99, ">="&A2, 'APS Tubes'!B$2:B99, "<="&B2) -> 17 | D2: =COUNTIFS('APS Tubes'!B:B, ">="&A2, 'APS Tubes'!B:B, "<="&B2) -> 17 | E2: =COUNTIFS('APS Tubes'!B:B, ">="&A2, 'APS Tubes'!B:B, "<="&B2, 'APS Tubes'!H:H, "Positive") -> 0 | F2: =COUNTIFS('APS Tubes'!B:B, ">="&A2, 'APS Tubes'!B:B, "<="&B2, 'APS Tubes'!H:H, "Inconclusive") -> 0 | G2: =IFERROR(E2/D2,IFERROR(0/0,"")) -> 0 | H2: =C2-N2 -> 17 | I2: =D2-O2 -> 17 | J2: =E2-P2-Q2 -> 0 | K2: =F2-S2 -> 0
A3: =B2+1 -> 44473 | B3: =A3+6 -> 44479 | C3: =SUMIFS('APS Tubes'!$N$2:$N99, 'APS Tubes'!B$2:B99, ">="&A3, 'APS Tubes'!B$2:B99, "<="&B3) -> 84 | D3: =COUNTIFS('APS Tubes'!B:B, ">="&A3, 'APS Tubes'!B:B, "<="&B3) -> 84 | E3: =COUNTIFS('APS Tubes'!B:B, ">="&A3, 'APS Tubes'!B:B, "<="&B3, 'APS Tubes'!H:H, "Positive") -> 0 | F3: =COUNTIFS('APS Tubes'!B:B, ">="&A3, 'APS Tubes'!B:B, "<="&B3, 'APS Tubes'!H:H, "Inconclusive") -> 0 | G3: =IFERROR(E3/D3,IFERROR(0/0,"")) -> 0 | H3: =C3-N3 -> -3 | I3: =D3-O3 -> -3 | J3: =E3-P3-Q3 -> 0 | K3: =F3-S3 -> 0 | L3: 44473 | M3: 44477 | N3: 87 | O3: 87 | P3: 0 | Q3: 0 | R3: 0 | S3: 0 | T3: No | U3: Week of 10/4-10/8
A4: =B3+1 -> 44480 | B4: =A4+6 -> 44486 | C4: =SUMIFS('APS Tubes'!$N$2:$N99, 'APS Tubes'!B$2:B99, ">="&A4, 'APS Tubes'!B$2:B99, "<="&B4) -> 79 | D4: =COUNTIFS('APS Tubes'!B:B, ">="&A4, 'APS Tubes'!B:B, "<="&B4) -> 79 | E4: =COUNTIFS('APS Tubes'!B:B, ">="&A4, 'APS Tubes'!B:B, "<="&B4, 'APS Tubes'!H:H, "Positive") -> 0 | F4: =COUNTIFS('APS Tubes'!B:B, ">="&A4, 'APS Tubes'!B:B, "<="&B4, 'APS Tubes'!H:H, "Inconclusive") -> 0 | G4: =IFERROR(E4/D4,IFERROR(0/0,"")) -> 0 | H4: =C4-N4 -> 0 | I4: =D4-O4 -> 0 | J4: =E4-P4-Q4 -> 0 | K4: =F4-S4 -> 0 | L4: 44480 | M4: 44484 | N4: 79 | O4: 79 | P4: 0 | Q4: 0 | R4: 0 | S4: 0 | T4: Yes | U4: 10/11/21-10/15/21
A5: =B4+1 -> 44487 | B5: =A5+6 -> 44493 | C5: =SUMIFS('APS Tubes'!$N$2:$N99, 'APS Tubes'!B$2:B99, ">="&A5, 'APS Tubes'!B$2:B99, "<="&B5) -> 64 | D5: =COUNTIFS('APS Tubes'!B:B, ">="&A5, 'APS Tubes'!B:B, "<="&B5) -> 64 | E5: =COUNTIFS('APS Tubes'!B:B, ">="&A5, 'APS Tubes'!B:B, "<="&B5, 'APS Tubes'!H:H, "Positive") -> 0 | F5: =COUNTIFS('APS Tubes'!B:B, ">="&A5, 'APS Tubes'!B:B, "<="&B5, 'APS Tubes'!H:H, "Inconclusive") -> 0 | G5: =IFERROR(E5/D5,IFERROR(0/0,"")) -> 0 | H5: =C5-N5 -> -3 | I5: =D5-O5 -> -3 | J5: =E5-P5-Q5 -> 0 | K5: =F5-S5 -> 0 | L5: 44487 | M5: 44491 | N5: 67 | O5: 67 | P5: 0 | Q5: 0 | R5: 0 | S5: 0 | T5: Yes | U5: Production Company 10/18/21-10/22/21 Run by Davie Fire
A6: =B5+1 -> 44494 | B6: =A6+6 -> 44500 | C6: =SUMIFS('APS Tubes'!$N$2:$N99, 'APS Tubes'!B$2:B99, ">="&A6, 'APS Tubes'!B$2:B99, "<="&B6) -> 53 | D6: =COUNTIFS('APS Tubes'!B:B, ">="&A6, 'APS Tubes'!B:B, "<="&B6) -> 53 | E6: =COUNTIFS('APS Tubes'!B:B, ">="&A6, 'APS Tubes'!B:B, "<="&B6, 'APS Tubes'!H:H, "Positive") -> 0 | F6: =COUNTIFS('APS Tubes'!B:B, ">="&A6, 'APS Tubes'!B:B, "<="&B6, 'APS Tubes'!H:H, "Inconclusive") -> 0 | G6: =IFERROR(E6/D6,IFERROR(0/0,"")) -> 0 | H6: =C6-N6 -> -7 | I6: =D6-O6 -> -7 | J6: =E6-P6-Q6 -> 0 | K6: =F6-S6 -> 0 | L6: 44494 | M6: 44498 | N6: 60 | O6: 60 | P6: 0 | Q6: 0 | R6: 0 | S6: 0 | T6: Yes | U6: Production Company 10/25/21-10/29/21 run by Davie Fire
A7: =B6+1 -> 44501 | B7: =A7+6 -> 44507 | C7: =SUMIFS('APS Tubes'!$N$2:$N99, 'APS Tubes'!B$2:B99, ">="&A7, 'APS Tubes'!B$2:B99, "<="&B7) -> 68 | D7: =COUNTIFS('APS Tubes'!B:B, ">="&A7, 'APS Tubes'!B:B, "<="&B7) -> 68 | E7: =COUNTIFS('APS Tubes'!B:B, ">="&A7, 'APS Tubes'!B:B, "<="&B7, 'APS Tubes'!H:H, "Positive") -> 0 | F7: =COUNTIFS('APS Tubes'!B:B, ">="&A7, 'APS Tubes'!B:B, "<="&B7, 'APS Tubes'!H:H, "Inconclusive") -> 0 | G7: =IFERROR(E7/D7,IFERROR(0/0,"")) -> 0 | H7: =C7-N7 -> -4 | I7: =D7-O7 -> -4 | J7: =E7-P7-Q7 -> 0 | K7: =F7-S7 -> 0 | L7: 44501 | M7: 44505 | N7: 72 | O7: 72 | P7: 0 | Q7: 0 | R7: 0 | S7: 0 | T7: Yes | U7: 11/1/21-11/5/21 Production company run by Davie Fire
A8: =B7+1 -> 44508 | B8: =A8+6 -> 44514 | C8: =SUMIFS('APS Tubes'!$N$2:$N99, 'APS Tubes'!B$2:B99, ">="&A8, 'APS Tubes'!B$2:B99, "<="&B8) -> 64 | D8: =COUNTIFS('APS Tubes'!B:B, ">="&A8, 'APS Tubes'!B:B, "<="&B8) -> 64 | E8: =COUNTIFS('APS Tubes'!B:B, ">="&A8, 'APS Tubes'!B:B, "<="&B8, 'APS Tubes'!H:H, "Positive") -> 0 | F8: =COUNTIFS('APS Tubes'!B:B, ">="&A8, 'APS Tubes'!B:B, "<="&B8, 'APS Tubes'!H:H, "Inconclusive") -> 0 | G8: =IFERROR(E8/D8,IFERROR(0/0,"")) -> 0 | H8: =C8-N8 -> 2 | I8: =D8-O8 -> 2 | J8: =E8-P8-Q8 -> 0 | K8: =F8-S8 -> 0 | L8: 44508 | M8: 44512 | N8: 62 | O8: 62 | P8: 0 | Q8: 0 | R8: 0 | S8: 0 | T8: Yes | U8: 11/8-11/12 Production Crew done by Davie Fire
A9: =B8+1 -> 44515 | B9: =A9+6 -> 44521 | C9: =SUMIFS('APS Tubes'!$N$2:$N99, 'APS Tubes'!B$2:B99, ">="&A9, 'APS Tubes'!B$2:B99, "<="&B9) -> 76 | D9: =COUNTIFS('APS Tubes'!B:B, ">="&A9, 'APS Tubes'!B:B, "<="&B9) -> 76 | E9: =COUNTIFS('APS Tubes'!B:B, ">="&A9, 'APS Tubes'!B:B, "<="&B9, 'APS Tubes'!H:H, "Positive") -> 0 | F9: =COUNTIFS('APS Tubes'!B:B, ">="&A9, 'APS Tubes'!B:B, "<="&B9, 'APS Tubes'!H:H, "Inconclusive") -> 0 | G9: =IFERROR(E9/D9,IFERROR(0/0,"")) -> 0 | H9: =C9-N9 -> 1 | I9: =D9-O9 -> 1 | J9: =E9-P9-Q9 -> 0 | K9: =F9-S9 -> 0 | L9: 44515 | M9: 44519 | N9: 75 | O9: 75 | P9: 0 | Q9: 0 | R9: 0 | S9: 0 | T9: Yes | U9: Production Company 11/15-11/19 Done by Davie Fire
A10: =B9+1 -> 44522 | B10: =A10+6 -> 44528 | C10: =SUMIFS('APS Tubes'!$N$2:$N99, 'APS Tubes'!B$2:B99, ">="&A10, 'APS Tubes'!B$2:B99, "<="&B10) -> 36 | D10: =COUNTIFS('APS Tubes'!B:B, ">="&A10, 'APS Tubes'!B:B, "<="&B10) -> 36 | E10: =COUNTIFS('APS Tubes'!B:B, ">="&A10, 'APS Tubes'!B:B, "<="&B10, 'APS Tubes'!H:H, "Positive") -> 0 | F10: =COUNTIFS('APS Tubes'!B:B, ">="&A10, 'APS Tubes'!B:B, "<="&B10, 'APS Tubes'!H:H, "Inconclusive") -> 0 | G10: =IFERROR(E10/D10,IFERROR(0/0,"")) -> 0 | H10: =C10-N10 -> 1 | I10: =D10-O10 -> 1 | J10: =E10-P10-Q10 -> 0 | K10: =F10-S10 -> 0 | L10: 44522 | M10: 44526 | N10: 35 | O10: 35 | P10: 0 | Q10: 0 | R10: 0 | S10: 0 | T10: Yes | U10: 11/22-11/26 Production Company via Davie Fire
A11: =B10+1 -> 44529 | B11: =A11+6 -> 44535 | C11: =SUMIFS('APS Tubes'!$N$2:$N99, 'APS Tubes'!B$2:B99, ">="&A11, 'APS Tubes'!B$2:B99, "<="&B11) -> 59 | D11: =COUNTIFS('APS Tubes'!B:B, ">="&A11, 'APS Tubes'!B:B, "<="&B11) -> 59 | E11: =COUNTIFS('APS Tubes'!B:B, ">="&A11, 'APS Tubes'!B:B, "<="&B11, 'APS Tubes'!H:H, "Positive") -> 0 | F11: =COUNTIFS('APS Tubes'!B:B, ">="&A11, 'APS Tubes'!B:B, "<="&B11, 'APS Tubes'!H:H, "Inconclusive") -> 0 | G11: =IFERROR(E11/D11,IFERROR(0/0,"")) -> 0 | H11: =C11-N11 -> -6 | I11: =D11-O11 -> -6 | J11: =E11-P11-Q11 -> 0 | K11: =F11-S11 -> 0 | L11: 44529 | M11: 44533 | N11: 65 | O11: 65 | P11: 0 | Q11: 0 | R11: 0 | S11: 0 | T11: Yes | U11: Production Crew tested via Davie Fire 11/29-12/3
A12: =B11+1 -> 44536 | B12: =A12+6 -> 44542 | C12: =SUMIFS('APS Tubes'!$N$2:$N99, 'APS Tubes'!B$2:B99, ">="&A12, 'APS Tubes'!B$2:B99, "<="&B12) -> 84 | D12: =COUNTIFS('APS Tubes'!B:B, ">="&A12, 'APS Tubes'!B:B, "<="&B12) -> 84 | E12: =COUNTIFS('APS Tubes'!B:B, ">="&A12, 'APS Tubes'!B:B, "<="&B12, 'APS Tubes'!H:H, "Positive") -> 0 | F12: =COUNTIFS('APS Tubes'!B:B, ">="&A12, 'APS Tubes'!B:B, "<="&B12, 'APS Tubes'!H:H, "Inconclusive") -> 0 | G12: =IFERROR(E12/D12,IFERROR(0/0,"")) -> 0 | H12: =C12-N12 -> -3 | I12: =D12-O12 -> -3 | J12: =E12-P12-Q12 -> 0 | K12: =F12-S12 -> 0 | L12: 44536 | M12: 44540 | N12: 87 | O12: 87 | P12: 0 | Q12: 0 | R12: 0 | S12: 0 | T12: Yes | U12: Production Company by Davie Fire 12/6-12/10
A13: =B12+1 -> 44543 | B13: =A13+6 -> 44549 | C13: =SUMIFS('APS Tubes'!$N$2:$N99, 'APS Tubes'!B$2:B99, ">="&A13, 'APS Tubes'!B$2:B99, "<="&B13) -> 97 | D13: =COUNTIFS('APS Tubes'!B:B, ">="&A13, 'APS Tubes'!B:B, "<="&B13) -> 97 | E13: =COUNTIFS('APS Tubes'!B:B, ">="&A13, 'APS Tubes'!B:B, "<="&B13, 'APS Tubes'!H:H, "Positive") -> 1 | F13: =COUNTIFS('APS Tubes'!B:B, ">="&A13, 'APS Tubes'!B:B, "<="&B13, 'APS Tubes'!H:H, "Inconclusive") -> 0 | G13: =IFERROR(E13/D13,IFERROR(0/0,"")) -> 0.010309278 | H13: =C13-N13 -> 1 | I13: =D13-O13 -> 1 | J13: =E13-P13-Q13 -> 0 | K13: =F13-S13 -> 0 | L13: 44543 | M13: 44547 | N13: 96 | O13: 96 | P13: 1 | Q13: 0 | R13: 1 | S13: 0 | T13: Yes | U13: 12/13-12/17
B16: APS TOTALS | C16: =SUM(C2:C13) -> 781 | D16: =SUM(D2:D13) -> 781 | E16: =SUM(E2:E13) -> 1 | F16: =SUM(F2:F13) -> 0 | H16: =C16-O16 -> -4 | I16: =D16-N16 -> -4 | J16: =E16-P16 -> 0 | K16: =F16-S16 -> 0 | M16: RSR TOTALS | N16: =SUM(N2:N13) -> 785 | O16: =SUM(O2:O13) -> 785 | P16: =SUM(P2:P13) -> 1 | Q16: =SUM(Q2:Q13) -> 0 | R16: =SUM(R2:R13) -> 1

Sheet Pos and Incl
A1: {='APS Tubes'!A1:O1} -> TUBE ID | B1: COLLECTION DATE | C1: COLLECTION TIME | D1: SPONSOR PERSON ID | E1: SPONSOR FIRSTNAME | F1: SPONSOR LASTNAME | G1: APP RESULT | H1: FINAL RESULT | I1: RESULT DATE | J1: RESULT TIME | K1: Result Correct Code | L1: Correction Notes | M1: NOTE | N1: NUM SAMPLES (Pool Level) | O1: Match Row | P1: Sample Person1 | Q1: Sample Person2 | R1: Sample Person3 | S1: Sample Person4 | T1: Referral Eval Notes | U1: =CONCATENATE(COUNTIF(U2:U2182,TRUE), " ACCOUNTED FOR IN RTR?") -> 1 ACCOUNTED FOR IN RTR? | V1: Re-test? | W1: Correspondence but no Referral Test | X1: Agreement with Referral or Correspondence? | Y1: Known Positive (not Re-test)? | Z1: =CONCATENATE(SUM(Z2:Z5), " Check") -> 0 Check | AA1: FloodLAMP Result Eval
A2: =IFERROR(__xludf.DUMMYFUNCTION("{ IFERROR( FILTER('APS Tubes'!A2:O2182,EXACT('APS Tubes'!H2:H2182,""Positive"")), {IFERROR(0/0),IFERROR(0/0),IFERROR(0/0),IFERROR(0/0),IFERROR(0/0),IFERROR(0/0),IFERROR(0/0),IFERROR(0/0),IFERROR(0/0),IFERROR(0/0),IFERROR(0/0),IFERROR(0/0),IFERRO"&"R(0/0),IFERROR(0/0),IFERROR(0/0)} ); IFERROR( FILTER('APS Tubes'!A2:O2182,EXACT('APS Tubes'!H2:H2182,""Inconclusive"")), {IFERROR(0/0),IFERROR(0/0),IFERROR(0/0),IFERROR(0/0),IFERROR(0/0),IFERROR(0/0),IFERROR(0/0),IFERROR(0/0),IFERROR(0/0),IFER"&"ROR(0/0),IFERROR(0/0),IFERROR(0/0),IFERROR(0/0),IFERROR(0/0),IFERROR(0/0)} ) }"),"FLB3372") -> FLB3372 | B2: =IFERROR(__xludf.DUMMYFUNCTION("""COMPUTED_VALUE"""),44543.0) -> 44543 | C2: =IFERROR(__xludf.DUMMYFUNCTION("""COMPUTED_VALUE"""),0.1517013888888889) -> 0.15170139 | D2: =IFERROR(__xludf.DUMMYFUNCTION("""COMPUTED_VALUE"""),"SpROSA145068") -> SpROSA145068 | G2: =IFERROR(__xludf.DUMMYFUNCTION("""COMPUTED_VALUE"""),"Positive") -> Positive | H2: =IFERROR(__xludf.DUMMYFUNCTION("""COMPUTED_VALUE"""),"Positive") -> Positive | I2: =IFERROR(__xludf.DUMMYFUNCTION("""COMPUTED_VALUE"""),44543.0) -> 44543 | J2: =IFERROR(__xludf.DUMMYFUNCTION("""COMPUTED_VALUE"""),0.5098032407407408) -> 0.50980324 | N2: =IFERROR(__xludf.DUMMYFUNCTION("""COMPUTED_VALUE"""),1.0) -> 1 | O2: =IFERROR(__xludf.DUMMYFUNCTION("""COMPUTED_VALUE"""),689.0) -> 689 | P2: {=INDEX(postDEL!$A$2:$AR2182,$O2,40)} -> ROSA970910 | Q2: {=IF($N2>1, INDEX(postDEL!$A$2:$AR2182,$O2+1,40),IFERROR(0/0,""))} | R2: {=IF($N2>2, INDEX(postDEL!$A$2:$AR2182,$O2+2,40),IFERROR(0/0,""))} | S2: {=IF($N2>3, INDEX(postDEL!$A$2:$AR2182,$O2+3,40),IFERROR(0/0,""))} | U2: TRUE | AA2: No Referral Test or Correspondence - FL Positive
Z7: =COUNTA(U2:U5) -> 1 | AA7: Number of Rows
Q8: {=IF($N8>1, INDEX(postDEL!$A$2:$AR2182,$O8+1,44),IFERROR(0/0,""))} | R8: {=IF($N8>2, INDEX(postDEL!$A$2:$AR2182,$O8+2,44),IFERROR(0/0,""))} | S8: {=IF($N8>3, INDEX(postDEL!$A$2:$AR2182,$O8+3,44),IFERROR(0/0,""))} | Z8: =COUNTIF(U2:U5,TRUE) -> 1 | AA8: Number of FL Tests (Final Results / Run Tests) Accounted for in Referral Tests (RTR)
Z9: =COUNTIF(W2:W5,TRUE) -> 0 | AA9: Number of FL Tests (Final Results / Run Tests) with Correspondence Only (no Referral Test Data put into RTR)
Z11: =Z8+Z9-Z22 -> 1 | AA11: Number of FloodLAMP Test Person Cases with Referral Tests or Correspondence | AB11: Final Results / Run Tests becomes Test Person Cases when you subtract Re-tests because those re-tests are for the same person on a day that's differnt but colse enough to the first test date ( a few days to a week apart) that it's the same case of COVID for that person.
Z12: 0 | AA12: Agree Positives
Z13: 0 | AA13: FL Inconclusives with Referal / Correspondence Positive
Z14: 0 | AA14: Disagree FL Positives but Referral / Correspondence Negative (FL False Positive)
Z15: 0 | AA15: FL Inconclusives but Referral / Correspondence Negative
Z18: =Z7-Z8-Z9 -> 0 | AA18: Number of FL Tests (Final Results / Run Tests) with No Referral Tests or Correspondence
Z19: 1 | AA19: FL Positives with No Referral Tests or Correspondence
Z20: 1 | AA20: FL Inconclusives with No Referral Tests or Correspondence
Z22: =COUNTIF(V$2:V5,TRUE) -> 0 | AA22: Number of Re-tests
Z23: =COUNTIF(V$2:V4,TRUE) -> 0 | AA23: Number of Re-tests Positive
Z24: =COUNTIF(V5,TRUE) -> 0 | AA24: Number of Re-tests Inconclusive
Q27: {=IF($N27>1, INDEX(postDEL!$A$2:$AR2182,$O27+1,44),IFERROR(0/0,""))} | R27: {=IF($N27>2, INDEX(postDEL!$A$2:$AR2182,$O27+2,44),IFERROR(0/0,""))} | S27: {=IF($N27>3, INDEX(postDEL!$A$2:$AR2182,$O27+3,44),IFERROR(0/0,""))}
Q28: {=IF($N28>1, INDEX(postDEL!$A$2:$AR2182,$O28+1,44),IFERROR(0/0,""))} | R28: {=IF($N28>2, INDEX(postDEL!$A$2:$AR2182,$O28+2,44),IFERROR(0/0,""))} | S28: {=IF($N28>3, INDEX(postDEL!$A$2:$AR2182,$O28+3,44),IFERROR(0/0,""))}
Q29: {=IF($N29>1, INDEX(postDEL!$A$2:$AR2182,$O29+1,44),IFERROR(0/0,""))} | R29: {=IF($N29>2, INDEX(postDEL!$A$2:$AR2182,$O29+2,44),IFERROR(0/0,""))} | S29: {=IF($N29>3, INDEX(postDEL!$A$2:$AR2182,$O29+3,44),IFERROR(0/0,""))}
Q30: {=IF($N30>1, INDEX(postDEL!$A$2:$AR2182,$O30+1,44),IFERROR(0/0,""))} | R30: {=IF($N30>2, INDEX(postDEL!$A$2:$AR2182,$O30+2,44),IFERROR(0/0,""))} | S30: {=IF($N30>3, INDEX(postDEL!$A$2:$AR2182,$O30+3,44),IFERROR(0/0,""))}
Q31: {=IF($N31>1, INDEX(postDEL!$A$2:$AR2182,$O31+1,44),IFERROR(0/0,""))} | R31: {=IF($N31>2, INDEX(postDEL!$A$2:$AR2182,$O31+2,44),IFERROR(0/0,""))} | S31: {=IF($N31>3, INDEX(postDEL!$A$2:$AR2182,$O31+3,44),IFERROR(0/0,""))}

Sheet preDEL
A1: TUBE ID | B1: COLLECTION DATE | C1: COLLECTION TIME | D1: SPONSOR FIRSTNAME | E1: SPONSOR LASTNAME | F1: PARTICIPANT FIRSTNAME | G1: PARTICIPANT LASTNAME | H1: PARTICIPANT EMAIL | I1: MINOR FIRSTNAME | J1: MINOR LASTNAME | K1: APP RESULT | L1: RESULT DATE | M1: RESULT TIME | N1: APP GROUP | O1: NOTE | P1: REPS IN RAW_APT? | Q1: STATUS | R1: Tube ID First Row? | S1: Num Tube IDs | T1: Add N Names | U1: NOTE FIRSTNAME | V1: NOTE LASTNAME | W1: Names Adjust | X1: =IF(ISNA(MATCH("ER - LAST ONLY",$X$2:$X808,0)),"Note Name?","ERROR!! Note Name?") -> Note Name? | Y1: FRAN | Z1: >4 Samples | AA1: Has Note? | AB1: Preserve Note | AC1: Initial Order | AD1: Added from APT? | AE1: Minutes Col to Result | AF1: =IF(COUNTIF($AF2:$AF808,TRUE)=0,"Tube IDs w Diff Times?",CONCATENATE("ERROR!! Tube IDs w Diff Times? ",COUNTIF($AF2:$AF808,TRUE))) -> Tube IDs w Diff Times? | AG1: Delete? | AH1: Delete Code | AI1: Basic Correct Code | AJ1: Result Correct Code | AK1: FINAL RESULT | AL1: Correction Notes | AM1: Sponsor ID | AN1: Participant ID | AO1: Sponsor FullName | AP1: Combined Participant Firstname | AQ1: Combined Participant Lastname | AR1: Combined Participant Fullname | AS1: FINAL GROUP | AT1: =(IF(COUNTIF($AT2:$AT808,FALSE)=0,"NAME COLS CHECK?",CONCATENATE("ERROR!! NAME COLS CHECK? ",COUNTIF($AT2:$AT808,FALSE)))) -> ERROR!! NAME COLS CHECK? 781 | AU1: PARTCIP NAME COLS | AV1: MINOR NAME COLS | AW1: NOTE NAME COLS | AX1: Note Name Extras - Rows Added Not Orig Tube ID Row | AY1: =SUM($AX2:$AX808) -> 0 | AZ1: END | BA1: =CONCATENATE("CURRENT BOOL TRUE = ",COUNTIF(BA$2:BA808,TRUE)) -> CURRENT BOOL TRUE = 0 | BB1: CURRENT BOOL TRUE = 2 | BC1: CURRENT BOOL TRUE = 0 | BD1: Rep Cols | BE1: =CONCATENATE("Rep Tube IDs Sorted = ",COUNTA(BL3:BL808)) -> Rep Tube IDs Sorted = 0 | BF1: 3 Num Rep Rows | BG1: 1 Tube Samecols Not Deleted | BH1: 3 Tube ID in Reps? | BI1: 2 SORTED Tube Timestamp | BJ1: 2 TUBE ID ONLY | BK1: 2 Replicate Tube ID? (First Row) | BL1: 2 Rep Tube IDs Not Sorted | BM1: More | BN1: =CONCATENATE("Blank or Whitespace ", COUNTIF(BN2:BN808, TRUE)) -> Blank or Whitespace 781 | BO1: =CONCATENATE("Blank ", COUNTIF(BO2:BO808, TRUE)) -> Blank 0 | BP1: =CONCATENATE("Whitespace ", COUNTIF(BP2:BP808, TRUE)) -> Whitespace 781
A2: TEST100 | B2: 44463 | C2: 0.5330787 | K2: Fail | L2: 44463 | M2: 0.53498843 | P2: =IFNA(IF(VLOOKUP($A2,'Add from APT'!$AA$2:$AC808,3,FALSE)>0,TRUE,FALSE),"ER - NOT IN APT") -> FALSE | Q2: =IF(ISLOGICAL(P2),IF(P2,"ER - REPS IN APT", IFNA(VLOOKUP($A2,RAW_APT!$A$3:$M808,7,FALSE),"ER - NOT IN APT")),P2) -> Result | R2: =IF(EXACT($A2,$A1),FALSE,TRUE) -> TRUE | S2: =COUNTIF($A$2:$A808,$A2) -> 1 | X2: =IF(ISBLANK($U2),IF(ISBLANK($V2),FALSE,"ER - LAST ONLY"),TRUE) -> FALSE | Y2: FALSE | Z2: =IF($S2>4,TRUE,IFERROR(0/0,"")) | AA2: =IF(ISBLANK($O2),FALSE,TRUE) -> FALSE | AB2: FALSE | AC2: 807 | AD2: TRUE | AE2: =IFERROR(IF(EXACT($L2,$B2),(TIMEVALUE($M2)-TIMEVALUE($C2))*24*60,IFERROR(0/0,"")),IFERROR(0/0,"")) | AF2: =OR(AND(NOT($AG2),IFERROR(NOT($AG3),""),EXACT($A2,$A3),NOT(EXACT(CONCATENATE($B2,$C2),CONCATENATE($B3,$C3)))),AND(NOT($AG2),IFERROR(NOT($AG1),""),EXACT($A2,$A1),NOT(EXACT(CONCATENATE($B2,$C2),CONCATENATE($B1,$C1))))) -> FALSE | AG2: =IF($AH2>0,TRUE,FALSE) -> TRUE | AH2: 1 | AK2: =IFS(AND($AJ2>=2,$AJ2<3),"Negative",AND($AJ2>=3,$AJ2<4),"Positive",AND($AJ2>=4,$AJ2<5),"Inconclusive",$AJ2=5,"MANUAL FILL",$AG2,"DELETED",TRUE,$K2) -> DELETED | AM2: DELETED | AN2: DELETED | AO2: =IFERROR(__xludf.DUMMYFUNCTION("IF($AG2, ""DELETED"",TRIM(JOIN("" "",D2:E2)))"),"DELETED") -> DELETED | AP2: =IF($AG2, "DELETED", TRIM(CONCATENATE(F2,I2,U2))) -> DELETED | AQ2: =IF($AG2, "DELETED", TRIM(CONCATENATE(G2,J2,V2))) -> DELETED | AR2: =IFERROR(__xludf.DUMMYFUNCTION("IF($AG2, ""DELETED"", TRIM(JOIN("" "",AP2,AQ2)))"),"DELETED") -> DELETED | AT2: =IF(OR($AG2,SUM($AU2:$AW2)=1),TRUE,FALSE) -> TRUE | AU2: =IF($AG2,IFERROR(0/0,""),IF(ISBLANK($F2),IF(ISBLANK($G2),IFERROR(0/0,""),2),1)) | AV2: =IF($AG2,IFERROR(0/0,""),IF(ISBLANK($I2),IF(ISBLANK($J2),IFERROR(0/0,""),2),1)) | AW2: =IF($AG2,IFERROR(0/0,""),IF(ISBLANK($U2),IF(ISBLANK($V2),IFERROR(0/0,""),2),1)) | AX2: =IF(AND($X2,$A3=$A2),1,IFERROR(0/0,"")) | BA2: =IF(AG2,IFERROR(0/0,""),IF(EXACT(UPPER(A2),A2),IFERROR(0/0,""),TRUE)) | BE2: {=SORT(BL$2:BL808,1,TRUE)} | BF2: =IF(COUNTIF(BJ$2:BJ808,BE2)>0,COUNTIF(BJ$2:BJ808,BE2),IFERROR(0/0,"")) | BG2: =IF($AG2,IFERROR(0/0,""),CONCATENATE($A2,"__",$B2,"_",$C2,"_",$D2,"_",$E2,"_",$K2,"_",$L2,"_",$M2,"_",$O2)) | BH2: =IF(ISBLANK(IFERROR(MATCH(LEFT(BG2, FIND("__",BG2)-1),BE$2:BE808,0),"")),IFERROR(0/0,""),TRUE) | BI2: {=SORT(UNIQUE(BG$2:BG808),1,TRUE)} -> FLB1047__44545_0.33380787037037___Negative_44545_0.518958333333333_ | BJ2: =IFERROR(LEFT(BI2, FIND("__",BI2)-1),"") -> FLB1047 | BK2: =IFERROR(AND(EXACT(BJ3,BJ2),NOT(EXACT(BJ2,BJ1))),"") -> FALSE | BL2: =IF(BK2,BJ2,IFERROR(0/0,"")) | BN2: =OR(BO2,BP2) -> FALSE | BO2: =ISBLANK($AR2) -> FALSE | BP2: =IF(TRIM($AR2)="",TRUE,FALSE) -> FALSE | BR2: =IF(EXACT(AK2,"Null"),2.2,IFERROR(0/0,""))
A3: TESTK | B3: 44463 | C3: 0.59236111 | K3: Null | L3: 44868 | M3: 0.53552083 | P3: =IFNA(IF(VLOOKUP($A3,'Add from APT'!$AA$2:$AC808,3,FALSE)>0,TRUE,FALSE),"ER - NOT IN APT") -> FALSE | Q3: =IF(ISLOGICAL(P3),IF(P3,"ER - REPS IN APT", IFNA(VLOOKUP($A3,RAW_APT!$A$3:$M808,7,FALSE),"ER - NOT IN APT")),P3) -> Collected | R3: =IF(EXACT($A3,$A2),FALSE,TRUE) -> TRUE | S3: =COUNTIF($A$2:$A809,$A3) -> 1 | X3: =IF(ISBLANK($U3),IF(ISBLANK($V3),FALSE,"ER - LAST ONLY"),TRUE) -> FALSE | Y3: FALSE | Z3: =IF($S3>4,TRUE,IFERROR(0/0,"")) | AA3: =IF(ISBLANK($O3),FALSE,TRUE) -> FALSE | AB3: FALSE | AC3: 806 | AD3: TRUE | AE3: =IFERROR(IF(EXACT($L3,$B3),(TIMEVALUE($M3)-TIMEVALUE($C3))*24*60,IFERROR(0/0,"")),IFERROR(0/0,"")) | AF3: =OR(AND(NOT($AG3),IFERROR(NOT($AG4),""),EXACT($A3,$A4),NOT(EXACT(CONCATENATE($B3,$C3),CONCATENATE($B4,$C4)))),AND(NOT($AG3),IFERROR(NOT($AG2),""),EXACT($A3,$A2),NOT(EXACT(CONCATENATE($B3,$C3),CONCATENATE($B2,$C2))))) -> FALSE | AG3: =IF($AH3>0,TRUE,FALSE) -> TRUE | AH3: 1 | AK3: =IFS(AND($AJ3>=2,$AJ3<3),"Negative",AND($AJ3>=3,$AJ3<4),"Positive",AND($AJ3>=4,$AJ3<5),"Inconclusive",$AJ3=5,"MANUAL FILL",$AG3,"DELETED",TRUE,$K3) -> DELETED | AM3: DELETED | AN3: DELETED | AO3: =IFERROR(__xludf.DUMMYFUNCTION("IF($AG3, ""DELETED"",TRIM(JOIN("" "",D3:E3)))"),"DELETED") -> DELETED | AP3: =IF($AG3, "DELETED", TRIM(CONCATENATE(F3,I3,U3))) -> DELETED | AQ3: =IF($AG3, "DELETED", TRIM(CONCATENATE(G3,J3,V3))) -> DELETED | AR3: =IFERROR(__xludf.DUMMYFUNCTION("IF($AG3, ""DELETED"", TRIM(JOIN("" "",AP3,AQ3)))"),"DELETED") -> DELETED | AT3: =IF(OR($AG3,SUM($AU3:$AW3)=1),TRUE,FALSE) -> TRUE | AU3: =IF($AG3,IFERROR(0/0,""),IF(ISBLANK($F3),IF(ISBLANK($G3),IFERROR(0/0,""),2),1)) | AV3: =IF($AG3,IFERROR(0/0,""),IF(ISBLANK($I3),IF(ISBLANK($J3),IFERROR(0/0,""),2),1)) | AW3: =IF($AG3,IFERROR(0/0,""),IF(ISBLANK($U3),IF(ISBLANK($V3),IFERROR(0/0,""),2),1)) | AX3: =IF(AND($X3,$A4=$A3),1,IFERROR(0/0,"")) | BA3: =IF(AG3,IFERROR(0/0,""),IF(EXACT(UPPER(A3),A3),IFERROR(0/0,""),TRUE)) | BF3: =IF(COUNTIF(BJ$2:BJ809,BE3)>0,COUNTIF(BJ$2:BJ809,BE3),IFERROR(0/0,"")) | BG3: =IF($AG3,IFERROR(0/0,""),CONCATENATE($A3,"__",$B3,"_",$C3,"_",$D3,"_",$E3,"_",$K3,"_",$L3,"_",$M3,"_",$O3)) | BH3: =IF(ISBLANK(IFERROR(MATCH(LEFT(BG3, FIND("__",BG3)-1),BE$2:BE809,0),"")),IFERROR(0/0,""),TRUE) | BI3: FLB1313__44545_0.276458333333333___Negative_44545_0.518958333333333_ | BJ3: =IFERROR(LEFT(BI3, FIND("__",BI3)-1),"") -> FLB1313 | BK3: =IFERROR(AND(EXACT(BJ4,BJ3),NOT(EXACT(BJ3,BJ2))),"") -> FALSE | BL3: =IF(BK3,BJ3,IFERROR(0/0,"")) | BN3: =OR(BO3,BP3) -> FALSE | BO3: =ISBLANK($AR3) -> FALSE | BP3: =IF(TRIM($AR3)="",TRUE,FALSE) -> FALSE | BR3: =IF(EXACT(AK3,"Null"),2.2,IFERROR(0/0,""))
A4: TEST1 | B4: 44463 | C4: 0.59377315 | K4: Null | L4: 44868 | M4: 0.53552083 | P4: =IFNA(IF(VLOOKUP($A4,'Add from APT'!$AA$2:$AC808,3,FALSE)>0,TRUE,FALSE),"ER - NOT IN APT") -> FALSE | Q4: =IF(ISLOGICAL(P4),IF(P4,"ER - REPS IN APT", IFNA(VLOOKUP($A4,RAW_APT!$A$3:$M808,7,FALSE),"ER - NOT IN APT")),P4) -> Collected | R4: =IF(EXACT($A4,$A3),FALSE,TRUE) -> TRUE | S4: =COUNTIF($A$2:$A810,$A4) -> 1 | X4: =IF(ISBLANK($U4),IF(ISBLANK($V4),FALSE,"ER - LAST ONLY"),TRUE) -> FALSE | Y4: FALSE | Z4: =IF($S4>4,TRUE,IFERROR(0/0,"")) | AA4: =IF(ISBLANK($O4),FALSE,TRUE) -> FALSE | AB4: FALSE | AC4: 805 | AD4: TRUE | AE4: =IFERROR(IF(EXACT($L4,$B4),(TIMEVALUE($M4)-TIMEVALUE($C4))*24*60,IFERROR(0/0,"")),IFERROR(0/0,"")) | AF4: =OR(AND(NOT($AG4),IFERROR(NOT($AG5),""),EXACT($A4,$A5),NOT(EXACT(CONCATENATE($B4,$C4),CONCATENATE($B5,$C5)))),AND(NOT($AG4),IFERROR(NOT($AG3),""),EXACT($A4,$A3),NOT(EXACT(CONCATENATE($B4,$C4),CONCATENATE($B3,$C3))))) -> FALSE | AG4: =IF($AH4>0,TRUE,FALSE) -> TRUE | AH4: 1 | AK4: =IFS(AND($AJ4>=2,$AJ4<3),"Negative",AND($AJ4>=3,$AJ4<4),"Positive",AND($AJ4>=4,$AJ4<5),"Inconclusive",$AJ4=5,"MANUAL FILL",$AG4,"DELETED",TRUE,$K4) -> DELETED | AM4: DELETED | AN4: DELETED | AO4: =IFERROR(__xludf.DUMMYFUNCTION("IF($AG4, ""DELETED"",TRIM(JOIN("" "",D4:E4)))"),"DELETED") -> DELETED | AP4: =IF($AG4, "DELETED", TRIM(CONCATENATE(F4,I4,U4))) -> DELETED | AQ4: =IF($AG4, "DELETED", TRIM(CONCATENATE(G4,J4,V4))) -> DELETED | AR4: =IFERROR(__xludf.DUMMYFUNCTION("IF($AG4, ""DELETED"", TRIM(JOIN("" "",AP4,AQ4)))"),"DELETED") -> DELETED | AT4: =IF(OR($AG4,SUM($AU4:$AW4)=1),TRUE,FALSE) -> TRUE | AU4: =IF($AG4,IFERROR(0/0,""),IF(ISBLANK($F4),IF(ISBLANK($G4),IFERROR(0/0,""),2),1)) | AV4: =IF($AG4,IFERROR(0/0,""),IF(ISBLANK($I4),IF(ISBLANK($J4),IFERROR(0/0,""),2),1)) | AW4: =IF($AG4,IFERROR(0/0,""),IF(ISBLANK($U4),IF(ISBLANK($V4),IFERROR(0/0,""),2),1)) | AX4: =IF(AND($X4,$A5=$A4),1,IFERROR(0/0,"")) | BA4: =IF(AG4,IFERROR(0/0,""),IF(EXACT(UPPER(A4),A4),IFERROR(0/0,""),TRUE)) | BF4: =IF(COUNTIF(BJ$2:BJ810,BE4)>0,COUNTIF(BJ$2:BJ810,BE4),IFERROR(0/0,"")) | BG4: =IF($AG4,IFERROR(0/0,""),CONCATENATE($A4,"__",$B4,"_",$C4,"_",$D4,"_",$E4,"_",$K4,"_",$L4,"_",$M4,"_",$O4)) | BH4: =IF(ISBLANK(IFERROR(MATCH(LEFT(BG4, FIND("__",BG4)-1),BE$2:BE810,0),"")),IFERROR(0/0,""),TRUE) | BI4: FLB1331__44547_0.176030092592593___Negative_44547_0.401863425925926_ | BJ4: =IFERROR(LEFT(BI4, FIND("__",BI4)-1),"") -> FLB1331 | BK4: =IFERROR(AND(EXACT(BJ5,BJ4),NOT(EXACT(BJ4,BJ3))),"") -> FALSE | BL4: =IF(BK4,BJ4,IFERROR(0/0,"")) | BN4: =OR(BO4,BP4) -> FALSE | BO4: =ISBLANK($AR4) -> FALSE | BP4: =IF(TRIM($AR4)="",TRUE,FALSE) -> FALSE | BR4: =IF(EXACT(AK4,"Null"),2.2,IFERROR(0/0,""))
A5: PA9527 | B5: 44467 | C5: 0.28556713 | K5: Null | L5: 44868 | M5: 0.53552083 | P5: =IFNA(IF(VLOOKUP($A5,'Add from APT'!$AA$2:$AC808,3,FALSE)>0,TRUE,FALSE),"ER - NOT IN APT") -> FALSE | Q5: =IF(ISLOGICAL(P5),IF(P5,"ER - REPS IN APT", IFNA(VLOOKUP($A5,RAW_APT!$A$3:$M808,7,FALSE),"ER - NOT IN APT")),P5) -> Collected | R5: =IF(EXACT($A5,$A4),FALSE,TRUE) -> TRUE | S5: =COUNTIF($A$2:$A811,$A5) -> 1 | X5: =IF(ISBLANK($U5),IF(ISBLANK($V5),FALSE,"ER - LAST ONLY"),TRUE) -> FALSE | Y5: FALSE | Z5: =IF($S5>4,TRUE,IFERROR(0/0,"")) | AA5: =IF(ISBLANK($O5),FALSE,TRUE) -> FALSE | AB5: FALSE | AC5: 804 | AD5: TRUE | AE5: =IFERROR(IF(EXACT($L5,$B5),(TIMEVALUE($M5)-TIMEVALUE($C5))*24*60,IFERROR(0/0,"")),IFERROR(0/0,"")) | AF5: =OR(AND(NOT($AG5),IFERROR(NOT($AG6),""),EXACT($A5,$A6),NOT(EXACT(CONCATENATE($B5,$C5),CONCATENATE($B6,$C6)))),AND(NOT($AG5),IFERROR(NOT($AG4),""),EXACT($A5,$A4),NOT(EXACT(CONCATENATE($B5,$C5),CONCATENATE($B4,$C4))))) -> FALSE | AG5: =IF($AH5>0,TRUE,FALSE) -> TRUE | AH5: 5.5 | AK5: =IFS(AND($AJ5>=2,$AJ5<3),"Negative",AND($AJ5>=3,$AJ5<4),"Positive",AND($AJ5>=4,$AJ5<5),"Inconclusive",$AJ5=5,"MANUAL FILL",$AG5,"DELETED",TRUE,$K5) -> DELETED | AM5: DELETED | AN5: DELETED | AO5: =IFERROR(__xludf.DUMMYFUNCTION("IF($AG5, ""DELETED"",TRIM(JOIN("" "",D5:E5)))"),"DELETED") -> DELETED | AP5: =IF($AG5, "DELETED", TRIM(CONCATENATE(F5,I5,U5))) -> DELETED | AQ5: =IF($AG5, "DELETED", TRIM(CONCATENATE(G5,J5,V5))) -> DELETED | AR5: =IFERROR(__xludf.DUMMYFUNCTION("IF($AG5, ""DELETED"", TRIM(JOIN("" "",AP5,AQ5)))"),"DELETED") -> DELETED | AT5: =IF(OR($AG5,SUM($AU5:$AW5)=1),TRUE,FALSE) -> TRUE | AU5: =IF($AG5,IFERROR(0/0,""),IF(ISBLANK($F5),IF(ISBLANK($G5),IFERROR(0/0,""),2),1)) | AV5: =IF($AG5,IFERROR(0/0,""),IF(ISBLANK($I5),IF(ISBLANK($J5),IFERROR(0/0,""),2),1)) | AW5: =IF($AG5,IFERROR(0/0,""),IF(ISBLANK($U5),IF(ISBLANK($V5),IFERROR(0/0,""),2),1)) | AX5: =IF(AND($X5,$A6=$A5),1,IFERROR(0/0,"")) | BA5: =IF(AG5,IFERROR(0/0,""),IF(EXACT(UPPER(A5),A5),IFERROR(0/0,""),TRUE)) | BF5: =IF(COUNTIF(BJ$2:BJ811,BE5)>0,COUNTIF(BJ$2:BJ811,BE5),IFERROR(0/0,"")) | BG5: =IF($AG5,IFERROR(0/0,""),CONCATENATE($A5,"__",$B5,"_",$C5,"_",$D5,"_",$E5,"_",$K5,"_",$L5,"_",$M5,"_",$O5)) | BH5: =IF(ISBLANK(IFERROR(MATCH(LEFT(BG5, FIND("__",BG5)-1),BE$2:BE811,0),"")),IFERROR(0/0,""),TRUE) | BI5: FLB1334__44545_0.253587962962963___Negative_44545_0.518958333333333_ | BJ5: =IFERROR(LEFT(BI5, FIND("__",BI5)-1),"") -> FLB1334 | BK5: =IFERROR(AND(EXACT(BJ6,BJ5),NOT(EXACT(BJ5,BJ4))),"") -> FALSE | BL5: =IF(BK5,BJ5,IFERROR(0/0,"")) | BN5: =OR(BO5,BP5) -> FALSE | BO5: =ISBLANK($AR5) -> FALSE | BP5: =IF(TRIM($AR5)="",TRUE,FALSE) -> FALSE | BR5: =IF(EXACT(AK5,"Null"),2.2,IFERROR(0/0,""))
A6: PA9446 | B6: 44467 | C6: 0.29219907 | K6: Null | L6: 44868 | M6: 0.53552083 | P6: =IFNA(IF(VLOOKUP($A6,'Add from APT'!$AA$2:$AC808,3,FALSE)>0,TRUE,FALSE),"ER - NOT IN APT") -> FALSE | Q6: =IF(ISLOGICAL(P6),IF(P6,"ER - REPS IN APT", IFNA(VLOOKUP($A6,RAW_APT!$A$3:$M808,7,FALSE),"ER - NOT IN APT")),P6) -> Collected | R6: =IF(EXACT($A6,$A5),FALSE,TRUE) -> TRUE | S6: =COUNTIF($A$2:$A812,$A6) -> 1 | X6: =IF(ISBLANK($U6),IF(ISBLANK($V6),FALSE,"ER - LAST ONLY"),TRUE) -> FALSE | Y6: FALSE | Z6: =IF($S6>4,TRUE,IFERROR(0/0,"")) | AA6: =IF(ISBLANK($O6),FALSE,TRUE) -> FALSE | AB6: FALSE | AC6: 803 | AD6: TRUE | AE6: =IFERROR(IF(EXACT($L6,$B6),(TIMEVALUE($M6)-TIMEVALUE($C6))*24*60,IFERROR(0/0,"")),IFERROR(0/0,"")) | AF6: =OR(AND(NOT($AG6),IFERROR(NOT($AG7),""),EXACT($A6,$A7),NOT(EXACT(CONCATENATE($B6,$C6),CONCATENATE($B7,$C7)))),AND(NOT($AG6),IFERROR(NOT($AG5),""),EXACT($A6,$A5),NOT(EXACT(CONCATENATE($B6,$C6),CONCATENATE($B5,$C5))))) -> FALSE | AG6: =IF($AH6>0,TRUE,FALSE) -> TRUE | AH6: 5.5 | AK6: =IFS(AND($AJ6>=2,$AJ6<3),"Negative",AND($AJ6>=3,$AJ6<4),"Positive",AND($AJ6>=4,$AJ6<5),"Inconclusive",$AJ6=5,"MANUAL FILL",$AG6,"DELETED",TRUE,$K6) -> DELETED | AM6: DELETED | AN6: DELETED | AO6: =IFERROR(__xludf.DUMMYFUNCTION("IF($AG6, ""DELETED"",TRIM(JOIN("" "",D6:E6)))"),"DELETED") -> DELETED | AP6: =IF($AG6, "DELETED", TRIM(CONCATENATE(F6,I6,U6))) -> DELETED | AQ6: =IF($AG6, "DELETED", TRIM(CONCATENATE(G6,J6,V6))) -> DELETED | AR6: =IFERROR(__xludf.DUMMYFUNCTION("IF($AG6, ""DELETED"", TRIM(JOIN("" "",AP6,AQ6)))"),"DELETED") -> DELETED | AT6: =IF(OR($AG6,SUM($AU6:$AW6)=1),TRUE,FALSE) -> TRUE | AU6: =IF($AG6,IFERROR(0/0,""),IF(ISBLANK($F6),IF(ISBLANK($G6),IFERROR(0/0,""),2),1)) | AV6: =IF($AG6,IFERROR(0/0,""),IF(ISBLANK($I6),IF(ISBLANK($J6),IFERROR(0/0,""),2),1)) | AW6: =IF($AG6,IFERROR(0/0,""),IF(ISBLANK($U6),IF(ISBLANK($V6),IFERROR(0/0,""),2),1)) | AX6: =IF(AND($X6,$A7=$A6),1,IFERROR(0/0,"")) | BA6: =IF(AG6,IFERROR(0/0,""),IF(EXACT(UPPER(A6),A6),IFERROR(0/0,""),TRUE)) | BF6: =IF(COUNTIF(BJ$2:BJ812,BE6)>0,COUNTIF(BJ$2:BJ812,BE6),IFERROR(0/0,"")) | BG6: =IF($AG6,IFERROR(0/0,""),CONCATENATE($A6,"__",$B6,"_",$C6,"_",$D6,"_",$E6,"_",$K6,"_",$L6,"_",$M6,"_",$O6)) | BH6: =IF(ISBLANK(IFERROR(MATCH(LEFT(BG6, FIND("__",BG6)-1),BE$2:BE812,0),"")),IFERROR(0/0,""),TRUE) | BI6: FLB1343__44545_0.276168981481482___Negative_44545_0.518958333333333_ | BJ6: =IFERROR(LEFT(BI6, FIND("__",BI6)-1),"") -> FLB1343 | BK6: =IFERROR(AND(EXACT(BJ7,BJ6),NOT(EXACT(BJ6,BJ5))),"") -> FALSE | BL6: =IF(BK6,BJ6,IFERROR(0/0,"")) | BN6: =OR(BO6,BP6) -> FALSE | BO6: =ISBLANK($AR6) -> FALSE | BP6: =IF(TRIM($AR6)="",TRUE,FALSE) -> FALSE | BR6: =IF(EXACT(AK6,"Null"),2.2,IFERROR(0/0,""))
A7: PA9436 | B7: 44467 | C7: 0.29356481 | K7: Null | L7: 44868 | M7: 0.53552083 | P7: =IFNA(IF(VLOOKUP($A7,'Add from APT'!$AA$2:$AC808,3,FALSE)>0,TRUE,FALSE),"ER - NOT IN APT") -> FALSE | Q7: =IF(ISLOGICAL(P7),IF(P7,"ER - REPS IN APT", IFNA(VLOOKUP($A7,RAW_APT!$A$3:$M808,7,FALSE),"ER - NOT IN APT")),P7) -> Collected | R7: =IF(EXACT($A7,$A6),FALSE,TRUE) -> TRUE | S7: =COUNTIF($A$2:$A813,$A7) -> 1 | T7: 0 | X7: =IF(ISBLANK($U7),IF(ISBLANK($V7),FALSE,"ER - LAST ONLY"),TRUE) -> FALSE | Y7: FALSE | Z7: =IF($S7>4,TRUE,IFERROR(0/0,"")) | AA7: =IF(ISBLANK($O7),FALSE,TRUE) -> FALSE | AB7: FALSE | AC7: 802 | AD7: TRUE | AE7: =IFERROR(IF(EXACT($L7,$B7),(TIMEVALUE($M7)-TIMEVALUE($C7))*24*60,IFERROR(0/0,"")),IFERROR(0/0,"")) | AF7: =OR(AND(NOT($AG7),IFERROR(NOT($AG8),""),EXACT($A7,$A8),NOT(EXACT(CONCATENATE($B7,$C7),CONCATENATE($B8,$C8)))),AND(NOT($AG7),IFERROR(NOT($AG6),""),EXACT($A7,$A6),NOT(EXACT(CONCATENATE($B7,$C7),CONCATENATE($B6,$C6))))) -> FALSE | AG7: =IF($AH7>0,TRUE,FALSE) -> FALSE | AJ7: 2.2 | AK7: =IFS(AND($AJ7>=2,$AJ7<3),"Negative",AND($AJ7>=3,$AJ7<4),"Positive",AND($AJ7>=4,$AJ7<5),"Inconclusive",$AJ7=5,"MANUAL FILL",$AG7,"DELETED",TRUE,$K7) -> Negative | AM7: SpROSA145068 | AN7: ROSA661034 | AO7: =IFERROR(__xludf.DUMMYFUNCTION("IF($AG7, ""DELETED"",TRIM(JOIN("" "",D7:E7)))"),"") | AP7: =IF($AG7, "DELETED", TRIM(CONCATENATE(F7,I7,U7))) | AQ7: =IF($AG7, "DELETED", TRIM(CONCATENATE(G7,J7,V7))) | AR7: =IFERROR(__xludf.DUMMYFUNCTION("IF($AG7, ""DELETED"", TRIM(JOIN("" "",AP7,AQ7)))"),"") | AT7: =IF(OR($AG7,SUM($AU7:$AW7)=1),TRUE,FALSE) -> FALSE | AU7: =IF($AG7,IFERROR(0/0,""),IF(ISBLANK($F7),IF(ISBLANK($G7),IFERROR(0/0,""),2),1)) | AV7: =IF($AG7,IFERROR(0/0,""),IF(ISBLANK($I7),IF(ISBLANK($J7),IFERROR(0/0,""),2),1)) | AW7: =IF($AG7,IFERROR(0/0,""),IF(ISBLANK($U7),IF(ISBLANK($V7),IFERROR(0/0,""),2),1)) | AX7: =IF(AND($X7,$A8=$A7),1,IFERROR(0/0,"")) | BA7: =IF(AG7,IFERROR(0/0,""),IF(EXACT(UPPER(A7),A7),IFERROR(0/0,""),TRUE)) | BF7: =IF(COUNTIF(BJ$2:BJ813,BE7)>0,COUNTIF(BJ$2:BJ813,BE7),IFERROR(0/0,"")) | BG7: =IF($AG7,IFERROR(0/0,""),CONCATENATE($A7,"__",$B7,"_",$C7,"_",$D7,"_",$E7,"_",$K7,"_",$L7,"_",$M7,"_",$O7)) -> PA9436__44467_0.293564814814815___Null_44868_0.535520833333333_ | BH7: =IF(ISBLANK(IFERROR(MATCH(LEFT(BG7, FIND("__",BG7)-1),BE$2:BE813,0),"")),IFERROR(0/0,""),TRUE) | BI7: FLB1344__44545_0.257893518518519___Negative_44545_0.518958333333333_ | BJ7: =IFERROR(LEFT(BI7, FIND("__",BI7)-1),"") -> FLB1344 | BK7: =IFERROR(AND(EXACT(BJ8,BJ7),NOT(EXACT(BJ7,BJ6))),"") -> FALSE | BL7: =IF(BK7,BJ7,IFERROR(0/0,"")) | BN7: =OR(BO7,BP7) -> TRUE | BO7: =ISBLANK($AR7) -> FALSE | BP7: =IF(TRIM($AR7)="",TRUE,FALSE) -> TRUE | BR7: =IF(EXACT(AK7,"Null"),2.2,IFERROR(0/0,""))
A8: PA9627 | B8: 44467 | C8: 0.35224537 | K8: Null | L8: 44868 | M8: 0.53552083 | P8: =IFNA(IF(VLOOKUP($A8,'Add from APT'!$AA$2:$AC808,3,FALSE)>0,TRUE,FALSE),"ER - NOT IN APT") -> FALSE | Q8: =IF(ISLOGICAL(P8),IF(P8,"ER - REPS IN APT", IFNA(VLOOKUP($A8,RAW_APT!$A$3:$M808,7,FALSE),"ER - NOT IN APT")),P8) -> Collected | R8: =IF(EXACT($A8,$A7),FALSE,TRUE) -> TRUE | S8: =COUNTIF($A$2:$A814,$A8) -> 1 | T8: 0 | X8: =IF(ISBLANK($U8),IF(ISBLANK($V8),FALSE,"ER - LAST ONLY"),TRUE) -> FALSE | Y8: FALSE | Z8: =IF($S8>4,TRUE,IFERROR(0/0,"")) | AA8: =IF(ISBLANK($O8),FALSE,TRUE) -> FALSE | AB8: FALSE | AC8: 801 | AD8: TRUE | AE8: =IFERROR(IF(EXACT($L8,$B8),(TIMEVALUE($M8)-TIMEVALUE($C8))*24*60,IFERROR(0/0,"")),IFERROR(0/0,"")) | AF8: =OR(AND(NOT($AG8),IFERROR(NOT($AG9),""),EXACT($A8,$A9),NOT(EXACT(CONCATENATE($B8,$C8),CONCATENATE($B9,$C9)))),AND(NOT($AG8),IFERROR(NOT($AG7),""),EXACT($A8,$A7),NOT(EXACT(CONCATENATE($B8,$C8),CONCATENATE($B7,$C7))))) -> FALSE | AG8: =IF($AH8>0,TRUE,FALSE) -> FALSE | AJ8: 2.2 | AK8: =IFS(AND($AJ8>=2,$AJ8<3),"Negative",AND($AJ8>=3,$AJ8<4),"Positive",AND($AJ8>=4,$AJ8<5),"Inconclusive",$AJ8=5,"MANUAL FILL",$AG8,"DELETED",TRUE,$K8) -> Negative | AM8: SpROSA145068 | AN8: ROSA681730 | AO8: =IFERROR(__xludf.DUMMYFUNCTION("IF($AG8, ""DELETED"",TRIM(JOIN("" "",D8:E8)))"),"") | AP8: =IF($AG8, "DELETED", TRIM(CONCATENATE(F8,I8,U8))) | AQ8: =IF($AG8, "DELETED", TRIM(CONCATENATE(G8,J8,V8))) | AR8: =IFERROR(__xludf.DUMMYFUNCTION("IF($AG8, ""DELETED"", TRIM(JOIN("" "",AP8,AQ8)))"),"") | AT8: =IF(OR($AG8,SUM($AU8:$AW8)=1),TRUE,FALSE) -> FALSE | AU8: =IF($AG8,IFERROR(0/0,""),IF(ISBLANK($F8),IF(ISBLANK($G8),IFERROR(0/0,""),2),1)) | AV8: =IF($AG8,IFERROR(0/0,""),IF(ISBLANK($I8),IF(ISBLANK($J8),IFERROR(0/0,""),2),1)) | AW8: =IF($AG8,IFERROR(0/0,""),IF(ISBLANK($U8),IF(ISBLANK($V8),IFERROR(0/0,""),2),1)) | AX8: =IF(AND($X8,$A9=$A8),1,IFERROR(0/0,"")) | BA8: =IF(AG8,IFERROR(0/0,""),IF(EXACT(UPPER(A8),A8),IFERROR(0/0,""),TRUE)) | BF8: =IF(COUNTIF(BJ$2:BJ814,BE8)>0,COUNTIF(BJ$2:BJ814,BE8),IFERROR(0/0,"")) | BG8: =IF($AG8,IFERROR(0/0,""),CONCATENATE($A8,"__",$B8,"_",$C8,"_",$D8,"_",$E8,"_",$K8,"_",$L8,"_",$M8,"_",$O8)) -> PA9627__44467_0.35224537037037___Null_44868_0.535520833333333_ | BH8: =IF(ISBLANK(IFERROR(MATCH(LEFT(BG8, FIND("__",BG8)-1),BE$2:BE814,0),"")),IFERROR(0/0,""),TRUE) | BI8: FLB2377__44508_0.31693287037037___Negative_44508_0.412673611111111_ | BJ8: =IFERROR(LEFT(BI8, FIND("__",BI8)-1),"") -> FLB2377 | BK8: =IFERROR(AND(EXACT(BJ9,BJ8),NOT(EXACT(BJ8,BJ7))),"") -> FALSE | BL8: =IF(BK8,BJ8,IFERROR(0/0,"")) | BN8: =OR(BO8,BP8) -> TRUE | BO8: =ISBLANK($AR8) -> FALSE | BP8: =IF(TRIM($AR8)="",TRUE,FALSE) -> TRUE | BR8: =IF(EXACT(AK8,"Null"),2.2,IFERROR(0/0,""))
A9: PA9633 | B9: 44467 | C9: 0.35263889 | K9: Null | L9: 44868 | M9: 0.53552083 | P9: =IFNA(IF(VLOOKUP($A9,'Add from APT'!$AA$2:$AC808,3,FALSE)>0,TRUE,FALSE),"ER - NOT IN APT") -> FALSE | Q9: =IF(ISLOGICAL(P9),IF(P9,"ER - REPS IN APT", IFNA(VLOOKUP($A9,RAW_APT!$A$3:$M808,7,FALSE),"ER - NOT IN APT")),P9) -> Collected | R9: =IF(EXACT($A9,$A8),FALSE,TRUE) -> TRUE | S9: =COUNTIF($A$2:$A815,$A9) -> 1 | T9: 0 | X9: =IF(ISBLANK($U9),IF(ISBLANK($V9),FALSE,"ER - LAST ONLY"),TRUE) -> FALSE | Y9: FALSE | Z9: =IF($S9>4,TRUE,IFERROR(0/0,"")) | AA9: =IF(ISBLANK($O9),FALSE,TRUE) -> FALSE | AB9: FALSE | AC9: 800 | AD9: TRUE | AE9: =IFERROR(IF(EXACT($L9,$B9),(TIMEVALUE($M9)-TIMEVALUE($C9))*24*60,IFERROR(0/0,"")),IFERROR(0/0,"")) | AF9: =OR(AND(NOT($AG9),IFERROR(NOT($AG10),""),EXACT($A9,$A10),NOT(EXACT(CONCATENATE($B9,$C9),CONCATENATE($B10,$C10)))),AND(NOT($AG9),IFERROR(NOT($AG8),""),EXACT($A9,$A8),NOT(EXACT(CONCATENATE($B9,$C9),CONCATENATE($B8,$C8))))) -> FALSE | AG9: =IF($AH9>0,TRUE,FALSE) -> FALSE | AJ9: 2.2 | AK9: =IFS(AND($AJ9>=2,$AJ9<3),"Negative",AND($AJ9>=3,$AJ9<4),"Positive",AND($AJ9>=4,$AJ9<5),"Inconclusive",$AJ9=5,"MANUAL FILL",$AG9,"DELETED",TRUE,$K9) -> Negative | AM9: SpROSA145068 | AN9: ROSA216934 | AO9: =IFERROR(__xludf.DUMMYFUNCTION("IF($AG9, ""DELETED"",TRIM(JOIN("" "",D9:E9)))"),"") | AP9: =IF($AG9, "DELETED", TRIM(CONCATENATE(F9,I9,U9))) | AQ9: =IF($AG9, "DELETED", TRIM(CONCATENATE(G9,J9,V9))) | AR9: =IFERROR(__xludf.DUMMYFUNCTION("IF($AG9, ""DELETED"", TRIM(JOIN("" "",AP9,AQ9)))"),"") | AT9: =IF(OR($AG9,SUM($AU9:$AW9)=1),TRUE,FALSE) -> FALSE | AU9: =IF($AG9,IFERROR(0/0,""),IF(ISBLANK($F9),IF(ISBLANK($G9),IFERROR(0/0,""),2),1)) | AV9: =IF($AG9,IFERROR(0/0,""),IF(ISBLANK($I9),IF(ISBLANK($J9),IFERROR(0/0,""),2),1)) | AW9: =IF($AG9,IFERROR(0/0,""),IF(ISBLANK($U9),IF(ISBLANK($V9),IFERROR(0/0,""),2),1)) | AX9: =IF(AND($X9,$A10=$A9),1,IFERROR(0/0,"")) | BA9: =IF(AG9,IFERROR(0/0,""),IF(EXACT(UPPER(A9),A9),IFERROR(0/0,""),TRUE)) | BF9: =IF(COUNTIF(BJ$2:BJ815,BE9)>0,COUNTIF(BJ$2:BJ815,BE9),IFERROR(0/0,"")) | BG9: =IF($AG9,IFERROR(0/0,""),CONCATENATE($A9,"__",$B9,"_",$C9,"_",$D9,"_",$E9,"_",$K9,"_",$L9,"_",$M9,"_",$O9)) -> PA9633__44467_0.352638888888889___Null_44868_0.535520833333333_ | BH9: =IF(ISBLANK(IFERROR(MATCH(LEFT(BG9, FIND("__",BG9)-1),BE$2:BE815,0),"")),IFERROR(0/0,""),TRUE) | BI9: FLB2380__44537_0.201689814814815___Negative_44537_0.51181712962963_ | BJ9: =IFERROR(LEFT(BI9, FIND("__",BI9)-1),"") -> FLB2380 | BK9: =IFERROR(AND(EXACT(BJ10,BJ9),NOT(EXACT(BJ9,BJ8))),"") -> FALSE | BL9: =IF(BK9,BJ9,IFERROR(0/0,"")) | BN9: =OR(BO9,BP9) -> TRUE | BO9: =ISBLANK($AR9) -> FALSE | BP9: =IF(TRIM($AR9)="",TRUE,FALSE) -> TRUE | BR9: =IF(EXACT(AK9,"Null"),2.2,IFERROR(0/0,""))
A10: PA9584 | B10: 44467 | C10: 0.35299769 | K10: Null | L10: 44868 | M10: 0.53552083 | P10: =IFNA(IF(VLOOKUP($A10,'Add from APT'!$AA$2:$AC808,3,FALSE)>0,TRUE,FALSE),"ER - NOT IN APT") -> FALSE | Q10: =IF(ISLOGICAL(P10),IF(P10,"ER - REPS IN APT", IFNA(VLOOKUP($A10,RAW_APT!$A$3:$M808,7,FALSE),"ER - NOT IN APT")),P10) -> Collected | R10: =IF(EXACT($A10,$A9),FALSE,TRUE) -> TRUE | S10: =COUNTIF($A$2:$A816,$A10) -> 1 | X10: =IF(ISBLANK($U10),IF(ISBLANK($V10),FALSE,"ER - LAST ONLY"),TRUE) -> FALSE | Y10: FALSE | Z10: =IF($S10>4,TRUE,IFERROR(0/0,"")) | AA10: =IF(ISBLANK($O10),FALSE,TRUE) -> FALSE | AB10: FALSE | AC10: 799 | AD10: TRUE | AE10: =IFERROR(IF(EXACT($L10,$B10),(TIMEVALUE($M10)-TIMEVALUE($C10))*24*60,IFERROR(0/0,"")),IFERROR(0/0,"")) | AF10: =OR(AND(NOT($AG10),IFERROR(NOT($AG11),""),EXACT($A10,$A11),NOT(EXACT(CONCATENATE($B10,$C10),CONCATENATE($B11,$C11)))),AND(NOT($AG10),IFERROR(NOT($AG9),""),EXACT($A10,$A9),NOT(EXACT(CONCATENATE($B10,$C10),CONCATENATE($B9,$C9))))) -> FALSE | AG10: =IF($AH10>0,TRUE,FALSE) -> TRUE | AH10: 5.5 | AK10: =IFS(AND($AJ10>=2,$AJ10<3),"Negative",AND($AJ10>=3,$AJ10<4),"Positive",AND($AJ10>=4,$AJ10<5),"Inconclusive",$AJ10=5,"MANUAL FILL",$AG10,"DELETED",TRUE,$K10) -> DELETED | AM10: DELETED | AN10: DELETED | AO10: =IFERROR(__xludf.DUMMYFUNCTION("IF($AG10, ""DELETED"",TRIM(JOIN("" "",D10:E10)))"),"DELETED") -> DELETED | AP10: =IF($AG10, "DELETED", TRIM(CONCATENATE(F10,I10,U10))) -> DELETED | AQ10: =IF($AG10, "DELETED", TRIM(CONCATENATE(G10,J10,V10))) -> DELETED | AR10: =IFERROR(__xludf.DUMMYFUNCTION("IF($AG10, ""DELETED"", TRIM(JOIN("" "",AP10,AQ10)))"),"DELETED") -> DELETED | AT10: =IF(OR($AG10,SUM($AU10:$AW10)=1),TRUE,FALSE) -> TRUE | AU10: =IF($AG10,IFERROR(0/0,""),IF(ISBLANK($F10),IF(ISBLANK($G10),IFERROR(0/0,""),2),1)) | AV10: =IF($AG10,IFERROR(0/0,""),IF(ISBLANK($I10),IF(ISBLANK($J10),IFERROR(0/0,""),2),1)) | AW10: =IF($AG10,IFERROR(0/0,""),IF(ISBLANK($U10),IF(ISBLANK($V10),IFERROR(0/0,""),2),1)) | AX10: =IF(AND($X10,$A11=$A10),1,IFERROR(0/0,"")) | BA10: =IF(AG10,IFERROR(0/0,""),IF(EXACT(UPPER(A10),A10),IFERROR(0/0,""),TRUE)) | BF10: =IF(COUNTIF(BJ$2:BJ816,BE10)>0,COUNTIF(BJ$2:BJ816,BE10),IFERROR(0/0,"")) | BG10: =IF($AG10,IFERROR(0/0,""),CONCATENATE($A10,"__",$B10,"_",$C10,"_",$D10,"_",$E10,"_",$K10,"_",$L10,"_",$M10,"_",$O10)) | BH10: =IF(ISBLANK(IFERROR(MATCH(LEFT(BG10, FIND("__",BG10)-1),BE$2:BE816,0),"")),IFERROR(0/0,""),TRUE) | BI10: FLB2714__44529_0.235231481481482___Negative_44529_0.500277777777778_ | BJ10: =IFERROR(LEFT(BI10, FIND("__",BI10)-1),"") -> FLB2714 | BK10: =IFERROR(AND(EXACT(BJ11,BJ10),NOT(EXACT(BJ10,BJ9))),"") -> FALSE | BL10: =IF(BK10,BJ10,IFERROR(0/0,"")) | BN10: =OR(BO10,BP10) -> FALSE | BO10: =ISBLANK($AR10) -> FALSE | BP10: =IF(TRIM($AR10)="",TRUE,FALSE) -> FALSE | BR10: =IF(EXACT(AK10,"Null"),2.2,IFERROR(0/0,""))
A11: PA9480 | B11: 44468 | C11: 0.27606481 | K11: Null | L11: 44868 | M11: 0.53552083 | P11: =IFNA(IF(VLOOKUP($A11,'Add from APT'!$AA$2:$AC808,3,FALSE)>0,TRUE,FALSE),"ER - NOT IN APT") -> FALSE | Q11: =IF(ISLOGICAL(P11),IF(P11,"ER - REPS IN APT", IFNA(VLOOKUP($A11,RAW_APT!$A$3:$M808,7,FALSE),"ER - NOT IN APT")),P11) -> Collected | R11: =IF(EXACT($A11,$A10),FALSE,TRUE) -> TRUE | S11: =COUNTIF($A$2:$A817,$A11) -> 1 | T11: 0 | X11: =IF(ISBLANK($U11),IF(ISBLANK($V11),FALSE,"ER - LAST ONLY"),TRUE) -> FALSE | Y11: FALSE | Z11: =IF($S11>4,TRUE,IFERROR(0/0,"")) | AA11: =IF(ISBLANK($O11),FALSE,TRUE) -> FALSE | AB11: FALSE | AC11: 798 | AD11: TRUE | AE11: =IFERROR(IF(EXACT($L11,$B11),(TIMEVALUE($M11)-TIMEVALUE($C11))*24*60,IFERROR(0/0,"")),IFERROR(0/0,"")) | AF11: =OR(AND(NOT($AG11),IFERROR(NOT($AG12),""),EXACT($A11,$A12),NOT(EXACT(CONCATENATE($B11,$C11),CONCATENATE($B12,$C12)))),AND(NOT($AG11),IFERROR(NOT($AG10),""),EXACT($A11,$A10),NOT(EXACT(CONCATENATE($B11,$C11),CONCATENATE($B10,$C10))))) -> FALSE | AG11: =IF($AH11>0,TRUE,FALSE) -> FALSE | AJ11: 2.2 | AK11: =IFS(AND($AJ11>=2,$AJ11<3),"Negative",AND($AJ11>=3,$AJ11<4),"Positive",AND($AJ11>=4,$AJ11<5),"Inconclusive",$AJ11=5,"MANUAL FILL",$AG11,"DELETED",TRUE,$K11) -> Negative | AM11: SpROSA145068 | AN11: ROSA216934 | AO11: =IFERROR(__xludf.DUMMYFUNCTION("IF($AG11, ""DELETED"",TRIM(JOIN("" "",D11:E11)))"),"") | AP11: =IF($AG11, "DELETED", TRIM(CONCATENATE(F11,I11,U11))) | AQ11: =IF($AG11, "DELETED", TRIM(CONCATENATE(G11,J11,V11))) | AR11: =IFERROR(__xludf.DUMMYFUNCTION("IF($AG11, ""DELETED"", TRIM(JOIN("" "",AP11,AQ11)))"),"") | AT11: =IF(OR($AG11,SUM($AU11:$AW11)=1),TRUE,FALSE) -> FALSE | AU11: =IF($AG11,IFERROR(0/0,""),IF(ISBLANK($F11),IF(ISBLANK($G11),IFERROR(0/0,""),2),1)) | AV11: =IF($AG11,IFERROR(0/0,""),IF(ISBLANK($I11),IF(ISBLANK($J11),IFERROR(0/0,""),2),1)) | AW11: =IF($AG11,IFERROR(0/0,""),IF(ISBLANK($U11),IF(ISBLANK($V11),IFERROR(0/0,""),2),1)) | AX11: =IF(AND($X11,$A12=$A11),1,IFERROR(0/0,"")) | BA11: =IF(AG11,IFERROR(0/0,""),IF(EXACT(UPPER(A11),A11),IFERROR(0/0,""),TRUE)) | BF11: =IF(COUNTIF(BJ$2:BJ817,BE11)>0,COUNTIF(BJ$2:BJ817,BE11),IFERROR(0/0,"")) | BG11: =IF($AG11,IFERROR(0/0,""),CONCATENATE($A11,"__",$B11,"_",$C11,"_",$D11,"_",$E11,"_",$K11,"_",$L11,"_",$M11,"_",$O11)) -> PA9480__44468_0.276064814814815___Null_44868_0.535520833333333_ | BH11: =IF(ISBLANK(IFERROR(MATCH(LEFT(BG11, FIND("__",BG11)-1),BE$2:BE817,0),"")),IFERROR(0/0,""),TRUE) | BI11: FLB2715__44529_0.307766203703704___Negative_44529_0.500277777777778_ | BJ11: =IFERROR(LEFT(BI11, FIND("__",BI11)-1),"") -> FLB2715 | BK11: =IFERROR(AND(EXACT(BJ12,BJ11),NOT(EXACT(BJ11,BJ10))),"") -> FALSE | BL11: =IF(BK11,BJ11,IFERROR(0/0,"")) | BN11: =OR(BO11,BP11) -> TRUE | BO11: =ISBLANK($AR11) -> FALSE | BP11: =IF(TRIM($AR11)="",TRUE,FALSE) -> TRUE | BR11: =IF(EXACT(AK11,"Null"),2.2,IFERROR(0/0,""))
A12: PA9548 | B12: 44468 | C12: 0.27634259 | K12: Null | L12: 44868 | M12: 0.53552083 | P12: =IFNA(IF(VLOOKUP($A12,'Add from APT'!$AA$2:$AC808,3,FALSE)>0,TRUE,FALSE),"ER - NOT IN APT") -> FALSE | Q12: =IF(ISLOGICAL(P12),IF(P12,"ER - REPS IN APT", IFNA(VLOOKUP($A12,RAW_APT!$A$3:$M808,7,FALSE),"ER - NOT IN APT")),P12) -> Collected | R12: =IF(EXACT($A12,$A11),FALSE,TRUE) -> TRUE | S12: =COUNTIF($A$2:$A818,$A12) -> 1 | X12: =IF(ISBLANK($U12),IF(ISBLANK($V12),FALSE,"ER - LAST ONLY"),TRUE) -> FALSE | Y12: FALSE | Z12: =IF($S12>4,TRUE,IFERROR(0/0,"")) | AA12: =IF(ISBLANK($O12),FALSE,TRUE) -> FALSE | AB12: FALSE | AC12: 797 | AD12: TRUE | AE12: =IFERROR(IF(EXACT($L12,$B12),(TIMEVALUE($M12)-TIMEVALUE($C12))*24*60,IFERROR(0/0,"")),IFERROR(0/0,"")) | AF12: =OR(AND(NOT($AG12),IFERROR(NOT($AG13),""),EXACT($A12,$A13),NOT(EXACT(CONCATENATE($B12,$C12),CONCATENATE($B13,$C13)))),AND(NOT($AG12),IFERROR(NOT($AG11),""),EXACT($A12,$A11),NOT(EXACT(CONCATENATE($B12,$C12),CONCATENATE($B11,$C11))))) -> FALSE | AG12: =IF($AH12>0,TRUE,FALSE) -> TRUE | AH12: 5.5 | AK12: =IFS(AND($AJ12>=2,$AJ12<3),"Negative",AND($AJ12>=3,$AJ12<4),"Positive",AND($AJ12>=4,$AJ12<5),"Inconclusive",$AJ12=5,"MANUAL FILL",$AG12,"DELETED",TRUE,$K12) -> DELETED | AM12: DELETED | AN12: DELETED | AO12: =IFERROR(__xludf.DUMMYFUNCTION("IF($AG12, ""DELETED"",TRIM(JOIN("" "",D12:E12)))"),"DELETED") -> DELETED | AP12: =IF($AG12, "DELETED", TRIM(CONCATENATE(F12,I12,U12))) -> DELETED | AQ12: =IF($AG12, "DELETED", TRIM(CONCATENATE(G12,J12,V12))) -> DELETED | AR12: =IFERROR(__xludf.DUMMYFUNCTION("IF($AG12, ""DELETED"", TRIM(JOIN("" "",AP12,AQ12)))"),"DELETED") -> DELETED | AT12: =IF(OR($AG12,SUM($AU12:$AW12)=1),TRUE,FALSE) -> TRUE | AU12: =IF($AG12,IFERROR(0/0,""),IF(ISBLANK($F12),IF(ISBLANK($G12),IFERROR(0/0,""),2),1)) | AV12: =IF($AG12,IFERROR(0/0,""),IF(ISBLANK($I12),IF(ISBLANK($J12),IFERROR(0/0,""),2),1)) | AW12: =IF($AG12,IFERROR(0/0,""),IF(ISBLANK($U12),IF(ISBLANK($V12),IFERROR(0/0,""),2),1)) | AX12: =IF(AND($X12,$A13=$A12),1,IFERROR(0/0,"")) | BA12: =IF(AG12,IFERROR(0/0,""),IF(EXACT(UPPER(A12),A12),IFERROR(0/0,""),TRUE)) | BF12: =IF(COUNTIF(BJ$2:BJ818,BE12)>0,COUNTIF(BJ$2:BJ818,BE12),IFERROR(0/0,"")) | BG12: =IF($AG12,IFERROR(0/0,""),CONCATENATE($A12,"__",$B12,"_",$C12,"_",$D12,"_",$E12,"_",$K12,"_",$L12,"_",$M12,"_",$O12)) | BH12: =IF(ISBLANK(IFERROR(MATCH(LEFT(BG12, FIND("__",BG12)-1),BE$2:BE818,0),"")),IFERROR(0/0,""),TRUE) | BI12: FLB2716__44529_0.326863425925926___Negative_44529_0.500277777777778_ | BJ12: =IFERROR(LEFT(BI12, FIND("__",BI12)-1),"") -> FLB2716 | BK12: =IFERROR(AND(EXACT(BJ13,BJ12),NOT(EXACT(BJ12,BJ11))),"") -> FALSE | BL12: =IF(BK12,BJ12,IFERROR(0/0,"")) | BN12: =OR(BO12,BP12) -> FALSE | BO12: =ISBLANK($AR12) -> FALSE | BP12: =IF(TRIM($AR12)="",TRUE,FALSE) -> FALSE | BR12: =IF(EXACT(AK12,"Null"),2.2,IFERROR(0/0,""))
A13: PA9612 | B13: 44468 | C13: 0.27738426 | K13: Null | L13: 44868 | M13: 0.53552083 | P13: =IFNA(IF(VLOOKUP($A13,'Add from APT'!$AA$2:$AC808,3,FALSE)>0,TRUE,FALSE),"ER - NOT IN APT") -> FALSE | Q13: =IF(ISLOGICAL(P13),IF(P13,"ER - REPS IN APT", IFNA(VLOOKUP($A13,RAW_APT!$A$3:$M808,7,FALSE),"ER - NOT IN APT")),P13) -> Collected | R13: =IF(EXACT($A13,$A12),FALSE,TRUE) -> TRUE | S13: =COUNTIF($A$2:$A819,$A13) -> 1 | X13: =IF(ISBLANK($U13),IF(ISBLANK($V13),FALSE,"ER - LAST ONLY"),TRUE) -> FALSE | Y13: FALSE | Z13: =IF($S13>4,TRUE,IFERROR(0/0,"")) | AA13: =IF(ISBLANK($O13),FALSE,TRUE) -> FALSE | AB13: FALSE | AC13: 796 | AD13: TRUE | AE13: =IFERROR(IF(EXACT($L13,$B13),(TIMEVALUE($M13)-TIMEVALUE($C13))*24*60,IFERROR(0/0,"")),IFERROR(0/0,"")) | AF13: =OR(AND(NOT($AG13),IFERROR(NOT($AG14),""),EXACT($A13,$A14),NOT(EXACT(CONCATENATE($B13,$C13),CONCATENATE($B14,$C14)))),AND(NOT($AG13),IFERROR(NOT($AG12),""),EXACT($A13,$A12),NOT(EXACT(CONCATENATE($B13,$C13),CONCATENATE($B12,$C12))))) -> FALSE | AG13: =IF($AH13>0,TRUE,FALSE) -> TRUE | AH13: 5.5 | AK13: =IFS(AND($AJ13>=2,$AJ13<3),"Negative",AND($AJ13>=3,$AJ13<4),"Positive",AND($AJ13>=4,$AJ13<5),"Inconclusive",$AJ13=5,"MANUAL FILL",$AG13,"DELETED",TRUE,$K13) -> DELETED | AM13: DELETED | AN13: DELETED | AO13: =IFERROR(__xludf.DUMMYFUNCTION("IF($AG13, ""DELETED"",TRIM(JOIN("" "",D13:E13)))"),"DELETED") -> DELETED | AP13: =IF($AG13, "DELETED", TRIM(CONCATENATE(F13,I13,U13))) -> DELETED | AQ13: =IF($AG13, "DELETED", TRIM(CONCATENATE(G13,J13,V13))) -> DELETED | AR13: =IFERROR(__xludf.DUMMYFUNCTION("IF($AG13, ""DELETED"", TRIM(JOIN("" "",AP13,AQ13)))"),"DELETED") -> DELETED | AT13: =IF(OR($AG13,SUM($AU13:$AW13)=1),TRUE,FALSE) -> TRUE | AU13: =IF($AG13,IFERROR(0/0,""),IF(ISBLANK($F13),IF(ISBLANK($G13),IFERROR(0/0,""),2),1)) | AV13: =IF($AG13,IFERROR(0/0,""),IF(ISBLANK($I13),IF(ISBLANK($J13),IFERROR(0/0,""),2),1)) | AW13: =IF($AG13,IFERROR(0/0,""),IF(ISBLANK($U13),IF(ISBLANK($V13),IFERROR(0/0,""),2),1)) | AX13: =IF(AND($X13,$A14=$A13),1,IFERROR(0/0,"")) | BA13: =IF(AG13,IFERROR(0/0,""),IF(EXACT(UPPER(A13),A13),IFERROR(0/0,""),TRUE)) | BF13: =IF(COUNTIF(BJ$2:BJ819,BE13)>0,COUNTIF(BJ$2:BJ819,BE13),IFERROR(0/0,"")) | BG13: =IF($AG13,IFERROR(0/0,""),CONCATENATE($A13,"__",$B13,"_",$C13,"_",$D13,"_",$E13,"_",$K13,"_",$L13,"_",$M13,"_",$O13)) | BH13: =IF(ISBLANK(IFERROR(MATCH(LEFT(BG13, FIND("__",BG13)-1),BE$2:BE819,0),"")),IFERROR(0/0,""),TRUE) | BI13: FLB2717__44536_0.325625___Negative_44536_0.506469907407407_ | BJ13: =IFERROR(LEFT(BI13, FIND("__",BI13)-1),"") -> FLB2717 | BK13: =IFERROR(AND(EXACT(BJ14,BJ13),NOT(EXACT(BJ13,BJ12))),"") -> FALSE | BL13: =IF(BK13,BJ13,IFERROR(0/0,"")) | BN13: =OR(BO13,BP13) -> FALSE | BO13: =ISBLANK($AR13) -> FALSE | BP13: =IF(TRIM($AR13)="",TRUE,FALSE) -> FALSE | BR13: =IF(EXACT(AK13,"Null"),2.2,IFERROR(0/0,""))
A14: PA9565 | B14: 44468 | C14: 0.28090278 | K14: Null | L14: 44868 | M14: 0.53552083 | P14: =IFNA(IF(VLOOKUP($A14,'Add from APT'!$AA$2:$AC808,3,FALSE)>0,TRUE,FALSE),"ER - NOT IN APT") -> FALSE | Q14: =IF(ISLOGICAL(P14),IF(P14,"ER - REPS IN APT", IFNA(VLOOKUP($A14,RAW_APT!$A$3:$M808,7,FALSE),"ER - NOT IN APT")),P14) -> Collected | R14: =IF(EXACT($A14,$A13),FALSE,TRUE) -> TRUE | S14: =COUNTIF($A$2:$A820,$A14) -> 1 | X14: =IF(ISBLANK($U14),IF(ISBLANK($V14),FALSE,"ER - LAST ONLY"),TRUE) -> FALSE | Y14: FALSE | Z14: =IF($S14>4,TRUE,IFERROR(0/0,"")) | AA14: =IF(ISBLANK($O14),FALSE,TRUE) -> FALSE | AB14: FALSE | AC14: 795 | AD14: TRUE | AE14: =IFERROR(IF(EXACT($L14,$B14),(TIMEVALUE($M14)-TIMEVALUE($C14))*24*60,IFERROR(0/0,"")),IFERROR(0/0,"")) | AF14: =OR(AND(NOT($AG14),IFERROR(NOT($AG15),""),EXACT($A14,$A15),NOT(EXACT(CONCATENATE($B14,$C14),CONCATENATE($B15,$C15)))),AND(NOT($AG14),IFERROR(NOT($AG13),""),EXACT($A14,$A13),NOT(EXACT(CONCATENATE($B14,$C14),CONCATENATE($B13,$C13))))) -> FALSE | AG14: =IF($AH14>0,TRUE,FALSE) -> TRUE | AH14: 5.5 | AK14: =IFS(AND($AJ14>=2,$AJ14<3),"Negative",AND($AJ14>=3,$AJ14<4),"Positive",AND($AJ14>=4,$AJ14<5),"Inconclusive",$AJ14=5,"MANUAL FILL",$AG14,"DELETED",TRUE,$K14) -> DELETED | AM14: DELETED | AN14: DELETED | AO14: =IFERROR(__xludf.DUMMYFUNCTION("IF($AG14, ""DELETED"",TRIM(JOIN("" "",D14:E14)))"),"DELETED") -> DELETED | AP14: =IF($AG14, "DELETED", TRIM(CONCATENATE(F14,I14,U14))) -> DELETED | AQ14: =IF($AG14, "DELETED", TRIM(CONCATENATE(G14,J14,V14))) -> DELETED | AR14: =IFERROR(__xludf.DUMMYFUNCTION("IF($AG14, ""DELETED"", TRIM(JOIN("" "",AP14,AQ14)))"),"DELETED") -> DELETED | AT14: =IF(OR($AG14,SUM($AU14:$AW14)=1),TRUE,FALSE) -> TRUE | AU14: =IF($AG14,IFERROR(0/0,""),IF(ISBLANK($F14),IF(ISBLANK($G14),IFERROR(0/0,""),2),1)) | AV14: =IF($AG14,IFERROR(0/0,""),IF(ISBLANK($I14),IF(ISBLANK($J14),IFERROR(0/0,""),2),1)) | AW14: =IF($AG14,IFERROR(0/0,""),IF(ISBLANK($U14),IF(ISBLANK($V14),IFERROR(0/0,""),2),1)) | AX14: =IF(AND($X14,$A15=$A14),1,IFERROR(0/0,"")) | BA14: =IF(AG14,IFERROR(0/0,""),IF(EXACT(UPPER(A14),A14),IFERROR(0/0,""),TRUE)) | BF14: =IF(COUNTIF(BJ$2:BJ820,BE14)>0,COUNTIF(BJ$2:BJ820,BE14),IFERROR(0/0,"")) | BG14: =IF($AG14,IFERROR(0/0,""),CONCATENATE($A14,"__",$B14,"_",$C14,"_",$D14,"_",$E14,"_",$K14,"_",$L14,"_",$M14,"_",$O14)) | BH14: =IF(ISBLANK(IFERROR(MATCH(LEFT(BG14, FIND("__",BG14)-1),BE$2:BE820,0),"")),IFERROR(0/0,""),TRUE) | BI14: FLB2718__44536_0.25275462962963___Negative_44536_0.506458333333333_ | BJ14: =IFERROR(LEFT(BI14, FIND("__",BI14)-1),"") -> FLB2718 | BK14: =IFERROR(AND(EXACT(BJ15,BJ14),NOT(EXACT(BJ14,BJ13))),"") -> FALSE | BL14: =IF(BK14,BJ14,IFERROR(0/0,"")) | BN14: =OR(BO14,BP14) -> FALSE | BO14: =ISBLANK($AR14) -> FALSE | BP14: =IF(TRIM($AR14)="",TRUE,FALSE) -> FALSE | BR14: =IF(EXACT(AK14,"Null"),2.2,IFERROR(0/0,""))
